Workbook

Sheet SEED
B2: Ref_ID COA | C2: COA | D2: COA Name | F2: Link ID
B4: =[1]DataLookUp!$B$8 -> 65000000000005 | C4: =IF(EXACT($B4, ""), "", VLOOKUP($B4, [1]DataLookUp!$B$4:$D$1000, 2, FALSE)) -> 1-1101.01 | D4: =IF(EXACT($B4, ""), "", VLOOKUP($B4, [1]DataLookUp!$B$4:$D$1000, 3, FALSE)) -> Petty Cash (IDR)
B5: =[1]DataLookUp!$B$10 -> 65000000000007 | C5: =IF(EXACT($B5, ""), "", VLOOKUP($B5, [1]DataLookUp!$B$4:$D$1000, 2, FALSE)) -> 1-1102.01 | D5: =IF(EXACT($B5, ""), "", VLOOKUP($B5, [1]DataLookUp!$B$4:$D$1000, 3, FALSE)) -> Bank (IDR)
B6: =[1]DataLookUp!$B$11 -> 65000000000008 | C6: =IF(EXACT($B6, ""), "", VLOOKUP($B6, [1]DataLookUp!$B$4:$D$1000, 2, FALSE)) -> 1-1102.02 | D6: =IF(EXACT($B6, ""), "", VLOOKUP($B6, [1]DataLookUp!$B$4:$D$1000, 3, FALSE)) -> Bank (USD)
B7: =[1]DataLookUp!$B$13 -> 65000000000010 | C7: =IF(EXACT($B7, ""), "", VLOOKUP($B7, [1]DataLookUp!$B$4:$D$1000, 2, FALSE)) -> 1-1103.01 | D7: =IF(EXACT($B7, ""), "", VLOOKUP($B7, [1]DataLookUp!$B$4:$D$1000, 3, FALSE)) -> Money In Transfer (IDR)
B8: =[1]DataLookUp!$B$14 -> 65000000000011 | C8: =IF(EXACT($B8, ""), "", VLOOKUP($B8, [1]DataLookUp!$B$4:$D$1000, 2, FALSE)) -> 1-1200 | D8: =IF(EXACT($B8, ""), "", VLOOKUP($B8, [1]DataLookUp!$B$4:$D$1000, 3, FALSE)) -> Account Receivable
B9: =[1]DataLookUp!$B$15 -> 65000000000012 | C9: =IF(EXACT($B9, ""), "", VLOOKUP($B9, [1]DataLookUp!$B$4:$D$1000, 2, FALSE)) -> 1-1201 | D9: =IF(EXACT($B9, ""), "", VLOOKUP($B9, [1]DataLookUp!$B$4:$D$1000, 3, FALSE)) -> Piutang Usaha
B10: =[1]DataLookUp!$B$17 -> 65000000000014 | C10: =IF(EXACT($B10, ""), "", VLOOKUP($B10, [1]DataLookUp!$B$4:$D$1000, 2, FALSE)) -> 1-1201.02 | D10: =IF(EXACT($B10, ""), "", VLOOKUP($B10, [1]DataLookUp!$B$4:$D$1000, 3, FALSE)) -> AR (USD)
B11: =[1]DataLookUp!$B$18 -> 65000000000015 | C11: =IF(EXACT($B11, ""), "", VLOOKUP($B11, [1]DataLookUp!$B$4:$D$1000, 2, FALSE)) -> 1-1202 | D11: =IF(EXACT($B11, ""), "", VLOOKUP($B11, [1]DataLookUp!$B$4:$D$1000, 3, FALSE)) -> Cadangan Kerugian Piutang
B12: =[1]DataLookUp!$B$20 -> 65000000000017 | C12: =IF(EXACT($B12, ""), "", VLOOKUP($B12, [1]DataLookUp!$B$4:$D$1000, 2, FALSE)) -> 1-1202.02 | D12: =IF(EXACT($B12, ""), "", VLOOKUP($B12, [1]DataLookUp!$B$4:$D$1000, 3, FALSE)) -> Cadangan Kerugian Piutang (USD)
B13: =[1]DataLookUp!$B$21 -> 65000000000018 | C13: =IF(EXACT($B13, ""), "", VLOOKUP($B13, [1]DataLookUp!$B$4:$D$1000, 2, FALSE)) -> 1-1203 | D13: =IF(EXACT($B13, ""), "", VLOOKUP($B13, [1]DataLookUp!$B$4:$D$1000, 3, FALSE)) -> Piutang Non Usaha
B14: =[1]DataLookUp!$B$23 -> 65000000000020 | C14: =IF(EXACT($B14, ""), "", VLOOKUP($B14, [1]DataLookUp!$B$4:$D$1000, 2, FALSE)) -> 1-1203.02 | D14: =IF(EXACT($B14, ""), "", VLOOKUP($B14, [1]DataLookUp!$B$4:$D$1000, 3, FALSE)) -> Piutang Non Usaha (USD)
B15: =[1]DataLookUp!$B$24 -> 65000000000021 | C15: =IF(EXACT($B15, ""), "", VLOOKUP($B15, [1]DataLookUp!$B$4:$D$1000, 2, FALSE)) -> 1-1204 | D15: =IF(EXACT($B15, ""), "", VLOOKUP($B15, [1]DataLookUp!$B$4:$D$1000, 3, FALSE)) -> Piutang Antar Perusahaan
B16: =[1]DataLookUp!$B$27 -> 65000000000024 | C16: =IF(EXACT($B16, ""), "", VLOOKUP($B16, [1]DataLookUp!$B$4:$D$1000, 2, FALSE)) -> 1-1300 | D16: =IF(EXACT($B16, ""), "", VLOOKUP($B16, [1]DataLookUp!$B$4:$D$1000, 3, FALSE)) -> Inventory
B17: =[1]DataLookUp!$B$29 -> 65000000000026 | C17: =IF(EXACT($B17, ""), "", VLOOKUP($B17, [1]DataLookUp!$B$4:$D$1000, 2, FALSE)) -> 1-1301.01 | D17: =IF(EXACT($B17, ""), "", VLOOKUP($B17, [1]DataLookUp!$B$4:$D$1000, 3, FALSE)) -> Inventory (IDR)
B18: =[1]DataLookUp!$B$32 -> 65000000000029 | C18: =IF(EXACT($B18, ""), "", VLOOKUP($B18, [1]DataLookUp!$B$4:$D$1000, 2, FALSE)) -> 1-1500 | D18: =IF(EXACT($B18, ""), "", VLOOKUP($B18, [1]DataLookUp!$B$4:$D$1000, 3, FALSE)) -> Pajak Dibayar Dimuka
B19: =[1]DataLookUp!$B$34 -> 65000000000031 | C19: =IF(EXACT($B19, ""), "", VLOOKUP($B19, [1]DataLookUp!$B$4:$D$1000, 2, FALSE)) -> 1-1501.01 | D19: =IF(EXACT($B19, ""), "", VLOOKUP($B19, [1]DataLookUp!$B$4:$D$1000, 3, FALSE)) -> VAT IN (IDR)
B20: =[1]DataLookUp!$B$36 -> 65000000000033 | C20: =IF(EXACT($B20, ""), "", VLOOKUP($B20, [1]DataLookUp!$B$4:$D$1000, 2, FALSE)) -> 1-1502.01 | D20: =IF(EXACT($B20, ""), "", VLOOKUP($B20, [1]DataLookUp!$B$4:$D$1000, 3, FALSE)) -> Prepaid Tax 22 (IDR)
B21: =[1]DataLookUp!$B$38 -> 65000000000035 | C21: =IF(EXACT($B21, ""), "", VLOOKUP($B21, [1]DataLookUp!$B$4:$D$1000, 2, FALSE)) -> 1-1503.01 | D21: =IF(EXACT($B21, ""), "", VLOOKUP($B21, [1]DataLookUp!$B$4:$D$1000, 3, FALSE)) -> Prepaid Tax 23 (IDR)
B22: =[1]DataLookUp!$B$40 -> 65000000000037 | C22: =IF(EXACT($B22, ""), "", VLOOKUP($B22, [1]DataLookUp!$B$4:$D$1000, 2, FALSE)) -> 1-1504.01 | D22: =IF(EXACT($B22, ""), "", VLOOKUP($B22, [1]DataLookUp!$B$4:$D$1000, 3, FALSE)) -> Prepaid Tax 25 (IDR)
B23: =[1]DataLookUp!$B$42 -> 65000000000039 | C23: =IF(EXACT($B23, ""), "", VLOOKUP($B23, [1]DataLookUp!$B$4:$D$1000, 2, FALSE)) -> 1-1600.01 | D23: =IF(EXACT($B23, ""), "", VLOOKUP($B23, [1]DataLookUp!$B$4:$D$1000, 3, FALSE)) -> Perlengkapan Kantor (IDR)
B24: =[1]DataLookUp!$B$45 -> 65000000000042 | C24: =IF(EXACT($B24, ""), "", VLOOKUP($B24, [1]DataLookUp!$B$4:$D$1000, 2, FALSE)) -> 1-1900 | D24: =IF(EXACT($B24, ""), "", VLOOKUP($B24, [1]DataLookUp!$B$4:$D$1000, 3, FALSE)) -> Other Current Asset
B25: =[1]DataLookUp!$B$47 -> 65000000000044 | C25: =IF(EXACT($B25, ""), "", VLOOKUP($B25, [1]DataLookUp!$B$4:$D$1000, 2, FALSE)) -> 1-1901.01 | D25: =IF(EXACT($B25, ""), "", VLOOKUP($B25, [1]DataLookUp!$B$4:$D$1000, 3, FALSE)) -> Paid in Advance (IDR)
B26: =[1]DataLookUp!$B$49 -> 65000000000046 | C26: =IF(EXACT($B26, ""), "", VLOOKUP($B26, [1]DataLookUp!$B$4:$D$1000, 2, FALSE)) -> 1-1902.01 | D26: =IF(EXACT($B26, ""), "", VLOOKUP($B26, [1]DataLookUp!$B$4:$D$1000, 3, FALSE)) -> Suspense (IDR)
B27: =[1]DataLookUp!$B$51 -> 65000000000048 | C27: =IF(EXACT($B27, ""), "", VLOOKUP($B27, [1]DataLookUp!$B$4:$D$1000, 2, FALSE)) -> 1-1903.01 | D27: =IF(EXACT($B27, ""), "", VLOOKUP($B27, [1]DataLookUp!$B$4:$D$1000, 3, FALSE)) -> Security Deposit (IDR)
B28: =[1]DataLookUp!$B$53 -> 65000000000050 | C28: =IF(EXACT($B28, ""), "", VLOOKUP($B28, [1]DataLookUp!$B$4:$D$1000, 2, FALSE)) -> 1-1904.01 | D28: =IF(EXACT($B28, ""), "", VLOOKUP($B28, [1]DataLookUp!$B$4:$D$1000, 3, FALSE)) -> Unbilled Receivable (IDR)
B29: =[1]DataLookUp!$B$55 -> 65000000000052 | C29: =IF(EXACT($B29, ""), "", VLOOKUP($B29, [1]DataLookUp!$B$4:$D$1000, 2, FALSE)) -> 1-1905.01 | D29: =IF(EXACT($B29, ""), "", VLOOKUP($B29, [1]DataLookUp!$B$4:$D$1000, 3, FALSE)) -> Work in Progress (IDR)
B30: =[1]DataLookUp!$B$58 -> 65000000000055 | C30: =IF(EXACT($B30, ""), "", VLOOKUP($B30, [1]DataLookUp!$B$4:$D$1000, 2, FALSE)) -> 1-2000 | D30: =IF(EXACT($B30, ""), "", VLOOKUP($B30, [1]DataLookUp!$B$4:$D$1000, 3, FALSE)) -> Investasi Jangka Panjang
B31: =[1]DataLookUp!$B$62 -> 65000000000059 | C31: =IF(EXACT($B31, ""), "", VLOOKUP($B31, [1]DataLookUp!$B$4:$D$1000, 2, FALSE)) -> 1-3100 | D31: =IF(EXACT($B31, ""), "", VLOOKUP($B31, [1]DataLookUp!$B$4:$D$1000, 3, FALSE)) -> Aset Tetap
B32: =[1]DataLookUp!$B$64 -> 65000000000061 | C32: =IF(EXACT($B32, ""), "", VLOOKUP($B32, [1]DataLookUp!$B$4:$D$1000, 2, FALSE)) -> 1-3101.01 | D32: =IF(EXACT($B32, ""), "", VLOOKUP($B32, [1]DataLookUp!$B$4:$D$1000, 3, FALSE)) -> Land (IDR)
B33: =[1]DataLookUp!$B$66 -> 65000000000063 | C33: =IF(EXACT($B33, ""), "", VLOOKUP($B33, [1]DataLookUp!$B$4:$D$1000, 2, FALSE)) -> 1-3102.01 | D33: =IF(EXACT($B33, ""), "", VLOOKUP($B33, [1]DataLookUp!$B$4:$D$1000, 3, FALSE)) -> Building - Improvement (IDR)
B34: =[1]DataLookUp!$B$68 -> 65000000000065 | C34: =IF(EXACT($B34, ""), "", VLOOKUP($B34, [1]DataLookUp!$B$4:$D$1000, 2, FALSE)) -> 1-3103.01 | D34: =IF(EXACT($B34, ""), "", VLOOKUP($B34, [1]DataLookUp!$B$4:$D$1000, 3, FALSE)) -> Building - Office (IDR)
B35: =[1]DataLookUp!$B$70 -> 65000000000067 | C35: =IF(EXACT($B35, ""), "", VLOOKUP($B35, [1]DataLookUp!$B$4:$D$1000, 2, FALSE)) -> 1-3104.01 | D35: =IF(EXACT($B35, ""), "", VLOOKUP($B35, [1]DataLookUp!$B$4:$D$1000, 3, FALSE)) -> Info Tech Equipment (IDR)
B36: =[1]DataLookUp!$B$72 -> 65000000000069 | C36: =IF(EXACT($B36, ""), "", VLOOKUP($B36, [1]DataLookUp!$B$4:$D$1000, 2, FALSE)) -> 1-3105.01 | D36: =IF(EXACT($B36, ""), "", VLOOKUP($B36, [1]DataLookUp!$B$4:$D$1000, 3, FALSE)) -> Office Machine & Equipment (IDR)
B37: =[1]DataLookUp!$B$74 -> 65000000000071 | C37: =IF(EXACT($B37, ""), "", VLOOKUP($B37, [1]DataLookUp!$B$4:$D$1000, 2, FALSE)) -> 1-3106.01 | D37: =IF(EXACT($B37, ""), "", VLOOKUP($B37, [1]DataLookUp!$B$4:$D$1000, 3, FALSE)) -> Sundry Plant & Equipment (IDR)
B38: =[1]DataLookUp!$B$76 -> 65000000000073 | C38: =IF(EXACT($B38, ""), "", VLOOKUP($B38, [1]DataLookUp!$B$4:$D$1000, 2, FALSE)) -> 1-3107.01 | D38: =IF(EXACT($B38, ""), "", VLOOKUP($B38, [1]DataLookUp!$B$4:$D$1000, 3, FALSE)) -> Test Equipment (IDR)
B39: =[1]DataLookUp!$B$78 -> 65000000000075 | C39: =IF(EXACT($B39, ""), "", VLOOKUP($B39, [1]DataLookUp!$B$4:$D$1000, 2, FALSE)) -> 1-3108.01 | D39: =IF(EXACT($B39, ""), "", VLOOKUP($B39, [1]DataLookUp!$B$4:$D$1000, 3, FALSE)) -> Motor Vehicle (IDR)
B40: =[1]DataLookUp!$B$80 -> 65000000000077 | C40: =IF(EXACT($B40, ""), "", VLOOKUP($B40, [1]DataLookUp!$B$4:$D$1000, 2, FALSE)) -> 1-3109.01 | D40: =IF(EXACT($B40, ""), "", VLOOKUP($B40, [1]DataLookUp!$B$4:$D$1000, 3, FALSE)) -> Tools (IDR)
B41: =[1]DataLookUp!$B$82 -> 65000000000079 | C41: =IF(EXACT($B41, ""), "", VLOOKUP($B41, [1]DataLookUp!$B$4:$D$1000, 2, FALSE)) -> 1-3110.01 | D41: =IF(EXACT($B41, ""), "", VLOOKUP($B41, [1]DataLookUp!$B$4:$D$1000, 3, FALSE)) -> Furniture Fitting (IDR)
B42: =[1]DataLookUp!$B$85 -> 65000000000082 | C42: =IF(EXACT($B42, ""), "", VLOOKUP($B42, [1]DataLookUp!$B$4:$D$1000, 2, FALSE)) -> 1-3200 | D42: =IF(EXACT($B42, ""), "", VLOOKUP($B42, [1]DataLookUp!$B$4:$D$1000, 3, FALSE)) -> Akumulasi Penyusutan Aktiva Tetap
...

Sheet SEED 1-1101.01
B2: PARENT COA
B3: =SUBSTITUTE(RIGHT(CELL("filename", $A$1), LEN(CELL("filename", $A$1))-FIND("]", CELL("filename", $A$1), 1)), "SEED ", "") -> 1-1101.01 | C3: =IF(EXACT(B3, ""), "", VLOOKUP(B3, SEED!C4:D258, 2, FALSE)) -> Petty Cash (IDR)
B5: Ref_ID COA | C5: Linkage_RefID | D5: Name | E5: Full Name | F5: Sign Other Things | G5: COA Suffix
B7: =$B$3 -> 1-1101.01 | D7: Lainnya | E7: =IF(EXACT($D7, ""), "", CONCATENATE($C$3, " - ", $D7)) -> Petty Cash (IDR) - Lainnya | F7: TRUE | G7: =IF(EXACT($B7, ""), "", CONCATENATE($B7, ".", TEXT(IF(ROW($B$7)=ROW($B7), IF(EXACT($F7, "FALSE"), 1, 0), (RIGHT($G6, 6)*1)+1), "000000"))) -> 1-1101.01.000000
B8: =$B$3 -> 1-1101.01 | D8: Kantor Pusat | E8: =IF(EXACT($D8, ""), "", CONCATENATE($C$3, " - ", $D8)) -> Petty Cash (IDR) - Kantor Pusat | F8: FALSE | G8: =IF(EXACT($B8, ""), "", CONCATENATE($B8, ".", TEXT(IF(ROW($B$7)=ROW($B8), IF(EXACT($F8, "FALSE"), 1, 0), (RIGHT($G7, 6)*1)+1), "000000"))) -> 1-1101.01.000001
B9: =$B$3 -> 1-1101.01 | D9: PJO Surabaya | E9: =IF(EXACT($D9, ""), "", CONCATENATE($C$3, " - ", $D9)) -> Petty Cash (IDR) - PJO Surabaya | F9: FALSE | G9: =IF(EXACT($B9, ""), "", CONCATENATE($B9, ".", TEXT(IF(ROW($B$7)=ROW($B9), IF(EXACT($F9, "FALSE"), 1, 0), (RIGHT($G8, 6)*1)+1), "000000"))) -> 1-1101.01.000002
B10: =$B$3 -> 1-1101.01 | D10: PJO Medan | E10: =IF(EXACT($D10, ""), "", CONCATENATE($C$3, " - ", $D10)) -> Petty Cash (IDR) - PJO Medan | F10: FALSE | G10: =IF(EXACT($B10, ""), "", CONCATENATE($B10, ".", TEXT(IF(ROW($B$7)=ROW($B10), IF(EXACT($F10, "FALSE"), 1, 0), (RIGHT($G9, 6)*1)+1), "000000"))) -> 1-1101.01.000003

Sheet SEED 1-1102.01
B2: PARENT COA
B3: =SUBSTITUTE(RIGHT(CELL("filename", $A$1), LEN(CELL("filename", $A$1))-FIND("]", CELL("filename", $A$1), 1)), "SEED ", "") -> 1-1102.01 | C3: =IF(EXACT(B3, ""), "", VLOOKUP(B3, SEED!C4:D258, 2, FALSE)) -> Bank (IDR)
B5: Ref_ID COA | C5: Linkage_RefID | D5: Name | E5: Full Name | F5: Sign Other Things | G5: COA Suffix
B7: =$B$3 -> 1-1102.01 | D7: MT | E7: =IF(EXACT($D7, ""), "", CONCATENATE($C$3, " - ", $D7)) -> Bank (IDR) - MT | F7: FALSE | G7: =IF(EXACT($B7, ""), "", CONCATENATE($B7, ".", TEXT(IF(ROW($B$7)=ROW($B7), IF(EXACT($F7, "FALSE"), 1, 0), (RIGHT($G6, 6)*1)+1), "000000"))) -> 1-1102.01.000001
B8: =$B$3 -> 1-1102.01 | C8: 167000000000001 | D8: =IF(EXACT($C8, ""), "", VLOOKUP($C8, [2]DataLookUp!$B$4:$C$4000, 2, FALSE)) -> Bank Central Asia - 0063032911 | E8: =IF(EXACT($D8, ""), "", CONCATENATE($C$3, " - ", $D8)) -> Bank (IDR) - Bank Central Asia - 0063032911 | F8: FALSE | G8: =IF(EXACT($B8, ""), "", CONCATENATE($B8, ".", TEXT(IF(ROW($B$7)=ROW($B8), IF(EXACT($F8, "FALSE"), 1, 0), (RIGHT($G7, 6)*1)+1), "000000"))) -> 1-1102.01.000002
B9: =$B$3 -> 1-1102.01 | C9: 167000000000002 | D9: =IF(EXACT($C9, ""), "", VLOOKUP($C9, [2]DataLookUp!$B$4:$C$4000, 2, FALSE)) -> Bank Central Asia - 0065557750 | E9: =IF(EXACT($D9, ""), "", CONCATENATE($C$3, " - ", $D9)) -> Bank (IDR) - Bank Central Asia - 0065557750 | F9: FALSE | G9: =IF(EXACT($B9, ""), "", CONCATENATE($B9, ".", TEXT(IF(ROW($B$7)=ROW($B9), IF(EXACT($F9, "FALSE"), 1, 0), (RIGHT($G8, 6)*1)+1), "000000"))) -> 1-1102.01.000003
B10: =$B$3 -> 1-1102.01 | C10: 167000000000003 | D10: =IF(EXACT($C10, ""), "", VLOOKUP($C10, [2]DataLookUp!$B$4:$C$4000, 2, FALSE)) -> Bank Central Asia - 0068502911 | E10: =IF(EXACT($D10, ""), "", CONCATENATE($C$3, " - ", $D10)) -> Bank (IDR) - Bank Central Asia - 0068502911 | F10: FALSE | G10: =IF(EXACT($B10, ""), "", CONCATENATE($B10, ".", TEXT(IF(ROW($B$7)=ROW($B10), IF(EXACT($F10, "FALSE"), 1, 0), (RIGHT($G9, 6)*1)+1), "000000"))) -> 1-1102.01.000004
B11: =$B$3 -> 1-1102.01 | C11: 167000000000004 | D11: =IF(EXACT($C11, ""), "", VLOOKUP($C11, [2]DataLookUp!$B$4:$C$4000, 2, FALSE)) -> Bank Central Asia - 2173050101 | E11: =IF(EXACT($D11, ""), "", CONCATENATE($C$3, " - ", $D11)) -> Bank (IDR) - Bank Central Asia - 2173050101 | F11: FALSE | G11: =IF(EXACT($B11, ""), "", CONCATENATE($B11, ".", TEXT(IF(ROW($B$7)=ROW($B11), IF(EXACT($F11, "FALSE"), 1, 0), (RIGHT($G10, 6)*1)+1), "000000"))) -> 1-1102.01.000005
B12: =$B$3 -> 1-1102.01 | C12: 167000000000005 | D12: =IF(EXACT($C12, ""), "", VLOOKUP($C12, [2]DataLookUp!$B$4:$C$4000, 2, FALSE)) -> Bank Central Asia - 2173108214 | E12: =IF(EXACT($D12, ""), "", CONCATENATE($C$3, " - ", $D12)) -> Bank (IDR) - Bank Central Asia - 2173108214 | F12: FALSE | G12: =IF(EXACT($B12, ""), "", CONCATENATE($B12, ".", TEXT(IF(ROW($B$7)=ROW($B12), IF(EXACT($F12, "FALSE"), 1, 0), (RIGHT($G11, 6)*1)+1), "000000"))) -> 1-1102.01.000006
B13: =$B$3 -> 1-1102.01 | C13: 167000000000006 | D13: =IF(EXACT($C13, ""), "", VLOOKUP($C13, [2]DataLookUp!$B$4:$C$4000, 2, FALSE)) -> Bank CIMB Niaga - 762375277200 | E13: =IF(EXACT($D13, ""), "", CONCATENATE($C$3, " - ", $D13)) -> Bank (IDR) - Bank CIMB Niaga - 762375277200 | F13: FALSE | G13: =IF(EXACT($B13, ""), "", CONCATENATE($B13, ".", TEXT(IF(ROW($B$7)=ROW($B13), IF(EXACT($F13, "FALSE"), 1, 0), (RIGHT($G12, 6)*1)+1), "000000"))) -> 1-1102.01.000007
B14: =$B$3 -> 1-1102.01 | C14: 167000000000007 | D14: =IF(EXACT($C14, ""), "", VLOOKUP($C14, [2]DataLookUp!$B$4:$C$4000, 2, FALSE)) -> Bank CIMB Niaga - 800039839400 | E14: =IF(EXACT($D14, ""), "", CONCATENATE($C$3, " - ", $D14)) -> Bank (IDR) - Bank CIMB Niaga - 800039839400 | F14: FALSE | G14: =IF(EXACT($B14, ""), "", CONCATENATE($B14, ".", TEXT(IF(ROW($B$7)=ROW($B14), IF(EXACT($F14, "FALSE"), 1, 0), (RIGHT($G13, 6)*1)+1), "000000"))) -> 1-1102.01.000008
B15: =$B$3 -> 1-1102.01 | C15: 167000000000008 | D15: =IF(EXACT($C15, ""), "", VLOOKUP($C15, [2]DataLookUp!$B$4:$C$4000, 2, FALSE)) -> Bank CIMB Niaga - 800039840100 | E15: =IF(EXACT($D15, ""), "", CONCATENATE($C$3, " - ", $D15)) -> Bank (IDR) - Bank CIMB Niaga - 800039840100 | F15: FALSE | G15: =IF(EXACT($B15, ""), "", CONCATENATE($B15, ".", TEXT(IF(ROW($B$7)=ROW($B15), IF(EXACT($F15, "FALSE"), 1, 0), (RIGHT($G14, 6)*1)+1), "000000"))) -> 1-1102.01.000009
B16: =$B$3 -> 1-1102.01 | C16: 167000000000009 | D16: =IF(EXACT($C16, ""), "", VLOOKUP($C16, [2]DataLookUp!$B$4:$C$4000, 2, FALSE)) -> Bank CIMB Niaga - 860012900500 | E16: =IF(EXACT($D16, ""), "", CONCATENATE($C$3, " - ", $D16)) -> Bank (IDR) - Bank CIMB Niaga - 860012900500 | F16: FALSE | G16: =IF(EXACT($B16, ""), "", CONCATENATE($B16, ".", TEXT(IF(ROW($B$7)=ROW($B16), IF(EXACT($F16, "FALSE"), 1, 0), (RIGHT($G15, 6)*1)+1), "000000"))) -> 1-1102.01.000010
B17: =$B$3 -> 1-1102.01 | C17: 167000000000010 | D17: =IF(EXACT($C17, ""), "", VLOOKUP($C17, [2]DataLookUp!$B$4:$C$4000, 2, FALSE)) -> Bank Commonwealth - 1051189606 | E17: =IF(EXACT($D17, ""), "", CONCATENATE($C$3, " - ", $D17)) -> Bank (IDR) - Bank Commonwealth - 1051189606 | F17: FALSE | G17: =IF(EXACT($B17, ""), "", CONCATENATE($B17, ".", TEXT(IF(ROW($B$7)=ROW($B17), IF(EXACT($F17, "FALSE"), 1, 0), (RIGHT($G16, 6)*1)+1), "000000"))) -> 1-1102.01.000011
B18: =$B$3 -> 1-1102.01 | C18: 167000000000012 | D18: =IF(EXACT($C18, ""), "", VLOOKUP($C18, [2]DataLookUp!$B$4:$C$4000, 2, FALSE)) -> Bank KB Bukopin - 1001327468 | E18: =IF(EXACT($D18, ""), "", CONCATENATE($C$3, " - ", $D18)) -> Bank (IDR) - Bank KB Bukopin - 1001327468 | F18: FALSE | G18: =IF(EXACT($B18, ""), "", CONCATENATE($B18, ".", TEXT(IF(ROW($B$7)=ROW($B18), IF(EXACT($F18, "FALSE"), 1, 0), (RIGHT($G17, 6)*1)+1), "000000"))) -> 1-1102.01.000012
B19: =$B$3 -> 1-1102.01 | C19: 167000000000013 | D19: =IF(EXACT($C19, ""), "", VLOOKUP($C19, [2]DataLookUp!$B$4:$C$4000, 2, FALSE)) -> Bank KB Bukopin - 1001374466 | E19: =IF(EXACT($D19, ""), "", CONCATENATE($C$3, " - ", $D19)) -> Bank (IDR) - Bank KB Bukopin - 1001374466 | F19: FALSE | G19: =IF(EXACT($B19, ""), "", CONCATENATE($B19, ".", TEXT(IF(ROW($B$7)=ROW($B19), IF(EXACT($F19, "FALSE"), 1, 0), (RIGHT($G18, 6)*1)+1), "000000"))) -> 1-1102.01.000013
... B58: =$B$3 -> 1-1102.01 | C58: 167000000000056 | D58: =IF(EXACT($C58, ""), "", VLOOKUP($C58, [2]DataLookUp!$B$4:$C$4000, 2, FALSE)) -> Bank Tabungan Negara - 0100201300000052 | E58: =IF(EXACT($D58, ""), "", CONCATENATE($C$3, " - ", $D58)) -> Bank (IDR) - Bank Tabungan Negara - 0100201300000052 | F58: FALSE | G58: =IF(EXACT($B58, ""), "", CONCATENATE($B58, ".", TEXT(IF(ROW($B$7)=ROW($B58), IF(EXACT($F58, "FALSE"), 1, 0), (RIGHT($G57, 6)*1)+1), "000000"))) -> 1-1102.01.000052

Sheet SEED 1-1102.02
B2: PARENT COA
B3: =SUBSTITUTE(RIGHT(CELL("filename", $A$1), LEN(CELL("filename", $A$1))-FIND("]", CELL("filename", $A$1), 1)), "SEED ", "") -> 1-1102.02 | C3: =IF(EXACT(B3, ""), "", VLOOKUP(B3, SEED!C4:D258, 2, FALSE)) -> Bank (USD)
B5: Ref_ID COA | C5: Linkage_RefID | D5: Name | E5: Full Name | F5: Sign Other Things | G5: COA Suffix
B7: =$B$3 -> 1-1102.02 | C7: 167000000000011 | D7: =IF(EXACT($C7, ""), "", VLOOKUP($C7, [2]DataLookUp!$B$4:$C$4000, 2, FALSE)) -> Bank Commonwealth - 1051189707 | E7: =IF(EXACT($D7, ""), "", CONCATENATE($C$3, " - ", $D7)) -> Bank (USD) - Bank Commonwealth - 1051189707 | F7: FALSE | G7: =IF(EXACT($B7, ""), "", CONCATENATE($B7, ".", TEXT(IF(ROW($B$7)=ROW($B7), IF(EXACT($F7, "FALSE"), 1, 0), (RIGHT($G6, 6)*1)+1), "000000"))) -> 1-1102.02.000001
B8: =$B$3 -> 1-1102.02 | C8: 167000000000029 | D8: =IF(EXACT($C8, ""), "", VLOOKUP($C8, [2]DataLookUp!$B$4:$C$4000, 2, FALSE)) -> Bank Permata - 0701393414 | E8: =IF(EXACT($D8, ""), "", CONCATENATE($C$3, " - ", $D8)) -> Bank (USD) - Bank Permata - 0701393414 | F8: FALSE | G8: =IF(EXACT($B8, ""), "", CONCATENATE($B8, ".", TEXT(IF(ROW($B$7)=ROW($B8), IF(EXACT($F8, "FALSE"), 1, 0), (RIGHT($G7, 6)*1)+1), "000000"))) -> 1-1102.02.000002
B9: =$B$3 -> 1-1102.02 | C9: 167000000000030 | D9: =IF(EXACT($C9, ""), "", VLOOKUP($C9, [2]DataLookUp!$B$4:$C$4000, 2, FALSE)) -> Bank Permata - 0701393481 | E9: =IF(EXACT($D9, ""), "", CONCATENATE($C$3, " - ", $D9)) -> Bank (USD) - Bank Permata - 0701393481 | F9: FALSE | G9: =IF(EXACT($B9, ""), "", CONCATENATE($B9, ".", TEXT(IF(ROW($B$7)=ROW($B9), IF(EXACT($F9, "FALSE"), 1, 0), (RIGHT($G8, 6)*1)+1), "000000"))) -> 1-1102.02.000003
B10: =$B$3 -> 1-1102.02 | C10: 167000000000048 | D10: =IF(EXACT($C10, ""), "", VLOOKUP($C10, [2]DataLookUp!$B$4:$C$4000, 2, FALSE)) -> Bank Rakyat Indonesia - 34101002395300 | E10: =IF(EXACT($D10, ""), "", CONCATENATE($C$3, " - ", $D10)) -> Bank (USD) - Bank Rakyat Indonesia - 34101002395300 | F10: FALSE | G10: =IF(EXACT($B10, ""), "", CONCATENATE($B10, ".", TEXT(IF(ROW($B$7)=ROW($B10), IF(EXACT($F10, "FALSE"), 1, 0), (RIGHT($G9, 6)*1)+1), "000000"))) -> 1-1102.02.000004
B11: =$B$3 -> 1-1102.02 | C11: 167000000000049 | D11: =IF(EXACT($C11, ""), "", VLOOKUP($C11, [2]DataLookUp!$B$4:$C$4000, 2, FALSE)) -> Bank Standard Chartered - 30601430287 | E11: =IF(EXACT($D11, ""), "", CONCATENATE($C$3, " - ", $D11)) -> Bank (USD) - Bank Standard Chartered - 30601430287 | F11: FALSE | G11: =IF(EXACT($B11, ""), "", CONCATENATE($B11, ".", TEXT(IF(ROW($B$7)=ROW($B11), IF(EXACT($F11, "FALSE"), 1, 0), (RIGHT($G10, 6)*1)+1), "000000"))) -> 1-1102.02.000005

Sheet SEED 1-1700.01
B2: PARENT COA
B3: =SUBSTITUTE(RIGHT(CELL("filename", $A$1), LEN(CELL("filename", $A$1))-FIND("]", CELL("filename", $A$1), 1)), "SEED ", "") -> 1-1700.01 | C3: =IF(EXACT(B3, ""), "", VLOOKUP(B3, SEED!C4:D258, 2, FALSE)) -> #N/A
B5: Ref_ID COA | C5: Linkage_RefID | D5: Name | E5: Full Name | F5: Sign Other Things | G5: COA Suffix
B7: =$B$3 -> 1-1700.01 | D7: Lainnya | E7: =IF(EXACT($D7, ""), "", CONCATENATE($C$3, " - ", $D7)) -> #N/A | F7: TRUE | G7: =IF(EXACT($B7, ""), "", CONCATENATE($B7, ".", TEXT(IF(ROW($B$7)=ROW($B7), IF(EXACT($F7, "FALSE"), 1, 0), (RIGHT($G6, 6)*1)+1), "000000"))) -> 1-1700.01.000000
B8: =$B$3 -> 1-1700.01 | C8: 32000000000012 | D8: =IF(EXACT($C8, ""), "", CONCATENATE(VLOOKUP($C8, [3]DataLookUp!$B$4:$E$4000, 3, FALSE), IF(EXACT(VLOOKUP($C8, [3]DataLookUp!$B$4:$E$4000, 4, FALSE), ""), "", CONCATENATE(" (NIK : ", VLOOKUP($C8, [3]DataLookUp!$B$4:$E$4000, 4, FALSE),")")))) -> Agnes Sutedja (NIK : 010703020) | E8: =IF(EXACT($D8, ""), "", CONCATENATE($C$3, " - ", $D8)) -> #N/A | F8: FALSE | G8: =IF(EXACT($B8, ""), "", CONCATENATE($B8, ".", TEXT(IF(ROW($B$7)=ROW($B8), IF(EXACT($F8, "FALSE"), 1, 0), (RIGHT($G7, 6)*1)+1), "000000"))) -> 1-1700.01.000001
B9: =$B$3 -> 1-1700.01 | C9: 32000000000017 | D9: =IF(EXACT($C9, ""), "", CONCATENATE(VLOOKUP($C9, [3]DataLookUp!$B$4:$E$4000, 3, FALSE), IF(EXACT(VLOOKUP($C9, [3]DataLookUp!$B$4:$E$4000, 4, FALSE), ""), "", CONCATENATE(" (NIK : ", VLOOKUP($C9, [3]DataLookUp!$B$4:$E$4000, 4, FALSE),")")))) -> Ahmad Faiz Haems Muda (NIK : 280314716) | E9: =IF(EXACT($D9, ""), "", CONCATENATE($C$3, " - ", $D9)) -> #N/A | F9: FALSE | G9: =IF(EXACT($B9, ""), "", CONCATENATE($B9, ".", TEXT(IF(ROW($B$7)=ROW($B9), IF(EXACT($F9, "FALSE"), 1, 0), (RIGHT($G8, 6)*1)+1), "000000"))) -> 1-1700.01.000002
B10: =$B$3 -> 1-1700.01 | C10: 32000000000023 | D10: =IF(EXACT($C10, ""), "", CONCATENATE(VLOOKUP($C10, [3]DataLookUp!$B$4:$E$4000, 3, FALSE), IF(EXACT(VLOOKUP($C10, [3]DataLookUp!$B$4:$E$4000, 4, FALSE), ""), "", CONCATENATE(" (NIK : ", VLOOKUP($C10, [3]DataLookUp!$B$4:$E$4000, 4, FALSE),")")))) -> Aldi Mulyadi (NIK : 141020935) | E10: =IF(EXACT($D10, ""), "", CONCATENATE($C$3, " - ", $D10)) -> #N/A | F10: FALSE | G10: =IF(EXACT($B10, ""), "", CONCATENATE($B10, ".", TEXT(IF(ROW($B$7)=ROW($B10), IF(EXACT($F10, "FALSE"), 1, 0), (RIGHT($G9, 6)*1)+1), "000000"))) -> 1-1700.01.000003
B11: =$B$3 -> 1-1700.01 | C11: 32000000000075 | D11: =IF(EXACT($C11, ""), "", CONCATENATE(VLOOKUP($C11, [3]DataLookUp!$B$4:$E$4000, 3, FALSE), IF(EXACT(VLOOKUP($C11, [3]DataLookUp!$B$4:$E$4000, 4, FALSE), ""), "", CONCATENATE(" (NIK : ", VLOOKUP($C11, [3]DataLookUp!$B$4:$E$4000, 4, FALSE),")")))) -> Belina Lindarwani (NIK : 100920934) | E11: =IF(EXACT($D11, ""), "", CONCATENATE($C$3, " - ", $D11)) -> #N/A | F11: FALSE | G11: =IF(EXACT($B11, ""), "", CONCATENATE($B11, ".", TEXT(IF(ROW($B$7)=ROW($B11), IF(EXACT($F11, "FALSE"), 1, 0), (RIGHT($G10, 6)*1)+1), "000000"))) -> 1-1700.01.000004
B12: =$B$3 -> 1-1700.01 | C12: 32000000000082 | D12: =IF(EXACT($C12, ""), "", CONCATENATE(VLOOKUP($C12, [3]DataLookUp!$B$4:$E$4000, 3, FALSE), IF(EXACT(VLOOKUP($C12, [3]DataLookUp!$B$4:$E$4000, 4, FALSE), ""), "", CONCATENATE(" (NIK : ", VLOOKUP($C12, [3]DataLookUp!$B$4:$E$4000, 4, FALSE),")")))) -> Budianto (NIK : 060515769) | E12: =IF(EXACT($D12, ""), "", CONCATENATE($C$3, " - ", $D12)) -> #N/A | F12: FALSE | G12: =IF(EXACT($B12, ""), "", CONCATENATE($B12, ".", TEXT(IF(ROW($B$7)=ROW($B12), IF(EXACT($F12, "FALSE"), 1, 0), (RIGHT($G11, 6)*1)+1), "000000"))) -> 1-1700.01.000005
B13: =$B$3 -> 1-1700.01 | C13: 32000000000092 | D13: =IF(EXACT($C13, ""), "", CONCATENATE(VLOOKUP($C13, [3]DataLookUp!$B$4:$E$4000, 3, FALSE), IF(EXACT(VLOOKUP($C13, [3]DataLookUp!$B$4:$E$4000, 4, FALSE), ""), "", CONCATENATE(" (NIK : ", VLOOKUP($C13, [3]DataLookUp!$B$4:$E$4000, 4, FALSE),")")))) -> Darsito (NIK : 031212631) | E13: =IF(EXACT($D13, ""), "", CONCATENATE($C$3, " - ", $D13)) -> #N/A | F13: FALSE | G13: =IF(EXACT($B13, ""), "", CONCATENATE($B13, ".", TEXT(IF(ROW($B$7)=ROW($B13), IF(EXACT($F13, "FALSE"), 1, 0), (RIGHT($G12, 6)*1)+1), "000000"))) -> 1-1700.01.000006
B14: =$B$3 -> 1-1700.01 | C14: 32000000000100 | D14: =IF(EXACT($C14, ""), "", CONCATENATE(VLOOKUP($C14, [3]DataLookUp!$B$4:$E$4000, 3, FALSE), IF(EXACT(VLOOKUP($C14, [3]DataLookUp!$B$4:$E$4000, 4, FALSE), ""), "", CONCATENATE(" (NIK : ", VLOOKUP($C14, [3]DataLookUp!$B$4:$E$4000, 4, FALSE),")")))) -> Deny Adi Purnama (NIK : 050123975) | E14: =IF(EXACT($D14, ""), "", CONCATENATE($C$3, " - ", $D14)) -> #N/A | F14: FALSE | G14: =IF(EXACT($B14, ""), "", CONCATENATE($B14, ".", TEXT(IF(ROW($B$7)=ROW($B14), IF(EXACT($F14, "FALSE"), 1, 0), (RIGHT($G13, 6)*1)+1), "000000"))) -> 1-1700.01.000007
B15: =$B$3 -> 1-1700.01 | C15: 32000000000106 | D15: =IF(EXACT($C15, ""), "", CONCATENATE(VLOOKUP($C15, [3]DataLookUp!$B$4:$E$4000, 3, FALSE), IF(EXACT(VLOOKUP($C15, [3]DataLookUp!$B$4:$E$4000, 4, FALSE), ""), "", CONCATENATE(" (NIK : ", VLOOKUP($C15, [3]DataLookUp!$B$4:$E$4000, 4, FALSE),")")))) -> Dionesius Sostenist Duka (NIK : 010605133) | E15: =IF(EXACT($D15, ""), "", CONCATENATE($C$3, " - ", $D15)) -> #N/A | F15: FALSE | G15: =IF(EXACT($B15, ""), "", CONCATENATE($B15, ".", TEXT(IF(ROW($B$7)=ROW($B15), IF(EXACT($F15, "FALSE"), 1, 0), (RIGHT($G14, 6)*1)+1), "000000"))) -> 1-1700.01.000008
B16: =$B$3 -> 1-1700.01 | C16: 32000000000116 | D16: =IF(EXACT($C16, ""), "", CONCATENATE(VLOOKUP($C16, [3]DataLookUp!$B$4:$E$4000, 3, FALSE), IF(EXACT(VLOOKUP($C16, [3]DataLookUp!$B$4:$E$4000, 4, FALSE), ""), "", CONCATENATE(" (NIK : ", VLOOKUP($C16, [3]DataLookUp!$B$4:$E$4000, 4, FALSE),")")))) -> Edi Waluyo (NIK : 040803040) | E16: =IF(EXACT($D16, ""), "", CONCATENATE($C$3, " - ", $D16)) -> #N/A | F16: FALSE | G16: =IF(EXACT($B16, ""), "", CONCATENATE($B16, ".", TEXT(IF(ROW($B$7)=ROW($B16), IF(EXACT($F16, "FALSE"), 1, 0), (RIGHT($G15, 6)*1)+1), "000000"))) -> 1-1700.01.000009
B17: =$B$3 -> 1-1700.01 | C17: 32000000000123 | D17: =IF(EXACT($C17, ""), "", CONCATENATE(VLOOKUP($C17, [3]DataLookUp!$B$4:$E$4000, 3, FALSE), IF(EXACT(VLOOKUP($C17, [3]DataLookUp!$B$4:$E$4000, 4, FALSE), ""), "", CONCATENATE(" (NIK : ", VLOOKUP($C17, [3]DataLookUp!$B$4:$E$4000, 4, FALSE),")")))) -> Eka Bagus Dwi Putra (NIK : 200420932) | E17: =IF(EXACT($D17, ""), "", CONCATENATE($C$3, " - ", $D17)) -> #N/A | F17: FALSE | G17: =IF(EXACT($B17, ""), "", CONCATENATE($B17, ".", TEXT(IF(ROW($B$7)=ROW($B17), IF(EXACT($F17, "FALSE"), 1, 0), (RIGHT($G16, 6)*1)+1), "000000"))) -> 1-1700.01.000010
B18: =$B$3 -> 1-1700.01 | C18: 32000000000125 | D18: =IF(EXACT($C18, ""), "", CONCATENATE(VLOOKUP($C18, [3]DataLookUp!$B$4:$E$4000, 3, FALSE), IF(EXACT(VLOOKUP($C18, [3]DataLookUp!$B$4:$E$4000, 4, FALSE), ""), "", CONCATENATE(" (NIK : ", VLOOKUP($C18, [3]DataLookUp!$B$4:$E$4000, 4, FALSE),")")))) -> Eka Purwanti (NIK : 060121944) | E18: =IF(EXACT($D18, ""), "", CONCATENATE($C$3, " - ", $D18)) -> #N/A | F18: FALSE | G18: =IF(EXACT($B18, ""), "", CONCATENATE($B18, ".", TEXT(IF(ROW($B$7)=ROW($B18), IF(EXACT($F18, "FALSE"), 1, 0), (RIGHT($G17, 6)*1)+1), "000000"))) -> 1-1700.01.000011
B19: =$B$3 -> 1-1700.01 | C19: 32000000000126 | D19: =IF(EXACT($C19, ""), "", CONCATENATE(VLOOKUP($C19, [3]DataLookUp!$B$4:$E$4000, 3, FALSE), IF(EXACT(VLOOKUP($C19, [3]DataLookUp!$B$4:$E$4000, 4, FALSE), ""), "", CONCATENATE(" (NIK : ", VLOOKUP($C19, [3]DataLookUp!$B$4:$E$4000, 4, FALSE),")")))) -> Eka Kurniawan Hidayatullah (NIK : 120324987) | E19: =IF(EXACT($D19, ""), "", CONCATENATE($C$3, " - ", $D19)) -> #N/A | F19: FALSE | G19: =IF(EXACT($B19, ""), "", CONCATENATE($B19, ".", TEXT(IF(ROW($B$7)=ROW($B19), IF(EXACT($F19, "FALSE"), 1, 0), (RIGHT($G18, 6)*1)+1), "000000"))) -> 1-1700.01.000012
... B65: =$B$3 -> 1-1700.01 | C65: 32000000000609 | D65: =IF(EXACT($C65, ""), "", CONCATENATE(VLOOKUP($C65, [3]DataLookUp!$B$4:$E$4000, 3, FALSE), IF(EXACT(VLOOKUP($C65, [3]DataLookUp!$B$4:$E$4000, 4, FALSE), ""), "", CONCATENATE(" (NIK : ", VLOOKUP($C65, [3]DataLookUp!$B$4:$E$4000, 4, FALSE),")")))) -> Risty Alawiyah (NIK : 2703251004) | E65: =IF(EXACT($D65, ""), "", CONCATENATE($C$3, " - ", $D65)) -> #N/A | F65: FALSE | G65: =IF(EXACT($B65, ""), "", CONCATENATE($B65, ".", TEXT(IF(ROW($B$7)=ROW($B65), IF(EXACT($F65, "FALSE"), 1, 0), (RIGHT($G64, 6)*1)+1), "000000"))) -> 1-1700.01.000058

Sheet SEED 1-1901.01
B2: PARENT COA
B3: =SUBSTITUTE(RIGHT(CELL("filename", $A$1), LEN(CELL("filename", $A$1))-FIND("]", CELL("filename", $A$1), 1)), "SEED ", "") -> 1-1901.01 | C3: =IF(EXACT(B3, ""), "", VLOOKUP(B3, SEED!C4:D258, 2, FALSE)) -> Paid in Advance (IDR)
B5: Ref_ID COA | C5: Linkage_RefID | D5: Name | E5: Full Name | F5: Sign Other Things | G5: COA Suffix
B7: =$B$3 -> 1-1901.01 | D7: Lainnya | E7: =IF(EXACT($D7, ""), "", CONCATENATE($C$3, " - ", $D7)) -> Paid in Advance (IDR) - Lainnya | F7: TRUE | G7: =IF(EXACT($B7, ""), "", CONCATENATE($B7, ".", TEXT(IF(ROW($B$7)=ROW($B7), IF(EXACT($F7, "FALSE"), 1, 0), (RIGHT($G6, 6)*1)+1), "000000"))) -> 1-1901.01.000000
B8: =$B$3 -> 1-1901.01 | C8: 32000000000012 | D8: =IF(EXACT($C8, ""), "", CONCATENATE(VLOOKUP($C8, [3]DataLookUp!$B$4:$E$4000, 3, FALSE), IF(EXACT(VLOOKUP($C8, [3]DataLookUp!$B$4:$E$4000, 4, FALSE), ""), "", CONCATENATE(" (NIK : ", VLOOKUP($C8, [3]DataLookUp!$B$4:$E$4000, 4, FALSE),")")))) -> Agnes Sutedja (NIK : 010703020) | E8: =IF(EXACT($D8, ""), "", CONCATENATE($C$3, " - ", $D8)) -> Paid in Advance (IDR) - Agnes Sutedja (NIK : 010703020) | F8: FALSE | G8: =IF(EXACT($B8, ""), "", CONCATENATE($B8, ".", TEXT(IF(ROW($B$7)=ROW($B8), IF(EXACT($F8, "FALSE"), 1, 0), (RIGHT($G7, 6)*1)+1), "000000"))) -> 1-1901.01.000001
B9: =$B$3 -> 1-1901.01 | C9: 32000000000017 | D9: =IF(EXACT($C9, ""), "", CONCATENATE(VLOOKUP($C9, [3]DataLookUp!$B$4:$E$4000, 3, FALSE), IF(EXACT(VLOOKUP($C9, [3]DataLookUp!$B$4:$E$4000, 4, FALSE), ""), "", CONCATENATE(" (NIK : ", VLOOKUP($C9, [3]DataLookUp!$B$4:$E$4000, 4, FALSE),")")))) -> Ahmad Faiz Haems Muda (NIK : 280314716) | E9: =IF(EXACT($D9, ""), "", CONCATENATE($C$3, " - ", $D9)) -> Paid in Advance (IDR) - Ahmad Faiz Haems Muda (NIK : 280314716) | F9: FALSE | G9: =IF(EXACT($B9, ""), "", CONCATENATE($B9, ".", TEXT(IF(ROW($B$7)=ROW($B9), IF(EXACT($F9, "FALSE"), 1, 0), (RIGHT($G8, 6)*1)+1), "000000"))) -> 1-1901.01.000002
B10: =$B$3 -> 1-1901.01 | C10: 32000000000023 | D10: =IF(EXACT($C10, ""), "", CONCATENATE(VLOOKUP($C10, [3]DataLookUp!$B$4:$E$4000, 3, FALSE), IF(EXACT(VLOOKUP($C10, [3]DataLookUp!$B$4:$E$4000, 4, FALSE), ""), "", CONCATENATE(" (NIK : ", VLOOKUP($C10, [3]DataLookUp!$B$4:$E$4000, 4, FALSE),")")))) -> Aldi Mulyadi (NIK : 141020935) | E10: =IF(EXACT($D10, ""), "", CONCATENATE($C$3, " - ", $D10)) -> Paid in Advance (IDR) - Aldi Mulyadi (NIK : 141020935) | F10: FALSE | G10: =IF(EXACT($B10, ""), "", CONCATENATE($B10, ".", TEXT(IF(ROW($B$7)=ROW($B10), IF(EXACT($F10, "FALSE"), 1, 0), (RIGHT($G9, 6)*1)+1), "000000"))) -> 1-1901.01.000003
B11: =$B$3 -> 1-1901.01 | C11: 32000000000075 | D11: =IF(EXACT($C11, ""), "", CONCATENATE(VLOOKUP($C11, [3]DataLookUp!$B$4:$E$4000, 3, FALSE), IF(EXACT(VLOOKUP($C11, [3]DataLookUp!$B$4:$E$4000, 4, FALSE), ""), "", CONCATENATE(" (NIK : ", VLOOKUP($C11, [3]DataLookUp!$B$4:$E$4000, 4, FALSE),")")))) -> Belina Lindarwani (NIK : 100920934) | E11: =IF(EXACT($D11, ""), "", CONCATENATE($C$3, " - ", $D11)) -> Paid in Advance (IDR) - Belina Lindarwani (NIK : 100920934) | F11: FALSE | G11: =IF(EXACT($B11, ""), "", CONCATENATE($B11, ".", TEXT(IF(ROW($B$7)=ROW($B11), IF(EXACT($F11, "FALSE"), 1, 0), (RIGHT($G10, 6)*1)+1), "000000"))) -> 1-1901.01.000004
B12: =$B$3 -> 1-1901.01 | C12: 32000000000082 | D12: =IF(EXACT($C12, ""), "", CONCATENATE(VLOOKUP($C12, [3]DataLookUp!$B$4:$E$4000, 3, FALSE), IF(EXACT(VLOOKUP($C12, [3]DataLookUp!$B$4:$E$4000, 4, FALSE), ""), "", CONCATENATE(" (NIK : ", VLOOKUP($C12, [3]DataLookUp!$B$4:$E$4000, 4, FALSE),")")))) -> Budianto (NIK : 060515769) | E12: =IF(EXACT($D12, ""), "", CONCATENATE($C$3, " - ", $D12)) -> Paid in Advance (IDR) - Budianto (NIK : 060515769) | F12: FALSE | G12: =IF(EXACT($B12, ""), "", CONCATENATE($B12, ".", TEXT(IF(ROW($B$7)=ROW($B12), IF(EXACT($F12, "FALSE"), 1, 0), (RIGHT($G11, 6)*1)+1), "000000"))) -> 1-1901.01.000005
B13: =$B$3 -> 1-1901.01 | C13: 32000000000092 | D13: =IF(EXACT($C13, ""), "", CONCATENATE(VLOOKUP($C13, [3]DataLookUp!$B$4:$E$4000, 3, FALSE), IF(EXACT(VLOOKUP($C13, [3]DataLookUp!$B$4:$E$4000, 4, FALSE), ""), "", CONCATENATE(" (NIK : ", VLOOKUP($C13, [3]DataLookUp!$B$4:$E$4000, 4, FALSE),")")))) -> Darsito (NIK : 031212631) | E13: =IF(EXACT($D13, ""), "", CONCATENATE($C$3, " - ", $D13)) -> Paid in Advance (IDR) - Darsito (NIK : 031212631) | F13: FALSE | G13: =IF(EXACT($B13, ""), "", CONCATENATE($B13, ".", TEXT(IF(ROW($B$7)=ROW($B13), IF(EXACT($F13, "FALSE"), 1, 0), (RIGHT($G12, 6)*1)+1), "000000"))) -> 1-1901.01.000006
B14: =$B$3 -> 1-1901.01 | C14: 32000000000100 | D14: =IF(EXACT($C14, ""), "", CONCATENATE(VLOOKUP($C14, [3]DataLookUp!$B$4:$E$4000, 3, FALSE), IF(EXACT(VLOOKUP($C14, [3]DataLookUp!$B$4:$E$4000, 4, FALSE), ""), "", CONCATENATE(" (NIK : ", VLOOKUP($C14, [3]DataLookUp!$B$4:$E$4000, 4, FALSE),")")))) -> Deny Adi Purnama (NIK : 050123975) | E14: =IF(EXACT($D14, ""), "", CONCATENATE($C$3, " - ", $D14)) -> Paid in Advance (IDR) - Deny Adi Purnama (NIK : 050123975) | F14: FALSE | G14: =IF(EXACT($B14, ""), "", CONCATENATE($B14, ".", TEXT(IF(ROW($B$7)=ROW($B14), IF(EXACT($F14, "FALSE"), 1, 0), (RIGHT($G13, 6)*1)+1), "000000"))) -> 1-1901.01.000007
B15: =$B$3 -> 1-1901.01 | C15: 32000000000106 | D15: =IF(EXACT($C15, ""), "", CONCATENATE(VLOOKUP($C15, [3]DataLookUp!$B$4:$E$4000, 3, FALSE), IF(EXACT(VLOOKUP($C15, [3]DataLookUp!$B$4:$E$4000, 4, FALSE), ""), "", CONCATENATE(" (NIK : ", VLOOKUP($C15, [3]DataLookUp!$B$4:$E$4000, 4, FALSE),")")))) -> Dionesius Sostenist Duka (NIK : 010605133) | E15: =IF(EXACT($D15, ""), "", CONCATENATE($C$3, " - ", $D15)) -> Paid in Advance (IDR) - Dionesius Sostenist Duka (NIK : 010605133) | F15: FALSE | G15: =IF(EXACT($B15, ""), "", CONCATENATE($B15, ".", TEXT(IF(ROW($B$7)=ROW($B15), IF(EXACT($F15, "FALSE"), 1, 0), (RIGHT($G14, 6)*1)+1), "000000"))) -> 1-1901.01.000008
B16: =$B$3 -> 1-1901.01 | C16: 32000000000116 | D16: =IF(EXACT($C16, ""), "", CONCATENATE(VLOOKUP($C16, [3]DataLookUp!$B$4:$E$4000, 3, FALSE), IF(EXACT(VLOOKUP($C16, [3]DataLookUp!$B$4:$E$4000, 4, FALSE), ""), "", CONCATENATE(" (NIK : ", VLOOKUP($C16, [3]DataLookUp!$B$4:$E$4000, 4, FALSE),")")))) -> Edi Waluyo (NIK : 040803040) | E16: =IF(EXACT($D16, ""), "", CONCATENATE($C$3, " - ", $D16)) -> Paid in Advance (IDR) - Edi Waluyo (NIK : 040803040) | F16: FALSE | G16: =IF(EXACT($B16, ""), "", CONCATENATE($B16, ".", TEXT(IF(ROW($B$7)=ROW($B16), IF(EXACT($F16, "FALSE"), 1, 0), (RIGHT($G15, 6)*1)+1), "000000"))) -> 1-1901.01.000009
B17: =$B$3 -> 1-1901.01 | C17: 32000000000123 | D17: =IF(EXACT($C17, ""), "", CONCATENATE(VLOOKUP($C17, [3]DataLookUp!$B$4:$E$4000, 3, FALSE), IF(EXACT(VLOOKUP($C17, [3]DataLookUp!$B$4:$E$4000, 4, FALSE), ""), "", CONCATENATE(" (NIK : ", VLOOKUP($C17, [3]DataLookUp!$B$4:$E$4000, 4, FALSE),")")))) -> Eka Bagus Dwi Putra (NIK : 200420932) | E17: =IF(EXACT($D17, ""), "", CONCATENATE($C$3, " - ", $D17)) -> Paid in Advance (IDR) - Eka Bagus Dwi Putra (NIK : 200420932) | F17: FALSE | G17: =IF(EXACT($B17, ""), "", CONCATENATE($B17, ".", TEXT(IF(ROW($B$7)=ROW($B17), IF(EXACT($F17, "FALSE"), 1, 0), (RIGHT($G16, 6)*1)+1), "000000"))) -> 1-1901.01.000010
B18: =$B$3 -> 1-1901.01 | C18: 32000000000125 | D18: =IF(EXACT($C18, ""), "", CONCATENATE(VLOOKUP($C18, [3]DataLookUp!$B$4:$E$4000, 3, FALSE), IF(EXACT(VLOOKUP($C18, [3]DataLookUp!$B$4:$E$4000, 4, FALSE), ""), "", CONCATENATE(" (NIK : ", VLOOKUP($C18, [3]DataLookUp!$B$4:$E$4000, 4, FALSE),")")))) -> Eka Purwanti (NIK : 060121944) | E18: =IF(EXACT($D18, ""), "", CONCATENATE($C$3, " - ", $D18)) -> Paid in Advance (IDR) - Eka Purwanti (NIK : 060121944) | F18: FALSE | G18: =IF(EXACT($B18, ""), "", CONCATENATE($B18, ".", TEXT(IF(ROW($B$7)=ROW($B18), IF(EXACT($F18, "FALSE"), 1, 0), (RIGHT($G17, 6)*1)+1), "000000"))) -> 1-1901.01.000011
B19: =$B$3 -> 1-1901.01 | C19: 32000000000126 | D19: =IF(EXACT($C19, ""), "", CONCATENATE(VLOOKUP($C19, [3]DataLookUp!$B$4:$E$4000, 3, FALSE), IF(EXACT(VLOOKUP($C19, [3]DataLookUp!$B$4:$E$4000, 4, FALSE), ""), "", CONCATENATE(" (NIK : ", VLOOKUP($C19, [3]DataLookUp!$B$4:$E$4000, 4, FALSE),")")))) -> Eka Kurniawan Hidayatullah (NIK : 120324987) | E19: =IF(EXACT($D19, ""), "", CONCATENATE($C$3, " - ", $D19)) -> Paid in Advance (IDR) - Eka Kurniawan Hidayatullah (NIK : 120324987) | F19: FALSE | G19: =IF(EXACT($B19, ""), "", CONCATENATE($B19, ".", TEXT(IF(ROW($B$7)=ROW($B19), IF(EXACT($F19, "FALSE"), 1, 0), (RIGHT($G18, 6)*1)+1), "000000"))) -> 1-1901.01.000012
... B65: =$B$3 -> 1-1901.01 | C65: 32000000000609 | D65: =IF(EXACT($C65, ""), "", CONCATENATE(VLOOKUP($C65, [3]DataLookUp!$B$4:$E$4000, 3, FALSE), IF(EXACT(VLOOKUP($C65, [3]DataLookUp!$B$4:$E$4000, 4, FALSE), ""), "", CONCATENATE(" (NIK : ", VLOOKUP($C65, [3]DataLookUp!$B$4:$E$4000, 4, FALSE),")")))) -> Risty Alawiyah (NIK : 2703251004) | E65: =IF(EXACT($D65, ""), "", CONCATENATE($C$3, " - ", $D65)) -> Paid in Advance (IDR) - Risty Alawiyah (NIK : 2703251004) | F65: FALSE | G65: =IF(EXACT($B65, ""), "", CONCATENATE($B65, ".", TEXT(IF(ROW($B$7)=ROW($B65), IF(EXACT($F65, "FALSE"), 1, 0), (RIGHT($G64, 6)*1)+1), "000000"))) -> 1-1901.01.000058
