Workbook

Sheet SEED
AD1: SEQUENCE | AM1: PARENT
B2: LEVEL 1 | D2: LEVEL 2 | F2: LEVEL 3 | H2: LEVEL 4 | J2: LEVEL 5 (Currency) | L2: LEVEL 6 (Data Linkage) | V2: ALL LEVEL | W2: L1 | X2: L2 | Y2: L3 | Z2: L4 | AA2: L5 | AB2: L6 | AD2: L1 | AE2: L2 | AF2: L3 | AG2: L4 | AH2: L5 | AI2: L6 | AK2: PERUBAHAN | AM2: L1 | AN2: L2 | AO2: L3 | AP2: L4 | AQ2: L5 | AS2: Conclution
B3: a-bcdd.ee.ff | D3: a-bcdd.ee.ff | F3: a-bcdd.ee.ff | H3: a-bcdd.ee.ff | J3: a-bcdd.ee.ff | L3: a-bcdd.ee.ff | O3: L1 | P3: L2 | Q3: L3 | R3: L4 | S3: L5 | T3: L6 | BA3: SYS_PID Prediction | BB3: SQL Syntax | BC3: =IF(EXACT(LEFT($B5, 1), "1"), "TRUE", "FALSE") -> TRUE
B4: COA | C4: Name | D4: COA | E4: Name | F4: COA | G4: Name | H4: COA | I4: Name | J4: COA | K4: Name | L4: COA | M4: Name | V4: 65000000000000 | W4: =$V4 -> 65000000000000 | X4: =$V4 -> 65000000000000 | Y4: =$V4 -> 65000000000000 | Z4: =$V4 -> 65000000000000 | AA4: =$V4 -> 65000000000000 | AB4: =$V4 -> 65000000000000 | AM4: null | AV4: SYS_PID | AW4: PARENT ID | BA4: 65000000000000
B5: 1-0000 | C5: Aset | O5: =IF(EXACT($B5, ""), $O4, $B5) -> 1-0000 | P5: =IF(EXACT($D5, ""), $P4, $D5) | Q5: =IF(EXACT($F5, ""), $Q4, $F5) | R5: =IF(EXACT($H5, ""), $R4, $H5) | S5: =IF(EXACT($J5, ""), $S4, $J5) | T5: =IF(EXACT($L5, ""), $T4, $L5) | V5: =V4+IF(AND(EXACT(B5, ""), EXACT(D5, ""), EXACT(F5, ""), EXACT(H5, ""), EXACT(J5, ""), EXACT(L5, "")), 0, 1) -> 65000000000001 | W5: =IF(EXACT($B5, ""), $W4, $V5) -> 65000000000001 | X5: =IF(EXACT($D5, ""), $X4, $V5) -> 65000000000000 | Y5: =IF(EXACT($F5, ""), $Y4, $V5) -> 65000000000000 | Z5: =IF(EXACT($H5, ""), $Z4, $V5) -> 65000000000000 | AA5: =IF(EXACT($J5, ""), $AA4, $V5) -> 65000000000000 | AB5: =IF(EXACT($L5, ""), $AB4, $V5) -> 65000000000000 | AD5: =AD4 + IF(W5<>W4, 1, 0) -> 1 | AE5: =IF(AD4<>AD5, 1, AE4) + IF(X5<>X4, 1, 0) -> 1 | AF5: =IF(AE4<>AE5, 1, AF4) + IF(Y5<>Y4, 1, 0) -> 1 | AG5: =IF(AF4<>AF5, 1, AG4) + IF(Z5<>Z4, 1, 0) -> 1 | AH5: =IF(AG4<>AG5, 1, AH4) + IF(AA5<>AA4, 1, 0) -> 1 | AI5: =IF(AH4<>AH5, 1, AI4) + IF(AB5<>AB4, 1, 0) -> 1 | AK5: =IF(AA5<>AA4, "L5", IF(Z5<>Z4, "L4", IF(Y5<>Y4, "L3", IF(X5<>X4, "L2", IF(W5<>W4, "L1", "L1" ) ) ) ) ) -> L1 | AM5: null | AN5: =IF(EXACT($AK4, "L1"), $W4, AN4) -> 0 | AO5: =IF(EXACT($AK4, "L1"), $W4, IF(EXACT($AK4, "L2"), $X4, AO4)) -> 0 | AP5: =IF(EXACT($AK4, "L1"), $W4, IF(EXACT($AK4, "L2"), $X4, IF(EXACT($AK4, "L3"), $Y4, AP4))) -> 0 | AQ5: =IF(EXACT($AK4, "L1"), $W4, IF(EXACT($AK4, "L2"), $X4, IF(EXACT($AK4, "L3"), $Y4, IF(EXACT($AK4, "L4"), $Z4, AQ4)))) -> 0 | AS5: =IF(EXACT($AK5, "L1"), AM5, IF(EXACT($AK5, "L2"), AN5, IF(EXACT($AK5, "L3"), AO5, IF(EXACT($AK5, "L4"), AP5, IF(EXACT($AK5, "L5"), AQ5, ""))))) -> null | AU5: =IF(AND(EXACT(B5, ""), EXACT(D5, ""), EXACT(F5, ""), EXACT(H5, ""), EXACT(J5, ""), EXACT(L5, "")), "", CONCATENATE( "PERFORM * FROM ""SchData-OLTP-Accounting"".""Func_TblChartOfAccount_SET""(varSystemLoginSession, null, null, null, varInstitutionBranchID, 62000000000001::bigint,'", IF(EXACT(B5, ""), IF(EXACT(D5, ""), IF(EXACT(F5, ""), IF(EXACT(H5, ""), IF(EXACT(J5, ""), IF(EXACT(L5, ""), "", L5), J5), H5), F5), D5), B5), "', '", IF(EXACT(B5, ""), IF(EXACT(D5, ""), IF(EXACT(F5, ""), IF(EXACT(H5, ""), IF(EXACT(J5, ""), IF(EXACT(L5, ""), "", M5), K5), I5), G5), E5), C5), "', ", IF(EXACT(J5, ""), "62000000000001::bigint", IF((RIGHT(J5, 2)*1 = 1), "62000000000001::bigint", IF((RIGHT(J5, 2)*1 = 2), "62000000000002::bigint", "null"))), ", '2016-01-01 00:00:00'::timestamp, null::timestamp, ", AW5, "::bigint, 66000000000001::bigint);")) -> PERFORM * FROM "SchData-OLTP-Accounting"."Func_TblChartOfAccount_SET"(varSystemLoginSession, null, null, null, varInstitutionBranchID, 62000000000001::bigint,'1-0000', 'Aset', 62000000000001::bigint, '2016-01-01 00:00:00'::timestamp, null::timestamp, null::bigint, 66000000000001::bigint); | AV5: =IF(AND(EXACT($B5, ""), EXACT($D5, ""), EXACT($F5, ""), EXACT($H5, ""), EXACT($J5, ""), EXACT($L5, "")), "", V5) -> 65000000000001 | AW5: =AS5 -> null | AY5: =IF(AND(EXACT($B5, ""), EXACT($D5, ""), EXACT($F5, ""), EXACT($H5, ""), EXACT($J5, ""), EXACT($L5, "")), "", IF(NOT(EXACT($B5, "")), "null", IF(NOT(EXACT($D5, "")), IF($W4<>$W3, $W4, $W5), IF(NOT(EXACT($F5, "")), IF($X4<>$X3, $X4, IF($W4<>$W3, $W4, $X5)), IF(NOT(EXACT($H5, "")), IF($Y4<>$Y3, $Y4, IF($X4<>$X3, $X4, IF($W4<>$W3, $W4, $Y5))), IF(NOT(EXACT($J5, "")), IF($Z4<>$Z3, $Z4, IF($Y4<>$Y3, $Y4, IF($X4<>$X3, $X4, IF($W4<>$W3, $W4, $Z5)))), IF(NOT(EXACT($L5, "")), IF($AA4<>$AA3, $AA4, IF($Z4<>$Z3, $Z4, IF($Y4<>$Y3, $Y4, IF($X4<>$X3, $X4, IF($W4<>$W3, $W4, $AA5))))), "others"))))))) -> null | BA5: =BA4 + IF(EXACT(BB5, ""), 0, 1) -> 65000000000001 | BB5: =IF(AND(EXACT($B5, ""), EXACT($D5, ""), EXACT($F5, ""), EXACT($H5, ""), EXACT($J5, ""), EXACT($L5, "")), "", CONCATENATE( "PERFORM * FROM ""SchData-OLTP-Accounting"".""Func_TblChartOfAccount_SET""(varSystemLoginSession, null, null, null, null, null, varInstitutionBranchID, 62000000000001::bigint,'", IF(EXACT($B5, ""), IF(EXACT($D5, ""), IF(EXACT($F5, ""), IF(EXACT($H5, ""), IF(EXACT($J5, ""), IF(EXACT($L5, ""), "", $L5), $J5), $H5), $F5), $D5), $B5), "', '", IF(EXACT($B5, ""), IF(EXACT($D5, ""), IF(EXACT($F5, ""), IF(EXACT($H5, ""), IF(EXACT($J5, ""), IF(EXACT($L5, ""), "", $M5), $K5), $I5), $G5), $E5), $C5), "', ", IF(EXACT($J5, ""), "62000000000001::bigint", IF((RIGHT($J5, 2)*1 = 1), "62000000000001::bigint", IF((RIGHT($J5, 2)*1 = 2), "62000000000002::bigint", "null"))), ", '2016-01-01 00:00:00'::timestamp, null::timestamp, ", $AW5, "::bigint, 66000000000001::bigint, ", IF(EXACT(LEFT(IF(EXACT($B5, ""), IF(EXACT($D5, ""), IF(EXACT($F5, ""), IF(EXACT($H5, ""), IF(EXACT($J5, ""), IF(EXACT($L5, ""), "", $L5), $J5), $H5), $F5), $D5), $B5), 1), "1"), "TRUE", "FALSE"), "::boolean);")) -> PERFORM * FROM "SchData-OLTP-Accounting"."Func_TblChartOfAccount_SET"(varSystemLoginSession, null, null, null, null, null, varInstitutionBranchID, 62000000000001::bigint,'1-0000', 'Aset', 62000000000001::bigint, '2016-01-01 00:00:00'::timestamp, null::timestamp, null::bigint, 66000000000001::bigint, TRUE::boolean);
D6: 1-1000 | E6: Aset Lancar | O6: =IF(EXACT($B6, ""), $O5, $B6) -> 1-0000 | P6: =IF(EXACT($D6, ""), $P5, $D6) -> 1-1000 | Q6: =IF(EXACT($F6, ""), $Q5, $F6) | R6: =IF(EXACT($H6, ""), $R5, $H6) | S6: =IF(EXACT($J6, ""), $S5, $J6) | T6: =IF(EXACT($L6, ""), $T5, $L6) | V6: =V5+IF(AND(EXACT(B6, ""), EXACT(D6, ""), EXACT(F6, ""), EXACT(H6, ""), EXACT(J6, ""), EXACT(L6, "")), 0, 1) -> 65000000000002 | W6: =IF(EXACT($B6, ""), $W5, $V6) -> 65000000000001 | X6: =IF(EXACT($D6, ""), $X5, $V6) -> 65000000000002 | Y6: =IF(EXACT($F6, ""), $Y5, $V6) -> 65000000000000 | Z6: =IF(EXACT($H6, ""), $Z5, $V6) -> 65000000000000 | AA6: =IF(EXACT($J6, ""), $AA5, $V6) -> 65000000000000 | AB6: =IF(EXACT($L6, ""), $AB5, $V6) -> 65000000000000 | AD6: =AD5 + IF(W6<>W5, 1, 0) -> 1 | AE6: =IF(AD5<>AD6, 1, AE5) + IF(X6<>X5, 1, 0) -> 2 | AF6: =IF(AE5<>AE6, 1, AF5) + IF(Y6<>Y5, 1, 0) -> 1 | AG6: =IF(AF5<>AF6, 1, AG5) + IF(Z6<>Z5, 1, 0) -> 1 | AH6: =IF(AG5<>AG6, 1, AH5) + IF(AA6<>AA5, 1, 0) -> 1 | AI6: =IF(AH5<>AH6, 1, AI5) + IF(AB6<>AB5, 1, 0) -> 1 | AK6: =IF(AA6<>AA5, "L5", IF(Z6<>Z5, "L4", IF(Y6<>Y5, "L3", IF(X6<>X5, "L2", IF(W6<>W5, "L1", "L1" ) ) ) ) ) -> L2 | AM6: null | AN6: =IF(EXACT($AK5, "L1"), $W5, AN5) -> 65000000000001 | AO6: =IF(EXACT($AK5, "L1"), $W5, IF(EXACT($AK5, "L2"), $X5, AO5)) -> 65000000000001 | AP6: =IF(EXACT($AK5, "L1"), $W5, IF(EXACT($AK5, "L2"), $X5, IF(EXACT($AK5, "L3"), $Y5, AP5))) -> 65000000000001 | AQ6: =IF(EXACT($AK5, "L1"), $W5, IF(EXACT($AK5, "L2"), $X5, IF(EXACT($AK5, "L3"), $Y5, IF(EXACT($AK5, "L4"), $Z5, AQ5)))) -> 65000000000001 | AS6: =IF(EXACT($AK6, "L1"), AM6, IF(EXACT($AK6, "L2"), AN6, IF(EXACT($AK6, "L3"), AO6, IF(EXACT($AK6, "L4"), AP6, IF(EXACT($AK6, "L5"), AQ6, ""))))) -> 65000000000001 | AU6: =IF(AND(EXACT(B6, ""), EXACT(D6, ""), EXACT(F6, ""), EXACT(H6, ""), EXACT(J6, ""), EXACT(L6, "")), "", CONCATENATE( "PERFORM * FROM ""SchData-OLTP-Accounting"".""Func_TblChartOfAccount_SET""(varSystemLoginSession, null, null, null, varInstitutionBranchID, 62000000000001::bigint,'", IF(EXACT(B6, ""), IF(EXACT(D6, ""), IF(EXACT(F6, ""), IF(EXACT(H6, ""), IF(EXACT(J6, ""), IF(EXACT(L6, ""), "", L6), J6), H6), F6), D6), B6), "', '", IF(EXACT(B6, ""), IF(EXACT(D6, ""), IF(EXACT(F6, ""), IF(EXACT(H6, ""), IF(EXACT(J6, ""), IF(EXACT(L6, ""), "", M6), K6), I6), G6), E6), C6), "', ", IF(EXACT(J6, ""), "62000000000001::bigint", IF((RIGHT(J6, 2)*1 = 1), "62000000000001::bigint", IF((RIGHT(J6, 2)*1 = 2), "62000000000002::bigint", "null"))), ", '2016-01-01 00:00:00'::timestamp, null::timestamp, ", AW6, "::bigint, 66000000000001::bigint);")) -> PERFORM * FROM "SchData-OLTP-Accounting"."Func_TblChartOfAccount_SET"(varSystemLoginSession, null, null, null, varInstitutionBranchID, 62000000000001::bigint,'1-1000', 'Aset Lancar', 62000000000001::bigint, '2016-01-01 00:00:00'::timestamp, null::timestamp, 65000000000001::bigint, 66000000000001::bigint); | AV6: =IF(AND(EXACT($B6, ""), EXACT($D6, ""), EXACT($F6, ""), EXACT($H6, ""), EXACT($J6, ""), EXACT($L6, "")), "", V6) -> 65000000000002 | AW6: =AS6 -> 65000000000001 | AY6: =IF(AND(EXACT($B6, ""), EXACT($D6, ""), EXACT($F6, ""), EXACT($H6, ""), EXACT($J6, ""), EXACT($L6, "")), "", IF(NOT(EXACT($B6, "")), "null", IF(NOT(EXACT($D6, "")), IF($W5<>$W4, $W5, $W6), IF(NOT(EXACT($F6, "")), IF($X5<>$X4, $X5, IF($W5<>$W4, $W5, $X6)), IF(NOT(EXACT($H6, "")), IF($Y5<>$Y4, $Y5, IF($X5<>$X4, $X5, IF($W5<>$W4, $W5, $Y6))), IF(NOT(EXACT($J6, "")), IF($Z5<>$Z4, $Z5, IF($Y5<>$Y4, $Y5, IF($X5<>$X4, $X5, IF($W5<>$W4, $W5, $Z6)))), IF(NOT(EXACT($L6, "")), IF($AA5<>$AA4, $AA5, IF($Z5<>$Z4, $Z5, IF($Y5<>$Y4, $Y5, IF($X5<>$X4, $X5, IF($W5<>$W4, $W5, $AA6))))), "others"))))))) -> 65000000000001 | BA6: =BA5 + IF(EXACT(BB6, ""), 0, 1) -> 65000000000002 | BB6: =IF(AND(EXACT($B6, ""), EXACT($D6, ""), EXACT($F6, ""), EXACT($H6, ""), EXACT($J6, ""), EXACT($L6, "")), "", CONCATENATE( "PERFORM * FROM ""SchData-OLTP-Accounting"".""Func_TblChartOfAccount_SET""(varSystemLoginSession, null, null, null, null, null, varInstitutionBranchID, 62000000000001::bigint,'", IF(EXACT($B6, ""), IF(EXACT($D6, ""), IF(EXACT($F6, ""), IF(EXACT($H6, ""), IF(EXACT($J6, ""), IF(EXACT($L6, ""), "", $L6), $J6), $H6), $F6), $D6), $B6), "', '", IF(EXACT($B6, ""), IF(EXACT($D6, ""), IF(EXACT($F6, ""), IF(EXACT($H6, ""), IF(EXACT($J6, ""), IF(EXACT($L6, ""), "", $M6), $K6), $I6), $G6), $E6), $C6), "', ", IF(EXACT($J6, ""), "62000000000001::bigint", IF((RIGHT($J6, 2)*1 = 1), "62000000000001::bigint", IF((RIGHT($J6, 2)*1 = 2), "62000000000002::bigint", "null"))), ", '2016-01-01 00:00:00'::timestamp, null::timestamp, ", $AW6, "::bigint, 66000000000001::bigint, ", IF(EXACT(LEFT(IF(EXACT($B6, ""), IF(EXACT($D6, ""), IF(EXACT($F6, ""), IF(EXACT($H6, ""), IF(EXACT($J6, ""), IF(EXACT($L6, ""), "", $L6), $J6), $H6), $F6), $D6), $B6), 1), "1"), "TRUE", "FALSE"), "::boolean);")) -> PERFORM * FROM "SchData-OLTP-Accounting"."Func_TblChartOfAccount_SET"(varSystemLoginSession, null, null, null, null, null, varInstitutionBranchID, 62000000000001::bigint,'1-1000', 'Aset Lancar', 62000000000001::bigint, '2016-01-01 00:00:00'::timestamp, null::timestamp, 65000000000001::bigint, 66000000000001::bigint, TRUE::boolean);
F7: 1-1100 | G7: Cash & Bank | O7: =IF(EXACT($B7, ""), $O6, $B7) -> 1-0000 | P7: =IF(EXACT($D7, ""), $P6, $D7) -> 1-1000 | Q7: =IF(EXACT($F7, ""), $Q6, $F7) -> 1-1100 | R7: =IF(EXACT($H7, ""), $R6, $H7) | S7: =IF(EXACT($J7, ""), $S6, $J7) | T7: =IF(EXACT($L7, ""), $T6, $L7) | V7: =V6+IF(AND(EXACT(B7, ""), EXACT(D7, ""), EXACT(F7, ""), EXACT(H7, ""), EXACT(J7, ""), EXACT(L7, "")), 0, 1) -> 65000000000003 | W7: =IF(EXACT($B7, ""), $W6, $V7) -> 65000000000001 | X7: =IF(EXACT($D7, ""), $X6, $V7) -> 65000000000002 | Y7: =IF(EXACT($F7, ""), $Y6, $V7) -> 65000000000003 | Z7: =IF(EXACT($H7, ""), $Z6, $V7) -> 65000000000000 | AA7: =IF(EXACT($J7, ""), $AA6, $V7) -> 65000000000000 | AB7: =IF(EXACT($L7, ""), $AB6, $V7) -> 65000000000000 | AD7: =AD6 + IF(W7<>W6, 1, 0) -> 1 | AE7: =IF(AD6<>AD7, 1, AE6) + IF(X7<>X6, 1, 0) -> 2 | AF7: =IF(AE6<>AE7, 1, AF6) + IF(Y7<>Y6, 1, 0) -> 2 | AG7: =IF(AF6<>AF7, 1, AG6) + IF(Z7<>Z6, 1, 0) -> 1 | AH7: =IF(AG6<>AG7, 1, AH6) + IF(AA7<>AA6, 1, 0) -> 1 | AI7: =IF(AH6<>AH7, 1, AI6) + IF(AB7<>AB6, 1, 0) -> 1 | AK7: =IF(AA7<>AA6, "L5", IF(Z7<>Z6, "L4", IF(Y7<>Y6, "L3", IF(X7<>X6, "L2", IF(W7<>W6, "L1", "L1" ) ) ) ) ) -> L3 | AM7: null | AN7: =IF(EXACT($AK6, "L1"), $W6, AN6) -> 65000000000001 | AO7: =IF(EXACT($AK6, "L1"), $W6, IF(EXACT($AK6, "L2"), $X6, AO6)) -> 65000000000002 | AP7: =IF(EXACT($AK6, "L1"), $W6, IF(EXACT($AK6, "L2"), $X6, IF(EXACT($AK6, "L3"), $Y6, AP6))) -> 65000000000002 | AQ7: =IF(EXACT($AK6, "L1"), $W6, IF(EXACT($AK6, "L2"), $X6, IF(EXACT($AK6, "L3"), $Y6, IF(EXACT($AK6, "L4"), $Z6, AQ6)))) -> 65000000000002 | AS7: =IF(EXACT($AK7, "L1"), AM7, IF(EXACT($AK7, "L2"), AN7, IF(EXACT($AK7, "L3"), AO7, IF(EXACT($AK7, "L4"), AP7, IF(EXACT($AK7, "L5"), AQ7, ""))))) -> 65000000000002 | AU7: =IF(AND(EXACT(B7, ""), EXACT(D7, ""), EXACT(F7, ""), EXACT(H7, ""), EXACT(J7, ""), EXACT(L7, "")), "", CONCATENATE( "PERFORM * FROM ""SchData-OLTP-Accounting"".""Func_TblChartOfAccount_SET""(varSystemLoginSession, null, null, null, varInstitutionBranchID, 62000000000001::bigint,'", IF(EXACT(B7, ""), IF(EXACT(D7, ""), IF(EXACT(F7, ""), IF(EXACT(H7, ""), IF(EXACT(J7, ""), IF(EXACT(L7, ""), "", L7), J7), H7), F7), D7), B7), "', '", IF(EXACT(B7, ""), IF(EXACT(D7, ""), IF(EXACT(F7, ""), IF(EXACT(H7, ""), IF(EXACT(J7, ""), IF(EXACT(L7, ""), "", M7), K7), I7), G7), E7), C7), "', ", IF(EXACT(J7, ""), "62000000000001::bigint", IF((RIGHT(J7, 2)*1 = 1), "62000000000001::bigint", IF((RIGHT(J7, 2)*1 = 2), "62000000000002::bigint", "null"))), ", '2016-01-01 00:00:00'::timestamp, null::timestamp, ", AW7, "::bigint, 66000000000001::bigint);")) -> PERFORM * FROM "SchData-OLTP-Accounting"."Func_TblChartOfAccount_SET"(varSystemLoginSession, null, null, null, varInstitutionBranchID, 62000000000001::bigint,'1-1100', 'Cash & Bank', 62000000000001::bigint, '2016-01-01 00:00:00'::timestamp, null::timestamp, 65000000000002::bigint, 66000000000001::bigint); | AV7: =IF(AND(EXACT($B7, ""), EXACT($D7, ""), EXACT($F7, ""), EXACT($H7, ""), EXACT($J7, ""), EXACT($L7, "")), "", V7) -> 65000000000003 | AW7: =AS7 -> 65000000000002 | AY7: =IF(AND(EXACT($B7, ""), EXACT($D7, ""), EXACT($F7, ""), EXACT($H7, ""), EXACT($J7, ""), EXACT($L7, "")), "", IF(NOT(EXACT($B7, "")), "null", IF(NOT(EXACT($D7, "")), IF($W6<>$W5, $W6, $W7), IF(NOT(EXACT($F7, "")), IF($X6<>$X5, $X6, IF($W6<>$W5, $W6, $X7)), IF(NOT(EXACT($H7, "")), IF($Y6<>$Y5, $Y6, IF($X6<>$X5, $X6, IF($W6<>$W5, $W6, $Y7))), IF(NOT(EXACT($J7, "")), IF($Z6<>$Z5, $Z6, IF($Y6<>$Y5, $Y6, IF($X6<>$X5, $X6, IF($W6<>$W5, $W6, $Z7)))), IF(NOT(EXACT($L7, "")), IF($AA6<>$AA5, $AA6, IF($Z6<>$Z5, $Z6, IF($Y6<>$Y5, $Y6, IF($X6<>$X5, $X6, IF($W6<>$W5, $W6, $AA7))))), "others"))))))) -> 65000000000002 | BA7: =BA6 + IF(EXACT(BB7, ""), 0, 1) -> 65000000000003 | BB7: =IF(AND(EXACT($B7, ""), EXACT($D7, ""), EXACT($F7, ""), EXACT($H7, ""), EXACT($J7, ""), EXACT($L7, "")), "", CONCATENATE( "PERFORM * FROM ""SchData-OLTP-Accounting"".""Func_TblChartOfAccount_SET""(varSystemLoginSession, null, null, null, null, null, varInstitutionBranchID, 62000000000001::bigint,'", IF(EXACT($B7, ""), IF(EXACT($D7, ""), IF(EXACT($F7, ""), IF(EXACT($H7, ""), IF(EXACT($J7, ""), IF(EXACT($L7, ""), "", $L7), $J7), $H7), $F7), $D7), $B7), "', '", IF(EXACT($B7, ""), IF(EXACT($D7, ""), IF(EXACT($F7, ""), IF(EXACT($H7, ""), IF(EXACT($J7, ""), IF(EXACT($L7, ""), "", $M7), $K7), $I7), $G7), $E7), $C7), "', ", IF(EXACT($J7, ""), "62000000000001::bigint", IF((RIGHT($J7, 2)*1 = 1), "62000000000001::bigint", IF((RIGHT($J7, 2)*1 = 2), "62000000000002::bigint", "null"))), ", '2016-01-01 00:00:00'::timestamp, null::timestamp, ", $AW7, "::bigint, 66000000000001::bigint, ", IF(EXACT(LEFT(IF(EXACT($B7, ""), IF(EXACT($D7, ""), IF(EXACT($F7, ""), IF(EXACT($H7, ""), IF(EXACT($J7, ""), IF(EXACT($L7, ""), "", $L7), $J7), $H7), $F7), $D7), $B7), 1), "1"), "TRUE", "FALSE"), "::boolean);")) -> PERFORM * FROM "SchData-OLTP-Accounting"."Func_TblChartOfAccount_SET"(varSystemLoginSession, null, null, null, null, null, varInstitutionBranchID, 62000000000001::bigint,'1-1100', 'Cash & Bank', 62000000000001::bigint, '2016-01-01 00:00:00'::timestamp, null::timestamp, 65000000000002::bigint, 66000000000001::bigint, TRUE::boolean);
H8: 1-1101 | I8: Petty Cash | O8: =IF(EXACT($B8, ""), $O7, $B8) -> 1-0000 | P8: =IF(EXACT($D8, ""), $P7, $D8) -> 1-1000 | Q8: =IF(EXACT($F8, ""), $Q7, $F8) -> 1-1100 | R8: =IF(EXACT($H8, ""), $R7, $H8) -> 1-1101 | S8: =IF(EXACT($J8, ""), $S7, $J8) | T8: =IF(EXACT($L8, ""), $T7, $L8) | V8: =V7+IF(AND(EXACT(B8, ""), EXACT(D8, ""), EXACT(F8, ""), EXACT(H8, ""), EXACT(J8, ""), EXACT(L8, "")), 0, 1) -> 65000000000004 | W8: =IF(EXACT($B8, ""), $W7, $V8) -> 65000000000001 | X8: =IF(EXACT($D8, ""), $X7, $V8) -> 65000000000002 | Y8: =IF(EXACT($F8, ""), $Y7, $V8) -> 65000000000003 | Z8: =IF(EXACT($H8, ""), $Z7, $V8) -> 65000000000004 | AA8: =IF(EXACT($J8, ""), $AA7, $V8) -> 65000000000000 | AB8: =IF(EXACT($L8, ""), $AB7, $V8) -> 65000000000000 | AD8: =AD7 + IF(W8<>W7, 1, 0) -> 1 | AE8: =IF(AD7<>AD8, 1, AE7) + IF(X8<>X7, 1, 0) -> 2 | AF8: =IF(AE7<>AE8, 1, AF7) + IF(Y8<>Y7, 1, 0) -> 2 | AG8: =IF(AF7<>AF8, 1, AG7) + IF(Z8<>Z7, 1, 0) -> 2 | AH8: =IF(AG7<>AG8, 1, AH7) + IF(AA8<>AA7, 1, 0) -> 1 | AI8: =IF(AH7<>AH8, 1, AI7) + IF(AB8<>AB7, 1, 0) -> 1 | AK8: =IF(AA8<>AA7, "L5", IF(Z8<>Z7, "L4", IF(Y8<>Y7, "L3", IF(X8<>X7, "L2", IF(W8<>W7, "L1", "L1" ) ) ) ) ) -> L4 | AM8: null | AN8: =IF(EXACT($AK7, "L1"), $W7, AN7) -> 65000000000001 | AO8: =IF(EXACT($AK7, "L1"), $W7, IF(EXACT($AK7, "L2"), $X7, AO7)) -> 65000000000002 | AP8: =IF(EXACT($AK7, "L1"), $W7, IF(EXACT($AK7, "L2"), $X7, IF(EXACT($AK7, "L3"), $Y7, AP7))) -> 65000000000003 | AQ8: =IF(EXACT($AK7, "L1"), $W7, IF(EXACT($AK7, "L2"), $X7, IF(EXACT($AK7, "L3"), $Y7, IF(EXACT($AK7, "L4"), $Z7, AQ7)))) -> 65000000000003 | AS8: =IF(EXACT($AK8, "L1"), AM8, IF(EXACT($AK8, "L2"), AN8, IF(EXACT($AK8, "L3"), AO8, IF(EXACT($AK8, "L4"), AP8, IF(EXACT($AK8, "L5"), AQ8, ""))))) -> 65000000000003 | AU8: =IF(AND(EXACT(B8, ""), EXACT(D8, ""), EXACT(F8, ""), EXACT(H8, ""), EXACT(J8, ""), EXACT(L8, "")), "", CONCATENATE( "PERFORM * FROM ""SchData-OLTP-Accounting"".""Func_TblChartOfAccount_SET""(varSystemLoginSession, null, null, null, varInstitutionBranchID, 62000000000001::bigint,'", IF(EXACT(B8, ""), IF(EXACT(D8, ""), IF(EXACT(F8, ""), IF(EXACT(H8, ""), IF(EXACT(J8, ""), IF(EXACT(L8, ""), "", L8), J8), H8), F8), D8), B8), "', '", IF(EXACT(B8, ""), IF(EXACT(D8, ""), IF(EXACT(F8, ""), IF(EXACT(H8, ""), IF(EXACT(J8, ""), IF(EXACT(L8, ""), "", M8), K8), I8), G8), E8), C8), "', ", IF(EXACT(J8, ""), "62000000000001::bigint", IF((RIGHT(J8, 2)*1 = 1), "62000000000001::bigint", IF((RIGHT(J8, 2)*1 = 2), "62000000000002::bigint", "null"))), ", '2016-01-01 00:00:00'::timestamp, null::timestamp, ", AW8, "::bigint, 66000000000001::bigint);")) -> PERFORM * FROM "SchData-OLTP-Accounting"."Func_TblChartOfAccount_SET"(varSystemLoginSession, null, null, null, varInstitutionBranchID, 62000000000001::bigint,'1-1101', 'Petty Cash', 62000000000001::bigint, '2016-01-01 00:00:00'::timestamp, null::timestamp, 65000000000003::bigint, 66000000000001::bigint); | AV8: =IF(AND(EXACT($B8, ""), EXACT($D8, ""), EXACT($F8, ""), EXACT($H8, ""), EXACT($J8, ""), EXACT($L8, "")), "", V8) -> 65000000000004 | AW8: =AS8 -> 65000000000003 | AY8: =IF(AND(EXACT($B8, ""), EXACT($D8, ""), EXACT($F8, ""), EXACT($H8, ""), EXACT($J8, ""), EXACT($L8, "")), "", IF(NOT(EXACT($B8, "")), "null", IF(NOT(EXACT($D8, "")), IF($W7<>$W6, $W7, $W8), IF(NOT(EXACT($F8, "")), IF($X7<>$X6, $X7, IF($W7<>$W6, $W7, $X8)), IF(NOT(EXACT($H8, "")), IF($Y7<>$Y6, $Y7, IF($X7<>$X6, $X7, IF($W7<>$W6, $W7, $Y8))), IF(NOT(EXACT($J8, "")), IF($Z7<>$Z6, $Z7, IF($Y7<>$Y6, $Y7, IF($X7<>$X6, $X7, IF($W7<>$W6, $W7, $Z8)))), IF(NOT(EXACT($L8, "")), IF($AA7<>$AA6, $AA7, IF($Z7<>$Z6, $Z7, IF($Y7<>$Y6, $Y7, IF($X7<>$X6, $X7, IF($W7<>$W6, $W7, $AA8))))), "others"))))))) -> 65000000000003 | BA8: =BA7 + IF(EXACT(BB8, ""), 0, 1) -> 65000000000004 | BB8: =IF(AND(EXACT($B8, ""), EXACT($D8, ""), EXACT($F8, ""), EXACT($H8, ""), EXACT($J8, ""), EXACT($L8, "")), "", CONCATENATE( "PERFORM * FROM ""SchData-OLTP-Accounting"".""Func_TblChartOfAccount_SET""(varSystemLoginSession, null, null, null, null, null, varInstitutionBranchID, 62000000000001::bigint,'", IF(EXACT($B8, ""), IF(EXACT($D8, ""), IF(EXACT($F8, ""), IF(EXACT($H8, ""), IF(EXACT($J8, ""), IF(EXACT($L8, ""), "", $L8), $J8), $H8), $F8), $D8), $B8), "', '", IF(EXACT($B8, ""), IF(EXACT($D8, ""), IF(EXACT($F8, ""), IF(EXACT($H8, ""), IF(EXACT($J8, ""), IF(EXACT($L8, ""), "", $M8), $K8), $I8), $G8), $E8), $C8), "', ", IF(EXACT($J8, ""), "62000000000001::bigint", IF((RIGHT($J8, 2)*1 = 1), "62000000000001::bigint", IF((RIGHT($J8, 2)*1 = 2), "62000000000002::bigint", "null"))), ", '2016-01-01 00:00:00'::timestamp, null::timestamp, ", $AW8, "::bigint, 66000000000001::bigint, ", IF(EXACT(LEFT(IF(EXACT($B8, ""), IF(EXACT($D8, ""), IF(EXACT($F8, ""), IF(EXACT($H8, ""), IF(EXACT($J8, ""), IF(EXACT($L8, ""), "", $L8), $J8), $H8), $F8), $D8), $B8), 1), "1"), "TRUE", "FALSE"), "::boolean);")) -> PERFORM * FROM "SchData-OLTP-Accounting"."Func_TblChartOfAccount_SET"(varSystemLoginSession, null, null, null, null, null, varInstitutionBranchID, 62000000000001::bigint,'1-1101', 'Petty Cash', 62000000000001::bigint, '2016-01-01 00:00:00'::timestamp, null::timestamp, 65000000000003::bigint, 66000000000001::bigint, TRUE::boolean);
J9: 1-1101.01 | K9: Petty Cash (IDR) | O9: =IF(EXACT($B9, ""), $O8, $B9) -> 1-0000 | P9: =IF(EXACT($D9, ""), $P8, $D9) -> 1-1000 | Q9: =IF(EXACT($F9, ""), $Q8, $F9) -> 1-1100 | R9: =IF(EXACT($H9, ""), $R8, $H9) -> 1-1101 | S9: =IF(EXACT($J9, ""), $S8, $J9) -> 1-1101.01 | T9: =IF(EXACT($L9, ""), $T8, $L9) | V9: =V8+IF(AND(EXACT(B9, ""), EXACT(D9, ""), EXACT(F9, ""), EXACT(H9, ""), EXACT(J9, ""), EXACT(L9, "")), 0, 1) -> 65000000000005 | W9: =IF(EXACT($B9, ""), $W8, $V9) -> 65000000000001 | X9: =IF(EXACT($D9, ""), $X8, $V9) -> 65000000000002 | Y9: =IF(EXACT($F9, ""), $Y8, $V9) -> 65000000000003 | Z9: =IF(EXACT($H9, ""), $Z8, $V9) -> 65000000000004 | AA9: =IF(EXACT($J9, ""), $AA8, $V9) -> 65000000000005 | AB9: =IF(EXACT($L9, ""), $AB8, $V9) -> 65000000000000 | AD9: =AD8 + IF(W9<>W8, 1, 0) -> 1 | AE9: =IF(AD8<>AD9, 1, AE8) + IF(X9<>X8, 1, 0) -> 2 | AF9: =IF(AE8<>AE9, 1, AF8) + IF(Y9<>Y8, 1, 0) -> 2 | AG9: =IF(AF8<>AF9, 1, AG8) + IF(Z9<>Z8, 1, 0) -> 2 | AH9: =IF(AG8<>AG9, 1, AH8) + IF(AA9<>AA8, 1, 0) -> 2 | AI9: =IF(AH8<>AH9, 1, AI8) + IF(AB9<>AB8, 1, 0) -> 1 | AK9: =IF(AA9<>AA8, "L5", IF(Z9<>Z8, "L4", IF(Y9<>Y8, "L3", IF(X9<>X8, "L2", IF(W9<>W8, "L1", "L1" ) ) ) ) ) -> L5 | AM9: null | AN9: =IF(EXACT($AK8, "L1"), $W8, AN8) -> 65000000000001 | AO9: =IF(EXACT($AK8, "L1"), $W8, IF(EXACT($AK8, "L2"), $X8, AO8)) -> 65000000000002 | AP9: =IF(EXACT($AK8, "L1"), $W8, IF(EXACT($AK8, "L2"), $X8, IF(EXACT($AK8, "L3"), $Y8, AP8))) -> 65000000000003 | AQ9: =IF(EXACT($AK8, "L1"), $W8, IF(EXACT($AK8, "L2"), $X8, IF(EXACT($AK8, "L3"), $Y8, IF(EXACT($AK8, "L4"), $Z8, AQ8)))) -> 65000000000004 | AS9: =IF(EXACT($AK9, "L1"), AM9, IF(EXACT($AK9, "L2"), AN9, IF(EXACT($AK9, "L3"), AO9, IF(EXACT($AK9, "L4"), AP9, IF(EXACT($AK9, "L5"), AQ9, ""))))) -> 65000000000004 | AU9: =IF(AND(EXACT(B9, ""), EXACT(D9, ""), EXACT(F9, ""), EXACT(H9, ""), EXACT(J9, ""), EXACT(L9, "")), "", CONCATENATE( "PERFORM * FROM ""SchData-OLTP-Accounting"".""Func_TblChartOfAccount_SET""(varSystemLoginSession, null, null, null, varInstitutionBranchID, 62000000000001::bigint,'", IF(EXACT(B9, ""), IF(EXACT(D9, ""), IF(EXACT(F9, ""), IF(EXACT(H9, ""), IF(EXACT(J9, ""), IF(EXACT(L9, ""), "", L9), J9), H9), F9), D9), B9), "', '", IF(EXACT(B9, ""), IF(EXACT(D9, ""), IF(EXACT(F9, ""), IF(EXACT(H9, ""), IF(EXACT(J9, ""), IF(EXACT(L9, ""), "", M9), K9), I9), G9), E9), C9), "', ", IF(EXACT(J9, ""), "62000000000001::bigint", IF((RIGHT(J9, 2)*1 = 1), "62000000000001::bigint", IF((RIGHT(J9, 2)*1 = 2), "62000000000002::bigint", "null"))), ", '2016-01-01 00:00:00'::timestamp, null::timestamp, ", AW9, "::bigint, 66000000000001::bigint);")) -> PERFORM * FROM "SchData-OLTP-Accounting"."Func_TblChartOfAccount_SET"(varSystemLoginSession, null, null, null, varInstitutionBranchID, 62000000000001::bigint,'1-1101.01', 'Petty Cash (IDR)', 62000000000001::bigint, '2016-01-01 00:00:00'::timestamp, null::timestamp, 65000000000004::bigint, 66000000000001::bigint); | AV9: =IF(AND(EXACT($B9, ""), EXACT($D9, ""), EXACT($F9, ""), EXACT($H9, ""), EXACT($J9, ""), EXACT($L9, "")), "", V9) -> 65000000000005 | AW9: =AS9 -> 65000000000004 | AY9: =IF(AND(EXACT($B9, ""), EXACT($D9, ""), EXACT($F9, ""), EXACT($H9, ""), EXACT($J9, ""), EXACT($L9, "")), "", IF(NOT(EXACT($B9, "")), "null", IF(NOT(EXACT($D9, "")), IF($W8<>$W7, $W8, $W9), IF(NOT(EXACT($F9, "")), IF($X8<>$X7, $X8, IF($W8<>$W7, $W8, $X9)), IF(NOT(EXACT($H9, "")), IF($Y8<>$Y7, $Y8, IF($X8<>$X7, $X8, IF($W8<>$W7, $W8, $Y9))), IF(NOT(EXACT($J9, "")), IF($Z8<>$Z7, $Z8, IF($Y8<>$Y7, $Y8, IF($X8<>$X7, $X8, IF($W8<>$W7, $W8, $Z9)))), IF(NOT(EXACT($L9, "")), IF($AA8<>$AA7, $AA8, IF($Z8<>$Z7, $Z8, IF($Y8<>$Y7, $Y8, IF($X8<>$X7, $X8, IF($W8<>$W7, $W8, $AA9))))), "others"))))))) -> 65000000000004 | BA9: =BA8 + IF(EXACT(BB9, ""), 0, 1) -> 65000000000005 | BB9: =IF(AND(EXACT($B9, ""), EXACT($D9, ""), EXACT($F9, ""), EXACT($H9, ""), EXACT($J9, ""), EXACT($L9, "")), "", CONCATENATE( "PERFORM * FROM ""SchData-OLTP-Accounting"".""Func_TblChartOfAccount_SET""(varSystemLoginSession, null, null, null, null, null, varInstitutionBranchID, 62000000000001::bigint,'", IF(EXACT($B9, ""), IF(EXACT($D9, ""), IF(EXACT($F9, ""), IF(EXACT($H9, ""), IF(EXACT($J9, ""), IF(EXACT($L9, ""), "", $L9), $J9), $H9), $F9), $D9), $B9), "', '", IF(EXACT($B9, ""), IF(EXACT($D9, ""), IF(EXACT($F9, ""), IF(EXACT($H9, ""), IF(EXACT($J9, ""), IF(EXACT($L9, ""), "", $M9), $K9), $I9), $G9), $E9), $C9), "', ", IF(EXACT($J9, ""), "62000000000001::bigint", IF((RIGHT($J9, 2)*1 = 1), "62000000000001::bigint", IF((RIGHT($J9, 2)*1 = 2), "62000000000002::bigint", "null"))), ", '2016-01-01 00:00:00'::timestamp, null::timestamp, ", $AW9, "::bigint, 66000000000001::bigint, ", IF(EXACT(LEFT(IF(EXACT($B9, ""), IF(EXACT($D9, ""), IF(EXACT($F9, ""), IF(EXACT($H9, ""), IF(EXACT($J9, ""), IF(EXACT($L9, ""), "", $L9), $J9), $H9), $F9), $D9), $B9), 1), "1"), "TRUE", "FALSE"), "::boolean);")) -> PERFORM * FROM "SchData-OLTP-Accounting"."Func_TblChartOfAccount_SET"(varSystemLoginSession, null, null, null, null, null, varInstitutionBranchID, 62000000000001::bigint,'1-1101.01', 'Petty Cash (IDR)', 62000000000001::bigint, '2016-01-01 00:00:00'::timestamp, null::timestamp, 65000000000004::bigint, 66000000000001::bigint, TRUE::boolean);
H10: 1-1102 | I10: Bank | O10: =IF(EXACT($B10, ""), $O9, $B10) -> 1-0000 | P10: =IF(EXACT($D10, ""), $P9, $D10) -> 1-1000 | Q10: =IF(EXACT($F10, ""), $Q9, $F10) -> 1-1100 | R10: =IF(EXACT($H10, ""), $R9, $H10) -> 1-1102 | S10: =IF(EXACT($J10, ""), $S9, $J10) -> 1-1101.01 | T10: =IF(EXACT($L10, ""), $T9, $L10) | V10: =V9+IF(AND(EXACT(B10, ""), EXACT(D10, ""), EXACT(F10, ""), EXACT(H10, ""), EXACT(J10, ""), EXACT(L10, "")), 0, 1) -> 65000000000006 | W10: =IF(EXACT($B10, ""), $W9, $V10) -> 65000000000001 | X10: =IF(EXACT($D10, ""), $X9, $V10) -> 65000000000002 | Y10: =IF(EXACT($F10, ""), $Y9, $V10) -> 65000000000003 | Z10: =IF(EXACT($H10, ""), $Z9, $V10) -> 65000000000006 | AA10: =IF(EXACT($J10, ""), $AA9, $V10) -> 65000000000005 | AB10: =IF(EXACT($L10, ""), $AB9, $V10) -> 65000000000000 | AD10: =AD9 + IF(W10<>W9, 1, 0) -> 1 | AE10: =IF(AD9<>AD10, 1, AE9) + IF(X10<>X9, 1, 0) -> 2 | AF10: =IF(AE9<>AE10, 1, AF9) + IF(Y10<>Y9, 1, 0) -> 2 | AG10: =IF(AF9<>AF10, 1, AG9) + IF(Z10<>Z9, 1, 0) -> 3 | AH10: =IF(AG9<>AG10, 1, AH9) + IF(AA10<>AA9, 1, 0) -> 1 | AI10: =IF(AH9<>AH10, 1, AI9) + IF(AB10<>AB9, 1, 0) -> 1 | AK10: =IF(AA10<>AA9, "L5", IF(Z10<>Z9, "L4", IF(Y10<>Y9, "L3", IF(X10<>X9, "L2", IF(W10<>W9, "L1", "L1" ) ) ) ) ) -> L4 | AM10: null | AN10: =IF(EXACT($AK9, "L1"), $W9, AN9) -> 65000000000001 | AO10: =IF(EXACT($AK9, "L1"), $W9, IF(EXACT($AK9, "L2"), $X9, AO9)) -> 65000000000002 | AP10: =IF(EXACT($AK9, "L1"), $W9, IF(EXACT($AK9, "L2"), $X9, IF(EXACT($AK9, "L3"), $Y9, AP9))) -> 65000000000003 | AQ10: =IF(EXACT($AK9, "L1"), $W9, IF(EXACT($AK9, "L2"), $X9, IF(EXACT($AK9, "L3"), $Y9, IF(EXACT($AK9, "L4"), $Z9, AQ9)))) -> 65000000000004 | AS10: =IF(EXACT($AK10, "L1"), AM10, IF(EXACT($AK10, "L2"), AN10, IF(EXACT($AK10, "L3"), AO10, IF(EXACT($AK10, "L4"), AP10, IF(EXACT($AK10, "L5"), AQ10, ""))))) -> 65000000000003 | AU10: =IF(AND(EXACT(B10, ""), EXACT(D10, ""), EXACT(F10, ""), EXACT(H10, ""), EXACT(J10, ""), EXACT(L10, "")), "", CONCATENATE( "PERFORM * FROM ""SchData-OLTP-Accounting"".""Func_TblChartOfAccount_SET""(varSystemLoginSession, null, null, null, varInstitutionBranchID, 62000000000001::bigint,'", IF(EXACT(B10, ""), IF(EXACT(D10, ""), IF(EXACT(F10, ""), IF(EXACT(H10, ""), IF(EXACT(J10, ""), IF(EXACT(L10, ""), "", L10), J10), H10), F10), D10), B10), "', '", IF(EXACT(B10, ""), IF(EXACT(D10, ""), IF(EXACT(F10, ""), IF(EXACT(H10, ""), IF(EXACT(J10, ""), IF(EXACT(L10, ""), "", M10), K10), I10), G10), E10), C10), "', ", IF(EXACT(J10, ""), "62000000000001::bigint", IF((RIGHT(J10, 2)*1 = 1), "62000000000001::bigint", IF((RIGHT(J10, 2)*1 = 2), "62000000000002::bigint", "null"))), ", '2016-01-01 00:00:00'::timestamp, null::timestamp, ", AW10, "::bigint, 66000000000001::bigint);")) -> PERFORM * FROM "SchData-OLTP-Accounting"."Func_TblChartOfAccount_SET"(varSystemLoginSession, null, null, null, varInstitutionBranchID, 62000000000001::bigint,'1-1102', 'Bank', 62000000000001::bigint, '2016-01-01 00:00:00'::timestamp, null::timestamp, 65000000000003::bigint, 66000000000001::bigint); | AV10: =IF(AND(EXACT($B10, ""), EXACT($D10, ""), EXACT($F10, ""), EXACT($H10, ""), EXACT($J10, ""), EXACT($L10, "")), "", V10) -> 65000000000006 | AW10: =AS10 -> 65000000000003 | AY10: =IF(AND(EXACT($B10, ""), EXACT($D10, ""), EXACT($F10, ""), EXACT($H10, ""), EXACT($J10, ""), EXACT($L10, "")), "", IF(NOT(EXACT($B10, "")), "null", IF(NOT(EXACT($D10, "")), IF($W9<>$W8, $W9, $W10), IF(NOT(EXACT($F10, "")), IF($X9<>$X8, $X9, IF($W9<>$W8, $W9, $X10)), IF(NOT(EXACT($H10, "")), IF($Y9<>$Y8, $Y9, IF($X9<>$X8, $X9, IF($W9<>$W8, $W9, $Y10))), IF(NOT(EXACT($J10, "")), IF($Z9<>$Z8, $Z9, IF($Y9<>$Y8, $Y9, IF($X9<>$X8, $X9, IF($W9<>$W8, $W9, $Z10)))), IF(NOT(EXACT($L10, "")), IF($AA9<>$AA8, $AA9, IF($Z9<>$Z8, $Z9, IF($Y9<>$Y8, $Y9, IF($X9<>$X8, $X9, IF($W9<>$W8, $W9, $AA10))))), "others"))))))) -> 65000000000003 | BA10: =BA9 + IF(EXACT(BB10, ""), 0, 1) -> 65000000000006 | BB10: =IF(AND(EXACT($B10, ""), EXACT($D10, ""), EXACT($F10, ""), EXACT($H10, ""), EXACT($J10, ""), EXACT($L10, "")), "", CONCATENATE( "PERFORM * FROM ""SchData-OLTP-Accounting"".""Func_TblChartOfAccount_SET""(varSystemLoginSession, null, null, null, null, null, varInstitutionBranchID, 62000000000001::bigint,'", IF(EXACT($B10, ""), IF(EXACT($D10, ""), IF(EXACT($F10, ""), IF(EXACT($H10, ""), IF(EXACT($J10, ""), IF(EXACT($L10, ""), "", $L10), $J10), $H10), $F10), $D10), $B10), "', '", IF(EXACT($B10, ""), IF(EXACT($D10, ""), IF(EXACT($F10, ""), IF(EXACT($H10, ""), IF(EXACT($J10, ""), IF(EXACT($L10, ""), "", $M10), $K10), $I10), $G10), $E10), $C10), "', ", IF(EXACT($J10, ""), "62000000000001::bigint", IF((RIGHT($J10, 2)*1 = 1), "62000000000001::bigint", IF((RIGHT($J10, 2)*1 = 2), "62000000000002::bigint", "null"))), ", '2016-01-01 00:00:00'::timestamp, null::timestamp, ", $AW10, "::bigint, 66000000000001::bigint, ", IF(EXACT(LEFT(IF(EXACT($B10, ""), IF(EXACT($D10, ""), IF(EXACT($F10, ""), IF(EXACT($H10, ""), IF(EXACT($J10, ""), IF(EXACT($L10, ""), "", $L10), $J10), $H10), $F10), $D10), $B10), 1), "1"), "TRUE", "FALSE"), "::boolean);")) -> PERFORM * FROM "SchData-OLTP-Accounting"."Func_TblChartOfAccount_SET"(varSystemLoginSession, null, null, null, null, null, varInstitutionBranchID, 62000000000001::bigint,'1-1102', 'Bank', 62000000000001::bigint, '2016-01-01 00:00:00'::timestamp, null::timestamp, 65000000000003::bigint, 66000000000001::bigint, TRUE::boolean);
J11: 1-1102.01 | K11: Bank (IDR) | M11: Tag : Bank-IDR | O11: =IF(EXACT($B11, ""), $O10, $B11) -> 1-0000 | P11: =IF(EXACT($D11, ""), $P10, $D11) -> 1-1000 | Q11: =IF(EXACT($F11, ""), $Q10, $F11) -> 1-1100 | R11: =IF(EXACT($H11, ""), $R10, $H11) -> 1-1102 | S11: =IF(EXACT($J11, ""), $S10, $J11) -> 1-1102.01 | T11: =IF(EXACT($L11, ""), $T10, $L11) | V11: =V10+IF(AND(EXACT(B11, ""), EXACT(D11, ""), EXACT(F11, ""), EXACT(H11, ""), EXACT(J11, ""), EXACT(L11, "")), 0, 1) -> 65000000000007 | W11: =IF(EXACT($B11, ""), $W10, $V11) -> 65000000000001 | X11: =IF(EXACT($D11, ""), $X10, $V11) -> 65000000000002 | Y11: =IF(EXACT($F11, ""), $Y10, $V11) -> 65000000000003 | Z11: =IF(EXACT($H11, ""), $Z10, $V11) -> 65000000000006 | AA11: =IF(EXACT($J11, ""), $AA10, $V11) -> 65000000000007 | AB11: =IF(EXACT($L11, ""), $AB10, $V11) -> 65000000000000 | AD11: =AD10 + IF(W11<>W10, 1, 0) -> 1 | AE11: =IF(AD10<>AD11, 1, AE10) + IF(X11<>X10, 1, 0) -> 2 | AF11: =IF(AE10<>AE11, 1, AF10) + IF(Y11<>Y10, 1, 0) -> 2 | AG11: =IF(AF10<>AF11, 1, AG10) + IF(Z11<>Z10, 1, 0) -> 3 | AH11: =IF(AG10<>AG11, 1, AH10) + IF(AA11<>AA10, 1, 0) -> 2 | AI11: =IF(AH10<>AH11, 1, AI10) + IF(AB11<>AB10, 1, 0) -> 1 | AK11: =IF(AA11<>AA10, "L5", IF(Z11<>Z10, "L4", IF(Y11<>Y10, "L3", IF(X11<>X10, "L2", IF(W11<>W10, "L1", "L1" ) ) ) ) ) -> L5 | AM11: null | AN11: =IF(EXACT($AK10, "L1"), $W10, AN10) -> 65000000000001 | AO11: =IF(EXACT($AK10, "L1"), $W10, IF(EXACT($AK10, "L2"), $X10, AO10)) -> 65000000000002 | AP11: =IF(EXACT($AK10, "L1"), $W10, IF(EXACT($AK10, "L2"), $X10, IF(EXACT($AK10, "L3"), $Y10, AP10))) -> 65000000000003 | AQ11: =IF(EXACT($AK10, "L1"), $W10, IF(EXACT($AK10, "L2"), $X10, IF(EXACT($AK10, "L3"), $Y10, IF(EXACT($AK10, "L4"), $Z10, AQ10)))) -> 65000000000006 | AS11: =IF(EXACT($AK11, "L1"), AM11, IF(EXACT($AK11, "L2"), AN11, IF(EXACT($AK11, "L3"), AO11, IF(EXACT($AK11, "L4"), AP11, IF(EXACT($AK11, "L5"), AQ11, ""))))) -> 65000000000006 | AU11: =IF(AND(EXACT(B11, ""), EXACT(D11, ""), EXACT(F11, ""), EXACT(H11, ""), EXACT(J11, ""), EXACT(L11, "")), "", CONCATENATE( "PERFORM * FROM ""SchData-OLTP-Accounting"".""Func_TblChartOfAccount_SET""(varSystemLoginSession, null, null, null, varInstitutionBranchID, 62000000000001::bigint,'", IF(EXACT(B11, ""), IF(EXACT(D11, ""), IF(EXACT(F11, ""), IF(EXACT(H11, ""), IF(EXACT(J11, ""), IF(EXACT(L11, ""), "", L11), J11), H11), F11), D11), B11), "', '", IF(EXACT(B11, ""), IF(EXACT(D11, ""), IF(EXACT(F11, ""), IF(EXACT(H11, ""), IF(EXACT(J11, ""), IF(EXACT(L11, ""), "", M11), K11), I11), G11), E11), C11), "', ", IF(EXACT(J11, ""), "62000000000001::bigint", IF((RIGHT(J11, 2)*1 = 1), "62000000000001::bigint", IF((RIGHT(J11, 2)*1 = 2), "62000000000002::bigint", "null"))), ", '2016-01-01 00:00:00'::timestamp, null::timestamp, ", AW11, "::bigint, 66000000000001::bigint);")) -> PERFORM * FROM "SchData-OLTP-Accounting"."Func_TblChartOfAccount_SET"(varSystemLoginSession, null, null, null, varInstitutionBranchID, 62000000000001::bigint,'1-1102.01', 'Bank (IDR)', 62000000000001::bigint, '2016-01-01 00:00:00'::timestamp, null::timestamp, 65000000000006::bigint, 66000000000001::bigint); | AV11: =IF(AND(EXACT($B11, ""), EXACT($D11, ""), EXACT($F11, ""), EXACT($H11, ""), EXACT($J11, ""), EXACT($L11, "")), "", V11) -> 65000000000007 | AW11: =AS11 -> 65000000000006 | AY11: =IF(AND(EXACT($B11, ""), EXACT($D11, ""), EXACT($F11, ""), EXACT($H11, ""), EXACT($J11, ""), EXACT($L11, "")), "", IF(NOT(EXACT($B11, "")), "null", IF(NOT(EXACT($D11, "")), IF($W10<>$W9, $W10, $W11), IF(NOT(EXACT($F11, "")), IF($X10<>$X9, $X10, IF($W10<>$W9, $W10, $X11)), IF(NOT(EXACT($H11, "")), IF($Y10<>$Y9, $Y10, IF($X10<>$X9, $X10, IF($W10<>$W9, $W10, $Y11))), IF(NOT(EXACT($J11, "")), IF($Z10<>$Z9, $Z10, IF($Y10<>$Y9, $Y10, IF($X10<>$X9, $X10, IF($W10<>$W9, $W10, $Z11)))), IF(NOT(EXACT($L11, "")), IF($AA10<>$AA9, $AA10, IF($Z10<>$Z9, $Z10, IF($Y10<>$Y9, $Y10, IF($X10<>$X9, $X10, IF($W10<>$W9, $W10, $AA11))))), "others"))))))) -> 65000000000006 | BA11: =BA10 + IF(EXACT(BB11, ""), 0, 1) -> 65000000000007 | BB11: =IF(AND(EXACT($B11, ""), EXACT($D11, ""), EXACT($F11, ""), EXACT($H11, ""), EXACT($J11, ""), EXACT($L11, "")), "", CONCATENATE( "PERFORM * FROM ""SchData-OLTP-Accounting"".""Func_TblChartOfAccount_SET""(varSystemLoginSession, null, null, null, null, null, varInstitutionBranchID, 62000000000001::bigint,'", IF(EXACT($B11, ""), IF(EXACT($D11, ""), IF(EXACT($F11, ""), IF(EXACT($H11, ""), IF(EXACT($J11, ""), IF(EXACT($L11, ""), "", $L11), $J11), $H11), $F11), $D11), $B11), "', '", IF(EXACT($B11, ""), IF(EXACT($D11, ""), IF(EXACT($F11, ""), IF(EXACT($H11, ""), IF(EXACT($J11, ""), IF(EXACT($L11, ""), "", $M11), $K11), $I11), $G11), $E11), $C11), "', ", IF(EXACT($J11, ""), "62000000000001::bigint", IF((RIGHT($J11, 2)*1 = 1), "62000000000001::bigint", IF((RIGHT($J11, 2)*1 = 2), "62000000000002::bigint", "null"))), ", '2016-01-01 00:00:00'::timestamp, null::timestamp, ", $AW11, "::bigint, 66000000000001::bigint, ", IF(EXACT(LEFT(IF(EXACT($B11, ""), IF(EXACT($D11, ""), IF(EXACT($F11, ""), IF(EXACT($H11, ""), IF(EXACT($J11, ""), IF(EXACT($L11, ""), "", $L11), $J11), $H11), $F11), $D11), $B11), 1), "1"), "TRUE", "FALSE"), "::boolean);")) -> PERFORM * FROM "SchData-OLTP-Accounting"."Func_TblChartOfAccount_SET"(varSystemLoginSession, null, null, null, null, null, varInstitutionBranchID, 62000000000001::bigint,'1-1102.01', 'Bank (IDR)', 62000000000001::bigint, '2016-01-01 00:00:00'::timestamp, null::timestamp, 65000000000006::bigint, 66000000000001::bigint, TRUE::boolean);
J12: 1-1102.02 | K12: Bank (USD) | M12: Tag : Bank-USD | O12: =IF(EXACT($B12, ""), $O11, $B12) -> 1-0000 | P12: =IF(EXACT($D12, ""), $P11, $D12) -> 1-1000 | Q12: =IF(EXACT($F12, ""), $Q11, $F12) -> 1-1100 | R12: =IF(EXACT($H12, ""), $R11, $H12) -> 1-1102 | S12: =IF(EXACT($J12, ""), $S11, $J12) -> 1-1102.02 | T12: =IF(EXACT($L12, ""), $T11, $L12) | V12: =V11+IF(AND(EXACT(B12, ""), EXACT(D12, ""), EXACT(F12, ""), EXACT(H12, ""), EXACT(J12, ""), EXACT(L12, "")), 0, 1) -> 65000000000008 | W12: =IF(EXACT($B12, ""), $W11, $V12) -> 65000000000001 | X12: =IF(EXACT($D12, ""), $X11, $V12) -> 65000000000002 | Y12: =IF(EXACT($F12, ""), $Y11, $V12) -> 65000000000003 | Z12: =IF(EXACT($H12, ""), $Z11, $V12) -> 65000000000006 | AA12: =IF(EXACT($J12, ""), $AA11, $V12) -> 65000000000008 | AB12: =IF(EXACT($L12, ""), $AB11, $V12) -> 65000000000000 | AD12: =AD11 + IF(W12<>W11, 1, 0) -> 1 | AE12: =IF(AD11<>AD12, 1, AE11) + IF(X12<>X11, 1, 0) -> 2 | AF12: =IF(AE11<>AE12, 1, AF11) + IF(Y12<>Y11, 1, 0) -> 2 | AG12: =IF(AF11<>AF12, 1, AG11) + IF(Z12<>Z11, 1, 0) -> 3 | AH12: =IF(AG11<>AG12, 1, AH11) + IF(AA12<>AA11, 1, 0) -> 3 | AI12: =IF(AH11<>AH12, 1, AI11) + IF(AB12<>AB11, 1, 0) -> 1 | AK12: =IF(AA12<>AA11, "L5", IF(Z12<>Z11, "L4", IF(Y12<>Y11, "L3", IF(X12<>X11, "L2", IF(W12<>W11, "L1", "L1" ) ) ) ) ) -> L5 | AM12: null | AN12: =IF(EXACT($AK11, "L1"), $W11, AN11) -> 65000000000001 | AO12: =IF(EXACT($AK11, "L1"), $W11, IF(EXACT($AK11, "L2"), $X11, AO11)) -> 65000000000002 | AP12: =IF(EXACT($AK11, "L1"), $W11, IF(EXACT($AK11, "L2"), $X11, IF(EXACT($AK11, "L3"), $Y11, AP11))) -> 65000000000003 | AQ12: =IF(EXACT($AK11, "L1"), $W11, IF(EXACT($AK11, "L2"), $X11, IF(EXACT($AK11, "L3"), $Y11, IF(EXACT($AK11, "L4"), $Z11, AQ11)))) -> 65000000000006 | AS12: =IF(EXACT($AK12, "L1"), AM12, IF(EXACT($AK12, "L2"), AN12, IF(EXACT($AK12, "L3"), AO12, IF(EXACT($AK12, "L4"), AP12, IF(EXACT($AK12, "L5"), AQ12, ""))))) -> 65000000000006 | AU12: =IF(AND(EXACT(B12, ""), EXACT(D12, ""), EXACT(F12, ""), EXACT(H12, ""), EXACT(J12, ""), EXACT(L12, "")), "", CONCATENATE( "PERFORM * FROM ""SchData-OLTP-Accounting"".""Func_TblChartOfAccount_SET""(varSystemLoginSession, null, null, null, varInstitutionBranchID, 62000000000001::bigint,'", IF(EXACT(B12, ""), IF(EXACT(D12, ""), IF(EXACT(F12, ""), IF(EXACT(H12, ""), IF(EXACT(J12, ""), IF(EXACT(L12, ""), "", L12), J12), H12), F12), D12), B12), "', '", IF(EXACT(B12, ""), IF(EXACT(D12, ""), IF(EXACT(F12, ""), IF(EXACT(H12, ""), IF(EXACT(J12, ""), IF(EXACT(L12, ""), "", M12), K12), I12), G12), E12), C12), "', ", IF(EXACT(J12, ""), "62000000000001::bigint", IF((RIGHT(J12, 2)*1 = 1), "62000000000001::bigint", IF((RIGHT(J12, 2)*1 = 2), "62000000000002::bigint", "null"))), ", '2016-01-01 00:00:00'::timestamp, null::timestamp, ", AW12, "::bigint, 66000000000001::bigint);")) -> PERFORM * FROM "SchData-OLTP-Accounting"."Func_TblChartOfAccount_SET"(varSystemLoginSession, null, null, null, varInstitutionBranchID, 62000000000001::bigint,'1-1102.02', 'Bank (USD)', 62000000000002::bigint, '2016-01-01 00:00:00'::timestamp, null::timestamp, 65000000000006::bigint, 66000000000001::bigint); | AV12: =IF(AND(EXACT($B12, ""), EXACT($D12, ""), EXACT($F12, ""), EXACT($H12, ""), EXACT($J12, ""), EXACT($L12, "")), "", V12) -> 65000000000008 | AW12: =AS12 -> 65000000000006 | AY12: =IF(AND(EXACT($B12, ""), EXACT($D12, ""), EXACT($F12, ""), EXACT($H12, ""), EXACT($J12, ""), EXACT($L12, "")), "", IF(NOT(EXACT($B12, "")), "null", IF(NOT(EXACT($D12, "")), IF($W11<>$W10, $W11, $W12), IF(NOT(EXACT($F12, "")), IF($X11<>$X10, $X11, IF($W11<>$W10, $W11, $X12)), IF(NOT(EXACT($H12, "")), IF($Y11<>$Y10, $Y11, IF($X11<>$X10, $X11, IF($W11<>$W10, $W11, $Y12))), IF(NOT(EXACT($J12, "")), IF($Z11<>$Z10, $Z11, IF($Y11<>$Y10, $Y11, IF($X11<>$X10, $X11, IF($W11<>$W10, $W11, $Z12)))), IF(NOT(EXACT($L12, "")), IF($AA11<>$AA10, $AA11, IF($Z11<>$Z10, $Z11, IF($Y11<>$Y10, $Y11, IF($X11<>$X10, $X11, IF($W11<>$W10, $W11, $AA12))))), "others"))))))) -> 65000000000006 | BA12: =BA11 + IF(EXACT(BB12, ""), 0, 1) -> 65000000000008 | BB12: =IF(AND(EXACT($B12, ""), EXACT($D12, ""), EXACT($F12, ""), EXACT($H12, ""), EXACT($J12, ""), EXACT($L12, "")), "", CONCATENATE( "PERFORM * FROM ""SchData-OLTP-Accounting"".""Func_TblChartOfAccount_SET""(varSystemLoginSession, null, null, null, null, null, varInstitutionBranchID, 62000000000001::bigint,'", IF(EXACT($B12, ""), IF(EXACT($D12, ""), IF(EXACT($F12, ""), IF(EXACT($H12, ""), IF(EXACT($J12, ""), IF(EXACT($L12, ""), "", $L12), $J12), $H12), $F12), $D12), $B12), "', '", IF(EXACT($B12, ""), IF(EXACT($D12, ""), IF(EXACT($F12, ""), IF(EXACT($H12, ""), IF(EXACT($J12, ""), IF(EXACT($L12, ""), "", $M12), $K12), $I12), $G12), $E12), $C12), "', ", IF(EXACT($J12, ""), "62000000000001::bigint", IF((RIGHT($J12, 2)*1 = 1), "62000000000001::bigint", IF((RIGHT($J12, 2)*1 = 2), "62000000000002::bigint", "null"))), ", '2016-01-01 00:00:00'::timestamp, null::timestamp, ", $AW12, "::bigint, 66000000000001::bigint, ", IF(EXACT(LEFT(IF(EXACT($B12, ""), IF(EXACT($D12, ""), IF(EXACT($F12, ""), IF(EXACT($H12, ""), IF(EXACT($J12, ""), IF(EXACT($L12, ""), "", $L12), $J12), $H12), $F12), $D12), $B12), 1), "1"), "TRUE", "FALSE"), "::boolean);")) -> PERFORM * FROM "SchData-OLTP-Accounting"."Func_TblChartOfAccount_SET"(varSystemLoginSession, null, null, null, null, null, varInstitutionBranchID, 62000000000001::bigint,'1-1102.02', 'Bank (USD)', 62000000000002::bigint, '2016-01-01 00:00:00'::timestamp, null::timestamp, 65000000000006::bigint, 66000000000001::bigint, TRUE::boolean);
F13: 1-1200 | G13: Account Receivable | O13: =IF(EXACT($B13, ""), $O12, $B13) -> 1-0000 | P13: =IF(EXACT($D13, ""), $P12, $D13) -> 1-1000 | Q13: =IF(EXACT($F13, ""), $Q12, $F13) -> 1-1200 | R13: =IF(EXACT($H13, ""), $R12, $H13) -> 1-1102 | S13: =IF(EXACT($J13, ""), $S12, $J13) -> 1-1102.02 | T13: =IF(EXACT($L13, ""), $T12, $L13) | V13: =V12+IF(AND(EXACT(B13, ""), EXACT(D13, ""), EXACT(F13, ""), EXACT(H13, ""), EXACT(J13, ""), EXACT(L13, "")), 0, 1) -> 65000000000009 | W13: =IF(EXACT($B13, ""), $W12, $V13) -> 65000000000001 | X13: =IF(EXACT($D13, ""), $X12, $V13) -> 65000000000002 | Y13: =IF(EXACT($F13, ""), $Y12, $V13) -> 65000000000009 | Z13: =IF(EXACT($H13, ""), $Z12, $V13) -> 65000000000006 | AA13: =IF(EXACT($J13, ""), $AA12, $V13) -> 65000000000008 | AB13: =IF(EXACT($L13, ""), $AB12, $V13) -> 65000000000000 | AD13: =AD12 + IF(W13<>W12, 1, 0) -> 1 | AE13: =IF(AD12<>AD13, 1, AE12) + IF(X13<>X12, 1, 0) -> 2 | AF13: =IF(AE12<>AE13, 1, AF12) + IF(Y13<>Y12, 1, 0) -> 3 | AG13: =IF(AF12<>AF13, 1, AG12) + IF(Z13<>Z12, 1, 0) -> 1 | AH13: =IF(AG12<>AG13, 1, AH12) + IF(AA13<>AA12, 1, 0) -> 1 | AI13: =IF(AH12<>AH13, 1, AI12) + IF(AB13<>AB12, 1, 0) -> 1 | AK13: =IF(AA13<>AA12, "L5", IF(Z13<>Z12, "L4", IF(Y13<>Y12, "L3", IF(X13<>X12, "L2", IF(W13<>W12, "L1", "L1" ) ) ) ) ) -> L3 | AM13: null | AN13: =IF(EXACT($AK12, "L1"), $W12, AN12) -> 65000000000001 | AO13: =IF(EXACT($AK12, "L1"), $W12, IF(EXACT($AK12, "L2"), $X12, AO12)) -> 65000000000002 | AP13: =IF(EXACT($AK12, "L1"), $W12, IF(EXACT($AK12, "L2"), $X12, IF(EXACT($AK12, "L3"), $Y12, AP12))) -> 65000000000003 | AQ13: =IF(EXACT($AK12, "L1"), $W12, IF(EXACT($AK12, "L2"), $X12, IF(EXACT($AK12, "L3"), $Y12, IF(EXACT($AK12, "L4"), $Z12, AQ12)))) -> 65000000000006 | AS13: =IF(EXACT($AK13, "L1"), AM13, IF(EXACT($AK13, "L2"), AN13, IF(EXACT($AK13, "L3"), AO13, IF(EXACT($AK13, "L4"), AP13, IF(EXACT($AK13, "L5"), AQ13, ""))))) -> 65000000000002 | AU13: =IF(AND(EXACT(B13, ""), EXACT(D13, ""), EXACT(F13, ""), EXACT(H13, ""), EXACT(J13, ""), EXACT(L13, "")), "", CONCATENATE( "PERFORM * FROM ""SchData-OLTP-Accounting"".""Func_TblChartOfAccount_SET""(varSystemLoginSession, null, null, null, varInstitutionBranchID, 62000000000001::bigint,'", IF(EXACT(B13, ""), IF(EXACT(D13, ""), IF(EXACT(F13, ""), IF(EXACT(H13, ""), IF(EXACT(J13, ""), IF(EXACT(L13, ""), "", L13), J13), H13), F13), D13), B13), "', '", IF(EXACT(B13, ""), IF(EXACT(D13, ""), IF(EXACT(F13, ""), IF(EXACT(H13, ""), IF(EXACT(J13, ""), IF(EXACT(L13, ""), "", M13), K13), I13), G13), E13), C13), "', ", IF(EXACT(J13, ""), "62000000000001::bigint", IF((RIGHT(J13, 2)*1 = 1), "62000000000001::bigint", IF((RIGHT(J13, 2)*1 = 2), "62000000000002::bigint", "null"))), ", '2016-01-01 00:00:00'::timestamp, null::timestamp, ", AW13, "::bigint, 66000000000001::bigint);")) -> PERFORM * FROM "SchData-OLTP-Accounting"."Func_TblChartOfAccount_SET"(varSystemLoginSession, null, null, null, varInstitutionBranchID, 62000000000001::bigint,'1-1200', 'Account Receivable', 62000000000001::bigint, '2016-01-01 00:00:00'::timestamp, null::timestamp, 65000000000002::bigint, 66000000000001::bigint); | AV13: =IF(AND(EXACT($B13, ""), EXACT($D13, ""), EXACT($F13, ""), EXACT($H13, ""), EXACT($J13, ""), EXACT($L13, "")), "", V13) -> 65000000000009 | AW13: =AS13 -> 65000000000002 | AY13: =IF(AND(EXACT($B13, ""), EXACT($D13, ""), EXACT($F13, ""), EXACT($H13, ""), EXACT($J13, ""), EXACT($L13, "")), "", IF(NOT(EXACT($B13, "")), "null", IF(NOT(EXACT($D13, "")), IF($W12<>$W11, $W12, $W13), IF(NOT(EXACT($F13, "")), IF($X12<>$X11, $X12, IF($W12<>$W11, $W12, $X13)), IF(NOT(EXACT($H13, "")), IF($Y12<>$Y11, $Y12, IF($X12<>$X11, $X12, IF($W12<>$W11, $W12, $Y13))), IF(NOT(EXACT($J13, "")), IF($Z12<>$Z11, $Z12, IF($Y12<>$Y11, $Y12, IF($X12<>$X11, $X12, IF($W12<>$W11, $W12, $Z13)))), IF(NOT(EXACT($L13, "")), IF($AA12<>$AA11, $AA12, IF($Z12<>$Z11, $Z12, IF($Y12<>$Y11, $Y12, IF($X12<>$X11, $X12, IF($W12<>$W11, $W12, $AA13))))), "others"))))))) -> 65000000000002 | BA13: =BA12 + IF(EXACT(BB13, ""), 0, 1) -> 65000000000009 | BB13: =IF(AND(EXACT($B13, ""), EXACT($D13, ""), EXACT($F13, ""), EXACT($H13, ""), EXACT($J13, ""), EXACT($L13, "")), "", CONCATENATE( "PERFORM * FROM ""SchData-OLTP-Accounting"".""Func_TblChartOfAccount_SET""(varSystemLoginSession, null, null, null, null, null, varInstitutionBranchID, 62000000000001::bigint,'", IF(EXACT($B13, ""), IF(EXACT($D13, ""), IF(EXACT($F13, ""), IF(EXACT($H13, ""), IF(EXACT($J13, ""), IF(EXACT($L13, ""), "", $L13), $J13), $H13), $F13), $D13), $B13), "', '", IF(EXACT($B13, ""), IF(EXACT($D13, ""), IF(EXACT($F13, ""), IF(EXACT($H13, ""), IF(EXACT($J13, ""), IF(EXACT($L13, ""), "", $M13), $K13), $I13), $G13), $E13), $C13), "', ", IF(EXACT($J13, ""), "62000000000001::bigint", IF((RIGHT($J13, 2)*1 = 1), "62000000000001::bigint", IF((RIGHT($J13, 2)*1 = 2), "62000000000002::bigint", "null"))), ", '2016-01-01 00:00:00'::timestamp, null::timestamp, ", $AW13, "::bigint, 66000000000001::bigint, ", IF(EXACT(LEFT(IF(EXACT($B13, ""), IF(EXACT($D13, ""), IF(EXACT($F13, ""), IF(EXACT($H13, ""), IF(EXACT($J13, ""), IF(EXACT($L13, ""), "", $L13), $J13), $H13), $F13), $D13), $B13), 1), "1"), "TRUE", "FALSE"), "::boolean);")) -> PERFORM * FROM "SchData-OLTP-Accounting"."Func_TblChartOfAccount_SET"(varSystemLoginSession, null, null, null, null, null, varInstitutionBranchID, 62000000000001::bigint,'1-1200', 'Account Receivable', 62000000000001::bigint, '2016-01-01 00:00:00'::timestamp, null::timestamp, 65000000000002::bigint, 66000000000001::bigint, TRUE::boolean);
H14: 1-1201 | I14: Piutang Usaha | O14: =IF(EXACT($B14, ""), $O13, $B14) -> 1-0000 | P14: =IF(EXACT($D14, ""), $P13, $D14) -> 1-1000 | Q14: =IF(EXACT($F14, ""), $Q13, $F14) -> 1-1200 | R14: =IF(EXACT($H14, ""), $R13, $H14) -> 1-1201 | S14: =IF(EXACT($J14, ""), $S13, $J14) -> 1-1102.02 | T14: =IF(EXACT($L14, ""), $T13, $L14) | V14: =V13+IF(AND(EXACT(B14, ""), EXACT(D14, ""), EXACT(F14, ""), EXACT(H14, ""), EXACT(J14, ""), EXACT(L14, "")), 0, 1) -> 65000000000010 | W14: =IF(EXACT($B14, ""), $W13, $V14) -> 65000000000001 | X14: =IF(EXACT($D14, ""), $X13, $V14) -> 65000000000002 | Y14: =IF(EXACT($F14, ""), $Y13, $V14) -> 65000000000009 | Z14: =IF(EXACT($H14, ""), $Z13, $V14) -> 65000000000010 | AA14: =IF(EXACT($J14, ""), $AA13, $V14) -> 65000000000008 | AB14: =IF(EXACT($L14, ""), $AB13, $V14) -> 65000000000000 | AD14: =AD13 + IF(W14<>W13, 1, 0) -> 1 | AE14: =IF(AD13<>AD14, 1, AE13) + IF(X14<>X13, 1, 0) -> 2 | AF14: =IF(AE13<>AE14, 1, AF13) + IF(Y14<>Y13, 1, 0) -> 3 | AG14: =IF(AF13<>AF14, 1, AG13) + IF(Z14<>Z13, 1, 0) -> 2 | AH14: =IF(AG13<>AG14, 1, AH13) + IF(AA14<>AA13, 1, 0) -> 1 | AI14: =IF(AH13<>AH14, 1, AI13) + IF(AB14<>AB13, 1, 0) -> 1 | AK14: =IF(AA14<>AA13, "L5", IF(Z14<>Z13, "L4", IF(Y14<>Y13, "L3", IF(X14<>X13, "L2", IF(W14<>W13, "L1", "L1" ) ) ) ) ) -> L4 | AM14: null | AN14: =IF(EXACT($AK13, "L1"), $W13, AN13) -> 65000000000001 | AO14: =IF(EXACT($AK13, "L1"), $W13, IF(EXACT($AK13, "L2"), $X13, AO13)) -> 65000000000002 | AP14: =IF(EXACT($AK13, "L1"), $W13, IF(EXACT($AK13, "L2"), $X13, IF(EXACT($AK13, "L3"), $Y13, AP13))) -> 65000000000009 | AQ14: =IF(EXACT($AK13, "L1"), $W13, IF(EXACT($AK13, "L2"), $X13, IF(EXACT($AK13, "L3"), $Y13, IF(EXACT($AK13, "L4"), $Z13, AQ13)))) -> 65000000000009 | AS14: =IF(EXACT($AK14, "L1"), AM14, IF(EXACT($AK14, "L2"), AN14, IF(EXACT($AK14, "L3"), AO14, IF(EXACT($AK14, "L4"), AP14, IF(EXACT($AK14, "L5"), AQ14, ""))))) -> 65000000000009 | AU14: =IF(AND(EXACT(B14, ""), EXACT(D14, ""), EXACT(F14, ""), EXACT(H14, ""), EXACT(J14, ""), EXACT(L14, "")), "", CONCATENATE( "PERFORM * FROM ""SchData-OLTP-Accounting"".""Func_TblChartOfAccount_SET""(varSystemLoginSession, null, null, null, varInstitutionBranchID, 62000000000001::bigint,'", IF(EXACT(B14, ""), IF(EXACT(D14, ""), IF(EXACT(F14, ""), IF(EXACT(H14, ""), IF(EXACT(J14, ""), IF(EXACT(L14, ""), "", L14), J14), H14), F14), D14), B14), "', '", IF(EXACT(B14, ""), IF(EXACT(D14, ""), IF(EXACT(F14, ""), IF(EXACT(H14, ""), IF(EXACT(J14, ""), IF(EXACT(L14, ""), "", M14), K14), I14), G14), E14), C14), "', ", IF(EXACT(J14, ""), "62000000000001::bigint", IF((RIGHT(J14, 2)*1 = 1), "62000000000001::bigint", IF((RIGHT(J14, 2)*1 = 2), "62000000000002::bigint", "null"))), ", '2016-01-01 00:00:00'::timestamp, null::timestamp, ", AW14, "::bigint, 66000000000001::bigint);")) -> PERFORM * FROM "SchData-OLTP-Accounting"."Func_TblChartOfAccount_SET"(varSystemLoginSession, null, null, null, varInstitutionBranchID, 62000000000001::bigint,'1-1201', 'Piutang Usaha', 62000000000001::bigint, '2016-01-01 00:00:00'::timestamp, null::timestamp, 65000000000009::bigint, 66000000000001::bigint); | AV14: =IF(AND(EXACT($B14, ""), EXACT($D14, ""), EXACT($F14, ""), EXACT($H14, ""), EXACT($J14, ""), EXACT($L14, "")), "", V14) -> 65000000000010 | AW14: =AS14 -> 65000000000009 | AY14: =IF(AND(EXACT($B14, ""), EXACT($D14, ""), EXACT($F14, ""), EXACT($H14, ""), EXACT($J14, ""), EXACT($L14, "")), "", IF(NOT(EXACT($B14, "")), "null", IF(NOT(EXACT($D14, "")), IF($W13<>$W12, $W13, $W14), IF(NOT(EXACT($F14, "")), IF($X13<>$X12, $X13, IF($W13<>$W12, $W13, $X14)), IF(NOT(EXACT($H14, "")), IF($Y13<>$Y12, $Y13, IF($X13<>$X12, $X13, IF($W13<>$W12, $W13, $Y14))), IF(NOT(EXACT($J14, "")), IF($Z13<>$Z12, $Z13, IF($Y13<>$Y12, $Y13, IF($X13<>$X12, $X13, IF($W13<>$W12, $W13, $Z14)))), IF(NOT(EXACT($L14, "")), IF($AA13<>$AA12, $AA13, IF($Z13<>$Z12, $Z13, IF($Y13<>$Y12, $Y13, IF($X13<>$X12, $X13, IF($W13<>$W12, $W13, $AA14))))), "others"))))))) -> 65000000000009 | BA14: =BA13 + IF(EXACT(BB14, ""), 0, 1) -> 65000000000010 | BB14: =IF(AND(EXACT($B14, ""), EXACT($D14, ""), EXACT($F14, ""), EXACT($H14, ""), EXACT($J14, ""), EXACT($L14, "")), "", CONCATENATE( "PERFORM * FROM ""SchData-OLTP-Accounting"".""Func_TblChartOfAccount_SET""(varSystemLoginSession, null, null, null, null, null, varInstitutionBranchID, 62000000000001::bigint,'", IF(EXACT($B14, ""), IF(EXACT($D14, ""), IF(EXACT($F14, ""), IF(EXACT($H14, ""), IF(EXACT($J14, ""), IF(EXACT($L14, ""), "", $L14), $J14), $H14), $F14), $D14), $B14), "', '", IF(EXACT($B14, ""), IF(EXACT($D14, ""), IF(EXACT($F14, ""), IF(EXACT($H14, ""), IF(EXACT($J14, ""), IF(EXACT($L14, ""), "", $M14), $K14), $I14), $G14), $E14), $C14), "', ", IF(EXACT($J14, ""), "62000000000001::bigint", IF((RIGHT($J14, 2)*1 = 1), "62000000000001::bigint", IF((RIGHT($J14, 2)*1 = 2), "62000000000002::bigint", "null"))), ", '2016-01-01 00:00:00'::timestamp, null::timestamp, ", $AW14, "::bigint, 66000000000001::bigint, ", IF(EXACT(LEFT(IF(EXACT($B14, ""), IF(EXACT($D14, ""), IF(EXACT($F14, ""), IF(EXACT($H14, ""), IF(EXACT($J14, ""), IF(EXACT($L14, ""), "", $L14), $J14), $H14), $F14), $D14), $B14), 1), "1"), "TRUE", "FALSE"), "::boolean);")) -> PERFORM * FROM "SchData-OLTP-Accounting"."Func_TblChartOfAccount_SET"(varSystemLoginSession, null, null, null, null, null, varInstitutionBranchID, 62000000000001::bigint,'1-1201', 'Piutang Usaha', 62000000000001::bigint, '2016-01-01 00:00:00'::timestamp, null::timestamp, 65000000000009::bigint, 66000000000001::bigint, TRUE::boolean);
J15: 1-1201.01 | K15: AR (IDR) | M15: Tag : Customer-IDR | O15: =IF(EXACT($B15, ""), $O14, $B15) -> 1-0000 | P15: =IF(EXACT($D15, ""), $P14, $D15) -> 1-1000 | Q15: =IF(EXACT($F15, ""), $Q14, $F15) -> 1-1200 | R15: =IF(EXACT($H15, ""), $R14, $H15) -> 1-1201 | S15: =IF(EXACT($J15, ""), $S14, $J15) -> 1-1201.01 | T15: =IF(EXACT($L15, ""), $T14, $L15) | V15: =V14+IF(AND(EXACT(B15, ""), EXACT(D15, ""), EXACT(F15, ""), EXACT(H15, ""), EXACT(J15, ""), EXACT(L15, "")), 0, 1) -> 65000000000011 | W15: =IF(EXACT($B15, ""), $W14, $V15) -> 65000000000001 | X15: =IF(EXACT($D15, ""), $X14, $V15) -> 65000000000002 | Y15: =IF(EXACT($F15, ""), $Y14, $V15) -> 65000000000009 | Z15: =IF(EXACT($H15, ""), $Z14, $V15) -> 65000000000010 | AA15: =IF(EXACT($J15, ""), $AA14, $V15) -> 65000000000011 | AB15: =IF(EXACT($L15, ""), $AB14, $V15) -> 65000000000000 | AD15: =AD14 + IF(W15<>W14, 1, 0) -> 1 | AE15: =IF(AD14<>AD15, 1, AE14) + IF(X15<>X14, 1, 0) -> 2 | AF15: =IF(AE14<>AE15, 1, AF14) + IF(Y15<>Y14, 1, 0) -> 3 | AG15: =IF(AF14<>AF15, 1, AG14) + IF(Z15<>Z14, 1, 0) -> 2 | AH15: =IF(AG14<>AG15, 1, AH14) + IF(AA15<>AA14, 1, 0) -> 2 | AI15: =IF(AH14<>AH15, 1, AI14) + IF(AB15<>AB14, 1, 0) -> 1 | AK15: =IF(AA15<>AA14, "L5", IF(Z15<>Z14, "L4", IF(Y15<>Y14, "L3", IF(X15<>X14, "L2", IF(W15<>W14, "L1", "L1" ) ) ) ) ) -> L5 | AM15: null | AN15: =IF(EXACT($AK14, "L1"), $W14, AN14) -> 65000000000001 | AO15: =IF(EXACT($AK14, "L1"), $W14, IF(EXACT($AK14, "L2"), $X14, AO14)) -> 65000000000002 | AP15: =IF(EXACT($AK14, "L1"), $W14, IF(EXACT($AK14, "L2"), $X14, IF(EXACT($AK14, "L3"), $Y14, AP14))) -> 65000000000009 | AQ15: =IF(EXACT($AK14, "L1"), $W14, IF(EXACT($AK14, "L2"), $X14, IF(EXACT($AK14, "L3"), $Y14, IF(EXACT($AK14, "L4"), $Z14, AQ14)))) -> 65000000000010 | AS15: =IF(EXACT($AK15, "L1"), AM15, IF(EXACT($AK15, "L2"), AN15, IF(EXACT($AK15, "L3"), AO15, IF(EXACT($AK15, "L4"), AP15, IF(EXACT($AK15, "L5"), AQ15, ""))))) -> 65000000000010 | AU15: =IF(AND(EXACT(B15, ""), EXACT(D15, ""), EXACT(F15, ""), EXACT(H15, ""), EXACT(J15, ""), EXACT(L15, "")), "", CONCATENATE( "PERFORM * FROM ""SchData-OLTP-Accounting"".""Func_TblChartOfAccount_SET""(varSystemLoginSession, null, null, null, varInstitutionBranchID, 62000000000001::bigint,'", IF(EXACT(B15, ""), IF(EXACT(D15, ""), IF(EXACT(F15, ""), IF(EXACT(H15, ""), IF(EXACT(J15, ""), IF(EXACT(L15, ""), "", L15), J15), H15), F15), D15), B15), "', '", IF(EXACT(B15, ""), IF(EXACT(D15, ""), IF(EXACT(F15, ""), IF(EXACT(H15, ""), IF(EXACT(J15, ""), IF(EXACT(L15, ""), "", M15), K15), I15), G15), E15), C15), "', ", IF(EXACT(J15, ""), "62000000000001::bigint", IF((RIGHT(J15, 2)*1 = 1), "62000000000001::bigint", IF((RIGHT(J15, 2)*1 = 2), "62000000000002::bigint", "null"))), ", '2016-01-01 00:00:00'::timestamp, null::timestamp, ", AW15, "::bigint, 66000000000001::bigint);")) -> PERFORM * FROM "SchData-OLTP-Accounting"."Func_TblChartOfAccount_SET"(varSystemLoginSession, null, null, null, varInstitutionBranchID, 62000000000001::bigint,'1-1201.01', 'AR (IDR)', 62000000000001::bigint, '2016-01-01 00:00:00'::timestamp, null::timestamp, 65000000000010::bigint, 66000000000001::bigint); | AV15: =IF(AND(EXACT($B15, ""), EXACT($D15, ""), EXACT($F15, ""), EXACT($H15, ""), EXACT($J15, ""), EXACT($L15, "")), "", V15) -> 65000000000011 | AW15: =AS15 -> 65000000000010 | AY15: =IF(AND(EXACT($B15, ""), EXACT($D15, ""), EXACT($F15, ""), EXACT($H15, ""), EXACT($J15, ""), EXACT($L15, "")), "", IF(NOT(EXACT($B15, "")), "null", IF(NOT(EXACT($D15, "")), IF($W14<>$W13, $W14, $W15), IF(NOT(EXACT($F15, "")), IF($X14<>$X13, $X14, IF($W14<>$W13, $W14, $X15)), IF(NOT(EXACT($H15, "")), IF($Y14<>$Y13, $Y14, IF($X14<>$X13, $X14, IF($W14<>$W13, $W14, $Y15))), IF(NOT(EXACT($J15, "")), IF($Z14<>$Z13, $Z14, IF($Y14<>$Y13, $Y14, IF($X14<>$X13, $X14, IF($W14<>$W13, $W14, $Z15)))), IF(NOT(EXACT($L15, "")), IF($AA14<>$AA13, $AA14, IF($Z14<>$Z13, $Z14, IF($Y14<>$Y13, $Y14, IF($X14<>$X13, $X14, IF($W14<>$W13, $W14, $AA15))))), "others"))))))) -> 65000000000010 | BA15: =BA14 + IF(EXACT(BB15, ""), 0, 1) -> 65000000000011 | BB15: =IF(AND(EXACT($B15, ""), EXACT($D15, ""), EXACT($F15, ""), EXACT($H15, ""), EXACT($J15, ""), EXACT($L15, "")), "", CONCATENATE( "PERFORM * FROM ""SchData-OLTP-Accounting"".""Func_TblChartOfAccount_SET""(varSystemLoginSession, null, null, null, null, null, varInstitutionBranchID, 62000000000001::bigint,'", IF(EXACT($B15, ""), IF(EXACT($D15, ""), IF(EXACT($F15, ""), IF(EXACT($H15, ""), IF(EXACT($J15, ""), IF(EXACT($L15, ""), "", $L15), $J15), $H15), $F15), $D15), $B15), "', '", IF(EXACT($B15, ""), IF(EXACT($D15, ""), IF(EXACT($F15, ""), IF(EXACT($H15, ""), IF(EXACT($J15, ""), IF(EXACT($L15, ""), "", $M15), $K15), $I15), $G15), $E15), $C15), "', ", IF(EXACT($J15, ""), "62000000000001::bigint", IF((RIGHT($J15, 2)*1 = 1), "62000000000001::bigint", IF((RIGHT($J15, 2)*1 = 2), "62000000000002::bigint", "null"))), ", '2016-01-01 00:00:00'::timestamp, null::timestamp, ", $AW15, "::bigint, 66000000000001::bigint, ", IF(EXACT(LEFT(IF(EXACT($B15, ""), IF(EXACT($D15, ""), IF(EXACT($F15, ""), IF(EXACT($H15, ""), IF(EXACT($J15, ""), IF(EXACT($L15, ""), "", $L15), $J15), $H15), $F15), $D15), $B15), 1), "1"), "TRUE", "FALSE"), "::boolean);")) -> PERFORM * FROM "SchData-OLTP-Accounting"."Func_TblChartOfAccount_SET"(varSystemLoginSession, null, null, null, null, null, varInstitutionBranchID, 62000000000001::bigint,'1-1201.01', 'AR (IDR)', 62000000000001::bigint, '2016-01-01 00:00:00'::timestamp, null::timestamp, 65000000000010::bigint, 66000000000001::bigint, TRUE::boolean);
