Workbook

Sheet MAIN
B2: Ref ID Person | C2: Person Name | D2: Nomor Induk Pekerja | E2: Default Entity | G2: SYS_PID Prediction | H2: SQL Syntax
G3: 32000000000000
B4: =IF(EXACT([1]DataLookUp!$B4, ""), "", [1]DataLookUp!$B4) -> 25000000000001 | C4: =IF(EXACT(B4, ""), "", VLOOKUP(B4, [1]DataLookUp!$B$4:$C$1000, 2,FALSE )) -> Abdollah Syani Siregar | G4: =G3 + IF(EXACT(H4, ""), 0, 1) -> 32000000000001 | H4: =CONCATENATE("PERFORM ""SchData-OLTP-HumanResource"".""Func_TblWorker_SET""(varSystemLoginSession, null::bigint, null::varchar, null::timestamptz, null::timestamptz, null::varchar, varInstitutionBranchID, varBaseCurrencyID, ", B4, "::bigint, ", IF(EXACT(D4, ""), "null", CONCATENATE("'", D4, "'")), "::varchar);") -> PERFORM "SchData-OLTP-HumanResource"."Func_TblWorker_SET"(varSystemLoginSession, null::bigint, null::varchar, null::timestamptz, null::timestamptz, null::varchar, varInstitutionBranchID, varBaseCurrencyID, 25000000000001::bigint, null::varchar);
B5: =IF(EXACT([1]DataLookUp!$B5, ""), "", [1]DataLookUp!$B5) -> 25000000000002 | C5: =IF(EXACT(B5, ""), "", VLOOKUP(B5, [1]DataLookUp!$B$4:$C$1000, 2,FALSE )) -> Abdul Karim | G5: =G4 + IF(EXACT(H5, ""), 0, 1) -> 32000000000002 | H5: =CONCATENATE("PERFORM ""SchData-OLTP-HumanResource"".""Func_TblWorker_SET""(varSystemLoginSession, null::bigint, null::varchar, null::timestamptz, null::timestamptz, null::varchar, varInstitutionBranchID, varBaseCurrencyID, ", B5, "::bigint, ", IF(EXACT(D5, ""), "null", CONCATENATE("'", D5, "'")), "::varchar);") -> PERFORM "SchData-OLTP-HumanResource"."Func_TblWorker_SET"(varSystemLoginSession, null::bigint, null::varchar, null::timestamptz, null::timestamptz, null::varchar, varInstitutionBranchID, varBaseCurrencyID, 25000000000002::bigint, null::varchar);
B6: =IF(EXACT([1]DataLookUp!$B6, ""), "", [1]DataLookUp!$B6) -> 25000000000003 | C6: =IF(EXACT(B6, ""), "", VLOOKUP(B6, [1]DataLookUp!$B$4:$C$1000, 2,FALSE )) -> Abdul Rahman Sitompul | G6: =G5 + IF(EXACT(H6, ""), 0, 1) -> 32000000000003 | H6: =CONCATENATE("PERFORM ""SchData-OLTP-HumanResource"".""Func_TblWorker_SET""(varSystemLoginSession, null::bigint, null::varchar, null::timestamptz, null::timestamptz, null::varchar, varInstitutionBranchID, varBaseCurrencyID, ", B6, "::bigint, ", IF(EXACT(D6, ""), "null", CONCATENATE("'", D6, "'")), "::varchar);") -> PERFORM "SchData-OLTP-HumanResource"."Func_TblWorker_SET"(varSystemLoginSession, null::bigint, null::varchar, null::timestamptz, null::timestamptz, null::varchar, varInstitutionBranchID, varBaseCurrencyID, 25000000000003::bigint, null::varchar);
B7: =IF(EXACT([1]DataLookUp!$B7, ""), "", [1]DataLookUp!$B7) -> 25000000000004 | C7: =IF(EXACT(B7, ""), "", VLOOKUP(B7, [1]DataLookUp!$B$4:$C$1000, 2,FALSE )) -> Abdul Risan | G7: =G6 + IF(EXACT(H7, ""), 0, 1) -> 32000000000004 | H7: =CONCATENATE("PERFORM ""SchData-OLTP-HumanResource"".""Func_TblWorker_SET""(varSystemLoginSession, null::bigint, null::varchar, null::timestamptz, null::timestamptz, null::varchar, varInstitutionBranchID, varBaseCurrencyID, ", B7, "::bigint, ", IF(EXACT(D7, ""), "null", CONCATENATE("'", D7, "'")), "::varchar);") -> PERFORM "SchData-OLTP-HumanResource"."Func_TblWorker_SET"(varSystemLoginSession, null::bigint, null::varchar, null::timestamptz, null::timestamptz, null::varchar, varInstitutionBranchID, varBaseCurrencyID, 25000000000004::bigint, null::varchar);
B8: =IF(EXACT([1]DataLookUp!$B8, ""), "", [1]DataLookUp!$B8) -> 25000000000005 | C8: =IF(EXACT(B8, ""), "", VLOOKUP(B8, [1]DataLookUp!$B$4:$C$1000, 2,FALSE )) -> Abdullah Nabil | G8: =G7 + IF(EXACT(H8, ""), 0, 1) -> 32000000000005 | H8: =CONCATENATE("PERFORM ""SchData-OLTP-HumanResource"".""Func_TblWorker_SET""(varSystemLoginSession, null::bigint, null::varchar, null::timestamptz, null::timestamptz, null::varchar, varInstitutionBranchID, varBaseCurrencyID, ", B8, "::bigint, ", IF(EXACT(D8, ""), "null", CONCATENATE("'", D8, "'")), "::varchar);") -> PERFORM "SchData-OLTP-HumanResource"."Func_TblWorker_SET"(varSystemLoginSession, null::bigint, null::varchar, null::timestamptz, null::timestamptz, null::varchar, varInstitutionBranchID, varBaseCurrencyID, 25000000000005::bigint, null::varchar);
B9: =IF(EXACT([1]DataLookUp!$B9, ""), "", [1]DataLookUp!$B9) -> 25000000000006 | C9: =IF(EXACT(B9, ""), "", VLOOKUP(B9, [1]DataLookUp!$B$4:$C$1000, 2,FALSE )) -> Adhitya Danar | G9: =G8 + IF(EXACT(H9, ""), 0, 1) -> 32000000000006 | H9: =CONCATENATE("PERFORM ""SchData-OLTP-HumanResource"".""Func_TblWorker_SET""(varSystemLoginSession, null::bigint, null::varchar, null::timestamptz, null::timestamptz, null::varchar, varInstitutionBranchID, varBaseCurrencyID, ", B9, "::bigint, ", IF(EXACT(D9, ""), "null", CONCATENATE("'", D9, "'")), "::varchar);") -> PERFORM "SchData-OLTP-HumanResource"."Func_TblWorker_SET"(varSystemLoginSession, null::bigint, null::varchar, null::timestamptz, null::timestamptz, null::varchar, varInstitutionBranchID, varBaseCurrencyID, 25000000000006::bigint, null::varchar);
B10: =IF(EXACT([1]DataLookUp!$B10, ""), "", [1]DataLookUp!$B10) -> 25000000000007 | C10: =IF(EXACT(B10, ""), "", VLOOKUP(B10, [1]DataLookUp!$B$4:$C$1000, 2,FALSE )) -> Adi Ruswandi | D10: 0209251009 | E10: QDC | G10: =G9 + IF(EXACT(H10, ""), 0, 1) -> 32000000000007 | H10: =CONCATENATE("PERFORM ""SchData-OLTP-HumanResource"".""Func_TblWorker_SET""(varSystemLoginSession, null::bigint, null::varchar, null::timestamptz, null::timestamptz, null::varchar, varInstitutionBranchID, varBaseCurrencyID, ", B10, "::bigint, ", IF(EXACT(D10, ""), "null", CONCATENATE("'", D10, "'")), "::varchar);") -> PERFORM "SchData-OLTP-HumanResource"."Func_TblWorker_SET"(varSystemLoginSession, null::bigint, null::varchar, null::timestamptz, null::timestamptz, null::varchar, varInstitutionBranchID, varBaseCurrencyID, 25000000000007::bigint, '0209251009'::varchar);
B11: =IF(EXACT([1]DataLookUp!$B11, ""), "", [1]DataLookUp!$B11) -> 25000000000008 | C11: =IF(EXACT(B11, ""), "", VLOOKUP(B11, [1]DataLookUp!$B$4:$C$1000, 2,FALSE )) -> Adietya Dharmawan | D11: 050321947 | E11: QDC | G11: =G10 + IF(EXACT(H11, ""), 0, 1) -> 32000000000008 | H11: =CONCATENATE("PERFORM ""SchData-OLTP-HumanResource"".""Func_TblWorker_SET""(varSystemLoginSession, null::bigint, null::varchar, null::timestamptz, null::timestamptz, null::varchar, varInstitutionBranchID, varBaseCurrencyID, ", B11, "::bigint, ", IF(EXACT(D11, ""), "null", CONCATENATE("'", D11, "'")), "::varchar);") -> PERFORM "SchData-OLTP-HumanResource"."Func_TblWorker_SET"(varSystemLoginSession, null::bigint, null::varchar, null::timestamptz, null::timestamptz, null::varchar, varInstitutionBranchID, varBaseCurrencyID, 25000000000008::bigint, '050321947'::varchar);
B12: =IF(EXACT([1]DataLookUp!$B12, ""), "", [1]DataLookUp!$B12) -> 25000000000009 | C12: =IF(EXACT(B12, ""), "", VLOOKUP(B12, [1]DataLookUp!$B$4:$C$1000, 2,FALSE )) -> Aditya Yudha Prawira | G12: =G11 + IF(EXACT(H12, ""), 0, 1) -> 32000000000009 | H12: =CONCATENATE("PERFORM ""SchData-OLTP-HumanResource"".""Func_TblWorker_SET""(varSystemLoginSession, null::bigint, null::varchar, null::timestamptz, null::timestamptz, null::varchar, varInstitutionBranchID, varBaseCurrencyID, ", B12, "::bigint, ", IF(EXACT(D12, ""), "null", CONCATENATE("'", D12, "'")), "::varchar);") -> PERFORM "SchData-OLTP-HumanResource"."Func_TblWorker_SET"(varSystemLoginSession, null::bigint, null::varchar, null::timestamptz, null::timestamptz, null::varchar, varInstitutionBranchID, varBaseCurrencyID, 25000000000009::bigint, null::varchar);
B13: =IF(EXACT([1]DataLookUp!$B13, ""), "", [1]DataLookUp!$B13) -> 25000000000010 | C13: =IF(EXACT(B13, ""), "", VLOOKUP(B13, [1]DataLookUp!$B$4:$C$1000, 2,FALSE )) -> Adli Margie | G13: =G12 + IF(EXACT(H13, ""), 0, 1) -> 32000000000010 | H13: =CONCATENATE("PERFORM ""SchData-OLTP-HumanResource"".""Func_TblWorker_SET""(varSystemLoginSession, null::bigint, null::varchar, null::timestamptz, null::timestamptz, null::varchar, varInstitutionBranchID, varBaseCurrencyID, ", B13, "::bigint, ", IF(EXACT(D13, ""), "null", CONCATENATE("'", D13, "'")), "::varchar);") -> PERFORM "SchData-OLTP-HumanResource"."Func_TblWorker_SET"(varSystemLoginSession, null::bigint, null::varchar, null::timestamptz, null::timestamptz, null::varchar, varInstitutionBranchID, varBaseCurrencyID, 25000000000010::bigint, null::varchar);
B14: =IF(EXACT([1]DataLookUp!$B14, ""), "", [1]DataLookUp!$B14) -> 25000000000011 | C14: =IF(EXACT(B14, ""), "", VLOOKUP(B14, [1]DataLookUp!$B$4:$C$1000, 2,FALSE )) -> Afrida Eka Putri | G14: =G13 + IF(EXACT(H14, ""), 0, 1) -> 32000000000011 | H14: =CONCATENATE("PERFORM ""SchData-OLTP-HumanResource"".""Func_TblWorker_SET""(varSystemLoginSession, null::bigint, null::varchar, null::timestamptz, null::timestamptz, null::varchar, varInstitutionBranchID, varBaseCurrencyID, ", B14, "::bigint, ", IF(EXACT(D14, ""), "null", CONCATENATE("'", D14, "'")), "::varchar);") -> PERFORM "SchData-OLTP-HumanResource"."Func_TblWorker_SET"(varSystemLoginSession, null::bigint, null::varchar, null::timestamptz, null::timestamptz, null::varchar, varInstitutionBranchID, varBaseCurrencyID, 25000000000011::bigint, null::varchar);
B15: =IF(EXACT([1]DataLookUp!$B15, ""), "", [1]DataLookUp!$B15) -> 25000000000012 | C15: =IF(EXACT(B15, ""), "", VLOOKUP(B15, [1]DataLookUp!$B$4:$C$1000, 2,FALSE )) -> Agnes Sutedja | D15: 010703020 | E15: QDC | G15: =G14 + IF(EXACT(H15, ""), 0, 1) -> 32000000000012 | H15: =CONCATENATE("PERFORM ""SchData-OLTP-HumanResource"".""Func_TblWorker_SET""(varSystemLoginSession, null::bigint, null::varchar, null::timestamptz, null::timestamptz, null::varchar, varInstitutionBranchID, varBaseCurrencyID, ", B15, "::bigint, ", IF(EXACT(D15, ""), "null", CONCATENATE("'", D15, "'")), "::varchar);") -> PERFORM "SchData-OLTP-HumanResource"."Func_TblWorker_SET"(varSystemLoginSession, null::bigint, null::varchar, null::timestamptz, null::timestamptz, null::varchar, varInstitutionBranchID, varBaseCurrencyID, 25000000000012::bigint, '010703020'::varchar);
B16: =IF(EXACT([1]DataLookUp!$B16, ""), "", [1]DataLookUp!$B16) -> 25000000000013 | C16: =IF(EXACT(B16, ""), "", VLOOKUP(B16, [1]DataLookUp!$B$4:$C$1000, 2,FALSE )) -> Agung Hendarto | G16: =G15 + IF(EXACT(H16, ""), 0, 1) -> 32000000000013 | H16: =CONCATENATE("PERFORM ""SchData-OLTP-HumanResource"".""Func_TblWorker_SET""(varSystemLoginSession, null::bigint, null::varchar, null::timestamptz, null::timestamptz, null::varchar, varInstitutionBranchID, varBaseCurrencyID, ", B16, "::bigint, ", IF(EXACT(D16, ""), "null", CONCATENATE("'", D16, "'")), "::varchar);") -> PERFORM "SchData-OLTP-HumanResource"."Func_TblWorker_SET"(varSystemLoginSession, null::bigint, null::varchar, null::timestamptz, null::timestamptz, null::varchar, varInstitutionBranchID, varBaseCurrencyID, 25000000000013::bigint, null::varchar);
B17: =IF(EXACT([1]DataLookUp!$B17, ""), "", [1]DataLookUp!$B17) -> 25000000000014 | C17: =IF(EXACT(B17, ""), "", VLOOKUP(B17, [1]DataLookUp!$B$4:$C$1000, 2,FALSE )) -> Agus Priyatno Mahmudo | G17: =G16 + IF(EXACT(H17, ""), 0, 1) -> 32000000000014 | H17: =CONCATENATE("PERFORM ""SchData-OLTP-HumanResource"".""Func_TblWorker_SET""(varSystemLoginSession, null::bigint, null::varchar, null::timestamptz, null::timestamptz, null::varchar, varInstitutionBranchID, varBaseCurrencyID, ", B17, "::bigint, ", IF(EXACT(D17, ""), "null", CONCATENATE("'", D17, "'")), "::varchar);") -> PERFORM "SchData-OLTP-HumanResource"."Func_TblWorker_SET"(varSystemLoginSession, null::bigint, null::varchar, null::timestamptz, null::timestamptz, null::varchar, varInstitutionBranchID, varBaseCurrencyID, 25000000000014::bigint, null::varchar);
B18: =IF(EXACT([1]DataLookUp!$B18, ""), "", [1]DataLookUp!$B18) -> 25000000000015 | C18: =IF(EXACT(B18, ""), "", VLOOKUP(B18, [1]DataLookUp!$B$4:$C$1000, 2,FALSE )) -> Agus Salim | D18: 130223978 | E18: QDC | G18: =G17 + IF(EXACT(H18, ""), 0, 1) -> 32000000000015 | H18: =CONCATENATE("PERFORM ""SchData-OLTP-HumanResource"".""Func_TblWorker_SET""(varSystemLoginSession, null::bigint, null::varchar, null::timestamptz, null::timestamptz, null::varchar, varInstitutionBranchID, varBaseCurrencyID, ", B18, "::bigint, ", IF(EXACT(D18, ""), "null", CONCATENATE("'", D18, "'")), "::varchar);") -> PERFORM "SchData-OLTP-HumanResource"."Func_TblWorker_SET"(varSystemLoginSession, null::bigint, null::varchar, null::timestamptz, null::timestamptz, null::varchar, varInstitutionBranchID, varBaseCurrencyID, 25000000000015::bigint, '130223978'::varchar);
B19: =IF(EXACT([1]DataLookUp!$B19, ""), "", [1]DataLookUp!$B19) -> 25000000000016 | C19: =IF(EXACT(B19, ""), "", VLOOKUP(B19, [1]DataLookUp!$B$4:$C$1000, 2,FALSE )) -> Agus Tanto | G19: =G18 + IF(EXACT(H19, ""), 0, 1) -> 32000000000016 | H19: =CONCATENATE("PERFORM ""SchData-OLTP-HumanResource"".""Func_TblWorker_SET""(varSystemLoginSession, null::bigint, null::varchar, null::timestamptz, null::timestamptz, null::varchar, varInstitutionBranchID, varBaseCurrencyID, ", B19, "::bigint, ", IF(EXACT(D19, ""), "null", CONCATENATE("'", D19, "'")), "::varchar);") -> PERFORM "SchData-OLTP-HumanResource"."Func_TblWorker_SET"(varSystemLoginSession, null::bigint, null::varchar, null::timestamptz, null::timestamptz, null::varchar, varInstitutionBranchID, varBaseCurrencyID, 25000000000016::bigint, null::varchar);
B20: =IF(EXACT([1]DataLookUp!$B20, ""), "", [1]DataLookUp!$B20) -> 25000000000017 | C20: =IF(EXACT(B20, ""), "", VLOOKUP(B20, [1]DataLookUp!$B$4:$C$1000, 2,FALSE )) -> Ahmad Faiz Haems Muda | D20: 280314716 | E20: QDC | G20: =G19 + IF(EXACT(H20, ""), 0, 1) -> 32000000000017 | H20: =CONCATENATE("PERFORM ""SchData-OLTP-HumanResource"".""Func_TblWorker_SET""(varSystemLoginSession, null::bigint, null::varchar, null::timestamptz, null::timestamptz, null::varchar, varInstitutionBranchID, varBaseCurrencyID, ", B20, "::bigint, ", IF(EXACT(D20, ""), "null", CONCATENATE("'", D20, "'")), "::varchar);") -> PERFORM "SchData-OLTP-HumanResource"."Func_TblWorker_SET"(varSystemLoginSession, null::bigint, null::varchar, null::timestamptz, null::timestamptz, null::varchar, varInstitutionBranchID, varBaseCurrencyID, 25000000000017::bigint, '280314716'::varchar);
B21: =IF(EXACT([1]DataLookUp!$B21, ""), "", [1]DataLookUp!$B21) -> 25000000000018 | C21: =IF(EXACT(B21, ""), "", VLOOKUP(B21, [1]DataLookUp!$B$4:$C$1000, 2,FALSE )) -> Ahmad Faza | G21: =G20 + IF(EXACT(H21, ""), 0, 1) -> 32000000000018 | H21: =CONCATENATE("PERFORM ""SchData-OLTP-HumanResource"".""Func_TblWorker_SET""(varSystemLoginSession, null::bigint, null::varchar, null::timestamptz, null::timestamptz, null::varchar, varInstitutionBranchID, varBaseCurrencyID, ", B21, "::bigint, ", IF(EXACT(D21, ""), "null", CONCATENATE("'", D21, "'")), "::varchar);") -> PERFORM "SchData-OLTP-HumanResource"."Func_TblWorker_SET"(varSystemLoginSession, null::bigint, null::varchar, null::timestamptz, null::timestamptz, null::varchar, varInstitutionBranchID, varBaseCurrencyID, 25000000000018::bigint, null::varchar);
B22: =IF(EXACT([1]DataLookUp!$B22, ""), "", [1]DataLookUp!$B22) -> 25000000000019 | C22: =IF(EXACT(B22, ""), "", VLOOKUP(B22, [1]DataLookUp!$B$4:$C$1000, 2,FALSE )) -> Ahmad Syaifulloh | D22: 150506222 | E22: QDC | G22: =G21 + IF(EXACT(H22, ""), 0, 1) -> 32000000000019 | H22: =CONCATENATE("PERFORM ""SchData-OLTP-HumanResource"".""Func_TblWorker_SET""(varSystemLoginSession, null::bigint, null::varchar, null::timestamptz, null::timestamptz, null::varchar, varInstitutionBranchID, varBaseCurrencyID, ", B22, "::bigint, ", IF(EXACT(D22, ""), "null", CONCATENATE("'", D22, "'")), "::varchar);") -> PERFORM "SchData-OLTP-HumanResource"."Func_TblWorker_SET"(varSystemLoginSession, null::bigint, null::varchar, null::timestamptz, null::timestamptz, null::varchar, varInstitutionBranchID, varBaseCurrencyID, 25000000000019::bigint, '150506222'::varchar);
B23: =IF(EXACT([1]DataLookUp!$B23, ""), "", [1]DataLookUp!$B23) -> 25000000000020 | C23: =IF(EXACT(B23, ""), "", VLOOKUP(B23, [1]DataLookUp!$B$4:$C$1000, 2,FALSE )) -> Ahmad Zulkarnaen | G23: =G22 + IF(EXACT(H23, ""), 0, 1) -> 32000000000020 | H23: =CONCATENATE("PERFORM ""SchData-OLTP-HumanResource"".""Func_TblWorker_SET""(varSystemLoginSession, null::bigint, null::varchar, null::timestamptz, null::timestamptz, null::varchar, varInstitutionBranchID, varBaseCurrencyID, ", B23, "::bigint, ", IF(EXACT(D23, ""), "null", CONCATENATE("'", D23, "'")), "::varchar);") -> PERFORM "SchData-OLTP-HumanResource"."Func_TblWorker_SET"(varSystemLoginSession, null::bigint, null::varchar, null::timestamptz, null::timestamptz, null::varchar, varInstitutionBranchID, varBaseCurrencyID, 25000000000020::bigint, null::varchar);
B24: =IF(EXACT([1]DataLookUp!$B24, ""), "", [1]DataLookUp!$B24) -> 25000000000021 | C24: =IF(EXACT(B24, ""), "", VLOOKUP(B24, [1]DataLookUp!$B$4:$C$1000, 2,FALSE )) -> Ajan | G24: =G23 + IF(EXACT(H24, ""), 0, 1) -> 32000000000021 | H24: =CONCATENATE("PERFORM ""SchData-OLTP-HumanResource"".""Func_TblWorker_SET""(varSystemLoginSession, null::bigint, null::varchar, null::timestamptz, null::timestamptz, null::varchar, varInstitutionBranchID, varBaseCurrencyID, ", B24, "::bigint, ", IF(EXACT(D24, ""), "null", CONCATENATE("'", D24, "'")), "::varchar);") -> PERFORM "SchData-OLTP-HumanResource"."Func_TblWorker_SET"(varSystemLoginSession, null::bigint, null::varchar, null::timestamptz, null::timestamptz, null::varchar, varInstitutionBranchID, varBaseCurrencyID, 25000000000021::bigint, null::varchar);
B25: =IF(EXACT([1]DataLookUp!$B25, ""), "", [1]DataLookUp!$B25) -> 25000000000022 | C25: =IF(EXACT(B25, ""), "", VLOOKUP(B25, [1]DataLookUp!$B$4:$C$1000, 2,FALSE )) -> Al Amin | G25: =G24 + IF(EXACT(H25, ""), 0, 1) -> 32000000000022 | H25: =CONCATENATE("PERFORM ""SchData-OLTP-HumanResource"".""Func_TblWorker_SET""(varSystemLoginSession, null::bigint, null::varchar, null::timestamptz, null::timestamptz, null::varchar, varInstitutionBranchID, varBaseCurrencyID, ", B25, "::bigint, ", IF(EXACT(D25, ""), "null", CONCATENATE("'", D25, "'")), "::varchar);") -> PERFORM "SchData-OLTP-HumanResource"."Func_TblWorker_SET"(varSystemLoginSession, null::bigint, null::varchar, null::timestamptz, null::timestamptz, null::varchar, varInstitutionBranchID, varBaseCurrencyID, 25000000000022::bigint, null::varchar);
B26: =IF(EXACT([1]DataLookUp!$B26, ""), "", [1]DataLookUp!$B26) -> 25000000000023 | C26: =IF(EXACT(B26, ""), "", VLOOKUP(B26, [1]DataLookUp!$B$4:$C$1000, 2,FALSE )) -> Aldi Mulyadi | D26: 141020935 | E26: QDC | G26: =G25 + IF(EXACT(H26, ""), 0, 1) -> 32000000000023 | H26: =CONCATENATE("PERFORM ""SchData-OLTP-HumanResource"".""Func_TblWorker_SET""(varSystemLoginSession, null::bigint, null::varchar, null::timestamptz, null::timestamptz, null::varchar, varInstitutionBranchID, varBaseCurrencyID, ", B26, "::bigint, ", IF(EXACT(D26, ""), "null", CONCATENATE("'", D26, "'")), "::varchar);") -> PERFORM "SchData-OLTP-HumanResource"."Func_TblWorker_SET"(varSystemLoginSession, null::bigint, null::varchar, null::timestamptz, null::timestamptz, null::varchar, varInstitutionBranchID, varBaseCurrencyID, 25000000000023::bigint, '141020935'::varchar);
B27: =IF(EXACT([1]DataLookUp!$B27, ""), "", [1]DataLookUp!$B27) -> 25000000000024 | C27: =IF(EXACT(B27, ""), "", VLOOKUP(B27, [1]DataLookUp!$B$4:$C$1000, 2,FALSE )) -> Alexandri | G27: =G26 + IF(EXACT(H27, ""), 0, 1) -> 32000000000024 | H27: =CONCATENATE("PERFORM ""SchData-OLTP-HumanResource"".""Func_TblWorker_SET""(varSystemLoginSession, null::bigint, null::varchar, null::timestamptz, null::timestamptz, null::varchar, varInstitutionBranchID, varBaseCurrencyID, ", B27, "::bigint, ", IF(EXACT(D27, ""), "null", CONCATENATE("'", D27, "'")), "::varchar);") -> PERFORM "SchData-OLTP-HumanResource"."Func_TblWorker_SET"(varSystemLoginSession, null::bigint, null::varchar, null::timestamptz, null::timestamptz, null::varchar, varInstitutionBranchID, varBaseCurrencyID, 25000000000024::bigint, null::varchar);
B28: =IF(EXACT([1]DataLookUp!$B28, ""), "", [1]DataLookUp!$B28) -> 25000000000025 | C28: =IF(EXACT(B28, ""), "", VLOOKUP(B28, [1]DataLookUp!$B$4:$C$1000, 2,FALSE )) -> Alfaedi | G28: =G27 + IF(EXACT(H28, ""), 0, 1) -> 32000000000025 | H28: =CONCATENATE("PERFORM ""SchData-OLTP-HumanResource"".""Func_TblWorker_SET""(varSystemLoginSession, null::bigint, null::varchar, null::timestamptz, null::timestamptz, null::varchar, varInstitutionBranchID, varBaseCurrencyID, ", B28, "::bigint, ", IF(EXACT(D28, ""), "null", CONCATENATE("'", D28, "'")), "::varchar);") -> PERFORM "SchData-OLTP-HumanResource"."Func_TblWorker_SET"(varSystemLoginSession, null::bigint, null::varchar, null::timestamptz, null::timestamptz, null::varchar, varInstitutionBranchID, varBaseCurrencyID, 25000000000025::bigint, null::varchar);
B29: =IF(EXACT([1]DataLookUp!$B29, ""), "", [1]DataLookUp!$B29) -> 25000000000026 | C29: =IF(EXACT(B29, ""), "", VLOOKUP(B29, [1]DataLookUp!$B$4:$C$1000, 2,FALSE )) -> Ali Wahono | G29: =G28 + IF(EXACT(H29, ""), 0, 1) -> 32000000000026 | H29: =CONCATENATE("PERFORM ""SchData-OLTP-HumanResource"".""Func_TblWorker_SET""(varSystemLoginSession, null::bigint, null::varchar, null::timestamptz, null::timestamptz, null::varchar, varInstitutionBranchID, varBaseCurrencyID, ", B29, "::bigint, ", IF(EXACT(D29, ""), "null", CONCATENATE("'", D29, "'")), "::varchar);") -> PERFORM "SchData-OLTP-HumanResource"."Func_TblWorker_SET"(varSystemLoginSession, null::bigint, null::varchar, null::timestamptz, null::timestamptz, null::varchar, varInstitutionBranchID, varBaseCurrencyID, 25000000000026::bigint, null::varchar);
B30: =IF(EXACT([1]DataLookUp!$B30, ""), "", [1]DataLookUp!$B30) -> 25000000000027 | C30: =IF(EXACT(B30, ""), "", VLOOKUP(B30, [1]DataLookUp!$B$4:$C$1000, 2,FALSE )) -> Alphaliyanri Lasria | G30: =G29 + IF(EXACT(H30, ""), 0, 1) -> 32000000000027 | H30: =CONCATENATE("PERFORM ""SchData-OLTP-HumanResource"".""Func_TblWorker_SET""(varSystemLoginSession, null::bigint, null::varchar, null::timestamptz, null::timestamptz, null::varchar, varInstitutionBranchID, varBaseCurrencyID, ", B30, "::bigint, ", IF(EXACT(D30, ""), "null", CONCATENATE("'", D30, "'")), "::varchar);") -> PERFORM "SchData-OLTP-HumanResource"."Func_TblWorker_SET"(varSystemLoginSession, null::bigint, null::varchar, null::timestamptz, null::timestamptz, null::varchar, varInstitutionBranchID, varBaseCurrencyID, 25000000000027::bigint, null::varchar);
B31: =IF(EXACT([1]DataLookUp!$B31, ""), "", [1]DataLookUp!$B31) -> 25000000000028 | C31: =IF(EXACT(B31, ""), "", VLOOKUP(B31, [1]DataLookUp!$B$4:$C$1000, 2,FALSE )) -> Ambon Rumalean | G31: =G30 + IF(EXACT(H31, ""), 0, 1) -> 32000000000028 | H31: =CONCATENATE("PERFORM ""SchData-OLTP-HumanResource"".""Func_TblWorker_SET""(varSystemLoginSession, null::bigint, null::varchar, null::timestamptz, null::timestamptz, null::varchar, varInstitutionBranchID, varBaseCurrencyID, ", B31, "::bigint, ", IF(EXACT(D31, ""), "null", CONCATENATE("'", D31, "'")), "::varchar);") -> PERFORM "SchData-OLTP-HumanResource"."Func_TblWorker_SET"(varSystemLoginSession, null::bigint, null::varchar, null::timestamptz, null::timestamptz, null::varchar, varInstitutionBranchID, varBaseCurrencyID, 25000000000028::bigint, null::varchar);
B32: =IF(EXACT([1]DataLookUp!$B32, ""), "", [1]DataLookUp!$B32) -> 25000000000029 | C32: =IF(EXACT(B32, ""), "", VLOOKUP(B32, [1]DataLookUp!$B$4:$C$1000, 2,FALSE )) -> Amir Sofyan Hadi | G32: =G31 + IF(EXACT(H32, ""), 0, 1) -> 32000000000029 | H32: =CONCATENATE("PERFORM ""SchData-OLTP-HumanResource"".""Func_TblWorker_SET""(varSystemLoginSession, null::bigint, null::varchar, null::timestamptz, null::timestamptz, null::varchar, varInstitutionBranchID, varBaseCurrencyID, ", B32, "::bigint, ", IF(EXACT(D32, ""), "null", CONCATENATE("'", D32, "'")), "::varchar);") -> PERFORM "SchData-OLTP-HumanResource"."Func_TblWorker_SET"(varSystemLoginSession, null::bigint, null::varchar, null::timestamptz, null::timestamptz, null::varchar, varInstitutionBranchID, varBaseCurrencyID, 25000000000029::bigint, null::varchar);
B33: =IF(EXACT([1]DataLookUp!$B33, ""), "", [1]DataLookUp!$B33) -> 25000000000030 | C33: =IF(EXACT(B33, ""), "", VLOOKUP(B33, [1]DataLookUp!$B$4:$C$1000, 2,FALSE )) -> Anak Agung Netti Ariani | G33: =G32 + IF(EXACT(H33, ""), 0, 1) -> 32000000000030 | H33: =CONCATENATE("PERFORM ""SchData-OLTP-HumanResource"".""Func_TblWorker_SET""(varSystemLoginSession, null::bigint, null::varchar, null::timestamptz, null::timestamptz, null::varchar, varInstitutionBranchID, varBaseCurrencyID, ", B33, "::bigint, ", IF(EXACT(D33, ""), "null", CONCATENATE("'", D33, "'")), "::varchar);") -> PERFORM "SchData-OLTP-HumanResource"."Func_TblWorker_SET"(varSystemLoginSession, null::bigint, null::varchar, null::timestamptz, null::timestamptz, null::varchar, varInstitutionBranchID, varBaseCurrencyID, 25000000000030::bigint, null::varchar);
B34: =IF(EXACT([1]DataLookUp!$B34, ""), "", [1]DataLookUp!$B34) -> 25000000000031 | C34: =IF(EXACT(B34, ""), "", VLOOKUP(B34, [1]DataLookUp!$B$4:$C$1000, 2,FALSE )) -> Andri Gunawan | G34: =G33 + IF(EXACT(H34, ""), 0, 1) -> 32000000000031 | H34: =CONCATENATE("PERFORM ""SchData-OLTP-HumanResource"".""Func_TblWorker_SET""(varSystemLoginSession, null::bigint, null::varchar, null::timestamptz, null::timestamptz, null::varchar, varInstitutionBranchID, varBaseCurrencyID, ", B34, "::bigint, ", IF(EXACT(D34, ""), "null", CONCATENATE("'", D34, "'")), "::varchar);") -> PERFORM "SchData-OLTP-HumanResource"."Func_TblWorker_SET"(varSystemLoginSession, null::bigint, null::varchar, null::timestamptz, null::timestamptz, null::varchar, varInstitutionBranchID, varBaseCurrencyID, 25000000000031::bigint, null::varchar);
B35: =IF(EXACT([1]DataLookUp!$B35, ""), "", [1]DataLookUp!$B35) -> 25000000000032 | C35: =IF(EXACT(B35, ""), "", VLOOKUP(B35, [1]DataLookUp!$B$4:$C$1000, 2,FALSE )) -> Andri Herdiansyah | G35: =G34 + IF(EXACT(H35, ""), 0, 1) -> 32000000000032 | H35: =CONCATENATE("PERFORM ""SchData-OLTP-HumanResource"".""Func_TblWorker_SET""(varSystemLoginSession, null::bigint, null::varchar, null::timestamptz, null::timestamptz, null::varchar, varInstitutionBranchID, varBaseCurrencyID, ", B35, "::bigint, ", IF(EXACT(D35, ""), "null", CONCATENATE("'", D35, "'")), "::varchar);") -> PERFORM "SchData-OLTP-HumanResource"."Func_TblWorker_SET"(varSystemLoginSession, null::bigint, null::varchar, null::timestamptz, null::timestamptz, null::varchar, varInstitutionBranchID, varBaseCurrencyID, 25000000000032::bigint, null::varchar);
B36: =IF(EXACT([1]DataLookUp!$B36, ""), "", [1]DataLookUp!$B36) -> 25000000000033 | C36: =IF(EXACT(B36, ""), "", VLOOKUP(B36, [1]DataLookUp!$B$4:$C$1000, 2,FALSE )) -> Andrie | G36: =G35 + IF(EXACT(H36, ""), 0, 1) -> 32000000000033 | H36: =CONCATENATE("PERFORM ""SchData-OLTP-HumanResource"".""Func_TblWorker_SET""(varSystemLoginSession, null::bigint, null::varchar, null::timestamptz, null::timestamptz, null::varchar, varInstitutionBranchID, varBaseCurrencyID, ", B36, "::bigint, ", IF(EXACT(D36, ""), "null", CONCATENATE("'", D36, "'")), "::varchar);") -> PERFORM "SchData-OLTP-HumanResource"."Func_TblWorker_SET"(varSystemLoginSession, null::bigint, null::varchar, null::timestamptz, null::timestamptz, null::varchar, varInstitutionBranchID, varBaseCurrencyID, 25000000000033::bigint, null::varchar);
B37: =IF(EXACT([1]DataLookUp!$B37, ""), "", [1]DataLookUp!$B37) -> 25000000000034 | C37: =IF(EXACT(B37, ""), "", VLOOKUP(B37, [1]DataLookUp!$B$4:$C$1000, 2,FALSE )) -> Anggina Tri Yudandi | G37: =G36 + IF(EXACT(H37, ""), 0, 1) -> 32000000000034 | H37: =CONCATENATE("PERFORM ""SchData-OLTP-HumanResource"".""Func_TblWorker_SET""(varSystemLoginSession, null::bigint, null::varchar, null::timestamptz, null::timestamptz, null::varchar, varInstitutionBranchID, varBaseCurrencyID, ", B37, "::bigint, ", IF(EXACT(D37, ""), "null", CONCATENATE("'", D37, "'")), "::varchar);") -> PERFORM "SchData-OLTP-HumanResource"."Func_TblWorker_SET"(varSystemLoginSession, null::bigint, null::varchar, null::timestamptz, null::timestamptz, null::varchar, varInstitutionBranchID, varBaseCurrencyID, 25000000000034::bigint, null::varchar);
B38: =IF(EXACT([1]DataLookUp!$B38, ""), "", [1]DataLookUp!$B38) -> 25000000000035 | C38: =IF(EXACT(B38, ""), "", VLOOKUP(B38, [1]DataLookUp!$B$4:$C$1000, 2,FALSE )) -> Anggit Ismiyanto | G38: =G37 + IF(EXACT(H38, ""), 0, 1) -> 32000000000035 | H38: =CONCATENATE("PERFORM ""SchData-OLTP-HumanResource"".""Func_TblWorker_SET""(varSystemLoginSession, null::bigint, null::varchar, null::timestamptz, null::timestamptz, null::varchar, varInstitutionBranchID, varBaseCurrencyID, ", B38, "::bigint, ", IF(EXACT(D38, ""), "null", CONCATENATE("'", D38, "'")), "::varchar);") -> PERFORM "SchData-OLTP-HumanResource"."Func_TblWorker_SET"(varSystemLoginSession, null::bigint, null::varchar, null::timestamptz, null::timestamptz, null::varchar, varInstitutionBranchID, varBaseCurrencyID, 25000000000035::bigint, null::varchar);
... B41: =IF(EXACT([1]DataLookUp!$B41, ""), "", [1]DataLookUp!$B41) -> 25000000000038 | C41: =IF(EXACT(B41, ""), "", VLOOKUP(B41, [1]DataLookUp!$B$4:$C$1000, 2,FALSE )) -> Anna Savitrie | G41: =G40 + IF(EXACT(H41, ""), 0, 1) -> 32000000000038 | H41: =CONCATENATE("PERFORM ""SchData-OLTP-HumanResource"".""Func_TblWorker_SET""(varSystemLoginSession, null::bigint, null::varchar, null::timestamptz, null::timestamptz, null::varchar, varInstitutionBranchID, varBaseCurrencyID, ", B41, "::bigint, ", IF(EXACT(D41, ""), "null", CONCATENATE("'", D41, "'")), "::varchar);") -> PERFORM "SchData-OLTP-HumanResource"."Func_TblWorker_SET"(varSystemLoginSession, null::bigint, null::varchar, null::timestamptz, null::timestamptz, null::varchar, varInstitutionBranchID, varBaseCurrencyID, 25000000000038::bigint, null::varchar);
B42: =IF(EXACT([1]DataLookUp!$B42, ""), "", [1]DataLookUp!$B42) -> 25000000000039 | C42: =IF(EXACT(B42, ""), "", VLOOKUP(B42, [1]DataLookUp!$B$4:$C$1000, 2,FALSE )) -> Annisa Dewi Arumsari | D42: 100419903 | E42: QDC | G42: =G41 + IF(EXACT(H42, ""), 0, 1) -> 32000000000039 | H42: =CONCATENATE("PERFORM ""SchData-OLTP-HumanResource"".""Func_TblWorker_SET""(varSystemLoginSession, null::bigint, null::varchar, null::timestamptz, null::timestamptz, null::varchar, varInstitutionBranchID, varBaseCurrencyID, ", B42, "::bigint, ", IF(EXACT(D42, ""), "null", CONCATENATE("'", D42, "'")), "::varchar);") -> PERFORM "SchData-OLTP-HumanResource"."Func_TblWorker_SET"(varSystemLoginSession, null::bigint, null::varchar, null::timestamptz, null::timestamptz, null::varchar, varInstitutionBranchID, varBaseCurrencyID, 25000000000039::bigint, '100419903'::varchar);
B43: =IF(EXACT([1]DataLookUp!$B43, ""), "", [1]DataLookUp!$B43) -> 25000000000040 | C43: =IF(EXACT(B43, ""), "", VLOOKUP(B43, [1]DataLookUp!$B$4:$C$1000, 2,FALSE )) -> Annyes Sri Maristi | G43: =G42 + IF(EXACT(H43, ""), 0, 1) -> 32000000000040 | H43: =CONCATENATE("PERFORM ""SchData-OLTP-HumanResource"".""Func_TblWorker_SET""(varSystemLoginSession, null::bigint, null::varchar, null::timestamptz, null::timestamptz, null::varchar, varInstitutionBranchID, varBaseCurrencyID, ", B43, "::bigint, ", IF(EXACT(D43, ""), "null", CONCATENATE("'", D43, "'")), "::varchar);") -> PERFORM "SchData-OLTP-HumanResource"."Func_TblWorker_SET"(varSystemLoginSession, null::bigint, null::varchar, null::timestamptz, null::timestamptz, null::varchar, varInstitutionBranchID, varBaseCurrencyID, 25000000000040::bigint, null::varchar);
...

Sheet DataLookUp
B2: SYS_PID | C2: =MAIN!B2 -> Ref ID Person | D2: =MAIN!C2 -> Person Name | E2: =MAIN!D2 -> Nomor Induk Pekerja
B4: =IF(EXACT(MAIN!$H4, ""), "", MAIN!$G4) -> 32000000000001 | C4: =IF(EXACT(MAIN!$H4, ""), "", MAIN!$B4) -> 25000000000001 | D4: =IF(EXACT(MAIN!$H4, ""), "", MAIN!$C4) -> Abdollah Syani Siregar | E4: =IF(EXACT(MAIN!$B4, ""), "", ""&MAIN!$D4) | G4: =C4 -> 25000000000001
B5: =IF(EXACT(MAIN!$H5, ""), "", MAIN!$G5) -> 32000000000002 | C5: =IF(EXACT(MAIN!$H5, ""), "", MAIN!$B5) -> 25000000000002 | D5: =IF(EXACT(MAIN!$H5, ""), "", MAIN!$C5) -> Abdul Karim | E5: =IF(EXACT(MAIN!$B5, ""), "", ""&MAIN!$D5) | G5: =C5 -> 25000000000002
B6: =IF(EXACT(MAIN!$H6, ""), "", MAIN!$G6) -> 32000000000003 | C6: =IF(EXACT(MAIN!$H6, ""), "", MAIN!$B6) -> 25000000000003 | D6: =IF(EXACT(MAIN!$H6, ""), "", MAIN!$C6) -> Abdul Rahman Sitompul | E6: =IF(EXACT(MAIN!$B6, ""), "", ""&MAIN!$D6) | G6: =C6 -> 25000000000003
B7: =IF(EXACT(MAIN!$H7, ""), "", MAIN!$G7) -> 32000000000004 | C7: =IF(EXACT(MAIN!$H7, ""), "", MAIN!$B7) -> 25000000000004 | D7: =IF(EXACT(MAIN!$H7, ""), "", MAIN!$C7) -> Abdul Risan | E7: =IF(EXACT(MAIN!$B7, ""), "", ""&MAIN!$D7) | G7: =C7 -> 25000000000004
B8: =IF(EXACT(MAIN!$H8, ""), "", MAIN!$G8) -> 32000000000005 | C8: =IF(EXACT(MAIN!$H8, ""), "", MAIN!$B8) -> 25000000000005 | D8: =IF(EXACT(MAIN!$H8, ""), "", MAIN!$C8) -> Abdullah Nabil | E8: =IF(EXACT(MAIN!$B8, ""), "", ""&MAIN!$D8) | G8: =C8 -> 25000000000005
B9: =IF(EXACT(MAIN!$H9, ""), "", MAIN!$G9) -> 32000000000006 | C9: =IF(EXACT(MAIN!$H9, ""), "", MAIN!$B9) -> 25000000000006 | D9: =IF(EXACT(MAIN!$H9, ""), "", MAIN!$C9) -> Adhitya Danar | E9: =IF(EXACT(MAIN!$B9, ""), "", ""&MAIN!$D9) | G9: =C9 -> 25000000000006
B10: =IF(EXACT(MAIN!$H10, ""), "", MAIN!$G10) -> 32000000000007 | C10: =IF(EXACT(MAIN!$H10, ""), "", MAIN!$B10) -> 25000000000007 | D10: =IF(EXACT(MAIN!$H10, ""), "", MAIN!$C10) -> Adi Ruswandi | E10: =IF(EXACT(MAIN!$B10, ""), "", ""&MAIN!$D10) -> 0209251009 | G10: =C10 -> 25000000000007
B11: =IF(EXACT(MAIN!$H11, ""), "", MAIN!$G11) -> 32000000000008 | C11: =IF(EXACT(MAIN!$H11, ""), "", MAIN!$B11) -> 25000000000008 | D11: =IF(EXACT(MAIN!$H11, ""), "", MAIN!$C11) -> Adietya Dharmawan | E11: =IF(EXACT(MAIN!$B11, ""), "", ""&MAIN!$D11) -> 050321947 | G11: =C11 -> 25000000000008
B12: =IF(EXACT(MAIN!$H12, ""), "", MAIN!$G12) -> 32000000000009 | C12: =IF(EXACT(MAIN!$H12, ""), "", MAIN!$B12) -> 25000000000009 | D12: =IF(EXACT(MAIN!$H12, ""), "", MAIN!$C12) -> Aditya Yudha Prawira | E12: =IF(EXACT(MAIN!$B12, ""), "", ""&MAIN!$D12) | G12: =C12 -> 25000000000009
B13: =IF(EXACT(MAIN!$H13, ""), "", MAIN!$G13) -> 32000000000010 | C13: =IF(EXACT(MAIN!$H13, ""), "", MAIN!$B13) -> 25000000000010 | D13: =IF(EXACT(MAIN!$H13, ""), "", MAIN!$C13) -> Adli Margie | E13: =IF(EXACT(MAIN!$B13, ""), "", ""&MAIN!$D13) | G13: =C13 -> 25000000000010
B14: =IF(EXACT(MAIN!$H14, ""), "", MAIN!$G14) -> 32000000000011 | C14: =IF(EXACT(MAIN!$H14, ""), "", MAIN!$B14) -> 25000000000011 | D14: =IF(EXACT(MAIN!$H14, ""), "", MAIN!$C14) -> Afrida Eka Putri | E14: =IF(EXACT(MAIN!$B14, ""), "", ""&MAIN!$D14) | G14: =C14 -> 25000000000011
B15: =IF(EXACT(MAIN!$H15, ""), "", MAIN!$G15) -> 32000000000012 | C15: =IF(EXACT(MAIN!$H15, ""), "", MAIN!$B15) -> 25000000000012 | D15: =IF(EXACT(MAIN!$H15, ""), "", MAIN!$C15) -> Agnes Sutedja | E15: =IF(EXACT(MAIN!$B15, ""), "", ""&MAIN!$D15) -> 010703020 | G15: =C15 -> 25000000000012
... B617: =IF(EXACT(MAIN!$H617, ""), "", MAIN!$G617) -> 32000000000614 | C617: =IF(EXACT(MAIN!$H617, ""), "", MAIN!$B617) -> 25000000000614 | D617: =IF(EXACT(MAIN!$H617, ""), "", MAIN!$C617) -> Timotius Tabun | E617: =IF(EXACT(MAIN!$B617, ""), "", ""&MAIN!$D617) -> 300913696 | G617: =C617 -> 25000000000614
B618: =IF(EXACT(MAIN!$H618, ""), "", MAIN!$G618) -> 32000000000615 | C618: =IF(EXACT(MAIN!$H618, ""), "", MAIN!$B618) -> 25000000000615 | D618: =IF(EXACT(MAIN!$H618, ""), "", MAIN!$C618) -> Adi | E618: =IF(EXACT(MAIN!$B618, ""), "", ""&MAIN!$D618) -> 0209251009
B619: =IF(EXACT(MAIN!$H619, ""), "", MAIN!$G619) -> 32000000000616 | C619: =IF(EXACT(MAIN!$H619, ""), "", MAIN!$B619) -> 25000000000616 | D619: =IF(EXACT(MAIN!$H619, ""), "", MAIN!$C619) -> Andrean Fahrizi | E619: =IF(EXACT(MAIN!$B619, ""), "", ""&MAIN!$D619)
B620: =IF(EXACT(MAIN!$H620, ""), "", MAIN!$G620) -> 32000000000617 | C620: =IF(EXACT(MAIN!$H620, ""), "", MAIN!$B620) -> 25000000000617 | D620: =IF(EXACT(MAIN!$H620, ""), "", MAIN!$C620) -> Amar Abdilah | E620: =IF(EXACT(MAIN!$B620, ""), "", ""&MAIN!$D620)
B621: =IF(EXACT(MAIN!$H621, ""), "", MAIN!$G621) -> 32000000000618 | C621: =IF(EXACT(MAIN!$H621, ""), "", MAIN!$B621) -> 25000000000618 | D621: =IF(EXACT(MAIN!$H621, ""), "", MAIN!$C621) -> Heru Indra Permana | E621: =IF(EXACT(MAIN!$B621, ""), "", ""&MAIN!$D621)
B622: =IF(EXACT(MAIN!$H622, ""), "", MAIN!$G622) -> 32000000000619 | C622: =IF(EXACT(MAIN!$H622, ""), "", MAIN!$B622) -> 25000000000619 | D622: =IF(EXACT(MAIN!$H622, ""), "", MAIN!$C622) -> Budi Santosa (KSO) | E622: =IF(EXACT(MAIN!$B622, ""), "", ""&MAIN!$D622)
B623: =IF(EXACT(MAIN!$H623, ""), "", MAIN!$G623) -> 32000000000620 | C623: =IF(EXACT(MAIN!$H623, ""), "", MAIN!$B623) -> 25000000000620 | D623: =IF(EXACT(MAIN!$H623, ""), "", MAIN!$C623) -> Haryono | E623: =IF(EXACT(MAIN!$B623, ""), "", ""&MAIN!$D623)
B624: =IF(EXACT(MAIN!$H624, ""), "", MAIN!$G624) -> 32000000000621 | C624: =IF(EXACT(MAIN!$H624, ""), "", MAIN!$B624) -> 25000000000621 | D624: =IF(EXACT(MAIN!$H624, ""), "", MAIN!$C624) -> Indah Sri Rejeki | E624: =IF(EXACT(MAIN!$B624, ""), "", ""&MAIN!$D624)
B625: =IF(EXACT(MAIN!$H626, ""), "", MAIN!$G626) | C625: =IF(EXACT(MAIN!$H626, ""), "", MAIN!$B626) | D625: =IF(EXACT(MAIN!$H626, ""), "", MAIN!$C626) | E625: =IF(EXACT(MAIN!$B626, ""), "", ""&MAIN!$D626)

Sheet MAIN - OrgJobsPos
B2: 160000000000001 | C2: Clerical | D2: 9
B3: 160000000000002 | C3: Senior Clerical | D3: 8
B4: 160000000000003 | C4: Staff | D4: 7
B5: 160000000000004 | C5: Supervisor | D5: 6
B6: 160000000000005 | C6: Senior Supervisor | D6: 5
B7: 160000000000006 | C7: Manager | D7: 4
B8: 160000000000007 | C8: Senior Manager | D8: 3
B9: 160000000000008 | C9: General Manager | D9: 2
B10: 160000000000009 | C10: Director | D10: 1

Sheet MAIN - OrgDepartment
A3: QDC | B3: 11000000000004 | C3: 111000000000001 | D3: Non Department
B4: 11000000000004 | C4: 111000000000002 | D4: Business Development
B5: 11000000000004 | C5: 111000000000003 | D5: Information Technology
B6: 11000000000004 | C6: 111000000000004 | D6: Sales & Marketing
B7: 11000000000004 | C7: 111000000000005 | D7: Finance & Accounting
B8: 11000000000004 | C8: 111000000000006 | D8: Human Resource Development
B9: 11000000000004 | C9: 111000000000007 | D9: Health Safety Environment
B10: 11000000000004 | C10: 111000000000008 | D10: Logistics & Warehouse
B11: 11000000000004 | C11: 111000000000009 | D11: Legal
B12: 11000000000004 | C12: 111000000000010 | D12: Tools & Asset Management
B13: 11000000000004 | C13: 111000000000011 | D13: Project
B14: 11000000000004 | C14: 111000000000012 | D14: Procurement
B15: 11000000000004 | C15: 111000000000013 | D15: Civil And Mechanical Engineering
... B19: 11000000000004 | C19: 111000000000017 | D19: Estimator
A20: IMD | B20: 11000000000007 | C20: 111000000000018 | D20: Non Department
B21: 11000000000007 | C21: 111000000000019 | D21: Operation & Business Development
B22: 11000000000007 | C22: 111000000000020 | D22: Business Development
B23: 11000000000007 | C23: 111000000000021 | D23: Finance & Accounting
B24: 11000000000007 | C24: 111000000000022 | D24: Sales
B25: 11000000000007 | C25: 111000000000023 | D25: Operation & Maintenance
B26: 11000000000007 | C26: 111000000000024 | D26: Warehouse & TAM
G28: Maintenance Building & Technician
G29: Security
G30: Driver
G31: Driver Operational & Ops Truck Crane
G32: Office Boy
G33: Warehouse & Stringing Machine Operator
G34: Mechanic & Maintenance
G35: Warehouse

Sheet Internal Career (Last Position)
B2: Ref ID Worker | C2: =DataLookUp!D2 -> Person Name | D2: Ref ID Worker Type | E2: Worker Type Name | F2: Ref ID Organizational Department | G2: Organizational Department Name | H2: Ref ID Organizational Job Position | I2: Organizational Job Position Name | J2: Job Title | K2: Valid Start DateTimeTZ | L2: Valid Finish DateTimeTZ | M2: Ref ID Document Employment Relationship | O2: SYS_PID Prediction | P2: SQL Syntax
O3: 164000000000000
B4: =IF(EXACT(DataLookUp!$B4, ""), "", DataLookUp!$B4) -> 32000000000001 | C4: =IF(EXACT(DataLookUp!$B4, ""), "", DataLookUp!$D4) -> Abdollah Syani Siregar | D4: 163000000000003 | E4: =IF(EXACT($D4, ""), "", VLOOKUP($D4, [2]DataLookUp!$B$4:$D$15, 2, FALSE )) -> Karyawan Tidak Tetap (Kontrak) | G4: =IF(EXACT($F4, ""), "", VLOOKUP($F4, 'MAIN - OrgDepartment'!$C$3:$D$104, 2, FALSE)) | I4: =IF(EXACT($H4, ""), "", VLOOKUP($H4, 'MAIN - OrgJobsPos'!$B$2:$C$101, 2, FALSE)) | L4: 1900-12-31 23:59:59+07 | O4: =O3 + IF(EXACT(P4, ""), 0, 1) -> 164000000000001 | P4: =CONCATENATE("PERFORM ""SchData-OLTP-HumanResource"".""Func_TblWorkerCareerInternal_SET""(varSystemLoginSession, null::bigint, null::varchar", CONCATENATE(IF(EXACT($K4, ""), ", null", CONCATENATE(", '", $K4, "'")), "::timestamptz"), CONCATENATE(IF(EXACT($L4, ""), ", null", CONCATENATE(", '", $L4, "'")), "::timestamptz"), ", null::varchar, varInstitutionBranchID, varBaseCurrencyID", CONCATENATE(IF(EXACT($B4, ""), ", null", CONCATENATE(", ", $B4, "")), "::bigint"), CONCATENATE(IF(EXACT($D4, ""), ", null", CONCATENATE(", ", $D4, "")), "::bigint"), CONCATENATE(IF(EXACT($F4, ""), ", null", CONCATENATE(", ", $F4, "")), "::bigint"), CONCATENATE(IF(EXACT($H4, ""), ", null", CONCATENATE(", ", $H4, "")), "::bigint"), CONCATENATE(IF(EXACT($J4, ""), ", null", CONCATENATE(", '", $J4, "'")), "::varchar"), CONCATENATE(IF(EXACT($K4, ""), ", null", CONCATENATE(", '", $K4, "'")), "::timestamptz"), CONCATENATE(IF(EXACT($L4, ""), ", null", CONCATENATE(", '", $L4, "'")), "::timestamptz"), CONCATENATE(IF(EXACT($M4, ""), ", null", CONCATENATE(", ", $M4, "")), "::bigint"), ");") -> PERFORM "SchData-OLTP-HumanResource"."Func_TblWorkerCareerInternal_SET"(varSystemLoginSession, null::bigint, null::varchar, null::timestamptz, '1900-12-31 23:59:59+07'::timestamptz, null::varchar, varInstitutionBranchID, varBaseCurrencyID, 32000000000001::bigint, 163000000000003::bigint, null::bigint, null::bigint, null::varchar, null::timestamptz, '1900-12-31 23:59:59+07'::timestamptz, null::bigint);
B5: =IF(EXACT(DataLookUp!$B5, ""), "", DataLookUp!$B5) -> 32000000000002 | C5: =MAIN!C5 -> Abdul Karim | D5: 163000000000003 | E5: =IF(EXACT($D5, ""), "", VLOOKUP($D5, [2]DataLookUp!$B$4:$D$15, 2, FALSE )) -> Karyawan Tidak Tetap (Kontrak) | G5: =IF(EXACT($F5, ""), "", VLOOKUP($F5, 'MAIN - OrgDepartment'!$C$3:$D$104, 2, FALSE)) | I5: =IF(EXACT($H5, ""), "", VLOOKUP($H5, 'MAIN - OrgJobsPos'!$B$2:$C$101, 2, FALSE)) | L5: 1900-12-31 23:59:59+07 | O5: =O4 + IF(EXACT(P5, ""), 0, 1) -> 164000000000002 | P5: =CONCATENATE("PERFORM ""SchData-OLTP-HumanResource"".""Func_TblWorkerCareerInternal_SET""(varSystemLoginSession, null::bigint, null::varchar", CONCATENATE(IF(EXACT($K5, ""), ", null", CONCATENATE(", '", $K5, "'")), "::timestamptz"), CONCATENATE(IF(EXACT($L5, ""), ", null", CONCATENATE(", '", $L5, "'")), "::timestamptz"), ", null::varchar, varInstitutionBranchID, varBaseCurrencyID", CONCATENATE(IF(EXACT($B5, ""), ", null", CONCATENATE(", ", $B5, "")), "::bigint"), CONCATENATE(IF(EXACT($D5, ""), ", null", CONCATENATE(", ", $D5, "")), "::bigint"), CONCATENATE(IF(EXACT($F5, ""), ", null", CONCATENATE(", ", $F5, "")), "::bigint"), CONCATENATE(IF(EXACT($H5, ""), ", null", CONCATENATE(", ", $H5, "")), "::bigint"), CONCATENATE(IF(EXACT($J5, ""), ", null", CONCATENATE(", '", $J5, "'")), "::varchar"), CONCATENATE(IF(EXACT($K5, ""), ", null", CONCATENATE(", '", $K5, "'")), "::timestamptz"), CONCATENATE(IF(EXACT($L5, ""), ", null", CONCATENATE(", '", $L5, "'")), "::timestamptz"), CONCATENATE(IF(EXACT($M5, ""), ", null", CONCATENATE(", ", $M5, "")), "::bigint"), ");") -> PERFORM "SchData-OLTP-HumanResource"."Func_TblWorkerCareerInternal_SET"(varSystemLoginSession, null::bigint, null::varchar, null::timestamptz, '1900-12-31 23:59:59+07'::timestamptz, null::varchar, varInstitutionBranchID, varBaseCurrencyID, 32000000000002::bigint, 163000000000003::bigint, null::bigint, null::bigint, null::varchar, null::timestamptz, '1900-12-31 23:59:59+07'::timestamptz, null::bigint);
B6: =IF(EXACT(DataLookUp!$B6, ""), "", DataLookUp!$B6) -> 32000000000003 | C6: =MAIN!C6 -> Abdul Rahman Sitompul | D6: 163000000000003 | E6: =IF(EXACT($D6, ""), "", VLOOKUP($D6, [2]DataLookUp!$B$4:$D$15, 2, FALSE )) -> Karyawan Tidak Tetap (Kontrak) | G6: =IF(EXACT($F6, ""), "", VLOOKUP($F6, 'MAIN - OrgDepartment'!$C$3:$D$104, 2, FALSE)) | I6: =IF(EXACT($H6, ""), "", VLOOKUP($H6, 'MAIN - OrgJobsPos'!$B$2:$C$101, 2, FALSE)) | L6: 1900-12-31 23:59:59+07 | O6: =O5 + IF(EXACT(P6, ""), 0, 1) -> 164000000000003 | P6: =CONCATENATE("PERFORM ""SchData-OLTP-HumanResource"".""Func_TblWorkerCareerInternal_SET""(varSystemLoginSession, null::bigint, null::varchar", CONCATENATE(IF(EXACT($K6, ""), ", null", CONCATENATE(", '", $K6, "'")), "::timestamptz"), CONCATENATE(IF(EXACT($L6, ""), ", null", CONCATENATE(", '", $L6, "'")), "::timestamptz"), ", null::varchar, varInstitutionBranchID, varBaseCurrencyID", CONCATENATE(IF(EXACT($B6, ""), ", null", CONCATENATE(", ", $B6, "")), "::bigint"), CONCATENATE(IF(EXACT($D6, ""), ", null", CONCATENATE(", ", $D6, "")), "::bigint"), CONCATENATE(IF(EXACT($F6, ""), ", null", CONCATENATE(", ", $F6, "")), "::bigint"), CONCATENATE(IF(EXACT($H6, ""), ", null", CONCATENATE(", ", $H6, "")), "::bigint"), CONCATENATE(IF(EXACT($J6, ""), ", null", CONCATENATE(", '", $J6, "'")), "::varchar"), CONCATENATE(IF(EXACT($K6, ""), ", null", CONCATENATE(", '", $K6, "'")), "::timestamptz"), CONCATENATE(IF(EXACT($L6, ""), ", null", CONCATENATE(", '", $L6, "'")), "::timestamptz"), CONCATENATE(IF(EXACT($M6, ""), ", null", CONCATENATE(", ", $M6, "")), "::bigint"), ");") -> PERFORM "SchData-OLTP-HumanResource"."Func_TblWorkerCareerInternal_SET"(varSystemLoginSession, null::bigint, null::varchar, null::timestamptz, '1900-12-31 23:59:59+07'::timestamptz, null::varchar, varInstitutionBranchID, varBaseCurrencyID, 32000000000003::bigint, 163000000000003::bigint, null::bigint, null::bigint, null::varchar, null::timestamptz, '1900-12-31 23:59:59+07'::timestamptz, null::bigint);
B7: =IF(EXACT(DataLookUp!$B7, ""), "", DataLookUp!$B7) -> 32000000000004 | C7: =MAIN!C7 -> Abdul Risan | D7: 163000000000003 | E7: =IF(EXACT($D7, ""), "", VLOOKUP($D7, [2]DataLookUp!$B$4:$D$15, 2, FALSE )) -> Karyawan Tidak Tetap (Kontrak) | G7: =IF(EXACT($F7, ""), "", VLOOKUP($F7, 'MAIN - OrgDepartment'!$C$3:$D$104, 2, FALSE)) | I7: =IF(EXACT($H7, ""), "", VLOOKUP($H7, 'MAIN - OrgJobsPos'!$B$2:$C$101, 2, FALSE)) | L7: 1900-12-31 23:59:59+07 | O7: =O6 + IF(EXACT(P7, ""), 0, 1) -> 164000000000004 | P7: =CONCATENATE("PERFORM ""SchData-OLTP-HumanResource"".""Func_TblWorkerCareerInternal_SET""(varSystemLoginSession, null::bigint, null::varchar", CONCATENATE(IF(EXACT($K7, ""), ", null", CONCATENATE(", '", $K7, "'")), "::timestamptz"), CONCATENATE(IF(EXACT($L7, ""), ", null", CONCATENATE(", '", $L7, "'")), "::timestamptz"), ", null::varchar, varInstitutionBranchID, varBaseCurrencyID", CONCATENATE(IF(EXACT($B7, ""), ", null", CONCATENATE(", ", $B7, "")), "::bigint"), CONCATENATE(IF(EXACT($D7, ""), ", null", CONCATENATE(", ", $D7, "")), "::bigint"), CONCATENATE(IF(EXACT($F7, ""), ", null", CONCATENATE(", ", $F7, "")), "::bigint"), CONCATENATE(IF(EXACT($H7, ""), ", null", CONCATENATE(", ", $H7, "")), "::bigint"), CONCATENATE(IF(EXACT($J7, ""), ", null", CONCATENATE(", '", $J7, "'")), "::varchar"), CONCATENATE(IF(EXACT($K7, ""), ", null", CONCATENATE(", '", $K7, "'")), "::timestamptz"), CONCATENATE(IF(EXACT($L7, ""), ", null", CONCATENATE(", '", $L7, "'")), "::timestamptz"), CONCATENATE(IF(EXACT($M7, ""), ", null", CONCATENATE(", ", $M7, "")), "::bigint"), ");") -> PERFORM "SchData-OLTP-HumanResource"."Func_TblWorkerCareerInternal_SET"(varSystemLoginSession, null::bigint, null::varchar, null::timestamptz, '1900-12-31 23:59:59+07'::timestamptz, null::varchar, varInstitutionBranchID, varBaseCurrencyID, 32000000000004::bigint, 163000000000003::bigint, null::bigint, null::bigint, null::varchar, null::timestamptz, '1900-12-31 23:59:59+07'::timestamptz, null::bigint);
B8: =IF(EXACT(DataLookUp!$B8, ""), "", DataLookUp!$B8) -> 32000000000005 | C8: =MAIN!C8 -> Abdullah Nabil | D8: 163000000000003 | E8: =IF(EXACT($D8, ""), "", VLOOKUP($D8, [2]DataLookUp!$B$4:$D$15, 2, FALSE )) -> Karyawan Tidak Tetap (Kontrak) | G8: =IF(EXACT($F8, ""), "", VLOOKUP($F8, 'MAIN - OrgDepartment'!$C$3:$D$104, 2, FALSE)) | I8: =IF(EXACT($H8, ""), "", VLOOKUP($H8, 'MAIN - OrgJobsPos'!$B$2:$C$101, 2, FALSE)) | L8: 1900-12-31 23:59:59+07 | O8: =O7 + IF(EXACT(P8, ""), 0, 1) -> 164000000000005 | P8: =CONCATENATE("PERFORM ""SchData-OLTP-HumanResource"".""Func_TblWorkerCareerInternal_SET""(varSystemLoginSession, null::bigint, null::varchar", CONCATENATE(IF(EXACT($K8, ""), ", null", CONCATENATE(", '", $K8, "'")), "::timestamptz"), CONCATENATE(IF(EXACT($L8, ""), ", null", CONCATENATE(", '", $L8, "'")), "::timestamptz"), ", null::varchar, varInstitutionBranchID, varBaseCurrencyID", CONCATENATE(IF(EXACT($B8, ""), ", null", CONCATENATE(", ", $B8, "")), "::bigint"), CONCATENATE(IF(EXACT($D8, ""), ", null", CONCATENATE(", ", $D8, "")), "::bigint"), CONCATENATE(IF(EXACT($F8, ""), ", null", CONCATENATE(", ", $F8, "")), "::bigint"), CONCATENATE(IF(EXACT($H8, ""), ", null", CONCATENATE(", ", $H8, "")), "::bigint"), CONCATENATE(IF(EXACT($J8, ""), ", null", CONCATENATE(", '", $J8, "'")), "::varchar"), CONCATENATE(IF(EXACT($K8, ""), ", null", CONCATENATE(", '", $K8, "'")), "::timestamptz"), CONCATENATE(IF(EXACT($L8, ""), ", null", CONCATENATE(", '", $L8, "'")), "::timestamptz"), CONCATENATE(IF(EXACT($M8, ""), ", null", CONCATENATE(", ", $M8, "")), "::bigint"), ");") -> PERFORM "SchData-OLTP-HumanResource"."Func_TblWorkerCareerInternal_SET"(varSystemLoginSession, null::bigint, null::varchar, null::timestamptz, '1900-12-31 23:59:59+07'::timestamptz, null::varchar, varInstitutionBranchID, varBaseCurrencyID, 32000000000005::bigint, 163000000000003::bigint, null::bigint, null::bigint, null::varchar, null::timestamptz, '1900-12-31 23:59:59+07'::timestamptz, null::bigint);
B9: =IF(EXACT(DataLookUp!$B9, ""), "", DataLookUp!$B9) -> 32000000000006 | C9: =MAIN!C9 -> Adhitya Danar | D9: 163000000000003 | E9: =IF(EXACT($D9, ""), "", VLOOKUP($D9, [2]DataLookUp!$B$4:$D$15, 2, FALSE )) -> Karyawan Tidak Tetap (Kontrak) | G9: =IF(EXACT($F9, ""), "", VLOOKUP($F9, 'MAIN - OrgDepartment'!$C$3:$D$104, 2, FALSE)) | I9: =IF(EXACT($H9, ""), "", VLOOKUP($H9, 'MAIN - OrgJobsPos'!$B$2:$C$101, 2, FALSE)) | L9: 1900-12-31 23:59:59+07 | O9: =O8 + IF(EXACT(P9, ""), 0, 1) -> 164000000000006 | P9: =CONCATENATE("PERFORM ""SchData-OLTP-HumanResource"".""Func_TblWorkerCareerInternal_SET""(varSystemLoginSession, null::bigint, null::varchar", CONCATENATE(IF(EXACT($K9, ""), ", null", CONCATENATE(", '", $K9, "'")), "::timestamptz"), CONCATENATE(IF(EXACT($L9, ""), ", null", CONCATENATE(", '", $L9, "'")), "::timestamptz"), ", null::varchar, varInstitutionBranchID, varBaseCurrencyID", CONCATENATE(IF(EXACT($B9, ""), ", null", CONCATENATE(", ", $B9, "")), "::bigint"), CONCATENATE(IF(EXACT($D9, ""), ", null", CONCATENATE(", ", $D9, "")), "::bigint"), CONCATENATE(IF(EXACT($F9, ""), ", null", CONCATENATE(", ", $F9, "")), "::bigint"), CONCATENATE(IF(EXACT($H9, ""), ", null", CONCATENATE(", ", $H9, "")), "::bigint"), CONCATENATE(IF(EXACT($J9, ""), ", null", CONCATENATE(", '", $J9, "'")), "::varchar"), CONCATENATE(IF(EXACT($K9, ""), ", null", CONCATENATE(", '", $K9, "'")), "::timestamptz"), CONCATENATE(IF(EXACT($L9, ""), ", null", CONCATENATE(", '", $L9, "'")), "::timestamptz"), CONCATENATE(IF(EXACT($M9, ""), ", null", CONCATENATE(", ", $M9, "")), "::bigint"), ");") -> PERFORM "SchData-OLTP-HumanResource"."Func_TblWorkerCareerInternal_SET"(varSystemLoginSession, null::bigint, null::varchar, null::timestamptz, '1900-12-31 23:59:59+07'::timestamptz, null::varchar, varInstitutionBranchID, varBaseCurrencyID, 32000000000006::bigint, 163000000000003::bigint, null::bigint, null::bigint, null::varchar, null::timestamptz, '1900-12-31 23:59:59+07'::timestamptz, null::bigint);
B10: =IF(EXACT(DataLookUp!$B10, ""), "", DataLookUp!$B10) -> 32000000000007 | C10: =MAIN!C10 -> Adi Ruswandi | D10: 163000000000003 | E10: =IF(EXACT($D10, ""), "", VLOOKUP($D10, [2]DataLookUp!$B$4:$D$15, 2, FALSE )) -> Karyawan Tidak Tetap (Kontrak) | G10: =IF(EXACT($F10, ""), "", VLOOKUP($F10, 'MAIN - OrgDepartment'!$C$3:$D$104, 2, FALSE)) | I10: =IF(EXACT($H10, ""), "", VLOOKUP($H10, 'MAIN - OrgJobsPos'!$B$2:$C$101, 2, FALSE)) | L10: 1900-12-31 23:59:59+07 | O10: =O9 + IF(EXACT(P10, ""), 0, 1) -> 164000000000007 | P10: =CONCATENATE("PERFORM ""SchData-OLTP-HumanResource"".""Func_TblWorkerCareerInternal_SET""(varSystemLoginSession, null::bigint, null::varchar", CONCATENATE(IF(EXACT($K10, ""), ", null", CONCATENATE(", '", $K10, "'")), "::timestamptz"), CONCATENATE(IF(EXACT($L10, ""), ", null", CONCATENATE(", '", $L10, "'")), "::timestamptz"), ", null::varchar, varInstitutionBranchID, varBaseCurrencyID", CONCATENATE(IF(EXACT($B10, ""), ", null", CONCATENATE(", ", $B10, "")), "::bigint"), CONCATENATE(IF(EXACT($D10, ""), ", null", CONCATENATE(", ", $D10, "")), "::bigint"), CONCATENATE(IF(EXACT($F10, ""), ", null", CONCATENATE(", ", $F10, "")), "::bigint"), CONCATENATE(IF(EXACT($H10, ""), ", null", CONCATENATE(", ", $H10, "")), "::bigint"), CONCATENATE(IF(EXACT($J10, ""), ", null", CONCATENATE(", '", $J10, "'")), "::varchar"), CONCATENATE(IF(EXACT($K10, ""), ", null", CONCATENATE(", '", $K10, "'")), "::timestamptz"), CONCATENATE(IF(EXACT($L10, ""), ", null", CONCATENATE(", '", $L10, "'")), "::timestamptz"), CONCATENATE(IF(EXACT($M10, ""), ", null", CONCATENATE(", ", $M10, "")), "::bigint"), ");") -> PERFORM "SchData-OLTP-HumanResource"."Func_TblWorkerCareerInternal_SET"(varSystemLoginSession, null::bigint, null::varchar, null::timestamptz, '1900-12-31 23:59:59+07'::timestamptz, null::varchar, varInstitutionBranchID, varBaseCurrencyID, 32000000000007::bigint, 163000000000003::bigint, null::bigint, null::bigint, null::varchar, null::timestamptz, '1900-12-31 23:59:59+07'::timestamptz, null::bigint);
B11: =IF(EXACT(DataLookUp!$B11, ""), "", DataLookUp!$B11) -> 32000000000008 | C11: =MAIN!C11 -> Adietya Dharmawan | D11: 163000000000003 | E11: =IF(EXACT($D11, ""), "", VLOOKUP($D11, [2]DataLookUp!$B$4:$D$15, 2, FALSE )) -> Karyawan Tidak Tetap (Kontrak) | G11: =IF(EXACT($F11, ""), "", VLOOKUP($F11, 'MAIN - OrgDepartment'!$C$3:$D$104, 2, FALSE)) | I11: =IF(EXACT($H11, ""), "", VLOOKUP($H11, 'MAIN - OrgJobsPos'!$B$2:$C$101, 2, FALSE)) | L11: 1900-12-31 23:59:59+07 | O11: =O10 + IF(EXACT(P11, ""), 0, 1) -> 164000000000008 | P11: =CONCATENATE("PERFORM ""SchData-OLTP-HumanResource"".""Func_TblWorkerCareerInternal_SET""(varSystemLoginSession, null::bigint, null::varchar", CONCATENATE(IF(EXACT($K11, ""), ", null", CONCATENATE(", '", $K11, "'")), "::timestamptz"), CONCATENATE(IF(EXACT($L11, ""), ", null", CONCATENATE(", '", $L11, "'")), "::timestamptz"), ", null::varchar, varInstitutionBranchID, varBaseCurrencyID", CONCATENATE(IF(EXACT($B11, ""), ", null", CONCATENATE(", ", $B11, "")), "::bigint"), CONCATENATE(IF(EXACT($D11, ""), ", null", CONCATENATE(", ", $D11, "")), "::bigint"), CONCATENATE(IF(EXACT($F11, ""), ", null", CONCATENATE(", ", $F11, "")), "::bigint"), CONCATENATE(IF(EXACT($H11, ""), ", null", CONCATENATE(", ", $H11, "")), "::bigint"), CONCATENATE(IF(EXACT($J11, ""), ", null", CONCATENATE(", '", $J11, "'")), "::varchar"), CONCATENATE(IF(EXACT($K11, ""), ", null", CONCATENATE(", '", $K11, "'")), "::timestamptz"), CONCATENATE(IF(EXACT($L11, ""), ", null", CONCATENATE(", '", $L11, "'")), "::timestamptz"), CONCATENATE(IF(EXACT($M11, ""), ", null", CONCATENATE(", ", $M11, "")), "::bigint"), ");") -> PERFORM "SchData-OLTP-HumanResource"."Func_TblWorkerCareerInternal_SET"(varSystemLoginSession, null::bigint, null::varchar, null::timestamptz, '1900-12-31 23:59:59+07'::timestamptz, null::varchar, varInstitutionBranchID, varBaseCurrencyID, 32000000000008::bigint, 163000000000003::bigint, null::bigint, null::bigint, null::varchar, null::timestamptz, '1900-12-31 23:59:59+07'::timestamptz, null::bigint);
B12: =IF(EXACT(DataLookUp!$B12, ""), "", DataLookUp!$B12) -> 32000000000009 | C12: =MAIN!C12 -> Aditya Yudha Prawira | D12: 163000000000003 | E12: =IF(EXACT($D12, ""), "", VLOOKUP($D12, [2]DataLookUp!$B$4:$D$15, 2, FALSE )) -> Karyawan Tidak Tetap (Kontrak) | G12: =IF(EXACT($F12, ""), "", VLOOKUP($F12, 'MAIN - OrgDepartment'!$C$3:$D$104, 2, FALSE)) | I12: =IF(EXACT($H12, ""), "", VLOOKUP($H12, 'MAIN - OrgJobsPos'!$B$2:$C$101, 2, FALSE)) | L12: 1900-12-31 23:59:59+07 | O12: =O11 + IF(EXACT(P12, ""), 0, 1) -> 164000000000009 | P12: =CONCATENATE("PERFORM ""SchData-OLTP-HumanResource"".""Func_TblWorkerCareerInternal_SET""(varSystemLoginSession, null::bigint, null::varchar", CONCATENATE(IF(EXACT($K12, ""), ", null", CONCATENATE(", '", $K12, "'")), "::timestamptz"), CONCATENATE(IF(EXACT($L12, ""), ", null", CONCATENATE(", '", $L12, "'")), "::timestamptz"), ", null::varchar, varInstitutionBranchID, varBaseCurrencyID", CONCATENATE(IF(EXACT($B12, ""), ", null", CONCATENATE(", ", $B12, "")), "::bigint"), CONCATENATE(IF(EXACT($D12, ""), ", null", CONCATENATE(", ", $D12, "")), "::bigint"), CONCATENATE(IF(EXACT($F12, ""), ", null", CONCATENATE(", ", $F12, "")), "::bigint"), CONCATENATE(IF(EXACT($H12, ""), ", null", CONCATENATE(", ", $H12, "")), "::bigint"), CONCATENATE(IF(EXACT($J12, ""), ", null", CONCATENATE(", '", $J12, "'")), "::varchar"), CONCATENATE(IF(EXACT($K12, ""), ", null", CONCATENATE(", '", $K12, "'")), "::timestamptz"), CONCATENATE(IF(EXACT($L12, ""), ", null", CONCATENATE(", '", $L12, "'")), "::timestamptz"), CONCATENATE(IF(EXACT($M12, ""), ", null", CONCATENATE(", ", $M12, "")), "::bigint"), ");") -> PERFORM "SchData-OLTP-HumanResource"."Func_TblWorkerCareerInternal_SET"(varSystemLoginSession, null::bigint, null::varchar, null::timestamptz, '1900-12-31 23:59:59+07'::timestamptz, null::varchar, varInstitutionBranchID, varBaseCurrencyID, 32000000000009::bigint, 163000000000003::bigint, null::bigint, null::bigint, null::varchar, null::timestamptz, '1900-12-31 23:59:59+07'::timestamptz, null::bigint);
B13: =IF(EXACT(DataLookUp!$B13, ""), "", DataLookUp!$B13) -> 32000000000010 | C13: =MAIN!C13 -> Adli Margie | D13: 163000000000002 | E13: =IF(EXACT($D13, ""), "", VLOOKUP($D13, [2]DataLookUp!$B$4:$D$15, 2, FALSE )) -> Karyawan Tetap (Purna Waktu) | G13: =IF(EXACT($F13, ""), "", VLOOKUP($F13, 'MAIN - OrgDepartment'!$C$3:$D$104, 2, FALSE)) | I13: =IF(EXACT($H13, ""), "", VLOOKUP($H13, 'MAIN - OrgJobsPos'!$B$2:$C$101, 2, FALSE)) | L13: 1900-12-31 23:59:59+07 | O13: =O12 + IF(EXACT(P13, ""), 0, 1) -> 164000000000010 | P13: =CONCATENATE("PERFORM ""SchData-OLTP-HumanResource"".""Func_TblWorkerCareerInternal_SET""(varSystemLoginSession, null::bigint, null::varchar", CONCATENATE(IF(EXACT($K13, ""), ", null", CONCATENATE(", '", $K13, "'")), "::timestamptz"), CONCATENATE(IF(EXACT($L13, ""), ", null", CONCATENATE(", '", $L13, "'")), "::timestamptz"), ", null::varchar, varInstitutionBranchID, varBaseCurrencyID", CONCATENATE(IF(EXACT($B13, ""), ", null", CONCATENATE(", ", $B13, "")), "::bigint"), CONCATENATE(IF(EXACT($D13, ""), ", null", CONCATENATE(", ", $D13, "")), "::bigint"), CONCATENATE(IF(EXACT($F13, ""), ", null", CONCATENATE(", ", $F13, "")), "::bigint"), CONCATENATE(IF(EXACT($H13, ""), ", null", CONCATENATE(", ", $H13, "")), "::bigint"), CONCATENATE(IF(EXACT($J13, ""), ", null", CONCATENATE(", '", $J13, "'")), "::varchar"), CONCATENATE(IF(EXACT($K13, ""), ", null", CONCATENATE(", '", $K13, "'")), "::timestamptz"), CONCATENATE(IF(EXACT($L13, ""), ", null", CONCATENATE(", '", $L13, "'")), "::timestamptz"), CONCATENATE(IF(EXACT($M13, ""), ", null", CONCATENATE(", ", $M13, "")), "::bigint"), ");") -> PERFORM "SchData-OLTP-HumanResource"."Func_TblWorkerCareerInternal_SET"(varSystemLoginSession, null::bigint, null::varchar, null::timestamptz, '1900-12-31 23:59:59+07'::timestamptz, null::varchar, varInstitutionBranchID, varBaseCurrencyID, 32000000000010::bigint, 163000000000002::bigint, null::bigint, null::bigint, null::varchar, null::timestamptz, '1900-12-31 23:59:59+07'::timestamptz, null::bigint);
