Workbook

Sheet MAIN
B2: Ref ID Worker Career Internal | C2: Worker Name | D2: Ref ID User Role | E2: User Role Name | F2: Ref ID Combined Budget | H2: SYS_PID Prediction | I2: SQL Syntax
H3: 225000000000000
B4: =IF(EXACT('[1]DataLookUp - InternalCareer(LP)'!$B4, ""), "", '[1]DataLookUp - InternalCareer(LP)'!$B4) -> 164000000000001 | C4: =IF(EXACT($B4, ""), "", VLOOKUP(B4, '[1]DataLookUp - InternalCareer(LP)'!$B$4:$D$620, 3, FALSE)) -> Abdollah Syani Siregar | E4: =IF(EXACT($D4, ""), "", VLOOKUP($D4, [2]DataLookUp!$B$4:$C$84, 2, FALSE)) | H4: =H3 + IF(EXACT(I4, ""), 0, 1) -> 225000000000000 | I4: =IF(EXACT(D4, ""), "", CONCATENATE("PERFORM ""SchData-OLTP-HumanResource"".""Func_TblMapper_WorkerCareerInternalToUserRole_SET""(varSystemLoginSession, null::bigint, null::varchar, null::timestamptz, null::timestamptz, null::varchar, varInstitutionBranchID, varBaseCurrencyID, ", IF(EXACT(B4, ""), "null", B4), "::bigint, ", IF(EXACT(D4, ""), "null", D4), "::bigint, ", IF(EXACT(F4, ""), "null", F4), "::bigint);"))
B5: =IF(EXACT('[1]DataLookUp - InternalCareer(LP)'!$B5, ""), "", '[1]DataLookUp - InternalCareer(LP)'!$B5) -> 164000000000002 | C5: =IF(EXACT($B5, ""), "", VLOOKUP(B5, '[1]DataLookUp - InternalCareer(LP)'!$B$4:$D$620, 3, FALSE)) -> Abdul Karim | E5: =IF(EXACT($D5, ""), "", VLOOKUP($D5, [2]DataLookUp!$B$4:$C$84, 2, FALSE)) | H5: =H4 + IF(EXACT(I5, ""), 0, 1) -> 225000000000000 | I5: =IF(EXACT(D5, ""), "", CONCATENATE("PERFORM ""SchData-OLTP-HumanResource"".""Func_TblMapper_WorkerCareerInternalToUserRole_SET""(varSystemLoginSession, null::bigint, null::varchar, null::timestamptz, null::timestamptz, null::varchar, varInstitutionBranchID, varBaseCurrencyID, ", IF(EXACT(B5, ""), "null", B5), "::bigint, ", IF(EXACT(D5, ""), "null", D5), "::bigint, ", IF(EXACT(F5, ""), "null", F5), "::bigint);"))
B6: =IF(EXACT('[1]DataLookUp - InternalCareer(LP)'!$B6, ""), "", '[1]DataLookUp - InternalCareer(LP)'!$B6) -> 164000000000003 | C6: =IF(EXACT($B6, ""), "", VLOOKUP(B6, '[1]DataLookUp - InternalCareer(LP)'!$B$4:$D$620, 3, FALSE)) -> Abdul Rahman Sitompul | E6: =IF(EXACT($D6, ""), "", VLOOKUP($D6, [2]DataLookUp!$B$4:$C$84, 2, FALSE)) | H6: =H5 + IF(EXACT(I6, ""), 0, 1) -> 225000000000000 | I6: =IF(EXACT(D6, ""), "", CONCATENATE("PERFORM ""SchData-OLTP-HumanResource"".""Func_TblMapper_WorkerCareerInternalToUserRole_SET""(varSystemLoginSession, null::bigint, null::varchar, null::timestamptz, null::timestamptz, null::varchar, varInstitutionBranchID, varBaseCurrencyID, ", IF(EXACT(B6, ""), "null", B6), "::bigint, ", IF(EXACT(D6, ""), "null", D6), "::bigint, ", IF(EXACT(F6, ""), "null", F6), "::bigint);"))
B7: =IF(EXACT('[1]DataLookUp - InternalCareer(LP)'!$B7, ""), "", '[1]DataLookUp - InternalCareer(LP)'!$B7) -> 164000000000004 | C7: =IF(EXACT($B7, ""), "", VLOOKUP(B7, '[1]DataLookUp - InternalCareer(LP)'!$B$4:$D$620, 3, FALSE)) -> Abdul Risan | E7: =IF(EXACT($D7, ""), "", VLOOKUP($D7, [2]DataLookUp!$B$4:$C$84, 2, FALSE)) | H7: =H6 + IF(EXACT(I7, ""), 0, 1) -> 225000000000000 | I7: =IF(EXACT(D7, ""), "", CONCATENATE("PERFORM ""SchData-OLTP-HumanResource"".""Func_TblMapper_WorkerCareerInternalToUserRole_SET""(varSystemLoginSession, null::bigint, null::varchar, null::timestamptz, null::timestamptz, null::varchar, varInstitutionBranchID, varBaseCurrencyID, ", IF(EXACT(B7, ""), "null", B7), "::bigint, ", IF(EXACT(D7, ""), "null", D7), "::bigint, ", IF(EXACT(F7, ""), "null", F7), "::bigint);"))
B8: =IF(EXACT('[1]DataLookUp - InternalCareer(LP)'!$B8, ""), "", '[1]DataLookUp - InternalCareer(LP)'!$B8) -> 164000000000005 | C8: =IF(EXACT($B8, ""), "", VLOOKUP(B8, '[1]DataLookUp - InternalCareer(LP)'!$B$4:$D$620, 3, FALSE)) -> Abdullah Nabil | E8: =IF(EXACT($D8, ""), "", VLOOKUP($D8, [2]DataLookUp!$B$4:$C$84, 2, FALSE)) | H8: =H7 + IF(EXACT(I8, ""), 0, 1) -> 225000000000000 | I8: =IF(EXACT(D8, ""), "", CONCATENATE("PERFORM ""SchData-OLTP-HumanResource"".""Func_TblMapper_WorkerCareerInternalToUserRole_SET""(varSystemLoginSession, null::bigint, null::varchar, null::timestamptz, null::timestamptz, null::varchar, varInstitutionBranchID, varBaseCurrencyID, ", IF(EXACT(B8, ""), "null", B8), "::bigint, ", IF(EXACT(D8, ""), "null", D8), "::bigint, ", IF(EXACT(F8, ""), "null", F8), "::bigint);"))
B9: =IF(EXACT('[1]DataLookUp - InternalCareer(LP)'!$B9, ""), "", '[1]DataLookUp - InternalCareer(LP)'!$B9) -> 164000000000006 | C9: =IF(EXACT($B9, ""), "", VLOOKUP(B9, '[1]DataLookUp - InternalCareer(LP)'!$B$4:$D$620, 3, FALSE)) -> Adhitya Danar | E9: =IF(EXACT($D9, ""), "", VLOOKUP($D9, [2]DataLookUp!$B$4:$C$84, 2, FALSE)) | H9: =H8 + IF(EXACT(I9, ""), 0, 1) -> 225000000000000 | I9: =IF(EXACT(D9, ""), "", CONCATENATE("PERFORM ""SchData-OLTP-HumanResource"".""Func_TblMapper_WorkerCareerInternalToUserRole_SET""(varSystemLoginSession, null::bigint, null::varchar, null::timestamptz, null::timestamptz, null::varchar, varInstitutionBranchID, varBaseCurrencyID, ", IF(EXACT(B9, ""), "null", B9), "::bigint, ", IF(EXACT(D9, ""), "null", D9), "::bigint, ", IF(EXACT(F9, ""), "null", F9), "::bigint);"))
B10: =IF(EXACT('[1]DataLookUp - InternalCareer(LP)'!$B10, ""), "", '[1]DataLookUp - InternalCareer(LP)'!$B10) -> 164000000000007 | C10: =IF(EXACT($B10, ""), "", VLOOKUP(B10, '[1]DataLookUp - InternalCareer(LP)'!$B$4:$D$620, 3, FALSE)) -> Adi Ruswandi | E10: =IF(EXACT($D10, ""), "", VLOOKUP($D10, [2]DataLookUp!$B$4:$C$84, 2, FALSE)) | H10: =H9 + IF(EXACT(I10, ""), 0, 1) -> 225000000000000 | I10: =IF(EXACT(D10, ""), "", CONCATENATE("PERFORM ""SchData-OLTP-HumanResource"".""Func_TblMapper_WorkerCareerInternalToUserRole_SET""(varSystemLoginSession, null::bigint, null::varchar, null::timestamptz, null::timestamptz, null::varchar, varInstitutionBranchID, varBaseCurrencyID, ", IF(EXACT(B10, ""), "null", B10), "::bigint, ", IF(EXACT(D10, ""), "null", D10), "::bigint, ", IF(EXACT(F10, ""), "null", F10), "::bigint);"))
B11: =IF(EXACT('[1]DataLookUp - InternalCareer(LP)'!$B11, ""), "", '[1]DataLookUp - InternalCareer(LP)'!$B11) -> 164000000000008 | C11: =IF(EXACT($B11, ""), "", VLOOKUP(B11, '[1]DataLookUp - InternalCareer(LP)'!$B$4:$D$620, 3, FALSE)) -> Adietya Dharmawan | E11: =IF(EXACT($D11, ""), "", VLOOKUP($D11, [2]DataLookUp!$B$4:$C$84, 2, FALSE)) | H11: =H10 + IF(EXACT(I11, ""), 0, 1) -> 225000000000000 | I11: =IF(EXACT(D11, ""), "", CONCATENATE("PERFORM ""SchData-OLTP-HumanResource"".""Func_TblMapper_WorkerCareerInternalToUserRole_SET""(varSystemLoginSession, null::bigint, null::varchar, null::timestamptz, null::timestamptz, null::varchar, varInstitutionBranchID, varBaseCurrencyID, ", IF(EXACT(B11, ""), "null", B11), "::bigint, ", IF(EXACT(D11, ""), "null", D11), "::bigint, ", IF(EXACT(F11, ""), "null", F11), "::bigint);"))
B12: =IF(EXACT('[1]DataLookUp - InternalCareer(LP)'!$B12, ""), "", '[1]DataLookUp - InternalCareer(LP)'!$B12) -> 164000000000009 | C12: =IF(EXACT($B12, ""), "", VLOOKUP(B12, '[1]DataLookUp - InternalCareer(LP)'!$B$4:$D$620, 3, FALSE)) -> Aditya Yudha Prawira | E12: =IF(EXACT($D12, ""), "", VLOOKUP($D12, [2]DataLookUp!$B$4:$C$84, 2, FALSE)) | H12: =H11 + IF(EXACT(I12, ""), 0, 1) -> 225000000000000 | I12: =IF(EXACT(D12, ""), "", CONCATENATE("PERFORM ""SchData-OLTP-HumanResource"".""Func_TblMapper_WorkerCareerInternalToUserRole_SET""(varSystemLoginSession, null::bigint, null::varchar, null::timestamptz, null::timestamptz, null::varchar, varInstitutionBranchID, varBaseCurrencyID, ", IF(EXACT(B12, ""), "null", B12), "::bigint, ", IF(EXACT(D12, ""), "null", D12), "::bigint, ", IF(EXACT(F12, ""), "null", F12), "::bigint);"))
B13: =IF(EXACT('[1]DataLookUp - InternalCareer(LP)'!$B13, ""), "", '[1]DataLookUp - InternalCareer(LP)'!$B13) -> 164000000000010 | C13: =IF(EXACT($B13, ""), "", VLOOKUP(B13, '[1]DataLookUp - InternalCareer(LP)'!$B$4:$D$620, 3, FALSE)) -> Adli Margie | E13: =IF(EXACT($D13, ""), "", VLOOKUP($D13, [2]DataLookUp!$B$4:$C$84, 2, FALSE)) | H13: =H12 + IF(EXACT(I13, ""), 0, 1) -> 225000000000000 | I13: =IF(EXACT(D13, ""), "", CONCATENATE("PERFORM ""SchData-OLTP-HumanResource"".""Func_TblMapper_WorkerCareerInternalToUserRole_SET""(varSystemLoginSession, null::bigint, null::varchar, null::timestamptz, null::timestamptz, null::varchar, varInstitutionBranchID, varBaseCurrencyID, ", IF(EXACT(B13, ""), "null", B13), "::bigint, ", IF(EXACT(D13, ""), "null", D13), "::bigint, ", IF(EXACT(F13, ""), "null", F13), "::bigint);"))
B14: =IF(EXACT('[1]DataLookUp - InternalCareer(LP)'!$B14, ""), "", '[1]DataLookUp - InternalCareer(LP)'!$B14) -> 164000000000011 | C14: =IF(EXACT($B14, ""), "", VLOOKUP(B14, '[1]DataLookUp - InternalCareer(LP)'!$B$4:$D$620, 3, FALSE)) -> Afrida Eka Putri | E14: =IF(EXACT($D14, ""), "", VLOOKUP($D14, [2]DataLookUp!$B$4:$C$84, 2, FALSE)) | H14: =H13 + IF(EXACT(I14, ""), 0, 1) -> 225000000000000 | I14: =IF(EXACT(D14, ""), "", CONCATENATE("PERFORM ""SchData-OLTP-HumanResource"".""Func_TblMapper_WorkerCareerInternalToUserRole_SET""(varSystemLoginSession, null::bigint, null::varchar, null::timestamptz, null::timestamptz, null::varchar, varInstitutionBranchID, varBaseCurrencyID, ", IF(EXACT(B14, ""), "null", B14), "::bigint, ", IF(EXACT(D14, ""), "null", D14), "::bigint, ", IF(EXACT(F14, ""), "null", F14), "::bigint);"))
B15: =IF(EXACT('[1]DataLookUp - InternalCareer(LP)'!$B15, ""), "", '[1]DataLookUp - InternalCareer(LP)'!$B15) -> 164000000000012 | C15: =IF(EXACT($B15, ""), "", VLOOKUP(B15, '[1]DataLookUp - InternalCareer(LP)'!$B$4:$D$620, 3, FALSE)) -> Agnes Sutedja | D15: =[2]MAIN!$D$62 -> 95000000000048 | E15: =IF(EXACT($D15, ""), "", VLOOKUP($D15, [2]DataLookUp!$B$4:$C$84, 2, FALSE)) -> Health Safety Environment Manager | H15: =H14 + IF(EXACT(I15, ""), 0, 1) -> 225000000000001 | I15: =IF(EXACT(D15, ""), "", CONCATENATE("PERFORM ""SchData-OLTP-HumanResource"".""Func_TblMapper_WorkerCareerInternalToUserRole_SET""(varSystemLoginSession, null::bigint, null::varchar, null::timestamptz, null::timestamptz, null::varchar, varInstitutionBranchID, varBaseCurrencyID, ", IF(EXACT(B15, ""), "null", B15), "::bigint, ", IF(EXACT(D15, ""), "null", D15), "::bigint, ", IF(EXACT(F15, ""), "null", F15), "::bigint);")) -> PERFORM "SchData-OLTP-HumanResource"."Func_TblMapper_WorkerCareerInternalToUserRole_SET"(varSystemLoginSession, null::bigint, null::varchar, null::timestamptz, null::timestamptz, null::varchar, varInstitutionBranchID, varBaseCurrencyID, 164000000000012::bigint, 95000000000048::bigint, null::bigint);
B16: =IF(EXACT('[1]DataLookUp - InternalCareer(LP)'!$B16, ""), "", '[1]DataLookUp - InternalCareer(LP)'!$B16) -> 164000000000013 | C16: =IF(EXACT($B16, ""), "", VLOOKUP(B16, '[1]DataLookUp - InternalCareer(LP)'!$B$4:$D$620, 3, FALSE)) -> Agung Hendarto | E16: =IF(EXACT($D16, ""), "", VLOOKUP($D16, [2]DataLookUp!$B$4:$C$84, 2, FALSE)) | H16: =H15 + IF(EXACT(I16, ""), 0, 1) -> 225000000000001 | I16: =IF(EXACT(D16, ""), "", CONCATENATE("PERFORM ""SchData-OLTP-HumanResource"".""Func_TblMapper_WorkerCareerInternalToUserRole_SET""(varSystemLoginSession, null::bigint, null::varchar, null::timestamptz, null::timestamptz, null::varchar, varInstitutionBranchID, varBaseCurrencyID, ", IF(EXACT(B16, ""), "null", B16), "::bigint, ", IF(EXACT(D16, ""), "null", D16), "::bigint, ", IF(EXACT(F16, ""), "null", F16), "::bigint);"))
B17: =IF(EXACT('[1]DataLookUp - InternalCareer(LP)'!$B17, ""), "", '[1]DataLookUp - InternalCareer(LP)'!$B17) -> 164000000000014 | C17: =IF(EXACT($B17, ""), "", VLOOKUP(B17, '[1]DataLookUp - InternalCareer(LP)'!$B$4:$D$620, 3, FALSE)) -> Agus Priyatno Mahmudo | E17: =IF(EXACT($D17, ""), "", VLOOKUP($D17, [2]DataLookUp!$B$4:$C$84, 2, FALSE)) | H17: =H16 + IF(EXACT(I17, ""), 0, 1) -> 225000000000001 | I17: =IF(EXACT(D17, ""), "", CONCATENATE("PERFORM ""SchData-OLTP-HumanResource"".""Func_TblMapper_WorkerCareerInternalToUserRole_SET""(varSystemLoginSession, null::bigint, null::varchar, null::timestamptz, null::timestamptz, null::varchar, varInstitutionBranchID, varBaseCurrencyID, ", IF(EXACT(B17, ""), "null", B17), "::bigint, ", IF(EXACT(D17, ""), "null", D17), "::bigint, ", IF(EXACT(F17, ""), "null", F17), "::bigint);"))
B18: =IF(EXACT('[1]DataLookUp - InternalCareer(LP)'!$B18, ""), "", '[1]DataLookUp - InternalCareer(LP)'!$B18) -> 164000000000015 | C18: =IF(EXACT($B18, ""), "", VLOOKUP(B18, '[1]DataLookUp - InternalCareer(LP)'!$B$4:$D$620, 3, FALSE)) -> Agus Salim | E18: =IF(EXACT($D18, ""), "", VLOOKUP($D18, [2]DataLookUp!$B$4:$C$84, 2, FALSE)) | H18: =H17 + IF(EXACT(I18, ""), 0, 1) -> 225000000000001 | I18: =IF(EXACT(D18, ""), "", CONCATENATE("PERFORM ""SchData-OLTP-HumanResource"".""Func_TblMapper_WorkerCareerInternalToUserRole_SET""(varSystemLoginSession, null::bigint, null::varchar, null::timestamptz, null::timestamptz, null::varchar, varInstitutionBranchID, varBaseCurrencyID, ", IF(EXACT(B18, ""), "null", B18), "::bigint, ", IF(EXACT(D18, ""), "null", D18), "::bigint, ", IF(EXACT(F18, ""), "null", F18), "::bigint);"))
B19: =IF(EXACT('[1]DataLookUp - InternalCareer(LP)'!$B19, ""), "", '[1]DataLookUp - InternalCareer(LP)'!$B19) -> 164000000000016 | C19: =IF(EXACT($B19, ""), "", VLOOKUP(B19, '[1]DataLookUp - InternalCareer(LP)'!$B$4:$D$620, 3, FALSE)) -> Agus Tanto | E19: =IF(EXACT($D19, ""), "", VLOOKUP($D19, [2]DataLookUp!$B$4:$C$84, 2, FALSE)) | H19: =H18 + IF(EXACT(I19, ""), 0, 1) -> 225000000000001 | I19: =IF(EXACT(D19, ""), "", CONCATENATE("PERFORM ""SchData-OLTP-HumanResource"".""Func_TblMapper_WorkerCareerInternalToUserRole_SET""(varSystemLoginSession, null::bigint, null::varchar, null::timestamptz, null::timestamptz, null::varchar, varInstitutionBranchID, varBaseCurrencyID, ", IF(EXACT(B19, ""), "null", B19), "::bigint, ", IF(EXACT(D19, ""), "null", D19), "::bigint, ", IF(EXACT(F19, ""), "null", F19), "::bigint);"))
B20: =IF(EXACT('[1]DataLookUp - InternalCareer(LP)'!$B20, ""), "", '[1]DataLookUp - InternalCareer(LP)'!$B20) -> 164000000000017 | C20: =IF(EXACT($B20, ""), "", VLOOKUP(B20, '[1]DataLookUp - InternalCareer(LP)'!$B$4:$D$620, 3, FALSE)) -> Ahmad Faiz Haems Muda | D20: =[2]MAIN!$D$24 -> 95000000000017 | E20: =IF(EXACT($D20, ""), "", VLOOKUP($D20, [2]DataLookUp!$B$4:$C$84, 2, FALSE)) -> HR, GA, & TAM General Manager | H20: =H19 + IF(EXACT(I20, ""), 0, 1) -> 225000000000002 | I20: =IF(EXACT(D20, ""), "", CONCATENATE("PERFORM ""SchData-OLTP-HumanResource"".""Func_TblMapper_WorkerCareerInternalToUserRole_SET""(varSystemLoginSession, null::bigint, null::varchar, null::timestamptz, null::timestamptz, null::varchar, varInstitutionBranchID, varBaseCurrencyID, ", IF(EXACT(B20, ""), "null", B20), "::bigint, ", IF(EXACT(D20, ""), "null", D20), "::bigint, ", IF(EXACT(F20, ""), "null", F20), "::bigint);")) -> PERFORM "SchData-OLTP-HumanResource"."Func_TblMapper_WorkerCareerInternalToUserRole_SET"(varSystemLoginSession, null::bigint, null::varchar, null::timestamptz, null::timestamptz, null::varchar, varInstitutionBranchID, varBaseCurrencyID, 164000000000017::bigint, 95000000000017::bigint, null::bigint);
B21: =IF(EXACT('[1]DataLookUp - InternalCareer(LP)'!$B21, ""), "", '[1]DataLookUp - InternalCareer(LP)'!$B21) -> 164000000000018 | C21: =IF(EXACT($B21, ""), "", VLOOKUP(B21, '[1]DataLookUp - InternalCareer(LP)'!$B$4:$D$620, 3, FALSE)) -> Ahmad Faza | E21: =IF(EXACT($D21, ""), "", VLOOKUP($D21, [2]DataLookUp!$B$4:$C$84, 2, FALSE)) | H21: =H20 + IF(EXACT(I21, ""), 0, 1) -> 225000000000002 | I21: =IF(EXACT(D21, ""), "", CONCATENATE("PERFORM ""SchData-OLTP-HumanResource"".""Func_TblMapper_WorkerCareerInternalToUserRole_SET""(varSystemLoginSession, null::bigint, null::varchar, null::timestamptz, null::timestamptz, null::varchar, varInstitutionBranchID, varBaseCurrencyID, ", IF(EXACT(B21, ""), "null", B21), "::bigint, ", IF(EXACT(D21, ""), "null", D21), "::bigint, ", IF(EXACT(F21, ""), "null", F21), "::bigint);"))
B22: =IF(EXACT('[1]DataLookUp - InternalCareer(LP)'!$B22, ""), "", '[1]DataLookUp - InternalCareer(LP)'!$B22) -> 164000000000019 | C22: =IF(EXACT($B22, ""), "", VLOOKUP(B22, '[1]DataLookUp - InternalCareer(LP)'!$B$4:$D$620, 3, FALSE)) -> Ahmad Syaifulloh | E22: =IF(EXACT($D22, ""), "", VLOOKUP($D22, [2]DataLookUp!$B$4:$C$84, 2, FALSE)) | H22: =H21 + IF(EXACT(I22, ""), 0, 1) -> 225000000000002 | I22: =IF(EXACT(D22, ""), "", CONCATENATE("PERFORM ""SchData-OLTP-HumanResource"".""Func_TblMapper_WorkerCareerInternalToUserRole_SET""(varSystemLoginSession, null::bigint, null::varchar, null::timestamptz, null::timestamptz, null::varchar, varInstitutionBranchID, varBaseCurrencyID, ", IF(EXACT(B22, ""), "null", B22), "::bigint, ", IF(EXACT(D22, ""), "null", D22), "::bigint, ", IF(EXACT(F22, ""), "null", F22), "::bigint);"))
B23: =IF(EXACT('[1]DataLookUp - InternalCareer(LP)'!$B23, ""), "", '[1]DataLookUp - InternalCareer(LP)'!$B23) -> 164000000000020 | C23: =IF(EXACT($B23, ""), "", VLOOKUP(B23, '[1]DataLookUp - InternalCareer(LP)'!$B$4:$D$620, 3, FALSE)) -> Ahmad Zulkarnaen | E23: =IF(EXACT($D23, ""), "", VLOOKUP($D23, [2]DataLookUp!$B$4:$C$84, 2, FALSE)) | H23: =H22 + IF(EXACT(I23, ""), 0, 1) -> 225000000000002 | I23: =IF(EXACT(D23, ""), "", CONCATENATE("PERFORM ""SchData-OLTP-HumanResource"".""Func_TblMapper_WorkerCareerInternalToUserRole_SET""(varSystemLoginSession, null::bigint, null::varchar, null::timestamptz, null::timestamptz, null::varchar, varInstitutionBranchID, varBaseCurrencyID, ", IF(EXACT(B23, ""), "null", B23), "::bigint, ", IF(EXACT(D23, ""), "null", D23), "::bigint, ", IF(EXACT(F23, ""), "null", F23), "::bigint);"))
B24: =IF(EXACT('[1]DataLookUp - InternalCareer(LP)'!$B24, ""), "", '[1]DataLookUp - InternalCareer(LP)'!$B24) -> 164000000000021 | C24: =IF(EXACT($B24, ""), "", VLOOKUP(B24, '[1]DataLookUp - InternalCareer(LP)'!$B$4:$D$620, 3, FALSE)) -> Ajan | E24: =IF(EXACT($D24, ""), "", VLOOKUP($D24, [2]DataLookUp!$B$4:$C$84, 2, FALSE)) | H24: =H23 + IF(EXACT(I24, ""), 0, 1) -> 225000000000002 | I24: =IF(EXACT(D24, ""), "", CONCATENATE("PERFORM ""SchData-OLTP-HumanResource"".""Func_TblMapper_WorkerCareerInternalToUserRole_SET""(varSystemLoginSession, null::bigint, null::varchar, null::timestamptz, null::timestamptz, null::varchar, varInstitutionBranchID, varBaseCurrencyID, ", IF(EXACT(B24, ""), "null", B24), "::bigint, ", IF(EXACT(D24, ""), "null", D24), "::bigint, ", IF(EXACT(F24, ""), "null", F24), "::bigint);"))
B25: =IF(EXACT('[1]DataLookUp - InternalCareer(LP)'!$B25, ""), "", '[1]DataLookUp - InternalCareer(LP)'!$B25) -> 164000000000022 | C25: =IF(EXACT($B25, ""), "", VLOOKUP(B25, '[1]DataLookUp - InternalCareer(LP)'!$B$4:$D$620, 3, FALSE)) -> Al Amin | E25: =IF(EXACT($D25, ""), "", VLOOKUP($D25, [2]DataLookUp!$B$4:$C$84, 2, FALSE)) | H25: =H24 + IF(EXACT(I25, ""), 0, 1) -> 225000000000002 | I25: =IF(EXACT(D25, ""), "", CONCATENATE("PERFORM ""SchData-OLTP-HumanResource"".""Func_TblMapper_WorkerCareerInternalToUserRole_SET""(varSystemLoginSession, null::bigint, null::varchar, null::timestamptz, null::timestamptz, null::varchar, varInstitutionBranchID, varBaseCurrencyID, ", IF(EXACT(B25, ""), "null", B25), "::bigint, ", IF(EXACT(D25, ""), "null", D25), "::bigint, ", IF(EXACT(F25, ""), "null", F25), "::bigint);"))
B26: =IF(EXACT('[1]DataLookUp - InternalCareer(LP)'!$B26, ""), "", '[1]DataLookUp - InternalCareer(LP)'!$B26) -> 164000000000023 | C26: =IF(EXACT($B26, ""), "", VLOOKUP(B26, '[1]DataLookUp - InternalCareer(LP)'!$B$4:$D$620, 3, FALSE)) -> Aldi Mulyadi | D26: =[2]MAIN!$D$50 -> 95000000000039 | E26: =IF(EXACT($D26, ""), "", VLOOKUP($D26, [2]DataLookUp!$B$4:$C$84, 2, FALSE)) -> IT Software Engineer Staff | H26: =H25 + IF(EXACT(I26, ""), 0, 1) -> 225000000000003 | I26: =IF(EXACT(D26, ""), "", CONCATENATE("PERFORM ""SchData-OLTP-HumanResource"".""Func_TblMapper_WorkerCareerInternalToUserRole_SET""(varSystemLoginSession, null::bigint, null::varchar, null::timestamptz, null::timestamptz, null::varchar, varInstitutionBranchID, varBaseCurrencyID, ", IF(EXACT(B26, ""), "null", B26), "::bigint, ", IF(EXACT(D26, ""), "null", D26), "::bigint, ", IF(EXACT(F26, ""), "null", F26), "::bigint);")) -> PERFORM "SchData-OLTP-HumanResource"."Func_TblMapper_WorkerCareerInternalToUserRole_SET"(varSystemLoginSession, null::bigint, null::varchar, null::timestamptz, null::timestamptz, null::varchar, varInstitutionBranchID, varBaseCurrencyID, 164000000000023::bigint, 95000000000039::bigint, null::bigint);
B27: =IF(EXACT('[1]DataLookUp - InternalCareer(LP)'!$B27, ""), "", '[1]DataLookUp - InternalCareer(LP)'!$B27) -> 164000000000024 | C27: =IF(EXACT($B27, ""), "", VLOOKUP(B27, '[1]DataLookUp - InternalCareer(LP)'!$B$4:$D$620, 3, FALSE)) -> Alexandri | E27: =IF(EXACT($D27, ""), "", VLOOKUP($D27, [2]DataLookUp!$B$4:$C$84, 2, FALSE)) | H27: =H26 + IF(EXACT(I27, ""), 0, 1) -> 225000000000003 | I27: =IF(EXACT(D27, ""), "", CONCATENATE("PERFORM ""SchData-OLTP-HumanResource"".""Func_TblMapper_WorkerCareerInternalToUserRole_SET""(varSystemLoginSession, null::bigint, null::varchar, null::timestamptz, null::timestamptz, null::varchar, varInstitutionBranchID, varBaseCurrencyID, ", IF(EXACT(B27, ""), "null", B27), "::bigint, ", IF(EXACT(D27, ""), "null", D27), "::bigint, ", IF(EXACT(F27, ""), "null", F27), "::bigint);"))
B28: =IF(EXACT('[1]DataLookUp - InternalCareer(LP)'!$B28, ""), "", '[1]DataLookUp - InternalCareer(LP)'!$B28) -> 164000000000025 | C28: =IF(EXACT($B28, ""), "", VLOOKUP(B28, '[1]DataLookUp - InternalCareer(LP)'!$B$4:$D$620, 3, FALSE)) -> Alfaedi | E28: =IF(EXACT($D28, ""), "", VLOOKUP($D28, [2]DataLookUp!$B$4:$C$84, 2, FALSE)) | H28: =H27 + IF(EXACT(I28, ""), 0, 1) -> 225000000000003 | I28: =IF(EXACT(D28, ""), "", CONCATENATE("PERFORM ""SchData-OLTP-HumanResource"".""Func_TblMapper_WorkerCareerInternalToUserRole_SET""(varSystemLoginSession, null::bigint, null::varchar, null::timestamptz, null::timestamptz, null::varchar, varInstitutionBranchID, varBaseCurrencyID, ", IF(EXACT(B28, ""), "null", B28), "::bigint, ", IF(EXACT(D28, ""), "null", D28), "::bigint, ", IF(EXACT(F28, ""), "null", F28), "::bigint);"))
B29: =IF(EXACT('[1]DataLookUp - InternalCareer(LP)'!$B29, ""), "", '[1]DataLookUp - InternalCareer(LP)'!$B29) -> 164000000000026 | C29: =IF(EXACT($B29, ""), "", VLOOKUP(B29, '[1]DataLookUp - InternalCareer(LP)'!$B$4:$D$620, 3, FALSE)) -> Ali Wahono | E29: =IF(EXACT($D29, ""), "", VLOOKUP($D29, [2]DataLookUp!$B$4:$C$84, 2, FALSE)) | H29: =H28 + IF(EXACT(I29, ""), 0, 1) -> 225000000000003 | I29: =IF(EXACT(D29, ""), "", CONCATENATE("PERFORM ""SchData-OLTP-HumanResource"".""Func_TblMapper_WorkerCareerInternalToUserRole_SET""(varSystemLoginSession, null::bigint, null::varchar, null::timestamptz, null::timestamptz, null::varchar, varInstitutionBranchID, varBaseCurrencyID, ", IF(EXACT(B29, ""), "null", B29), "::bigint, ", IF(EXACT(D29, ""), "null", D29), "::bigint, ", IF(EXACT(F29, ""), "null", F29), "::bigint);"))
B30: =IF(EXACT('[1]DataLookUp - InternalCareer(LP)'!$B30, ""), "", '[1]DataLookUp - InternalCareer(LP)'!$B30) -> 164000000000027 | C30: =IF(EXACT($B30, ""), "", VLOOKUP(B30, '[1]DataLookUp - InternalCareer(LP)'!$B$4:$D$620, 3, FALSE)) -> Alphaliyanri Lasria | E30: =IF(EXACT($D30, ""), "", VLOOKUP($D30, [2]DataLookUp!$B$4:$C$84, 2, FALSE)) | H30: =H29 + IF(EXACT(I30, ""), 0, 1) -> 225000000000003 | I30: =IF(EXACT(D30, ""), "", CONCATENATE("PERFORM ""SchData-OLTP-HumanResource"".""Func_TblMapper_WorkerCareerInternalToUserRole_SET""(varSystemLoginSession, null::bigint, null::varchar, null::timestamptz, null::timestamptz, null::varchar, varInstitutionBranchID, varBaseCurrencyID, ", IF(EXACT(B30, ""), "null", B30), "::bigint, ", IF(EXACT(D30, ""), "null", D30), "::bigint, ", IF(EXACT(F30, ""), "null", F30), "::bigint);"))
B31: =IF(EXACT('[1]DataLookUp - InternalCareer(LP)'!$B31, ""), "", '[1]DataLookUp - InternalCareer(LP)'!$B31) -> 164000000000028 | C31: =IF(EXACT($B31, ""), "", VLOOKUP(B31, '[1]DataLookUp - InternalCareer(LP)'!$B$4:$D$620, 3, FALSE)) -> Ambon Rumalean | E31: =IF(EXACT($D31, ""), "", VLOOKUP($D31, [2]DataLookUp!$B$4:$C$84, 2, FALSE)) | H31: =H30 + IF(EXACT(I31, ""), 0, 1) -> 225000000000003 | I31: =IF(EXACT(D31, ""), "", CONCATENATE("PERFORM ""SchData-OLTP-HumanResource"".""Func_TblMapper_WorkerCareerInternalToUserRole_SET""(varSystemLoginSession, null::bigint, null::varchar, null::timestamptz, null::timestamptz, null::varchar, varInstitutionBranchID, varBaseCurrencyID, ", IF(EXACT(B31, ""), "null", B31), "::bigint, ", IF(EXACT(D31, ""), "null", D31), "::bigint, ", IF(EXACT(F31, ""), "null", F31), "::bigint);"))
B32: =IF(EXACT('[1]DataLookUp - InternalCareer(LP)'!$B32, ""), "", '[1]DataLookUp - InternalCareer(LP)'!$B32) -> 164000000000029 | C32: =IF(EXACT($B32, ""), "", VLOOKUP(B32, '[1]DataLookUp - InternalCareer(LP)'!$B$4:$D$620, 3, FALSE)) -> Amir Sofyan Hadi | E32: =IF(EXACT($D32, ""), "", VLOOKUP($D32, [2]DataLookUp!$B$4:$C$84, 2, FALSE)) | H32: =H31 + IF(EXACT(I32, ""), 0, 1) -> 225000000000003 | I32: =IF(EXACT(D32, ""), "", CONCATENATE("PERFORM ""SchData-OLTP-HumanResource"".""Func_TblMapper_WorkerCareerInternalToUserRole_SET""(varSystemLoginSession, null::bigint, null::varchar, null::timestamptz, null::timestamptz, null::varchar, varInstitutionBranchID, varBaseCurrencyID, ", IF(EXACT(B32, ""), "null", B32), "::bigint, ", IF(EXACT(D32, ""), "null", D32), "::bigint, ", IF(EXACT(F32, ""), "null", F32), "::bigint);"))
B33: =IF(EXACT('[1]DataLookUp - InternalCareer(LP)'!$B33, ""), "", '[1]DataLookUp - InternalCareer(LP)'!$B33) -> 164000000000030 | C33: =IF(EXACT($B33, ""), "", VLOOKUP(B33, '[1]DataLookUp - InternalCareer(LP)'!$B$4:$D$620, 3, FALSE)) -> Anak Agung Netti Ariani | E33: =IF(EXACT($D33, ""), "", VLOOKUP($D33, [2]DataLookUp!$B$4:$C$84, 2, FALSE)) | H33: =H32 + IF(EXACT(I33, ""), 0, 1) -> 225000000000003 | I33: =IF(EXACT(D33, ""), "", CONCATENATE("PERFORM ""SchData-OLTP-HumanResource"".""Func_TblMapper_WorkerCareerInternalToUserRole_SET""(varSystemLoginSession, null::bigint, null::varchar, null::timestamptz, null::timestamptz, null::varchar, varInstitutionBranchID, varBaseCurrencyID, ", IF(EXACT(B33, ""), "null", B33), "::bigint, ", IF(EXACT(D33, ""), "null", D33), "::bigint, ", IF(EXACT(F33, ""), "null", F33), "::bigint);"))
B34: =IF(EXACT('[1]DataLookUp - InternalCareer(LP)'!$B34, ""), "", '[1]DataLookUp - InternalCareer(LP)'!$B34) -> 164000000000031 | C34: =IF(EXACT($B34, ""), "", VLOOKUP(B34, '[1]DataLookUp - InternalCareer(LP)'!$B$4:$D$620, 3, FALSE)) -> Andri Gunawan | E34: =IF(EXACT($D34, ""), "", VLOOKUP($D34, [2]DataLookUp!$B$4:$C$84, 2, FALSE)) | H34: =H33 + IF(EXACT(I34, ""), 0, 1) -> 225000000000003 | I34: =IF(EXACT(D34, ""), "", CONCATENATE("PERFORM ""SchData-OLTP-HumanResource"".""Func_TblMapper_WorkerCareerInternalToUserRole_SET""(varSystemLoginSession, null::bigint, null::varchar, null::timestamptz, null::timestamptz, null::varchar, varInstitutionBranchID, varBaseCurrencyID, ", IF(EXACT(B34, ""), "null", B34), "::bigint, ", IF(EXACT(D34, ""), "null", D34), "::bigint, ", IF(EXACT(F34, ""), "null", F34), "::bigint);"))
B35: =IF(EXACT('[1]DataLookUp - InternalCareer(LP)'!$B35, ""), "", '[1]DataLookUp - InternalCareer(LP)'!$B35) -> 164000000000032 | C35: =IF(EXACT($B35, ""), "", VLOOKUP(B35, '[1]DataLookUp - InternalCareer(LP)'!$B$4:$D$620, 3, FALSE)) -> Andri Herdiansyah | E35: =IF(EXACT($D35, ""), "", VLOOKUP($D35, [2]DataLookUp!$B$4:$C$84, 2, FALSE)) | H35: =H34 + IF(EXACT(I35, ""), 0, 1) -> 225000000000003 | I35: =IF(EXACT(D35, ""), "", CONCATENATE("PERFORM ""SchData-OLTP-HumanResource"".""Func_TblMapper_WorkerCareerInternalToUserRole_SET""(varSystemLoginSession, null::bigint, null::varchar, null::timestamptz, null::timestamptz, null::varchar, varInstitutionBranchID, varBaseCurrencyID, ", IF(EXACT(B35, ""), "null", B35), "::bigint, ", IF(EXACT(D35, ""), "null", D35), "::bigint, ", IF(EXACT(F35, ""), "null", F35), "::bigint);"))
B36: =IF(EXACT('[1]DataLookUp - InternalCareer(LP)'!$B36, ""), "", '[1]DataLookUp - InternalCareer(LP)'!$B36) -> 164000000000033 | C36: =IF(EXACT($B36, ""), "", VLOOKUP(B36, '[1]DataLookUp - InternalCareer(LP)'!$B$4:$D$620, 3, FALSE)) -> Andrie | E36: =IF(EXACT($D36, ""), "", VLOOKUP($D36, [2]DataLookUp!$B$4:$C$84, 2, FALSE)) | H36: =H35 + IF(EXACT(I36, ""), 0, 1) -> 225000000000003 | I36: =IF(EXACT(D36, ""), "", CONCATENATE("PERFORM ""SchData-OLTP-HumanResource"".""Func_TblMapper_WorkerCareerInternalToUserRole_SET""(varSystemLoginSession, null::bigint, null::varchar, null::timestamptz, null::timestamptz, null::varchar, varInstitutionBranchID, varBaseCurrencyID, ", IF(EXACT(B36, ""), "null", B36), "::bigint, ", IF(EXACT(D36, ""), "null", D36), "::bigint, ", IF(EXACT(F36, ""), "null", F36), "::bigint);"))
B37: =IF(EXACT('[1]DataLookUp - InternalCareer(LP)'!$B37, ""), "", '[1]DataLookUp - InternalCareer(LP)'!$B37) -> 164000000000034 | C37: =IF(EXACT($B37, ""), "", VLOOKUP(B37, '[1]DataLookUp - InternalCareer(LP)'!$B$4:$D$620, 3, FALSE)) -> Anggina Tri Yudandi | E37: =IF(EXACT($D37, ""), "", VLOOKUP($D37, [2]DataLookUp!$B$4:$C$84, 2, FALSE)) | H37: =H36 + IF(EXACT(I37, ""), 0, 1) -> 225000000000003 | I37: =IF(EXACT(D37, ""), "", CONCATENATE("PERFORM ""SchData-OLTP-HumanResource"".""Func_TblMapper_WorkerCareerInternalToUserRole_SET""(varSystemLoginSession, null::bigint, null::varchar, null::timestamptz, null::timestamptz, null::varchar, varInstitutionBranchID, varBaseCurrencyID, ", IF(EXACT(B37, ""), "null", B37), "::bigint, ", IF(EXACT(D37, ""), "null", D37), "::bigint, ", IF(EXACT(F37, ""), "null", F37), "::bigint);"))
B38: =IF(EXACT('[1]DataLookUp - InternalCareer(LP)'!$B38, ""), "", '[1]DataLookUp - InternalCareer(LP)'!$B38) -> 164000000000035 | C38: =IF(EXACT($B38, ""), "", VLOOKUP(B38, '[1]DataLookUp - InternalCareer(LP)'!$B$4:$D$620, 3, FALSE)) -> Anggit Ismiyanto | E38: =IF(EXACT($D38, ""), "", VLOOKUP($D38, [2]DataLookUp!$B$4:$C$84, 2, FALSE)) | H38: =H37 + IF(EXACT(I38, ""), 0, 1) -> 225000000000003 | I38: =IF(EXACT(D38, ""), "", CONCATENATE("PERFORM ""SchData-OLTP-HumanResource"".""Func_TblMapper_WorkerCareerInternalToUserRole_SET""(varSystemLoginSession, null::bigint, null::varchar, null::timestamptz, null::timestamptz, null::varchar, varInstitutionBranchID, varBaseCurrencyID, ", IF(EXACT(B38, ""), "null", B38), "::bigint, ", IF(EXACT(D38, ""), "null", D38), "::bigint, ", IF(EXACT(F38, ""), "null", F38), "::bigint);"))
... B77: =IF(EXACT('[1]DataLookUp - InternalCareer(LP)'!$B77, ""), "", '[1]DataLookUp - InternalCareer(LP)'!$B77) -> 164000000000074 | C77: =IF(EXACT($B77, ""), "", VLOOKUP(B77, '[1]DataLookUp - InternalCareer(LP)'!$B$4:$D$620, 3, FALSE)) -> Bela Retmalantika | E77: =IF(EXACT($D77, ""), "", VLOOKUP($D77, [2]DataLookUp!$B$4:$C$84, 2, FALSE)) | H77: =H76 + IF(EXACT(I77, ""), 0, 1) -> 225000000000003 | I77: =IF(EXACT(D77, ""), "", CONCATENATE("PERFORM ""SchData-OLTP-HumanResource"".""Func_TblMapper_WorkerCareerInternalToUserRole_SET""(varSystemLoginSession, null::bigint, null::varchar, null::timestamptz, null::timestamptz, null::varchar, varInstitutionBranchID, varBaseCurrencyID, ", IF(EXACT(B77, ""), "null", B77), "::bigint, ", IF(EXACT(D77, ""), "null", D77), "::bigint, ", IF(EXACT(F77, ""), "null", F77), "::bigint);"))
B78: =IF(EXACT('[1]DataLookUp - InternalCareer(LP)'!$B78, ""), "", '[1]DataLookUp - InternalCareer(LP)'!$B78) -> 164000000000075 | C78: =IF(EXACT($B78, ""), "", VLOOKUP(B78, '[1]DataLookUp - InternalCareer(LP)'!$B$4:$D$620, 3, FALSE)) -> Belina Lindarwani | D78: =[2]MAIN!$D$44 -> 95000000000034 | E78: =IF(EXACT($D78, ""), "", VLOOKUP($D78, [2]DataLookUp!$B$4:$C$84, 2, FALSE)) -> Accounting & Tax Staff | H78: =H77 + IF(EXACT(I78, ""), 0, 1) -> 225000000000004 | I78: =IF(EXACT(D78, ""), "", CONCATENATE("PERFORM ""SchData-OLTP-HumanResource"".""Func_TblMapper_WorkerCareerInternalToUserRole_SET""(varSystemLoginSession, null::bigint, null::varchar, null::timestamptz, null::timestamptz, null::varchar, varInstitutionBranchID, varBaseCurrencyID, ", IF(EXACT(B78, ""), "null", B78), "::bigint, ", IF(EXACT(D78, ""), "null", D78), "::bigint, ", IF(EXACT(F78, ""), "null", F78), "::bigint);")) -> PERFORM "SchData-OLTP-HumanResource"."Func_TblMapper_WorkerCareerInternalToUserRole_SET"(varSystemLoginSession, null::bigint, null::varchar, null::timestamptz, null::timestamptz, null::varchar, varInstitutionBranchID, varBaseCurrencyID, 164000000000075::bigint, 95000000000034::bigint, null::bigint);
B79: =IF(EXACT('[1]DataLookUp - InternalCareer(LP)'!$B79, ""), "", '[1]DataLookUp - InternalCareer(LP)'!$B79) -> 164000000000076 | C79: =IF(EXACT($B79, ""), "", VLOOKUP(B79, '[1]DataLookUp - InternalCareer(LP)'!$B$4:$D$620, 3, FALSE)) -> Benita Sofia | E79: =IF(EXACT($D79, ""), "", VLOOKUP($D79, [2]DataLookUp!$B$4:$C$84, 2, FALSE)) | H79: =H78 + IF(EXACT(I79, ""), 0, 1) -> 225000000000004 | I79: =IF(EXACT(D79, ""), "", CONCATENATE("PERFORM ""SchData-OLTP-HumanResource"".""Func_TblMapper_WorkerCareerInternalToUserRole_SET""(varSystemLoginSession, null::bigint, null::varchar, null::timestamptz, null::timestamptz, null::varchar, varInstitutionBranchID, varBaseCurrencyID, ", IF(EXACT(B79, ""), "null", B79), "::bigint, ", IF(EXACT(D79, ""), "null", D79), "::bigint, ", IF(EXACT(F79, ""), "null", F79), "::bigint);"))
...

Sheet DataLookUp
B2: Sys_PID | C2: =MAIN!B2 -> Ref ID Worker Career Internal | D2: =MAIN!C2 -> Worker Name | E2: =MAIN!D2 -> Ref ID User Role | F2: =MAIN!F2 -> Ref ID Combined Budget
B4: =IF(EXACT(MAIN!I4, ""), "", MAIN!H4) | C4: =IF(EXACT(MAIN!$I4, ""), "", MAIN!$B4) | D4: =IF(EXACT(MAIN!$I4, ""), "", MAIN!$C4) | E4: =IF(EXACT(MAIN!$I4, ""), "", MAIN!$D4) | F4: =IF(EXACT(MAIN!$I4, ""), "", ""&MAIN!$F4)
B5: =IF(EXACT(MAIN!I5, ""), "", MAIN!H5) | C5: =IF(EXACT(MAIN!$I5, ""), "", MAIN!$B5) | D5: =IF(EXACT(MAIN!$I5, ""), "", MAIN!$C5) | E5: =IF(EXACT(MAIN!$I5, ""), "", MAIN!$D5) | F5: =IF(EXACT(MAIN!$I5, ""), "", ""&MAIN!$F5)
B6: =IF(EXACT(MAIN!I6, ""), "", MAIN!H6) | C6: =IF(EXACT(MAIN!$I6, ""), "", MAIN!$B6) | D6: =IF(EXACT(MAIN!$I6, ""), "", MAIN!$C6) | E6: =IF(EXACT(MAIN!$I6, ""), "", MAIN!$D6) | F6: =IF(EXACT(MAIN!$I6, ""), "", ""&MAIN!$F6)
B7: =IF(EXACT(MAIN!I7, ""), "", MAIN!H7) | C7: =IF(EXACT(MAIN!$I7, ""), "", MAIN!$B7) | D7: =IF(EXACT(MAIN!$I7, ""), "", MAIN!$C7) | E7: =IF(EXACT(MAIN!$I7, ""), "", MAIN!$D7) | F7: =IF(EXACT(MAIN!$I7, ""), "", ""&MAIN!$F7)
B8: =IF(EXACT(MAIN!I8, ""), "", MAIN!H8) | C8: =IF(EXACT(MAIN!$I8, ""), "", MAIN!$B8) | D8: =IF(EXACT(MAIN!$I8, ""), "", MAIN!$C8) | E8: =IF(EXACT(MAIN!$I8, ""), "", MAIN!$D8) | F8: =IF(EXACT(MAIN!$I8, ""), "", ""&MAIN!$F8)
B9: =IF(EXACT(MAIN!I9, ""), "", MAIN!H9) | C9: =IF(EXACT(MAIN!$I9, ""), "", MAIN!$B9) | D9: =IF(EXACT(MAIN!$I9, ""), "", MAIN!$C9) | E9: =IF(EXACT(MAIN!$I9, ""), "", MAIN!$D9) | F9: =IF(EXACT(MAIN!$I9, ""), "", ""&MAIN!$F9)
B10: =IF(EXACT(MAIN!I10, ""), "", MAIN!H10) | C10: =IF(EXACT(MAIN!$I10, ""), "", MAIN!$B10) | D10: =IF(EXACT(MAIN!$I10, ""), "", MAIN!$C10) | E10: =IF(EXACT(MAIN!$I10, ""), "", MAIN!$D10) | F10: =IF(EXACT(MAIN!$I10, ""), "", ""&MAIN!$F10)
B11: =IF(EXACT(MAIN!I11, ""), "", MAIN!H11) | C11: =IF(EXACT(MAIN!$I11, ""), "", MAIN!$B11) | D11: =IF(EXACT(MAIN!$I11, ""), "", MAIN!$C11) | E11: =IF(EXACT(MAIN!$I11, ""), "", MAIN!$D11) | F11: =IF(EXACT(MAIN!$I11, ""), "", ""&MAIN!$F11)
B12: =IF(EXACT(MAIN!I12, ""), "", MAIN!H12) | C12: =IF(EXACT(MAIN!$I12, ""), "", MAIN!$B12) | D12: =IF(EXACT(MAIN!$I12, ""), "", MAIN!$C12) | E12: =IF(EXACT(MAIN!$I12, ""), "", MAIN!$D12) | F12: =IF(EXACT(MAIN!$I12, ""), "", ""&MAIN!$F12)
B13: =IF(EXACT(MAIN!I13, ""), "", MAIN!H13) | C13: =IF(EXACT(MAIN!$I13, ""), "", MAIN!$B13) | D13: =IF(EXACT(MAIN!$I13, ""), "", MAIN!$C13) | E13: =IF(EXACT(MAIN!$I13, ""), "", MAIN!$D13) | F13: =IF(EXACT(MAIN!$I13, ""), "", ""&MAIN!$F13)
B14: =IF(EXACT(MAIN!I14, ""), "", MAIN!H14) | C14: =IF(EXACT(MAIN!$I14, ""), "", MAIN!$B14) | D14: =IF(EXACT(MAIN!$I14, ""), "", MAIN!$C14) | E14: =IF(EXACT(MAIN!$I14, ""), "", MAIN!$D14) | F14: =IF(EXACT(MAIN!$I14, ""), "", ""&MAIN!$F14)
B15: =IF(EXACT(MAIN!$I15, ""), "", MAIN!$H15) -> 225000000000001 | C15: =IF(EXACT(MAIN!$I15, ""), "", MAIN!$B15) -> 164000000000012 | D15: =IF(EXACT(MAIN!$I15, ""), "", MAIN!$C15) -> Agnes Sutedja | E15: =IF(EXACT(MAIN!$I15, ""), "", MAIN!$D15) -> 95000000000048 | F15: =IF(EXACT(MAIN!$I15, ""), "", ""&MAIN!$F15)
B16: =IF(EXACT(MAIN!I16, ""), "", MAIN!H16) | C16: =IF(EXACT(MAIN!$I16, ""), "", MAIN!$B16) | D16: =IF(EXACT(MAIN!$I16, ""), "", MAIN!$C16) | E16: =IF(EXACT(MAIN!$I16, ""), "", MAIN!$D16) | F16: =IF(EXACT(MAIN!$I16, ""), "", ""&MAIN!$F16)
B17: =IF(EXACT(MAIN!I17, ""), "", MAIN!H17) | C17: =IF(EXACT(MAIN!$I17, ""), "", MAIN!$B17) | D17: =IF(EXACT(MAIN!$I17, ""), "", MAIN!$C17) | E17: =IF(EXACT(MAIN!$I17, ""), "", MAIN!$D17) | F17: =IF(EXACT(MAIN!$I17, ""), "", ""&MAIN!$F17)
B18: =IF(EXACT(MAIN!I18, ""), "", MAIN!H18) | C18: =IF(EXACT(MAIN!$I18, ""), "", MAIN!$B18) | D18: =IF(EXACT(MAIN!$I18, ""), "", MAIN!$C18) | E18: =IF(EXACT(MAIN!$I18, ""), "", MAIN!$D18) | F18: =IF(EXACT(MAIN!$I18, ""), "", ""&MAIN!$F18)
B19: =IF(EXACT(MAIN!I19, ""), "", MAIN!H19) | C19: =IF(EXACT(MAIN!$I19, ""), "", MAIN!$B19) | D19: =IF(EXACT(MAIN!$I19, ""), "", MAIN!$C19) | E19: =IF(EXACT(MAIN!$I19, ""), "", MAIN!$D19) | F19: =IF(EXACT(MAIN!$I19, ""), "", ""&MAIN!$F19)
B20: =IF(EXACT(MAIN!I20, ""), "", MAIN!H20) -> 225000000000002 | C20: =IF(EXACT(MAIN!$I20, ""), "", MAIN!$B20) -> 164000000000017 | D20: =IF(EXACT(MAIN!$I20, ""), "", MAIN!$C20) -> Ahmad Faiz Haems Muda | E20: =IF(EXACT(MAIN!$I20, ""), "", MAIN!$D20) -> 95000000000017 | F20: =IF(EXACT(MAIN!$I20, ""), "", ""&MAIN!$F20)
B21: =IF(EXACT(MAIN!I21, ""), "", MAIN!H21) | C21: =IF(EXACT(MAIN!$I21, ""), "", MAIN!$B21) | D21: =IF(EXACT(MAIN!$I21, ""), "", MAIN!$C21) | E21: =IF(EXACT(MAIN!$I21, ""), "", MAIN!$D21) | F21: =IF(EXACT(MAIN!$I21, ""), "", ""&MAIN!$F21)
B22: =IF(EXACT(MAIN!I22, ""), "", MAIN!H22) | C22: =IF(EXACT(MAIN!$I22, ""), "", MAIN!$B22) | D22: =IF(EXACT(MAIN!$I22, ""), "", MAIN!$C22) | E22: =IF(EXACT(MAIN!$I22, ""), "", MAIN!$D22) | F22: =IF(EXACT(MAIN!$I22, ""), "", ""&MAIN!$F22)
B23: =IF(EXACT(MAIN!I23, ""), "", MAIN!H23) | C23: =IF(EXACT(MAIN!$I23, ""), "", MAIN!$B23) | D23: =IF(EXACT(MAIN!$I23, ""), "", MAIN!$C23) | E23: =IF(EXACT(MAIN!$I23, ""), "", MAIN!$D23) | F23: =IF(EXACT(MAIN!$I23, ""), "", ""&MAIN!$F23)
B24: =IF(EXACT(MAIN!I24, ""), "", MAIN!H24) | C24: =IF(EXACT(MAIN!$I24, ""), "", MAIN!$B24) | D24: =IF(EXACT(MAIN!$I24, ""), "", MAIN!$C24) | E24: =IF(EXACT(MAIN!$I24, ""), "", MAIN!$D24) | F24: =IF(EXACT(MAIN!$I24, ""), "", ""&MAIN!$F24)
B25: =IF(EXACT(MAIN!I25, ""), "", MAIN!H25) | C25: =IF(EXACT(MAIN!$I25, ""), "", MAIN!$B25) | D25: =IF(EXACT(MAIN!$I25, ""), "", MAIN!$C25) | E25: =IF(EXACT(MAIN!$I25, ""), "", MAIN!$D25) | F25: =IF(EXACT(MAIN!$I25, ""), "", ""&MAIN!$F25)
B26: =IF(EXACT(MAIN!I26, ""), "", MAIN!H26) -> 225000000000003 | C26: =IF(EXACT(MAIN!$I26, ""), "", MAIN!$B26) -> 164000000000023 | D26: =IF(EXACT(MAIN!$I26, ""), "", MAIN!$C26) -> Aldi Mulyadi | E26: =IF(EXACT(MAIN!$I26, ""), "", MAIN!$D26) -> 95000000000039 | F26: =IF(EXACT(MAIN!$I26, ""), "", ""&MAIN!$F26)
B27: =IF(EXACT(MAIN!I27, ""), "", MAIN!H27) | C27: =IF(EXACT(MAIN!$I27, ""), "", MAIN!$B27) | D27: =IF(EXACT(MAIN!$I27, ""), "", MAIN!$C27) | E27: =IF(EXACT(MAIN!$I27, ""), "", MAIN!$D27) | F27: =IF(EXACT(MAIN!$I27, ""), "", ""&MAIN!$F27)
... B586: =IF(EXACT(MAIN!I586, ""), "", MAIN!H586) | C586: =IF(EXACT(MAIN!$I586, ""), "", MAIN!$B586) | D586: =IF(EXACT(MAIN!$I586, ""), "", MAIN!$C586) | E586: =IF(EXACT(MAIN!$I586, ""), "", MAIN!$D586) | F586: =IF(EXACT(MAIN!$I586, ""), "", ""&MAIN!$F586)
B587: =IF(EXACT(MAIN!I587, ""), "", MAIN!H587) | C587: =IF(EXACT(MAIN!$I587, ""), "", MAIN!$B587) | D587: =IF(EXACT(MAIN!$I587, ""), "", MAIN!$C587) | E587: =IF(EXACT(MAIN!$I587, ""), "", MAIN!$D587)
B588: =IF(EXACT(MAIN!I588, ""), "", MAIN!H588) | C588: =IF(EXACT(MAIN!$I588, ""), "", MAIN!$B588) | D588: =IF(EXACT(MAIN!$I588, ""), "", MAIN!$C588) | E588: =IF(EXACT(MAIN!$I588, ""), "", MAIN!$D588)
B589: =IF(EXACT(MAIN!I589, ""), "", MAIN!H589) | C589: =IF(EXACT(MAIN!$I589, ""), "", MAIN!$B589) | D589: =IF(EXACT(MAIN!$I589, ""), "", MAIN!$C589) | E589: =IF(EXACT(MAIN!$I589, ""), "", MAIN!$D589)
B590: =IF(EXACT(MAIN!I590, ""), "", MAIN!H590) -> 225000000000054 | C590: =IF(EXACT(MAIN!$I590, ""), "", MAIN!$B590) -> 164000000000587 | D590: =IF(EXACT(MAIN!$I590, ""), "", MAIN!$C590) -> Firmansyah Awaludin | E590: =IF(EXACT(MAIN!$I590, ""), "", MAIN!$D590) -> 95000000000029
B591: =IF(EXACT(MAIN!I591, ""), "", MAIN!H591) -> 225000000000055 | C591: =IF(EXACT(MAIN!$I591, ""), "", MAIN!$B591) -> 164000000000588 | D591: =IF(EXACT(MAIN!$I591, ""), "", MAIN!$C591) -> Iman Faisal Abdurahman | E591: =IF(EXACT(MAIN!$I591, ""), "", MAIN!$D591) -> 95000000000008 | F591: =IF(EXACT(MAIN!$I587, ""), "", ""&MAIN!$F587)
B592: =IF(EXACT(MAIN!I592, ""), "", MAIN!H592) | C592: =IF(EXACT(MAIN!$I592, ""), "", MAIN!$B592) | D592: =IF(EXACT(MAIN!$I592, ""), "", MAIN!$C592) | E592: =IF(EXACT(MAIN!$I592, ""), "", MAIN!$D592) | F592: =IF(EXACT(MAIN!$I588, ""), "", ""&MAIN!$F588)
B593: =IF(EXACT(MAIN!I593, ""), "", MAIN!H593) | C593: =IF(EXACT(MAIN!$I593, ""), "", MAIN!$B593) | D593: =IF(EXACT(MAIN!$I593, ""), "", MAIN!$C593) | E593: =IF(EXACT(MAIN!$I593, ""), "", MAIN!$D593) | F593: =IF(EXACT(MAIN!$I589, ""), "", ""&MAIN!$F589)
B594: =IF(EXACT(MAIN!I594, ""), "", MAIN!H594) | C594: =IF(EXACT(MAIN!$I594, ""), "", MAIN!$B594) | D594: =IF(EXACT(MAIN!$I594, ""), "", MAIN!$C594) | E594: =IF(EXACT(MAIN!$I594, ""), "", MAIN!$D594) | F594: =IF(EXACT(MAIN!$I590, ""), "", ""&MAIN!$F590)
B595: =IF(EXACT(MAIN!I595, ""), "", MAIN!H595) -> 225000000000056 | C595: =IF(EXACT(MAIN!$I595, ""), "", MAIN!$B595) -> 164000000000592 | D595: =IF(EXACT(MAIN!$I595, ""), "", MAIN!$C595) -> Ahmad Sandi Asyuri | E595: =IF(EXACT(MAIN!$I595, ""), "", MAIN!$D595) -> 95000000000065 | F595: =IF(EXACT(MAIN!$I591, ""), "", ""&MAIN!$F591)
B596: =IF(EXACT(MAIN!I596, ""), "", MAIN!H596) -> 225000000000057 | C596: =IF(EXACT(MAIN!$I596, ""), "", MAIN!$B596) -> 164000000000593 | D596: =IF(EXACT(MAIN!$I596, ""), "", MAIN!$C596) -> Andi Mapasoro | E596: =IF(EXACT(MAIN!$I596, ""), "", MAIN!$D596) -> 95000000000019 | F596: =IF(EXACT(MAIN!$I592, ""), "", ""&MAIN!$F592)
B597: =IF(EXACT(MAIN!I597, ""), "", MAIN!H597) | C597: =IF(EXACT(MAIN!$I597, ""), "", MAIN!$B597) | D597: =IF(EXACT(MAIN!$I597, ""), "", MAIN!$C597) | E597: =IF(EXACT(MAIN!$I597, ""), "", MAIN!$D597) | F597: =IF(EXACT(MAIN!$I593, ""), "", ""&MAIN!$F593)
B598: =IF(EXACT(MAIN!I598, ""), "", MAIN!H598) | C598: =IF(EXACT(MAIN!$I598, ""), "", MAIN!$B598) | D598: =IF(EXACT(MAIN!$I598, ""), "", MAIN!$C598) | E598: =IF(EXACT(MAIN!$I598, ""), "", MAIN!$D598) | F598: =IF(EXACT(MAIN!$I594, ""), "", ""&MAIN!$F594)
B599: =IF(EXACT(MAIN!I599, ""), "", MAIN!H599) -> 225000000000058 | C599: =IF(EXACT(MAIN!$I599, ""), "", MAIN!$B599) -> 164000000000596 | D599: =IF(EXACT(MAIN!$I599, ""), "", MAIN!$C599) -> Burhan | E599: =IF(EXACT(MAIN!$I599, ""), "", MAIN!$D599) -> 95000000000003 | F599: =IF(EXACT(MAIN!$I595, ""), "", ""&MAIN!$F595)
B600: =IF(EXACT(MAIN!I600, ""), "", MAIN!H600) | C600: =IF(EXACT(MAIN!$I600, ""), "", MAIN!$B600) | D600: =IF(EXACT(MAIN!$I600, ""), "", MAIN!$C600) | E600: =IF(EXACT(MAIN!$I600, ""), "", MAIN!$D600) | F600: =IF(EXACT(MAIN!$I596, ""), "", ""&MAIN!$F596)
...
