Workbook

Sheet MAIN
B2: Bank Name | C2: Acronym | D2: SWIFT Code | F2: SYS_PID Prediction | G2: SQL Syntax
F3: 166000000000000
B4: Bank Mandiri | D4: BMRIIDJA | F4: =F3 + IF(EXACT(G4, ""), 0, 1) -> 166000000000001 | G4: =IF(EXACT(B4, ""), "", CONCATENATE("PERFORM ""SchData-OLTP-Master"".""Func_TblBank_SET""(varSystemLoginSession, null::bigint, null::varchar, null::varchar, varInstitutionBranchID, varBaseCurrencyID, '", B4, "', ", IF(EXACT(C4, ""), "null", CONCATENATE("'", C4, "'")), ", '", D4, "');")) -> PERFORM "SchData-OLTP-Master"."Func_TblBank_SET"(varSystemLoginSession, null::bigint, null::varchar, null::varchar, varInstitutionBranchID, varBaseCurrencyID, 'Bank Mandiri', null, 'BMRIIDJA');
B5: Bank Rakyat Indonesia | C5: BRI | D5: BRINIDJA | F5: =F4 + IF(EXACT(G5, ""), 0, 1) -> 166000000000002 | G5: =IF(EXACT(B5, ""), "", CONCATENATE("PERFORM ""SchData-OLTP-Master"".""Func_TblBank_SET""(varSystemLoginSession, null::bigint, null::varchar, null::varchar, varInstitutionBranchID, varBaseCurrencyID, '", B5, "', ", IF(EXACT(C5, ""), "null", CONCATENATE("'", C5, "'")), ", '", D5, "');")) -> PERFORM "SchData-OLTP-Master"."Func_TblBank_SET"(varSystemLoginSession, null::bigint, null::varchar, null::varchar, varInstitutionBranchID, varBaseCurrencyID, 'Bank Rakyat Indonesia', 'BRI', 'BRINIDJA');
B6: Bank Negara Indonesia | C6: BNI | D6: BNINIDJA | F6: =F5 + IF(EXACT(G6, ""), 0, 1) -> 166000000000003 | G6: =IF(EXACT(B6, ""), "", CONCATENATE("PERFORM ""SchData-OLTP-Master"".""Func_TblBank_SET""(varSystemLoginSession, null::bigint, null::varchar, null::varchar, varInstitutionBranchID, varBaseCurrencyID, '", B6, "', ", IF(EXACT(C6, ""), "null", CONCATENATE("'", C6, "'")), ", '", D6, "');")) -> PERFORM "SchData-OLTP-Master"."Func_TblBank_SET"(varSystemLoginSession, null::bigint, null::varchar, null::varchar, varInstitutionBranchID, varBaseCurrencyID, 'Bank Negara Indonesia', 'BNI', 'BNINIDJA');
B7: Bank Tabungan Negara | C7: BTN | D7: BTANIDJA | F7: =F6 + IF(EXACT(G7, ""), 0, 1) -> 166000000000004 | G7: =IF(EXACT(B7, ""), "", CONCATENATE("PERFORM ""SchData-OLTP-Master"".""Func_TblBank_SET""(varSystemLoginSession, null::bigint, null::varchar, null::varchar, varInstitutionBranchID, varBaseCurrencyID, '", B7, "', ", IF(EXACT(C7, ""), "null", CONCATENATE("'", C7, "'")), ", '", D7, "');")) -> PERFORM "SchData-OLTP-Master"."Func_TblBank_SET"(varSystemLoginSession, null::bigint, null::varchar, null::varchar, varInstitutionBranchID, varBaseCurrencyID, 'Bank Tabungan Negara', 'BTN', 'BTANIDJA');
B8: Bank Central Asia | C8: BCA | D8: CENAIDJA | F8: =F7 + IF(EXACT(G8, ""), 0, 1) -> 166000000000005 | G8: =IF(EXACT(B8, ""), "", CONCATENATE("PERFORM ""SchData-OLTP-Master"".""Func_TblBank_SET""(varSystemLoginSession, null::bigint, null::varchar, null::varchar, varInstitutionBranchID, varBaseCurrencyID, '", B8, "', ", IF(EXACT(C8, ""), "null", CONCATENATE("'", C8, "'")), ", '", D8, "');")) -> PERFORM "SchData-OLTP-Master"."Func_TblBank_SET"(varSystemLoginSession, null::bigint, null::varchar, null::varchar, varInstitutionBranchID, varBaseCurrencyID, 'Bank Central Asia', 'BCA', 'CENAIDJA');
B9: Bank Mega | D9: MEGAIDJA | F9: =F8 + IF(EXACT(G9, ""), 0, 1) -> 166000000000006 | G9: =IF(EXACT(B9, ""), "", CONCATENATE("PERFORM ""SchData-OLTP-Master"".""Func_TblBank_SET""(varSystemLoginSession, null::bigint, null::varchar, null::varchar, varInstitutionBranchID, varBaseCurrencyID, '", B9, "', ", IF(EXACT(C9, ""), "null", CONCATENATE("'", C9, "'")), ", '", D9, "');")) -> PERFORM "SchData-OLTP-Master"."Func_TblBank_SET"(varSystemLoginSession, null::bigint, null::varchar, null::varchar, varInstitutionBranchID, varBaseCurrencyID, 'Bank Mega', null, 'MEGAIDJA');
B10: Bank Permata | D10: BBBAIDJA | F10: =F9 + IF(EXACT(G10, ""), 0, 1) -> 166000000000007 | G10: =IF(EXACT(B10, ""), "", CONCATENATE("PERFORM ""SchData-OLTP-Master"".""Func_TblBank_SET""(varSystemLoginSession, null::bigint, null::varchar, null::varchar, varInstitutionBranchID, varBaseCurrencyID, '", B10, "', ", IF(EXACT(C10, ""), "null", CONCATENATE("'", C10, "'")), ", '", D10, "');")) -> PERFORM "SchData-OLTP-Master"."Func_TblBank_SET"(varSystemLoginSession, null::bigint, null::varchar, null::varchar, varInstitutionBranchID, varBaseCurrencyID, 'Bank Permata', null, 'BBBAIDJA');
B11: Bank Danamon | D11: BDINIDJA | F11: =F10 + IF(EXACT(G11, ""), 0, 1) -> 166000000000008 | G11: =IF(EXACT(B11, ""), "", CONCATENATE("PERFORM ""SchData-OLTP-Master"".""Func_TblBank_SET""(varSystemLoginSession, null::bigint, null::varchar, null::varchar, varInstitutionBranchID, varBaseCurrencyID, '", B11, "', ", IF(EXACT(C11, ""), "null", CONCATENATE("'", C11, "'")), ", '", D11, "');")) -> PERFORM "SchData-OLTP-Master"."Func_TblBank_SET"(varSystemLoginSession, null::bigint, null::varchar, null::varchar, varInstitutionBranchID, varBaseCurrencyID, 'Bank Danamon', null, 'BDINIDJA');
B12: Bank KB Bukopin | D12: BBUKIDJA | F12: =F11 + IF(EXACT(G12, ""), 0, 1) -> 166000000000009 | G12: =IF(EXACT(B12, ""), "", CONCATENATE("PERFORM ""SchData-OLTP-Master"".""Func_TblBank_SET""(varSystemLoginSession, null::bigint, null::varchar, null::varchar, varInstitutionBranchID, varBaseCurrencyID, '", B12, "', ", IF(EXACT(C12, ""), "null", CONCATENATE("'", C12, "'")), ", '", D12, "');")) -> PERFORM "SchData-OLTP-Master"."Func_TblBank_SET"(varSystemLoginSession, null::bigint, null::varchar, null::varchar, varInstitutionBranchID, varBaseCurrencyID, 'Bank KB Bukopin', null, 'BBUKIDJA');
B13: Bank Syariah Indonesia | C13: BSI | D13: BSMDIDJA | F13: =F12 + IF(EXACT(G13, ""), 0, 1) -> 166000000000010 | G13: =IF(EXACT(B13, ""), "", CONCATENATE("PERFORM ""SchData-OLTP-Master"".""Func_TblBank_SET""(varSystemLoginSession, null::bigint, null::varchar, null::varchar, varInstitutionBranchID, varBaseCurrencyID, '", B13, "', ", IF(EXACT(C13, ""), "null", CONCATENATE("'", C13, "'")), ", '", D13, "');")) -> PERFORM "SchData-OLTP-Master"."Func_TblBank_SET"(varSystemLoginSession, null::bigint, null::varchar, null::varchar, varInstitutionBranchID, varBaseCurrencyID, 'Bank Syariah Indonesia', 'BSI', 'BSMDIDJA');
B14: Bank OCBC Nilai Inti Sari Penyimpanan | C14: OCBC NISP | D14: NISPIDJA | F14: =F13 + IF(EXACT(G14, ""), 0, 1) -> 166000000000011 | G14: =IF(EXACT(B14, ""), "", CONCATENATE("PERFORM ""SchData-OLTP-Master"".""Func_TblBank_SET""(varSystemLoginSession, null::bigint, null::varchar, null::varchar, varInstitutionBranchID, varBaseCurrencyID, '", B14, "', ", IF(EXACT(C14, ""), "null", CONCATENATE("'", C14, "'")), ", '", D14, "');")) -> PERFORM "SchData-OLTP-Master"."Func_TblBank_SET"(varSystemLoginSession, null::bigint, null::varchar, null::varchar, varInstitutionBranchID, varBaseCurrencyID, 'Bank OCBC Nilai Inti Sari Penyimpanan', 'OCBC NISP', 'NISPIDJA');
B15: Bank Tabungan Pensiunan Nasional | C15: BTPN | D15: SUNIIDJA | F15: =F14 + IF(EXACT(G15, ""), 0, 1) -> 166000000000012 | G15: =IF(EXACT(B15, ""), "", CONCATENATE("PERFORM ""SchData-OLTP-Master"".""Func_TblBank_SET""(varSystemLoginSession, null::bigint, null::varchar, null::varchar, varInstitutionBranchID, varBaseCurrencyID, '", B15, "', ", IF(EXACT(C15, ""), "null", CONCATENATE("'", C15, "'")), ", '", D15, "');")) -> PERFORM "SchData-OLTP-Master"."Func_TblBank_SET"(varSystemLoginSession, null::bigint, null::varchar, null::varchar, varInstitutionBranchID, varBaseCurrencyID, 'Bank Tabungan Pensiunan Nasional', 'BTPN', 'SUNIIDJA');
B16: Bank Pan Indonesia | D16: PINBIDJA | F16: =F15 + IF(EXACT(G16, ""), 0, 1) -> 166000000000013 | G16: =IF(EXACT(B16, ""), "", CONCATENATE("PERFORM ""SchData-OLTP-Master"".""Func_TblBank_SET""(varSystemLoginSession, null::bigint, null::varchar, null::varchar, varInstitutionBranchID, varBaseCurrencyID, '", B16, "', ", IF(EXACT(C16, ""), "null", CONCATENATE("'", C16, "'")), ", '", D16, "');")) -> PERFORM "SchData-OLTP-Master"."Func_TblBank_SET"(varSystemLoginSession, null::bigint, null::varchar, null::varchar, varInstitutionBranchID, varBaseCurrencyID, 'Bank Pan Indonesia', null, 'PINBIDJA');
B17: Bank Maybank Indonesia | D17: IBBKIDJA | F17: =F16 + IF(EXACT(G17, ""), 0, 1) -> 166000000000014 | G17: =IF(EXACT(B17, ""), "", CONCATENATE("PERFORM ""SchData-OLTP-Master"".""Func_TblBank_SET""(varSystemLoginSession, null::bigint, null::varchar, null::varchar, varInstitutionBranchID, varBaseCurrencyID, '", B17, "', ", IF(EXACT(C17, ""), "null", CONCATENATE("'", C17, "'")), ", '", D17, "');")) -> PERFORM "SchData-OLTP-Master"."Func_TblBank_SET"(varSystemLoginSession, null::bigint, null::varchar, null::varchar, varInstitutionBranchID, varBaseCurrencyID, 'Bank Maybank Indonesia', null, 'IBBKIDJA');
B18: Bank Commonwealth | C18: Commonwealth | D18: BICNIDJA | F18: =F17 + IF(EXACT(G18, ""), 0, 1) -> 166000000000015 | G18: =IF(EXACT(B18, ""), "", CONCATENATE("PERFORM ""SchData-OLTP-Master"".""Func_TblBank_SET""(varSystemLoginSession, null::bigint, null::varchar, null::varchar, varInstitutionBranchID, varBaseCurrencyID, '", B18, "', ", IF(EXACT(C18, ""), "null", CONCATENATE("'", C18, "'")), ", '", D18, "');")) -> PERFORM "SchData-OLTP-Master"."Func_TblBank_SET"(varSystemLoginSession, null::bigint, null::varchar, null::varchar, varInstitutionBranchID, varBaseCurrencyID, 'Bank Commonwealth', 'Commonwealth', 'BICNIDJA');
B19: Bank Standard Chartered | D19: SCBLIDJX | F19: =F18 + IF(EXACT(G19, ""), 0, 1) -> 166000000000016 | G19: =IF(EXACT(B19, ""), "", CONCATENATE("PERFORM ""SchData-OLTP-Master"".""Func_TblBank_SET""(varSystemLoginSession, null::bigint, null::varchar, null::varchar, varInstitutionBranchID, varBaseCurrencyID, '", B19, "', ", IF(EXACT(C19, ""), "null", CONCATENATE("'", C19, "'")), ", '", D19, "');")) -> PERFORM "SchData-OLTP-Master"."Func_TblBank_SET"(varSystemLoginSession, null::bigint, null::varchar, null::varchar, varInstitutionBranchID, varBaseCurrencyID, 'Bank Standard Chartered', null, 'SCBLIDJX');
B20: Bank CIMB Niaga | C20: CIMB Niaga | D20: BNIAIDJA | F20: =F19 + IF(EXACT(G20, ""), 0, 1) -> 166000000000017 | G20: =IF(EXACT(B20, ""), "", CONCATENATE("PERFORM ""SchData-OLTP-Master"".""Func_TblBank_SET""(varSystemLoginSession, null::bigint, null::varchar, null::varchar, varInstitutionBranchID, varBaseCurrencyID, '", B20, "', ", IF(EXACT(C20, ""), "null", CONCATENATE("'", C20, "'")), ", '", D20, "');")) -> PERFORM "SchData-OLTP-Master"."Func_TblBank_SET"(varSystemLoginSession, null::bigint, null::varchar, null::varchar, varInstitutionBranchID, varBaseCurrencyID, 'Bank CIMB Niaga', 'CIMB Niaga', 'BNIAIDJA');
B21: Bank Rakyat Indonesia Syariah | C21: BRI Syariah | D21: BRISIDJA | F21: =F20 + IF(EXACT(G21, ""), 0, 1) -> 166000000000018 | G21: =IF(EXACT(B21, ""), "", CONCATENATE("PERFORM ""SchData-OLTP-Master"".""Func_TblBank_SET""(varSystemLoginSession, null::bigint, null::varchar, null::varchar, varInstitutionBranchID, varBaseCurrencyID, '", B21, "', ", IF(EXACT(C21, ""), "null", CONCATENATE("'", C21, "'")), ", '", D21, "');")) -> PERFORM "SchData-OLTP-Master"."Func_TblBank_SET"(varSystemLoginSession, null::bigint, null::varchar, null::varchar, varInstitutionBranchID, varBaseCurrencyID, 'Bank Rakyat Indonesia Syariah', 'BRI Syariah', 'BRISIDJA');
B22: Bank Pembangunan Daerah Bengkulu | C22: BPD Bengkulu | D22: PDBKIDJ1 | F22: =F21 + IF(EXACT(G22, ""), 0, 1) -> 166000000000019 | G22: =IF(EXACT(B22, ""), "", CONCATENATE("PERFORM ""SchData-OLTP-Master"".""Func_TblBank_SET""(varSystemLoginSession, null::bigint, null::varchar, null::varchar, varInstitutionBranchID, varBaseCurrencyID, '", B22, "', ", IF(EXACT(C22, ""), "null", CONCATENATE("'", C22, "'")), ", '", D22, "');")) -> PERFORM "SchData-OLTP-Master"."Func_TblBank_SET"(varSystemLoginSession, null::bigint, null::varchar, null::varchar, varInstitutionBranchID, varBaseCurrencyID, 'Bank Pembangunan Daerah Bengkulu', 'BPD Bengkulu', 'PDBKIDJ1');
B23: Bank Pembangunan Daerah Jawa Barat Banten | C23: BJB | D23: PDJBIDJA | F23: =F22 + IF(EXACT(G23, ""), 0, 1) -> 166000000000020 | G23: =IF(EXACT(B23, ""), "", CONCATENATE("PERFORM ""SchData-OLTP-Master"".""Func_TblBank_SET""(varSystemLoginSession, null::bigint, null::varchar, null::varchar, varInstitutionBranchID, varBaseCurrencyID, '", B23, "', ", IF(EXACT(C23, ""), "null", CONCATENATE("'", C23, "'")), ", '", D23, "');")) -> PERFORM "SchData-OLTP-Master"."Func_TblBank_SET"(varSystemLoginSession, null::bigint, null::varchar, null::varchar, varInstitutionBranchID, varBaseCurrencyID, 'Bank Pembangunan Daerah Jawa Barat Banten', 'BJB', 'PDJBIDJA');
B24: Bank Pembangunan Daerah Jawa Timur | C24: BPD Jatim | D24: BJTMIDJA | F24: =F23 + IF(EXACT(G24, ""), 0, 1) -> 166000000000021 | G24: =IF(EXACT(B24, ""), "", CONCATENATE("PERFORM ""SchData-OLTP-Master"".""Func_TblBank_SET""(varSystemLoginSession, null::bigint, null::varchar, null::varchar, varInstitutionBranchID, varBaseCurrencyID, '", B24, "', ", IF(EXACT(C24, ""), "null", CONCATENATE("'", C24, "'")), ", '", D24, "');")) -> PERFORM "SchData-OLTP-Master"."Func_TblBank_SET"(varSystemLoginSession, null::bigint, null::varchar, null::varchar, varInstitutionBranchID, varBaseCurrencyID, 'Bank Pembangunan Daerah Jawa Timur', 'BPD Jatim', 'BJTMIDJA');
B25: Bank Pembangunan Daerah Kalimantan Selatan | C25: BPD Kalsel | D25: PDKSIDJ1 | F25: =F24 + IF(EXACT(G25, ""), 0, 1) -> 166000000000022 | G25: =IF(EXACT(B25, ""), "", CONCATENATE("PERFORM ""SchData-OLTP-Master"".""Func_TblBank_SET""(varSystemLoginSession, null::bigint, null::varchar, null::varchar, varInstitutionBranchID, varBaseCurrencyID, '", B25, "', ", IF(EXACT(C25, ""), "null", CONCATENATE("'", C25, "'")), ", '", D25, "');")) -> PERFORM "SchData-OLTP-Master"."Func_TblBank_SET"(varSystemLoginSession, null::bigint, null::varchar, null::varchar, varInstitutionBranchID, varBaseCurrencyID, 'Bank Pembangunan Daerah Kalimantan Selatan', 'BPD Kalsel', 'PDKSIDJ1');

Sheet DataLookUp2
B2: Sys_PID | C2: Bank Name | D2: Bank Acronym
B4: =IF(EXACT(MAIN!F4, ""), "", MAIN!F4) -> 166000000000001 | C4: =IF(EXACT($B4, ""), "", MAIN!$B4) -> Bank Mandiri | D4: =IF(EXACT($B4, ""), "", IF(EXACT(MAIN!$C4, ""), "", MAIN!$C4))
B5: =IF(EXACT(MAIN!F5, ""), "", MAIN!F5) -> 166000000000002 | C5: =IF(EXACT($B5, ""), "", MAIN!$B5) -> Bank Rakyat Indonesia | D5: =IF(EXACT($B5, ""), "", IF(EXACT(MAIN!$C5, ""), "", MAIN!$C5)) -> BRI
B6: =IF(EXACT(MAIN!F6, ""), "", MAIN!F6) -> 166000000000003 | C6: =IF(EXACT($B6, ""), "", MAIN!$B6) -> Bank Negara Indonesia | D6: =IF(EXACT($B6, ""), "", IF(EXACT(MAIN!$C6, ""), "", MAIN!$C6)) -> BNI
B7: =IF(EXACT(MAIN!F7, ""), "", MAIN!F7) -> 166000000000004 | C7: =IF(EXACT($B7, ""), "", MAIN!$B7) -> Bank Tabungan Negara | D7: =IF(EXACT($B7, ""), "", IF(EXACT(MAIN!$C7, ""), "", MAIN!$C7)) -> BTN
B8: =IF(EXACT(MAIN!F8, ""), "", MAIN!F8) -> 166000000000005 | C8: =IF(EXACT($B8, ""), "", MAIN!$B8) -> Bank Central Asia | D8: =IF(EXACT($B8, ""), "", IF(EXACT(MAIN!$C8, ""), "", MAIN!$C8)) -> BCA
B9: =IF(EXACT(MAIN!F9, ""), "", MAIN!F9) -> 166000000000006 | C9: =IF(EXACT($B9, ""), "", MAIN!$B9) -> Bank Mega | D9: =IF(EXACT($B9, ""), "", IF(EXACT(MAIN!$C9, ""), "", MAIN!$C9))
B10: =IF(EXACT(MAIN!F10, ""), "", MAIN!F10) -> 166000000000007 | C10: =IF(EXACT($B10, ""), "", MAIN!$B10) -> Bank Permata | D10: =IF(EXACT($B10, ""), "", IF(EXACT(MAIN!$C10, ""), "", MAIN!$C10))
B11: =IF(EXACT(MAIN!F11, ""), "", MAIN!F11) -> 166000000000008 | C11: =IF(EXACT($B11, ""), "", MAIN!$B11) -> Bank Danamon | D11: =IF(EXACT($B11, ""), "", IF(EXACT(MAIN!$C11, ""), "", MAIN!$C11))
B12: =IF(EXACT(MAIN!F12, ""), "", MAIN!F12) -> 166000000000009 | C12: =IF(EXACT($B12, ""), "", MAIN!$B12) -> Bank KB Bukopin | D12: =IF(EXACT($B12, ""), "", IF(EXACT(MAIN!$C12, ""), "", MAIN!$C12))
B13: =IF(EXACT(MAIN!F13, ""), "", MAIN!F13) -> 166000000000010 | C13: =IF(EXACT($B13, ""), "", MAIN!$B13) -> Bank Syariah Indonesia | D13: =IF(EXACT($B13, ""), "", IF(EXACT(MAIN!$C13, ""), "", MAIN!$C13)) -> BSI
B14: =IF(EXACT(MAIN!F14, ""), "", MAIN!F14) -> 166000000000011 | C14: =IF(EXACT($B14, ""), "", MAIN!$B14) -> Bank OCBC Nilai Inti Sari Penyimpanan | D14: =IF(EXACT($B14, ""), "", IF(EXACT(MAIN!$C14, ""), "", MAIN!$C14)) -> OCBC NISP
B15: =IF(EXACT(MAIN!F15, ""), "", MAIN!F15) -> 166000000000012 | C15: =IF(EXACT($B15, ""), "", MAIN!$B15) -> Bank Tabungan Pensiunan Nasional | D15: =IF(EXACT($B15, ""), "", IF(EXACT(MAIN!$C15, ""), "", MAIN!$C15)) -> BTPN
... B25: =IF(EXACT(MAIN!F25, ""), "", MAIN!F25) -> 166000000000022 | C25: =IF(EXACT($B25, ""), "", MAIN!$B25) -> Bank Pembangunan Daerah Kalimantan Selatan | D25: =IF(EXACT($B25, ""), "", IF(EXACT(MAIN!$C25, ""), "", MAIN!$C25)) -> BPD Kalsel

Sheet DataLookUp
B1: Name | C1: Acronym | D1: SWIFT Code | E1: Bank Code | H1: SYS_PID
B2: Bank Mandiri | D2: BMRIIDJA | E2: MRI | G2: =IF(EXACT(B2, ""), "", CONCATENATE("PERFORM ""SchData-OLTP-Master"".""Func_TblBank_SET""(varSystemLoginSession, null::bigint, null::varchar, null::varchar, varInstitutionBranchID, varBaseCurrencyID, ", IF(EXACT($B2, ""), "null", CONCATENATE("'", $B2, "'")), ", ", IF(EXACT($C2, ""), "null", CONCATENATE("'", $C2, "'")), ", ", IF(EXACT($D2, ""), "null", CONCATENATE("'", $D2, "'")), ", ", IF(EXACT($E2, ""), "null", CONCATENATE("'", $E2, "'")), ");")) -> PERFORM "SchData-OLTP-Master"."Func_TblBank_SET"(varSystemLoginSession, null::bigint, null::varchar, null::varchar, varInstitutionBranchID, varBaseCurrencyID, 'Bank Mandiri', null, 'BMRIIDJA', 'MRI'); | H2: 166000000000001 | J2: =CONCATENATE( "varSQL := varSQL || (CASE WHEN (varSQL = '') THEN '' ELSE ', ' END) || (SELECT JSON_BUILD_OBJECT (", "'recordID', NULL::bigint,", "'entities', ", "JSON_BUILD_OBJECT (", "'sysLoginSession_RefID', varSystemLoginSession::bigint,", "'sysDataAnnotation', NULL::varchar,", "'sysDataSetDateTimeTZ', NULL::timestamptz,", "'sysDataValidityStartDateTimeTZ', NULL::timestamptz,", "'sysDataValidityFinishDateTimeTZ', NULL::timestamptz,", "'sysPartitionRemovableRecordKey_RefID', NULL::bigint,", "'sysBranch_RefID', varInstitutionBranchID::bigint,", "'sysBaseCurrency_RefID',varBaseCurrencyID::bigint,", "'sysDataAnnotation', ", IF(EXACT($B2, ""), "null", CONCATENATE("'", SUBSTITUTE($B2, "'", "\'"), "'")), "::varchar,", "'acronym', ", IF(EXACT($C2, ""), "null", CONCATENATE("'", SUBSTITUTE($C2, "'", "\'"), "'")), "::varchar,", "'SWIFTCode', ", IF(EXACT($D2, ""), "null", CONCATENATE("'", SUBSTITUTE($D2, "'", "\'"), "'")), "::varchar,", "'bankCode', ", IF(EXACT($E2, ""), "null", CONCATENATE("'", SUBSTITUTE($E2, "'", "\'"), "'")), "::varchar", ")))::varchar;") -> varSQL := varSQL || (CASE WHEN (varSQL = '') THEN '' ELSE ', ' END) || (SELECT JSON_BUILD_OBJECT ('recordID', NULL::bigint,'entities', JSON_BUILD_OBJECT ('sysLoginSession_RefID', varSystemLoginSession::bigint,'sysDataAnnotation', NULL::varchar,'sysDataSetDateTimeTZ', NULL::timestamptz,'sysDataValidityStartDateTimeTZ', NULL::timestamptz,'sysDataValidityFinishDateTimeTZ', NULL::timestamptz,'sysPartitionRemovableRecordKey_RefID', NULL::bigint,'sysBranch_RefID', varInstitutionBranchID::bigint,'sysBaseCurrency_RefID',varBaseCurrencyID::bigint,'sysDataAnnotation', 'Bank Mandiri'::varchar,'acronym', null::varchar,'SWIFTCode', 'BMRIIDJA'::varchar,'bankCode', 'MRI'::varchar)))::varchar;
B3: Bank Rakyat Indonesia | C3: BRI | D3: BRINIDJA | E3: BRI | G3: =IF(EXACT(B3, ""), "", CONCATENATE("PERFORM ""SchData-OLTP-Master"".""Func_TblBank_SET""(varSystemLoginSession, null::bigint, null::varchar, null::varchar, varInstitutionBranchID, varBaseCurrencyID, ", IF(EXACT($B3, ""), "null", CONCATENATE("'", $B3, "'")), ", ", IF(EXACT($C3, ""), "null", CONCATENATE("'", $C3, "'")), ", ", IF(EXACT($D3, ""), "null", CONCATENATE("'", $D3, "'")), ", ", IF(EXACT($E3, ""), "null", CONCATENATE("'", $E3, "'")), ");")) -> PERFORM "SchData-OLTP-Master"."Func_TblBank_SET"(varSystemLoginSession, null::bigint, null::varchar, null::varchar, varInstitutionBranchID, varBaseCurrencyID, 'Bank Rakyat Indonesia', 'BRI', 'BRINIDJA', 'BRI'); | H3: 166000000000002 | J3: =CONCATENATE( "varSQL := varSQL || (CASE WHEN (varSQL = '') THEN '' ELSE ', ' END) || (SELECT JSON_BUILD_OBJECT (", "'recordID', NULL::bigint,", "'entities', ", "JSON_BUILD_OBJECT (", "'sysLoginSession_RefID', varSystemLoginSession::bigint,", "'sysDataAnnotation', NULL::varchar,", "'sysDataSetDateTimeTZ', NULL::timestamptz,", "'sysDataValidityStartDateTimeTZ', NULL::timestamptz,", "'sysDataValidityFinishDateTimeTZ', NULL::timestamptz,", "'sysPartitionRemovableRecordKey_RefID', NULL::bigint,", "'sysBranch_RefID', varInstitutionBranchID::bigint,", "'sysBaseCurrency_RefID',varBaseCurrencyID::bigint,", "'sysDataAnnotation', ", IF(EXACT($B3, ""), "null", CONCATENATE("'", SUBSTITUTE($B3, "'", "\'"), "'")), "::varchar,", "'acronym', ", IF(EXACT($C3, ""), "null", CONCATENATE("'", SUBSTITUTE($C3, "'", "\'"), "'")), "::varchar,", "'SWIFTCode', ", IF(EXACT($D3, ""), "null", CONCATENATE("'", SUBSTITUTE($D3, "'", "\'"), "'")), "::varchar,", "'bankCode', ", IF(EXACT($E3, ""), "null", CONCATENATE("'", SUBSTITUTE($E3, "'", "\'"), "'")), "::varchar", ")))::varchar;") -> varSQL := varSQL || (CASE WHEN (varSQL = '') THEN '' ELSE ', ' END) || (SELECT JSON_BUILD_OBJECT ('recordID', NULL::bigint,'entities', JSON_BUILD_OBJECT ('sysLoginSession_RefID', varSystemLoginSession::bigint,'sysDataAnnotation', NULL::varchar,'sysDataSetDateTimeTZ', NULL::timestamptz,'sysDataValidityStartDateTimeTZ', NULL::timestamptz,'sysDataValidityFinishDateTimeTZ', NULL::timestamptz,'sysPartitionRemovableRecordKey_RefID', NULL::bigint,'sysBranch_RefID', varInstitutionBranchID::bigint,'sysBaseCurrency_RefID',varBaseCurrencyID::bigint,'sysDataAnnotation', 'Bank Rakyat Indonesia'::varchar,'acronym', 'BRI'::varchar,'SWIFTCode', 'BRINIDJA'::varchar,'bankCode', 'BRI'::varchar)))::varchar;
B4: Bank Negara Indonesia | C4: BNI | D4: BNINIDJA | E4: BNI | G4: =IF(EXACT(B4, ""), "", CONCATENATE("PERFORM ""SchData-OLTP-Master"".""Func_TblBank_SET""(varSystemLoginSession, null::bigint, null::varchar, null::varchar, varInstitutionBranchID, varBaseCurrencyID, ", IF(EXACT($B4, ""), "null", CONCATENATE("'", $B4, "'")), ", ", IF(EXACT($C4, ""), "null", CONCATENATE("'", $C4, "'")), ", ", IF(EXACT($D4, ""), "null", CONCATENATE("'", $D4, "'")), ", ", IF(EXACT($E4, ""), "null", CONCATENATE("'", $E4, "'")), ");")) -> PERFORM "SchData-OLTP-Master"."Func_TblBank_SET"(varSystemLoginSession, null::bigint, null::varchar, null::varchar, varInstitutionBranchID, varBaseCurrencyID, 'Bank Negara Indonesia', 'BNI', 'BNINIDJA', 'BNI'); | H4: 166000000000003 | J4: =CONCATENATE( "varSQL := varSQL || (CASE WHEN (varSQL = '') THEN '' ELSE ', ' END) || (SELECT JSON_BUILD_OBJECT (", "'recordID', NULL::bigint,", "'entities', ", "JSON_BUILD_OBJECT (", "'sysLoginSession_RefID', varSystemLoginSession::bigint,", "'sysDataAnnotation', NULL::varchar,", "'sysDataSetDateTimeTZ', NULL::timestamptz,", "'sysDataValidityStartDateTimeTZ', NULL::timestamptz,", "'sysDataValidityFinishDateTimeTZ', NULL::timestamptz,", "'sysPartitionRemovableRecordKey_RefID', NULL::bigint,", "'sysBranch_RefID', varInstitutionBranchID::bigint,", "'sysBaseCurrency_RefID',varBaseCurrencyID::bigint,", "'sysDataAnnotation', ", IF(EXACT($B4, ""), "null", CONCATENATE("'", SUBSTITUTE($B4, "'", "\'"), "'")), "::varchar,", "'acronym', ", IF(EXACT($C4, ""), "null", CONCATENATE("'", SUBSTITUTE($C4, "'", "\'"), "'")), "::varchar,", "'SWIFTCode', ", IF(EXACT($D4, ""), "null", CONCATENATE("'", SUBSTITUTE($D4, "'", "\'"), "'")), "::varchar,", "'bankCode', ", IF(EXACT($E4, ""), "null", CONCATENATE("'", SUBSTITUTE($E4, "'", "\'"), "'")), "::varchar", ")))::varchar;") -> varSQL := varSQL || (CASE WHEN (varSQL = '') THEN '' ELSE ', ' END) || (SELECT JSON_BUILD_OBJECT ('recordID', NULL::bigint,'entities', JSON_BUILD_OBJECT ('sysLoginSession_RefID', varSystemLoginSession::bigint,'sysDataAnnotation', NULL::varchar,'sysDataSetDateTimeTZ', NULL::timestamptz,'sysDataValidityStartDateTimeTZ', NULL::timestamptz,'sysDataValidityFinishDateTimeTZ', NULL::timestamptz,'sysPartitionRemovableRecordKey_RefID', NULL::bigint,'sysBranch_RefID', varInstitutionBranchID::bigint,'sysBaseCurrency_RefID',varBaseCurrencyID::bigint,'sysDataAnnotation', 'Bank Negara Indonesia'::varchar,'acronym', 'BNI'::varchar,'SWIFTCode', 'BNINIDJA'::varchar,'bankCode', 'BNI'::varchar)))::varchar;
B5: Bank Tabungan Negara | C5: BTN | D5: BTANIDJA | E5: BTN | G5: =IF(EXACT(B5, ""), "", CONCATENATE("PERFORM ""SchData-OLTP-Master"".""Func_TblBank_SET""(varSystemLoginSession, null::bigint, null::varchar, null::varchar, varInstitutionBranchID, varBaseCurrencyID, ", IF(EXACT($B5, ""), "null", CONCATENATE("'", $B5, "'")), ", ", IF(EXACT($C5, ""), "null", CONCATENATE("'", $C5, "'")), ", ", IF(EXACT($D5, ""), "null", CONCATENATE("'", $D5, "'")), ", ", IF(EXACT($E5, ""), "null", CONCATENATE("'", $E5, "'")), ");")) -> PERFORM "SchData-OLTP-Master"."Func_TblBank_SET"(varSystemLoginSession, null::bigint, null::varchar, null::varchar, varInstitutionBranchID, varBaseCurrencyID, 'Bank Tabungan Negara', 'BTN', 'BTANIDJA', 'BTN'); | H5: 166000000000004 | J5: =CONCATENATE( "varSQL := varSQL || (CASE WHEN (varSQL = '') THEN '' ELSE ', ' END) || (SELECT JSON_BUILD_OBJECT (", "'recordID', NULL::bigint,", "'entities', ", "JSON_BUILD_OBJECT (", "'sysLoginSession_RefID', varSystemLoginSession::bigint,", "'sysDataAnnotation', NULL::varchar,", "'sysDataSetDateTimeTZ', NULL::timestamptz,", "'sysDataValidityStartDateTimeTZ', NULL::timestamptz,", "'sysDataValidityFinishDateTimeTZ', NULL::timestamptz,", "'sysPartitionRemovableRecordKey_RefID', NULL::bigint,", "'sysBranch_RefID', varInstitutionBranchID::bigint,", "'sysBaseCurrency_RefID',varBaseCurrencyID::bigint,", "'sysDataAnnotation', ", IF(EXACT($B5, ""), "null", CONCATENATE("'", SUBSTITUTE($B5, "'", "\'"), "'")), "::varchar,", "'acronym', ", IF(EXACT($C5, ""), "null", CONCATENATE("'", SUBSTITUTE($C5, "'", "\'"), "'")), "::varchar,", "'SWIFTCode', ", IF(EXACT($D5, ""), "null", CONCATENATE("'", SUBSTITUTE($D5, "'", "\'"), "'")), "::varchar,", "'bankCode', ", IF(EXACT($E5, ""), "null", CONCATENATE("'", SUBSTITUTE($E5, "'", "\'"), "'")), "::varchar", ")))::varchar;") -> varSQL := varSQL || (CASE WHEN (varSQL = '') THEN '' ELSE ', ' END) || (SELECT JSON_BUILD_OBJECT ('recordID', NULL::bigint,'entities', JSON_BUILD_OBJECT ('sysLoginSession_RefID', varSystemLoginSession::bigint,'sysDataAnnotation', NULL::varchar,'sysDataSetDateTimeTZ', NULL::timestamptz,'sysDataValidityStartDateTimeTZ', NULL::timestamptz,'sysDataValidityFinishDateTimeTZ', NULL::timestamptz,'sysPartitionRemovableRecordKey_RefID', NULL::bigint,'sysBranch_RefID', varInstitutionBranchID::bigint,'sysBaseCurrency_RefID',varBaseCurrencyID::bigint,'sysDataAnnotation', 'Bank Tabungan Negara'::varchar,'acronym', 'BTN'::varchar,'SWIFTCode', 'BTANIDJA'::varchar,'bankCode', 'BTN'::varchar)))::varchar;
B6: Bank Central Asia | C6: BCA | D6: CENAIDJA | E6: BCA | G6: =IF(EXACT(B6, ""), "", CONCATENATE("PERFORM ""SchData-OLTP-Master"".""Func_TblBank_SET""(varSystemLoginSession, null::bigint, null::varchar, null::varchar, varInstitutionBranchID, varBaseCurrencyID, ", IF(EXACT($B6, ""), "null", CONCATENATE("'", $B6, "'")), ", ", IF(EXACT($C6, ""), "null", CONCATENATE("'", $C6, "'")), ", ", IF(EXACT($D6, ""), "null", CONCATENATE("'", $D6, "'")), ", ", IF(EXACT($E6, ""), "null", CONCATENATE("'", $E6, "'")), ");")) -> PERFORM "SchData-OLTP-Master"."Func_TblBank_SET"(varSystemLoginSession, null::bigint, null::varchar, null::varchar, varInstitutionBranchID, varBaseCurrencyID, 'Bank Central Asia', 'BCA', 'CENAIDJA', 'BCA'); | H6: 166000000000005 | J6: =CONCATENATE( "varSQL := varSQL || (CASE WHEN (varSQL = '') THEN '' ELSE ', ' END) || (SELECT JSON_BUILD_OBJECT (", "'recordID', NULL::bigint,", "'entities', ", "JSON_BUILD_OBJECT (", "'sysLoginSession_RefID', varSystemLoginSession::bigint,", "'sysDataAnnotation', NULL::varchar,", "'sysDataSetDateTimeTZ', NULL::timestamptz,", "'sysDataValidityStartDateTimeTZ', NULL::timestamptz,", "'sysDataValidityFinishDateTimeTZ', NULL::timestamptz,", "'sysPartitionRemovableRecordKey_RefID', NULL::bigint,", "'sysBranch_RefID', varInstitutionBranchID::bigint,", "'sysBaseCurrency_RefID',varBaseCurrencyID::bigint,", "'sysDataAnnotation', ", IF(EXACT($B6, ""), "null", CONCATENATE("'", SUBSTITUTE($B6, "'", "\'"), "'")), "::varchar,", "'acronym', ", IF(EXACT($C6, ""), "null", CONCATENATE("'", SUBSTITUTE($C6, "'", "\'"), "'")), "::varchar,", "'SWIFTCode', ", IF(EXACT($D6, ""), "null", CONCATENATE("'", SUBSTITUTE($D6, "'", "\'"), "'")), "::varchar,", "'bankCode', ", IF(EXACT($E6, ""), "null", CONCATENATE("'", SUBSTITUTE($E6, "'", "\'"), "'")), "::varchar", ")))::varchar;") -> varSQL := varSQL || (CASE WHEN (varSQL = '') THEN '' ELSE ', ' END) || (SELECT JSON_BUILD_OBJECT ('recordID', NULL::bigint,'entities', JSON_BUILD_OBJECT ('sysLoginSession_RefID', varSystemLoginSession::bigint,'sysDataAnnotation', NULL::varchar,'sysDataSetDateTimeTZ', NULL::timestamptz,'sysDataValidityStartDateTimeTZ', NULL::timestamptz,'sysDataValidityFinishDateTimeTZ', NULL::timestamptz,'sysPartitionRemovableRecordKey_RefID', NULL::bigint,'sysBranch_RefID', varInstitutionBranchID::bigint,'sysBaseCurrency_RefID',varBaseCurrencyID::bigint,'sysDataAnnotation', 'Bank Central Asia'::varchar,'acronym', 'BCA'::varchar,'SWIFTCode', 'CENAIDJA'::varchar,'bankCode', 'BCA'::varchar)))::varchar;
B7: Bank Mega | D7: MEGAIDJA | E7: MEG | G7: =IF(EXACT(B7, ""), "", CONCATENATE("PERFORM ""SchData-OLTP-Master"".""Func_TblBank_SET""(varSystemLoginSession, null::bigint, null::varchar, null::varchar, varInstitutionBranchID, varBaseCurrencyID, ", IF(EXACT($B7, ""), "null", CONCATENATE("'", $B7, "'")), ", ", IF(EXACT($C7, ""), "null", CONCATENATE("'", $C7, "'")), ", ", IF(EXACT($D7, ""), "null", CONCATENATE("'", $D7, "'")), ", ", IF(EXACT($E7, ""), "null", CONCATENATE("'", $E7, "'")), ");")) -> PERFORM "SchData-OLTP-Master"."Func_TblBank_SET"(varSystemLoginSession, null::bigint, null::varchar, null::varchar, varInstitutionBranchID, varBaseCurrencyID, 'Bank Mega', null, 'MEGAIDJA', 'MEG'); | H7: 166000000000006 | J7: =CONCATENATE( "varSQL := varSQL || (CASE WHEN (varSQL = '') THEN '' ELSE ', ' END) || (SELECT JSON_BUILD_OBJECT (", "'recordID', NULL::bigint,", "'entities', ", "JSON_BUILD_OBJECT (", "'sysLoginSession_RefID', varSystemLoginSession::bigint,", "'sysDataAnnotation', NULL::varchar,", "'sysDataSetDateTimeTZ', NULL::timestamptz,", "'sysDataValidityStartDateTimeTZ', NULL::timestamptz,", "'sysDataValidityFinishDateTimeTZ', NULL::timestamptz,", "'sysPartitionRemovableRecordKey_RefID', NULL::bigint,", "'sysBranch_RefID', varInstitutionBranchID::bigint,", "'sysBaseCurrency_RefID',varBaseCurrencyID::bigint,", "'sysDataAnnotation', ", IF(EXACT($B7, ""), "null", CONCATENATE("'", SUBSTITUTE($B7, "'", "\'"), "'")), "::varchar,", "'acronym', ", IF(EXACT($C7, ""), "null", CONCATENATE("'", SUBSTITUTE($C7, "'", "\'"), "'")), "::varchar,", "'SWIFTCode', ", IF(EXACT($D7, ""), "null", CONCATENATE("'", SUBSTITUTE($D7, "'", "\'"), "'")), "::varchar,", "'bankCode', ", IF(EXACT($E7, ""), "null", CONCATENATE("'", SUBSTITUTE($E7, "'", "\'"), "'")), "::varchar", ")))::varchar;") -> varSQL := varSQL || (CASE WHEN (varSQL = '') THEN '' ELSE ', ' END) || (SELECT JSON_BUILD_OBJECT ('recordID', NULL::bigint,'entities', JSON_BUILD_OBJECT ('sysLoginSession_RefID', varSystemLoginSession::bigint,'sysDataAnnotation', NULL::varchar,'sysDataSetDateTimeTZ', NULL::timestamptz,'sysDataValidityStartDateTimeTZ', NULL::timestamptz,'sysDataValidityFinishDateTimeTZ', NULL::timestamptz,'sysPartitionRemovableRecordKey_RefID', NULL::bigint,'sysBranch_RefID', varInstitutionBranchID::bigint,'sysBaseCurrency_RefID',varBaseCurrencyID::bigint,'sysDataAnnotation', 'Bank Mega'::varchar,'acronym', null::varchar,'SWIFTCode', 'MEGAIDJA'::varchar,'bankCode', 'MEG'::varchar)))::varchar;
B8: Bank Permata | D8: BBBAIDJA | E8: PER | G8: =IF(EXACT(B8, ""), "", CONCATENATE("PERFORM ""SchData-OLTP-Master"".""Func_TblBank_SET""(varSystemLoginSession, null::bigint, null::varchar, null::varchar, varInstitutionBranchID, varBaseCurrencyID, ", IF(EXACT($B8, ""), "null", CONCATENATE("'", $B8, "'")), ", ", IF(EXACT($C8, ""), "null", CONCATENATE("'", $C8, "'")), ", ", IF(EXACT($D8, ""), "null", CONCATENATE("'", $D8, "'")), ", ", IF(EXACT($E8, ""), "null", CONCATENATE("'", $E8, "'")), ");")) -> PERFORM "SchData-OLTP-Master"."Func_TblBank_SET"(varSystemLoginSession, null::bigint, null::varchar, null::varchar, varInstitutionBranchID, varBaseCurrencyID, 'Bank Permata', null, 'BBBAIDJA', 'PER'); | H8: 166000000000007 | J8: =CONCATENATE( "varSQL := varSQL || (CASE WHEN (varSQL = '') THEN '' ELSE ', ' END) || (SELECT JSON_BUILD_OBJECT (", "'recordID', NULL::bigint,", "'entities', ", "JSON_BUILD_OBJECT (", "'sysLoginSession_RefID', varSystemLoginSession::bigint,", "'sysDataAnnotation', NULL::varchar,", "'sysDataSetDateTimeTZ', NULL::timestamptz,", "'sysDataValidityStartDateTimeTZ', NULL::timestamptz,", "'sysDataValidityFinishDateTimeTZ', NULL::timestamptz,", "'sysPartitionRemovableRecordKey_RefID', NULL::bigint,", "'sysBranch_RefID', varInstitutionBranchID::bigint,", "'sysBaseCurrency_RefID',varBaseCurrencyID::bigint,", "'sysDataAnnotation', ", IF(EXACT($B8, ""), "null", CONCATENATE("'", SUBSTITUTE($B8, "'", "\'"), "'")), "::varchar,", "'acronym', ", IF(EXACT($C8, ""), "null", CONCATENATE("'", SUBSTITUTE($C8, "'", "\'"), "'")), "::varchar,", "'SWIFTCode', ", IF(EXACT($D8, ""), "null", CONCATENATE("'", SUBSTITUTE($D8, "'", "\'"), "'")), "::varchar,", "'bankCode', ", IF(EXACT($E8, ""), "null", CONCATENATE("'", SUBSTITUTE($E8, "'", "\'"), "'")), "::varchar", ")))::varchar;") -> varSQL := varSQL || (CASE WHEN (varSQL = '') THEN '' ELSE ', ' END) || (SELECT JSON_BUILD_OBJECT ('recordID', NULL::bigint,'entities', JSON_BUILD_OBJECT ('sysLoginSession_RefID', varSystemLoginSession::bigint,'sysDataAnnotation', NULL::varchar,'sysDataSetDateTimeTZ', NULL::timestamptz,'sysDataValidityStartDateTimeTZ', NULL::timestamptz,'sysDataValidityFinishDateTimeTZ', NULL::timestamptz,'sysPartitionRemovableRecordKey_RefID', NULL::bigint,'sysBranch_RefID', varInstitutionBranchID::bigint,'sysBaseCurrency_RefID',varBaseCurrencyID::bigint,'sysDataAnnotation', 'Bank Permata'::varchar,'acronym', null::varchar,'SWIFTCode', 'BBBAIDJA'::varchar,'bankCode', 'PER'::varchar)))::varchar;
B9: Bank Danamon | D9: BDINIDJA | E9: DAN | G9: =IF(EXACT(B9, ""), "", CONCATENATE("PERFORM ""SchData-OLTP-Master"".""Func_TblBank_SET""(varSystemLoginSession, null::bigint, null::varchar, null::varchar, varInstitutionBranchID, varBaseCurrencyID, ", IF(EXACT($B9, ""), "null", CONCATENATE("'", $B9, "'")), ", ", IF(EXACT($C9, ""), "null", CONCATENATE("'", $C9, "'")), ", ", IF(EXACT($D9, ""), "null", CONCATENATE("'", $D9, "'")), ", ", IF(EXACT($E9, ""), "null", CONCATENATE("'", $E9, "'")), ");")) -> PERFORM "SchData-OLTP-Master"."Func_TblBank_SET"(varSystemLoginSession, null::bigint, null::varchar, null::varchar, varInstitutionBranchID, varBaseCurrencyID, 'Bank Danamon', null, 'BDINIDJA', 'DAN'); | H9: 166000000000008 | J9: =CONCATENATE( "varSQL := varSQL || (CASE WHEN (varSQL = '') THEN '' ELSE ', ' END) || (SELECT JSON_BUILD_OBJECT (", "'recordID', NULL::bigint,", "'entities', ", "JSON_BUILD_OBJECT (", "'sysLoginSession_RefID', varSystemLoginSession::bigint,", "'sysDataAnnotation', NULL::varchar,", "'sysDataSetDateTimeTZ', NULL::timestamptz,", "'sysDataValidityStartDateTimeTZ', NULL::timestamptz,", "'sysDataValidityFinishDateTimeTZ', NULL::timestamptz,", "'sysPartitionRemovableRecordKey_RefID', NULL::bigint,", "'sysBranch_RefID', varInstitutionBranchID::bigint,", "'sysBaseCurrency_RefID',varBaseCurrencyID::bigint,", "'sysDataAnnotation', ", IF(EXACT($B9, ""), "null", CONCATENATE("'", SUBSTITUTE($B9, "'", "\'"), "'")), "::varchar,", "'acronym', ", IF(EXACT($C9, ""), "null", CONCATENATE("'", SUBSTITUTE($C9, "'", "\'"), "'")), "::varchar,", "'SWIFTCode', ", IF(EXACT($D9, ""), "null", CONCATENATE("'", SUBSTITUTE($D9, "'", "\'"), "'")), "::varchar,", "'bankCode', ", IF(EXACT($E9, ""), "null", CONCATENATE("'", SUBSTITUTE($E9, "'", "\'"), "'")), "::varchar", ")))::varchar;") -> varSQL := varSQL || (CASE WHEN (varSQL = '') THEN '' ELSE ', ' END) || (SELECT JSON_BUILD_OBJECT ('recordID', NULL::bigint,'entities', JSON_BUILD_OBJECT ('sysLoginSession_RefID', varSystemLoginSession::bigint,'sysDataAnnotation', NULL::varchar,'sysDataSetDateTimeTZ', NULL::timestamptz,'sysDataValidityStartDateTimeTZ', NULL::timestamptz,'sysDataValidityFinishDateTimeTZ', NULL::timestamptz,'sysPartitionRemovableRecordKey_RefID', NULL::bigint,'sysBranch_RefID', varInstitutionBranchID::bigint,'sysBaseCurrency_RefID',varBaseCurrencyID::bigint,'sysDataAnnotation', 'Bank Danamon'::varchar,'acronym', null::varchar,'SWIFTCode', 'BDINIDJA'::varchar,'bankCode', 'DAN'::varchar)))::varchar;
B10: Bank KB Bukopin | D10: BBUKIDJA | E10: BUK | G10: =IF(EXACT(B10, ""), "", CONCATENATE("PERFORM ""SchData-OLTP-Master"".""Func_TblBank_SET""(varSystemLoginSession, null::bigint, null::varchar, null::varchar, varInstitutionBranchID, varBaseCurrencyID, ", IF(EXACT($B10, ""), "null", CONCATENATE("'", $B10, "'")), ", ", IF(EXACT($C10, ""), "null", CONCATENATE("'", $C10, "'")), ", ", IF(EXACT($D10, ""), "null", CONCATENATE("'", $D10, "'")), ", ", IF(EXACT($E10, ""), "null", CONCATENATE("'", $E10, "'")), ");")) -> PERFORM "SchData-OLTP-Master"."Func_TblBank_SET"(varSystemLoginSession, null::bigint, null::varchar, null::varchar, varInstitutionBranchID, varBaseCurrencyID, 'Bank KB Bukopin', null, 'BBUKIDJA', 'BUK'); | H10: 166000000000009 | J10: =CONCATENATE( "varSQL := varSQL || (CASE WHEN (varSQL = '') THEN '' ELSE ', ' END) || (SELECT JSON_BUILD_OBJECT (", "'recordID', NULL::bigint,", "'entities', ", "JSON_BUILD_OBJECT (", "'sysLoginSession_RefID', varSystemLoginSession::bigint,", "'sysDataAnnotation', NULL::varchar,", "'sysDataSetDateTimeTZ', NULL::timestamptz,", "'sysDataValidityStartDateTimeTZ', NULL::timestamptz,", "'sysDataValidityFinishDateTimeTZ', NULL::timestamptz,", "'sysPartitionRemovableRecordKey_RefID', NULL::bigint,", "'sysBranch_RefID', varInstitutionBranchID::bigint,", "'sysBaseCurrency_RefID',varBaseCurrencyID::bigint,", "'sysDataAnnotation', ", IF(EXACT($B10, ""), "null", CONCATENATE("'", SUBSTITUTE($B10, "'", "\'"), "'")), "::varchar,", "'acronym', ", IF(EXACT($C10, ""), "null", CONCATENATE("'", SUBSTITUTE($C10, "'", "\'"), "'")), "::varchar,", "'SWIFTCode', ", IF(EXACT($D10, ""), "null", CONCATENATE("'", SUBSTITUTE($D10, "'", "\'"), "'")), "::varchar,", "'bankCode', ", IF(EXACT($E10, ""), "null", CONCATENATE("'", SUBSTITUTE($E10, "'", "\'"), "'")), "::varchar", ")))::varchar;") -> varSQL := varSQL || (CASE WHEN (varSQL = '') THEN '' ELSE ', ' END) || (SELECT JSON_BUILD_OBJECT ('recordID', NULL::bigint,'entities', JSON_BUILD_OBJECT ('sysLoginSession_RefID', varSystemLoginSession::bigint,'sysDataAnnotation', NULL::varchar,'sysDataSetDateTimeTZ', NULL::timestamptz,'sysDataValidityStartDateTimeTZ', NULL::timestamptz,'sysDataValidityFinishDateTimeTZ', NULL::timestamptz,'sysPartitionRemovableRecordKey_RefID', NULL::bigint,'sysBranch_RefID', varInstitutionBranchID::bigint,'sysBaseCurrency_RefID',varBaseCurrencyID::bigint,'sysDataAnnotation', 'Bank KB Bukopin'::varchar,'acronym', null::varchar,'SWIFTCode', 'BBUKIDJA'::varchar,'bankCode', 'BUK'::varchar)))::varchar;
B11: Bank Syariah Indonesia | C11: BSI | D11: BSMDIDJA | E11: BSI | G11: =IF(EXACT(B11, ""), "", CONCATENATE("PERFORM ""SchData-OLTP-Master"".""Func_TblBank_SET""(varSystemLoginSession, null::bigint, null::varchar, null::varchar, varInstitutionBranchID, varBaseCurrencyID, ", IF(EXACT($B11, ""), "null", CONCATENATE("'", $B11, "'")), ", ", IF(EXACT($C11, ""), "null", CONCATENATE("'", $C11, "'")), ", ", IF(EXACT($D11, ""), "null", CONCATENATE("'", $D11, "'")), ", ", IF(EXACT($E11, ""), "null", CONCATENATE("'", $E11, "'")), ");")) -> PERFORM "SchData-OLTP-Master"."Func_TblBank_SET"(varSystemLoginSession, null::bigint, null::varchar, null::varchar, varInstitutionBranchID, varBaseCurrencyID, 'Bank Syariah Indonesia', 'BSI', 'BSMDIDJA', 'BSI'); | H11: 166000000000010 | J11: =CONCATENATE( "varSQL := varSQL || (CASE WHEN (varSQL = '') THEN '' ELSE ', ' END) || (SELECT JSON_BUILD_OBJECT (", "'recordID', NULL::bigint,", "'entities', ", "JSON_BUILD_OBJECT (", "'sysLoginSession_RefID', varSystemLoginSession::bigint,", "'sysDataAnnotation', NULL::varchar,", "'sysDataSetDateTimeTZ', NULL::timestamptz,", "'sysDataValidityStartDateTimeTZ', NULL::timestamptz,", "'sysDataValidityFinishDateTimeTZ', NULL::timestamptz,", "'sysPartitionRemovableRecordKey_RefID', NULL::bigint,", "'sysBranch_RefID', varInstitutionBranchID::bigint,", "'sysBaseCurrency_RefID',varBaseCurrencyID::bigint,", "'sysDataAnnotation', ", IF(EXACT($B11, ""), "null", CONCATENATE("'", SUBSTITUTE($B11, "'", "\'"), "'")), "::varchar,", "'acronym', ", IF(EXACT($C11, ""), "null", CONCATENATE("'", SUBSTITUTE($C11, "'", "\'"), "'")), "::varchar,", "'SWIFTCode', ", IF(EXACT($D11, ""), "null", CONCATENATE("'", SUBSTITUTE($D11, "'", "\'"), "'")), "::varchar,", "'bankCode', ", IF(EXACT($E11, ""), "null", CONCATENATE("'", SUBSTITUTE($E11, "'", "\'"), "'")), "::varchar", ")))::varchar;") -> varSQL := varSQL || (CASE WHEN (varSQL = '') THEN '' ELSE ', ' END) || (SELECT JSON_BUILD_OBJECT ('recordID', NULL::bigint,'entities', JSON_BUILD_OBJECT ('sysLoginSession_RefID', varSystemLoginSession::bigint,'sysDataAnnotation', NULL::varchar,'sysDataSetDateTimeTZ', NULL::timestamptz,'sysDataValidityStartDateTimeTZ', NULL::timestamptz,'sysDataValidityFinishDateTimeTZ', NULL::timestamptz,'sysPartitionRemovableRecordKey_RefID', NULL::bigint,'sysBranch_RefID', varInstitutionBranchID::bigint,'sysBaseCurrency_RefID',varBaseCurrencyID::bigint,'sysDataAnnotation', 'Bank Syariah Indonesia'::varchar,'acronym', 'BSI'::varchar,'SWIFTCode', 'BSMDIDJA'::varchar,'bankCode', 'BSI'::varchar)))::varchar;
B12: Bank OCBC Nilai Inti Sari Penyimpanan | C12: OCBC NISP | D12: NISPIDJA | E12: OCB | G12: =IF(EXACT(B12, ""), "", CONCATENATE("PERFORM ""SchData-OLTP-Master"".""Func_TblBank_SET""(varSystemLoginSession, null::bigint, null::varchar, null::varchar, varInstitutionBranchID, varBaseCurrencyID, ", IF(EXACT($B12, ""), "null", CONCATENATE("'", $B12, "'")), ", ", IF(EXACT($C12, ""), "null", CONCATENATE("'", $C12, "'")), ", ", IF(EXACT($D12, ""), "null", CONCATENATE("'", $D12, "'")), ", ", IF(EXACT($E12, ""), "null", CONCATENATE("'", $E12, "'")), ");")) -> PERFORM "SchData-OLTP-Master"."Func_TblBank_SET"(varSystemLoginSession, null::bigint, null::varchar, null::varchar, varInstitutionBranchID, varBaseCurrencyID, 'Bank OCBC Nilai Inti Sari Penyimpanan', 'OCBC NISP', 'NISPIDJA', 'OCB'); | H12: 166000000000011 | J12: =CONCATENATE( "varSQL := varSQL || (CASE WHEN (varSQL = '') THEN '' ELSE ', ' END) || (SELECT JSON_BUILD_OBJECT (", "'recordID', NULL::bigint,", "'entities', ", "JSON_BUILD_OBJECT (", "'sysLoginSession_RefID', varSystemLoginSession::bigint,", "'sysDataAnnotation', NULL::varchar,", "'sysDataSetDateTimeTZ', NULL::timestamptz,", "'sysDataValidityStartDateTimeTZ', NULL::timestamptz,", "'sysDataValidityFinishDateTimeTZ', NULL::timestamptz,", "'sysPartitionRemovableRecordKey_RefID', NULL::bigint,", "'sysBranch_RefID', varInstitutionBranchID::bigint,", "'sysBaseCurrency_RefID',varBaseCurrencyID::bigint,", "'sysDataAnnotation', ", IF(EXACT($B12, ""), "null", CONCATENATE("'", SUBSTITUTE($B12, "'", "\'"), "'")), "::varchar,", "'acronym', ", IF(EXACT($C12, ""), "null", CONCATENATE("'", SUBSTITUTE($C12, "'", "\'"), "'")), "::varchar,", "'SWIFTCode', ", IF(EXACT($D12, ""), "null", CONCATENATE("'", SUBSTITUTE($D12, "'", "\'"), "'")), "::varchar,", "'bankCode', ", IF(EXACT($E12, ""), "null", CONCATENATE("'", SUBSTITUTE($E12, "'", "\'"), "'")), "::varchar", ")))::varchar;") -> varSQL := varSQL || (CASE WHEN (varSQL = '') THEN '' ELSE ', ' END) || (SELECT JSON_BUILD_OBJECT ('recordID', NULL::bigint,'entities', JSON_BUILD_OBJECT ('sysLoginSession_RefID', varSystemLoginSession::bigint,'sysDataAnnotation', NULL::varchar,'sysDataSetDateTimeTZ', NULL::timestamptz,'sysDataValidityStartDateTimeTZ', NULL::timestamptz,'sysDataValidityFinishDateTimeTZ', NULL::timestamptz,'sysPartitionRemovableRecordKey_RefID', NULL::bigint,'sysBranch_RefID', varInstitutionBranchID::bigint,'sysBaseCurrency_RefID',varBaseCurrencyID::bigint,'sysDataAnnotation', 'Bank OCBC Nilai Inti Sari Penyimpanan'::varchar,'acronym', 'OCBC NISP'::varchar,'SWIFTCode', 'NISPIDJA'::varchar,'bankCode', 'OCB'::varchar)))::varchar;
B13: Bank Tabungan Pensiunan Nasional | C13: BTPN | D13: SUNIIDJA | E13: TPN | G13: =IF(EXACT(B13, ""), "", CONCATENATE("PERFORM ""SchData-OLTP-Master"".""Func_TblBank_SET""(varSystemLoginSession, null::bigint, null::varchar, null::varchar, varInstitutionBranchID, varBaseCurrencyID, ", IF(EXACT($B13, ""), "null", CONCATENATE("'", $B13, "'")), ", ", IF(EXACT($C13, ""), "null", CONCATENATE("'", $C13, "'")), ", ", IF(EXACT($D13, ""), "null", CONCATENATE("'", $D13, "'")), ", ", IF(EXACT($E13, ""), "null", CONCATENATE("'", $E13, "'")), ");")) -> PERFORM "SchData-OLTP-Master"."Func_TblBank_SET"(varSystemLoginSession, null::bigint, null::varchar, null::varchar, varInstitutionBranchID, varBaseCurrencyID, 'Bank Tabungan Pensiunan Nasional', 'BTPN', 'SUNIIDJA', 'TPN'); | H13: 166000000000012 | J13: =CONCATENATE( "varSQL := varSQL || (CASE WHEN (varSQL = '') THEN '' ELSE ', ' END) || (SELECT JSON_BUILD_OBJECT (", "'recordID', NULL::bigint,", "'entities', ", "JSON_BUILD_OBJECT (", "'sysLoginSession_RefID', varSystemLoginSession::bigint,", "'sysDataAnnotation', NULL::varchar,", "'sysDataSetDateTimeTZ', NULL::timestamptz,", "'sysDataValidityStartDateTimeTZ', NULL::timestamptz,", "'sysDataValidityFinishDateTimeTZ', NULL::timestamptz,", "'sysPartitionRemovableRecordKey_RefID', NULL::bigint,", "'sysBranch_RefID', varInstitutionBranchID::bigint,", "'sysBaseCurrency_RefID',varBaseCurrencyID::bigint,", "'sysDataAnnotation', ", IF(EXACT($B13, ""), "null", CONCATENATE("'", SUBSTITUTE($B13, "'", "\'"), "'")), "::varchar,", "'acronym', ", IF(EXACT($C13, ""), "null", CONCATENATE("'", SUBSTITUTE($C13, "'", "\'"), "'")), "::varchar,", "'SWIFTCode', ", IF(EXACT($D13, ""), "null", CONCATENATE("'", SUBSTITUTE($D13, "'", "\'"), "'")), "::varchar,", "'bankCode', ", IF(EXACT($E13, ""), "null", CONCATENATE("'", SUBSTITUTE($E13, "'", "\'"), "'")), "::varchar", ")))::varchar;") -> varSQL := varSQL || (CASE WHEN (varSQL = '') THEN '' ELSE ', ' END) || (SELECT JSON_BUILD_OBJECT ('recordID', NULL::bigint,'entities', JSON_BUILD_OBJECT ('sysLoginSession_RefID', varSystemLoginSession::bigint,'sysDataAnnotation', NULL::varchar,'sysDataSetDateTimeTZ', NULL::timestamptz,'sysDataValidityStartDateTimeTZ', NULL::timestamptz,'sysDataValidityFinishDateTimeTZ', NULL::timestamptz,'sysPartitionRemovableRecordKey_RefID', NULL::bigint,'sysBranch_RefID', varInstitutionBranchID::bigint,'sysBaseCurrency_RefID',varBaseCurrencyID::bigint,'sysDataAnnotation', 'Bank Tabungan Pensiunan Nasional'::varchar,'acronym', 'BTPN'::varchar,'SWIFTCode', 'SUNIIDJA'::varchar,'bankCode', 'TPN'::varchar)))::varchar;
B14: Bank Pan Indonesia | D14: PINBIDJA | E14: PAN | G14: =IF(EXACT(B14, ""), "", CONCATENATE("PERFORM ""SchData-OLTP-Master"".""Func_TblBank_SET""(varSystemLoginSession, null::bigint, null::varchar, null::varchar, varInstitutionBranchID, varBaseCurrencyID, ", IF(EXACT($B14, ""), "null", CONCATENATE("'", $B14, "'")), ", ", IF(EXACT($C14, ""), "null", CONCATENATE("'", $C14, "'")), ", ", IF(EXACT($D14, ""), "null", CONCATENATE("'", $D14, "'")), ", ", IF(EXACT($E14, ""), "null", CONCATENATE("'", $E14, "'")), ");")) -> PERFORM "SchData-OLTP-Master"."Func_TblBank_SET"(varSystemLoginSession, null::bigint, null::varchar, null::varchar, varInstitutionBranchID, varBaseCurrencyID, 'Bank Pan Indonesia', null, 'PINBIDJA', 'PAN'); | H14: 166000000000013 | J14: =CONCATENATE( "varSQL := varSQL || (CASE WHEN (varSQL = '') THEN '' ELSE ', ' END) || (SELECT JSON_BUILD_OBJECT (", "'recordID', NULL::bigint,", "'entities', ", "JSON_BUILD_OBJECT (", "'sysLoginSession_RefID', varSystemLoginSession::bigint,", "'sysDataAnnotation', NULL::varchar,", "'sysDataSetDateTimeTZ', NULL::timestamptz,", "'sysDataValidityStartDateTimeTZ', NULL::timestamptz,", "'sysDataValidityFinishDateTimeTZ', NULL::timestamptz,", "'sysPartitionRemovableRecordKey_RefID', NULL::bigint,", "'sysBranch_RefID', varInstitutionBranchID::bigint,", "'sysBaseCurrency_RefID',varBaseCurrencyID::bigint,", "'sysDataAnnotation', ", IF(EXACT($B14, ""), "null", CONCATENATE("'", SUBSTITUTE($B14, "'", "\'"), "'")), "::varchar,", "'acronym', ", IF(EXACT($C14, ""), "null", CONCATENATE("'", SUBSTITUTE($C14, "'", "\'"), "'")), "::varchar,", "'SWIFTCode', ", IF(EXACT($D14, ""), "null", CONCATENATE("'", SUBSTITUTE($D14, "'", "\'"), "'")), "::varchar,", "'bankCode', ", IF(EXACT($E14, ""), "null", CONCATENATE("'", SUBSTITUTE($E14, "'", "\'"), "'")), "::varchar", ")))::varchar;") -> varSQL := varSQL || (CASE WHEN (varSQL = '') THEN '' ELSE ', ' END) || (SELECT JSON_BUILD_OBJECT ('recordID', NULL::bigint,'entities', JSON_BUILD_OBJECT ('sysLoginSession_RefID', varSystemLoginSession::bigint,'sysDataAnnotation', NULL::varchar,'sysDataSetDateTimeTZ', NULL::timestamptz,'sysDataValidityStartDateTimeTZ', NULL::timestamptz,'sysDataValidityFinishDateTimeTZ', NULL::timestamptz,'sysPartitionRemovableRecordKey_RefID', NULL::bigint,'sysBranch_RefID', varInstitutionBranchID::bigint,'sysBaseCurrency_RefID',varBaseCurrencyID::bigint,'sysDataAnnotation', 'Bank Pan Indonesia'::varchar,'acronym', null::varchar,'SWIFTCode', 'PINBIDJA'::varchar,'bankCode', 'PAN'::varchar)))::varchar;
B15: Bank Maybank Indonesia | D15: IBBKIDJA | E15: MAY | G15: =IF(EXACT(B15, ""), "", CONCATENATE("PERFORM ""SchData-OLTP-Master"".""Func_TblBank_SET""(varSystemLoginSession, null::bigint, null::varchar, null::varchar, varInstitutionBranchID, varBaseCurrencyID, ", IF(EXACT($B15, ""), "null", CONCATENATE("'", $B15, "'")), ", ", IF(EXACT($C15, ""), "null", CONCATENATE("'", $C15, "'")), ", ", IF(EXACT($D15, ""), "null", CONCATENATE("'", $D15, "'")), ", ", IF(EXACT($E15, ""), "null", CONCATENATE("'", $E15, "'")), ");")) -> PERFORM "SchData-OLTP-Master"."Func_TblBank_SET"(varSystemLoginSession, null::bigint, null::varchar, null::varchar, varInstitutionBranchID, varBaseCurrencyID, 'Bank Maybank Indonesia', null, 'IBBKIDJA', 'MAY'); | H15: 166000000000014 | J15: =CONCATENATE( "varSQL := varSQL || (CASE WHEN (varSQL = '') THEN '' ELSE ', ' END) || (SELECT JSON_BUILD_OBJECT (", "'recordID', NULL::bigint,", "'entities', ", "JSON_BUILD_OBJECT (", "'sysLoginSession_RefID', varSystemLoginSession::bigint,", "'sysDataAnnotation', NULL::varchar,", "'sysDataSetDateTimeTZ', NULL::timestamptz,", "'sysDataValidityStartDateTimeTZ', NULL::timestamptz,", "'sysDataValidityFinishDateTimeTZ', NULL::timestamptz,", "'sysPartitionRemovableRecordKey_RefID', NULL::bigint,", "'sysBranch_RefID', varInstitutionBranchID::bigint,", "'sysBaseCurrency_RefID',varBaseCurrencyID::bigint,", "'sysDataAnnotation', ", IF(EXACT($B15, ""), "null", CONCATENATE("'", SUBSTITUTE($B15, "'", "\'"), "'")), "::varchar,", "'acronym', ", IF(EXACT($C15, ""), "null", CONCATENATE("'", SUBSTITUTE($C15, "'", "\'"), "'")), "::varchar,", "'SWIFTCode', ", IF(EXACT($D15, ""), "null", CONCATENATE("'", SUBSTITUTE($D15, "'", "\'"), "'")), "::varchar,", "'bankCode', ", IF(EXACT($E15, ""), "null", CONCATENATE("'", SUBSTITUTE($E15, "'", "\'"), "'")), "::varchar", ")))::varchar;") -> varSQL := varSQL || (CASE WHEN (varSQL = '') THEN '' ELSE ', ' END) || (SELECT JSON_BUILD_OBJECT ('recordID', NULL::bigint,'entities', JSON_BUILD_OBJECT ('sysLoginSession_RefID', varSystemLoginSession::bigint,'sysDataAnnotation', NULL::varchar,'sysDataSetDateTimeTZ', NULL::timestamptz,'sysDataValidityStartDateTimeTZ', NULL::timestamptz,'sysDataValidityFinishDateTimeTZ', NULL::timestamptz,'sysPartitionRemovableRecordKey_RefID', NULL::bigint,'sysBranch_RefID', varInstitutionBranchID::bigint,'sysBaseCurrency_RefID',varBaseCurrencyID::bigint,'sysDataAnnotation', 'Bank Maybank Indonesia'::varchar,'acronym', null::varchar,'SWIFTCode', 'IBBKIDJA'::varchar,'bankCode', 'MAY'::varchar)))::varchar;
B16: Bank Commonwealth | C16: Commonwealth | D16: BICNIDJA | E16: CMW | G16: =IF(EXACT(B16, ""), "", CONCATENATE("PERFORM ""SchData-OLTP-Master"".""Func_TblBank_SET""(varSystemLoginSession, null::bigint, null::varchar, null::varchar, varInstitutionBranchID, varBaseCurrencyID, ", IF(EXACT($B16, ""), "null", CONCATENATE("'", $B16, "'")), ", ", IF(EXACT($C16, ""), "null", CONCATENATE("'", $C16, "'")), ", ", IF(EXACT($D16, ""), "null", CONCATENATE("'", $D16, "'")), ", ", IF(EXACT($E16, ""), "null", CONCATENATE("'", $E16, "'")), ");")) -> PERFORM "SchData-OLTP-Master"."Func_TblBank_SET"(varSystemLoginSession, null::bigint, null::varchar, null::varchar, varInstitutionBranchID, varBaseCurrencyID, 'Bank Commonwealth', 'Commonwealth', 'BICNIDJA', 'CMW'); | H16: 166000000000015 | J16: =CONCATENATE( "varSQL := varSQL || (CASE WHEN (varSQL = '') THEN '' ELSE ', ' END) || (SELECT JSON_BUILD_OBJECT (", "'recordID', NULL::bigint,", "'entities', ", "JSON_BUILD_OBJECT (", "'sysLoginSession_RefID', varSystemLoginSession::bigint,", "'sysDataAnnotation', NULL::varchar,", "'sysDataSetDateTimeTZ', NULL::timestamptz,", "'sysDataValidityStartDateTimeTZ', NULL::timestamptz,", "'sysDataValidityFinishDateTimeTZ', NULL::timestamptz,", "'sysPartitionRemovableRecordKey_RefID', NULL::bigint,", "'sysBranch_RefID', varInstitutionBranchID::bigint,", "'sysBaseCurrency_RefID',varBaseCurrencyID::bigint,", "'sysDataAnnotation', ", IF(EXACT($B16, ""), "null", CONCATENATE("'", SUBSTITUTE($B16, "'", "\'"), "'")), "::varchar,", "'acronym', ", IF(EXACT($C16, ""), "null", CONCATENATE("'", SUBSTITUTE($C16, "'", "\'"), "'")), "::varchar,", "'SWIFTCode', ", IF(EXACT($D16, ""), "null", CONCATENATE("'", SUBSTITUTE($D16, "'", "\'"), "'")), "::varchar,", "'bankCode', ", IF(EXACT($E16, ""), "null", CONCATENATE("'", SUBSTITUTE($E16, "'", "\'"), "'")), "::varchar", ")))::varchar;") -> varSQL := varSQL || (CASE WHEN (varSQL = '') THEN '' ELSE ', ' END) || (SELECT JSON_BUILD_OBJECT ('recordID', NULL::bigint,'entities', JSON_BUILD_OBJECT ('sysLoginSession_RefID', varSystemLoginSession::bigint,'sysDataAnnotation', NULL::varchar,'sysDataSetDateTimeTZ', NULL::timestamptz,'sysDataValidityStartDateTimeTZ', NULL::timestamptz,'sysDataValidityFinishDateTimeTZ', NULL::timestamptz,'sysPartitionRemovableRecordKey_RefID', NULL::bigint,'sysBranch_RefID', varInstitutionBranchID::bigint,'sysBaseCurrency_RefID',varBaseCurrencyID::bigint,'sysDataAnnotation', 'Bank Commonwealth'::varchar,'acronym', 'Commonwealth'::varchar,'SWIFTCode', 'BICNIDJA'::varchar,'bankCode', 'CMW'::varchar)))::varchar;
B17: Bank Standard Chartered | D17: SCBLIDJX | E17: SCD | G17: =IF(EXACT(B17, ""), "", CONCATENATE("PERFORM ""SchData-OLTP-Master"".""Func_TblBank_SET""(varSystemLoginSession, null::bigint, null::varchar, null::varchar, varInstitutionBranchID, varBaseCurrencyID, ", IF(EXACT($B17, ""), "null", CONCATENATE("'", $B17, "'")), ", ", IF(EXACT($C17, ""), "null", CONCATENATE("'", $C17, "'")), ", ", IF(EXACT($D17, ""), "null", CONCATENATE("'", $D17, "'")), ", ", IF(EXACT($E17, ""), "null", CONCATENATE("'", $E17, "'")), ");")) -> PERFORM "SchData-OLTP-Master"."Func_TblBank_SET"(varSystemLoginSession, null::bigint, null::varchar, null::varchar, varInstitutionBranchID, varBaseCurrencyID, 'Bank Standard Chartered', null, 'SCBLIDJX', 'SCD'); | H17: 166000000000016 | J17: =CONCATENATE( "varSQL := varSQL || (CASE WHEN (varSQL = '') THEN '' ELSE ', ' END) || (SELECT JSON_BUILD_OBJECT (", "'recordID', NULL::bigint,", "'entities', ", "JSON_BUILD_OBJECT (", "'sysLoginSession_RefID', varSystemLoginSession::bigint,", "'sysDataAnnotation', NULL::varchar,", "'sysDataSetDateTimeTZ', NULL::timestamptz,", "'sysDataValidityStartDateTimeTZ', NULL::timestamptz,", "'sysDataValidityFinishDateTimeTZ', NULL::timestamptz,", "'sysPartitionRemovableRecordKey_RefID', NULL::bigint,", "'sysBranch_RefID', varInstitutionBranchID::bigint,", "'sysBaseCurrency_RefID',varBaseCurrencyID::bigint,", "'sysDataAnnotation', ", IF(EXACT($B17, ""), "null", CONCATENATE("'", SUBSTITUTE($B17, "'", "\'"), "'")), "::varchar,", "'acronym', ", IF(EXACT($C17, ""), "null", CONCATENATE("'", SUBSTITUTE($C17, "'", "\'"), "'")), "::varchar,", "'SWIFTCode', ", IF(EXACT($D17, ""), "null", CONCATENATE("'", SUBSTITUTE($D17, "'", "\'"), "'")), "::varchar,", "'bankCode', ", IF(EXACT($E17, ""), "null", CONCATENATE("'", SUBSTITUTE($E17, "'", "\'"), "'")), "::varchar", ")))::varchar;") -> varSQL := varSQL || (CASE WHEN (varSQL = '') THEN '' ELSE ', ' END) || (SELECT JSON_BUILD_OBJECT ('recordID', NULL::bigint,'entities', JSON_BUILD_OBJECT ('sysLoginSession_RefID', varSystemLoginSession::bigint,'sysDataAnnotation', NULL::varchar,'sysDataSetDateTimeTZ', NULL::timestamptz,'sysDataValidityStartDateTimeTZ', NULL::timestamptz,'sysDataValidityFinishDateTimeTZ', NULL::timestamptz,'sysPartitionRemovableRecordKey_RefID', NULL::bigint,'sysBranch_RefID', varInstitutionBranchID::bigint,'sysBaseCurrency_RefID',varBaseCurrencyID::bigint,'sysDataAnnotation', 'Bank Standard Chartered'::varchar,'acronym', null::varchar,'SWIFTCode', 'SCBLIDJX'::varchar,'bankCode', 'SCD'::varchar)))::varchar;
B18: Bank CIMB Niaga | C18: CIMB Niaga | D18: BNIAIDJA | E18: CIM | G18: =IF(EXACT(B18, ""), "", CONCATENATE("PERFORM ""SchData-OLTP-Master"".""Func_TblBank_SET""(varSystemLoginSession, null::bigint, null::varchar, null::varchar, varInstitutionBranchID, varBaseCurrencyID, ", IF(EXACT($B18, ""), "null", CONCATENATE("'", $B18, "'")), ", ", IF(EXACT($C18, ""), "null", CONCATENATE("'", $C18, "'")), ", ", IF(EXACT($D18, ""), "null", CONCATENATE("'", $D18, "'")), ", ", IF(EXACT($E18, ""), "null", CONCATENATE("'", $E18, "'")), ");")) -> PERFORM "SchData-OLTP-Master"."Func_TblBank_SET"(varSystemLoginSession, null::bigint, null::varchar, null::varchar, varInstitutionBranchID, varBaseCurrencyID, 'Bank CIMB Niaga', 'CIMB Niaga', 'BNIAIDJA', 'CIM'); | H18: 166000000000017 | J18: =CONCATENATE( "varSQL := varSQL || (CASE WHEN (varSQL = '') THEN '' ELSE ', ' END) || (SELECT JSON_BUILD_OBJECT (", "'recordID', NULL::bigint,", "'entities', ", "JSON_BUILD_OBJECT (", "'sysLoginSession_RefID', varSystemLoginSession::bigint,", "'sysDataAnnotation', NULL::varchar,", "'sysDataSetDateTimeTZ', NULL::timestamptz,", "'sysDataValidityStartDateTimeTZ', NULL::timestamptz,", "'sysDataValidityFinishDateTimeTZ', NULL::timestamptz,", "'sysPartitionRemovableRecordKey_RefID', NULL::bigint,", "'sysBranch_RefID', varInstitutionBranchID::bigint,", "'sysBaseCurrency_RefID',varBaseCurrencyID::bigint,", "'sysDataAnnotation', ", IF(EXACT($B18, ""), "null", CONCATENATE("'", SUBSTITUTE($B18, "'", "\'"), "'")), "::varchar,", "'acronym', ", IF(EXACT($C18, ""), "null", CONCATENATE("'", SUBSTITUTE($C18, "'", "\'"), "'")), "::varchar,", "'SWIFTCode', ", IF(EXACT($D18, ""), "null", CONCATENATE("'", SUBSTITUTE($D18, "'", "\'"), "'")), "::varchar,", "'bankCode', ", IF(EXACT($E18, ""), "null", CONCATENATE("'", SUBSTITUTE($E18, "'", "\'"), "'")), "::varchar", ")))::varchar;") -> varSQL := varSQL || (CASE WHEN (varSQL = '') THEN '' ELSE ', ' END) || (SELECT JSON_BUILD_OBJECT ('recordID', NULL::bigint,'entities', JSON_BUILD_OBJECT ('sysLoginSession_RefID', varSystemLoginSession::bigint,'sysDataAnnotation', NULL::varchar,'sysDataSetDateTimeTZ', NULL::timestamptz,'sysDataValidityStartDateTimeTZ', NULL::timestamptz,'sysDataValidityFinishDateTimeTZ', NULL::timestamptz,'sysPartitionRemovableRecordKey_RefID', NULL::bigint,'sysBranch_RefID', varInstitutionBranchID::bigint,'sysBaseCurrency_RefID',varBaseCurrencyID::bigint,'sysDataAnnotation', 'Bank CIMB Niaga'::varchar,'acronym', 'CIMB Niaga'::varchar,'SWIFTCode', 'BNIAIDJA'::varchar,'bankCode', 'CIM'::varchar)))::varchar;
