Workbook

Sheet RAW - HP
B2: 250117820 | C2: Yusri Azhar
B3: 140612611 | C3: Nancy Meriana Sinaga
B4: 210807401 | C4: Galuh Swastika
B5: 310717841 | C5: Maharani Uthmaniah
B6: 50913684 | C6: Elisa Krisnawati
B7: 261016808 | C7: M. Ervan Isyawal Akbar
B8: 161213705 | C8: Chairul Musaddat
B9: 140410529 | C9: Anda Zuchradi Dadi
B10: 10703025 | C10: Indawan Haryadi
B11: 130217822 | C11: Mia Puspitasari
B12: 10314719 | C12: Prayati Zai
B13: 211117851 | C13: Silvia Febi Putri
... B56: 210618875 | C56: Jaenudin
B57: 150419905 | C57: Khafid Fahrurrozi | D57: +62 878-7792-3708
B58: 11018884 | C58: Lucky Daniansyah | D58: +62 812-9397-4227
B59: 100918881 | C59: Rian Yushak | D59: +62 856-9401-0438
B60: 20519907 | C60: Bahyu Sanciko | D60: +62 896-8226-1128
B61: 111103059 | C61: Yusman W | D61: +62 838-7009-0020
B62: 81012521 | C62: Ardi | D62: +62 812-9592-4499
B63: 251016807 | C63: Abdul Rahman Sitompul
B64: 120417831 | C64: Erwin Firmansyah | D64: +62 857-2162-3338
B65: 290118856 | C65: Paryanto | D65: +62 813-8428-4951
B66: 111018884 | C66: Vidhy Putri Kartika | D66: +62 838-7375-2989
B67: 10317827 | C67: Rohendi | D67: +62 822-6092-0555
B68: 71217854 | C68: Anggit Ismiyanto | D68: +62 822-5131-3575
B69: 100613675 | C69: Firman Akbar | D69: +62 812-4519-2298
B70: 231219923 | C70: Fuad Febrian | D70: +62 813-1422-8295
B71: 90819916 | C71: Sulih | D71: +62 857-2881-8103
B72: 140518870 | C72: Heru Sugiri | D72: +62 812-2491-0322
B73: 221007407 | C73: Rinaldi Asrin | D73: +62 818-0691-9844
B74: 100220928 | C74: Rafi Firman Saputra | D74: +62 857-6021-1355
B75: 160718878 | C75: Putra Perdana Tirtomoyo | D75: +62 812-8884-4266
... B82: 31218894 | C82: Herlin Juli Asri | D82: +62 813-1920-7116
B83: 271120940 | C83: Sherly Tamira Happy | D83: +62 811-9568-886 | E83: +62 8128-2230-665
B84: 111218896 | C84: Muhammad Khadafy | D84: +62 812-8744-1774
B85: 251119920 | C85: Hernita Dwi Cahyani Putri | D85: +62 857-7048-1711
B86: 271217855 | C86: Amir Sofyan Hadi | D86: +62 813-1690-6639
B87: 140319901 | C87: Bani Mustazeni | D87: +62 857-1519-9050
B88: 120220929 | C88: Eko Kurniawan | D88: +62 859-4561-9900
B89: 140518871 | C89: Fani Dwi Astutik | D89: +62 812-9902-0267
...

Sheet SEED
B2: DefaultEntity _RefID | C2: Default Entity Name | D2: Email Account Type _RefID | E2: Email Account Type Name | F2: Email Account | G2: Holder Name | I2: SYS_PID Prediction | J2: SQL Syntax
I3: 286000000000000
B4: 124000000000087 | C4: =IF(EXACT($B4, ""), "", IF((($B4 - MOD($B4, 1000000000000))/1000000000000)=25, CONCATENATE("Person - ", VLOOKUP($B4, [1]DataLookUp!$B$4:$C$2000, 2, FALSE)), IF((($B4 - MOD($B4, 1000000000000))/1000000000000)=124, CONCATENATE("Institution - ", VLOOKUP($B4, '[2]DataLookUp - InstitutionBranch'!$B$4:$C$2000, 2, FALSE)), ""))) -> Institution - CV. Anugerah Karya Magantha | D4: 287000000000003 | E4: =IF(EXACT($D4, ""), "", VLOOKUP($D4, 'REF - EmailAccountType'!$B$4:$C$7, 2, FALSE)) -> Business | F4: anugrah_kry@yahoo.com | G4: Leonardo Sampetoding | I4: =I3 + IF(EXACT(J4, ""), 0, 1) -> 286000000000001 | J4: =IF(EXACT(F4, ""), "", CONCATENATE("PERFORM ""SchData-OLTP-Master"".""Func_TblEMailAccount_SET""(varSystemLoginSession::bigint, null::bigint, null::varchar, null::timestamptz, null::timestamptz, null::varchar, varInstitutionBranchID::bigint, varBaseCurrencyID::bigint, ", IF(EXACT($D4, ""), "NULL", ""&$D4&""), "::bigint, ", IF(EXACT($F4, ""), "NULL", "'"&$F4&"'"), "::varchar, ", IF(EXACT($G4, ""), "NULL", "'"&$G4&"'"), "::varchar, ", IF(EXACT($B4, ""), "NULL", "'"&$B4&"'"), "::bigint);")) -> PERFORM "SchData-OLTP-Master"."Func_TblEMailAccount_SET"(varSystemLoginSession::bigint, null::bigint, null::varchar, null::timestamptz, null::timestamptz, null::varchar, varInstitutionBranchID::bigint, varBaseCurrencyID::bigint, 287000000000003::bigint, 'anugrah_kry@yahoo.com'::varchar, 'Leonardo Sampetoding'::varchar, '124000000000087'::bigint);
B5: 124000000000090 | C5: =IF(EXACT($B5, ""), "", IF((($B5 - MOD($B5, 1000000000000))/1000000000000)=25, CONCATENATE("Person - ", VLOOKUP($B5, [1]DataLookUp!$B$4:$C$2000, 2, FALSE)), IF((($B5 - MOD($B5, 1000000000000))/1000000000000)=124, CONCATENATE("Institution - ", VLOOKUP($B5, '[2]DataLookUp - InstitutionBranch'!$B$4:$C$2000, 2, FALSE)), ""))) -> Institution - CV. Cipta Aneka Sarana | D5: 287000000000003 | E5: =IF(EXACT($D5, ""), "", VLOOKUP($D5, 'REF - EmailAccountType'!$B$4:$C$7, 2, FALSE)) -> Business | F5: maxcell_dpt@yahoo.co.id | G5: Maxcell Online Service | I5: =I4 + IF(EXACT(J5, ""), 0, 1) -> 286000000000002 | J5: =IF(EXACT(F5, ""), "", CONCATENATE("PERFORM ""SchData-OLTP-Master"".""Func_TblEMailAccount_SET""(varSystemLoginSession::bigint, null::bigint, null::varchar, null::timestamptz, null::timestamptz, null::varchar, varInstitutionBranchID::bigint, varBaseCurrencyID::bigint, ", IF(EXACT($D5, ""), "NULL", ""&$D5&""), "::bigint, ", IF(EXACT($F5, ""), "NULL", "'"&$F5&"'"), "::varchar, ", IF(EXACT($G5, ""), "NULL", "'"&$G5&"'"), "::varchar, ", IF(EXACT($B5, ""), "NULL", "'"&$B5&"'"), "::bigint);")) -> PERFORM "SchData-OLTP-Master"."Func_TblEMailAccount_SET"(varSystemLoginSession::bigint, null::bigint, null::varchar, null::timestamptz, null::timestamptz, null::varchar, varInstitutionBranchID::bigint, varBaseCurrencyID::bigint, 287000000000003::bigint, 'maxcell_dpt@yahoo.co.id'::varchar, 'Maxcell Online Service'::varchar, '124000000000090'::bigint);
B6: 124000000000091 | C6: =IF(EXACT($B6, ""), "", IF((($B6 - MOD($B6, 1000000000000))/1000000000000)=25, CONCATENATE("Person - ", VLOOKUP($B6, [1]DataLookUp!$B$4:$C$2000, 2, FALSE)), IF((($B6 - MOD($B6, 1000000000000))/1000000000000)=124, CONCATENATE("Institution - ", VLOOKUP($B6, '[2]DataLookUp - InstitutionBranch'!$B$4:$C$2000, 2, FALSE)), ""))) -> Institution - CV. Didi Dan Darwis Survey | D6: 287000000000003 | E6: =IF(EXACT($D6, ""), "", VLOOKUP($D6, 'REF - EmailAccountType'!$B$4:$C$7, 2, FALSE)) -> Business | F6: dndsurvey90@gmail.com | G6: DnD Survey Bandung | I6: =I5 + IF(EXACT(J6, ""), 0, 1) -> 286000000000003 | J6: =IF(EXACT(F6, ""), "", CONCATENATE("PERFORM ""SchData-OLTP-Master"".""Func_TblEMailAccount_SET""(varSystemLoginSession::bigint, null::bigint, null::varchar, null::timestamptz, null::timestamptz, null::varchar, varInstitutionBranchID::bigint, varBaseCurrencyID::bigint, ", IF(EXACT($D6, ""), "NULL", ""&$D6&""), "::bigint, ", IF(EXACT($F6, ""), "NULL", "'"&$F6&"'"), "::varchar, ", IF(EXACT($G6, ""), "NULL", "'"&$G6&"'"), "::varchar, ", IF(EXACT($B6, ""), "NULL", "'"&$B6&"'"), "::bigint);")) -> PERFORM "SchData-OLTP-Master"."Func_TblEMailAccount_SET"(varSystemLoginSession::bigint, null::bigint, null::varchar, null::timestamptz, null::timestamptz, null::varchar, varInstitutionBranchID::bigint, varBaseCurrencyID::bigint, 287000000000003::bigint, 'dndsurvey90@gmail.com'::varchar, 'DnD Survey Bandung'::varchar, '124000000000091'::bigint);
B7: 124000000000094 | C7: =IF(EXACT($B7, ""), "", IF((($B7 - MOD($B7, 1000000000000))/1000000000000)=25, CONCATENATE("Person - ", VLOOKUP($B7, [1]DataLookUp!$B$4:$C$2000, 2, FALSE)), IF((($B7 - MOD($B7, 1000000000000))/1000000000000)=124, CONCATENATE("Institution - ", VLOOKUP($B7, '[2]DataLookUp - InstitutionBranch'!$B$4:$C$2000, 2, FALSE)), ""))) -> Institution - CV. Edi Jaya Bangunan | D7: 287000000000003 | E7: =IF(EXACT($D7, ""), "", VLOOKUP($D7, 'REF - EmailAccountType'!$B$4:$C$7, 2, FALSE)) -> Business | F7: ejbpbun@gmail.com | G7: Edi Nuryanto | I7: =I6 + IF(EXACT(J7, ""), 0, 1) -> 286000000000004 | J7: =IF(EXACT(F7, ""), "", CONCATENATE("PERFORM ""SchData-OLTP-Master"".""Func_TblEMailAccount_SET""(varSystemLoginSession::bigint, null::bigint, null::varchar, null::timestamptz, null::timestamptz, null::varchar, varInstitutionBranchID::bigint, varBaseCurrencyID::bigint, ", IF(EXACT($D7, ""), "NULL", ""&$D7&""), "::bigint, ", IF(EXACT($F7, ""), "NULL", "'"&$F7&"'"), "::varchar, ", IF(EXACT($G7, ""), "NULL", "'"&$G7&"'"), "::varchar, ", IF(EXACT($B7, ""), "NULL", "'"&$B7&"'"), "::bigint);")) -> PERFORM "SchData-OLTP-Master"."Func_TblEMailAccount_SET"(varSystemLoginSession::bigint, null::bigint, null::varchar, null::timestamptz, null::timestamptz, null::varchar, varInstitutionBranchID::bigint, varBaseCurrencyID::bigint, 287000000000003::bigint, 'ejbpbun@gmail.com'::varchar, 'Edi Nuryanto'::varchar, '124000000000094'::bigint);
B8: 124000000000096 | C8: =IF(EXACT($B8, ""), "", IF((($B8 - MOD($B8, 1000000000000))/1000000000000)=25, CONCATENATE("Person - ", VLOOKUP($B8, [1]DataLookUp!$B$4:$C$2000, 2, FALSE)), IF((($B8 - MOD($B8, 1000000000000))/1000000000000)=124, CONCATENATE("Institution - ", VLOOKUP($B8, '[2]DataLookUp - InstitutionBranch'!$B$4:$C$2000, 2, FALSE)), ""))) -> Institution - CV. Gallazka Teknik | D8: 287000000000003 | E8: =IF(EXACT($D8, ""), "", VLOOKUP($D8, 'REF - EmailAccountType'!$B$4:$C$7, 2, FALSE)) -> Business | F8: gallazkateknik@gmail.com | G8: Wartim | I8: =I7 + IF(EXACT(J8, ""), 0, 1) -> 286000000000005 | J8: =IF(EXACT(F8, ""), "", CONCATENATE("PERFORM ""SchData-OLTP-Master"".""Func_TblEMailAccount_SET""(varSystemLoginSession::bigint, null::bigint, null::varchar, null::timestamptz, null::timestamptz, null::varchar, varInstitutionBranchID::bigint, varBaseCurrencyID::bigint, ", IF(EXACT($D8, ""), "NULL", ""&$D8&""), "::bigint, ", IF(EXACT($F8, ""), "NULL", "'"&$F8&"'"), "::varchar, ", IF(EXACT($G8, ""), "NULL", "'"&$G8&"'"), "::varchar, ", IF(EXACT($B8, ""), "NULL", "'"&$B8&"'"), "::bigint);")) -> PERFORM "SchData-OLTP-Master"."Func_TblEMailAccount_SET"(varSystemLoginSession::bigint, null::bigint, null::varchar, null::timestamptz, null::timestamptz, null::varchar, varInstitutionBranchID::bigint, varBaseCurrencyID::bigint, 287000000000003::bigint, 'gallazkateknik@gmail.com'::varchar, 'Wartim'::varchar, '124000000000096'::bigint);
B9: 124000000000099 | C9: =IF(EXACT($B9, ""), "", IF((($B9 - MOD($B9, 1000000000000))/1000000000000)=25, CONCATENATE("Person - ", VLOOKUP($B9, [1]DataLookUp!$B$4:$C$2000, 2, FALSE)), IF((($B9 - MOD($B9, 1000000000000))/1000000000000)=124, CONCATENATE("Institution - ", VLOOKUP($B9, '[2]DataLookUp - InstitutionBranch'!$B$4:$C$2000, 2, FALSE)), ""))) -> Institution - CV. Jember Elektrindo Gemilang | D9: 287000000000003 | E9: =IF(EXACT($D9, ""), "", VLOOKUP($D9, 'REF - EmailAccountType'!$B$4:$C$7, 2, FALSE)) -> Business | F9: owner.grd@gmail.com | G9: Sigit | I9: =I8 + IF(EXACT(J9, ""), 0, 1) -> 286000000000006 | J9: =IF(EXACT(F9, ""), "", CONCATENATE("PERFORM ""SchData-OLTP-Master"".""Func_TblEMailAccount_SET""(varSystemLoginSession::bigint, null::bigint, null::varchar, null::timestamptz, null::timestamptz, null::varchar, varInstitutionBranchID::bigint, varBaseCurrencyID::bigint, ", IF(EXACT($D9, ""), "NULL", ""&$D9&""), "::bigint, ", IF(EXACT($F9, ""), "NULL", "'"&$F9&"'"), "::varchar, ", IF(EXACT($G9, ""), "NULL", "'"&$G9&"'"), "::varchar, ", IF(EXACT($B9, ""), "NULL", "'"&$B9&"'"), "::bigint);")) -> PERFORM "SchData-OLTP-Master"."Func_TblEMailAccount_SET"(varSystemLoginSession::bigint, null::bigint, null::varchar, null::timestamptz, null::timestamptz, null::varchar, varInstitutionBranchID::bigint, varBaseCurrencyID::bigint, 287000000000003::bigint, 'owner.grd@gmail.com'::varchar, 'Sigit'::varchar, '124000000000099'::bigint);
B10: 124000000000106 | C10: =IF(EXACT($B10, ""), "", IF((($B10 - MOD($B10, 1000000000000))/1000000000000)=25, CONCATENATE("Person - ", VLOOKUP($B10, [1]DataLookUp!$B$4:$C$2000, 2, FALSE)), IF((($B10 - MOD($B10, 1000000000000))/1000000000000)=124, CONCATENATE("Institution - ", VLOOKUP($B10, '[2]DataLookUp - InstitutionBranch'!$B$4:$C$2000, 2, FALSE)), ""))) -> Institution - CV. Punokawan | D10: 287000000000003 | E10: =IF(EXACT($D10, ""), "", VLOOKUP($D10, 'REF - EmailAccountType'!$B$4:$C$7, 2, FALSE)) -> Business | F10: punokawan_smrg@yahoo.co.id | G10: Heri | I10: =I9 + IF(EXACT(J10, ""), 0, 1) -> 286000000000007 | J10: =IF(EXACT(F10, ""), "", CONCATENATE("PERFORM ""SchData-OLTP-Master"".""Func_TblEMailAccount_SET""(varSystemLoginSession::bigint, null::bigint, null::varchar, null::timestamptz, null::timestamptz, null::varchar, varInstitutionBranchID::bigint, varBaseCurrencyID::bigint, ", IF(EXACT($D10, ""), "NULL", ""&$D10&""), "::bigint, ", IF(EXACT($F10, ""), "NULL", "'"&$F10&"'"), "::varchar, ", IF(EXACT($G10, ""), "NULL", "'"&$G10&"'"), "::varchar, ", IF(EXACT($B10, ""), "NULL", "'"&$B10&"'"), "::bigint);")) -> PERFORM "SchData-OLTP-Master"."Func_TblEMailAccount_SET"(varSystemLoginSession::bigint, null::bigint, null::varchar, null::timestamptz, null::timestamptz, null::varchar, varInstitutionBranchID::bigint, varBaseCurrencyID::bigint, 287000000000003::bigint, 'punokawan_smrg@yahoo.co.id'::varchar, 'Heri'::varchar, '124000000000106'::bigint);
B11: 124000000000114 | C11: =IF(EXACT($B11, ""), "", IF((($B11 - MOD($B11, 1000000000000))/1000000000000)=25, CONCATENATE("Person - ", VLOOKUP($B11, [1]DataLookUp!$B$4:$C$2000, 2, FALSE)), IF((($B11 - MOD($B11, 1000000000000))/1000000000000)=124, CONCATENATE("Institution - ", VLOOKUP($B11, '[2]DataLookUp - InstitutionBranch'!$B$4:$C$2000, 2, FALSE)), ""))) -> Institution - PT. Abadi Rajawali Semesta | D11: 287000000000003 | E11: =IF(EXACT($D11, ""), "", VLOOKUP($D11, 'REF - EmailAccountType'!$B$4:$C$7, 2, FALSE)) -> Business | F11: office@ptasrs.id | G11: Shira | I11: =I10 + IF(EXACT(J11, ""), 0, 1) -> 286000000000008 | J11: =IF(EXACT(F11, ""), "", CONCATENATE("PERFORM ""SchData-OLTP-Master"".""Func_TblEMailAccount_SET""(varSystemLoginSession::bigint, null::bigint, null::varchar, null::timestamptz, null::timestamptz, null::varchar, varInstitutionBranchID::bigint, varBaseCurrencyID::bigint, ", IF(EXACT($D11, ""), "NULL", ""&$D11&""), "::bigint, ", IF(EXACT($F11, ""), "NULL", "'"&$F11&"'"), "::varchar, ", IF(EXACT($G11, ""), "NULL", "'"&$G11&"'"), "::varchar, ", IF(EXACT($B11, ""), "NULL", "'"&$B11&"'"), "::bigint);")) -> PERFORM "SchData-OLTP-Master"."Func_TblEMailAccount_SET"(varSystemLoginSession::bigint, null::bigint, null::varchar, null::timestamptz, null::timestamptz, null::varchar, varInstitutionBranchID::bigint, varBaseCurrencyID::bigint, 287000000000003::bigint, 'office@ptasrs.id'::varchar, 'Shira'::varchar, '124000000000114'::bigint);
B12: 124000000000117 | C12: =IF(EXACT($B12, ""), "", IF((($B12 - MOD($B12, 1000000000000))/1000000000000)=25, CONCATENATE("Person - ", VLOOKUP($B12, [1]DataLookUp!$B$4:$C$2000, 2, FALSE)), IF((($B12 - MOD($B12, 1000000000000))/1000000000000)=124, CONCATENATE("Institution - ", VLOOKUP($B12, '[2]DataLookUp - InstitutionBranch'!$B$4:$C$2000, 2, FALSE)), ""))) -> Institution - PT. Agape Biomedi Investama | D12: 287000000000003 | E12: =IF(EXACT($D12, ""), "", VLOOKUP($D12, 'REF - EmailAccountType'!$B$4:$C$7, 2, FALSE)) -> Business | F12: info@biomedilab.co.id | G12: PT. Agape Biomedi Investama | I12: =I11 + IF(EXACT(J12, ""), 0, 1) -> 286000000000009 | J12: =IF(EXACT(F12, ""), "", CONCATENATE("PERFORM ""SchData-OLTP-Master"".""Func_TblEMailAccount_SET""(varSystemLoginSession::bigint, null::bigint, null::varchar, null::timestamptz, null::timestamptz, null::varchar, varInstitutionBranchID::bigint, varBaseCurrencyID::bigint, ", IF(EXACT($D12, ""), "NULL", ""&$D12&""), "::bigint, ", IF(EXACT($F12, ""), "NULL", "'"&$F12&"'"), "::varchar, ", IF(EXACT($G12, ""), "NULL", "'"&$G12&"'"), "::varchar, ", IF(EXACT($B12, ""), "NULL", "'"&$B12&"'"), "::bigint);")) -> PERFORM "SchData-OLTP-Master"."Func_TblEMailAccount_SET"(varSystemLoginSession::bigint, null::bigint, null::varchar, null::timestamptz, null::timestamptz, null::varchar, varInstitutionBranchID::bigint, varBaseCurrencyID::bigint, 287000000000003::bigint, 'info@biomedilab.co.id'::varchar, 'PT. Agape Biomedi Investama'::varchar, '124000000000117'::bigint);
B13: 124000000000121 | C13: =IF(EXACT($B13, ""), "", IF((($B13 - MOD($B13, 1000000000000))/1000000000000)=25, CONCATENATE("Person - ", VLOOKUP($B13, [1]DataLookUp!$B$4:$C$2000, 2, FALSE)), IF((($B13 - MOD($B13, 1000000000000))/1000000000000)=124, CONCATENATE("Institution - ", VLOOKUP($B13, '[2]DataLookUp - InstitutionBranch'!$B$4:$C$2000, 2, FALSE)), ""))) -> Institution - PT. Asiatronic Indo Makmur | D13: 287000000000003 | E13: =IF(EXACT($D13, ""), "", VLOOKUP($D13, 'REF - EmailAccountType'!$B$4:$C$7, 2, FALSE)) -> Business | F13: yehezkiel_jc@yahoo.com08 | G13: Yehezkiel Yosafat | I13: =I12 + IF(EXACT(J13, ""), 0, 1) -> 286000000000010 | J13: =IF(EXACT(F13, ""), "", CONCATENATE("PERFORM ""SchData-OLTP-Master"".""Func_TblEMailAccount_SET""(varSystemLoginSession::bigint, null::bigint, null::varchar, null::timestamptz, null::timestamptz, null::varchar, varInstitutionBranchID::bigint, varBaseCurrencyID::bigint, ", IF(EXACT($D13, ""), "NULL", ""&$D13&""), "::bigint, ", IF(EXACT($F13, ""), "NULL", "'"&$F13&"'"), "::varchar, ", IF(EXACT($G13, ""), "NULL", "'"&$G13&"'"), "::varchar, ", IF(EXACT($B13, ""), "NULL", "'"&$B13&"'"), "::bigint);")) -> PERFORM "SchData-OLTP-Master"."Func_TblEMailAccount_SET"(varSystemLoginSession::bigint, null::bigint, null::varchar, null::timestamptz, null::timestamptz, null::varchar, varInstitutionBranchID::bigint, varBaseCurrencyID::bigint, 287000000000003::bigint, 'yehezkiel_jc@yahoo.com08'::varchar, 'Yehezkiel Yosafat'::varchar, '124000000000121'::bigint);
B14: 124000000000128 | C14: =IF(EXACT($B14, ""), "", IF((($B14 - MOD($B14, 1000000000000))/1000000000000)=25, CONCATENATE("Person - ", VLOOKUP($B14, [1]DataLookUp!$B$4:$C$2000, 2, FALSE)), IF((($B14 - MOD($B14, 1000000000000))/1000000000000)=124, CONCATENATE("Institution - ", VLOOKUP($B14, '[2]DataLookUp - InstitutionBranch'!$B$4:$C$2000, 2, FALSE)), ""))) -> Institution - PT. Berkat Sahabat Sejati | D14: 287000000000003 | E14: =IF(EXACT($D14, ""), "", VLOOKUP($D14, 'REF - EmailAccountType'!$B$4:$C$7, 2, FALSE)) -> Business | F14: pemudaban@ymail.com | G14: Pemuda | I14: =I13 + IF(EXACT(J14, ""), 0, 1) -> 286000000000011 | J14: =IF(EXACT(F14, ""), "", CONCATENATE("PERFORM ""SchData-OLTP-Master"".""Func_TblEMailAccount_SET""(varSystemLoginSession::bigint, null::bigint, null::varchar, null::timestamptz, null::timestamptz, null::varchar, varInstitutionBranchID::bigint, varBaseCurrencyID::bigint, ", IF(EXACT($D14, ""), "NULL", ""&$D14&""), "::bigint, ", IF(EXACT($F14, ""), "NULL", "'"&$F14&"'"), "::varchar, ", IF(EXACT($G14, ""), "NULL", "'"&$G14&"'"), "::varchar, ", IF(EXACT($B14, ""), "NULL", "'"&$B14&"'"), "::bigint);")) -> PERFORM "SchData-OLTP-Master"."Func_TblEMailAccount_SET"(varSystemLoginSession::bigint, null::bigint, null::varchar, null::timestamptz, null::timestamptz, null::varchar, varInstitutionBranchID::bigint, varBaseCurrencyID::bigint, 287000000000003::bigint, 'pemudaban@ymail.com'::varchar, 'Pemuda'::varchar, '124000000000128'::bigint);
B15: 124000000000130 | C15: =IF(EXACT($B15, ""), "", IF((($B15 - MOD($B15, 1000000000000))/1000000000000)=25, CONCATENATE("Person - ", VLOOKUP($B15, [1]DataLookUp!$B$4:$C$2000, 2, FALSE)), IF((($B15 - MOD($B15, 1000000000000))/1000000000000)=124, CONCATENATE("Institution - ", VLOOKUP($B15, '[2]DataLookUp - InstitutionBranch'!$B$4:$C$2000, 2, FALSE)), ""))) -> Institution - PT. Beton Perkasa Wijaksana | D15: 287000000000003 | E15: =IF(EXACT($D15, ""), "", VLOOKUP($D15, 'REF - EmailAccountType'!$B$4:$C$7, 2, FALSE)) -> Business | F15: sigit.koentjoro@betonperkasa.c | G15: Sigit Koencoro | I15: =I14 + IF(EXACT(J15, ""), 0, 1) -> 286000000000012 | J15: =IF(EXACT(F15, ""), "", CONCATENATE("PERFORM ""SchData-OLTP-Master"".""Func_TblEMailAccount_SET""(varSystemLoginSession::bigint, null::bigint, null::varchar, null::timestamptz, null::timestamptz, null::varchar, varInstitutionBranchID::bigint, varBaseCurrencyID::bigint, ", IF(EXACT($D15, ""), "NULL", ""&$D15&""), "::bigint, ", IF(EXACT($F15, ""), "NULL", "'"&$F15&"'"), "::varchar, ", IF(EXACT($G15, ""), "NULL", "'"&$G15&"'"), "::varchar, ", IF(EXACT($B15, ""), "NULL", "'"&$B15&"'"), "::bigint);")) -> PERFORM "SchData-OLTP-Master"."Func_TblEMailAccount_SET"(varSystemLoginSession::bigint, null::bigint, null::varchar, null::timestamptz, null::timestamptz, null::varchar, varInstitutionBranchID::bigint, varBaseCurrencyID::bigint, 287000000000003::bigint, 'sigit.koentjoro@betonperkasa.c'::varchar, 'Sigit Koencoro'::varchar, '124000000000130'::bigint);
... B18: 124000000000136 | C18: =IF(EXACT($B18, ""), "", IF((($B18 - MOD($B18, 1000000000000))/1000000000000)=25, CONCATENATE("Person - ", VLOOKUP($B18, [1]DataLookUp!$B$4:$C$2000, 2, FALSE)), IF((($B18 - MOD($B18, 1000000000000))/1000000000000)=124, CONCATENATE("Institution - ", VLOOKUP($B18, '[2]DataLookUp - InstitutionBranch'!$B$4:$C$2000, 2, FALSE)), ""))) -> Institution - PT. Blue Power International | D18: 287000000000003 | E18: =IF(EXACT($D18, ""), "", VLOOKUP($D18, 'REF - EmailAccountType'!$B$4:$C$7, 2, FALSE)) -> Business | F18: service@bpi-id.com | G18: Yani | I18: =I17 + IF(EXACT(J18, ""), 0, 1) -> 286000000000015 | J18: =IF(EXACT(F18, ""), "", CONCATENATE("PERFORM ""SchData-OLTP-Master"".""Func_TblEMailAccount_SET""(varSystemLoginSession::bigint, null::bigint, null::varchar, null::timestamptz, null::timestamptz, null::varchar, varInstitutionBranchID::bigint, varBaseCurrencyID::bigint, ", IF(EXACT($D18, ""), "NULL", ""&$D18&""), "::bigint, ", IF(EXACT($F18, ""), "NULL", "'"&$F18&"'"), "::varchar, ", IF(EXACT($G18, ""), "NULL", "'"&$G18&"'"), "::varchar, ", IF(EXACT($B18, ""), "NULL", "'"&$B18&"'"), "::bigint);")) -> PERFORM "SchData-OLTP-Master"."Func_TblEMailAccount_SET"(varSystemLoginSession::bigint, null::bigint, null::varchar, null::timestamptz, null::timestamptz, null::varchar, varInstitutionBranchID::bigint, varBaseCurrencyID::bigint, 287000000000003::bigint, 'service@bpi-id.com'::varchar, 'Yani'::varchar, '124000000000136'::bigint);
B19: 124000000000139 | C19: =IF(EXACT($B19, ""), "", IF((($B19 - MOD($B19, 1000000000000))/1000000000000)=25, CONCATENATE("Person - ", VLOOKUP($B19, [1]DataLookUp!$B$4:$C$2000, 2, FALSE)), IF((($B19 - MOD($B19, 1000000000000))/1000000000000)=124, CONCATENATE("Institution - ", VLOOKUP($B19, '[2]DataLookUp - InstitutionBranch'!$B$4:$C$2000, 2, FALSE)), ""))) -> Institution - PT. Cahaya Mentari Cemerlang | D19: 287000000000003 | E19: =IF(EXACT($D19, ""), "", VLOOKUP($D19, 'REF - EmailAccountType'!$B$4:$C$7, 2, FALSE)) -> Business | F19: mentariplywood@yahoo.com | I19: =I18 + IF(EXACT(J19, ""), 0, 1) -> 286000000000016 | J19: =IF(EXACT(F19, ""), "", CONCATENATE("PERFORM ""SchData-OLTP-Master"".""Func_TblEMailAccount_SET""(varSystemLoginSession::bigint, null::bigint, null::varchar, null::timestamptz, null::timestamptz, null::varchar, varInstitutionBranchID::bigint, varBaseCurrencyID::bigint, ", IF(EXACT($D19, ""), "NULL", ""&$D19&""), "::bigint, ", IF(EXACT($F19, ""), "NULL", "'"&$F19&"'"), "::varchar, ", IF(EXACT($G19, ""), "NULL", "'"&$G19&"'"), "::varchar, ", IF(EXACT($B19, ""), "NULL", "'"&$B19&"'"), "::bigint);")) -> PERFORM "SchData-OLTP-Master"."Func_TblEMailAccount_SET"(varSystemLoginSession::bigint, null::bigint, null::varchar, null::timestamptz, null::timestamptz, null::varchar, varInstitutionBranchID::bigint, varBaseCurrencyID::bigint, 287000000000003::bigint, 'mentariplywood@yahoo.com'::varchar, NULL::varchar, '124000000000139'::bigint);
B20: 124000000000140 | C20: =IF(EXACT($B20, ""), "", IF((($B20 - MOD($B20, 1000000000000))/1000000000000)=25, CONCATENATE("Person - ", VLOOKUP($B20, [1]DataLookUp!$B$4:$C$2000, 2, FALSE)), IF((($B20 - MOD($B20, 1000000000000))/1000000000000)=124, CONCATENATE("Institution - ", VLOOKUP($B20, '[2]DataLookUp - InstitutionBranch'!$B$4:$C$2000, 2, FALSE)), ""))) -> Institution - PT. Cakrawala Persada Internasional | D20: 287000000000003 | E20: =IF(EXACT($D20, ""), "", VLOOKUP($D20, 'REF - EmailAccountType'!$B$4:$C$7, 2, FALSE)) -> Business | F20: Mona@cakrawalainternasional.co | G20: Mona | I20: =I19 + IF(EXACT(J20, ""), 0, 1) -> 286000000000017 | J20: =IF(EXACT(F20, ""), "", CONCATENATE("PERFORM ""SchData-OLTP-Master"".""Func_TblEMailAccount_SET""(varSystemLoginSession::bigint, null::bigint, null::varchar, null::timestamptz, null::timestamptz, null::varchar, varInstitutionBranchID::bigint, varBaseCurrencyID::bigint, ", IF(EXACT($D20, ""), "NULL", ""&$D20&""), "::bigint, ", IF(EXACT($F20, ""), "NULL", "'"&$F20&"'"), "::varchar, ", IF(EXACT($G20, ""), "NULL", "'"&$G20&"'"), "::varchar, ", IF(EXACT($B20, ""), "NULL", "'"&$B20&"'"), "::bigint);")) -> PERFORM "SchData-OLTP-Master"."Func_TblEMailAccount_SET"(varSystemLoginSession::bigint, null::bigint, null::varchar, null::timestamptz, null::timestamptz, null::varchar, varInstitutionBranchID::bigint, varBaseCurrencyID::bigint, 287000000000003::bigint, 'Mona@cakrawalainternasional.co'::varchar, 'Mona'::varchar, '124000000000140'::bigint);
B21: 124000000000141 | C21: =IF(EXACT($B21, ""), "", IF((($B21 - MOD($B21, 1000000000000))/1000000000000)=25, CONCATENATE("Person - ", VLOOKUP($B21, [1]DataLookUp!$B$4:$C$2000, 2, FALSE)), IF((($B21 - MOD($B21, 1000000000000))/1000000000000)=124, CONCATENATE("Institution - ", VLOOKUP($B21, '[2]DataLookUp - InstitutionBranch'!$B$4:$C$2000, 2, FALSE)), ""))) -> Institution - PT. Caroline Trans Mandiri | D21: 287000000000003 | E21: =IF(EXACT($D21, ""), "", VLOOKUP($D21, 'REF - EmailAccountType'!$B$4:$C$7, 2, FALSE)) -> Business | F21: carolinetrans@yahoo.com | G21: Dohar Lumbanraja | I21: =I20 + IF(EXACT(J21, ""), 0, 1) -> 286000000000018 | J21: =IF(EXACT(F21, ""), "", CONCATENATE("PERFORM ""SchData-OLTP-Master"".""Func_TblEMailAccount_SET""(varSystemLoginSession::bigint, null::bigint, null::varchar, null::timestamptz, null::timestamptz, null::varchar, varInstitutionBranchID::bigint, varBaseCurrencyID::bigint, ", IF(EXACT($D21, ""), "NULL", ""&$D21&""), "::bigint, ", IF(EXACT($F21, ""), "NULL", "'"&$F21&"'"), "::varchar, ", IF(EXACT($G21, ""), "NULL", "'"&$G21&"'"), "::varchar, ", IF(EXACT($B21, ""), "NULL", "'"&$B21&"'"), "::bigint);")) -> PERFORM "SchData-OLTP-Master"."Func_TblEMailAccount_SET"(varSystemLoginSession::bigint, null::bigint, null::varchar, null::timestamptz, null::timestamptz, null::varchar, varInstitutionBranchID::bigint, varBaseCurrencyID::bigint, 287000000000003::bigint, 'carolinetrans@yahoo.com'::varchar, 'Dohar Lumbanraja'::varchar, '124000000000141'::bigint);
B22: 124000000000143 | C22: =IF(EXACT($B22, ""), "", IF((($B22 - MOD($B22, 1000000000000))/1000000000000)=25, CONCATENATE("Person - ", VLOOKUP($B22, [1]DataLookUp!$B$4:$C$2000, 2, FALSE)), IF((($B22 - MOD($B22, 1000000000000))/1000000000000)=124, CONCATENATE("Institution - ", VLOOKUP($B22, '[2]DataLookUp - InstitutionBranch'!$B$4:$C$2000, 2, FALSE)), ""))) -> Institution - PT. Citra Banjar Abadi | D22: 287000000000003 | E22: =IF(EXACT($D22, ""), "", VLOOKUP($D22, 'REF - EmailAccountType'!$B$4:$C$7, 2, FALSE)) -> Business | F22: citrabanjar@gmail.com / soleha | G22: Solehan | I22: =I21 + IF(EXACT(J22, ""), 0, 1) -> 286000000000019 | J22: =IF(EXACT(F22, ""), "", CONCATENATE("PERFORM ""SchData-OLTP-Master"".""Func_TblEMailAccount_SET""(varSystemLoginSession::bigint, null::bigint, null::varchar, null::timestamptz, null::timestamptz, null::varchar, varInstitutionBranchID::bigint, varBaseCurrencyID::bigint, ", IF(EXACT($D22, ""), "NULL", ""&$D22&""), "::bigint, ", IF(EXACT($F22, ""), "NULL", "'"&$F22&"'"), "::varchar, ", IF(EXACT($G22, ""), "NULL", "'"&$G22&"'"), "::varchar, ", IF(EXACT($B22, ""), "NULL", "'"&$B22&"'"), "::bigint);")) -> PERFORM "SchData-OLTP-Master"."Func_TblEMailAccount_SET"(varSystemLoginSession::bigint, null::bigint, null::varchar, null::timestamptz, null::timestamptz, null::varchar, varInstitutionBranchID::bigint, varBaseCurrencyID::bigint, 287000000000003::bigint, 'citrabanjar@gmail.com / soleha'::varchar, 'Solehan'::varchar, '124000000000143'::bigint);
B23: 124000000000144 | C23: =IF(EXACT($B23, ""), "", IF((($B23 - MOD($B23, 1000000000000))/1000000000000)=25, CONCATENATE("Person - ", VLOOKUP($B23, [1]DataLookUp!$B$4:$C$2000, 2, FALSE)), IF((($B23 - MOD($B23, 1000000000000))/1000000000000)=124, CONCATENATE("Institution - ", VLOOKUP($B23, '[2]DataLookUp - InstitutionBranch'!$B$4:$C$2000, 2, FALSE)), ""))) -> Institution - PT. Datascrip | D23: 287000000000003 | E23: =IF(EXACT($D23, ""), "", VLOOKUP($D23, 'REF - EmailAccountType'!$B$4:$C$7, 2, FALSE)) -> Business | F23: sahat@datascrip.co.id | G23: Sahat | I23: =I22 + IF(EXACT(J23, ""), 0, 1) -> 286000000000020 | J23: =IF(EXACT(F23, ""), "", CONCATENATE("PERFORM ""SchData-OLTP-Master"".""Func_TblEMailAccount_SET""(varSystemLoginSession::bigint, null::bigint, null::varchar, null::timestamptz, null::timestamptz, null::varchar, varInstitutionBranchID::bigint, varBaseCurrencyID::bigint, ", IF(EXACT($D23, ""), "NULL", ""&$D23&""), "::bigint, ", IF(EXACT($F23, ""), "NULL", "'"&$F23&"'"), "::varchar, ", IF(EXACT($G23, ""), "NULL", "'"&$G23&"'"), "::varchar, ", IF(EXACT($B23, ""), "NULL", "'"&$B23&"'"), "::bigint);")) -> PERFORM "SchData-OLTP-Master"."Func_TblEMailAccount_SET"(varSystemLoginSession::bigint, null::bigint, null::varchar, null::timestamptz, null::timestamptz, null::varchar, varInstitutionBranchID::bigint, varBaseCurrencyID::bigint, 287000000000003::bigint, 'sahat@datascrip.co.id'::varchar, 'Sahat'::varchar, '124000000000144'::bigint);
B24: 124000000000145 | C24: =IF(EXACT($B24, ""), "", IF((($B24 - MOD($B24, 1000000000000))/1000000000000)=25, CONCATENATE("Person - ", VLOOKUP($B24, [1]DataLookUp!$B$4:$C$2000, 2, FALSE)), IF((($B24 - MOD($B24, 1000000000000))/1000000000000)=124, CONCATENATE("Institution - ", VLOOKUP($B24, '[2]DataLookUp - InstitutionBranch'!$B$4:$C$2000, 2, FALSE)), ""))) -> Institution - PT. Denko Wahana Sakti | D24: 287000000000003 | E24: =IF(EXACT($D24, ""), "", VLOOKUP($D24, 'REF - EmailAccountType'!$B$4:$C$7, 2, FALSE)) -> Business | F24: indro@denko.co.id | G24: Indro | I24: =I23 + IF(EXACT(J24, ""), 0, 1) -> 286000000000021 | J24: =IF(EXACT(F24, ""), "", CONCATENATE("PERFORM ""SchData-OLTP-Master"".""Func_TblEMailAccount_SET""(varSystemLoginSession::bigint, null::bigint, null::varchar, null::timestamptz, null::timestamptz, null::varchar, varInstitutionBranchID::bigint, varBaseCurrencyID::bigint, ", IF(EXACT($D24, ""), "NULL", ""&$D24&""), "::bigint, ", IF(EXACT($F24, ""), "NULL", "'"&$F24&"'"), "::varchar, ", IF(EXACT($G24, ""), "NULL", "'"&$G24&"'"), "::varchar, ", IF(EXACT($B24, ""), "NULL", "'"&$B24&"'"), "::bigint);")) -> PERFORM "SchData-OLTP-Master"."Func_TblEMailAccount_SET"(varSystemLoginSession::bigint, null::bigint, null::varchar, null::timestamptz, null::timestamptz, null::varchar, varInstitutionBranchID::bigint, varBaseCurrencyID::bigint, 287000000000003::bigint, 'indro@denko.co.id'::varchar, 'Indro'::varchar, '124000000000145'::bigint);
B25: 124000000000151 | C25: =IF(EXACT($B25, ""), "", IF((($B25 - MOD($B25, 1000000000000))/1000000000000)=25, CONCATENATE("Person - ", VLOOKUP($B25, [1]DataLookUp!$B$4:$C$2000, 2, FALSE)), IF((($B25 - MOD($B25, 1000000000000))/1000000000000)=124, CONCATENATE("Institution - ", VLOOKUP($B25, '[2]DataLookUp - InstitutionBranch'!$B$4:$C$2000, 2, FALSE)), ""))) -> Institution - PT. Dwimitra Sejahtera Bersama | D25: 287000000000003 | E25: =IF(EXACT($D25, ""), "", VLOOKUP($D25, 'REF - EmailAccountType'!$B$4:$C$7, 2, FALSE)) -> Business | F25: marketing.dwimitra@gmail.com | G25: Devi | I25: =I24 + IF(EXACT(J25, ""), 0, 1) -> 286000000000022 | J25: =IF(EXACT(F25, ""), "", CONCATENATE("PERFORM ""SchData-OLTP-Master"".""Func_TblEMailAccount_SET""(varSystemLoginSession::bigint, null::bigint, null::varchar, null::timestamptz, null::timestamptz, null::varchar, varInstitutionBranchID::bigint, varBaseCurrencyID::bigint, ", IF(EXACT($D25, ""), "NULL", ""&$D25&""), "::bigint, ", IF(EXACT($F25, ""), "NULL", "'"&$F25&"'"), "::varchar, ", IF(EXACT($G25, ""), "NULL", "'"&$G25&"'"), "::varchar, ", IF(EXACT($B25, ""), "NULL", "'"&$B25&"'"), "::bigint);")) -> PERFORM "SchData-OLTP-Master"."Func_TblEMailAccount_SET"(varSystemLoginSession::bigint, null::bigint, null::varchar, null::timestamptz, null::timestamptz, null::varchar, varInstitutionBranchID::bigint, varBaseCurrencyID::bigint, 287000000000003::bigint, 'marketing.dwimitra@gmail.com'::varchar, 'Devi'::varchar, '124000000000151'::bigint);
B26: 124000000000153 | C26: =IF(EXACT($B26, ""), "", IF((($B26 - MOD($B26, 1000000000000))/1000000000000)=25, CONCATENATE("Person - ", VLOOKUP($B26, [1]DataLookUp!$B$4:$C$2000, 2, FALSE)), IF((($B26 - MOD($B26, 1000000000000))/1000000000000)=124, CONCATENATE("Institution - ", VLOOKUP($B26, '[2]DataLookUp - InstitutionBranch'!$B$4:$C$2000, 2, FALSE)), ""))) -> Institution - PT. Fortindo Maju Bersama | D26: 287000000000003 | E26: =IF(EXACT($D26, ""), "", VLOOKUP($D26, 'REF - EmailAccountType'!$B$4:$C$7, 2, FALSE)) -> Business | F26: adm.fortindo.id@gmail.com | G26: Martin | I26: =I25 + IF(EXACT(J26, ""), 0, 1) -> 286000000000023 | J26: =IF(EXACT(F26, ""), "", CONCATENATE("PERFORM ""SchData-OLTP-Master"".""Func_TblEMailAccount_SET""(varSystemLoginSession::bigint, null::bigint, null::varchar, null::timestamptz, null::timestamptz, null::varchar, varInstitutionBranchID::bigint, varBaseCurrencyID::bigint, ", IF(EXACT($D26, ""), "NULL", ""&$D26&""), "::bigint, ", IF(EXACT($F26, ""), "NULL", "'"&$F26&"'"), "::varchar, ", IF(EXACT($G26, ""), "NULL", "'"&$G26&"'"), "::varchar, ", IF(EXACT($B26, ""), "NULL", "'"&$B26&"'"), "::bigint);")) -> PERFORM "SchData-OLTP-Master"."Func_TblEMailAccount_SET"(varSystemLoginSession::bigint, null::bigint, null::varchar, null::timestamptz, null::timestamptz, null::varchar, varInstitutionBranchID::bigint, varBaseCurrencyID::bigint, 287000000000003::bigint, 'adm.fortindo.id@gmail.com'::varchar, 'Martin'::varchar, '124000000000153'::bigint);
B27: 124000000000154 | C27: =IF(EXACT($B27, ""), "", IF((($B27 - MOD($B27, 1000000000000))/1000000000000)=25, CONCATENATE("Person - ", VLOOKUP($B27, [1]DataLookUp!$B$4:$C$2000, 2, FALSE)), IF((($B27 - MOD($B27, 1000000000000))/1000000000000)=124, CONCATENATE("Institution - ", VLOOKUP($B27, '[2]DataLookUp - InstitutionBranch'!$B$4:$C$2000, 2, FALSE)), ""))) -> Institution - PT. Gateway Container Line Indonesia | D27: 287000000000003 | E27: =IF(EXACT($D27, ""), "", VLOOKUP($D27, 'REF - EmailAccountType'!$B$4:$C$7, 2, FALSE)) -> Business | F27: import1@gateway-id.com | G27: Fitri | I27: =I26 + IF(EXACT(J27, ""), 0, 1) -> 286000000000024 | J27: =IF(EXACT(F27, ""), "", CONCATENATE("PERFORM ""SchData-OLTP-Master"".""Func_TblEMailAccount_SET""(varSystemLoginSession::bigint, null::bigint, null::varchar, null::timestamptz, null::timestamptz, null::varchar, varInstitutionBranchID::bigint, varBaseCurrencyID::bigint, ", IF(EXACT($D27, ""), "NULL", ""&$D27&""), "::bigint, ", IF(EXACT($F27, ""), "NULL", "'"&$F27&"'"), "::varchar, ", IF(EXACT($G27, ""), "NULL", "'"&$G27&"'"), "::varchar, ", IF(EXACT($B27, ""), "NULL", "'"&$B27&"'"), "::bigint);")) -> PERFORM "SchData-OLTP-Master"."Func_TblEMailAccount_SET"(varSystemLoginSession::bigint, null::bigint, null::varchar, null::timestamptz, null::timestamptz, null::varchar, varInstitutionBranchID::bigint, varBaseCurrencyID::bigint, 287000000000003::bigint, 'import1@gateway-id.com'::varchar, 'Fitri'::varchar, '124000000000154'::bigint);
B28: 124000000000155 | C28: =IF(EXACT($B28, ""), "", IF((($B28 - MOD($B28, 1000000000000))/1000000000000)=25, CONCATENATE("Person - ", VLOOKUP($B28, [1]DataLookUp!$B$4:$C$2000, 2, FALSE)), IF((($B28 - MOD($B28, 1000000000000))/1000000000000)=124, CONCATENATE("Institution - ", VLOOKUP($B28, '[2]DataLookUp - InstitutionBranch'!$B$4:$C$2000, 2, FALSE)), ""))) -> Institution - PT. Geo Cipta Bangun | D28: 287000000000003 | E28: =IF(EXACT($D28, ""), "", VLOOKUP($D28, 'REF - EmailAccountType'!$B$4:$C$7, 2, FALSE)) -> Business | F28: pt.geociptabangun@gmail.com | G28: Yopi | I28: =I27 + IF(EXACT(J28, ""), 0, 1) -> 286000000000025 | J28: =IF(EXACT(F28, ""), "", CONCATENATE("PERFORM ""SchData-OLTP-Master"".""Func_TblEMailAccount_SET""(varSystemLoginSession::bigint, null::bigint, null::varchar, null::timestamptz, null::timestamptz, null::varchar, varInstitutionBranchID::bigint, varBaseCurrencyID::bigint, ", IF(EXACT($D28, ""), "NULL", ""&$D28&""), "::bigint, ", IF(EXACT($F28, ""), "NULL", "'"&$F28&"'"), "::varchar, ", IF(EXACT($G28, ""), "NULL", "'"&$G28&"'"), "::varchar, ", IF(EXACT($B28, ""), "NULL", "'"&$B28&"'"), "::bigint);")) -> PERFORM "SchData-OLTP-Master"."Func_TblEMailAccount_SET"(varSystemLoginSession::bigint, null::bigint, null::varchar, null::timestamptz, null::timestamptz, null::varchar, varInstitutionBranchID::bigint, varBaseCurrencyID::bigint, 287000000000003::bigint, 'pt.geociptabangun@gmail.com'::varchar, 'Yopi'::varchar, '124000000000155'::bigint);
B29: 124000000000169 | C29: =IF(EXACT($B29, ""), "", IF((($B29 - MOD($B29, 1000000000000))/1000000000000)=25, CONCATENATE("Person - ", VLOOKUP($B29, [1]DataLookUp!$B$4:$C$2000, 2, FALSE)), IF((($B29 - MOD($B29, 1000000000000))/1000000000000)=124, CONCATENATE("Institution - ", VLOOKUP($B29, '[2]DataLookUp - InstitutionBranch'!$B$4:$C$2000, 2, FALSE)), ""))) -> Institution - PT. Infracoo Pengadaan Indonesia | D29: 287000000000003 | E29: =IF(EXACT($D29, ""), "", VLOOKUP($D29, 'REF - EmailAccountType'!$B$4:$C$7, 2, FALSE)) -> Business | F29: infracoo.ip@gmail.com | I29: =I28 + IF(EXACT(J29, ""), 0, 1) -> 286000000000026 | J29: =IF(EXACT(F29, ""), "", CONCATENATE("PERFORM ""SchData-OLTP-Master"".""Func_TblEMailAccount_SET""(varSystemLoginSession::bigint, null::bigint, null::varchar, null::timestamptz, null::timestamptz, null::varchar, varInstitutionBranchID::bigint, varBaseCurrencyID::bigint, ", IF(EXACT($D29, ""), "NULL", ""&$D29&""), "::bigint, ", IF(EXACT($F29, ""), "NULL", "'"&$F29&"'"), "::varchar, ", IF(EXACT($G29, ""), "NULL", "'"&$G29&"'"), "::varchar, ", IF(EXACT($B29, ""), "NULL", "'"&$B29&"'"), "::bigint);")) -> PERFORM "SchData-OLTP-Master"."Func_TblEMailAccount_SET"(varSystemLoginSession::bigint, null::bigint, null::varchar, null::timestamptz, null::timestamptz, null::varchar, varInstitutionBranchID::bigint, varBaseCurrencyID::bigint, 287000000000003::bigint, 'infracoo.ip@gmail.com'::varchar, NULL::varchar, '124000000000169'::bigint);
B30: 124000000000170 | C30: =IF(EXACT($B30, ""), "", IF((($B30 - MOD($B30, 1000000000000))/1000000000000)=25, CONCATENATE("Person - ", VLOOKUP($B30, [1]DataLookUp!$B$4:$C$2000, 2, FALSE)), IF((($B30 - MOD($B30, 1000000000000))/1000000000000)=124, CONCATENATE("Institution - ", VLOOKUP($B30, '[2]DataLookUp - InstitutionBranch'!$B$4:$C$2000, 2, FALSE)), ""))) -> Institution - PT. Inti Teknologi Indonesia Utama | D30: 287000000000003 | E30: =IF(EXACT($D30, ""), "", VLOOKUP($D30, 'REF - EmailAccountType'!$B$4:$C$7, 2, FALSE)) -> Business | F30: fendilab3@yahoo.com | G30: Fendi | I30: =I29 + IF(EXACT(J30, ""), 0, 1) -> 286000000000027 | J30: =IF(EXACT(F30, ""), "", CONCATENATE("PERFORM ""SchData-OLTP-Master"".""Func_TblEMailAccount_SET""(varSystemLoginSession::bigint, null::bigint, null::varchar, null::timestamptz, null::timestamptz, null::varchar, varInstitutionBranchID::bigint, varBaseCurrencyID::bigint, ", IF(EXACT($D30, ""), "NULL", ""&$D30&""), "::bigint, ", IF(EXACT($F30, ""), "NULL", "'"&$F30&"'"), "::varchar, ", IF(EXACT($G30, ""), "NULL", "'"&$G30&"'"), "::varchar, ", IF(EXACT($B30, ""), "NULL", "'"&$B30&"'"), "::bigint);")) -> PERFORM "SchData-OLTP-Master"."Func_TblEMailAccount_SET"(varSystemLoginSession::bigint, null::bigint, null::varchar, null::timestamptz, null::timestamptz, null::varchar, varInstitutionBranchID::bigint, varBaseCurrencyID::bigint, 287000000000003::bigint, 'fendilab3@yahoo.com'::varchar, 'Fendi'::varchar, '124000000000170'::bigint);
B31: 124000000000171 | C31: =IF(EXACT($B31, ""), "", IF((($B31 - MOD($B31, 1000000000000))/1000000000000)=25, CONCATENATE("Person - ", VLOOKUP($B31, [1]DataLookUp!$B$4:$C$2000, 2, FALSE)), IF((($B31 - MOD($B31, 1000000000000))/1000000000000)=124, CONCATENATE("Institution - ", VLOOKUP($B31, '[2]DataLookUp - InstitutionBranch'!$B$4:$C$2000, 2, FALSE)), ""))) -> Institution - PT. Iradat Aman Globalindo | D31: 287000000000003 | E31: =IF(EXACT($D31, ""), "", VLOOKUP($D31, 'REF - EmailAccountType'!$B$4:$C$7, 2, FALSE)) -> Business | F31: iradat_aman@cbn.net.id, alaydr | G31: Zaenudin Hasan | I31: =I30 + IF(EXACT(J31, ""), 0, 1) -> 286000000000028 | J31: =IF(EXACT(F31, ""), "", CONCATENATE("PERFORM ""SchData-OLTP-Master"".""Func_TblEMailAccount_SET""(varSystemLoginSession::bigint, null::bigint, null::varchar, null::timestamptz, null::timestamptz, null::varchar, varInstitutionBranchID::bigint, varBaseCurrencyID::bigint, ", IF(EXACT($D31, ""), "NULL", ""&$D31&""), "::bigint, ", IF(EXACT($F31, ""), "NULL", "'"&$F31&"'"), "::varchar, ", IF(EXACT($G31, ""), "NULL", "'"&$G31&"'"), "::varchar, ", IF(EXACT($B31, ""), "NULL", "'"&$B31&"'"), "::bigint);")) -> PERFORM "SchData-OLTP-Master"."Func_TblEMailAccount_SET"(varSystemLoginSession::bigint, null::bigint, null::varchar, null::timestamptz, null::timestamptz, null::varchar, varInstitutionBranchID::bigint, varBaseCurrencyID::bigint, 287000000000003::bigint, 'iradat_aman@cbn.net.id, alaydr'::varchar, 'Zaenudin Hasan'::varchar, '124000000000171'::bigint);
B32: 124000000000173 | C32: =IF(EXACT($B32, ""), "", IF((($B32 - MOD($B32, 1000000000000))/1000000000000)=25, CONCATENATE("Person - ", VLOOKUP($B32, [1]DataLookUp!$B$4:$C$2000, 2, FALSE)), IF((($B32 - MOD($B32, 1000000000000))/1000000000000)=124, CONCATENATE("Institution - ", VLOOKUP($B32, '[2]DataLookUp - InstitutionBranch'!$B$4:$C$2000, 2, FALSE)), ""))) -> Institution - PT. Jaring Telekomunikasi Indonesia | D32: 287000000000003 | E32: =IF(EXACT($D32, ""), "", VLOOKUP($D32, 'REF - EmailAccountType'!$B$4:$C$7, 2, FALSE)) -> Business | F32: marketing@jaringtelekom.co.id | G32: Eddy | I32: =I31 + IF(EXACT(J32, ""), 0, 1) -> 286000000000029 | J32: =IF(EXACT(F32, ""), "", CONCATENATE("PERFORM ""SchData-OLTP-Master"".""Func_TblEMailAccount_SET""(varSystemLoginSession::bigint, null::bigint, null::varchar, null::timestamptz, null::timestamptz, null::varchar, varInstitutionBranchID::bigint, varBaseCurrencyID::bigint, ", IF(EXACT($D32, ""), "NULL", ""&$D32&""), "::bigint, ", IF(EXACT($F32, ""), "NULL", "'"&$F32&"'"), "::varchar, ", IF(EXACT($G32, ""), "NULL", "'"&$G32&"'"), "::varchar, ", IF(EXACT($B32, ""), "NULL", "'"&$B32&"'"), "::bigint);")) -> PERFORM "SchData-OLTP-Master"."Func_TblEMailAccount_SET"(varSystemLoginSession::bigint, null::bigint, null::varchar, null::timestamptz, null::timestamptz, null::varchar, varInstitutionBranchID::bigint, varBaseCurrencyID::bigint, 287000000000003::bigint, 'marketing@jaringtelekom.co.id'::varchar, 'Eddy'::varchar, '124000000000173'::bigint);
B33: 124000000000174 | C33: =IF(EXACT($B33, ""), "", IF((($B33 - MOD($B33, 1000000000000))/1000000000000)=25, CONCATENATE("Person - ", VLOOKUP($B33, [1]DataLookUp!$B$4:$C$2000, 2, FALSE)), IF((($B33 - MOD($B33, 1000000000000))/1000000000000)=124, CONCATENATE("Institution - ", VLOOKUP($B33, '[2]DataLookUp - InstitutionBranch'!$B$4:$C$2000, 2, FALSE)), ""))) -> Institution - PT. Jaya Beton Indonesia | D33: 287000000000003 | E33: =IF(EXACT($D33, ""), "", VLOOKUP($D33, 'REF - EmailAccountType'!$B$4:$C$7, 2, FALSE)) -> Business | F33: legal@jayabeton.com | G33: Reza | I33: =I32 + IF(EXACT(J33, ""), 0, 1) -> 286000000000030 | J33: =IF(EXACT(F33, ""), "", CONCATENATE("PERFORM ""SchData-OLTP-Master"".""Func_TblEMailAccount_SET""(varSystemLoginSession::bigint, null::bigint, null::varchar, null::timestamptz, null::timestamptz, null::varchar, varInstitutionBranchID::bigint, varBaseCurrencyID::bigint, ", IF(EXACT($D33, ""), "NULL", ""&$D33&""), "::bigint, ", IF(EXACT($F33, ""), "NULL", "'"&$F33&"'"), "::varchar, ", IF(EXACT($G33, ""), "NULL", "'"&$G33&"'"), "::varchar, ", IF(EXACT($B33, ""), "NULL", "'"&$B33&"'"), "::bigint);")) -> PERFORM "SchData-OLTP-Master"."Func_TblEMailAccount_SET"(varSystemLoginSession::bigint, null::bigint, null::varchar, null::timestamptz, null::timestamptz, null::varchar, varInstitutionBranchID::bigint, varBaseCurrencyID::bigint, 287000000000003::bigint, 'legal@jayabeton.com'::varchar, 'Reza'::varchar, '124000000000174'::bigint);
B34: 124000000000179 | C34: =IF(EXACT($B34, ""), "", IF((($B34 - MOD($B34, 1000000000000))/1000000000000)=25, CONCATENATE("Person - ", VLOOKUP($B34, [1]DataLookUp!$B$4:$C$2000, 2, FALSE)), IF((($B34 - MOD($B34, 1000000000000))/1000000000000)=124, CONCATENATE("Institution - ", VLOOKUP($B34, '[2]DataLookUp - InstitutionBranch'!$B$4:$C$2000, 2, FALSE)), ""))) -> Institution - PT. Karya Mega Sarana | D34: 287000000000003 | E34: =IF(EXACT($D34, ""), "", VLOOKUP($D34, 'REF - EmailAccountType'!$B$4:$C$7, 2, FALSE)) -> Business | F34: marketing.kamesa@gmail.com | G34: Galih | I34: =I33 + IF(EXACT(J34, ""), 0, 1) -> 286000000000031 | J34: =IF(EXACT(F34, ""), "", CONCATENATE("PERFORM ""SchData-OLTP-Master"".""Func_TblEMailAccount_SET""(varSystemLoginSession::bigint, null::bigint, null::varchar, null::timestamptz, null::timestamptz, null::varchar, varInstitutionBranchID::bigint, varBaseCurrencyID::bigint, ", IF(EXACT($D34, ""), "NULL", ""&$D34&""), "::bigint, ", IF(EXACT($F34, ""), "NULL", "'"&$F34&"'"), "::varchar, ", IF(EXACT($G34, ""), "NULL", "'"&$G34&"'"), "::varchar, ", IF(EXACT($B34, ""), "NULL", "'"&$B34&"'"), "::bigint);")) -> PERFORM "SchData-OLTP-Master"."Func_TblEMailAccount_SET"(varSystemLoginSession::bigint, null::bigint, null::varchar, null::timestamptz, null::timestamptz, null::varchar, varInstitutionBranchID::bigint, varBaseCurrencyID::bigint, 287000000000003::bigint, 'marketing.kamesa@gmail.com'::varchar, 'Galih'::varchar, '124000000000179'::bigint);
B35: 124000000000182 | C35: =IF(EXACT($B35, ""), "", IF((($B35 - MOD($B35, 1000000000000))/1000000000000)=25, CONCATENATE("Person - ", VLOOKUP($B35, [1]DataLookUp!$B$4:$C$2000, 2, FALSE)), IF((($B35 - MOD($B35, 1000000000000))/1000000000000)=124, CONCATENATE("Institution - ", VLOOKUP($B35, '[2]DataLookUp - InstitutionBranch'!$B$4:$C$2000, 2, FALSE)), ""))) -> Institution - PT. Kirana Purnama | D35: 287000000000003 | E35: =IF(EXACT($D35, ""), "", VLOOKUP($D35, 'REF - EmailAccountType'!$B$4:$C$7, 2, FALSE)) -> Business | F35: sales@kiranapurnama.sikadistri | G35: Dini | I35: =I34 + IF(EXACT(J35, ""), 0, 1) -> 286000000000032 | J35: =IF(EXACT(F35, ""), "", CONCATENATE("PERFORM ""SchData-OLTP-Master"".""Func_TblEMailAccount_SET""(varSystemLoginSession::bigint, null::bigint, null::varchar, null::timestamptz, null::timestamptz, null::varchar, varInstitutionBranchID::bigint, varBaseCurrencyID::bigint, ", IF(EXACT($D35, ""), "NULL", ""&$D35&""), "::bigint, ", IF(EXACT($F35, ""), "NULL", "'"&$F35&"'"), "::varchar, ", IF(EXACT($G35, ""), "NULL", "'"&$G35&"'"), "::varchar, ", IF(EXACT($B35, ""), "NULL", "'"&$B35&"'"), "::bigint);")) -> PERFORM "SchData-OLTP-Master"."Func_TblEMailAccount_SET"(varSystemLoginSession::bigint, null::bigint, null::varchar, null::timestamptz, null::timestamptz, null::varchar, varInstitutionBranchID::bigint, varBaseCurrencyID::bigint, 287000000000003::bigint, 'sales@kiranapurnama.sikadistri'::varchar, 'Dini'::varchar, '124000000000182'::bigint);
B36: 124000000000184 | C36: =IF(EXACT($B36, ""), "", IF((($B36 - MOD($B36, 1000000000000))/1000000000000)=25, CONCATENATE("Person - ", VLOOKUP($B36, [1]DataLookUp!$B$4:$C$2000, 2, FALSE)), IF((($B36 - MOD($B36, 1000000000000))/1000000000000)=124, CONCATENATE("Institution - ", VLOOKUP($B36, '[2]DataLookUp - InstitutionBranch'!$B$4:$C$2000, 2, FALSE)), ""))) -> Institution - PT. Magna Beton Indonesia | D36: 287000000000003 | E36: =IF(EXACT($D36, ""), "", VLOOKUP($D36, 'REF - EmailAccountType'!$B$4:$C$7, 2, FALSE)) -> Business | F36: magna.beton@gmail.com | G36: Lukman | I36: =I35 + IF(EXACT(J36, ""), 0, 1) -> 286000000000033 | J36: =IF(EXACT(F36, ""), "", CONCATENATE("PERFORM ""SchData-OLTP-Master"".""Func_TblEMailAccount_SET""(varSystemLoginSession::bigint, null::bigint, null::varchar, null::timestamptz, null::timestamptz, null::varchar, varInstitutionBranchID::bigint, varBaseCurrencyID::bigint, ", IF(EXACT($D36, ""), "NULL", ""&$D36&""), "::bigint, ", IF(EXACT($F36, ""), "NULL", "'"&$F36&"'"), "::varchar, ", IF(EXACT($G36, ""), "NULL", "'"&$G36&"'"), "::varchar, ", IF(EXACT($B36, ""), "NULL", "'"&$B36&"'"), "::bigint);")) -> PERFORM "SchData-OLTP-Master"."Func_TblEMailAccount_SET"(varSystemLoginSession::bigint, null::bigint, null::varchar, null::timestamptz, null::timestamptz, null::varchar, varInstitutionBranchID::bigint, varBaseCurrencyID::bigint, 287000000000003::bigint, 'magna.beton@gmail.com'::varchar, 'Lukman'::varchar, '124000000000184'::bigint);
B37: 124000000000185 | C37: =IF(EXACT($B37, ""), "", IF((($B37 - MOD($B37, 1000000000000))/1000000000000)=25, CONCATENATE("Person - ", VLOOKUP($B37, [1]DataLookUp!$B$4:$C$2000, 2, FALSE)), IF((($B37 - MOD($B37, 1000000000000))/1000000000000)=124, CONCATENATE("Institution - ", VLOOKUP($B37, '[2]DataLookUp - InstitutionBranch'!$B$4:$C$2000, 2, FALSE)), ""))) -> Institution - PT. Mandiri Maha Daya | D37: 287000000000003 | E37: =IF(EXACT($D37, ""), "", VLOOKUP($D37, 'REF - EmailAccountType'!$B$4:$C$7, 2, FALSE)) -> Business | F37: admin@mandirimahadaya.co.id | G37: PT Mandiri Maha Daya | I37: =I36 + IF(EXACT(J37, ""), 0, 1) -> 286000000000034 | J37: =IF(EXACT(F37, ""), "", CONCATENATE("PERFORM ""SchData-OLTP-Master"".""Func_TblEMailAccount_SET""(varSystemLoginSession::bigint, null::bigint, null::varchar, null::timestamptz, null::timestamptz, null::varchar, varInstitutionBranchID::bigint, varBaseCurrencyID::bigint, ", IF(EXACT($D37, ""), "NULL", ""&$D37&""), "::bigint, ", IF(EXACT($F37, ""), "NULL", "'"&$F37&"'"), "::varchar, ", IF(EXACT($G37, ""), "NULL", "'"&$G37&"'"), "::varchar, ", IF(EXACT($B37, ""), "NULL", "'"&$B37&"'"), "::bigint);")) -> PERFORM "SchData-OLTP-Master"."Func_TblEMailAccount_SET"(varSystemLoginSession::bigint, null::bigint, null::varchar, null::timestamptz, null::timestamptz, null::varchar, varInstitutionBranchID::bigint, varBaseCurrencyID::bigint, 287000000000003::bigint, 'admin@mandirimahadaya.co.id'::varchar, 'PT Mandiri Maha Daya'::varchar, '124000000000185'::bigint);
B38: 124000000000186 | C38: =IF(EXACT($B38, ""), "", IF((($B38 - MOD($B38, 1000000000000))/1000000000000)=25, CONCATENATE("Person - ", VLOOKUP($B38, [1]DataLookUp!$B$4:$C$2000, 2, FALSE)), IF((($B38 - MOD($B38, 1000000000000))/1000000000000)=124, CONCATENATE("Institution - ", VLOOKUP($B38, '[2]DataLookUp - InstitutionBranch'!$B$4:$C$2000, 2, FALSE)), ""))) -> Institution - PT. Markoen Engineering Indonesia | D38: 287000000000003 | E38: =IF(EXACT($D38, ""), "", VLOOKUP($D38, 'REF - EmailAccountType'!$B$4:$C$7, 2, FALSE)) -> Business | F38: marketing.ptmei@gmail.com | G38: Cici | I38: =I37 + IF(EXACT(J38, ""), 0, 1) -> 286000000000035 | J38: =IF(EXACT(F38, ""), "", CONCATENATE("PERFORM ""SchData-OLTP-Master"".""Func_TblEMailAccount_SET""(varSystemLoginSession::bigint, null::bigint, null::varchar, null::timestamptz, null::timestamptz, null::varchar, varInstitutionBranchID::bigint, varBaseCurrencyID::bigint, ", IF(EXACT($D38, ""), "NULL", ""&$D38&""), "::bigint, ", IF(EXACT($F38, ""), "NULL", "'"&$F38&"'"), "::varchar, ", IF(EXACT($G38, ""), "NULL", "'"&$G38&"'"), "::varchar, ", IF(EXACT($B38, ""), "NULL", "'"&$B38&"'"), "::bigint);")) -> PERFORM "SchData-OLTP-Master"."Func_TblEMailAccount_SET"(varSystemLoginSession::bigint, null::bigint, null::varchar, null::timestamptz, null::timestamptz, null::varchar, varInstitutionBranchID::bigint, varBaseCurrencyID::bigint, 287000000000003::bigint, 'marketing.ptmei@gmail.com'::varchar, 'Cici'::varchar, '124000000000186'::bigint);
B39: 124000000000194 | C39: =IF(EXACT($B39, ""), "", IF((($B39 - MOD($B39, 1000000000000))/1000000000000)=25, CONCATENATE("Person - ", VLOOKUP($B39, [1]DataLookUp!$B$4:$C$2000, 2, FALSE)), IF((($B39 - MOD($B39, 1000000000000))/1000000000000)=124, CONCATENATE("Institution - ", VLOOKUP($B39, '[2]DataLookUp - InstitutionBranch'!$B$4:$C$2000, 2, FALSE)), ""))) -> Institution - PT. Multi Guna Trans Energi | D39: 287000000000003 | E39: =IF(EXACT($D39, ""), "", VLOOKUP($D39, 'REF - EmailAccountType'!$B$4:$C$7, 2, FALSE)) -> Business | F39: andrianna@mgte.co.id | G39: Andrianna | I39: =I38 + IF(EXACT(J39, ""), 0, 1) -> 286000000000036 | J39: =IF(EXACT(F39, ""), "", CONCATENATE("PERFORM ""SchData-OLTP-Master"".""Func_TblEMailAccount_SET""(varSystemLoginSession::bigint, null::bigint, null::varchar, null::timestamptz, null::timestamptz, null::varchar, varInstitutionBranchID::bigint, varBaseCurrencyID::bigint, ", IF(EXACT($D39, ""), "NULL", ""&$D39&""), "::bigint, ", IF(EXACT($F39, ""), "NULL", "'"&$F39&"'"), "::varchar, ", IF(EXACT($G39, ""), "NULL", "'"&$G39&"'"), "::varchar, ", IF(EXACT($B39, ""), "NULL", "'"&$B39&"'"), "::bigint);")) -> PERFORM "SchData-OLTP-Master"."Func_TblEMailAccount_SET"(varSystemLoginSession::bigint, null::bigint, null::varchar, null::timestamptz, null::timestamptz, null::varchar, varInstitutionBranchID::bigint, varBaseCurrencyID::bigint, 287000000000003::bigint, 'andrianna@mgte.co.id'::varchar, 'Andrianna'::varchar, '124000000000194'::bigint);
B40: 124000000000195 | C40: =IF(EXACT($B40, ""), "", IF((($B40 - MOD($B40, 1000000000000))/1000000000000)=25, CONCATENATE("Person - ", VLOOKUP($B40, [1]DataLookUp!$B$4:$C$2000, 2, FALSE)), IF((($B40 - MOD($B40, 1000000000000))/1000000000000)=124, CONCATENATE("Institution - ", VLOOKUP($B40, '[2]DataLookUp - InstitutionBranch'!$B$4:$C$2000, 2, FALSE)), ""))) -> Institution - PT. Multi Kencana Niagatama | D40: 287000000000003 | E40: =IF(EXACT($D40, ""), "", VLOOKUP($D40, 'REF - EmailAccountType'!$B$4:$C$7, 2, FALSE)) -> Business | F40: sales@multi-kabel.com | G40: Arie Tri | I40: =I39 + IF(EXACT(J40, ""), 0, 1) -> 286000000000037 | J40: =IF(EXACT(F40, ""), "", CONCATENATE("PERFORM ""SchData-OLTP-Master"".""Func_TblEMailAccount_SET""(varSystemLoginSession::bigint, null::bigint, null::varchar, null::timestamptz, null::timestamptz, null::varchar, varInstitutionBranchID::bigint, varBaseCurrencyID::bigint, ", IF(EXACT($D40, ""), "NULL", ""&$D40&""), "::bigint, ", IF(EXACT($F40, ""), "NULL", "'"&$F40&"'"), "::varchar, ", IF(EXACT($G40, ""), "NULL", "'"&$G40&"'"), "::varchar, ", IF(EXACT($B40, ""), "NULL", "'"&$B40&"'"), "::bigint);")) -> PERFORM "SchData-OLTP-Master"."Func_TblEMailAccount_SET"(varSystemLoginSession::bigint, null::bigint, null::varchar, null::timestamptz, null::timestamptz, null::varchar, varInstitutionBranchID::bigint, varBaseCurrencyID::bigint, 287000000000003::bigint, 'sales@multi-kabel.com'::varchar, 'Arie Tri'::varchar, '124000000000195'::bigint);
B41: 124000000000199 | C41: =IF(EXACT($B41, ""), "", IF((($B41 - MOD($B41, 1000000000000))/1000000000000)=25, CONCATENATE("Person - ", VLOOKUP($B41, [1]DataLookUp!$B$4:$C$2000, 2, FALSE)), IF((($B41 - MOD($B41, 1000000000000))/1000000000000)=124, CONCATENATE("Institution - ", VLOOKUP($B41, '[2]DataLookUp - InstitutionBranch'!$B$4:$C$2000, 2, FALSE)), ""))) -> Institution - PT. NR Electric Jakarta | D41: 287000000000003 | E41: =IF(EXACT($D41, ""), "", VLOOKUP($D41, 'REF - EmailAccountType'!$B$4:$C$7, 2, FALSE)) -> Business | F41: rizaemir.emir@gmail.com | G41: Kofi Wang / Ryan Iskan | I41: =I40 + IF(EXACT(J41, ""), 0, 1) -> 286000000000038 | J41: =IF(EXACT(F41, ""), "", CONCATENATE("PERFORM ""SchData-OLTP-Master"".""Func_TblEMailAccount_SET""(varSystemLoginSession::bigint, null::bigint, null::varchar, null::timestamptz, null::timestamptz, null::varchar, varInstitutionBranchID::bigint, varBaseCurrencyID::bigint, ", IF(EXACT($D41, ""), "NULL", ""&$D41&""), "::bigint, ", IF(EXACT($F41, ""), "NULL", "'"&$F41&"'"), "::varchar, ", IF(EXACT($G41, ""), "NULL", "'"&$G41&"'"), "::varchar, ", IF(EXACT($B41, ""), "NULL", "'"&$B41&"'"), "::bigint);")) -> PERFORM "SchData-OLTP-Master"."Func_TblEMailAccount_SET"(varSystemLoginSession::bigint, null::bigint, null::varchar, null::timestamptz, null::timestamptz, null::varchar, varInstitutionBranchID::bigint, varBaseCurrencyID::bigint, 287000000000003::bigint, 'rizaemir.emir@gmail.com'::varchar, 'Kofi Wang / Ryan Iskan'::varchar, '124000000000199'::bigint);
... B50: 124000000000219 | C50: =IF(EXACT($B50, ""), "", IF((($B50 - MOD($B50, 1000000000000))/1000000000000)=25, CONCATENATE("Person - ", VLOOKUP($B50, [1]DataLookUp!$B$4:$C$2000, 2, FALSE)), IF((($B50 - MOD($B50, 1000000000000))/1000000000000)=124, CONCATENATE("Institution - ", VLOOKUP($B50, '[2]DataLookUp - InstitutionBranch'!$B$4:$C$2000, 2, FALSE)), ""))) -> Institution - PT. Primatech Jaya Abadi | D50: 287000000000003 | E50: =IF(EXACT($D50, ""), "", VLOOKUP($D50, 'REF - EmailAccountType'!$B$4:$C$7, 2, FALSE)) -> Business | F50: primatechjayaabadi@gmail.com | G50: Honorius | I50: =I49 + IF(EXACT(J50, ""), 0, 1) -> 286000000000047 | J50: =IF(EXACT(F50, ""), "", CONCATENATE("PERFORM ""SchData-OLTP-Master"".""Func_TblEMailAccount_SET""(varSystemLoginSession::bigint, null::bigint, null::varchar, null::timestamptz, null::timestamptz, null::varchar, varInstitutionBranchID::bigint, varBaseCurrencyID::bigint, ", IF(EXACT($D50, ""), "NULL", ""&$D50&""), "::bigint, ", IF(EXACT($F50, ""), "NULL", "'"&$F50&"'"), "::varchar, ", IF(EXACT($G50, ""), "NULL", "'"&$G50&"'"), "::varchar, ", IF(EXACT($B50, ""), "NULL", "'"&$B50&"'"), "::bigint);")) -> PERFORM "SchData-OLTP-Master"."Func_TblEMailAccount_SET"(varSystemLoginSession::bigint, null::bigint, null::varchar, null::timestamptz, null::timestamptz, null::varchar, varInstitutionBranchID::bigint, varBaseCurrencyID::bigint, 287000000000003::bigint, 'primatechjayaabadi@gmail.com'::varchar, 'Honorius'::varchar, '124000000000219'::bigint);
B51: 124000000000223 | C51: =IF(EXACT($B51, ""), "", IF((($B51 - MOD($B51, 1000000000000))/1000000000000)=25, CONCATENATE("Person - ", VLOOKUP($B51, [1]DataLookUp!$B$4:$C$2000, 2, FALSE)), IF((($B51 - MOD($B51, 1000000000000))/1000000000000)=124, CONCATENATE("Institution - ", VLOOKUP($B51, '[2]DataLookUp - InstitutionBranch'!$B$4:$C$2000, 2, FALSE)), ""))) -> Institution - PT. Radian Sarana Elektrika | D51: 287000000000003 | E51: =IF(EXACT($D51, ""), "", VLOOKUP($D51, 'REF - EmailAccountType'!$B$4:$C$7, 2, FALSE)) -> Business | F51: corsec@rse.co.id | I51: =I50 + IF(EXACT(J51, ""), 0, 1) -> 286000000000048 | J51: =IF(EXACT(F51, ""), "", CONCATENATE("PERFORM ""SchData-OLTP-Master"".""Func_TblEMailAccount_SET""(varSystemLoginSession::bigint, null::bigint, null::varchar, null::timestamptz, null::timestamptz, null::varchar, varInstitutionBranchID::bigint, varBaseCurrencyID::bigint, ", IF(EXACT($D51, ""), "NULL", ""&$D51&""), "::bigint, ", IF(EXACT($F51, ""), "NULL", "'"&$F51&"'"), "::varchar, ", IF(EXACT($G51, ""), "NULL", "'"&$G51&"'"), "::varchar, ", IF(EXACT($B51, ""), "NULL", "'"&$B51&"'"), "::bigint);")) -> PERFORM "SchData-OLTP-Master"."Func_TblEMailAccount_SET"(varSystemLoginSession::bigint, null::bigint, null::varchar, null::timestamptz, null::timestamptz, null::varchar, varInstitutionBranchID::bigint, varBaseCurrencyID::bigint, 287000000000003::bigint, 'corsec@rse.co.id'::varchar, NULL::varchar, '124000000000223'::bigint);
...

Sheet DataLookUp
B2: Sys_PID | C2: Contact Number
B4: =IF(EXACT(SEED!$F4, ""), "", SEED!$I4) -> 286000000000001 | C4: =IF(EXACT($B4, ""), "", CONCATENATE(SUBSTITUTE(SEED!$F4, "-", ""), " (", SEED!$E4, IF(EXACT(SEED!$C4, ""), "", CONCATENATE(" ►", SEED!$C4)), ")")) -> anugrah_kry@yahoo.com (Business ►Institution - CV. Anugerah Karya Magantha)
B5: =IF(EXACT(SEED!$F5, ""), "", SEED!$I5) -> 286000000000002 | C5: =IF(EXACT($B5, ""), "", CONCATENATE(SUBSTITUTE(SEED!$F5, "-", ""), " (", SEED!$E5, IF(EXACT(SEED!$C5, ""), "", CONCATENATE(" ►", SEED!$C5)), ")")) -> maxcell_dpt@yahoo.co.id (Business ►Institution - CV. Cipta Aneka Sarana)
B6: =IF(EXACT(SEED!$F6, ""), "", SEED!$I6) -> 286000000000003 | C6: =IF(EXACT($B6, ""), "", CONCATENATE(SUBSTITUTE(SEED!$F6, "-", ""), " (", SEED!$E6, IF(EXACT(SEED!$C6, ""), "", CONCATENATE(" ►", SEED!$C6)), ")")) -> dndsurvey90@gmail.com (Business ►Institution - CV. Didi Dan Darwis Survey )
