Workbook

Sheet SEED
B2: ID Person / ID Institution | C2: ID Employee | D2: Name Person / Institution | E2: Bank Name | F2: RefID Bank | G2: Account Number | H2: Owner Account | I2: Currency_RefID | J2: Bank Branch | K2: Bank Branch Address | M2: SYS_PID Prediction | N2: SQL Syntax
M3: 167000000000000
B4: 124000000000001 | D4: =IF(EXACT($B4, ""), "", IF((FLOOR($B4/1000000000000, 1) = 124), VLOOKUP($B4, '[1]DataLookUp - InstitutionBranch'!$B$4:$C$2000, 2, FALSE), IF((FLOOR($B4/1000000000000, 1) = 25), VLOOKUP($B4, [2]DataLookUp!$B$4:$D$2000, 2, FALSE), "xx"))) -> PT. QDC Technologies | E4: Bank Central Asia | F4: =VLOOKUP($E4, OFFSET([3]MAIN!$B$2, 0, 0, 100, 6), 5, FALSE) -> 166000000000005 | G4: 0063032911 | H4: PT QDC Technologies | I4: 62000000000001 | M4: =M3 + IF(EXACT(N4, ""), 0, 1) -> 167000000000001 | N4: =IF(OR(EXACT(B4, ""), EXACT(G4, "")), "", CONCATENATE("PERFORM ""SchData-OLTP-Master"".""Func_TblBankAccount_SET""(varSystemLoginSession, null, null, null, null, null, varInstitutionBranchID, varBaseCurrencyID, ", F4, ", '", G4, "', '", H4, "', ", I4, ", ", B4, ");")) -> PERFORM "SchData-OLTP-Master"."Func_TblBankAccount_SET"(varSystemLoginSession, null, null, null, null, null, varInstitutionBranchID, varBaseCurrencyID, 166000000000005, '0063032911', 'PT QDC Technologies', 62000000000001, 124000000000001);
B5: 124000000000001 | D5: =IF(EXACT($B5, ""), "", IF((FLOOR($B5/1000000000000, 1) = 124), VLOOKUP($B5, '[1]DataLookUp - InstitutionBranch'!$B$4:$C$2000, 2, FALSE), IF((FLOOR($B5/1000000000000, 1) = 25), VLOOKUP($B5, [2]DataLookUp!$B$4:$D$2000, 2, FALSE), "xx"))) -> PT. QDC Technologies | E5: Bank Central Asia | F5: =VLOOKUP($E5, OFFSET([3]MAIN!$B$2, 0, 0, 100, 6), 5, FALSE) -> 166000000000005 | G5: 0065557750 | H5: PT QDC Technologies | I5: 62000000000001 | M5: =M4 + IF(EXACT(N5, ""), 0, 1) -> 167000000000002 | N5: =IF(OR(EXACT(B5, ""), EXACT(G5, "")), "", CONCATENATE("PERFORM ""SchData-OLTP-Master"".""Func_TblBankAccount_SET""(varSystemLoginSession, null, null, null, null, null, varInstitutionBranchID, varBaseCurrencyID, ", F5, ", '", G5, "', '", H5, "', ", I5, ", ", B5, ");")) -> PERFORM "SchData-OLTP-Master"."Func_TblBankAccount_SET"(varSystemLoginSession, null, null, null, null, null, varInstitutionBranchID, varBaseCurrencyID, 166000000000005, '0065557750', 'PT QDC Technologies', 62000000000001, 124000000000001);
B6: 124000000000001 | D6: =IF(EXACT($B6, ""), "", IF((FLOOR($B6/1000000000000, 1) = 124), VLOOKUP($B6, '[1]DataLookUp - InstitutionBranch'!$B$4:$C$2000, 2, FALSE), IF((FLOOR($B6/1000000000000, 1) = 25), VLOOKUP($B6, [2]DataLookUp!$B$4:$D$2000, 2, FALSE), "xx"))) -> PT. QDC Technologies | E6: Bank Central Asia | F6: =VLOOKUP($E6, OFFSET([3]MAIN!$B$2, 0, 0, 100, 6), 5, FALSE) -> 166000000000005 | G6: 0068502911 | H6: PT QDC Technologies | I6: 62000000000001 | M6: =M5 + IF(EXACT(N6, ""), 0, 1) -> 167000000000003 | N6: =IF(OR(EXACT(B6, ""), EXACT(G6, "")), "", CONCATENATE("PERFORM ""SchData-OLTP-Master"".""Func_TblBankAccount_SET""(varSystemLoginSession, null, null, null, null, null, varInstitutionBranchID, varBaseCurrencyID, ", F6, ", '", G6, "', '", H6, "', ", I6, ", ", B6, ");")) -> PERFORM "SchData-OLTP-Master"."Func_TblBankAccount_SET"(varSystemLoginSession, null, null, null, null, null, varInstitutionBranchID, varBaseCurrencyID, 166000000000005, '0068502911', 'PT QDC Technologies', 62000000000001, 124000000000001);
B7: 124000000000001 | D7: =IF(EXACT($B7, ""), "", IF((FLOOR($B7/1000000000000, 1) = 124), VLOOKUP($B7, '[1]DataLookUp - InstitutionBranch'!$B$4:$C$2000, 2, FALSE), IF((FLOOR($B7/1000000000000, 1) = 25), VLOOKUP($B7, [2]DataLookUp!$B$4:$D$2000, 2, FALSE), "xx"))) -> PT. QDC Technologies | E7: Bank Central Asia | F7: =VLOOKUP($E7, OFFSET([3]MAIN!$B$2, 0, 0, 100, 6), 5, FALSE) -> 166000000000005 | G7: 2173050101 | H7: PT QDC Technologies | I7: 62000000000001 | M7: =M6 + IF(EXACT(N7, ""), 0, 1) -> 167000000000004 | N7: =IF(OR(EXACT(B7, ""), EXACT(G7, "")), "", CONCATENATE("PERFORM ""SchData-OLTP-Master"".""Func_TblBankAccount_SET""(varSystemLoginSession, null, null, null, null, null, varInstitutionBranchID, varBaseCurrencyID, ", F7, ", '", G7, "', '", H7, "', ", I7, ", ", B7, ");")) -> PERFORM "SchData-OLTP-Master"."Func_TblBankAccount_SET"(varSystemLoginSession, null, null, null, null, null, varInstitutionBranchID, varBaseCurrencyID, 166000000000005, '2173050101', 'PT QDC Technologies', 62000000000001, 124000000000001);
B8: 124000000000001 | D8: =IF(EXACT($B8, ""), "", IF((FLOOR($B8/1000000000000, 1) = 124), VLOOKUP($B8, '[1]DataLookUp - InstitutionBranch'!$B$4:$C$2000, 2, FALSE), IF((FLOOR($B8/1000000000000, 1) = 25), VLOOKUP($B8, [2]DataLookUp!$B$4:$D$2000, 2, FALSE), "xx"))) -> PT. QDC Technologies | E8: Bank Central Asia | F8: =VLOOKUP($E8, OFFSET([3]MAIN!$B$2, 0, 0, 100, 6), 5, FALSE) -> 166000000000005 | G8: 2173108214 | H8: PT QDC Technologies | I8: 62000000000001 | M8: =M7 + IF(EXACT(N8, ""), 0, 1) -> 167000000000005 | N8: =IF(OR(EXACT(B8, ""), EXACT(G8, "")), "", CONCATENATE("PERFORM ""SchData-OLTP-Master"".""Func_TblBankAccount_SET""(varSystemLoginSession, null, null, null, null, null, varInstitutionBranchID, varBaseCurrencyID, ", F8, ", '", G8, "', '", H8, "', ", I8, ", ", B8, ");")) -> PERFORM "SchData-OLTP-Master"."Func_TblBankAccount_SET"(varSystemLoginSession, null, null, null, null, null, varInstitutionBranchID, varBaseCurrencyID, 166000000000005, '2173108214', 'PT QDC Technologies', 62000000000001, 124000000000001);
B9: 124000000000001 | D9: =IF(EXACT($B9, ""), "", IF((FLOOR($B9/1000000000000, 1) = 124), VLOOKUP($B9, '[1]DataLookUp - InstitutionBranch'!$B$4:$C$2000, 2, FALSE), IF((FLOOR($B9/1000000000000, 1) = 25), VLOOKUP($B9, [2]DataLookUp!$B$4:$D$2000, 2, FALSE), "xx"))) -> PT. QDC Technologies | E9: Bank CIMB Niaga | F9: =VLOOKUP($E9, OFFSET([3]MAIN!$B$2, 0, 0, 100, 6), 5, FALSE) -> 166000000000017 | G9: 762375277200 | H9: PT QDC Technologies | I9: 62000000000001 | M9: =M8 + IF(EXACT(N9, ""), 0, 1) -> 167000000000006 | N9: =IF(OR(EXACT(B9, ""), EXACT(G9, "")), "", CONCATENATE("PERFORM ""SchData-OLTP-Master"".""Func_TblBankAccount_SET""(varSystemLoginSession, null, null, null, null, null, varInstitutionBranchID, varBaseCurrencyID, ", F9, ", '", G9, "', '", H9, "', ", I9, ", ", B9, ");")) -> PERFORM "SchData-OLTP-Master"."Func_TblBankAccount_SET"(varSystemLoginSession, null, null, null, null, null, varInstitutionBranchID, varBaseCurrencyID, 166000000000017, '762375277200', 'PT QDC Technologies', 62000000000001, 124000000000001);
B10: 124000000000001 | D10: =IF(EXACT($B10, ""), "", IF((FLOOR($B10/1000000000000, 1) = 124), VLOOKUP($B10, '[1]DataLookUp - InstitutionBranch'!$B$4:$C$2000, 2, FALSE), IF((FLOOR($B10/1000000000000, 1) = 25), VLOOKUP($B10, [2]DataLookUp!$B$4:$D$2000, 2, FALSE), "xx"))) -> PT. QDC Technologies | E10: Bank CIMB Niaga | F10: =VLOOKUP($E10, OFFSET([3]MAIN!$B$2, 0, 0, 100, 6), 5, FALSE) -> 166000000000017 | G10: 800039839400 | H10: PT QDC Technologies | I10: 62000000000001 | M10: =M9 + IF(EXACT(N10, ""), 0, 1) -> 167000000000007 | N10: =IF(OR(EXACT(B10, ""), EXACT(G10, "")), "", CONCATENATE("PERFORM ""SchData-OLTP-Master"".""Func_TblBankAccount_SET""(varSystemLoginSession, null, null, null, null, null, varInstitutionBranchID, varBaseCurrencyID, ", F10, ", '", G10, "', '", H10, "', ", I10, ", ", B10, ");")) -> PERFORM "SchData-OLTP-Master"."Func_TblBankAccount_SET"(varSystemLoginSession, null, null, null, null, null, varInstitutionBranchID, varBaseCurrencyID, 166000000000017, '800039839400', 'PT QDC Technologies', 62000000000001, 124000000000001);
B11: 124000000000001 | D11: =IF(EXACT($B11, ""), "", IF((FLOOR($B11/1000000000000, 1) = 124), VLOOKUP($B11, '[1]DataLookUp - InstitutionBranch'!$B$4:$C$2000, 2, FALSE), IF((FLOOR($B11/1000000000000, 1) = 25), VLOOKUP($B11, [2]DataLookUp!$B$4:$D$2000, 2, FALSE), "xx"))) -> PT. QDC Technologies | E11: Bank CIMB Niaga | F11: =VLOOKUP($E11, OFFSET([3]MAIN!$B$2, 0, 0, 100, 6), 5, FALSE) -> 166000000000017 | G11: 800039840100 | H11: PT QDC Technologies | I11: 62000000000001 | M11: =M10 + IF(EXACT(N11, ""), 0, 1) -> 167000000000008 | N11: =IF(OR(EXACT(B11, ""), EXACT(G11, "")), "", CONCATENATE("PERFORM ""SchData-OLTP-Master"".""Func_TblBankAccount_SET""(varSystemLoginSession, null, null, null, null, null, varInstitutionBranchID, varBaseCurrencyID, ", F11, ", '", G11, "', '", H11, "', ", I11, ", ", B11, ");")) -> PERFORM "SchData-OLTP-Master"."Func_TblBankAccount_SET"(varSystemLoginSession, null, null, null, null, null, varInstitutionBranchID, varBaseCurrencyID, 166000000000017, '800039840100', 'PT QDC Technologies', 62000000000001, 124000000000001);
B12: 124000000000001 | D12: =IF(EXACT($B12, ""), "", IF((FLOOR($B12/1000000000000, 1) = 124), VLOOKUP($B12, '[1]DataLookUp - InstitutionBranch'!$B$4:$C$2000, 2, FALSE), IF((FLOOR($B12/1000000000000, 1) = 25), VLOOKUP($B12, [2]DataLookUp!$B$4:$D$2000, 2, FALSE), "xx"))) -> PT. QDC Technologies | E12: Bank CIMB Niaga | F12: =VLOOKUP($E12, OFFSET([3]MAIN!$B$2, 0, 0, 100, 6), 5, FALSE) -> 166000000000017 | G12: 860012900500 | H12: PT QDC Technologies | I12: 62000000000001 | M12: =M11 + IF(EXACT(N12, ""), 0, 1) -> 167000000000009 | N12: =IF(OR(EXACT(B12, ""), EXACT(G12, "")), "", CONCATENATE("PERFORM ""SchData-OLTP-Master"".""Func_TblBankAccount_SET""(varSystemLoginSession, null, null, null, null, null, varInstitutionBranchID, varBaseCurrencyID, ", F12, ", '", G12, "', '", H12, "', ", I12, ", ", B12, ");")) -> PERFORM "SchData-OLTP-Master"."Func_TblBankAccount_SET"(varSystemLoginSession, null, null, null, null, null, varInstitutionBranchID, varBaseCurrencyID, 166000000000017, '860012900500', 'PT QDC Technologies', 62000000000001, 124000000000001);
B13: 124000000000001 | D13: =IF(EXACT($B13, ""), "", IF((FLOOR($B13/1000000000000, 1) = 124), VLOOKUP($B13, '[1]DataLookUp - InstitutionBranch'!$B$4:$C$2000, 2, FALSE), IF((FLOOR($B13/1000000000000, 1) = 25), VLOOKUP($B13, [2]DataLookUp!$B$4:$D$2000, 2, FALSE), "xx"))) -> PT. QDC Technologies | E13: Bank Commonwealth | F13: =VLOOKUP($E13, OFFSET([3]MAIN!$B$2, 0, 0, 100, 6), 5, FALSE) -> 166000000000015 | G13: 1051189606 | H13: PT QDC Technologies | I13: 62000000000001 | M13: =M12 + IF(EXACT(N13, ""), 0, 1) -> 167000000000010 | N13: =IF(OR(EXACT(B13, ""), EXACT(G13, "")), "", CONCATENATE("PERFORM ""SchData-OLTP-Master"".""Func_TblBankAccount_SET""(varSystemLoginSession, null, null, null, null, null, varInstitutionBranchID, varBaseCurrencyID, ", F13, ", '", G13, "', '", H13, "', ", I13, ", ", B13, ");")) -> PERFORM "SchData-OLTP-Master"."Func_TblBankAccount_SET"(varSystemLoginSession, null, null, null, null, null, varInstitutionBranchID, varBaseCurrencyID, 166000000000015, '1051189606', 'PT QDC Technologies', 62000000000001, 124000000000001);
B14: 124000000000001 | D14: =IF(EXACT($B14, ""), "", IF((FLOOR($B14/1000000000000, 1) = 124), VLOOKUP($B14, '[1]DataLookUp - InstitutionBranch'!$B$4:$C$2000, 2, FALSE), IF((FLOOR($B14/1000000000000, 1) = 25), VLOOKUP($B14, [2]DataLookUp!$B$4:$D$2000, 2, FALSE), "xx"))) -> PT. QDC Technologies | E14: Bank Commonwealth | F14: =VLOOKUP($E14, OFFSET([3]MAIN!$B$2, 0, 0, 100, 6), 5, FALSE) -> 166000000000015 | G14: 1051189707 | H14: PT QDC Technologies | I14: 62000000000002 | M14: =M13 + IF(EXACT(N14, ""), 0, 1) -> 167000000000011 | N14: =IF(OR(EXACT(B14, ""), EXACT(G14, "")), "", CONCATENATE("PERFORM ""SchData-OLTP-Master"".""Func_TblBankAccount_SET""(varSystemLoginSession, null, null, null, null, null, varInstitutionBranchID, varBaseCurrencyID, ", F14, ", '", G14, "', '", H14, "', ", I14, ", ", B14, ");")) -> PERFORM "SchData-OLTP-Master"."Func_TblBankAccount_SET"(varSystemLoginSession, null, null, null, null, null, varInstitutionBranchID, varBaseCurrencyID, 166000000000015, '1051189707', 'PT QDC Technologies', 62000000000002, 124000000000001);
B15: 124000000000001 | D15: =IF(EXACT($B15, ""), "", IF((FLOOR($B15/1000000000000, 1) = 124), VLOOKUP($B15, '[1]DataLookUp - InstitutionBranch'!$B$4:$C$2000, 2, FALSE), IF((FLOOR($B15/1000000000000, 1) = 25), VLOOKUP($B15, [2]DataLookUp!$B$4:$D$2000, 2, FALSE), "xx"))) -> PT. QDC Technologies | E15: Bank KB Bukopin | F15: =VLOOKUP($E15, OFFSET([3]MAIN!$B$2, 0, 0, 100, 6), 5, FALSE) -> 166000000000009 | G15: 1001327468 | H15: PT QDC Technologies | I15: 62000000000001 | M15: =M14 + IF(EXACT(N15, ""), 0, 1) -> 167000000000012 | N15: =IF(OR(EXACT(B15, ""), EXACT(G15, "")), "", CONCATENATE("PERFORM ""SchData-OLTP-Master"".""Func_TblBankAccount_SET""(varSystemLoginSession, null, null, null, null, null, varInstitutionBranchID, varBaseCurrencyID, ", F15, ", '", G15, "', '", H15, "', ", I15, ", ", B15, ");")) -> PERFORM "SchData-OLTP-Master"."Func_TblBankAccount_SET"(varSystemLoginSession, null, null, null, null, null, varInstitutionBranchID, varBaseCurrencyID, 166000000000009, '1001327468', 'PT QDC Technologies', 62000000000001, 124000000000001);
... B59: 124000000000001 | D59: =IF(EXACT($B59, ""), "", IF((FLOOR($B59/1000000000000, 1) = 124), VLOOKUP($B59, '[1]DataLookUp - InstitutionBranch'!$B$4:$C$2000, 2, FALSE), IF((FLOOR($B59/1000000000000, 1) = 25), VLOOKUP($B59, [2]DataLookUp!$B$4:$D$2000, 2, FALSE), "xx"))) -> PT. QDC Technologies | E59: Bank Tabungan Negara | F59: =VLOOKUP($E59, OFFSET([3]MAIN!$B$2, 0, 0, 100, 6), 5, FALSE) -> 166000000000004 | G59: 0100201300000052 | H59: PT QDC Technologies | I59: 62000000000001 | M59: =M58 + IF(EXACT(N59, ""), 0, 1) -> 167000000000056 | N59: =IF(OR(EXACT(B59, ""), EXACT(G59, "")), "", CONCATENATE("PERFORM ""SchData-OLTP-Master"".""Func_TblBankAccount_SET""(varSystemLoginSession, null, null, null, null, null, varInstitutionBranchID, varBaseCurrencyID, ", F59, ", '", G59, "', '", H59, "', ", I59, ", ", B59, ");")) -> PERFORM "SchData-OLTP-Master"."Func_TblBankAccount_SET"(varSystemLoginSession, null, null, null, null, null, varInstitutionBranchID, varBaseCurrencyID, 166000000000004, '0100201300000052', 'PT QDC Technologies', 62000000000001, 124000000000001);
M60: =M59 + IF(EXACT(N60, ""), 0, 1) -> 167000000000056 | N60: =IF(OR(EXACT(B60, ""), EXACT(G60, "")), "", CONCATENATE("PERFORM ""SchData-OLTP-Master"".""Func_TblBankAccount_SET""(varSystemLoginSession, null, null, null, null, null, varInstitutionBranchID, varBaseCurrencyID, ", F60, ", '", G60, "', '", H60, "', ", I60, ", ", B60, ");"))
B61: 25000000000439 | C61: =_xlfn.IFNA(IF(EXACT($B61, ""), "", VLOOKUP($B61, [4]DataLookUp!$C$4:$G$999, 3, FALSE )), "") -> 030717839 | D61: =IF(EXACT($B61, ""), "", IF((FLOOR($B61/1000000000000, 1) = 124), VLOOKUP($B61, '[1]DataLookUp - InstitutionBranch'!$B$4:$C$97, 2, FALSE), IF((FLOOR($B61/1000000000000, 1) = 25), VLOOKUP($B61, [2]DataLookUp!$B$4:$D$632, 2, FALSE), "xx"))) -> Teguh Pratama Januzir Sukin | E61: Bank Central Asia | F61: =IF(EXACT(E61, ""), "", VLOOKUP($E61, OFFSET([3]MAIN!$B$2, 0, 0, 100, 6), 5, FALSE)) -> 166000000000005 | G61: 6550289791 | H61: Teguh Pratama Januzir S | I61: 62000000000001 | M61: =M60 + IF(EXACT(N61, ""), 0, 1) -> 167000000000057 | N61: =IF(OR(EXACT(B61, ""), EXACT(G61, "")), "", CONCATENATE("PERFORM ""SchData-OLTP-Master"".""Func_TblBankAccount_SET""(varSystemLoginSession, null, null, null, null, null, varInstitutionBranchID, varBaseCurrencyID, ", F61, ", '", G61, "', '", H61, "', ", I61, ", ", B61, ");")) -> PERFORM "SchData-OLTP-Master"."Func_TblBankAccount_SET"(varSystemLoginSession, null, null, null, null, null, varInstitutionBranchID, varBaseCurrencyID, 166000000000005, '6550289791', 'Teguh Pratama Januzir S', 62000000000001, 25000000000439);
B62: 25000000000439 | C62: =_xlfn.IFNA(IF(EXACT($B62, ""), "", VLOOKUP($B62, [4]DataLookUp!$C$4:$G$999, 3, FALSE )), "") -> 030717839 | D62: =IF(EXACT($B62, ""), "", IF((FLOOR($B62/1000000000000, 1) = 124), VLOOKUP($B62, '[1]DataLookUp - InstitutionBranch'!$B$4:$C$97, 2, FALSE), IF((FLOOR($B62/1000000000000, 1) = 25), VLOOKUP($B62, [2]DataLookUp!$B$4:$D$632, 2, FALSE), "xx"))) -> Teguh Pratama Januzir Sukin | E62: Bank Mandiri | F62: =IF(EXACT(E62, ""), "", VLOOKUP($E62, OFFSET([3]MAIN!$B$2, 0, 0, 100, 6), 5, FALSE)) -> 166000000000001 | G62: 121-00-0599441-7 | H62: Teguh Pratama Januzi | I62: 62000000000001 | M62: =M61 + IF(EXACT(N62, ""), 0, 1) -> 167000000000058 | N62: =IF(OR(EXACT(B62, ""), EXACT(G62, "")), "", CONCATENATE("PERFORM ""SchData-OLTP-Master"".""Func_TblBankAccount_SET""(varSystemLoginSession, null, null, null, null, null, varInstitutionBranchID, varBaseCurrencyID, ", F62, ", '", G62, "', '", H62, "', ", I62, ", ", B62, ");")) -> PERFORM "SchData-OLTP-Master"."Func_TblBankAccount_SET"(varSystemLoginSession, null, null, null, null, null, varInstitutionBranchID, varBaseCurrencyID, 166000000000001, '121-00-0599441-7', 'Teguh Pratama Januzi', 62000000000001, 25000000000439);
B63: 25000000000439 | C63: =_xlfn.IFNA(IF(EXACT($B63, ""), "", VLOOKUP($B63, [4]DataLookUp!$C$4:$G$999, 3, FALSE )), "") -> 030717839 | D63: =IF(EXACT($B63, ""), "", IF((FLOOR($B63/1000000000000, 1) = 124), VLOOKUP($B63, '[1]DataLookUp - InstitutionBranch'!$B$4:$C$97, 2, FALSE), IF((FLOOR($B63/1000000000000, 1) = 25), VLOOKUP($B63, [2]DataLookUp!$B$4:$D$632, 2, FALSE), "xx"))) -> Teguh Pratama Januzir Sukin | E63: Bank Rakyat Indonesia | F63: =IF(EXACT(E63, ""), "", VLOOKUP($E63, OFFSET([3]MAIN!$B$2, 0, 0, 100, 6), 5, FALSE)) -> 166000000000002 | G63: 0206-01-095647-50-4 | H63: Teguh Pratama Januzi | I63: 62000000000001 | M63: =M62 + IF(EXACT(N63, ""), 0, 1) -> 167000000000059 | N63: =IF(OR(EXACT(B63, ""), EXACT(G63, "")), "", CONCATENATE("PERFORM ""SchData-OLTP-Master"".""Func_TblBankAccount_SET""(varSystemLoginSession, null, null, null, null, null, varInstitutionBranchID, varBaseCurrencyID, ", F63, ", '", G63, "', '", H63, "', ", I63, ", ", B63, ");")) -> PERFORM "SchData-OLTP-Master"."Func_TblBankAccount_SET"(varSystemLoginSession, null, null, null, null, null, varInstitutionBranchID, varBaseCurrencyID, 166000000000002, '0206-01-095647-50-4', 'Teguh Pratama Januzi', 62000000000001, 25000000000439);
B64: 25000000000382 | C64: =_xlfn.IFNA(IF(EXACT($B64, ""), "", VLOOKUP($B64, [4]DataLookUp!$C$4:$G$999, 3, FALSE )), "") -> 210904088 | D64: =IF(EXACT($B64, ""), "", IF((FLOOR($B64/1000000000000, 1) = 124), VLOOKUP($B64, '[1]DataLookUp - InstitutionBranch'!$B$4:$C$97, 2, FALSE), IF((FLOOR($B64/1000000000000, 1) = 25), VLOOKUP($B64, [2]DataLookUp!$B$4:$D$632, 2, FALSE), "xx"))) -> Abdul Samad | E64: Bank Central Asia | F64: =IF(EXACT(E64, ""), "", VLOOKUP($E64, OFFSET([3]MAIN!$B$2, 0, 0, 100, 6), 5, FALSE)) -> 166000000000005 | G64: 0060262641 | H64: Abd Samad | I64: 62000000000001 | M64: =M63 + IF(EXACT(N64, ""), 0, 1) -> 167000000000060 | N64: =IF(OR(EXACT(B64, ""), EXACT(G64, "")), "", CONCATENATE("PERFORM ""SchData-OLTP-Master"".""Func_TblBankAccount_SET""(varSystemLoginSession, null, null, null, null, null, varInstitutionBranchID, varBaseCurrencyID, ", F64, ", '", G64, "', '", H64, "', ", I64, ", ", B64, ");")) -> PERFORM "SchData-OLTP-Master"."Func_TblBankAccount_SET"(varSystemLoginSession, null, null, null, null, null, varInstitutionBranchID, varBaseCurrencyID, 166000000000005, '0060262641', 'Abd Samad', 62000000000001, 25000000000382);
B65: 25000000000514 | C65: =_xlfn.IFNA(IF(EXACT($B65, ""), "", VLOOKUP($B65, [4]DataLookUp!$C$4:$G$999, 3, FALSE )), "") -> 110422962 | D65: =IF(EXACT($B65, ""), "", IF((FLOOR($B65/1000000000000, 1) = 124), VLOOKUP($B65, '[1]DataLookUp - InstitutionBranch'!$B$4:$C$97, 2, FALSE), IF((FLOOR($B65/1000000000000, 1) = 25), VLOOKUP($B65, [2]DataLookUp!$B$4:$D$632, 2, FALSE), "xx"))) -> Achmad Yunadi | E65: Bank Central Asia | F65: =IF(EXACT(E65, ""), "", VLOOKUP($E65, OFFSET([3]MAIN!$B$2, 0, 0, 100, 6), 5, FALSE)) -> 166000000000005 | G65: 2040089643 | H65: Achmad Yunadi | I65: 62000000000001 | M65: =M64 + IF(EXACT(N65, ""), 0, 1) -> 167000000000061 | N65: =IF(OR(EXACT(B65, ""), EXACT(G65, "")), "", CONCATENATE("PERFORM ""SchData-OLTP-Master"".""Func_TblBankAccount_SET""(varSystemLoginSession, null, null, null, null, null, varInstitutionBranchID, varBaseCurrencyID, ", F65, ", '", G65, "', '", H65, "', ", I65, ", ", B65, ");")) -> PERFORM "SchData-OLTP-Master"."Func_TblBankAccount_SET"(varSystemLoginSession, null, null, null, null, null, varInstitutionBranchID, varBaseCurrencyID, 166000000000005, '2040089643', 'Achmad Yunadi', 62000000000001, 25000000000514);
B66: 25000000000012 | C66: =_xlfn.IFNA(IF(EXACT($B66, ""), "", VLOOKUP($B66, [4]DataLookUp!$C$4:$G$999, 3, FALSE )), "") -> 010703020 | D66: =IF(EXACT($B66, ""), "", IF((FLOOR($B66/1000000000000, 1) = 124), VLOOKUP($B66, '[1]DataLookUp - InstitutionBranch'!$B$4:$C$97, 2, FALSE), IF((FLOOR($B66/1000000000000, 1) = 25), VLOOKUP($B66, [2]DataLookUp!$B$4:$D$632, 2, FALSE), "xx"))) -> Agnes Sutedja | E66: Bank Central Asia | F66: =IF(EXACT(E66, ""), "", VLOOKUP($E66, OFFSET([3]MAIN!$B$2, 0, 0, 100, 6), 5, FALSE)) -> 166000000000005 | G66: 0350780718 | H66: The Giok Ing Agnes Suted | I66: 62000000000001 | M66: =M65 + IF(EXACT(N66, ""), 0, 1) -> 167000000000062 | N66: =IF(OR(EXACT(B66, ""), EXACT(G66, "")), "", CONCATENATE("PERFORM ""SchData-OLTP-Master"".""Func_TblBankAccount_SET""(varSystemLoginSession, null, null, null, null, null, varInstitutionBranchID, varBaseCurrencyID, ", F66, ", '", G66, "', '", H66, "', ", I66, ", ", B66, ");")) -> PERFORM "SchData-OLTP-Master"."Func_TblBankAccount_SET"(varSystemLoginSession, null, null, null, null, null, varInstitutionBranchID, varBaseCurrencyID, 166000000000005, '0350780718', 'The Giok Ing Agnes Suted', 62000000000001, 25000000000012);
B67: 25000000000549 | C67: =_xlfn.IFNA(IF(EXACT($B67, ""), "", VLOOKUP($B67, [4]DataLookUp!$C$4:$G$999, 3, FALSE )), "") -> 311022972 | D67: =IF(EXACT($B67, ""), "", IF((FLOOR($B67/1000000000000, 1) = 124), VLOOKUP($B67, '[1]DataLookUp - InstitutionBranch'!$B$4:$C$97, 2, FALSE), IF((FLOOR($B67/1000000000000, 1) = 25), VLOOKUP($B67, [2]DataLookUp!$B$4:$D$632, 2, FALSE), "xx"))) -> Agus Nuryadi | E67: Bank Central Asia | F67: =IF(EXACT(E67, ""), "", VLOOKUP($E67, OFFSET([3]MAIN!$B$2, 0, 0, 100, 6), 5, FALSE)) -> 166000000000005 | G67: 6821221339 | H67: Agus Nuryadi | I67: 62000000000001 | M67: =M66 + IF(EXACT(N67, ""), 0, 1) -> 167000000000063 | N67: =IF(OR(EXACT(B67, ""), EXACT(G67, "")), "", CONCATENATE("PERFORM ""SchData-OLTP-Master"".""Func_TblBankAccount_SET""(varSystemLoginSession, null, null, null, null, null, varInstitutionBranchID, varBaseCurrencyID, ", F67, ", '", G67, "', '", H67, "', ", I67, ", ", B67, ");")) -> PERFORM "SchData-OLTP-Master"."Func_TblBankAccount_SET"(varSystemLoginSession, null, null, null, null, null, varInstitutionBranchID, varBaseCurrencyID, 166000000000005, '6821221339', 'Agus Nuryadi', 62000000000001, 25000000000549);
B68: 25000000000015 | C68: =_xlfn.IFNA(IF(EXACT($B68, ""), "", VLOOKUP($B68, [4]DataLookUp!$C$4:$G$999, 3, FALSE )), "") -> 130223978 | D68: =IF(EXACT($B68, ""), "", IF((FLOOR($B68/1000000000000, 1) = 124), VLOOKUP($B68, '[1]DataLookUp - InstitutionBranch'!$B$4:$C$97, 2, FALSE), IF((FLOOR($B68/1000000000000, 1) = 25), VLOOKUP($B68, [2]DataLookUp!$B$4:$D$632, 2, FALSE), "xx"))) -> Agus Salim | E68: Bank Central Asia | F68: =IF(EXACT(E68, ""), "", VLOOKUP($E68, OFFSET([3]MAIN!$B$2, 0, 0, 100, 6), 5, FALSE)) -> 166000000000005 | G68: 5750423347 | H68: Agus Salim | I68: 62000000000001 | M68: =M67 + IF(EXACT(N68, ""), 0, 1) -> 167000000000064 | N68: =IF(OR(EXACT(B68, ""), EXACT(G68, "")), "", CONCATENATE("PERFORM ""SchData-OLTP-Master"".""Func_TblBankAccount_SET""(varSystemLoginSession, null, null, null, null, null, varInstitutionBranchID, varBaseCurrencyID, ", F68, ", '", G68, "', '", H68, "', ", I68, ", ", B68, ");")) -> PERFORM "SchData-OLTP-Master"."Func_TblBankAccount_SET"(varSystemLoginSession, null, null, null, null, null, varInstitutionBranchID, varBaseCurrencyID, 166000000000005, '5750423347', 'Agus Salim', 62000000000001, 25000000000015);
B69: 25000000000019 | C69: =_xlfn.IFNA(IF(EXACT($B69, ""), "", VLOOKUP($B69, [4]DataLookUp!$C$4:$G$999, 3, FALSE )), "") -> 150506222 | D69: =IF(EXACT($B69, ""), "", IF((FLOOR($B69/1000000000000, 1) = 124), VLOOKUP($B69, '[1]DataLookUp - InstitutionBranch'!$B$4:$C$97, 2, FALSE), IF((FLOOR($B69/1000000000000, 1) = 25), VLOOKUP($B69, [2]DataLookUp!$B$4:$D$632, 2, FALSE), "xx"))) -> Ahmad Syaifulloh | E69: Bank Central Asia | F69: =IF(EXACT(E69, ""), "", VLOOKUP($E69, OFFSET([3]MAIN!$B$2, 0, 0, 100, 6), 5, FALSE)) -> 166000000000005 | G69: 7150306269 | H69: Ahmad Syaifulloh | I69: 62000000000001 | M69: =M68 + IF(EXACT(N69, ""), 0, 1) -> 167000000000065 | N69: =IF(OR(EXACT(B69, ""), EXACT(G69, "")), "", CONCATENATE("PERFORM ""SchData-OLTP-Master"".""Func_TblBankAccount_SET""(varSystemLoginSession, null, null, null, null, null, varInstitutionBranchID, varBaseCurrencyID, ", F69, ", '", G69, "', '", H69, "', ", I69, ", ", B69, ");")) -> PERFORM "SchData-OLTP-Master"."Func_TblBankAccount_SET"(varSystemLoginSession, null, null, null, null, null, varInstitutionBranchID, varBaseCurrencyID, 166000000000005, '7150306269', 'Ahmad Syaifulloh', 62000000000001, 25000000000019);
B70: 25000000000513 | C70: =_xlfn.IFNA(IF(EXACT($B70, ""), "", VLOOKUP($B70, [4]DataLookUp!$C$4:$G$999, 3, FALSE )), "") -> 191022969 | D70: =IF(EXACT($B70, ""), "", IF((FLOOR($B70/1000000000000, 1) = 124), VLOOKUP($B70, '[1]DataLookUp - InstitutionBranch'!$B$4:$C$97, 2, FALSE), IF((FLOOR($B70/1000000000000, 1) = 25), VLOOKUP($B70, [2]DataLookUp!$B$4:$D$632, 2, FALSE), "xx"))) -> Ahmad Choerul | E70: Bank Central Asia | F70: =IF(EXACT(E70, ""), "", VLOOKUP($E70, OFFSET([3]MAIN!$B$2, 0, 0, 100, 6), 5, FALSE)) -> 166000000000005 | G70: 2670159496 | H70: Ahmad Choerul | I70: 62000000000001 | M70: =M69 + IF(EXACT(N70, ""), 0, 1) -> 167000000000066 | N70: =IF(OR(EXACT(B70, ""), EXACT(G70, "")), "", CONCATENATE("PERFORM ""SchData-OLTP-Master"".""Func_TblBankAccount_SET""(varSystemLoginSession, null, null, null, null, null, varInstitutionBranchID, varBaseCurrencyID, ", F70, ", '", G70, "', '", H70, "', ", I70, ", ", B70, ");")) -> PERFORM "SchData-OLTP-Master"."Func_TblBankAccount_SET"(varSystemLoginSession, null, null, null, null, null, varInstitutionBranchID, varBaseCurrencyID, 166000000000005, '2670159496', 'Ahmad Choerul', 62000000000001, 25000000000513);
B71: 25000000000023 | C71: =_xlfn.IFNA(IF(EXACT($B71, ""), "", VLOOKUP($B71, [4]DataLookUp!$C$4:$G$999, 3, FALSE )), "") -> 141020935 | D71: =IF(EXACT($B71, ""), "", IF((FLOOR($B71/1000000000000, 1) = 124), VLOOKUP($B71, '[1]DataLookUp - InstitutionBranch'!$B$4:$C$97, 2, FALSE), IF((FLOOR($B71/1000000000000, 1) = 25), VLOOKUP($B71, [2]DataLookUp!$B$4:$D$632, 2, FALSE), "xx"))) -> Aldi Mulyadi | E71: Bank Central Asia | F71: =IF(EXACT(E71, ""), "", VLOOKUP($E71, OFFSET([3]MAIN!$B$2, 0, 0, 100, 6), 5, FALSE)) -> 166000000000005 | G71: 5520607058 | H71: Aldi Mulyadi | I71: 62000000000001 | M71: =M70 + IF(EXACT(N71, ""), 0, 1) -> 167000000000067 | N71: =IF(OR(EXACT(B71, ""), EXACT(G71, "")), "", CONCATENATE("PERFORM ""SchData-OLTP-Master"".""Func_TblBankAccount_SET""(varSystemLoginSession, null, null, null, null, null, varInstitutionBranchID, varBaseCurrencyID, ", F71, ", '", G71, "', '", H71, "', ", I71, ", ", B71, ");")) -> PERFORM "SchData-OLTP-Master"."Func_TblBankAccount_SET"(varSystemLoginSession, null, null, null, null, null, varInstitutionBranchID, varBaseCurrencyID, 166000000000005, '5520607058', 'Aldi Mulyadi', 62000000000001, 25000000000023);
B72: 25000000000039 | C72: =_xlfn.IFNA(IF(EXACT($B72, ""), "", VLOOKUP($B72, [4]DataLookUp!$C$4:$G$999, 3, FALSE )), "") -> 100419903 | D72: =IF(EXACT($B72, ""), "", IF((FLOOR($B72/1000000000000, 1) = 124), VLOOKUP($B72, '[1]DataLookUp - InstitutionBranch'!$B$4:$C$97, 2, FALSE), IF((FLOOR($B72/1000000000000, 1) = 25), VLOOKUP($B72, [2]DataLookUp!$B$4:$D$632, 2, FALSE), "xx"))) -> Annisa Dewi Arumsari | E72: Bank Central Asia | F72: =IF(EXACT(E72, ""), "", VLOOKUP($E72, OFFSET([3]MAIN!$B$2, 0, 0, 100, 6), 5, FALSE)) -> 166000000000005 | G72: 5520537742 | H72: Annisa Dewi Arumsari | I72: 62000000000001 | M72: =M71 + IF(EXACT(N72, ""), 0, 1) -> 167000000000068 | N72: =IF(OR(EXACT(B72, ""), EXACT(G72, "")), "", CONCATENATE("PERFORM ""SchData-OLTP-Master"".""Func_TblBankAccount_SET""(varSystemLoginSession, null, null, null, null, null, varInstitutionBranchID, varBaseCurrencyID, ", F72, ", '", G72, "', '", H72, "', ", I72, ", ", B72, ");")) -> PERFORM "SchData-OLTP-Master"."Func_TblBankAccount_SET"(varSystemLoginSession, null, null, null, null, null, varInstitutionBranchID, varBaseCurrencyID, 166000000000005, '5520537742', 'Annisa Dewi Arumsari', 62000000000001, 25000000000039);
B73: 25000000000044 | C73: =_xlfn.IFNA(IF(EXACT($B73, ""), "", VLOOKUP($B73, [4]DataLookUp!$C$4:$G$999, 3, FALSE )), "") -> 310821007 | D73: =IF(EXACT($B73, ""), "", IF((FLOOR($B73/1000000000000, 1) = 124), VLOOKUP($B73, '[1]DataLookUp - InstitutionBranch'!$B$4:$C$97, 2, FALSE), IF((FLOOR($B73/1000000000000, 1) = 25), VLOOKUP($B73, [2]DataLookUp!$B$4:$D$632, 2, FALSE), "xx"))) -> Anugerah Januariansyah | E73: Bank Central Asia | F73: =IF(EXACT(E73, ""), "", VLOOKUP($E73, OFFSET([3]MAIN!$B$2, 0, 0, 100, 6), 5, FALSE)) -> 166000000000005 | G73: 4565061969 | H73: Anugerah Januariansyah | I73: 62000000000001 | M73: =M72 + IF(EXACT(N73, ""), 0, 1) -> 167000000000069 | N73: =IF(OR(EXACT(B73, ""), EXACT(G73, "")), "", CONCATENATE("PERFORM ""SchData-OLTP-Master"".""Func_TblBankAccount_SET""(varSystemLoginSession, null, null, null, null, null, varInstitutionBranchID, varBaseCurrencyID, ", F73, ", '", G73, "', '", H73, "', ", I73, ", ", B73, ");")) -> PERFORM "SchData-OLTP-Master"."Func_TblBankAccount_SET"(varSystemLoginSession, null, null, null, null, null, varInstitutionBranchID, varBaseCurrencyID, 166000000000005, '4565061969', 'Anugerah Januariansyah', 62000000000001, 25000000000044);
B74: 25000000000075 | C74: =_xlfn.IFNA(IF(EXACT($B74, ""), "", VLOOKUP($B74, [4]DataLookUp!$C$4:$G$999, 3, FALSE )), "") -> 100920934 | D74: =IF(EXACT($B74, ""), "", IF((FLOOR($B74/1000000000000, 1) = 124), VLOOKUP($B74, '[1]DataLookUp - InstitutionBranch'!$B$4:$C$97, 2, FALSE), IF((FLOOR($B74/1000000000000, 1) = 25), VLOOKUP($B74, [2]DataLookUp!$B$4:$D$632, 2, FALSE), "xx"))) -> Belina Lindarwani | E74: Bank Central Asia | F74: =IF(EXACT(E74, ""), "", VLOOKUP($E74, OFFSET([3]MAIN!$B$2, 0, 0, 100, 6), 5, FALSE)) -> 166000000000005 | G74: 5520579321 | H74: Belina Lindarwani | I74: 62000000000001 | M74: =M73 + IF(EXACT(N74, ""), 0, 1) -> 167000000000070 | N74: =IF(OR(EXACT(B74, ""), EXACT(G74, "")), "", CONCATENATE("PERFORM ""SchData-OLTP-Master"".""Func_TblBankAccount_SET""(varSystemLoginSession, null, null, null, null, null, varInstitutionBranchID, varBaseCurrencyID, ", F74, ", '", G74, "', '", H74, "', ", I74, ", ", B74, ");")) -> PERFORM "SchData-OLTP-Master"."Func_TblBankAccount_SET"(varSystemLoginSession, null, null, null, null, null, varInstitutionBranchID, varBaseCurrencyID, 166000000000005, '5520579321', 'Belina Lindarwani', 62000000000001, 25000000000075);
B75: 25000000000082 | C75: =_xlfn.IFNA(IF(EXACT($B75, ""), "", VLOOKUP($B75, [4]DataLookUp!$C$4:$G$999, 3, FALSE )), "") -> 060515769 | D75: =IF(EXACT($B75, ""), "", IF((FLOOR($B75/1000000000000, 1) = 124), VLOOKUP($B75, '[1]DataLookUp - InstitutionBranch'!$B$4:$C$97, 2, FALSE), IF((FLOOR($B75/1000000000000, 1) = 25), VLOOKUP($B75, [2]DataLookUp!$B$4:$D$632, 2, FALSE), "xx"))) -> Budianto | E75: Bank Central Asia | F75: =IF(EXACT(E75, ""), "", VLOOKUP($E75, OFFSET([3]MAIN!$B$2, 0, 0, 100, 6), 5, FALSE)) -> 166000000000005 | G75: 1280247568 | H75: Budianto | I75: 62000000000001 | M75: =M74 + IF(EXACT(N75, ""), 0, 1) -> 167000000000071 | N75: =IF(OR(EXACT(B75, ""), EXACT(G75, "")), "", CONCATENATE("PERFORM ""SchData-OLTP-Master"".""Func_TblBankAccount_SET""(varSystemLoginSession, null, null, null, null, null, varInstitutionBranchID, varBaseCurrencyID, ", F75, ", '", G75, "', '", H75, "', ", I75, ", ", B75, ");")) -> PERFORM "SchData-OLTP-Master"."Func_TblBankAccount_SET"(varSystemLoginSession, null, null, null, null, null, varInstitutionBranchID, varBaseCurrencyID, 166000000000005, '1280247568', 'Budianto', 62000000000001, 25000000000082);
B76: 25000000000092 | C76: =_xlfn.IFNA(IF(EXACT($B76, ""), "", VLOOKUP($B76, [4]DataLookUp!$C$4:$G$999, 3, FALSE )), "") -> 031212631 | D76: =IF(EXACT($B76, ""), "", IF((FLOOR($B76/1000000000000, 1) = 124), VLOOKUP($B76, '[1]DataLookUp - InstitutionBranch'!$B$4:$C$97, 2, FALSE), IF((FLOOR($B76/1000000000000, 1) = 25), VLOOKUP($B76, [2]DataLookUp!$B$4:$D$632, 2, FALSE), "xx"))) -> Darsito | E76: Bank Central Asia | F76: =IF(EXACT(E76, ""), "", VLOOKUP($E76, OFFSET([3]MAIN!$B$2, 0, 0, 100, 6), 5, FALSE)) -> 166000000000005 | G76: 2211206120 | H76: Darsito S Pd | I76: 62000000000001 | M76: =M75 + IF(EXACT(N76, ""), 0, 1) -> 167000000000072 | N76: =IF(OR(EXACT(B76, ""), EXACT(G76, "")), "", CONCATENATE("PERFORM ""SchData-OLTP-Master"".""Func_TblBankAccount_SET""(varSystemLoginSession, null, null, null, null, null, varInstitutionBranchID, varBaseCurrencyID, ", F76, ", '", G76, "', '", H76, "', ", I76, ", ", B76, ");")) -> PERFORM "SchData-OLTP-Master"."Func_TblBankAccount_SET"(varSystemLoginSession, null, null, null, null, null, varInstitutionBranchID, varBaseCurrencyID, 166000000000005, '2211206120', 'Darsito S Pd', 62000000000001, 25000000000092);
B77: 25000000000094 | C77: =_xlfn.IFNA(IF(EXACT($B77, ""), "", VLOOKUP($B77, [4]DataLookUp!$C$4:$G$999, 3, FALSE )), "") -> 171215791 | D77: =IF(EXACT($B77, ""), "", IF((FLOOR($B77/1000000000000, 1) = 124), VLOOKUP($B77, '[1]DataLookUp - InstitutionBranch'!$B$4:$C$97, 2, FALSE), IF((FLOOR($B77/1000000000000, 1) = 25), VLOOKUP($B77, [2]DataLookUp!$B$4:$D$632, 2, FALSE), "xx"))) -> Deddy Rochman | E77: Bank Central Asia | F77: =IF(EXACT(E77, ""), "", VLOOKUP($E77, OFFSET([3]MAIN!$B$2, 0, 0, 100, 6), 5, FALSE)) -> 166000000000005 | G77: 2839669733 | H77: Dedi Rohman | I77: 62000000000001 | M77: =M76 + IF(EXACT(N77, ""), 0, 1) -> 167000000000073 | N77: =IF(OR(EXACT(B77, ""), EXACT(G77, "")), "", CONCATENATE("PERFORM ""SchData-OLTP-Master"".""Func_TblBankAccount_SET""(varSystemLoginSession, null, null, null, null, null, varInstitutionBranchID, varBaseCurrencyID, ", F77, ", '", G77, "', '", H77, "', ", I77, ", ", B77, ");")) -> PERFORM "SchData-OLTP-Master"."Func_TblBankAccount_SET"(varSystemLoginSession, null, null, null, null, null, varInstitutionBranchID, varBaseCurrencyID, 166000000000005, '2839669733', 'Dedi Rohman', 62000000000001, 25000000000094);
B78: 25000000000106 | C78: =_xlfn.IFNA(IF(EXACT($B78, ""), "", VLOOKUP($B78, [4]DataLookUp!$C$4:$G$999, 3, FALSE )), "") -> 010605133 | D78: =IF(EXACT($B78, ""), "", IF((FLOOR($B78/1000000000000, 1) = 124), VLOOKUP($B78, '[1]DataLookUp - InstitutionBranch'!$B$4:$C$97, 2, FALSE), IF((FLOOR($B78/1000000000000, 1) = 25), VLOOKUP($B78, [2]DataLookUp!$B$4:$D$632, 2, FALSE), "xx"))) -> Dionesius Sostenist Duka | E78: Bank Central Asia | F78: =IF(EXACT(E78, ""), "", VLOOKUP($E78, OFFSET([3]MAIN!$B$2, 0, 0, 100, 6), 5, FALSE)) -> 166000000000005 | G78: 2731371123 | H78: Dionesius Sostenist Duka | I78: 62000000000001 | M78: =M77 + IF(EXACT(N78, ""), 0, 1) -> 167000000000074 | N78: =IF(OR(EXACT(B78, ""), EXACT(G78, "")), "", CONCATENATE("PERFORM ""SchData-OLTP-Master"".""Func_TblBankAccount_SET""(varSystemLoginSession, null, null, null, null, null, varInstitutionBranchID, varBaseCurrencyID, ", F78, ", '", G78, "', '", H78, "', ", I78, ", ", B78, ");")) -> PERFORM "SchData-OLTP-Master"."Func_TblBankAccount_SET"(varSystemLoginSession, null, null, null, null, null, varInstitutionBranchID, varBaseCurrencyID, 166000000000005, '2731371123', 'Dionesius Sostenist Duka', 62000000000001, 25000000000106);
B79: 25000000000116 | C79: =_xlfn.IFNA(IF(EXACT($B79, ""), "", VLOOKUP($B79, [4]DataLookUp!$C$4:$G$999, 3, FALSE )), "") -> 040803040 | D79: =IF(EXACT($B79, ""), "", IF((FLOOR($B79/1000000000000, 1) = 124), VLOOKUP($B79, '[1]DataLookUp - InstitutionBranch'!$B$4:$C$97, 2, FALSE), IF((FLOOR($B79/1000000000000, 1) = 25), VLOOKUP($B79, [2]DataLookUp!$B$4:$D$632, 2, FALSE), "xx"))) -> Edi Waluyo | E79: Bank Central Asia | F79: =IF(EXACT(E79, ""), "", VLOOKUP($E79, OFFSET([3]MAIN!$B$2, 0, 0, 100, 6), 5, FALSE)) -> 166000000000005 | G79: 0060185646 | H79: Edi Waluyo | I79: 62000000000001 | M79: =M78 + IF(EXACT(N79, ""), 0, 1) -> 167000000000075 | N79: =IF(OR(EXACT(B79, ""), EXACT(G79, "")), "", CONCATENATE("PERFORM ""SchData-OLTP-Master"".""Func_TblBankAccount_SET""(varSystemLoginSession, null, null, null, null, null, varInstitutionBranchID, varBaseCurrencyID, ", F79, ", '", G79, "', '", H79, "', ", I79, ", ", B79, ");")) -> PERFORM "SchData-OLTP-Master"."Func_TblBankAccount_SET"(varSystemLoginSession, null, null, null, null, null, varInstitutionBranchID, varBaseCurrencyID, 166000000000005, '0060185646', 'Edi Waluyo', 62000000000001, 25000000000116);
B80: 25000000000123 | C80: =_xlfn.IFNA(IF(EXACT($B80, ""), "", VLOOKUP($B80, [4]DataLookUp!$C$4:$G$999, 3, FALSE )), "") -> 200420932 | D80: =IF(EXACT($B80, ""), "", IF((FLOOR($B80/1000000000000, 1) = 124), VLOOKUP($B80, '[1]DataLookUp - InstitutionBranch'!$B$4:$C$97, 2, FALSE), IF((FLOOR($B80/1000000000000, 1) = 25), VLOOKUP($B80, [2]DataLookUp!$B$4:$D$632, 2, FALSE), "xx"))) -> Eka Bagus Dwi Putra | E80: Bank Central Asia | F80: =IF(EXACT(E80, ""), "", VLOOKUP($E80, OFFSET([3]MAIN!$B$2, 0, 0, 100, 6), 5, FALSE)) -> 166000000000005 | G80: 5211078091 | H80: Eka Bagus Dwi Putra | I80: 62000000000001 | M80: =M79 + IF(EXACT(N80, ""), 0, 1) -> 167000000000076 | N80: =IF(OR(EXACT(B80, ""), EXACT(G80, "")), "", CONCATENATE("PERFORM ""SchData-OLTP-Master"".""Func_TblBankAccount_SET""(varSystemLoginSession, null, null, null, null, null, varInstitutionBranchID, varBaseCurrencyID, ", F80, ", '", G80, "', '", H80, "', ", I80, ", ", B80, ");")) -> PERFORM "SchData-OLTP-Master"."Func_TblBankAccount_SET"(varSystemLoginSession, null, null, null, null, null, varInstitutionBranchID, varBaseCurrencyID, 166000000000005, '5211078091', 'Eka Bagus Dwi Putra', 62000000000001, 25000000000123);
B81: 25000000000125 | C81: =_xlfn.IFNA(IF(EXACT($B81, ""), "", VLOOKUP($B81, [4]DataLookUp!$C$4:$G$999, 3, FALSE )), "") -> 060121944 | D81: =IF(EXACT($B81, ""), "", IF((FLOOR($B81/1000000000000, 1) = 124), VLOOKUP($B81, '[1]DataLookUp - InstitutionBranch'!$B$4:$C$97, 2, FALSE), IF((FLOOR($B81/1000000000000, 1) = 25), VLOOKUP($B81, [2]DataLookUp!$B$4:$D$632, 2, FALSE), "xx"))) -> Eka Purwanti | E81: Bank Central Asia | F81: =IF(EXACT(E81, ""), "", VLOOKUP($E81, OFFSET([3]MAIN!$B$2, 0, 0, 100, 6), 5, FALSE)) -> 166000000000005 | G81: 5855178874 | H81: Eka Purwanti | I81: 62000000000001 | M81: =M80 + IF(EXACT(N81, ""), 0, 1) -> 167000000000077 | N81: =IF(OR(EXACT(B81, ""), EXACT(G81, "")), "", CONCATENATE("PERFORM ""SchData-OLTP-Master"".""Func_TblBankAccount_SET""(varSystemLoginSession, null, null, null, null, null, varInstitutionBranchID, varBaseCurrencyID, ", F81, ", '", G81, "', '", H81, "', ", I81, ", ", B81, ");")) -> PERFORM "SchData-OLTP-Master"."Func_TblBankAccount_SET"(varSystemLoginSession, null, null, null, null, null, varInstitutionBranchID, varBaseCurrencyID, 166000000000005, '5855178874', 'Eka Purwanti', 62000000000001, 25000000000125);
B82: 25000000000138 | C82: =_xlfn.IFNA(IF(EXACT($B82, ""), "", VLOOKUP($B82, [4]DataLookUp!$C$4:$G$999, 3, FALSE )), "") -> 010806250 | D82: =IF(EXACT($B82, ""), "", IF((FLOOR($B82/1000000000000, 1) = 124), VLOOKUP($B82, '[1]DataLookUp - InstitutionBranch'!$B$4:$C$97, 2, FALSE), IF((FLOOR($B82/1000000000000, 1) = 25), VLOOKUP($B82, [2]DataLookUp!$B$4:$D$632, 2, FALSE), "xx"))) -> Endang Sutrisna | E82: Bank Central Asia | F82: =IF(EXACT(E82, ""), "", VLOOKUP($E82, OFFSET([3]MAIN!$B$2, 0, 0, 100, 6), 5, FALSE)) -> 166000000000005 | G82: 5750226541 | H82: Endang Sutrisno | I82: 62000000000001 | M82: =M81 + IF(EXACT(N82, ""), 0, 1) -> 167000000000078 | N82: =IF(OR(EXACT(B82, ""), EXACT(G82, "")), "", CONCATENATE("PERFORM ""SchData-OLTP-Master"".""Func_TblBankAccount_SET""(varSystemLoginSession, null, null, null, null, null, varInstitutionBranchID, varBaseCurrencyID, ", F82, ", '", G82, "', '", H82, "', ", I82, ", ", B82, ");")) -> PERFORM "SchData-OLTP-Master"."Func_TblBankAccount_SET"(varSystemLoginSession, null, null, null, null, null, varInstitutionBranchID, varBaseCurrencyID, 166000000000005, '5750226541', 'Endang Sutrisno', 62000000000001, 25000000000138);
B83: 25000000000522 | C83: =_xlfn.IFNA(IF(EXACT($B83, ""), "", VLOOKUP($B83, [4]DataLookUp!$C$4:$G$999, 3, FALSE )), "") -> 191022968 | D83: =IF(EXACT($B83, ""), "", IF((FLOOR($B83/1000000000000, 1) = 124), VLOOKUP($B83, '[1]DataLookUp - InstitutionBranch'!$B$4:$C$97, 2, FALSE), IF((FLOOR($B83/1000000000000, 1) = 25), VLOOKUP($B83, [2]DataLookUp!$B$4:$D$632, 2, FALSE), "xx"))) -> Ferdian Kriswantoro | E83: Bank Central Asia | F83: =IF(EXACT(E83, ""), "", VLOOKUP($E83, OFFSET([3]MAIN!$B$2, 0, 0, 100, 6), 5, FALSE)) -> 166000000000005 | G83: 8760378217 | H83: Ferdian Kriswantoro | I83: 62000000000001 | M83: =M82 + IF(EXACT(N83, ""), 0, 1) -> 167000000000079 | N83: =IF(OR(EXACT(B83, ""), EXACT(G83, "")), "", CONCATENATE("PERFORM ""SchData-OLTP-Master"".""Func_TblBankAccount_SET""(varSystemLoginSession, null, null, null, null, null, varInstitutionBranchID, varBaseCurrencyID, ", F83, ", '", G83, "', '", H83, "', ", I83, ", ", B83, ");")) -> PERFORM "SchData-OLTP-Master"."Func_TblBankAccount_SET"(varSystemLoginSession, null, null, null, null, null, varInstitutionBranchID, varBaseCurrencyID, 166000000000005, '8760378217', 'Ferdian Kriswantoro', 62000000000001, 25000000000522);
B84: 25000000000159 | C84: =_xlfn.IFNA(IF(EXACT($B84, ""), "", VLOOKUP($B84, [4]DataLookUp!$C$4:$G$999, 3, FALSE )), "") -> 181114748 | D84: =IF(EXACT($B84, ""), "", IF((FLOOR($B84/1000000000000, 1) = 124), VLOOKUP($B84, '[1]DataLookUp - InstitutionBranch'!$B$4:$C$97, 2, FALSE), IF((FLOOR($B84/1000000000000, 1) = 25), VLOOKUP($B84, [2]DataLookUp!$B$4:$D$632, 2, FALSE), "xx"))) -> Frando Judi Siahaan | E84: Bank Central Asia | F84: =IF(EXACT(E84, ""), "", VLOOKUP($E84, OFFSET([3]MAIN!$B$2, 0, 0, 100, 6), 5, FALSE)) -> 166000000000005 | G84: 8200472447 | H84: Frando Judi Siahaan | I84: 62000000000001 | M84: =M83 + IF(EXACT(N84, ""), 0, 1) -> 167000000000080 | N84: =IF(OR(EXACT(B84, ""), EXACT(G84, "")), "", CONCATENATE("PERFORM ""SchData-OLTP-Master"".""Func_TblBankAccount_SET""(varSystemLoginSession, null, null, null, null, null, varInstitutionBranchID, varBaseCurrencyID, ", F84, ", '", G84, "', '", H84, "', ", I84, ", ", B84, ");")) -> PERFORM "SchData-OLTP-Master"."Func_TblBankAccount_SET"(varSystemLoginSession, null, null, null, null, null, varInstitutionBranchID, varBaseCurrencyID, 166000000000005, '8200472447', 'Frando Judi Siahaan', 62000000000001, 25000000000159);
...

Sheet DataLookUp
B2: Sys_PID | C2: Bank Account | D2: Currency | E2: Default Holder
B4: =IF(EXACT(SEED!$N4, ""), "", SEED!$M4) -> 167000000000001 | C4: =IF(EXACT($B4, ""), "", SEED!$E4&" - "&SEED!$G4) -> Bank Central Asia - 0063032911 | D4: =IF(EXACT($B4, ""), "", IF((SEED!I4*1)=62000000000001, "IDR", IF((SEED!I4*1)=62000000000002, "USD", IF((SEED!I4*1)=62000000000003, "AUD", "Others")))) -> IDR | E4: =IF(EXACT($B4, ""), "", IF(FLOOR(SEED!$B4/1000000000000, 1)=124, "Institution - "&VLOOKUP(SEED!$B4, '[1]DataLookUp - InstitutionBranch'!$B$4:$C$1000, 2, FALSE), "Person - "&VLOOKUP(SEED!$B4, [2]DataLookUp!$B$4:$D$1000, 2, FALSE))) -> Institution - PT. QDC Technologies
B5: =IF(EXACT(SEED!$N5, ""), "", SEED!$M5) -> 167000000000002 | C5: =IF(EXACT($B5, ""), "", SEED!$E5&" - "&SEED!$G5) -> Bank Central Asia - 0065557750 | D5: =IF(EXACT($B5, ""), "", IF((SEED!I5*1)=62000000000001, "IDR", IF((SEED!I5*1)=62000000000002, "USD", IF((SEED!I5*1)=62000000000003, "AUD", "Others")))) -> IDR | E5: =IF(EXACT($B5, ""), "", IF(FLOOR(SEED!$B5/1000000000000, 1)=124, "Institution - "&VLOOKUP(SEED!$B5, '[1]DataLookUp - InstitutionBranch'!$B$4:$C$1000, 2, FALSE), "Person - "&VLOOKUP(SEED!$B5, [2]DataLookUp!$B$4:$D$1000, 2, FALSE))) -> Institution - PT. QDC Technologies
B6: =IF(EXACT(SEED!$N6, ""), "", SEED!$M6) -> 167000000000003 | C6: =IF(EXACT($B6, ""), "", SEED!$E6&" - "&SEED!$G6) -> Bank Central Asia - 0068502911 | D6: =IF(EXACT($B6, ""), "", IF((SEED!I6*1)=62000000000001, "IDR", IF((SEED!I6*1)=62000000000002, "USD", IF((SEED!I6*1)=62000000000003, "AUD", "Others")))) -> IDR | E6: =IF(EXACT($B6, ""), "", IF(FLOOR(SEED!$B6/1000000000000, 1)=124, "Institution - "&VLOOKUP(SEED!$B6, '[1]DataLookUp - InstitutionBranch'!$B$4:$C$1000, 2, FALSE), "Person - "&VLOOKUP(SEED!$B6, [2]DataLookUp!$B$4:$D$1000, 2, FALSE))) -> Institution - PT. QDC Technologies
B7: =IF(EXACT(SEED!$N7, ""), "", SEED!$M7) -> 167000000000004 | C7: =IF(EXACT($B7, ""), "", SEED!$E7&" - "&SEED!$G7) -> Bank Central Asia - 2173050101 | D7: =IF(EXACT($B7, ""), "", IF((SEED!I7*1)=62000000000001, "IDR", IF((SEED!I7*1)=62000000000002, "USD", IF((SEED!I7*1)=62000000000003, "AUD", "Others")))) -> IDR | E7: =IF(EXACT($B7, ""), "", IF(FLOOR(SEED!$B7/1000000000000, 1)=124, "Institution - "&VLOOKUP(SEED!$B7, '[1]DataLookUp - InstitutionBranch'!$B$4:$C$1000, 2, FALSE), "Person - "&VLOOKUP(SEED!$B7, [2]DataLookUp!$B$4:$D$1000, 2, FALSE))) -> Institution - PT. QDC Technologies
B8: =IF(EXACT(SEED!$N8, ""), "", SEED!$M8) -> 167000000000005 | C8: =IF(EXACT($B8, ""), "", SEED!$E8&" - "&SEED!$G8) -> Bank Central Asia - 2173108214 | D8: =IF(EXACT($B8, ""), "", IF((SEED!I8*1)=62000000000001, "IDR", IF((SEED!I8*1)=62000000000002, "USD", IF((SEED!I8*1)=62000000000003, "AUD", "Others")))) -> IDR | E8: =IF(EXACT($B8, ""), "", IF(FLOOR(SEED!$B8/1000000000000, 1)=124, "Institution - "&VLOOKUP(SEED!$B8, '[1]DataLookUp - InstitutionBranch'!$B$4:$C$1000, 2, FALSE), "Person - "&VLOOKUP(SEED!$B8, [2]DataLookUp!$B$4:$D$1000, 2, FALSE))) -> Institution - PT. QDC Technologies
B9: =IF(EXACT(SEED!$N9, ""), "", SEED!$M9) -> 167000000000006 | C9: =IF(EXACT($B9, ""), "", SEED!$E9&" - "&SEED!$G9) -> Bank CIMB Niaga - 762375277200 | D9: =IF(EXACT($B9, ""), "", IF((SEED!I9*1)=62000000000001, "IDR", IF((SEED!I9*1)=62000000000002, "USD", IF((SEED!I9*1)=62000000000003, "AUD", "Others")))) -> IDR | E9: =IF(EXACT($B9, ""), "", IF(FLOOR(SEED!$B9/1000000000000, 1)=124, "Institution - "&VLOOKUP(SEED!$B9, '[1]DataLookUp - InstitutionBranch'!$B$4:$C$1000, 2, FALSE), "Person - "&VLOOKUP(SEED!$B9, [2]DataLookUp!$B$4:$D$1000, 2, FALSE))) -> Institution - PT. QDC Technologies
B10: =IF(EXACT(SEED!$N10, ""), "", SEED!$M10) -> 167000000000007 | C10: =IF(EXACT($B10, ""), "", SEED!$E10&" - "&SEED!$G10) -> Bank CIMB Niaga - 800039839400 | D10: =IF(EXACT($B10, ""), "", IF((SEED!I10*1)=62000000000001, "IDR", IF((SEED!I10*1)=62000000000002, "USD", IF((SEED!I10*1)=62000000000003, "AUD", "Others")))) -> IDR | E10: =IF(EXACT($B10, ""), "", IF(FLOOR(SEED!$B10/1000000000000, 1)=124, "Institution - "&VLOOKUP(SEED!$B10, '[1]DataLookUp - InstitutionBranch'!$B$4:$C$1000, 2, FALSE), "Person - "&VLOOKUP(SEED!$B10, [2]DataLookUp!$B$4:$D$1000, 2, FALSE))) -> Institution - PT. QDC Technologies
B11: =IF(EXACT(SEED!$N11, ""), "", SEED!$M11) -> 167000000000008 | C11: =IF(EXACT($B11, ""), "", SEED!$E11&" - "&SEED!$G11) -> Bank CIMB Niaga - 800039840100 | D11: =IF(EXACT($B11, ""), "", IF((SEED!I11*1)=62000000000001, "IDR", IF((SEED!I11*1)=62000000000002, "USD", IF((SEED!I11*1)=62000000000003, "AUD", "Others")))) -> IDR | E11: =IF(EXACT($B11, ""), "", IF(FLOOR(SEED!$B11/1000000000000, 1)=124, "Institution - "&VLOOKUP(SEED!$B11, '[1]DataLookUp - InstitutionBranch'!$B$4:$C$1000, 2, FALSE), "Person - "&VLOOKUP(SEED!$B11, [2]DataLookUp!$B$4:$D$1000, 2, FALSE))) -> Institution - PT. QDC Technologies
B12: =IF(EXACT(SEED!$N12, ""), "", SEED!$M12) -> 167000000000009 | C12: =IF(EXACT($B12, ""), "", SEED!$E12&" - "&SEED!$G12) -> Bank CIMB Niaga - 860012900500 | D12: =IF(EXACT($B12, ""), "", IF((SEED!I12*1)=62000000000001, "IDR", IF((SEED!I12*1)=62000000000002, "USD", IF((SEED!I12*1)=62000000000003, "AUD", "Others")))) -> IDR | E12: =IF(EXACT($B12, ""), "", IF(FLOOR(SEED!$B12/1000000000000, 1)=124, "Institution - "&VLOOKUP(SEED!$B12, '[1]DataLookUp - InstitutionBranch'!$B$4:$C$1000, 2, FALSE), "Person - "&VLOOKUP(SEED!$B12, [2]DataLookUp!$B$4:$D$1000, 2, FALSE))) -> Institution - PT. QDC Technologies
B13: =IF(EXACT(SEED!$N13, ""), "", SEED!$M13) -> 167000000000010 | C13: =IF(EXACT($B13, ""), "", SEED!$E13&" - "&SEED!$G13) -> Bank Commonwealth - 1051189606 | D13: =IF(EXACT($B13, ""), "", IF((SEED!I13*1)=62000000000001, "IDR", IF((SEED!I13*1)=62000000000002, "USD", IF((SEED!I13*1)=62000000000003, "AUD", "Others")))) -> IDR | E13: =IF(EXACT($B13, ""), "", IF(FLOOR(SEED!$B13/1000000000000, 1)=124, "Institution - "&VLOOKUP(SEED!$B13, '[1]DataLookUp - InstitutionBranch'!$B$4:$C$1000, 2, FALSE), "Person - "&VLOOKUP(SEED!$B13, [2]DataLookUp!$B$4:$D$1000, 2, FALSE))) -> Institution - PT. QDC Technologies
B14: =IF(EXACT(SEED!$N14, ""), "", SEED!$M14) -> 167000000000011 | C14: =IF(EXACT($B14, ""), "", SEED!$E14&" - "&SEED!$G14) -> Bank Commonwealth - 1051189707 | D14: =IF(EXACT($B14, ""), "", IF((SEED!I14*1)=62000000000001, "IDR", IF((SEED!I14*1)=62000000000002, "USD", IF((SEED!I14*1)=62000000000003, "AUD", "Others")))) -> USD | E14: =IF(EXACT($B14, ""), "", IF(FLOOR(SEED!$B14/1000000000000, 1)=124, "Institution - "&VLOOKUP(SEED!$B14, '[1]DataLookUp - InstitutionBranch'!$B$4:$C$1000, 2, FALSE), "Person - "&VLOOKUP(SEED!$B14, [2]DataLookUp!$B$4:$D$1000, 2, FALSE))) -> Institution - PT. QDC Technologies
B15: =IF(EXACT(SEED!$N15, ""), "", SEED!$M15) -> 167000000000012 | C15: =IF(EXACT($B15, ""), "", SEED!$E15&" - "&SEED!$G15) -> Bank KB Bukopin - 1001327468 | D15: =IF(EXACT($B15, ""), "", IF((SEED!I15*1)=62000000000001, "IDR", IF((SEED!I15*1)=62000000000002, "USD", IF((SEED!I15*1)=62000000000003, "AUD", "Others")))) -> IDR | E15: =IF(EXACT($B15, ""), "", IF(FLOOR(SEED!$B15/1000000000000, 1)=124, "Institution - "&VLOOKUP(SEED!$B15, '[1]DataLookUp - InstitutionBranch'!$B$4:$C$1000, 2, FALSE), "Person - "&VLOOKUP(SEED!$B15, [2]DataLookUp!$B$4:$D$1000, 2, FALSE))) -> Institution - PT. QDC Technologies
... B281: =IF(EXACT(SEED!$N281, ""), "", SEED!$M281) | C281: =IF(EXACT($B281, ""), "", SEED!$E281&" - "&SEED!$G281) | D281: =IF(EXACT($B281, ""), "", IF((SEED!I281*1)=62000000000001, "IDR", IF((SEED!I281*1)=62000000000002, "USD", IF((SEED!I281*1)=62000000000003, "AUD", "Others")))) | E281: =IF(EXACT($B281, ""), "", IF(FLOOR(SEED!$B281/1000000000000, 1)=124, "Institution - "&VLOOKUP(SEED!$B281, '[1]DataLookUp - InstitutionBranch'!$B$4:$C$1000, 2, FALSE), "Person - "&VLOOKUP(SEED!$B281, [2]DataLookUp!$B$4:$D$1000, 2, FALSE)))

Sheet Sheet2
B2: bnk_nama | C2: bnk_norek | D2: bnk_noreknama | E2: bnk_cabang | F2: bnk_alamat | G2: val_kode | H2: cabang | I2: bnk_kota
B3: Bank Central Asia | C3: 0063032911 | D3: PT. QDC Technologies | E3: KCU SCBD | F3: Equtiy Tower Ground Floor, Jl. Jend Sudirman Kav 5 | G3: IDR | H3: "" | I3: Jakarta
B4: Bank Central Asia | C4: 0065557750 | D4: PT QDC Technologies | E4: SCBD | F4: Equity Tower, Ground Floor, Unit D & Lantai 8, Uni | G4: IDR | H4: "" | I4: Jakarta Selatan
B5: Bank Central Asia | C5: 006-8502911 | D5: PT QDC Technologies | E5: KCU SCBD | F5: Equity Tower, Ground Floor, Unit D & Lantai 8, Uni | G5: IDR | H5: "" | I5: Jakarta Selata
B6: Bank Central Asia | C6: 2173050101 | D6: BCA Medan | E6: Gd. Menara Karya | F6: Jl. HR. Rasuna Said X-5 Kav.1-2 Jkt | G6: IDR | H6: "" | I6: DKI Jakarta
B7: Bank Central Asia | C7: 2173108214 | D7: BCA Surabaya | E7: Gd. Menara Karya | F7: Jl. HR. Rasuna Said X-5 Kav.1-2 Jkt | G7: IDR | H7: "" | I7: DKI Jakarta
B8: Bank CIMB Niaga | C8: 762375277200 | D8: QDC Technologies | E8: Sudirman | F8: Graha Niaga / Niaga Tower , Jl. Jendral Sudirman K | G8: IDR | H8: "" | I8: Jakarta
B9: Bank CIMB Niaga | C9: 800039839400 | D9: PT Qdc Technologies | E9: Sudirman | F9: BEJ | G9: IDR | H9: "" | I9: Jakarta
B10: Bank CIMB Niaga | C10: 800039840100 | D10: PT QDC TECHNOLOGIES | E10: Sudirman | F10: BEJ | G10: IDR | H10: "" | I10: Jakarta
B11: Bank CIMB Niaga | C11: 860012900500 | D11: PT QDC Technologies | E11: Sudirman | F11: Jl. Jendral Sudirman Kav 58 | G11: IDR | H11: "" | I11: Jakarta Selatan
B12: Bank Commonwealth | C12: 1051189606 | D12: PT QDC | E12: Sudirman | F12: Wisma Metropolitan 2 Jln Sudirman Kav 25 | G12: IDR | H12: "" | I12: Jakarta
B13: Bank Commonwealth | C13: 1051189707 | D13: PT QDC Technologies | E13: Sudirman | F13: Wisma Metropolitan II, 3A Floor Jl. Jenderal Sudir | G13: USD | H13: "" | I13: Jakarta
... B58: Bank Tabungan Negara | C58: 0100201300000052 | D58: PT QDC Technologies | E58: Mediterania | F58: Apartemen Mediterania Palace Residence, JL Landas | G58: IDR | H58: "" | I58: Apartemen Mediterania Palace Residence, JL Landas

Sheet Sheet4
B1: PERFORM "SchData-OLTP-Master"."Func_TblBankAccount_SET"(varSystemLoginSession, null, null, null, varInstitutionBranchID, 166000000000005, '6550289791', 'Teguh Pratama Januzir S', 25000000000439);
B2: bank | C2: bnk_norek | E2: bnk_nama | F2: bnk_noreknama | G2: bnk_cabang | H2: bnk_alamat | I2: val_kode | J2: cabang
B3: Bank Central Asia | C3: 0063032911 | E3: BCA | F3: PT QDC Technologies | J3: Jakarta
B4: Bank Central Asia | C4: 2173050101 | E4: BCA | F4: PT QDC Technologies | J4: PJO Medan
B5: Bank Central Asia | C5: 2173108214 | E5: BCA | F5: PT QDC Technologies | J5: PJO Surabaya
B6: Bank Central Asia | C6: 0063032911 | E6: BCA | F6: PT. QDC Technologies | G6: KCU SCBD | H6: Equtiy Tower Ground Floor, Jl. Jend Sudirman Kav 5 | I6: IDR | J6: ""
B7: Bank Central Asia | C7: 2173050101 | E7: BCM | F7: BCA Medan | G7: Gd. Menara Karya | H7: Jl. HR. Rasuna Said X-5 Kav.1-2 Jkt | I7: IDR | J7: ""
B8: Bank Central Asia | C8: 2173108214 | E8: BCS | F8: BCA Surabaya | G8: Gd. Menara Karya | H8: Jl. HR. Rasuna Said X-5 Kav.1-2 Jkt | I8: IDR | J8: ""
B9: Bank Central Asia | C9: 0068502911 | E9: BCA | F9: PT QDC Technologies | G9: KCU SCBD | H9: Equity Tower, Ground Floor, Unit D & Lantai 8, Uni | I9: IDR | J9: ""
B10: Bank Central Asia | C10: 0065557750 | E10: BCA-750 | F10: PT QDC Technologies | G10: SCBD | H10: Equity Tower, Ground Floor, Unit D & Lantai 8, Uni | I10: IDR | J10: ""
B11: Bank CIMB Niaga | C11: 800039839400 | E11: Niaga | F11: PT Qdc Technologies | G11: Sudirman | H11: BEJ | I11: IDR | J11: ""
B12: Bank CIMB Niaga | C12: 800039840100 | E12: NIAGA | F12: PT QDC TECHNOLOGIES | G12: Sudirman | H12: BEJ | I12: IDR | J12: ""
B13: Bank CIMB Niaga | C13: 762375277200 | E13: NiagaS200 | F13: QDC Technologies | G13: Sudirman | H13: Graha Niaga / Niaga Tower , Jl. Jendral Sudirman K | I13: IDR | J13: ""
B14: Bank CIMB Niaga | C14: 860012900500 | E14: Niaga Syariah | F14: PT QDC Technologies | G14: Sudirman | H14: Jl. Jendral Sudirman Kav 58 | I14: IDR | J14: ""
B15: Bank Commonwealth | C15: 1051189606 | E15: Commonwealth | F15: PT QDC | G15: Sudirman | H15: Wisma Metropolitan 2 Jln Sudirman Kav 25 | I15: IDR | J15: ""
B16: Bank Commonwealth | C16: 1051189707 | E16: Commonwealth | F16: PT QDC Technologies | G16: Sudirman | H16: Wisma Metropolitan II, 3A Floor Jl. Jenderal Sudir | I16: USD | J16: ""
B17: Bank KB Bukopin | C17: 1002405420 | E17: BANK BUKOPIN | F17: BANK BUKOPIN | G17: JAKARTA | H17: JAKARTA | I17: IDR | J17: ""
... B62: ZZZ | C62: 123456789 | E62: Sales Journal | F62: Sales Journal | G62: PT QDC Technologies | H62: PT QDC Technologies | I62: IDR | J62: ""

Sheet Sheet1
B2: 000600313QDCT2801006303291100000007000000493192690.00122022
B3: 00060262641000000537535400210904088 Abd Samad
B4: 02040089643000000681586400110422962 Achmad Yunadi
B5: 00350780718000001267490900010703020 Agnes Sutedja
B6: 06821221339000000513600000311022972 Agus Nuryadi
B7: 05750423347000000769750000081019918 Agus Salim
B8: 07150306269000000434308100150506222 Ahmad Syaifulloh
B9: 02670159496000000675090900191022969 Ahmad Choerul
B10: 05520607058000000660853600141020935 Aldi Mulyadi
B11: 05520537742000000460771800100419903 Annisa Dewi Arumsari
B12: 04565061969000000584986400310821955 Anugerah Januariansyah
B13: 05520579321000000617200000100920934 Belina Lindarwani
... B72: 07125461581000000455000000000000002 Muhammad Lukbani
