Workbook

Sheet RAW - HP
B2: 250117820 | C2: Yusri Azhar
B3: 140612611 | C3: Nancy Meriana Sinaga
B4: 210807401 | C4: Galuh Swastika
B5: 310717841 | C5: Maharani Uthmaniah
B6: 50913684 | C6: Elisa Krisnawati
B7: 261016808 | C7: M. Ervan Isyawal Akbar
B8: 161213705 | C8: Chairul Musaddat
B9: 140410529 | C9: Anda Zuchradi Dadi
B10: 10703025 | C10: Indawan Haryadi
B11: 130217822 | C11: Mia Puspitasari
B12: 10314719 | C12: Prayati Zai
B13: 211117851 | C13: Silvia Febi Putri
... B56: 210618875 | C56: Jaenudin
B57: 150419905 | C57: Khafid Fahrurrozi | D57: +62 878-7792-3708
B58: 11018884 | C58: Lucky Daniansyah | D58: +62 812-9397-4227
B59: 100918881 | C59: Rian Yushak | D59: +62 856-9401-0438
B60: 20519907 | C60: Bahyu Sanciko | D60: +62 896-8226-1128
B61: 111103059 | C61: Yusman W | D61: +62 838-7009-0020
B62: 81012521 | C62: Ardi | D62: +62 812-9592-4499
B63: 251016807 | C63: Abdul Rahman Sitompul
B64: 120417831 | C64: Erwin Firmansyah | D64: +62 857-2162-3338
B65: 290118856 | C65: Paryanto | D65: +62 813-8428-4951
B66: 111018884 | C66: Vidhy Putri Kartika | D66: +62 838-7375-2989
B67: 10317827 | C67: Rohendi | D67: +62 822-6092-0555
B68: 71217854 | C68: Anggit Ismiyanto | D68: +62 822-5131-3575
B69: 100613675 | C69: Firman Akbar | D69: +62 812-4519-2298
B70: 231219923 | C70: Fuad Febrian | D70: +62 813-1422-8295
B71: 90819916 | C71: Sulih | D71: +62 857-2881-8103
B72: 140518870 | C72: Heru Sugiri | D72: +62 812-2491-0322
B73: 221007407 | C73: Rinaldi Asrin | D73: +62 818-0691-9844
B74: 100220928 | C74: Rafi Firman Saputra | D74: +62 857-6021-1355
B75: 160718878 | C75: Putra Perdana Tirtomoyo | D75: +62 812-8884-4266
... B82: 31218894 | C82: Herlin Juli Asri | D82: +62 813-1920-7116
B83: 271120940 | C83: Sherly Tamira Happy | D83: +62 811-9568-886 | E83: +62 8128-2230-665
B84: 111218896 | C84: Muhammad Khadafy | D84: +62 812-8744-1774
B85: 251119920 | C85: Hernita Dwi Cahyani Putri | D85: +62 857-7048-1711
B86: 271217855 | C86: Amir Sofyan Hadi | D86: +62 813-1690-6639
B87: 140319901 | C87: Bani Mustazeni | D87: +62 857-1519-9050
B88: 120220929 | C88: Eko Kurniawan | D88: +62 859-4561-9900
B89: 140518871 | C89: Fani Dwi Astutik | D89: +62 812-9902-0267
...

Sheet SEED
B2: DefaultEntity _RefID | C2: Default Entity Name | D2: ContactNumberType _RefID | E2: Contact Number Type Name | F2: Contact Number | G2: Contact Number Extension | H2: Holder Name | J2: SYS_PID Prediction | K2: SQL Syntax
J3: 286000000000000
B4: 25000000000250 | C4: =IF(EXACT($B4, ""), "", IF((($B4 - MOD($B4, 1000000000000))/1000000000000)=25, CONCATENATE("Person - ", VLOOKUP($B4, [1]DataLookUp!$B$4:$C$2000, 2, FALSE)), IF((($B4 - MOD($B4, 1000000000000))/1000000000000)=124, CONCATENATE("Institution - ", VLOOKUP($B4, '[2]DataLookUp - InstitutionBranch'!$B$4:$C$2000, 2, FALSE)), ""))) -> Person - Khafid Fahrurrozi | D4: 223000000000002 | E4: =IF(EXACT($D4, ""), "", VLOOKUP($D4, 'REF - ContactNumberType'!$B$4:$C$10, 2, FALSE)) -> Mobile Phone | F4: +62 878-7792-3708 | H4: Khafid Fahrurrozi | J4: =J3 + IF(EXACT(K4, ""), 0, 1) -> 286000000000001 | K4: =IF(EXACT(F4, ""), "", CONCATENATE("PERFORM ""SchData-OLTP-Master"".""Func_TblContactNumber_SET""(varSystemLoginSession::bigint, null::bigint, null::varchar, null::timestamptz, null::timestamptz, null::varchar, varInstitutionBranchID::bigint, varBaseCurrencyID::bigint, ", IF(EXACT($D4, ""), "NULL", ""&$D4&""), "::bigint, ", IF(EXACT($F4, ""), "NULL", "'"&$F4&"'"), "::varchar, ", IF(EXACT($G4, ""), "NULL", "'"&$G4&"'"), "::varchar, ", IF(EXACT($H4, ""), "NULL", "'"&$H4&"'"), "::varchar, ", IF(EXACT($B4, ""), "NULL", "'"&$B4&"'"), "::bigint);")) -> PERFORM "SchData-OLTP-Master"."Func_TblContactNumber_SET"(varSystemLoginSession::bigint, null::bigint, null::varchar, null::timestamptz, null::timestamptz, null::varchar, varInstitutionBranchID::bigint, varBaseCurrencyID::bigint, 223000000000002::bigint, '+62 878-7792-3708'::varchar, NULL::varchar, 'Khafid Fahrurrozi'::varchar, '25000000000250'::bigint);
C5: =IF(EXACT($B5, ""), "", IF((($B5 - MOD($B5, 1000000000000))/1000000000000)=25, CONCATENATE("Person - ", VLOOKUP($B5, [1]DataLookUp!$B$4:$C$2000, 2, FALSE)), IF((($B5 - MOD($B5, 1000000000000))/1000000000000)=124, CONCATENATE("Institution - ", VLOOKUP($B5, '[2]DataLookUp - InstitutionBranch'!$B$4:$C$2000, 2, FALSE)), ""))) | D5: 223000000000002 | E5: =IF(EXACT($D5, ""), "", VLOOKUP($D5, 'REF - ContactNumberType'!$B$4:$C$10, 2, FALSE)) -> Mobile Phone | F5: +62 812-9397-4227 | H5: Lucky Daniansyah | J5: =J4 + IF(EXACT(K5, ""), 0, 1) -> 286000000000002 | K5: =IF(EXACT(F5, ""), "", CONCATENATE("PERFORM ""SchData-OLTP-Master"".""Func_TblContactNumber_SET""(varSystemLoginSession::bigint, null::bigint, null::varchar, null::timestamptz, null::timestamptz, null::varchar, varInstitutionBranchID::bigint, varBaseCurrencyID::bigint, ", IF(EXACT($D5, ""), "NULL", ""&$D5&""), "::bigint, ", IF(EXACT($F5, ""), "NULL", "'"&$F5&"'"), "::varchar, ", IF(EXACT($G5, ""), "NULL", "'"&$G5&"'"), "::varchar, ", IF(EXACT($H5, ""), "NULL", "'"&$H5&"'"), "::varchar, ", IF(EXACT($B5, ""), "NULL", "'"&$B5&"'"), "::bigint);")) -> PERFORM "SchData-OLTP-Master"."Func_TblContactNumber_SET"(varSystemLoginSession::bigint, null::bigint, null::varchar, null::timestamptz, null::timestamptz, null::varchar, varInstitutionBranchID::bigint, varBaseCurrencyID::bigint, 223000000000002::bigint, '+62 812-9397-4227'::varchar, NULL::varchar, 'Lucky Daniansyah'::varchar, NULL::bigint);
B6: 25000000000353 | C6: =IF(EXACT($B6, ""), "", IF((($B6 - MOD($B6, 1000000000000))/1000000000000)=25, CONCATENATE("Person - ", VLOOKUP($B6, [1]DataLookUp!$B$4:$C$2000, 2, FALSE)), IF((($B6 - MOD($B6, 1000000000000))/1000000000000)=124, CONCATENATE("Institution - ", VLOOKUP($B6, '[2]DataLookUp - InstitutionBranch'!$B$4:$C$2000, 2, FALSE)), ""))) -> Person - Rian Yushak | D6: 223000000000002 | E6: =IF(EXACT($D6, ""), "", VLOOKUP($D6, 'REF - ContactNumberType'!$B$4:$C$10, 2, FALSE)) -> Mobile Phone | F6: +62 856-9401-0438 | H6: Rian Yushak | J6: =J5 + IF(EXACT(K6, ""), 0, 1) -> 286000000000003 | K6: =IF(EXACT(F6, ""), "", CONCATENATE("PERFORM ""SchData-OLTP-Master"".""Func_TblContactNumber_SET""(varSystemLoginSession::bigint, null::bigint, null::varchar, null::timestamptz, null::timestamptz, null::varchar, varInstitutionBranchID::bigint, varBaseCurrencyID::bigint, ", IF(EXACT($D6, ""), "NULL", ""&$D6&""), "::bigint, ", IF(EXACT($F6, ""), "NULL", "'"&$F6&"'"), "::varchar, ", IF(EXACT($G6, ""), "NULL", "'"&$G6&"'"), "::varchar, ", IF(EXACT($H6, ""), "NULL", "'"&$H6&"'"), "::varchar, ", IF(EXACT($B6, ""), "NULL", "'"&$B6&"'"), "::bigint);")) -> PERFORM "SchData-OLTP-Master"."Func_TblContactNumber_SET"(varSystemLoginSession::bigint, null::bigint, null::varchar, null::timestamptz, null::timestamptz, null::varchar, varInstitutionBranchID::bigint, varBaseCurrencyID::bigint, 223000000000002::bigint, '+62 856-9401-0438'::varchar, NULL::varchar, 'Rian Yushak'::varchar, '25000000000353'::bigint);
C7: =IF(EXACT($B7, ""), "", IF((($B7 - MOD($B7, 1000000000000))/1000000000000)=25, CONCATENATE("Person - ", VLOOKUP($B7, [1]DataLookUp!$B$4:$C$2000, 2, FALSE)), IF((($B7 - MOD($B7, 1000000000000))/1000000000000)=124, CONCATENATE("Institution - ", VLOOKUP($B7, '[2]DataLookUp - InstitutionBranch'!$B$4:$C$2000, 2, FALSE)), ""))) | D7: 223000000000002 | E7: =IF(EXACT($D7, ""), "", VLOOKUP($D7, 'REF - ContactNumberType'!$B$4:$C$10, 2, FALSE)) -> Mobile Phone | F7: +62 896-8226-1128 | H7: Bahyu Sanciko | J7: =J6 + IF(EXACT(K7, ""), 0, 1) -> 286000000000004 | K7: =IF(EXACT(F7, ""), "", CONCATENATE("PERFORM ""SchData-OLTP-Master"".""Func_TblContactNumber_SET""(varSystemLoginSession::bigint, null::bigint, null::varchar, null::timestamptz, null::timestamptz, null::varchar, varInstitutionBranchID::bigint, varBaseCurrencyID::bigint, ", IF(EXACT($D7, ""), "NULL", ""&$D7&""), "::bigint, ", IF(EXACT($F7, ""), "NULL", "'"&$F7&"'"), "::varchar, ", IF(EXACT($G7, ""), "NULL", "'"&$G7&"'"), "::varchar, ", IF(EXACT($H7, ""), "NULL", "'"&$H7&"'"), "::varchar, ", IF(EXACT($B7, ""), "NULL", "'"&$B7&"'"), "::bigint);")) -> PERFORM "SchData-OLTP-Master"."Func_TblContactNumber_SET"(varSystemLoginSession::bigint, null::bigint, null::varchar, null::timestamptz, null::timestamptz, null::varchar, varInstitutionBranchID::bigint, varBaseCurrencyID::bigint, 223000000000002::bigint, '+62 896-8226-1128'::varchar, NULL::varchar, 'Bahyu Sanciko'::varchar, NULL::bigint);
C8: =IF(EXACT($B8, ""), "", IF((($B8 - MOD($B8, 1000000000000))/1000000000000)=25, CONCATENATE("Person - ", VLOOKUP($B8, [1]DataLookUp!$B$4:$C$2000, 2, FALSE)), IF((($B8 - MOD($B8, 1000000000000))/1000000000000)=124, CONCATENATE("Institution - ", VLOOKUP($B8, '[2]DataLookUp - InstitutionBranch'!$B$4:$C$2000, 2, FALSE)), ""))) | D8: 223000000000002 | E8: =IF(EXACT($D8, ""), "", VLOOKUP($D8, 'REF - ContactNumberType'!$B$4:$C$10, 2, FALSE)) -> Mobile Phone | F8: +62 838-7009-0020 | H8: Yusman W | J8: =J7 + IF(EXACT(K8, ""), 0, 1) -> 286000000000005 | K8: =IF(EXACT(F8, ""), "", CONCATENATE("PERFORM ""SchData-OLTP-Master"".""Func_TblContactNumber_SET""(varSystemLoginSession::bigint, null::bigint, null::varchar, null::timestamptz, null::timestamptz, null::varchar, varInstitutionBranchID::bigint, varBaseCurrencyID::bigint, ", IF(EXACT($D8, ""), "NULL", ""&$D8&""), "::bigint, ", IF(EXACT($F8, ""), "NULL", "'"&$F8&"'"), "::varchar, ", IF(EXACT($G8, ""), "NULL", "'"&$G8&"'"), "::varchar, ", IF(EXACT($H8, ""), "NULL", "'"&$H8&"'"), "::varchar, ", IF(EXACT($B8, ""), "NULL", "'"&$B8&"'"), "::bigint);")) -> PERFORM "SchData-OLTP-Master"."Func_TblContactNumber_SET"(varSystemLoginSession::bigint, null::bigint, null::varchar, null::timestamptz, null::timestamptz, null::varchar, varInstitutionBranchID::bigint, varBaseCurrencyID::bigint, 223000000000002::bigint, '+62 838-7009-0020'::varchar, NULL::varchar, 'Yusman W'::varchar, NULL::bigint);
B9: 25000000000047 | C9: =IF(EXACT($B9, ""), "", IF((($B9 - MOD($B9, 1000000000000))/1000000000000)=25, CONCATENATE("Person - ", VLOOKUP($B9, [1]DataLookUp!$B$4:$C$2000, 2, FALSE)), IF((($B9 - MOD($B9, 1000000000000))/1000000000000)=124, CONCATENATE("Institution - ", VLOOKUP($B9, '[2]DataLookUp - InstitutionBranch'!$B$4:$C$2000, 2, FALSE)), ""))) -> Person - Ardi | D9: 223000000000002 | E9: =IF(EXACT($D9, ""), "", VLOOKUP($D9, 'REF - ContactNumberType'!$B$4:$C$10, 2, FALSE)) -> Mobile Phone | F9: +62 812-9592-4499 | H9: Ardi | J9: =J8 + IF(EXACT(K9, ""), 0, 1) -> 286000000000006 | K9: =IF(EXACT(F9, ""), "", CONCATENATE("PERFORM ""SchData-OLTP-Master"".""Func_TblContactNumber_SET""(varSystemLoginSession::bigint, null::bigint, null::varchar, null::timestamptz, null::timestamptz, null::varchar, varInstitutionBranchID::bigint, varBaseCurrencyID::bigint, ", IF(EXACT($D9, ""), "NULL", ""&$D9&""), "::bigint, ", IF(EXACT($F9, ""), "NULL", "'"&$F9&"'"), "::varchar, ", IF(EXACT($G9, ""), "NULL", "'"&$G9&"'"), "::varchar, ", IF(EXACT($H9, ""), "NULL", "'"&$H9&"'"), "::varchar, ", IF(EXACT($B9, ""), "NULL", "'"&$B9&"'"), "::bigint);")) -> PERFORM "SchData-OLTP-Master"."Func_TblContactNumber_SET"(varSystemLoginSession::bigint, null::bigint, null::varchar, null::timestamptz, null::timestamptz, null::varchar, varInstitutionBranchID::bigint, varBaseCurrencyID::bigint, 223000000000002::bigint, '+62 812-9592-4499'::varchar, NULL::varchar, 'Ardi'::varchar, '25000000000047'::bigint);
B10: 25000000000141 | C10: =IF(EXACT($B10, ""), "", IF((($B10 - MOD($B10, 1000000000000))/1000000000000)=25, CONCATENATE("Person - ", VLOOKUP($B10, [1]DataLookUp!$B$4:$C$2000, 2, FALSE)), IF((($B10 - MOD($B10, 1000000000000))/1000000000000)=124, CONCATENATE("Institution - ", VLOOKUP($B10, '[2]DataLookUp - InstitutionBranch'!$B$4:$C$2000, 2, FALSE)), ""))) -> Person - Erwin Firmansyah | D10: 223000000000002 | E10: =IF(EXACT($D10, ""), "", VLOOKUP($D10, 'REF - ContactNumberType'!$B$4:$C$10, 2, FALSE)) -> Mobile Phone | F10: +62 857-2162-3338 | H10: Erwin Firmansyah | J10: =J9 + IF(EXACT(K10, ""), 0, 1) -> 286000000000007 | K10: =IF(EXACT(F10, ""), "", CONCATENATE("PERFORM ""SchData-OLTP-Master"".""Func_TblContactNumber_SET""(varSystemLoginSession::bigint, null::bigint, null::varchar, null::timestamptz, null::timestamptz, null::varchar, varInstitutionBranchID::bigint, varBaseCurrencyID::bigint, ", IF(EXACT($D10, ""), "NULL", ""&$D10&""), "::bigint, ", IF(EXACT($F10, ""), "NULL", "'"&$F10&"'"), "::varchar, ", IF(EXACT($G10, ""), "NULL", "'"&$G10&"'"), "::varchar, ", IF(EXACT($H10, ""), "NULL", "'"&$H10&"'"), "::varchar, ", IF(EXACT($B10, ""), "NULL", "'"&$B10&"'"), "::bigint);")) -> PERFORM "SchData-OLTP-Master"."Func_TblContactNumber_SET"(varSystemLoginSession::bigint, null::bigint, null::varchar, null::timestamptz, null::timestamptz, null::varchar, varInstitutionBranchID::bigint, varBaseCurrencyID::bigint, 223000000000002::bigint, '+62 857-2162-3338'::varchar, NULL::varchar, 'Erwin Firmansyah'::varchar, '25000000000141'::bigint);
B11: 25000000000328 | C11: =IF(EXACT($B11, ""), "", IF((($B11 - MOD($B11, 1000000000000))/1000000000000)=25, CONCATENATE("Person - ", VLOOKUP($B11, [1]DataLookUp!$B$4:$C$2000, 2, FALSE)), IF((($B11 - MOD($B11, 1000000000000))/1000000000000)=124, CONCATENATE("Institution - ", VLOOKUP($B11, '[2]DataLookUp - InstitutionBranch'!$B$4:$C$2000, 2, FALSE)), ""))) -> Person - Paryanto | D11: 223000000000002 | E11: =IF(EXACT($D11, ""), "", VLOOKUP($D11, 'REF - ContactNumberType'!$B$4:$C$10, 2, FALSE)) -> Mobile Phone | F11: +62 813-8428-4951 | H11: Paryanto | J11: =J10 + IF(EXACT(K11, ""), 0, 1) -> 286000000000008 | K11: =IF(EXACT(F11, ""), "", CONCATENATE("PERFORM ""SchData-OLTP-Master"".""Func_TblContactNumber_SET""(varSystemLoginSession::bigint, null::bigint, null::varchar, null::timestamptz, null::timestamptz, null::varchar, varInstitutionBranchID::bigint, varBaseCurrencyID::bigint, ", IF(EXACT($D11, ""), "NULL", ""&$D11&""), "::bigint, ", IF(EXACT($F11, ""), "NULL", "'"&$F11&"'"), "::varchar, ", IF(EXACT($G11, ""), "NULL", "'"&$G11&"'"), "::varchar, ", IF(EXACT($H11, ""), "NULL", "'"&$H11&"'"), "::varchar, ", IF(EXACT($B11, ""), "NULL", "'"&$B11&"'"), "::bigint);")) -> PERFORM "SchData-OLTP-Master"."Func_TblContactNumber_SET"(varSystemLoginSession::bigint, null::bigint, null::varchar, null::timestamptz, null::timestamptz, null::varchar, varInstitutionBranchID::bigint, varBaseCurrencyID::bigint, 223000000000002::bigint, '+62 813-8428-4951'::varchar, NULL::varchar, 'Paryanto'::varchar, '25000000000328'::bigint);
C12: =IF(EXACT($B12, ""), "", IF((($B12 - MOD($B12, 1000000000000))/1000000000000)=25, CONCATENATE("Person - ", VLOOKUP($B12, [1]DataLookUp!$B$4:$C$2000, 2, FALSE)), IF((($B12 - MOD($B12, 1000000000000))/1000000000000)=124, CONCATENATE("Institution - ", VLOOKUP($B12, '[2]DataLookUp - InstitutionBranch'!$B$4:$C$2000, 2, FALSE)), ""))) | D12: 223000000000002 | E12: =IF(EXACT($D12, ""), "", VLOOKUP($D12, 'REF - ContactNumberType'!$B$4:$C$10, 2, FALSE)) -> Mobile Phone | F12: +62 838-7375-2989 | H12: Vidhy Putri Kartika | J12: =J11 + IF(EXACT(K12, ""), 0, 1) -> 286000000000009 | K12: =IF(EXACT(F12, ""), "", CONCATENATE("PERFORM ""SchData-OLTP-Master"".""Func_TblContactNumber_SET""(varSystemLoginSession::bigint, null::bigint, null::varchar, null::timestamptz, null::timestamptz, null::varchar, varInstitutionBranchID::bigint, varBaseCurrencyID::bigint, ", IF(EXACT($D12, ""), "NULL", ""&$D12&""), "::bigint, ", IF(EXACT($F12, ""), "NULL", "'"&$F12&"'"), "::varchar, ", IF(EXACT($G12, ""), "NULL", "'"&$G12&"'"), "::varchar, ", IF(EXACT($H12, ""), "NULL", "'"&$H12&"'"), "::varchar, ", IF(EXACT($B12, ""), "NULL", "'"&$B12&"'"), "::bigint);")) -> PERFORM "SchData-OLTP-Master"."Func_TblContactNumber_SET"(varSystemLoginSession::bigint, null::bigint, null::varchar, null::timestamptz, null::timestamptz, null::varchar, varInstitutionBranchID::bigint, varBaseCurrencyID::bigint, 223000000000002::bigint, '+62 838-7375-2989'::varchar, NULL::varchar, 'Vidhy Putri Kartika'::varchar, NULL::bigint);
C13: =IF(EXACT($B13, ""), "", IF((($B13 - MOD($B13, 1000000000000))/1000000000000)=25, CONCATENATE("Person - ", VLOOKUP($B13, [1]DataLookUp!$B$4:$C$2000, 2, FALSE)), IF((($B13 - MOD($B13, 1000000000000))/1000000000000)=124, CONCATENATE("Institution - ", VLOOKUP($B13, '[2]DataLookUp - InstitutionBranch'!$B$4:$C$2000, 2, FALSE)), ""))) | D13: 223000000000002 | E13: =IF(EXACT($D13, ""), "", VLOOKUP($D13, 'REF - ContactNumberType'!$B$4:$C$10, 2, FALSE)) -> Mobile Phone | F13: +62 822-6092-0555 | H13: Rohendi | J13: =J12 + IF(EXACT(K13, ""), 0, 1) -> 286000000000010 | K13: =IF(EXACT(F13, ""), "", CONCATENATE("PERFORM ""SchData-OLTP-Master"".""Func_TblContactNumber_SET""(varSystemLoginSession::bigint, null::bigint, null::varchar, null::timestamptz, null::timestamptz, null::varchar, varInstitutionBranchID::bigint, varBaseCurrencyID::bigint, ", IF(EXACT($D13, ""), "NULL", ""&$D13&""), "::bigint, ", IF(EXACT($F13, ""), "NULL", "'"&$F13&"'"), "::varchar, ", IF(EXACT($G13, ""), "NULL", "'"&$G13&"'"), "::varchar, ", IF(EXACT($H13, ""), "NULL", "'"&$H13&"'"), "::varchar, ", IF(EXACT($B13, ""), "NULL", "'"&$B13&"'"), "::bigint);")) -> PERFORM "SchData-OLTP-Master"."Func_TblContactNumber_SET"(varSystemLoginSession::bigint, null::bigint, null::varchar, null::timestamptz, null::timestamptz, null::varchar, varInstitutionBranchID::bigint, varBaseCurrencyID::bigint, 223000000000002::bigint, '+62 822-6092-0555'::varchar, NULL::varchar, 'Rohendi'::varchar, NULL::bigint);
B14: 25000000000035 | C14: =IF(EXACT($B14, ""), "", IF((($B14 - MOD($B14, 1000000000000))/1000000000000)=25, CONCATENATE("Person - ", VLOOKUP($B14, [1]DataLookUp!$B$4:$C$2000, 2, FALSE)), IF((($B14 - MOD($B14, 1000000000000))/1000000000000)=124, CONCATENATE("Institution - ", VLOOKUP($B14, '[2]DataLookUp - InstitutionBranch'!$B$4:$C$2000, 2, FALSE)), ""))) -> Person - Anggit Ismiyanto | D14: 223000000000002 | E14: =IF(EXACT($D14, ""), "", VLOOKUP($D14, 'REF - ContactNumberType'!$B$4:$C$10, 2, FALSE)) -> Mobile Phone | F14: +62 822-5131-3575 | H14: Anggit Ismiyanto | J14: =J13 + IF(EXACT(K14, ""), 0, 1) -> 286000000000011 | K14: =IF(EXACT(F14, ""), "", CONCATENATE("PERFORM ""SchData-OLTP-Master"".""Func_TblContactNumber_SET""(varSystemLoginSession::bigint, null::bigint, null::varchar, null::timestamptz, null::timestamptz, null::varchar, varInstitutionBranchID::bigint, varBaseCurrencyID::bigint, ", IF(EXACT($D14, ""), "NULL", ""&$D14&""), "::bigint, ", IF(EXACT($F14, ""), "NULL", "'"&$F14&"'"), "::varchar, ", IF(EXACT($G14, ""), "NULL", "'"&$G14&"'"), "::varchar, ", IF(EXACT($H14, ""), "NULL", "'"&$H14&"'"), "::varchar, ", IF(EXACT($B14, ""), "NULL", "'"&$B14&"'"), "::bigint);")) -> PERFORM "SchData-OLTP-Master"."Func_TblContactNumber_SET"(varSystemLoginSession::bigint, null::bigint, null::varchar, null::timestamptz, null::timestamptz, null::varchar, varInstitutionBranchID::bigint, varBaseCurrencyID::bigint, 223000000000002::bigint, '+62 822-5131-3575'::varchar, NULL::varchar, 'Anggit Ismiyanto'::varchar, '25000000000035'::bigint);
B15: 25000000000156 | C15: =IF(EXACT($B15, ""), "", IF((($B15 - MOD($B15, 1000000000000))/1000000000000)=25, CONCATENATE("Person - ", VLOOKUP($B15, [1]DataLookUp!$B$4:$C$2000, 2, FALSE)), IF((($B15 - MOD($B15, 1000000000000))/1000000000000)=124, CONCATENATE("Institution - ", VLOOKUP($B15, '[2]DataLookUp - InstitutionBranch'!$B$4:$C$2000, 2, FALSE)), ""))) -> Person - Firman Akbar | D15: 223000000000002 | E15: =IF(EXACT($D15, ""), "", VLOOKUP($D15, 'REF - ContactNumberType'!$B$4:$C$10, 2, FALSE)) -> Mobile Phone | F15: +62 812-4519-2298 | H15: Firman Akbar | J15: =J14 + IF(EXACT(K15, ""), 0, 1) -> 286000000000012 | K15: =IF(EXACT(F15, ""), "", CONCATENATE("PERFORM ""SchData-OLTP-Master"".""Func_TblContactNumber_SET""(varSystemLoginSession::bigint, null::bigint, null::varchar, null::timestamptz, null::timestamptz, null::varchar, varInstitutionBranchID::bigint, varBaseCurrencyID::bigint, ", IF(EXACT($D15, ""), "NULL", ""&$D15&""), "::bigint, ", IF(EXACT($F15, ""), "NULL", "'"&$F15&"'"), "::varchar, ", IF(EXACT($G15, ""), "NULL", "'"&$G15&"'"), "::varchar, ", IF(EXACT($H15, ""), "NULL", "'"&$H15&"'"), "::varchar, ", IF(EXACT($B15, ""), "NULL", "'"&$B15&"'"), "::bigint);")) -> PERFORM "SchData-OLTP-Master"."Func_TblContactNumber_SET"(varSystemLoginSession::bigint, null::bigint, null::varchar, null::timestamptz, null::timestamptz, null::varchar, varInstitutionBranchID::bigint, varBaseCurrencyID::bigint, 223000000000002::bigint, '+62 812-4519-2298'::varchar, NULL::varchar, 'Firman Akbar'::varchar, '25000000000156'::bigint);
B16: 25000000000161 | C16: =IF(EXACT($B16, ""), "", IF((($B16 - MOD($B16, 1000000000000))/1000000000000)=25, CONCATENATE("Person - ", VLOOKUP($B16, [1]DataLookUp!$B$4:$C$2000, 2, FALSE)), IF((($B16 - MOD($B16, 1000000000000))/1000000000000)=124, CONCATENATE("Institution - ", VLOOKUP($B16, '[2]DataLookUp - InstitutionBranch'!$B$4:$C$2000, 2, FALSE)), ""))) -> Person - Fuad Febrian | D16: 223000000000002 | E16: =IF(EXACT($D16, ""), "", VLOOKUP($D16, 'REF - ContactNumberType'!$B$4:$C$10, 2, FALSE)) -> Mobile Phone | F16: +62 813-1422-8295 | H16: Fuad Febrian | J16: =J15 + IF(EXACT(K16, ""), 0, 1) -> 286000000000013 | K16: =IF(EXACT(F16, ""), "", CONCATENATE("PERFORM ""SchData-OLTP-Master"".""Func_TblContactNumber_SET""(varSystemLoginSession::bigint, null::bigint, null::varchar, null::timestamptz, null::timestamptz, null::varchar, varInstitutionBranchID::bigint, varBaseCurrencyID::bigint, ", IF(EXACT($D16, ""), "NULL", ""&$D16&""), "::bigint, ", IF(EXACT($F16, ""), "NULL", "'"&$F16&"'"), "::varchar, ", IF(EXACT($G16, ""), "NULL", "'"&$G16&"'"), "::varchar, ", IF(EXACT($H16, ""), "NULL", "'"&$H16&"'"), "::varchar, ", IF(EXACT($B16, ""), "NULL", "'"&$B16&"'"), "::bigint);")) -> PERFORM "SchData-OLTP-Master"."Func_TblContactNumber_SET"(varSystemLoginSession::bigint, null::bigint, null::varchar, null::timestamptz, null::timestamptz, null::varchar, varInstitutionBranchID::bigint, varBaseCurrencyID::bigint, 223000000000002::bigint, '+62 813-1422-8295'::varchar, NULL::varchar, 'Fuad Febrian'::varchar, '25000000000161'::bigint);
B17: 25000000000416 | C17: =IF(EXACT($B17, ""), "", IF((($B17 - MOD($B17, 1000000000000))/1000000000000)=25, CONCATENATE("Person - ", VLOOKUP($B17, [1]DataLookUp!$B$4:$C$2000, 2, FALSE)), IF((($B17 - MOD($B17, 1000000000000))/1000000000000)=124, CONCATENATE("Institution - ", VLOOKUP($B17, '[2]DataLookUp - InstitutionBranch'!$B$4:$C$2000, 2, FALSE)), ""))) -> Person - Sulih | D17: 223000000000002 | E17: =IF(EXACT($D17, ""), "", VLOOKUP($D17, 'REF - ContactNumberType'!$B$4:$C$10, 2, FALSE)) -> Mobile Phone | F17: +62 857-2881-8103 | H17: Sulih | J17: =J16 + IF(EXACT(K17, ""), 0, 1) -> 286000000000014 | K17: =IF(EXACT(F17, ""), "", CONCATENATE("PERFORM ""SchData-OLTP-Master"".""Func_TblContactNumber_SET""(varSystemLoginSession::bigint, null::bigint, null::varchar, null::timestamptz, null::timestamptz, null::varchar, varInstitutionBranchID::bigint, varBaseCurrencyID::bigint, ", IF(EXACT($D17, ""), "NULL", ""&$D17&""), "::bigint, ", IF(EXACT($F17, ""), "NULL", "'"&$F17&"'"), "::varchar, ", IF(EXACT($G17, ""), "NULL", "'"&$G17&"'"), "::varchar, ", IF(EXACT($H17, ""), "NULL", "'"&$H17&"'"), "::varchar, ", IF(EXACT($B17, ""), "NULL", "'"&$B17&"'"), "::bigint);")) -> PERFORM "SchData-OLTP-Master"."Func_TblContactNumber_SET"(varSystemLoginSession::bigint, null::bigint, null::varchar, null::timestamptz, null::timestamptz, null::varchar, varInstitutionBranchID::bigint, varBaseCurrencyID::bigint, 223000000000002::bigint, '+62 857-2881-8103'::varchar, NULL::varchar, 'Sulih'::varchar, '25000000000416'::bigint);
B18: 25000000000192 | C18: =IF(EXACT($B18, ""), "", IF((($B18 - MOD($B18, 1000000000000))/1000000000000)=25, CONCATENATE("Person - ", VLOOKUP($B18, [1]DataLookUp!$B$4:$C$2000, 2, FALSE)), IF((($B18 - MOD($B18, 1000000000000))/1000000000000)=124, CONCATENATE("Institution - ", VLOOKUP($B18, '[2]DataLookUp - InstitutionBranch'!$B$4:$C$2000, 2, FALSE)), ""))) -> Person - Heru Sugiri | D18: 223000000000002 | E18: =IF(EXACT($D18, ""), "", VLOOKUP($D18, 'REF - ContactNumberType'!$B$4:$C$10, 2, FALSE)) -> Mobile Phone | F18: +62 812-2491-0322 | H18: Heru Sugiri | J18: =J17 + IF(EXACT(K18, ""), 0, 1) -> 286000000000015 | K18: =IF(EXACT(F18, ""), "", CONCATENATE("PERFORM ""SchData-OLTP-Master"".""Func_TblContactNumber_SET""(varSystemLoginSession::bigint, null::bigint, null::varchar, null::timestamptz, null::timestamptz, null::varchar, varInstitutionBranchID::bigint, varBaseCurrencyID::bigint, ", IF(EXACT($D18, ""), "NULL", ""&$D18&""), "::bigint, ", IF(EXACT($F18, ""), "NULL", "'"&$F18&"'"), "::varchar, ", IF(EXACT($G18, ""), "NULL", "'"&$G18&"'"), "::varchar, ", IF(EXACT($H18, ""), "NULL", "'"&$H18&"'"), "::varchar, ", IF(EXACT($B18, ""), "NULL", "'"&$B18&"'"), "::bigint);")) -> PERFORM "SchData-OLTP-Master"."Func_TblContactNumber_SET"(varSystemLoginSession::bigint, null::bigint, null::varchar, null::timestamptz, null::timestamptz, null::varchar, varInstitutionBranchID::bigint, varBaseCurrencyID::bigint, 223000000000002::bigint, '+62 812-2491-0322'::varchar, NULL::varchar, 'Heru Sugiri'::varchar, '25000000000192'::bigint);
B19: 25000000000361 | C19: =IF(EXACT($B19, ""), "", IF((($B19 - MOD($B19, 1000000000000))/1000000000000)=25, CONCATENATE("Person - ", VLOOKUP($B19, [1]DataLookUp!$B$4:$C$2000, 2, FALSE)), IF((($B19 - MOD($B19, 1000000000000))/1000000000000)=124, CONCATENATE("Institution - ", VLOOKUP($B19, '[2]DataLookUp - InstitutionBranch'!$B$4:$C$2000, 2, FALSE)), ""))) -> Person - Rinaldi Asrin | D19: 223000000000002 | E19: =IF(EXACT($D19, ""), "", VLOOKUP($D19, 'REF - ContactNumberType'!$B$4:$C$10, 2, FALSE)) -> Mobile Phone | F19: +62 818-0691-9844 | H19: Rinaldi Asrin | J19: =J18 + IF(EXACT(K19, ""), 0, 1) -> 286000000000016 | K19: =IF(EXACT(F19, ""), "", CONCATENATE("PERFORM ""SchData-OLTP-Master"".""Func_TblContactNumber_SET""(varSystemLoginSession::bigint, null::bigint, null::varchar, null::timestamptz, null::timestamptz, null::varchar, varInstitutionBranchID::bigint, varBaseCurrencyID::bigint, ", IF(EXACT($D19, ""), "NULL", ""&$D19&""), "::bigint, ", IF(EXACT($F19, ""), "NULL", "'"&$F19&"'"), "::varchar, ", IF(EXACT($G19, ""), "NULL", "'"&$G19&"'"), "::varchar, ", IF(EXACT($H19, ""), "NULL", "'"&$H19&"'"), "::varchar, ", IF(EXACT($B19, ""), "NULL", "'"&$B19&"'"), "::bigint);")) -> PERFORM "SchData-OLTP-Master"."Func_TblContactNumber_SET"(varSystemLoginSession::bigint, null::bigint, null::varchar, null::timestamptz, null::timestamptz, null::varchar, varInstitutionBranchID::bigint, varBaseCurrencyID::bigint, 223000000000002::bigint, '+62 818-0691-9844'::varchar, NULL::varchar, 'Rinaldi Asrin'::varchar, '25000000000361'::bigint);
B20: 25000000000337 | C20: =IF(EXACT($B20, ""), "", IF((($B20 - MOD($B20, 1000000000000))/1000000000000)=25, CONCATENATE("Person - ", VLOOKUP($B20, [1]DataLookUp!$B$4:$C$2000, 2, FALSE)), IF((($B20 - MOD($B20, 1000000000000))/1000000000000)=124, CONCATENATE("Institution - ", VLOOKUP($B20, '[2]DataLookUp - InstitutionBranch'!$B$4:$C$2000, 2, FALSE)), ""))) -> Person - Rafi Firman Saputra | D20: 223000000000002 | E20: =IF(EXACT($D20, ""), "", VLOOKUP($D20, 'REF - ContactNumberType'!$B$4:$C$10, 2, FALSE)) -> Mobile Phone | F20: +62 857-6021-1355 | H20: Rafi Firman Saputra | J20: =J19 + IF(EXACT(K20, ""), 0, 1) -> 286000000000017 | K20: =IF(EXACT(F20, ""), "", CONCATENATE("PERFORM ""SchData-OLTP-Master"".""Func_TblContactNumber_SET""(varSystemLoginSession::bigint, null::bigint, null::varchar, null::timestamptz, null::timestamptz, null::varchar, varInstitutionBranchID::bigint, varBaseCurrencyID::bigint, ", IF(EXACT($D20, ""), "NULL", ""&$D20&""), "::bigint, ", IF(EXACT($F20, ""), "NULL", "'"&$F20&"'"), "::varchar, ", IF(EXACT($G20, ""), "NULL", "'"&$G20&"'"), "::varchar, ", IF(EXACT($H20, ""), "NULL", "'"&$H20&"'"), "::varchar, ", IF(EXACT($B20, ""), "NULL", "'"&$B20&"'"), "::bigint);")) -> PERFORM "SchData-OLTP-Master"."Func_TblContactNumber_SET"(varSystemLoginSession::bigint, null::bigint, null::varchar, null::timestamptz, null::timestamptz, null::varchar, varInstitutionBranchID::bigint, varBaseCurrencyID::bigint, 223000000000002::bigint, '+62 857-6021-1355'::varchar, NULL::varchar, 'Rafi Firman Saputra'::varchar, '25000000000337'::bigint);
B21: 25000000000333 | C21: =IF(EXACT($B21, ""), "", IF((($B21 - MOD($B21, 1000000000000))/1000000000000)=25, CONCATENATE("Person - ", VLOOKUP($B21, [1]DataLookUp!$B$4:$C$2000, 2, FALSE)), IF((($B21 - MOD($B21, 1000000000000))/1000000000000)=124, CONCATENATE("Institution - ", VLOOKUP($B21, '[2]DataLookUp - InstitutionBranch'!$B$4:$C$2000, 2, FALSE)), ""))) -> Person - Putra Perdana Tirtomoyo | D21: 223000000000002 | E21: =IF(EXACT($D21, ""), "", VLOOKUP($D21, 'REF - ContactNumberType'!$B$4:$C$10, 2, FALSE)) -> Mobile Phone | F21: +62 812-8884-4266 | H21: Putra Perdana Tirtomoyo | J21: =J20 + IF(EXACT(K21, ""), 0, 1) -> 286000000000018 | K21: =IF(EXACT(F21, ""), "", CONCATENATE("PERFORM ""SchData-OLTP-Master"".""Func_TblContactNumber_SET""(varSystemLoginSession::bigint, null::bigint, null::varchar, null::timestamptz, null::timestamptz, null::varchar, varInstitutionBranchID::bigint, varBaseCurrencyID::bigint, ", IF(EXACT($D21, ""), "NULL", ""&$D21&""), "::bigint, ", IF(EXACT($F21, ""), "NULL", "'"&$F21&"'"), "::varchar, ", IF(EXACT($G21, ""), "NULL", "'"&$G21&"'"), "::varchar, ", IF(EXACT($H21, ""), "NULL", "'"&$H21&"'"), "::varchar, ", IF(EXACT($B21, ""), "NULL", "'"&$B21&"'"), "::bigint);")) -> PERFORM "SchData-OLTP-Master"."Func_TblContactNumber_SET"(varSystemLoginSession::bigint, null::bigint, null::varchar, null::timestamptz, null::timestamptz, null::varchar, varInstitutionBranchID::bigint, varBaseCurrencyID::bigint, 223000000000002::bigint, '+62 812-8884-4266'::varchar, NULL::varchar, 'Putra Perdana Tirtomoyo'::varchar, '25000000000333'::bigint);
B22: 25000000000365 | C22: =IF(EXACT($B22, ""), "", IF((($B22 - MOD($B22, 1000000000000))/1000000000000)=25, CONCATENATE("Person - ", VLOOKUP($B22, [1]DataLookUp!$B$4:$C$2000, 2, FALSE)), IF((($B22 - MOD($B22, 1000000000000))/1000000000000)=124, CONCATENATE("Institution - ", VLOOKUP($B22, '[2]DataLookUp - InstitutionBranch'!$B$4:$C$2000, 2, FALSE)), ""))) -> Person - Rizak Tri Septian | D22: 223000000000002 | E22: =IF(EXACT($D22, ""), "", VLOOKUP($D22, 'REF - ContactNumberType'!$B$4:$C$10, 2, FALSE)) -> Mobile Phone | F22: +62 856-7124-030 | H22: Rizak Tri Septian | J22: =J21 + IF(EXACT(K22, ""), 0, 1) -> 286000000000019 | K22: =IF(EXACT(F22, ""), "", CONCATENATE("PERFORM ""SchData-OLTP-Master"".""Func_TblContactNumber_SET""(varSystemLoginSession::bigint, null::bigint, null::varchar, null::timestamptz, null::timestamptz, null::varchar, varInstitutionBranchID::bigint, varBaseCurrencyID::bigint, ", IF(EXACT($D22, ""), "NULL", ""&$D22&""), "::bigint, ", IF(EXACT($F22, ""), "NULL", "'"&$F22&"'"), "::varchar, ", IF(EXACT($G22, ""), "NULL", "'"&$G22&"'"), "::varchar, ", IF(EXACT($H22, ""), "NULL", "'"&$H22&"'"), "::varchar, ", IF(EXACT($B22, ""), "NULL", "'"&$B22&"'"), "::bigint);")) -> PERFORM "SchData-OLTP-Master"."Func_TblContactNumber_SET"(varSystemLoginSession::bigint, null::bigint, null::varchar, null::timestamptz, null::timestamptz, null::varchar, varInstitutionBranchID::bigint, varBaseCurrencyID::bigint, 223000000000002::bigint, '+62 856-7124-030'::varchar, NULL::varchar, 'Rizak Tri Septian'::varchar, '25000000000365'::bigint);
B23: 25000000000500 | C23: =IF(EXACT($B23, ""), "", IF((($B23 - MOD($B23, 1000000000000))/1000000000000)=25, CONCATENATE("Person - ", VLOOKUP($B23, [1]DataLookUp!$B$4:$C$2000, 2, FALSE)), IF((($B23 - MOD($B23, 1000000000000))/1000000000000)=124, CONCATENATE("Institution - ", VLOOKUP($B23, '[2]DataLookUp - InstitutionBranch'!$B$4:$C$2000, 2, FALSE)), ""))) -> Person - Zam Roji | D23: 223000000000002 | E23: =IF(EXACT($D23, ""), "", VLOOKUP($D23, 'REF - ContactNumberType'!$B$4:$C$10, 2, FALSE)) -> Mobile Phone | F23: +62 821-1395-1375 | H23: Zam Roji | J23: =J22 + IF(EXACT(K23, ""), 0, 1) -> 286000000000020 | K23: =IF(EXACT(F23, ""), "", CONCATENATE("PERFORM ""SchData-OLTP-Master"".""Func_TblContactNumber_SET""(varSystemLoginSession::bigint, null::bigint, null::varchar, null::timestamptz, null::timestamptz, null::varchar, varInstitutionBranchID::bigint, varBaseCurrencyID::bigint, ", IF(EXACT($D23, ""), "NULL", ""&$D23&""), "::bigint, ", IF(EXACT($F23, ""), "NULL", "'"&$F23&"'"), "::varchar, ", IF(EXACT($G23, ""), "NULL", "'"&$G23&"'"), "::varchar, ", IF(EXACT($H23, ""), "NULL", "'"&$H23&"'"), "::varchar, ", IF(EXACT($B23, ""), "NULL", "'"&$B23&"'"), "::bigint);")) -> PERFORM "SchData-OLTP-Master"."Func_TblContactNumber_SET"(varSystemLoginSession::bigint, null::bigint, null::varchar, null::timestamptz, null::timestamptz, null::varchar, varInstitutionBranchID::bigint, varBaseCurrencyID::bigint, 223000000000002::bigint, '+62 821-1395-1375'::varchar, NULL::varchar, 'Zam Roji'::varchar, '25000000000500'::bigint);
B24: 25000000000348 | C24: =IF(EXACT($B24, ""), "", IF((($B24 - MOD($B24, 1000000000000))/1000000000000)=25, CONCATENATE("Person - ", VLOOKUP($B24, [1]DataLookUp!$B$4:$C$2000, 2, FALSE)), IF((($B24 - MOD($B24, 1000000000000))/1000000000000)=124, CONCATENATE("Institution - ", VLOOKUP($B24, '[2]DataLookUp - InstitutionBranch'!$B$4:$C$2000, 2, FALSE)), ""))) -> Person - Rendy Prananta Purba | D24: 223000000000002 | E24: =IF(EXACT($D24, ""), "", VLOOKUP($D24, 'REF - ContactNumberType'!$B$4:$C$10, 2, FALSE)) -> Mobile Phone | F24: +62 852-9500-0042 | H24: Rendy Prananta Purba | J24: =J23 + IF(EXACT(K24, ""), 0, 1) -> 286000000000021 | K24: =IF(EXACT(F24, ""), "", CONCATENATE("PERFORM ""SchData-OLTP-Master"".""Func_TblContactNumber_SET""(varSystemLoginSession::bigint, null::bigint, null::varchar, null::timestamptz, null::timestamptz, null::varchar, varInstitutionBranchID::bigint, varBaseCurrencyID::bigint, ", IF(EXACT($D24, ""), "NULL", ""&$D24&""), "::bigint, ", IF(EXACT($F24, ""), "NULL", "'"&$F24&"'"), "::varchar, ", IF(EXACT($G24, ""), "NULL", "'"&$G24&"'"), "::varchar, ", IF(EXACT($H24, ""), "NULL", "'"&$H24&"'"), "::varchar, ", IF(EXACT($B24, ""), "NULL", "'"&$B24&"'"), "::bigint);")) -> PERFORM "SchData-OLTP-Master"."Func_TblContactNumber_SET"(varSystemLoginSession::bigint, null::bigint, null::varchar, null::timestamptz, null::timestamptz, null::varchar, varInstitutionBranchID::bigint, varBaseCurrencyID::bigint, 223000000000002::bigint, '+62 852-9500-0042'::varchar, NULL::varchar, 'Rendy Prananta Purba'::varchar, '25000000000348'::bigint);
B25: 25000000000323 | C25: =IF(EXACT($B25, ""), "", IF((($B25 - MOD($B25, 1000000000000))/1000000000000)=25, CONCATENATE("Person - ", VLOOKUP($B25, [1]DataLookUp!$B$4:$C$2000, 2, FALSE)), IF((($B25 - MOD($B25, 1000000000000))/1000000000000)=124, CONCATENATE("Institution - ", VLOOKUP($B25, '[2]DataLookUp - InstitutionBranch'!$B$4:$C$2000, 2, FALSE)), ""))) -> Person - Otong Bustori | D25: 223000000000002 | E25: =IF(EXACT($D25, ""), "", VLOOKUP($D25, 'REF - ContactNumberType'!$B$4:$C$10, 2, FALSE)) -> Mobile Phone | F25: +62 812-1021-3789 | H25: Otong Bustori | J25: =J24 + IF(EXACT(K25, ""), 0, 1) -> 286000000000022 | K25: =IF(EXACT(F25, ""), "", CONCATENATE("PERFORM ""SchData-OLTP-Master"".""Func_TblContactNumber_SET""(varSystemLoginSession::bigint, null::bigint, null::varchar, null::timestamptz, null::timestamptz, null::varchar, varInstitutionBranchID::bigint, varBaseCurrencyID::bigint, ", IF(EXACT($D25, ""), "NULL", ""&$D25&""), "::bigint, ", IF(EXACT($F25, ""), "NULL", "'"&$F25&"'"), "::varchar, ", IF(EXACT($G25, ""), "NULL", "'"&$G25&"'"), "::varchar, ", IF(EXACT($H25, ""), "NULL", "'"&$H25&"'"), "::varchar, ", IF(EXACT($B25, ""), "NULL", "'"&$B25&"'"), "::bigint);")) -> PERFORM "SchData-OLTP-Master"."Func_TblContactNumber_SET"(varSystemLoginSession::bigint, null::bigint, null::varchar, null::timestamptz, null::timestamptz, null::varchar, varInstitutionBranchID::bigint, varBaseCurrencyID::bigint, 223000000000002::bigint, '+62 812-1021-3789'::varchar, NULL::varchar, 'Otong Bustori'::varchar, '25000000000323'::bigint);
... B28: 25000000000187 | C28: =IF(EXACT($B28, ""), "", IF((($B28 - MOD($B28, 1000000000000))/1000000000000)=25, CONCATENATE("Person - ", VLOOKUP($B28, [1]DataLookUp!$B$4:$C$2000, 2, FALSE)), IF((($B28 - MOD($B28, 1000000000000))/1000000000000)=124, CONCATENATE("Institution - ", VLOOKUP($B28, '[2]DataLookUp - InstitutionBranch'!$B$4:$C$2000, 2, FALSE)), ""))) -> Person - Herlin Juli Asri | D28: 223000000000002 | E28: =IF(EXACT($D28, ""), "", VLOOKUP($D28, 'REF - ContactNumberType'!$B$4:$C$10, 2, FALSE)) -> Mobile Phone | F28: +62 813-1920-7116 | H28: Herlin Juli Asri | J28: =J27 + IF(EXACT(K28, ""), 0, 1) -> 286000000000025 | K28: =IF(EXACT(F28, ""), "", CONCATENATE("PERFORM ""SchData-OLTP-Master"".""Func_TblContactNumber_SET""(varSystemLoginSession::bigint, null::bigint, null::varchar, null::timestamptz, null::timestamptz, null::varchar, varInstitutionBranchID::bigint, varBaseCurrencyID::bigint, ", IF(EXACT($D28, ""), "NULL", ""&$D28&""), "::bigint, ", IF(EXACT($F28, ""), "NULL", "'"&$F28&"'"), "::varchar, ", IF(EXACT($G28, ""), "NULL", "'"&$G28&"'"), "::varchar, ", IF(EXACT($H28, ""), "NULL", "'"&$H28&"'"), "::varchar, ", IF(EXACT($B28, ""), "NULL", "'"&$B28&"'"), "::bigint);")) -> PERFORM "SchData-OLTP-Master"."Func_TblContactNumber_SET"(varSystemLoginSession::bigint, null::bigint, null::varchar, null::timestamptz, null::timestamptz, null::varchar, varInstitutionBranchID::bigint, varBaseCurrencyID::bigint, 223000000000002::bigint, '+62 813-1920-7116'::varchar, NULL::varchar, 'Herlin Juli Asri'::varchar, '25000000000187'::bigint);
C29: =IF(EXACT($B29, ""), "", IF((($B29 - MOD($B29, 1000000000000))/1000000000000)=25, CONCATENATE("Person - ", VLOOKUP($B29, [1]DataLookUp!$B$4:$C$2000, 2, FALSE)), IF((($B29 - MOD($B29, 1000000000000))/1000000000000)=124, CONCATENATE("Institution - ", VLOOKUP($B29, '[2]DataLookUp - InstitutionBranch'!$B$4:$C$2000, 2, FALSE)), ""))) | D29: 223000000000002 | E29: =IF(EXACT($D29, ""), "", VLOOKUP($D29, 'REF - ContactNumberType'!$B$4:$C$10, 2, FALSE)) -> Mobile Phone | F29: +62 811-9568-886 | H29: Sherly Tamira Happy | J29: =J28 + IF(EXACT(K29, ""), 0, 1) -> 286000000000026 | K29: =IF(EXACT(F29, ""), "", CONCATENATE("PERFORM ""SchData-OLTP-Master"".""Func_TblContactNumber_SET""(varSystemLoginSession::bigint, null::bigint, null::varchar, null::timestamptz, null::timestamptz, null::varchar, varInstitutionBranchID::bigint, varBaseCurrencyID::bigint, ", IF(EXACT($D29, ""), "NULL", ""&$D29&""), "::bigint, ", IF(EXACT($F29, ""), "NULL", "'"&$F29&"'"), "::varchar, ", IF(EXACT($G29, ""), "NULL", "'"&$G29&"'"), "::varchar, ", IF(EXACT($H29, ""), "NULL", "'"&$H29&"'"), "::varchar, ", IF(EXACT($B29, ""), "NULL", "'"&$B29&"'"), "::bigint);")) -> PERFORM "SchData-OLTP-Master"."Func_TblContactNumber_SET"(varSystemLoginSession::bigint, null::bigint, null::varchar, null::timestamptz, null::timestamptz, null::varchar, varInstitutionBranchID::bigint, varBaseCurrencyID::bigint, 223000000000002::bigint, '+62 811-9568-886'::varchar, NULL::varchar, 'Sherly Tamira Happy'::varchar, NULL::bigint);
C30: =IF(EXACT($B30, ""), "", IF((($B30 - MOD($B30, 1000000000000))/1000000000000)=25, CONCATENATE("Person - ", VLOOKUP($B30, [1]DataLookUp!$B$4:$C$2000, 2, FALSE)), IF((($B30 - MOD($B30, 1000000000000))/1000000000000)=124, CONCATENATE("Institution - ", VLOOKUP($B30, '[2]DataLookUp - InstitutionBranch'!$B$4:$C$2000, 2, FALSE)), ""))) | D30: 223000000000002 | E30: =IF(EXACT($D30, ""), "", VLOOKUP($D30, 'REF - ContactNumberType'!$B$4:$C$10, 2, FALSE)) -> Mobile Phone | F30: +62 812-8223-0665 | H30: Sherly Tamira Happy | J30: =J29 + IF(EXACT(K30, ""), 0, 1) -> 286000000000027 | K30: =IF(EXACT(F30, ""), "", CONCATENATE("PERFORM ""SchData-OLTP-Master"".""Func_TblContactNumber_SET""(varSystemLoginSession::bigint, null::bigint, null::varchar, null::timestamptz, null::timestamptz, null::varchar, varInstitutionBranchID::bigint, varBaseCurrencyID::bigint, ", IF(EXACT($D30, ""), "NULL", ""&$D30&""), "::bigint, ", IF(EXACT($F30, ""), "NULL", "'"&$F30&"'"), "::varchar, ", IF(EXACT($G30, ""), "NULL", "'"&$G30&"'"), "::varchar, ", IF(EXACT($H30, ""), "NULL", "'"&$H30&"'"), "::varchar, ", IF(EXACT($B30, ""), "NULL", "'"&$B30&"'"), "::bigint);")) -> PERFORM "SchData-OLTP-Master"."Func_TblContactNumber_SET"(varSystemLoginSession::bigint, null::bigint, null::varchar, null::timestamptz, null::timestamptz, null::varchar, varInstitutionBranchID::bigint, varBaseCurrencyID::bigint, 223000000000002::bigint, '+62 812-8223-0665'::varchar, NULL::varchar, 'Sherly Tamira Happy'::varchar, NULL::bigint);
B31: 25000000000297 | C31: =IF(EXACT($B31, ""), "", IF((($B31 - MOD($B31, 1000000000000))/1000000000000)=25, CONCATENATE("Person - ", VLOOKUP($B31, [1]DataLookUp!$B$4:$C$2000, 2, FALSE)), IF((($B31 - MOD($B31, 1000000000000))/1000000000000)=124, CONCATENATE("Institution - ", VLOOKUP($B31, '[2]DataLookUp - InstitutionBranch'!$B$4:$C$2000, 2, FALSE)), ""))) -> Person - Muhammad Khadafy | D31: 223000000000002 | E31: =IF(EXACT($D31, ""), "", VLOOKUP($D31, 'REF - ContactNumberType'!$B$4:$C$10, 2, FALSE)) -> Mobile Phone | F31: +62 812-8744-1774 | H31: Muhammad Khadafy | J31: =J30 + IF(EXACT(K31, ""), 0, 1) -> 286000000000028 | K31: =IF(EXACT(F31, ""), "", CONCATENATE("PERFORM ""SchData-OLTP-Master"".""Func_TblContactNumber_SET""(varSystemLoginSession::bigint, null::bigint, null::varchar, null::timestamptz, null::timestamptz, null::varchar, varInstitutionBranchID::bigint, varBaseCurrencyID::bigint, ", IF(EXACT($D31, ""), "NULL", ""&$D31&""), "::bigint, ", IF(EXACT($F31, ""), "NULL", "'"&$F31&"'"), "::varchar, ", IF(EXACT($G31, ""), "NULL", "'"&$G31&"'"), "::varchar, ", IF(EXACT($H31, ""), "NULL", "'"&$H31&"'"), "::varchar, ", IF(EXACT($B31, ""), "NULL", "'"&$B31&"'"), "::bigint);")) -> PERFORM "SchData-OLTP-Master"."Func_TblContactNumber_SET"(varSystemLoginSession::bigint, null::bigint, null::varchar, null::timestamptz, null::timestamptz, null::varchar, varInstitutionBranchID::bigint, varBaseCurrencyID::bigint, 223000000000002::bigint, '+62 812-8744-1774'::varchar, NULL::varchar, 'Muhammad Khadafy'::varchar, '25000000000297'::bigint);
C32: =IF(EXACT($B32, ""), "", IF((($B32 - MOD($B32, 1000000000000))/1000000000000)=25, CONCATENATE("Person - ", VLOOKUP($B32, [1]DataLookUp!$B$4:$C$2000, 2, FALSE)), IF((($B32 - MOD($B32, 1000000000000))/1000000000000)=124, CONCATENATE("Institution - ", VLOOKUP($B32, '[2]DataLookUp - InstitutionBranch'!$B$4:$C$2000, 2, FALSE)), ""))) | D32: 223000000000002 | E32: =IF(EXACT($D32, ""), "", VLOOKUP($D32, 'REF - ContactNumberType'!$B$4:$C$10, 2, FALSE)) -> Mobile Phone | F32: +62 857-7048-1711 | H32: Hernita Dwi Cahyani Putri | J32: =J31 + IF(EXACT(K32, ""), 0, 1) -> 286000000000029 | K32: =IF(EXACT(F32, ""), "", CONCATENATE("PERFORM ""SchData-OLTP-Master"".""Func_TblContactNumber_SET""(varSystemLoginSession::bigint, null::bigint, null::varchar, null::timestamptz, null::timestamptz, null::varchar, varInstitutionBranchID::bigint, varBaseCurrencyID::bigint, ", IF(EXACT($D32, ""), "NULL", ""&$D32&""), "::bigint, ", IF(EXACT($F32, ""), "NULL", "'"&$F32&"'"), "::varchar, ", IF(EXACT($G32, ""), "NULL", "'"&$G32&"'"), "::varchar, ", IF(EXACT($H32, ""), "NULL", "'"&$H32&"'"), "::varchar, ", IF(EXACT($B32, ""), "NULL", "'"&$B32&"'"), "::bigint);")) -> PERFORM "SchData-OLTP-Master"."Func_TblContactNumber_SET"(varSystemLoginSession::bigint, null::bigint, null::varchar, null::timestamptz, null::timestamptz, null::varchar, varInstitutionBranchID::bigint, varBaseCurrencyID::bigint, 223000000000002::bigint, '+62 857-7048-1711'::varchar, NULL::varchar, 'Hernita Dwi Cahyani Putri'::varchar, NULL::bigint);
B33: 25000000000029 | C33: =IF(EXACT($B33, ""), "", IF((($B33 - MOD($B33, 1000000000000))/1000000000000)=25, CONCATENATE("Person - ", VLOOKUP($B33, [1]DataLookUp!$B$4:$C$2000, 2, FALSE)), IF((($B33 - MOD($B33, 1000000000000))/1000000000000)=124, CONCATENATE("Institution - ", VLOOKUP($B33, '[2]DataLookUp - InstitutionBranch'!$B$4:$C$2000, 2, FALSE)), ""))) -> Person - Amir Sofyan Hadi | D33: 223000000000002 | E33: =IF(EXACT($D33, ""), "", VLOOKUP($D33, 'REF - ContactNumberType'!$B$4:$C$10, 2, FALSE)) -> Mobile Phone | F33: +62 813-1690-6639 | H33: Amir Sofyan Hadi | J33: =J32 + IF(EXACT(K33, ""), 0, 1) -> 286000000000030 | K33: =IF(EXACT(F33, ""), "", CONCATENATE("PERFORM ""SchData-OLTP-Master"".""Func_TblContactNumber_SET""(varSystemLoginSession::bigint, null::bigint, null::varchar, null::timestamptz, null::timestamptz, null::varchar, varInstitutionBranchID::bigint, varBaseCurrencyID::bigint, ", IF(EXACT($D33, ""), "NULL", ""&$D33&""), "::bigint, ", IF(EXACT($F33, ""), "NULL", "'"&$F33&"'"), "::varchar, ", IF(EXACT($G33, ""), "NULL", "'"&$G33&"'"), "::varchar, ", IF(EXACT($H33, ""), "NULL", "'"&$H33&"'"), "::varchar, ", IF(EXACT($B33, ""), "NULL", "'"&$B33&"'"), "::bigint);")) -> PERFORM "SchData-OLTP-Master"."Func_TblContactNumber_SET"(varSystemLoginSession::bigint, null::bigint, null::varchar, null::timestamptz, null::timestamptz, null::varchar, varInstitutionBranchID::bigint, varBaseCurrencyID::bigint, 223000000000002::bigint, '+62 813-1690-6639'::varchar, NULL::varchar, 'Amir Sofyan Hadi'::varchar, '25000000000029'::bigint);
B34: 25000000000071 | C34: =IF(EXACT($B34, ""), "", IF((($B34 - MOD($B34, 1000000000000))/1000000000000)=25, CONCATENATE("Person - ", VLOOKUP($B34, [1]DataLookUp!$B$4:$C$2000, 2, FALSE)), IF((($B34 - MOD($B34, 1000000000000))/1000000000000)=124, CONCATENATE("Institution - ", VLOOKUP($B34, '[2]DataLookUp - InstitutionBranch'!$B$4:$C$2000, 2, FALSE)), ""))) -> Person - Bani Mustazeni | D34: 223000000000002 | E34: =IF(EXACT($D34, ""), "", VLOOKUP($D34, 'REF - ContactNumberType'!$B$4:$C$10, 2, FALSE)) -> Mobile Phone | F34: +62 857-1519-9050 | H34: Bani Mustazeni | J34: =J33 + IF(EXACT(K34, ""), 0, 1) -> 286000000000031 | K34: =IF(EXACT(F34, ""), "", CONCATENATE("PERFORM ""SchData-OLTP-Master"".""Func_TblContactNumber_SET""(varSystemLoginSession::bigint, null::bigint, null::varchar, null::timestamptz, null::timestamptz, null::varchar, varInstitutionBranchID::bigint, varBaseCurrencyID::bigint, ", IF(EXACT($D34, ""), "NULL", ""&$D34&""), "::bigint, ", IF(EXACT($F34, ""), "NULL", "'"&$F34&"'"), "::varchar, ", IF(EXACT($G34, ""), "NULL", "'"&$G34&"'"), "::varchar, ", IF(EXACT($H34, ""), "NULL", "'"&$H34&"'"), "::varchar, ", IF(EXACT($B34, ""), "NULL", "'"&$B34&"'"), "::bigint);")) -> PERFORM "SchData-OLTP-Master"."Func_TblContactNumber_SET"(varSystemLoginSession::bigint, null::bigint, null::varchar, null::timestamptz, null::timestamptz, null::varchar, varInstitutionBranchID::bigint, varBaseCurrencyID::bigint, 223000000000002::bigint, '+62 857-1519-9050'::varchar, NULL::varchar, 'Bani Mustazeni'::varchar, '25000000000071'::bigint);
C35: =IF(EXACT($B35, ""), "", IF((($B35 - MOD($B35, 1000000000000))/1000000000000)=25, CONCATENATE("Person - ", VLOOKUP($B35, [1]DataLookUp!$B$4:$C$2000, 2, FALSE)), IF((($B35 - MOD($B35, 1000000000000))/1000000000000)=124, CONCATENATE("Institution - ", VLOOKUP($B35, '[2]DataLookUp - InstitutionBranch'!$B$4:$C$2000, 2, FALSE)), ""))) | D35: 223000000000002 | E35: =IF(EXACT($D35, ""), "", VLOOKUP($D35, 'REF - ContactNumberType'!$B$4:$C$10, 2, FALSE)) -> Mobile Phone | F35: +62 859-4561-9900 | H35: Eko Kurniawan | J35: =J34 + IF(EXACT(K35, ""), 0, 1) -> 286000000000032 | K35: =IF(EXACT(F35, ""), "", CONCATENATE("PERFORM ""SchData-OLTP-Master"".""Func_TblContactNumber_SET""(varSystemLoginSession::bigint, null::bigint, null::varchar, null::timestamptz, null::timestamptz, null::varchar, varInstitutionBranchID::bigint, varBaseCurrencyID::bigint, ", IF(EXACT($D35, ""), "NULL", ""&$D35&""), "::bigint, ", IF(EXACT($F35, ""), "NULL", "'"&$F35&"'"), "::varchar, ", IF(EXACT($G35, ""), "NULL", "'"&$G35&"'"), "::varchar, ", IF(EXACT($H35, ""), "NULL", "'"&$H35&"'"), "::varchar, ", IF(EXACT($B35, ""), "NULL", "'"&$B35&"'"), "::bigint);")) -> PERFORM "SchData-OLTP-Master"."Func_TblContactNumber_SET"(varSystemLoginSession::bigint, null::bigint, null::varchar, null::timestamptz, null::timestamptz, null::varchar, varInstitutionBranchID::bigint, varBaseCurrencyID::bigint, 223000000000002::bigint, '+62 859-4561-9900'::varchar, NULL::varchar, 'Eko Kurniawan'::varchar, NULL::bigint);
B36: 25000000000145 | C36: =IF(EXACT($B36, ""), "", IF((($B36 - MOD($B36, 1000000000000))/1000000000000)=25, CONCATENATE("Person - ", VLOOKUP($B36, [1]DataLookUp!$B$4:$C$2000, 2, FALSE)), IF((($B36 - MOD($B36, 1000000000000))/1000000000000)=124, CONCATENATE("Institution - ", VLOOKUP($B36, '[2]DataLookUp - InstitutionBranch'!$B$4:$C$2000, 2, FALSE)), ""))) -> Person - Fani Dwi Astutik | D36: 223000000000002 | E36: =IF(EXACT($D36, ""), "", VLOOKUP($D36, 'REF - ContactNumberType'!$B$4:$C$10, 2, FALSE)) -> Mobile Phone | F36: +62 812-9902-0267 | H36: Fani Dwi Astutik | J36: =J35 + IF(EXACT(K36, ""), 0, 1) -> 286000000000033 | K36: =IF(EXACT(F36, ""), "", CONCATENATE("PERFORM ""SchData-OLTP-Master"".""Func_TblContactNumber_SET""(varSystemLoginSession::bigint, null::bigint, null::varchar, null::timestamptz, null::timestamptz, null::varchar, varInstitutionBranchID::bigint, varBaseCurrencyID::bigint, ", IF(EXACT($D36, ""), "NULL", ""&$D36&""), "::bigint, ", IF(EXACT($F36, ""), "NULL", "'"&$F36&"'"), "::varchar, ", IF(EXACT($G36, ""), "NULL", "'"&$G36&"'"), "::varchar, ", IF(EXACT($H36, ""), "NULL", "'"&$H36&"'"), "::varchar, ", IF(EXACT($B36, ""), "NULL", "'"&$B36&"'"), "::bigint);")) -> PERFORM "SchData-OLTP-Master"."Func_TblContactNumber_SET"(varSystemLoginSession::bigint, null::bigint, null::varchar, null::timestamptz, null::timestamptz, null::varchar, varInstitutionBranchID::bigint, varBaseCurrencyID::bigint, 223000000000002::bigint, '+62 812-9902-0267'::varchar, NULL::varchar, 'Fani Dwi Astutik'::varchar, '25000000000145'::bigint);
C37: =IF(EXACT($B37, ""), "", IF((($B37 - MOD($B37, 1000000000000))/1000000000000)=25, CONCATENATE("Person - ", VLOOKUP($B37, [1]DataLookUp!$B$4:$C$2000, 2, FALSE)), IF((($B37 - MOD($B37, 1000000000000))/1000000000000)=124, CONCATENATE("Institution - ", VLOOKUP($B37, '[2]DataLookUp - InstitutionBranch'!$B$4:$C$2000, 2, FALSE)), ""))) | D37: 223000000000002 | E37: =IF(EXACT($D37, ""), "", VLOOKUP($D37, 'REF - ContactNumberType'!$B$4:$C$10, 2, FALSE)) -> Mobile Phone | F37: +62 856-4156-8410 | H37: Dony Setiyawan | J37: =J36 + IF(EXACT(K37, ""), 0, 1) -> 286000000000034 | K37: =IF(EXACT(F37, ""), "", CONCATENATE("PERFORM ""SchData-OLTP-Master"".""Func_TblContactNumber_SET""(varSystemLoginSession::bigint, null::bigint, null::varchar, null::timestamptz, null::timestamptz, null::varchar, varInstitutionBranchID::bigint, varBaseCurrencyID::bigint, ", IF(EXACT($D37, ""), "NULL", ""&$D37&""), "::bigint, ", IF(EXACT($F37, ""), "NULL", "'"&$F37&"'"), "::varchar, ", IF(EXACT($G37, ""), "NULL", "'"&$G37&"'"), "::varchar, ", IF(EXACT($H37, ""), "NULL", "'"&$H37&"'"), "::varchar, ", IF(EXACT($B37, ""), "NULL", "'"&$B37&"'"), "::bigint);")) -> PERFORM "SchData-OLTP-Master"."Func_TblContactNumber_SET"(varSystemLoginSession::bigint, null::bigint, null::varchar, null::timestamptz, null::timestamptz, null::varchar, varInstitutionBranchID::bigint, varBaseCurrencyID::bigint, 223000000000002::bigint, '+62 856-4156-8410'::varchar, NULL::varchar, 'Dony Setiyawan'::varchar, NULL::bigint);
C38: =IF(EXACT($B38, ""), "", IF((($B38 - MOD($B38, 1000000000000))/1000000000000)=25, CONCATENATE("Person - ", VLOOKUP($B38, [1]DataLookUp!$B$4:$C$2000, 2, FALSE)), IF((($B38 - MOD($B38, 1000000000000))/1000000000000)=124, CONCATENATE("Institution - ", VLOOKUP($B38, '[2]DataLookUp - InstitutionBranch'!$B$4:$C$2000, 2, FALSE)), ""))) | D38: 223000000000002 | E38: =IF(EXACT($D38, ""), "", VLOOKUP($D38, 'REF - ContactNumberType'!$B$4:$C$10, 2, FALSE)) -> Mobile Phone | F38: +62 813-6291-9395 | H38: M Ari Ardizah Nasution | J38: =J37 + IF(EXACT(K38, ""), 0, 1) -> 286000000000035 | K38: =IF(EXACT(F38, ""), "", CONCATENATE("PERFORM ""SchData-OLTP-Master"".""Func_TblContactNumber_SET""(varSystemLoginSession::bigint, null::bigint, null::varchar, null::timestamptz, null::timestamptz, null::varchar, varInstitutionBranchID::bigint, varBaseCurrencyID::bigint, ", IF(EXACT($D38, ""), "NULL", ""&$D38&""), "::bigint, ", IF(EXACT($F38, ""), "NULL", "'"&$F38&"'"), "::varchar, ", IF(EXACT($G38, ""), "NULL", "'"&$G38&"'"), "::varchar, ", IF(EXACT($H38, ""), "NULL", "'"&$H38&"'"), "::varchar, ", IF(EXACT($B38, ""), "NULL", "'"&$B38&"'"), "::bigint);")) -> PERFORM "SchData-OLTP-Master"."Func_TblContactNumber_SET"(varSystemLoginSession::bigint, null::bigint, null::varchar, null::timestamptz, null::timestamptz, null::varchar, varInstitutionBranchID::bigint, varBaseCurrencyID::bigint, 223000000000002::bigint, '+62 813-6291-9395'::varchar, NULL::varchar, 'M Ari Ardizah Nasution'::varchar, NULL::bigint);
B39: 25000000000277 | C39: =IF(EXACT($B39, ""), "", IF((($B39 - MOD($B39, 1000000000000))/1000000000000)=25, CONCATENATE("Person - ", VLOOKUP($B39, [1]DataLookUp!$B$4:$C$2000, 2, FALSE)), IF((($B39 - MOD($B39, 1000000000000))/1000000000000)=124, CONCATENATE("Institution - ", VLOOKUP($B39, '[2]DataLookUp - InstitutionBranch'!$B$4:$C$2000, 2, FALSE)), ""))) -> Person - Martimbul Rahman | D39: 223000000000002 | E39: =IF(EXACT($D39, ""), "", VLOOKUP($D39, 'REF - ContactNumberType'!$B$4:$C$10, 2, FALSE)) -> Mobile Phone | F39: +62 813-6193-0878 | H39: Martimbul Rahman | J39: =J38 + IF(EXACT(K39, ""), 0, 1) -> 286000000000036 | K39: =IF(EXACT(F39, ""), "", CONCATENATE("PERFORM ""SchData-OLTP-Master"".""Func_TblContactNumber_SET""(varSystemLoginSession::bigint, null::bigint, null::varchar, null::timestamptz, null::timestamptz, null::varchar, varInstitutionBranchID::bigint, varBaseCurrencyID::bigint, ", IF(EXACT($D39, ""), "NULL", ""&$D39&""), "::bigint, ", IF(EXACT($F39, ""), "NULL", "'"&$F39&"'"), "::varchar, ", IF(EXACT($G39, ""), "NULL", "'"&$G39&"'"), "::varchar, ", IF(EXACT($H39, ""), "NULL", "'"&$H39&"'"), "::varchar, ", IF(EXACT($B39, ""), "NULL", "'"&$B39&"'"), "::bigint);")) -> PERFORM "SchData-OLTP-Master"."Func_TblContactNumber_SET"(varSystemLoginSession::bigint, null::bigint, null::varchar, null::timestamptz, null::timestamptz, null::varchar, varInstitutionBranchID::bigint, varBaseCurrencyID::bigint, 223000000000002::bigint, '+62 813-6193-0878'::varchar, NULL::varchar, 'Martimbul Rahman'::varchar, '25000000000277'::bigint);
B40: 25000000000498 | C40: =IF(EXACT($B40, ""), "", IF((($B40 - MOD($B40, 1000000000000))/1000000000000)=25, CONCATENATE("Person - ", VLOOKUP($B40, [1]DataLookUp!$B$4:$C$2000, 2, FALSE)), IF((($B40 - MOD($B40, 1000000000000))/1000000000000)=124, CONCATENATE("Institution - ", VLOOKUP($B40, '[2]DataLookUp - InstitutionBranch'!$B$4:$C$2000, 2, FALSE)), ""))) -> Person - Zaire Dite Biscaya | D40: 223000000000002 | E40: =IF(EXACT($D40, ""), "", VLOOKUP($D40, 'REF - ContactNumberType'!$B$4:$C$10, 2, FALSE)) -> Mobile Phone | F40: +62 812-9102-5349 | H40: Zaire Biscaya Dite | J40: =J39 + IF(EXACT(K40, ""), 0, 1) -> 286000000000037 | K40: =IF(EXACT(F40, ""), "", CONCATENATE("PERFORM ""SchData-OLTP-Master"".""Func_TblContactNumber_SET""(varSystemLoginSession::bigint, null::bigint, null::varchar, null::timestamptz, null::timestamptz, null::varchar, varInstitutionBranchID::bigint, varBaseCurrencyID::bigint, ", IF(EXACT($D40, ""), "NULL", ""&$D40&""), "::bigint, ", IF(EXACT($F40, ""), "NULL", "'"&$F40&"'"), "::varchar, ", IF(EXACT($G40, ""), "NULL", "'"&$G40&"'"), "::varchar, ", IF(EXACT($H40, ""), "NULL", "'"&$H40&"'"), "::varchar, ", IF(EXACT($B40, ""), "NULL", "'"&$B40&"'"), "::bigint);")) -> PERFORM "SchData-OLTP-Master"."Func_TblContactNumber_SET"(varSystemLoginSession::bigint, null::bigint, null::varchar, null::timestamptz, null::timestamptz, null::varchar, varInstitutionBranchID::bigint, varBaseCurrencyID::bigint, 223000000000002::bigint, '+62 812-9102-5349'::varchar, NULL::varchar, 'Zaire Biscaya Dite'::varchar, '25000000000498'::bigint);
B41: 25000000000205 | C41: =IF(EXACT($B41, ""), "", IF((($B41 - MOD($B41, 1000000000000))/1000000000000)=25, CONCATENATE("Person - ", VLOOKUP($B41, [1]DataLookUp!$B$4:$C$2000, 2, FALSE)), IF((($B41 - MOD($B41, 1000000000000))/1000000000000)=124, CONCATENATE("Institution - ", VLOOKUP($B41, '[2]DataLookUp - InstitutionBranch'!$B$4:$C$2000, 2, FALSE)), ""))) -> Person - Imam Basuki | D41: 223000000000002 | E41: =IF(EXACT($D41, ""), "", VLOOKUP($D41, 'REF - ContactNumberType'!$B$4:$C$10, 2, FALSE)) -> Mobile Phone | F41: +62 813-1818-7318 | H41: Imam Basuki | J41: =J40 + IF(EXACT(K41, ""), 0, 1) -> 286000000000038 | K41: =IF(EXACT(F41, ""), "", CONCATENATE("PERFORM ""SchData-OLTP-Master"".""Func_TblContactNumber_SET""(varSystemLoginSession::bigint, null::bigint, null::varchar, null::timestamptz, null::timestamptz, null::varchar, varInstitutionBranchID::bigint, varBaseCurrencyID::bigint, ", IF(EXACT($D41, ""), "NULL", ""&$D41&""), "::bigint, ", IF(EXACT($F41, ""), "NULL", "'"&$F41&"'"), "::varchar, ", IF(EXACT($G41, ""), "NULL", "'"&$G41&"'"), "::varchar, ", IF(EXACT($H41, ""), "NULL", "'"&$H41&"'"), "::varchar, ", IF(EXACT($B41, ""), "NULL", "'"&$B41&"'"), "::bigint);")) -> PERFORM "SchData-OLTP-Master"."Func_TblContactNumber_SET"(varSystemLoginSession::bigint, null::bigint, null::varchar, null::timestamptz, null::timestamptz, null::varchar, varInstitutionBranchID::bigint, varBaseCurrencyID::bigint, 223000000000002::bigint, '+62 813-1818-7318'::varchar, NULL::varchar, 'Imam Basuki'::varchar, '25000000000205'::bigint);
B42: 25000000000511 | C42: =IF(EXACT($B42, ""), "", IF((($B42 - MOD($B42, 1000000000000))/1000000000000)=25, CONCATENATE("Person - ", VLOOKUP($B42, [1]DataLookUp!$B$4:$C$2000, 2, FALSE)), IF((($B42 - MOD($B42, 1000000000000))/1000000000000)=124, CONCATENATE("Institution - ", VLOOKUP($B42, '[2]DataLookUp - InstitutionBranch'!$B$4:$C$2000, 2, FALSE)), ""))) -> Person - Wisnu Andra Isdianto | D42: 223000000000002 | E42: =IF(EXACT($D42, ""), "", VLOOKUP($D42, 'REF - ContactNumberType'!$B$4:$C$10, 2, FALSE)) -> Mobile Phone | F42: +62 877-8419-0978 | H42: Wisnu Andra Isdianto | J42: =J41 + IF(EXACT(K42, ""), 0, 1) -> 286000000000039 | K42: =IF(EXACT(F42, ""), "", CONCATENATE("PERFORM ""SchData-OLTP-Master"".""Func_TblContactNumber_SET""(varSystemLoginSession::bigint, null::bigint, null::varchar, null::timestamptz, null::timestamptz, null::varchar, varInstitutionBranchID::bigint, varBaseCurrencyID::bigint, ", IF(EXACT($D42, ""), "NULL", ""&$D42&""), "::bigint, ", IF(EXACT($F42, ""), "NULL", "'"&$F42&"'"), "::varchar, ", IF(EXACT($G42, ""), "NULL", "'"&$G42&"'"), "::varchar, ", IF(EXACT($H42, ""), "NULL", "'"&$H42&"'"), "::varchar, ", IF(EXACT($B42, ""), "NULL", "'"&$B42&"'"), "::bigint);")) -> PERFORM "SchData-OLTP-Master"."Func_TblContactNumber_SET"(varSystemLoginSession::bigint, null::bigint, null::varchar, null::timestamptz, null::timestamptz, null::varchar, varInstitutionBranchID::bigint, varBaseCurrencyID::bigint, 223000000000002::bigint, '+62 877-8419-0978'::varchar, NULL::varchar, 'Wisnu Andra Isdianto'::varchar, '25000000000511'::bigint);
