Workbook

Sheet RAW EDITED 3 Years
A1: sup_kode | B1: statussupplier | C1: sup_nama | D1: alamat | E1: jenisupplier | F1: subjenisupplier | G1: ket | H1: tlp | I1: email | J1: fax | K1: ket_ASLI | L1: alamat2 | M1: master_kota | N1: master_propinsi | O1: negara | P1: orang | Q1: finance | R1: direktur | S1: hp | T1: namabank | U1: rekbank | V1: reknamabank | W1: tahunoperasi | X1: tahunberdiri | Y1: cabang | Z1: skala | AA1: daftarcabang | AB1: karyawan | AC1: aktif | AD1: npwp | AE1: pkp | AF1: tgl_pkp | AG1: bi_code | AH1: bank_branch | AI1: bank_city
A2: VDR3827 | B2: CV | C2: Alfa Link Mandiri | D2: WJV2+3WV, Lamokato, Kec. Kolaka, Kabupaten Kolaka, Sulawesi Tenggara | E2: Supplier Material Civil | F2: Tools | G2: Untuk Tools dan APD di Kolaka | H2: 081299000537 | I2: - | J2: - | M2: KABUPATEN KOLAKA | N2: SULAWESI TENGGARA | O2: Indonesia | P2: Fransisca | Q2: - | R2: - | T2: Bank Mandiri | U2: 1620002256992 | V2: CV Alfalink Mandiri | W2: - | X2: - | Y2: - | Z2: National | AA2: - | AB2: - | AC2: Y | AE2: f | AF2: 0000-00-00
A3: VDR3823 | B3: CV | C3: Alodia Makmur Abadi | D3: Jalan Garuda No 03 Lamokato , Kolaka | E3: Jasa Kesehatan | F3: Rumah Sakit | G3: untuk MCU | H3: 081356000488 | I3: - | J3: - | M3: KABUPATEN KOLAKA | N3: SULAWESI TENGGARA | O3: Indonesia | P3: Alodia | Q3: - | R3: - | T3: Bank Mandiri | U3: 1620033008800 | V3: Kilinik Alodia | W3: - | X3: - | Y3: - | Z3: National | AA3: - | AB3: - | AC3: Y | AD3: 45.578.379.2-815.000 | AE3: t | AF3: 0000-00-00
A4: VDR3828 | B4: CV | C4: Anugerah Karya Magantha | D4: Jalan Camp Security No. 4 , Sorowako , Luwu Timur | E4: Supplier | F4: Tools Kerja | G4: Pembelian APD di area Site | H4: 08114129780 | I4: anugrah_kry@yahoo.com | J4: - | L4: Jalan Poros Kolaka, Desa Samaenre Kecamatan Wolo | M4: KABUPATEN LUWU TIMUR | N4: SULAWESI SELATAN | O4: Indonesia | P4: Leonardo Sampetoding | Q4: - | R4: - | T4: - | U4: - | V4: - | W4: - | X4: - | Y4: - | Z4: National | AA4: - | AB4: - | AC4: Y | AD4: 02.031.309.4-803.000 | AE4: t | AF4: 0000-00-00
A5: VDR3970 | B5: CV | C5: Artha Jaya Mulya | D5: Jalan Melon No. 265 A RT 001 RW 004 Tanah Merah, Siak Hulu, Kab. Kampar - Riau | E5: Supplier Material Civil | F5: Tanah, Sirtu, Makadam | H5: +62 813-7833-4428 | M5: KABUPATEN KAMPAR | N5: RIAU | O5: Indonesia | P5: Sugito | Q5: - | R5: Sugito | T5: Bank Mandiri | U5: 108 00 2487725 1 | V5: CV Artha Jaya Mulya | Z5: National | AC5: Y | AE5: f | AF5: 0000-00-00
A6: VDR3939 | B6: CV | C6: Borneo Geotec Engginering | D6: Jl Menteng X No 18 RT 003 RW 008 Kel.Menteng Kec. Jekan Raya Palangkaraya Kalimantan tengah | E6: Soil Test | F6: Soil Test | H6: +62 812-5641-5655 | M6: Palangkara Raya | N6: Kalimantan Tengah | O6: Indonesia | P6: Atikah Harahap / Ikhwan | Q6: - | R6: - | T6: Kalimantan Tengah | U6: 1000030000032705 | V6: CV Borneo Geotec Engginering | Z6: National | AC6: Y | AD6: 706175718711000 | AE6: f | AF6: 0000-00-00
A7: VDR3784 | B7: CV | C7: Cipta Aneka Sarana | D7: Jl. M.T. Haryono, Bende, Kec. Kendari, Kota Kendari, Sulawesi Tenggara 93117 | E7: Supplier | F7: Bahan Bangunan | G7: Untuk pembelian bahan Bangunan, tools , alat kerja project Kolaka | H7: 04013192000 | I7: maxcell_dpt@yahoo.co.id | L7: https://www.maxcell.co.id | M7: KOTA KENDARI | N7: SULAWESI TENGGARA | O7: Indonesia | P7: Maxcell Online Service | Q7: - | R7: - | T7: Mandiri | U7: 1620000878888 | V7: CV Cipta Aneka Sarana | W7: - | X7: - | Y7: - | Z7: National | AA7: - | AB7: - | AC7: Y | AD7: 03.242.269.3.811.000 | AE7: t | AF7: 0000-00-00
A8: VDR3696 | B8: CV | C8: CV. Didi Dan Darwis Survey | D8: Komplek Sukamenak Blok Q-90, Kel. Sukamenak Kec. Margahayu Kab. Bandung Prov. Jawa Barat. | E8: Supplier | F8: Survey | G8: Toko Alat2 surveyor dibandung | H8: 082116167001 / +62 821-2990-0025 | I8: dndsurvey90@gmail.com | J8: - | L8: - | M8: KABUPATEN BANDUNG | N8: JAWA BARAT | O8: INDONESIA | P8: DnD Survey Bandung | Q8: - | R8: - | T8: BCA | U8: 8105588948 | V8: Novi Dahlia | W8: - | X8: - | Y8: - | Z8: National | AB8: - | AC8: Y | AE8: f | AF8: 0000-00-00
A9: VDR3516 | B9: CV | C9: CV. Surya Pandawa Nusa | D9: Jl. Utan Kayu Raya No. 104 D Utan Kayu Utara, Matraman Jakarat Timur | E9: Transportation | F9: Trucking | G9: Tranpsorter bisa cover giro pengiriman pole ACPD ke sanana maluku utara | H9: 081314800075 | I9: - | J9: - | L9: - | M9: KOTA JAKARTA TIMUR | N9: DKI JAKARTA | O9: INDONESIA | P9: Juana/Erwin | Q9: - | R9: - | T9: MANDIRI | U9: 0060050150170 | V9: CV. SURYA PANDAWA NUSA | W9: - | X9: - | Y9: - | Z9: National | AA9: - | AB9: - | AC9: Y | AD9: 84.355.656.4-002.000 | AE9: f | AF9: 0000-00-00
A10: VDR3971 | B10: CV | C10: Direct Linus Logistik | D10: Jl. Mawar Dalam Tengah No. 33, Desa/Kelurahan Lagoa, Kec. Koja, Kota Adm. Jakarta Utara, Provinsi DKI Jakarta, Kode Pos: 14270 | E10: Transportation | F10: Trucking | G10: Vendor Transportasi untuk ke Siak (CDD, Fuso, Tronton) | H10: +62 852-1832-5540 | M10: KOTA JAKARTA UTARA | N10: DKI JAKARTA | O10: Indonesia | P10: Nur Excellog | Q10: - | R10: Siti Masitoh | T10: Bank Mandiri | U10: 156 001 930 9493 | V10: Siti Masitoh | Z10: National | AC10: Y | AE10: f | AF10: 0000-00-00
A11: VDR4046 | B11: CV | C11: Edi Jaya Bangunan | D11: Jl. A. yani km. 21, Kel. Pangkalan Durin, Kec. Pangkalan Lada, Kab. Kotawaringin Barat Pmp. Kalimantan Tengah 92.612.879.4-7 I 3.000 | E11: Supplier | F11: Terpal plastik | G11: Terpal | H11: 0813 4970 3982 / | I11: ejbpbun@gmail.com | M11: KABUPATEN KOTAWARINGIN BARAT | N11: KALIMANTAN TENGAH | O11: Indonesia | P11: Edi Nuryanto | Q11: - | R11: - | T11: Bank Mandiri | U11: 159 000 798 6655 | V11: Edy Nuryanto | Z11: National | AC11: Y | AE11: f | AF11: 0000-00-00
A12: VDR3982 | B12: CV | C12: Elang Sega | D12: Jl. Pasanah Gg. Rusa No. 4, Kel. Sidorejo, Kec. Arut Selatan, Kab. Kotawaringin Barat, Prov. Kalimantan Tengah | E12: Supplier Material Civil | F12: Tanah, Sirtu, Makadam | G12: Supplier pasir beton untuk Pangkalan Bun CV. Elang Sega (Priyo Handoko) | H12: 0813 4924 6427 | M12: KABUPATEN KOTAWARINGIN BARAT | N12: KALIMANTAN TENGAH | O12: Indonesia | P12: Priyo Handoko | Q12: - | R12: - | T12: Bank Kalteng | U12: 4000103001616 | V12: Elang Sega | Z12: National | AC12: Y | AE12: f | AF12: 0000-00-00
A13: VDR3773 | B13: CV | C13: Gallazka Teknik | D13: JL. SYECH MUBAROK PERUMAHAN TRIRAKSA VILLAGE 2 BLOK P9 NO 38 KP LENGSIR | E13: Alat dan mesin teknik | F13: Aneka Mesin Diesel, Dynamo & G | G13: Untuk Perbaikan Mesin | H13: 083891165959 | I13: gallazkateknik@gmail.com | J13: - | M13: KABUPATEN TANGERANG | N13: BANTEN | O13: Indonesia | P13: Wartim | Q13: - | R13: Wartim | T13: - | U13: - | V13: - | W13: - | X13: - | Y13: - | Z13: National | AA13: - | AB13: - | AC13: Y | AD13: 62.240.566.0-451.000 | AE13: t | AF13: 0000-00-00
A14: VDR4106 | B14: CV | C14: Ghania Mandiri | D14: Perum. Taman Walet GWA.6 No. 28 RT004/013, Sindang Sari, Pasar Kemis, Kab. Tangerang - Banten | E14: Workshop | F14: Fabrikasi | G14: Pembuatan Name Plate | H14: +62 812-1934-5800 | M14: KABUPATEN TANGERANG | N14: BANTEN | O14: Indonesia | P14: Rahmat Rasyid | Q14: - | R14: - | T14: Bank BNI | U14: 0617 459 363 | V14: CV Ghania Mandiri | Z14: National | AC14: Y | AE14: f | AF14: 0000-00-00
A15: VDR3783 | B15: CV | C15: Istana Gemilang Mandiri | D15: Jalan Haluoleo, BTN Margahayu Regency Blok P Mokau Kambu, Kendari | E15: mobil | F15: Rental Mobil | G15: Untuk kendaraan Project di Kolala | H15: 082254016520 | I15: - | J15: - | M15: KOTA KENDARI | N15: SULAWESI TENGGARA | O15: Indonesia | P15: Hairul Amirudin | Q15: Hairul Amirudin | R15: Hairul Amirudin | T15: - | U15: - | V15: - | W15: - | X15: - | Y15: - | Z15: National | AA15: - | AB15: - | AC15: Y | AD15: 60.862.963.0-811.000 | AE15: t | AF15: 0000-00-00
A16: VDR2001 | B16: CV | C16: Jember Elektrindo Gemilang | D16: Pasar Kenari Lama Lantai Dasar Unit AKS No.184, JL Salemba Raya â€“ Jakarta Pusat | E16: Supplier Material ME | F16: Alat elektrical | G16: Cable AAACS dan AAAC, Peralatan grounding. Berubah nama, sebelumnya Toko Ground Rod | H16: 021-3158970 /0852 15866584 | I16: owner.grd@gmail.com | M16: KOTA JAKARTA PUSAT | N16: DKI JAKARTA | O16: Indonesia | P16: Sigit | Q16: - | R16: - | T16: BRI | U16: 002101020767565 | V16: CV Jember Elektrindo Gemilang | Z16: National | AC16: Y | AE16: f | AF16: 0000-00-00
A17: VDR4023 | B17: CV | C17: Karya Baru | D17: Jl. Utama Pasir Panjang, Kel. Pasir Panjang, Kec. Arut Selatan, Kab. Kotawaringin Barat, Kalimantan Tengah | E17: Supplier Material Civil | F17: Tanah, Sirtu, Makadam | G17: Kuari Pasir, split, gravel | H17: +62 812-5640-4650 / 053223788 | M17: KABUPATEN KOTAWARINGIN BARAT | N17: KALIMANTAN TENGAH | O17: Indonesia | P17: Ninum | Q17: - | R17: - | T17: Bank Mandiri | U17: 159 00 0245500 3 | V17: CV Karya Baru | Z17: National | AC17: Y | AE17: f | AF17: 0000-00-00
A18: VDR3990 | B18: CV | C18: Kawan Inti Jaya | D18: Jl. Peta Selatan Ruko Duta Indah Alpha Blok B.23 Kel. Kalideres Kec. Kalideres, Kota Jakarta Barat. Provinisi DKI Jakarta | E18: Workshop | F18: Alat, Mesin dan suku cadang | G18: Vendor Perbaikan alat bar bending | H18: +62 852-1771-8198 / 021 223 016 73 | M18: KOTA JAKARTA BARAT | N18: DKI JAKARTA | O18: Indonesia | P18: Karyadi | Q18: - | R18: - | T18: Bank BCA | U18: 866-040-8330 | V18: CV. Kawan Inti Jaya | Z18: National | AC18: Y | AE18: f | AF18: 0000-00-00
A19: VDR3803 | B19: CV | C19: Laba Mandiri Lapaopao | D19: Dusun III Polewali Belakang Kantor Desa Lapao | E19: Bahan Bakar | F19: Bahan Bakar Minyak | G19: Untuk suplay BBM kendaraan operational dan mesin | H19: 082187739295 | I19: - | J19: - | L19: RT 001 RW 003 | M19: KABUPATEN KOLAKA | N19: SULAWESI TENGGARA | O19: Indonesia | P19: Musdalifah | Q19: - | R19: Musdalifah | T19: Bank Rakyat Indonesia | U19: 493801020255535 | V19: Musdalifah | W19: - | X19: - | Y19: - | Z19: National | AA19: - | AB19: - | AC19: Y | AD19: 96.960.780.3-815.000 | AE19: f | AF19: 0000-00-00
A20: VDR1025 | B20: CV | C20: Mitra Bengawan Trans | D20: Jl. Ahmad Yani, Desa Bumiharjo RT/RW 009/005 Kec. Kumai Kab. Kotawaringin Barat Prov. Kalimantan Tengah | E20: Rental | F20: Alat Berat | G20: Sewa Forklift | H20: +62 811-5230-808 | K20: Supplier Rolling Door | M20: KABUPATEN KOTAWARINGIN BARAT | N20: KALIMANTAN TENGAH | O20: Indonesia | P20: Annisa | Q20: - | R20: - | S20: "" | T20: Bank Mandiri | U20: 159-00-0075222-9 | V20: Abdullah Nurrahman | Z20: National | AC20: Y | AE20: f | AF20: 0000-00-00
A21: VDR3787 | B21: CV | C21: Mulia Jaya Steel | D21: Jl.H Banawula Sin Apoy, Kendari, Sulawesi Tenggara | E21: Supplier Material Civil | F21: Bahan Bangunan | G21: Penyediaan beton bersertifikat, pipa bulat dll | H21: 081341905779 / 08114099189 | I21: - | J21: - | L21: - | M21: KOTA KENDARI | N21: SULAWESI TENGGARA | O21: Indonesia | P21: - | Q21: - | R21: - | T21: Bank Mandiri | U21: 1620007090909 | V21: Mulia Jaya Steel | W21: - | X21: - | Y21: - | Z21: National | AA21: - | AB21: - | AC21: Y | AE21: f | AF21: 0000-00-00
A22: VDR3866 | B22: CV | C22: Muzima | D22: Perumahan Cikande Permai Blok O, 4 No 23 , Cikande Permai , Serang 42186 | E22: Manufactur | F22: Steel | G22: Fabrikasi Angkur custom | H22: 081295709029 | I22: - | J22: - | M22: KOTA SERANG | N22: BANTEN | O22: Indonesia | P22: Rosid | Q22: - | R22: - | T22: Bank Central Asia | U22: 4921189723 | V22: CV Muzima | W22: - | X22: - | Y22: - | Z22: National | AA22: - | AB22: - | AC22: Y | AE22: f | AF22: 0000-00-00
A23: VDR4179 | B23: CV | C23: Punokawan | D23: Jl Borobudur Utara XV no 11, Manyaran | E23: Rental | F23: Alat Berat | G23: Rental Alat di Semarang untuk pengambilan Tower TE di Gardu Induk Ungaran, untuk kebutuhan proyek SUTT Indorama | H23: 024-76634217 | I23: punokawan_smrg@yahoo.co.id | J23: - | M23: KOTA SEMARANG | N23: JAWA TENGAH | O23: Indonesia | P23: Heri | Q23: - | R23: Budi | T23: BCA | U23: 8035497087 | V23: Dian Permana Sari | W23: - | X23: - | Z23: National | AC23: Y | AE23: f | AF23: 0000-00-00
A24: VDR4045 | B24: CV | C24: Putra Bintang Api | D24: Jl. Utama Pasir Panjang, Kel. Pasir Panjang, Kec. Arut Selatan, Kab. Kotawaringin Barat, Prov. Kalimantan Tengah | E24: Supplier | F24: Tools Kerja | G24: Selang, Tangki Air, Pompa Air | H24: 053224793 | M24: KABUPATEN KOTAWARINGIN BARAT | N24: KALIMANTAN TENGAH | O24: Indonesia | P24: Kian Fung | Q24: - | R24: - | T24: Bank BRI | U24: 0282-01-000302-561 | V24: CV Putra Bintang Api | Z24: National | AC24: Y | AE24: f | AF24: 0000-00-00
A25: VDR4166 | B25: CV | C25: Sangiang Teknik Perkasa | D25: Jl Industri No 27, Babakan cikao | E25: Rental | F25: Alat Berat | G25: Rental Alat Berat Purwakarta | H25: 081222631116 | I25: - | J25: - | M25: KABUPATEN PURWAKARTA | N25: JAWA BARAT | O25: Indonesia | P25: Ishak | Q25: - | R25: - | T25: BNI | U25: 0912901272 | V25: CV Sangiang Teknik Perkasa | W25: - | X25: - | Z25: National | AC25: Y | AE25: f | AF25: 0000-00-00
A26: VDR2981 | B26: CV | C26: Siliwangi jaya | D26: JL. Raya Bojongsoang No.224 (depan SPBU bojongsoang) RT001/007 Buah Batu | E26: Workshop | F26: Alat, Mesin dan suku cadang | G26: Borepile | H26: +62 821-1979-9987 | M26: KOTA BANDUNG | N26: JAWA BARAT | O26: Indonesia | P26: Ira | Q26: Ira | R26: 0 | T26: BCA | U26: 2803000409 | V26: Rachmat Sudrajat | Z26: National | AC26: Y | AE26: f | AF26: 0000-00-00
A27: VDR3912 | B27: CV | C27: Sukses Indo Pratama | D27: Rukan Exclusive Mediterania I No. 10 PIK, Kamal Muara, Penjaringan, Jakarta Utara | E27: Supplier Material ME | F27: Alat elektrical | G27: Distributor kabel merk Federal | H27: +62 811-1909-4011 | M27: Jakarta Utara | N27: DKI Jakarta | O27: Indonesia | P27: Eswin Gozali | Q27: - | R27: - | T27: Bank BCA | U27: 012-791-2029 | V27: CV. Sukses Indo Pratama | Z27: National | AC27: Y | AE27: f | AF27: 0000-00-00
A28: VDR4039 | B28: CV | C28: SUmber Rezeki | D28: Jalan Enggano Nomor 75, Kel. Tanjung Priok, Kec. Tanjung Priok, Kota Adm. Jakarta Utara, Provinsi DKI Jakarta | E28: Rental | F28: Alat Berat | G28: Rental forklift dan crane | H28: 02143931292 / +62 811-9650-3201 | M28: KOTA JAKARTA UTARA | N28: DKI JAKARTA | O28: Indonesia | P28: Evi Sinaga | Q28: - | R28: Dani Santoso | T28: Bank BCA | U28: 007 372 3768 | V28: CV. Sumber Rezeki | Z28: National | AC28: Y | AE28: f | AF28: 0000-00-00
A29: VDR4026 | B29: CV | C29: Sumber Sarana Karya | D29: Jl. Raya Pasir Panjang, Kel. Pasir Panjang, Kec. Arut Selatan, Kab. Kotawaringin Barat, Kalimantan Tengah | E29: Transportation | F29: Trucking | G29: Transporter khusus kuari di pangkalan bun | H29: 053223788 | M29: KABUPATEN KOTAWARINGIN BARAT | N29: KALIMANTAN TENGAH | O29: Indonesia | P29: Ninum | Q29: - | R29: - | T29: Bank Mandiri | U29: 159-00-0310388-3 | V29: CV Sumber Sarana Karya | Z29: National | AC29: Y | AE29: f | AF29: 0000-00-00
A30: VDR3888 | B30: Mandor | C30: Abd Karim | D30: Demanggala, RT 002 RW 004, Desa Balleangin , Pangkajene | E30: Mandor/Subcon | F30: Mandor Civil | G30: Mandor Pekerja Kolaka | H30: 085249859628 | I30: - | J30: - | M30: KABUPATEN PANGKAJENE DAN KEPULAUAN | N30: SULAWESI SELATAN | O30: Indonesia | P30: Abd Karim | Q30: - | R30: - | T30: Bank Rakyat Indonesia | U30: 500901019325533 | V30: Abd Karim | W30: - | X30: - | Y30: - | Z30: National | AB30: - | AC30: Y | AE30: f | AF30: 0000-00-00
A31: VDR4055 | B31: Mandor | C31: Ade Gunawan | D31: Lingk. II Toparuni RT 002 RW 002 Kel. Ulu Wolo Kec. Wolo Kabupaten Kolaka | E31: Mandor/Subcon | F31: Mandor Civil | G31: Mandor untuk pekerjaan pendingan STP dan BW | H31: - | M31: KABUPATEN KOLAKA | N31: SULAWESI TENGGARA | O31: Indonesia | P31: Ade Gunawan | Q31: - | R31: - | T31: Bank Mandiri | U31: 1620007350089 | V31: Ade Gunawan | Z31: National | AC31: Y | AE31: f | AF31: 0000-00-00
A32: VDR3843 | B32: Mandor | C32: Adi Sutrisno | D32: Perum Griya Inti Permata No. J-18 RT 003 RW 027 Martopuro , Purwosari | E32: Mandor/Subcon | F32: Mandor Civil | G32: Untuk Pekerjaan Civil Works Batch 2 Kolaka , rekomendasi PP | H32: 0821571923000 | I32: - | J32: - | M32: KABUPATEN PASURUAN | N32: JAWA TIMUR | O32: Indonesia | P32: Adi Sutrisno | Q32: - | R32: - | T32: Bank Mandiri | U32: 1400004374410 | V32: Adi Sutrisno | W32: - | X32: - | Y32: - | Z32: National | AA32: - | AB32: - | AC32: Y | AE32: f | AF32: 0000-00-00
A33: VDR3987 | B33: Mandor | C33: Afrizal | D33: Jl. Arifin Achmad RT 001 RW 015 Kel. Tangkerang Tengah Kec. Marpoyan Damai Kota Pekanbaru | E33: Mandor/Subcon | F33: Borepile | H33: +62 812-6865-2373 | M33: KOTA PEKANBARU | N33: RIAU | O33: Indonesia | P33: Afrizal | Q33: - | R33: - | T33: Bank Mandiri | U33: 108 001 741 9301 | V33: Afrizal | Z33: National | AC33: Y | AE33: f | AF33: 0000-00-00
A34: VDR4180 | B34: Mandor | C34: Ahmad Sholeh | D34: Kp Cipeuteuy RT 006 RW 002 Cilegong, Kec. Jatiluhur | E34: Mandor/Subcon | F34: Mandor Civil | G34: Mandor Pekerjaan Sipil di Purwakarta | H34: 087754475373 | I34: - | J34: - | M34: KABUPATEN PURWAKARTA | N34: JAWA BARAT | O34: Indonesia | P34: Ahmad Sholeh | Q34: - | R34: - | T34: BNI | U34: 0464850620 | V34: Yuyun | W34: - | X34: - | Z34: National | AC34: Y | AE34: f | AF34: 0000-00-00
A35: VDR4159 | B35: Mandor | C35: Ahmad Syamsudin | D35: Jl. Ahmad Yani Km 18 RT 005 RW 001 Bumi Harjo, Kumai, Kab. Kotawaringin Barat | E35: Mandor/Subcon | F35: Mandor Civil | G35: Pembuatan Site Storage / Office | H35: +62 812-3694-9841 | M35: KABUPATEN KOTAWARINGIN BARAT | N35: KALIMANTAN TENGAH | O35: Indonesia | P35: Ahmad | Q35: - | R35: - | T35: Bank BRI | U35: 7715-01-012518-53-0 | V35: Solikhati | Z35: National | AC35: Y | AE35: f | AF35: 0000-00-00
A36: VDR4251 | B36: Mandor | C36: Ajay | D36: Kp Bojong Sari Kaleur RT 01/05 Balebandung Jaya, Kec. Pabuaran | E36: Mandor/Subcon | F36: Mandor Civil | G36: Pekerjaan Batu Belah | H36: 087778930682 | I36: - | J36: - | M36: KABUPATEN SUBANG | N36: JAWA BARAT | O36: Indonesia | P36: Ajay | Q36: - | R36: - | T36: BCA | U36: 4600297665 | V36: Ajay | W36: - | X36: - | Z36: National | AC36: Y | AE36: f | AF36: 0000-00-00
A37: VDR4221 | B37: Mandor | C37: Alfian Dani | D37: Jln. Sultan Agung Blk LK. III Pantai Burung, Tanjungbalai Selatan, Kota Tanjungbalai | E37: Mandor/Subcon | F37: Mandor Civil | G37: Daily Worker | H37: +62 851-2619-9395 | L37: Jl. Merempan Hilir No. 20 Mempura, Kab. Siak | M37: KOTA TANJUNG BALAI | N37: SUMATERA UTARA | O37: Indonesia | P37: Dani | Q37: - | R37: - | T37: Sea Bank | U37: 901 577 241 697 | V37: Alfian Dani | Z37: National | AC37: Y | AE37: f | AF37: 0000-00-00
A38: VDR3887 | B38: Mandor | C38: Alimuddin | D38: Marranu , RT 000 RW 000 , Kec Lau , Maros | E38: Mandor/Subcon | F38: Mandor Civil | G38: Untuk pekerjaan Kolaka | H38: 081931448554 | I38: - | J38: - | M38: KABUPATEN MAROS | N38: SULAWESI SELATAN | O38: Indonesia | P38: Alimuddin | Q38: - | R38: - | T38: Bank Rakyat Indonesia | U38: 496701016566533 | V38: Alimuddin | W38: - | X38: - | Y38: - | Z38: National | AA38: - | AB38: - | AC38: Y | AE38: f | AF38: 0000-00-00
A39: VDR3109 | B39: Mandor | C39: Ari Setiawan | D39: Wlahar RT 004 RW 001 Wangon - Banyumas | E39: Mandor/Subcon | F39: Mandor Civil | H39: +62 859-7597-3027 | M39: KABUPATEN BANYUMAS | N39: JAWA TENGAH | O39: Indonesia | P39: Ari Setiawan | Q39: 0 | R39: 0 | T39: BCA | U39: 8015507612 | V39: ARI SETIAWAN | Z39: National | AC39: Y | AE39: f | AF39: 0000-00-00
A40: VDR3884 | B40: Mandor | C40: Baharuddin | D40: Dusun II Sratiombo, Kel Tamborasi , Kecamatan Wolo , Kolaka | E40: Mandor/Subcon | F40: Mandor Civil | H40: 082141000545 | I40: - | J40: - | M40: KABUPATEN KOLAKA | N40: SULAWESI TENGGARA | O40: Indonesia | P40: Baharuddin | Q40: - | R40: - | T40: Bank Rakyat Indonesia | U40: 493801029337538 | V40: Baharuddin | W40: - | X40: - | Y40: - | Z40: National | AA40: - | AB40: - | AC40: Y | AE40: f | AF40: 0000-00-00
...

Sheet PLN
A1: VDR0704 | B1: Other | C1: Dewan Pimpinan Pusat Serikat PT PLN | D1: Jl.Trinojoyo Blok M1/135 kebayoran baru jakarta se | E1: Supplier Others | G1: Pass Without Comment | H1: 021-7261122/7262234 | L1: Partisipasi Iklan | N1: Jakarta Selatan | P1: Indonesia | Q1: Frita | T1: Bank Mandiri Cabang Utama Roxy Mas Jakarta Pusat | U1: 117.00000.65086 | V1: PT Bagassindo Media Persada | Z1: National | AC1: Y
A2: VDR1410 | B2: Other | C2: Koperasi Pegawai PLN Pusat | D2: Jakarta Pusat | E2: Badan Pemerintah | F2: General | H2: 0 | J2: 0 | N2: KOTA JAKARTA PUSAT | O2: DKI JAKARTA | P2: Indonesia | Q2: 0 | R2: 0 | S2: 0 | T2: Mandiri | U2: 1260004878756 | V2: Koperasi Pegawai PLN Pusat | Z2: National | AC2: Y | AE2: N | AF2: 0000-00-00
A4: VDR3614 | C4: PERUSAHAAN LISTRIK NEGARA (PLN) | D4: Jl. Trunojoyo M I No. 135 Melawai Kebayoran, Jakarta Selatan Baru DKI Jakarta | E4: Sertifikasi | F4: Jasa Sertifikasi | G4: SLO Transmisi BATAM SUTT 150KV (46 Tower) | H4: 81317528644 | I4: - | J4: - | K4: - | N4: KOTA JAKARTA SELATAN | O4: DKI JAKARTA | P4: INDONESIA | Q4: Mba Rizki Andin | R4: - | S4: - | T4: MANDIRI | U4: PLN | V4: 127.000.424.2366 | W4: - | X4: - | Y4: - | Z4: National | AC4: Y | AD4: 01.001.629.3-051.000 | AE4: t | AF4: 0000-00-00
A5: VDR0724 | C5: PLN (PERSERO) | D5: Wilayah Riau dan Kepulauan Riau Cabang Tanjung Pin | E5: Supplier Others | G5: Pass Without Comment | H5: 0771-23755-24406-210 | I5: TBA | J5: 0771-21148 | K5: TBA | L5: PLN (PERSERO) | N5: Tanung Pinang | P5: Indonesia | Q5: Dedi J | T5: Bayar Langsung | U5: Bayar Langsung | V5: Bayar Langsung | W5: TBA | X5: TBA | Y5: TBA | Z5: National | AA5: TBA | AC5: Y
A6: VDR1401 | C6: PLN (Persero) Area Pelayanan Jaringan Klaten | D6: Jl, Perintis Kemerdekaan No. 3A Klaten | E6: Supplier Others | F6: AKLI | G6: PLN cabang KLaten utk pembayaran BP | H6: 0272-320912 | I6: apklaten@telkom.net | J6: 0272-326073 | K6: apklaten@telkom.net | N6: KABUPATEN KLATEN | O6: JAWA TENGAH | P6: Indonesia | Q6: I Ketut Wiriana | R6: Budi Pratomo | S6: Nur Pamuji | T6: bayar langsung di Loket PLN | U6: bayar langsung di Loket PLN | V6: bayar langsung di Loket PLN | Z6: National | AC6: Y | AE6: N | AF6: 0000-00-00
A7: VDR1161 | C7: PLN (Persero) Area Pelayanan Jaringan Salatiga | D7: Jl. Diponegoro No. 19 | E7: Mandor/Subcon | F7: Alat elektrical | G7: utk pembayaran BP site hotel grand wahid | H7: 0298-326883 | I7: pln-slg@indo.net.id | J7: 0298-324671 | K7: pln-slg@indo.net.id | N7: Salatiga | P7: Indonesia | Q7: Zubaidah (Manager APJ Sal | R7: Sri Wahyuni | S7: Zubaidah (Manager APJ Sal | T7: Dibayar langsung di Loket PLN | U7: Dibayar langsung di Loket PLN | V7: Dibayar langsung di Loket PLN | Z7: National | AC7: Y | AE7: N | AF7: 0000-00-00
A8: VDR3615 | C8: PLN (Persero) Pusat Sertifikasi | D8: Jalan Laboratorium, Duren Tiga, Jakarta Selatan Jakarta, 12760 | E8: Sertifikasi | F8: Jasa Sertifikasi | G8: Pusat Sertifikasi | H8: (021) 790 0034 | I8: niaga.pusertif@pln.co.id | J8: (021) 798 2034 | K8: niaga.pusertif@pln.co.id | N8: KOTA JAKARTA SELATAN | O8: DKI JAKARTA | P8: INDONESIA | Q8: PLN (Persero) Pusat Serti | R8: - | S8: - | T8: MANDIRI | U8: 127.000.424.2366 | V8: PLN | W8: - | X8: - | Y8: - | Z8: National | AB8: - | AC8: Y | AD8: 01.001.629.3-051.000 | AE8: t | AF8: 0000-00-00
A9: VDR2799 | C9: PLN (PERSERO) UIW SUMATERA UTARA, UP3 RANTAU PRAPAT, ULP TANJUNG BALAI | D9: TANJUNG BALAI | E9: Supplier Others | F9: Transmisi | G9: PLN untuk Penerangan Sementara | H9: 061-000000 | N9: KOTA TANJUNG BALAI | O9: SUMATERA UTARA | P9: INDONESIA | Q9: PT PLN | R9: 0 | S9: 0 | T9: Bank | U9: 1251129001298 | V9: PLN | Z9: National | AC9: Y | AE9: f | AF9: 0000-00-00
A10: VDR1073 | C10: PLN (Persero) Wilayah Aceh | D10: Jl. Malikussaleh No. 01 Lcg Garam | E10: Mandor/Subcon | F10: AKLI | G10: Pass Without Comment | H10: 0645-630255 | J10: 0645-48000 | N10: Lhokseumawe | P10: Indonesia | Q10: Kamaddin | R10: tba | S10: tba | T10: handcarry by finance PJO Medan | U10: handcarry by finance PJO Medan | V10: handcarry by finance PJO Medan | Z10: National | AC10: Y | AE10: N | AF10: 0000-00-00
A11: VDR1458 | C11: PLN Area Pelayanan Jaringan Pacitan | D11: Jl. Jendral A. Yani No. 94 Pacitan | E11: Distributor | F11: Alat elektrical | G11: PLN di area Pacitan (utk pengurusan BP site PLTU Pacitan) | H11: (0357)-881010 | J11: (0357)-881010. | N11: KABUPATEN PACITAN | O11: JAWA TIMUR | P11: Indonesia | Q11: Susanto Ardyanto | R11: Susanto Ardyanto | S11: Susanto Ardyanto | T11: dibayar langsung di loket PLN | U11: dibayar langsung di loket PLN | V11: dibayar langsung di loket PLN | Z11: National | AC11: Y | AE11: N | AF11: 0000-00-00
A12: VDR1566 | C12: PLN area pelayanan jaringan Surabaya | D12: Jl. Bratang Binangun Komp Manyaran Megah Indah Plaza BI A No. 31 | E12: Badan Pemerintah | F12: AKLI | G12: utk pembayaran BPUJL di area surabaya | H12: 031-5026556 | J12: 031-5029769 | N12: KOTA SURABAYA | O12: JAWA TIMUR | P12: Indonesia | Q12: Heru Subagyo | R12: Heru Subagyo | S12: Heru Subagyo | T12: dibayar langsung di loket | U12: dibayar langsung di loket | V12: dibayar langsung di loket | Z12: National | AC12: Y | AE12: N | AF12: 0000-00-00
A13: VDR0750 | C13: PLN Cab Medan | D13: Jl. Pembakitan Listirk No. 1 Paya Pasir Medan Ma | E13: Akli | G13: Pass Without Comment | H13: 061-6850064 | I13: TBA | J13: 061-6853842 | K13: TBA | N13: Medan | P13: Indonesia | Q13: Pak Marbun | T13: BCA | U13: 217305001 | V13: PT Qdc Technologies | W13: TBA | X13: TBA | Y13: TBA | Z13: National | AA13: TBA | AB13: TBA | AC13: Y
A14: VDR0962 | C14: PLN Distribusi Jawa Barat dan Banten Unit Jaringan | D14: Jl Raya Jakarta Bogor Km 31 No 16 Cimanggis | E14: Mandor/Subcon | F14: General | G14: Pass Without Comment | H14: 8730325 | J14: 8730324 | N14: Jakarta | P14: Indonesia | Q14: Tirta Rachim | T14: Mandiri Cab Gandaria | U14: 129.000.102.9467 | V14: PT. PLN Distribusi Jawa Barat dan Banten Unit Jari | Z14: National | AC14: Y
A15: VDR0875 | C15: PLN Kantor Layanan Pondok Kopi | D15: l. Sentra Primer Baru Timur, Pulogebang | E15: Travel Agency | G15: Pass Without Comment | H15: 021) 4806504, 480650 | I15: www.pln.co.id | J15: (021) 4807160 | K15: www.pln.co.id | L15: PLN PERSERO-URGENT | N15: Pondok Kopi | P15: Indonesia | Q15: Customer Service | T15: Cash Bayar langsung di Loket PLN | U15: Cash Bayar langsung di Loket PLN | V15: Cash Bayar langsung di Loket PLN | W15: TBA | X15: TBA | Y15: TBA | Z15: National | AA15: TBA | AB15: TBA | AC15: Y
A16: VDR0674 | C16: PLN Rayon PANAM | D16: Jl. H. Subrantas, PANAM, Kec. Tampan | E16: Akli | G16: Pass Without Comment | H16: 0761-62481 | I16: TBA | J16: 0761-66444 | K16: TBA | N16: Kota Pekanbaru | P16: Indonesia | Q16: TBA | T16: TBA | U16: TAB | V16: TBA | W16: TBA | X16: TBA | Y16: TBA | Z16: National | AA16: TBA | AC16: Y
A17: VDR0486 | C17: PT .PLN (PERSERO) - UPJ Garut Leles | D17: JL Raya Leles No.64 Leles Kab.Garut | E17: "" | G17: Pass Without Comment | H17: 0262-455671 | J17: 0262-457974 | N17: Garut | P17: Jawa Barat | AC17: Y
A18: VDR0487 | C18: PT PLN (PERSERO) - UPJ Majalaya | D18: JL Pamagersari No.26 Majalaya Kab.Bandung 40382 | E18: "" | G18: Pass Without Comment | H18: 022-5950354 | J18: 022-5951530 | N18: Bandung | P18: Indonesia | AC18: Y
A19: VDR0823 | C19: PT PLN (PERSERO) Salatiga Kota | D19: Jl Salatiga Kota Jawa Tengah | E19: Akli | G19: Pass Without Comment | H19: 024-123 | I19: www.pln.co.id | J19: 024-123 | K19: www.pln.co.id | L19: PLN | N19: Salatiga | P19: Jawa Tengah | Q19: Customer Service | T19: Dibayar langsung ke Loket PLN | U19: Dibayar langsung ke Loket PLN | V19: Dibayar langsung ke Loket PLN | W19: tba | X19: tba | Y19: tba | Z19: National | AA19: tba | AB19: tba | AC19: Y
A20: VDR0488 | C20: PT PLN PERSERO -UPJ BATAM | D20: Jl.Engku Putri, Batam Center | E20: "" | G20: Pass Without Comment | H20: (62-778) 463 150-153 | J20: (62-778) 463 143 | N20: Batam | P20: Indonesia | T20: Bank BRI | U20: 0621-01-000048-30-3 | V20: PT PLN | AC20: Y
A21: VDR0879 | C21: PT. PLN (PERSERO) DISTRIBUSI JAKARTA RAYA DAN TANG | D21: Jl. MIR Rais no. 1 Jakarta 10110 | E21: Supplier Others | G21: Pass Without Comment | H21: 021-345 4000 | I21: humasjaya@pln.co.id | J21: 021-385 6761 | K21: humasjaya@pln.co.id | L21: PLN Connection | M21: - | N21: Jakarta | P21: INDONESIA | Q21: - | T21: - | U21: - | V21: - | W21: - | X21: - | Y21: - | Z21: National | AA21: - | AB21: - | AC21: Y
A22: VDR2071 | C22: PT. PLN Persero | D22: Jl. Trunojoyo Blok M I/135 Melawai Kebayoran Baru Jakarta Selatan | E22: Supplier | F22: Building Management | G22: 0 | H22: (021) 7261122 | I22: 0 | J22: 0 | K22: 0 | M22: Jl. Trunojoyo Blok M I/135 Melawai Kebayoran Baru | N22: KOTA JAKARTA SELATAN | O22: DKI JAKARTA | P22: Indonesia | Q22: 0 | R22: 0 | S22: 0 | T22: 0 | U22: 0 | V22: 0 | W22: 0 | X22: 0 | Y22: 0 | Z22: National | AA22: 0 | AB22: 0 | AC22: Y | AE22: N | AF22: 0000-00-00
A23: VDR2236 | C23: PT. PLN Persero Jasa Diklat | D23: Jl. Harsono RM No. 59 Ragunan Pasar Minggu Jakarta Selatan 12550 | E23: University | F23: General | G23: Training | H23: 021 782 9525 | I23: 0 | J23: 021 7811 294 | K23: 0 | M23: Jl. Harsono RM No. 59 Ragunan Pasar Minggu Jakarta | N23: KOTA JAKARTA SELATAN | O23: DKI JAKARTA | P23: Indonesia | Q23: 0 | R23: 0 | S23: 0 | T23: Bank BRI | U23: 0339 01 000171 301 | V23: PT. PLN (Persero) Jasa Diklat | W23: 0 | X23: 0 | Y23: 0 | Z23: National | AA23: 0 | AB23: 0 | AC23: Y | AE23: N | AF23: 0000-00-00
A24: VDR0545 | C24: UPT - PLN CIANJUR KOTA | D24: CIANJUR | G24: Pass Without Comment | L24: PLN CIANJUR | N24: Jawa Barat | AC24: Y

Sheet REF - InstitutionType
B2: Sys_PID | C2: Name | D2: Prefix | E2: Suffix
B4: 141000000000001 | C4: Others
B5: 141000000000002 | C5: Persekutuan Komanditer | D5: CV.
B6: 141000000000003 | C6: Perusahaan Perorangan
B7: 141000000000004 | C7: Swasta Perseroan Terbatas (Tertutup) | D7: PT.
B8: 141000000000005 | C8: Swasta Perseroan Terbatas (Terbuka) | D8: PT. | E8: , Tbk
B9: 141000000000006 | C9: BUMN Perseroan Terbatas (Tertutup) | D9: PT. | E9: (Persero)
B10: 141000000000007 | C10: BUMN Perseroan Terbatas (Terbuka) | D10: PT. | E10: (Persero), Tbk
B11: 141000000000008 | C11: Perseroan Terbatas Perorangan | D11: PT.
B12: 141000000000009 | C12: BUMN Perusahaan Jawatan | D12: Perjan
B13: 141000000000010 | C13: BUMN Perusahaan Umum | D13: Perum
B14: 141000000000011 | C14: Firma | D14: FA.
B15: 141000000000012 | C15: Koperasi | D15: Koperasi
B16: 141000000000013 | C16: Yayasan
B17: 141000000000014 | C17: Lembaga Pemerintah
B18: 141000000000015 | C18: Usaha Dagang | D18: UD.
B19: 141000000000016 | C19: Perusahaan Dagang | D19: PD.
B20: 141000000000017 | C20: Perusahaan Otobus | D20: PO.
B21: 141000000000018 | C21: Toko | D21: Toko
B22: 141000000000019 | C22: Toko Bangunan | D22: TB.
B23: 141000000000020 | C23: Toko Online Market Place | D23: Toko Online
B24: 141000000000021 | C24: Mandor | D24: Mandor
B25: 141000000000022 | C25: Badan Penyelenggara Jaminan Sosial | D25: BPJS
B26: 141000000000023 | C26: Asosiasi Perusahaan

Sheet SEED - Institution
B2: Name | C2: InstitutionType _RefID | D2: Full Name | E2: Commercial Name | F2: Old Code | G2: Jenis Supplier | H2: Sub Jenis Supplier | I2: Keterangan | J2: NPWP | K2: Nama PKP / NPWP | L2: Entity Type | N2: SYS_PID Prediction | O2: SQL Syntax
N3: 123000000000000
A4: =IF( COUNTIF( $D$4:$D$1000, $D4 ) = 1, "", "Duplicated") | B4: QDC Technologies | C4: 141000000000004 | D4: =IF(EXACT($C4, ""), B4, CONCATENATE(VLOOKUP($C4, 'REF - InstitutionType'!$B$4:$E$102, 3, FALSE), IF(EXACT(VLOOKUP($C4, 'REF - InstitutionType'!$B$4:$E$102, 3, FALSE), ""), "", " "), $B4, "", VLOOKUP($C4, 'REF - InstitutionType'!$B$4:$E$102, 4, FALSE), IF(EXACT($E4, ""), "", " [a.k.a : "&$E4&"]"))) -> PT. QDC Technologies | F4: QDC | L4: Corporate | N4: =N3 + IF(EXACT(O4, ""), 0, 1) -> 123000000000001 | O4: =CONCATENATE("PERFORM ""SchData-OLTP-Master"".""Func_TblInstitution_SET""(varSystemLoginSession::bigint, null::bigint, null::varchar, null::timestamptz, null::timestamptz, null::varchar, varInstitutionBranchID::bigint, varBaseCurrencyID::bigint, '", B4, "'::varchar, ", IF(EXACT(C4, ""), "null", C4), "::bigint); ") -> PERFORM "SchData-OLTP-Master"."Func_TblInstitution_SET"(varSystemLoginSession::bigint, null::bigint, null::varchar, null::timestamptz, null::timestamptz, null::varchar, varInstitutionBranchID::bigint, varBaseCurrencyID::bigint, 'QDC Technologies'::varchar, 141000000000004::bigint);
A5: =IF( COUNTIF( $D$4:$D$1000, $D5 ) = 1, "", "Duplicated") | B5: Infra Media Dinamika | C5: 141000000000004 | D5: =IF(EXACT($C5, ""), B5, CONCATENATE(VLOOKUP($C5, 'REF - InstitutionType'!$B$4:$E$102, 3, FALSE), IF(EXACT(VLOOKUP($C5, 'REF - InstitutionType'!$B$4:$E$102, 3, FALSE), ""), "", " "), $B5, "", VLOOKUP($C5, 'REF - InstitutionType'!$B$4:$E$102, 4, FALSE), IF(EXACT($E5, ""), "", " [a.k.a : "&$E5&"]"))) -> PT. Infra Media Dinamika | F5: IMD | L5: Corporate | N5: =N4 + IF(EXACT(O5, ""), 0, 1) -> 123000000000002 | O5: =CONCATENATE("PERFORM ""SchData-OLTP-Master"".""Func_TblInstitution_SET""(varSystemLoginSession::bigint, null::bigint, null::varchar, null::timestamptz, null::timestamptz, null::varchar, varInstitutionBranchID::bigint, varBaseCurrencyID::bigint, '", B5, "'::varchar, ", IF(EXACT(C5, ""), "null", C5), "::bigint); ") -> PERFORM "SchData-OLTP-Master"."Func_TblInstitution_SET"(varSystemLoginSession::bigint, null::bigint, null::varchar, null::timestamptz, null::timestamptz, null::varchar, varInstitutionBranchID::bigint, varBaseCurrencyID::bigint, 'Infra Media Dinamika'::varchar, 141000000000004::bigint);
A6: =IF( COUNTIF( $D$4:$D$1000, $D6 ) = 1, "", "Duplicated") | B6: Daya Hidro Dinamika | C6: 141000000000004 | D6: =IF(EXACT($C6, ""), B6, CONCATENATE(VLOOKUP($C6, 'REF - InstitutionType'!$B$4:$E$102, 3, FALSE), IF(EXACT(VLOOKUP($C6, 'REF - InstitutionType'!$B$4:$E$102, 3, FALSE), ""), "", " "), $B6, "", VLOOKUP($C6, 'REF - InstitutionType'!$B$4:$E$102, 4, FALSE), IF(EXACT($E6, ""), "", " [a.k.a : "&$E6&"]"))) -> PT. Daya Hidro Dinamika | F6: DHD | L6: Corporate | N6: =N5 + IF(EXACT(O6, ""), 0, 1) -> 123000000000003 | O6: =CONCATENATE("PERFORM ""SchData-OLTP-Master"".""Func_TblInstitution_SET""(varSystemLoginSession::bigint, null::bigint, null::varchar, null::timestamptz, null::timestamptz, null::varchar, varInstitutionBranchID::bigint, varBaseCurrencyID::bigint, '", B6, "'::varchar, ", IF(EXACT(C6, ""), "null", C6), "::bigint); ") -> PERFORM "SchData-OLTP-Master"."Func_TblInstitution_SET"(varSystemLoginSession::bigint, null::bigint, null::varchar, null::timestamptz, null::timestamptz, null::varchar, varInstitutionBranchID::bigint, varBaseCurrencyID::bigint, 'Daya Hidro Dinamika'::varchar, 141000000000004::bigint);
A7: =IF( COUNTIF( $D$4:$D$1000, $D7 ) = 1, "", "Duplicated") -> Duplicated | B7: Energi Mekar Lestari | C7: 141000000000004 | D7: =IF(EXACT($C7, ""), B7, CONCATENATE(VLOOKUP($C7, 'REF - InstitutionType'!$B$4:$E$102, 3, FALSE), IF(EXACT(VLOOKUP($C7, 'REF - InstitutionType'!$B$4:$E$102, 3, FALSE), ""), "", " "), $B7, "", VLOOKUP($C7, 'REF - InstitutionType'!$B$4:$E$102, 4, FALSE), IF(EXACT($E7, ""), "", " [a.k.a : "&$E7&"]"))) -> PT. Energi Mekar Lestari | F7: EML | L7: Corporate | N7: =N6 + IF(EXACT(O7, ""), 0, 1) -> 123000000000004 | O7: =CONCATENATE("PERFORM ""SchData-OLTP-Master"".""Func_TblInstitution_SET""(varSystemLoginSession::bigint, null::bigint, null::varchar, null::timestamptz, null::timestamptz, null::varchar, varInstitutionBranchID::bigint, varBaseCurrencyID::bigint, '", B7, "'::varchar, ", IF(EXACT(C7, ""), "null", C7), "::bigint); ") -> PERFORM "SchData-OLTP-Master"."Func_TblInstitution_SET"(varSystemLoginSession::bigint, null::bigint, null::varchar, null::timestamptz, null::timestamptz, null::varchar, varInstitutionBranchID::bigint, varBaseCurrencyID::bigint, 'Energi Mekar Lestari'::varchar, 141000000000004::bigint);
A8: =IF( COUNTIF( $D$4:$D$1000, $D8 ) = 1, "", "Duplicated") | B8: KHA | C8: 141000000000004 | D8: =IF(EXACT($C8, ""), B8, CONCATENATE(VLOOKUP($C8, 'REF - InstitutionType'!$B$4:$E$102, 3, FALSE), IF(EXACT(VLOOKUP($C8, 'REF - InstitutionType'!$B$4:$E$102, 3, FALSE), ""), "", " "), $B8, "", VLOOKUP($C8, 'REF - InstitutionType'!$B$4:$E$102, 4, FALSE), IF(EXACT($E8, ""), "", " [a.k.a : "&$E8&"]"))) -> PT. KHA | F8: KHA | L8: Corporate | N8: =N7 + IF(EXACT(O8, ""), 0, 1) -> 123000000000005 | O8: =CONCATENATE("PERFORM ""SchData-OLTP-Master"".""Func_TblInstitution_SET""(varSystemLoginSession::bigint, null::bigint, null::varchar, null::timestamptz, null::timestamptz, null::varchar, varInstitutionBranchID::bigint, varBaseCurrencyID::bigint, '", B8, "'::varchar, ", IF(EXACT(C8, ""), "null", C8), "::bigint); ") -> PERFORM "SchData-OLTP-Master"."Func_TblInstitution_SET"(varSystemLoginSession::bigint, null::bigint, null::varchar, null::timestamptz, null::timestamptz, null::varchar, varInstitutionBranchID::bigint, varBaseCurrencyID::bigint, 'KHA'::varchar, 141000000000004::bigint);
A9: =IF( COUNTIF( $D$4:$D$1000, $D9 ) = 1, "", "Duplicated") | B9: Abhitama Citra Abadi | C9: 141000000000004 | D9: =IF(EXACT($C9, ""), B9, CONCATENATE(VLOOKUP($C9, 'REF - InstitutionType'!$B$4:$E$102, 3, FALSE), IF(EXACT(VLOOKUP($C9, 'REF - InstitutionType'!$B$4:$E$102, 3, FALSE), ""), "", " "), $B9, "", VLOOKUP($C9, 'REF - InstitutionType'!$B$4:$E$102, 4, FALSE), IF(EXACT($E9, ""), "", " [a.k.a : "&$E9&"]"))) -> PT. Abhitama Citra Abadi | F9: ACA | L9: Customer | N9: =N8 + IF(EXACT(O9, ""), 0, 1) -> 123000000000006 | O9: =CONCATENATE("PERFORM ""SchData-OLTP-Master"".""Func_TblInstitution_SET""(varSystemLoginSession::bigint, null::bigint, null::varchar, null::timestamptz, null::timestamptz, null::varchar, varInstitutionBranchID::bigint, varBaseCurrencyID::bigint, '", B9, "'::varchar, ", IF(EXACT(C9, ""), "null", C9), "::bigint); ") -> PERFORM "SchData-OLTP-Master"."Func_TblInstitution_SET"(varSystemLoginSession::bigint, null::bigint, null::varchar, null::timestamptz, null::timestamptz, null::varchar, varInstitutionBranchID::bigint, varBaseCurrencyID::bigint, 'Abhitama Citra Abadi'::varchar, 141000000000004::bigint);
A10: =IF( COUNTIF( $D$4:$D$1000, $D10 ) = 1, "", "Duplicated") | B10: Abiyasa Tunggal | C10: 141000000000004 | D10: =IF(EXACT($C10, ""), B10, CONCATENATE(VLOOKUP($C10, 'REF - InstitutionType'!$B$4:$E$102, 3, FALSE), IF(EXACT(VLOOKUP($C10, 'REF - InstitutionType'!$B$4:$E$102, 3, FALSE), ""), "", " "), $B10, "", VLOOKUP($C10, 'REF - InstitutionType'!$B$4:$E$102, 4, FALSE), IF(EXACT($E10, ""), "", " [a.k.a : "&$E10&"]"))) -> PT. Abiyasa Tunggal | F10: ABI | L10: Customer | N10: =N9 + IF(EXACT(O10, ""), 0, 1) -> 123000000000007 | O10: =CONCATENATE("PERFORM ""SchData-OLTP-Master"".""Func_TblInstitution_SET""(varSystemLoginSession::bigint, null::bigint, null::varchar, null::timestamptz, null::timestamptz, null::varchar, varInstitutionBranchID::bigint, varBaseCurrencyID::bigint, '", B10, "'::varchar, ", IF(EXACT(C10, ""), "null", C10), "::bigint); ") -> PERFORM "SchData-OLTP-Master"."Func_TblInstitution_SET"(varSystemLoginSession::bigint, null::bigint, null::varchar, null::timestamptz, null::timestamptz, null::varchar, varInstitutionBranchID::bigint, varBaseCurrencyID::bigint, 'Abiyasa Tunggal'::varchar, 141000000000004::bigint);
A11: =IF( COUNTIF( $D$4:$D$1000, $D11 ) = 1, "", "Duplicated") | B11: Aplika Nusa Lintas Arta | C11: =141000000000004*1 -> 141000000000004 | D11: =IF(EXACT($C11, ""), B11, CONCATENATE(VLOOKUP($C11, 'REF - InstitutionType'!$B$4:$E$102, 3, FALSE), IF(EXACT(VLOOKUP($C11, 'REF - InstitutionType'!$B$4:$E$102, 3, FALSE), ""), "", " "), $B11, "", VLOOKUP($C11, 'REF - InstitutionType'!$B$4:$E$102, 4, FALSE), IF(EXACT($E11, ""), "", " [a.k.a : "&$E11&"]"))) -> PT. Aplika Nusa Lintas Arta | F11: LTA | L11: Customer | N11: =N10 + IF(EXACT(O11, ""), 0, 1) -> 123000000000008 | O11: =CONCATENATE("PERFORM ""SchData-OLTP-Master"".""Func_TblInstitution_SET""(varSystemLoginSession::bigint, null::bigint, null::varchar, null::timestamptz, null::timestamptz, null::varchar, varInstitutionBranchID::bigint, varBaseCurrencyID::bigint, '", B11, "'::varchar, ", IF(EXACT(C11, ""), "null", C11), "::bigint); ") -> PERFORM "SchData-OLTP-Master"."Func_TblInstitution_SET"(varSystemLoginSession::bigint, null::bigint, null::varchar, null::timestamptz, null::timestamptz, null::varchar, varInstitutionBranchID::bigint, varBaseCurrencyID::bigint, 'Aplika Nusa Lintas Arta'::varchar, 141000000000004::bigint);
A12: =IF( COUNTIF( $D$4:$D$1000, $D12 ) = 1, "", "Duplicated") | B12: Bakrie Telecom | C12: 141000000000005 | D12: =IF(EXACT($C12, ""), B12, CONCATENATE(VLOOKUP($C12, 'REF - InstitutionType'!$B$4:$E$102, 3, FALSE), IF(EXACT(VLOOKUP($C12, 'REF - InstitutionType'!$B$4:$E$102, 3, FALSE), ""), "", " "), $B12, "", VLOOKUP($C12, 'REF - InstitutionType'!$B$4:$E$102, 4, FALSE), IF(EXACT($E12, ""), "", " [a.k.a : "&$E12&"]"))) -> PT. Bakrie Telecom, Tbk | F12: ESI | L12: Customer | N12: =N11 + IF(EXACT(O12, ""), 0, 1) -> 123000000000009 | O12: =CONCATENATE("PERFORM ""SchData-OLTP-Master"".""Func_TblInstitution_SET""(varSystemLoginSession::bigint, null::bigint, null::varchar, null::timestamptz, null::timestamptz, null::varchar, varInstitutionBranchID::bigint, varBaseCurrencyID::bigint, '", B12, "'::varchar, ", IF(EXACT(C12, ""), "null", C12), "::bigint); ") -> PERFORM "SchData-OLTP-Master"."Func_TblInstitution_SET"(varSystemLoginSession::bigint, null::bigint, null::varchar, null::timestamptz, null::timestamptz, null::varchar, varInstitutionBranchID::bigint, varBaseCurrencyID::bigint, 'Bakrie Telecom'::varchar, 141000000000005::bigint);
A13: =IF( COUNTIF( $D$4:$D$1000, $D13 ) = 1, "", "Duplicated") | B13: Bukaka Teknik Utama | C13: 141000000000005 | D13: =IF(EXACT($C13, ""), B13, CONCATENATE(VLOOKUP($C13, 'REF - InstitutionType'!$B$4:$E$102, 3, FALSE), IF(EXACT(VLOOKUP($C13, 'REF - InstitutionType'!$B$4:$E$102, 3, FALSE), ""), "", " "), $B13, "", VLOOKUP($C13, 'REF - InstitutionType'!$B$4:$E$102, 4, FALSE), IF(EXACT($E13, ""), "", " [a.k.a : "&$E13&"]"))) -> PT. Bukaka Teknik Utama, Tbk | F13: BTU, VDR0015 | L13: Customer | N13: =N12 + IF(EXACT(O13, ""), 0, 1) -> 123000000000010 | O13: =CONCATENATE("PERFORM ""SchData-OLTP-Master"".""Func_TblInstitution_SET""(varSystemLoginSession::bigint, null::bigint, null::varchar, null::timestamptz, null::timestamptz, null::varchar, varInstitutionBranchID::bigint, varBaseCurrencyID::bigint, '", B13, "'::varchar, ", IF(EXACT(C13, ""), "null", C13), "::bigint); ") -> PERFORM "SchData-OLTP-Master"."Func_TblInstitution_SET"(varSystemLoginSession::bigint, null::bigint, null::varchar, null::timestamptz, null::timestamptz, null::varchar, varInstitutionBranchID::bigint, varBaseCurrencyID::bigint, 'Bukaka Teknik Utama'::varchar, 141000000000005::bigint);
A14: =IF( COUNTIF( $D$4:$D$1000, $D14 ) = 1, "", "Duplicated") | B14: Citra Panji Manunggal | C14: 141000000000004 | D14: =IF(EXACT($C14, ""), B14, CONCATENATE(VLOOKUP($C14, 'REF - InstitutionType'!$B$4:$E$102, 3, FALSE), IF(EXACT(VLOOKUP($C14, 'REF - InstitutionType'!$B$4:$E$102, 3, FALSE), ""), "", " "), $B14, "", VLOOKUP($C14, 'REF - InstitutionType'!$B$4:$E$102, 4, FALSE), IF(EXACT($E14, ""), "", " [a.k.a : "&$E14&"]"))) -> PT. Citra Panji Manunggal | F14: CPM | L14: Customer | N14: =N13 + IF(EXACT(O14, ""), 0, 1) -> 123000000000011 | O14: =CONCATENATE("PERFORM ""SchData-OLTP-Master"".""Func_TblInstitution_SET""(varSystemLoginSession::bigint, null::bigint, null::varchar, null::timestamptz, null::timestamptz, null::varchar, varInstitutionBranchID::bigint, varBaseCurrencyID::bigint, '", B14, "'::varchar, ", IF(EXACT(C14, ""), "null", C14), "::bigint); ") -> PERFORM "SchData-OLTP-Master"."Func_TblInstitution_SET"(varSystemLoginSession::bigint, null::bigint, null::varchar, null::timestamptz, null::timestamptz, null::varchar, varInstitutionBranchID::bigint, varBaseCurrencyID::bigint, 'Citra Panji Manunggal'::varchar, 141000000000004::bigint);
A15: =IF( COUNTIF( $D$4:$D$1000, $D15 ) = 1, "", "Duplicated") | B15: Dayamitra Telekomunikasi | C15: 141000000000004 | D15: =IF(EXACT($C15, ""), B15, CONCATENATE(VLOOKUP($C15, 'REF - InstitutionType'!$B$4:$E$102, 3, FALSE), IF(EXACT(VLOOKUP($C15, 'REF - InstitutionType'!$B$4:$E$102, 3, FALSE), ""), "", " "), $B15, "", VLOOKUP($C15, 'REF - InstitutionType'!$B$4:$E$102, 4, FALSE), IF(EXACT($E15, ""), "", " [a.k.a : "&$E15&"]"))) -> PT. Dayamitra Telekomunikasi | F15: DAYA | L15: Customer | N15: =N14 + IF(EXACT(O15, ""), 0, 1) -> 123000000000012 | O15: =CONCATENATE("PERFORM ""SchData-OLTP-Master"".""Func_TblInstitution_SET""(varSystemLoginSession::bigint, null::bigint, null::varchar, null::timestamptz, null::timestamptz, null::varchar, varInstitutionBranchID::bigint, varBaseCurrencyID::bigint, '", B15, "'::varchar, ", IF(EXACT(C15, ""), "null", C15), "::bigint); ") -> PERFORM "SchData-OLTP-Master"."Func_TblInstitution_SET"(varSystemLoginSession::bigint, null::bigint, null::varchar, null::timestamptz, null::timestamptz, null::varchar, varInstitutionBranchID::bigint, varBaseCurrencyID::bigint, 'Dayamitra Telekomunikasi'::varchar, 141000000000004::bigint);
A16: =IF( COUNTIF( $D$4:$D$1000, $D16 ) = 1, "", "Duplicated") | B16: Departemen Dalam Negeri | C16: 141000000000014 | D16: =IF(EXACT($C16, ""), B16, CONCATENATE(VLOOKUP($C16, 'REF - InstitutionType'!$B$4:$E$102, 3, FALSE), IF(EXACT(VLOOKUP($C16, 'REF - InstitutionType'!$B$4:$E$102, 3, FALSE), ""), "", " "), $B16, "", VLOOKUP($C16, 'REF - InstitutionType'!$B$4:$E$102, 4, FALSE), IF(EXACT($E16, ""), "", " [a.k.a : "&$E16&"]"))) -> Departemen Dalam Negeri | F16: DDN | L16: Customer | N16: =N15 + IF(EXACT(O16, ""), 0, 1) -> 123000000000013 | O16: =CONCATENATE("PERFORM ""SchData-OLTP-Master"".""Func_TblInstitution_SET""(varSystemLoginSession::bigint, null::bigint, null::varchar, null::timestamptz, null::timestamptz, null::varchar, varInstitutionBranchID::bigint, varBaseCurrencyID::bigint, '", B16, "'::varchar, ", IF(EXACT(C16, ""), "null", C16), "::bigint); ") -> PERFORM "SchData-OLTP-Master"."Func_TblInstitution_SET"(varSystemLoginSession::bigint, null::bigint, null::varchar, null::timestamptz, null::timestamptz, null::varchar, varInstitutionBranchID::bigint, varBaseCurrencyID::bigint, 'Departemen Dalam Negeri'::varchar, 141000000000014::bigint);
A17: =IF( COUNTIF( $D$4:$D$1000, $D17 ) = 1, "", "Duplicated") | B17: Duta Hita Jaya | C17: 141000000000004 | D17: =IF(EXACT($C17, ""), B17, CONCATENATE(VLOOKUP($C17, 'REF - InstitutionType'!$B$4:$E$102, 3, FALSE), IF(EXACT(VLOOKUP($C17, 'REF - InstitutionType'!$B$4:$E$102, 3, FALSE), ""), "", " "), $B17, "", VLOOKUP($C17, 'REF - InstitutionType'!$B$4:$E$102, 4, FALSE), IF(EXACT($E17, ""), "", " [a.k.a : "&$E17&"]"))) -> PT. Duta Hita Jaya | F17: DHJ | G17: Manufactur | H17: Fabrikator Tower | L17: Customer | N17: =N16 + IF(EXACT(O17, ""), 0, 1) -> 123000000000014 | O17: =CONCATENATE("PERFORM ""SchData-OLTP-Master"".""Func_TblInstitution_SET""(varSystemLoginSession::bigint, null::bigint, null::varchar, null::timestamptz, null::timestamptz, null::varchar, varInstitutionBranchID::bigint, varBaseCurrencyID::bigint, '", B17, "'::varchar, ", IF(EXACT(C17, ""), "null", C17), "::bigint); ") -> PERFORM "SchData-OLTP-Master"."Func_TblInstitution_SET"(varSystemLoginSession::bigint, null::bigint, null::varchar, null::timestamptz, null::timestamptz, null::varchar, varInstitutionBranchID::bigint, varBaseCurrencyID::bigint, 'Duta Hita Jaya'::varchar, 141000000000004::bigint);
A18: =IF( COUNTIF( $D$4:$D$1000, $D18 ) = 1, "", "Duplicated") | B18: Duta Pertiwi | C18: 141000000000005 | D18: =IF(EXACT($C18, ""), B18, CONCATENATE(VLOOKUP($C18, 'REF - InstitutionType'!$B$4:$E$102, 3, FALSE), IF(EXACT(VLOOKUP($C18, 'REF - InstitutionType'!$B$4:$E$102, 3, FALSE), ""), "", " "), $B18, "", VLOOKUP($C18, 'REF - InstitutionType'!$B$4:$E$102, 4, FALSE), IF(EXACT($E18, ""), "", " [a.k.a : "&$E18&"]"))) -> PT. Duta Pertiwi, Tbk | F18: DPS | L18: Customer | N18: =N17 + IF(EXACT(O18, ""), 0, 1) -> 123000000000015 | O18: =CONCATENATE("PERFORM ""SchData-OLTP-Master"".""Func_TblInstitution_SET""(varSystemLoginSession::bigint, null::bigint, null::varchar, null::timestamptz, null::timestamptz, null::varchar, varInstitutionBranchID::bigint, varBaseCurrencyID::bigint, '", B18, "'::varchar, ", IF(EXACT(C18, ""), "null", C18), "::bigint); ") -> PERFORM "SchData-OLTP-Master"."Func_TblInstitution_SET"(varSystemLoginSession::bigint, null::bigint, null::varchar, null::timestamptz, null::timestamptz, null::varchar, varInstitutionBranchID::bigint, varBaseCurrencyID::bigint, 'Duta Pertiwi'::varchar, 141000000000005::bigint);
A19: =IF( COUNTIF( $D$4:$D$1000, $D19 ) = 1, "", "Duplicated") -> Duplicated | B19: Duta Realtindo Perkasa | C19: 141000000000004 | D19: =IF(EXACT($C19, ""), B19, CONCATENATE(VLOOKUP($C19, 'REF - InstitutionType'!$B$4:$E$102, 3, FALSE), IF(EXACT(VLOOKUP($C19, 'REF - InstitutionType'!$B$4:$E$102, 3, FALSE), ""), "", " "), $B19, "", VLOOKUP($C19, 'REF - InstitutionType'!$B$4:$E$102, 4, FALSE), IF(EXACT($E19, ""), "", " [a.k.a : "&$E19&"]"))) -> PT. Duta Realtindo Perkasa | F19: DRP | L19: Customer | N19: =N18 + IF(EXACT(O19, ""), 0, 1) -> 123000000000016 | O19: =CONCATENATE("PERFORM ""SchData-OLTP-Master"".""Func_TblInstitution_SET""(varSystemLoginSession::bigint, null::bigint, null::varchar, null::timestamptz, null::timestamptz, null::varchar, varInstitutionBranchID::bigint, varBaseCurrencyID::bigint, '", B19, "'::varchar, ", IF(EXACT(C19, ""), "null", C19), "::bigint); ") -> PERFORM "SchData-OLTP-Master"."Func_TblInstitution_SET"(varSystemLoginSession::bigint, null::bigint, null::varchar, null::timestamptz, null::timestamptz, null::varchar, varInstitutionBranchID::bigint, varBaseCurrencyID::bigint, 'Duta Realtindo Perkasa'::varchar, 141000000000004::bigint);
A20: =IF( COUNTIF( $D$4:$D$1000, $D20 ) = 1, "", "Duplicated") -> Duplicated | B20: Energi Mekar Lestari | C20: 141000000000004 | D20: =IF(EXACT($C20, ""), B20, CONCATENATE(VLOOKUP($C20, 'REF - InstitutionType'!$B$4:$E$102, 3, FALSE), IF(EXACT(VLOOKUP($C20, 'REF - InstitutionType'!$B$4:$E$102, 3, FALSE), ""), "", " "), $B20, "", VLOOKUP($C20, 'REF - InstitutionType'!$B$4:$E$102, 4, FALSE), IF(EXACT($E20, ""), "", " [a.k.a : "&$E20&"]"))) -> PT. Energi Mekar Lestari | F20: EML | L20: Customer | N20: =N19 + IF(EXACT(O20, ""), 0, 1) -> 123000000000017 | O20: =CONCATENATE("PERFORM ""SchData-OLTP-Master"".""Func_TblInstitution_SET""(varSystemLoginSession::bigint, null::bigint, null::varchar, null::timestamptz, null::timestamptz, null::varchar, varInstitutionBranchID::bigint, varBaseCurrencyID::bigint, '", B20, "'::varchar, ", IF(EXACT(C20, ""), "null", C20), "::bigint); ") -> PERFORM "SchData-OLTP-Master"."Func_TblInstitution_SET"(varSystemLoginSession::bigint, null::bigint, null::varchar, null::timestamptz, null::timestamptz, null::varchar, varInstitutionBranchID::bigint, varBaseCurrencyID::bigint, 'Energi Mekar Lestari'::varchar, 141000000000004::bigint);
A21: =IF( COUNTIF( $D$4:$D$1000, $D21 ) = 1, "", "Duplicated") | B21: Ericsson Indonesia | C21: 141000000000004 | D21: =IF(EXACT($C21, ""), B21, CONCATENATE(VLOOKUP($C21, 'REF - InstitutionType'!$B$4:$E$102, 3, FALSE), IF(EXACT(VLOOKUP($C21, 'REF - InstitutionType'!$B$4:$E$102, 3, FALSE), ""), "", " "), $B21, "", VLOOKUP($C21, 'REF - InstitutionType'!$B$4:$E$102, 4, FALSE), IF(EXACT($E21, ""), "", " [a.k.a : "&$E21&"]"))) -> PT. Ericsson Indonesia | F21: ERI | L21: Customer | N21: =N20 + IF(EXACT(O21, ""), 0, 1) -> 123000000000018 | O21: =CONCATENATE("PERFORM ""SchData-OLTP-Master"".""Func_TblInstitution_SET""(varSystemLoginSession::bigint, null::bigint, null::varchar, null::timestamptz, null::timestamptz, null::varchar, varInstitutionBranchID::bigint, varBaseCurrencyID::bigint, '", B21, "'::varchar, ", IF(EXACT(C21, ""), "null", C21), "::bigint); ") -> PERFORM "SchData-OLTP-Master"."Func_TblInstitution_SET"(varSystemLoginSession::bigint, null::bigint, null::varchar, null::timestamptz, null::timestamptz, null::varchar, varInstitutionBranchID::bigint, varBaseCurrencyID::bigint, 'Ericsson Indonesia'::varchar, 141000000000004::bigint);
A22: =IF( COUNTIF( $D$4:$D$1000, $D22 ) = 1, "", "Duplicated") | B22: Esa Mitra Teknologi | C22: 141000000000004 | D22: =IF(EXACT($C22, ""), B22, CONCATENATE(VLOOKUP($C22, 'REF - InstitutionType'!$B$4:$E$102, 3, FALSE), IF(EXACT(VLOOKUP($C22, 'REF - InstitutionType'!$B$4:$E$102, 3, FALSE), ""), "", " "), $B22, "", VLOOKUP($C22, 'REF - InstitutionType'!$B$4:$E$102, 4, FALSE), IF(EXACT($E22, ""), "", " [a.k.a : "&$E22&"]"))) -> PT. Esa Mitra Teknologi | F22: ESA | L22: Customer | N22: =N21 + IF(EXACT(O22, ""), 0, 1) -> 123000000000019 | O22: =CONCATENATE("PERFORM ""SchData-OLTP-Master"".""Func_TblInstitution_SET""(varSystemLoginSession::bigint, null::bigint, null::varchar, null::timestamptz, null::timestamptz, null::varchar, varInstitutionBranchID::bigint, varBaseCurrencyID::bigint, '", B22, "'::varchar, ", IF(EXACT(C22, ""), "null", C22), "::bigint); ") -> PERFORM "SchData-OLTP-Master"."Func_TblInstitution_SET"(varSystemLoginSession::bigint, null::bigint, null::varchar, null::timestamptz, null::timestamptz, null::varchar, varInstitutionBranchID::bigint, varBaseCurrencyID::bigint, 'Esa Mitra Teknologi'::varchar, 141000000000004::bigint);
A23: =IF( COUNTIF( $D$4:$D$1000, $D23 ) = 1, "", "Duplicated") | B23: First Media | C23: 141000000000005 | D23: =IF(EXACT($C23, ""), B23, CONCATENATE(VLOOKUP($C23, 'REF - InstitutionType'!$B$4:$E$102, 3, FALSE), IF(EXACT(VLOOKUP($C23, 'REF - InstitutionType'!$B$4:$E$102, 3, FALSE), ""), "", " "), $B23, "", VLOOKUP($C23, 'REF - InstitutionType'!$B$4:$E$102, 4, FALSE), IF(EXACT($E23, ""), "", " [a.k.a : "&$E23&"]"))) -> PT. First Media, Tbk | F23: FIRST | L23: Customer | N23: =N22 + IF(EXACT(O23, ""), 0, 1) -> 123000000000020 | O23: =CONCATENATE("PERFORM ""SchData-OLTP-Master"".""Func_TblInstitution_SET""(varSystemLoginSession::bigint, null::bigint, null::varchar, null::timestamptz, null::timestamptz, null::varchar, varInstitutionBranchID::bigint, varBaseCurrencyID::bigint, '", B23, "'::varchar, ", IF(EXACT(C23, ""), "null", C23), "::bigint); ") -> PERFORM "SchData-OLTP-Master"."Func_TblInstitution_SET"(varSystemLoginSession::bigint, null::bigint, null::varchar, null::timestamptz, null::timestamptz, null::varchar, varInstitutionBranchID::bigint, varBaseCurrencyID::bigint, 'First Media'::varchar, 141000000000005::bigint);
A24: =IF( COUNTIF( $D$4:$D$1000, $D24 ) = 1, "", "Duplicated") | B24: Flexi | D24: =IF(EXACT($C24, ""), B24, CONCATENATE(VLOOKUP($C24, 'REF - InstitutionType'!$B$4:$E$102, 3, FALSE), IF(EXACT(VLOOKUP($C24, 'REF - InstitutionType'!$B$4:$E$102, 3, FALSE), ""), "", " "), $B24, "", VLOOKUP($C24, 'REF - InstitutionType'!$B$4:$E$102, 4, FALSE), IF(EXACT($E24, ""), "", " [a.k.a : "&$E24&"]"))) -> Flexi | F24: FLEX | L24: Customer | N24: =N23 + IF(EXACT(O24, ""), 0, 1) -> 123000000000021 | O24: =CONCATENATE("PERFORM ""SchData-OLTP-Master"".""Func_TblInstitution_SET""(varSystemLoginSession::bigint, null::bigint, null::varchar, null::timestamptz, null::timestamptz, null::varchar, varInstitutionBranchID::bigint, varBaseCurrencyID::bigint, '", B24, "'::varchar, ", IF(EXACT(C24, ""), "null", C24), "::bigint); ") -> PERFORM "SchData-OLTP-Master"."Func_TblInstitution_SET"(varSystemLoginSession::bigint, null::bigint, null::varchar, null::timestamptz, null::timestamptz, null::varchar, varInstitutionBranchID::bigint, varBaseCurrencyID::bigint, 'Flexi '::varchar, null::bigint);
A25: =IF( COUNTIF( $D$4:$D$1000, $D25 ) = 1, "", "Duplicated") | B25: Flexi Mitrayasa | D25: =IF(EXACT($C25, ""), B25, CONCATENATE(VLOOKUP($C25, 'REF - InstitutionType'!$B$4:$E$102, 3, FALSE), IF(EXACT(VLOOKUP($C25, 'REF - InstitutionType'!$B$4:$E$102, 3, FALSE), ""), "", " "), $B25, "", VLOOKUP($C25, 'REF - InstitutionType'!$B$4:$E$102, 4, FALSE), IF(EXACT($E25, ""), "", " [a.k.a : "&$E25&"]"))) -> Flexi Mitrayasa | F25: FLM | L25: Customer | N25: =N24 + IF(EXACT(O25, ""), 0, 1) -> 123000000000022 | O25: =CONCATENATE("PERFORM ""SchData-OLTP-Master"".""Func_TblInstitution_SET""(varSystemLoginSession::bigint, null::bigint, null::varchar, null::timestamptz, null::timestamptz, null::varchar, varInstitutionBranchID::bigint, varBaseCurrencyID::bigint, '", B25, "'::varchar, ", IF(EXACT(C25, ""), "null", C25), "::bigint); ") -> PERFORM "SchData-OLTP-Master"."Func_TblInstitution_SET"(varSystemLoginSession::bigint, null::bigint, null::varchar, null::timestamptz, null::timestamptz, null::varchar, varInstitutionBranchID::bigint, varBaseCurrencyID::bigint, 'Flexi Mitrayasa'::varchar, null::bigint);
A26: =IF( COUNTIF( $D$4:$D$1000, $D26 ) = 1, "", "Duplicated") | B26: Huawei Tech Investment | C26: 141000000000004 | D26: =IF(EXACT($C26, ""), B26, CONCATENATE(VLOOKUP($C26, 'REF - InstitutionType'!$B$4:$E$102, 3, FALSE), IF(EXACT(VLOOKUP($C26, 'REF - InstitutionType'!$B$4:$E$102, 3, FALSE), ""), "", " "), $B26, "", VLOOKUP($C26, 'REF - InstitutionType'!$B$4:$E$102, 4, FALSE), IF(EXACT($E26, ""), "", " [a.k.a : "&$E26&"]"))) -> PT. Huawei Tech Investment | F26: HWEI | L26: Customer | N26: =N25 + IF(EXACT(O26, ""), 0, 1) -> 123000000000023 | O26: =CONCATENATE("PERFORM ""SchData-OLTP-Master"".""Func_TblInstitution_SET""(varSystemLoginSession::bigint, null::bigint, null::varchar, null::timestamptz, null::timestamptz, null::varchar, varInstitutionBranchID::bigint, varBaseCurrencyID::bigint, '", B26, "'::varchar, ", IF(EXACT(C26, ""), "null", C26), "::bigint); ") -> PERFORM "SchData-OLTP-Master"."Func_TblInstitution_SET"(varSystemLoginSession::bigint, null::bigint, null::varchar, null::timestamptz, null::timestamptz, null::varchar, varInstitutionBranchID::bigint, varBaseCurrencyID::bigint, 'Huawei Tech Investment'::varchar, 141000000000004::bigint);
A27: =IF( COUNTIF( $D$4:$D$1000, $D27 ) = 1, "", "Duplicated") | B27: Hutchinson 3 Indonesia | C27: 141000000000004 | D27: =IF(EXACT($C27, ""), B27, CONCATENATE(VLOOKUP($C27, 'REF - InstitutionType'!$B$4:$E$102, 3, FALSE), IF(EXACT(VLOOKUP($C27, 'REF - InstitutionType'!$B$4:$E$102, 3, FALSE), ""), "", " "), $B27, "", VLOOKUP($C27, 'REF - InstitutionType'!$B$4:$E$102, 4, FALSE), IF(EXACT($E27, ""), "", " [a.k.a : "&$E27&"]"))) -> PT. Hutchinson 3 Indonesia | F27: HCPT | L27: Customer | N27: =N26 + IF(EXACT(O27, ""), 0, 1) -> 123000000000024 | O27: =CONCATENATE("PERFORM ""SchData-OLTP-Master"".""Func_TblInstitution_SET""(varSystemLoginSession::bigint, null::bigint, null::varchar, null::timestamptz, null::timestamptz, null::varchar, varInstitutionBranchID::bigint, varBaseCurrencyID::bigint, '", B27, "'::varchar, ", IF(EXACT(C27, ""), "null", C27), "::bigint); ") -> PERFORM "SchData-OLTP-Master"."Func_TblInstitution_SET"(varSystemLoginSession::bigint, null::bigint, null::varchar, null::timestamptz, null::timestamptz, null::varchar, varInstitutionBranchID::bigint, varBaseCurrencyID::bigint, 'Hutchinson 3 Indonesia'::varchar, 141000000000004::bigint);
A28: =IF( COUNTIF( $D$4:$D$1000, $D28 ) = 1, "", "Duplicated") | B28: Indoprima Seluler | C28: 141000000000004 | D28: =IF(EXACT($C28, ""), B28, CONCATENATE(VLOOKUP($C28, 'REF - InstitutionType'!$B$4:$E$102, 3, FALSE), IF(EXACT(VLOOKUP($C28, 'REF - InstitutionType'!$B$4:$E$102, 3, FALSE), ""), "", " "), $B28, "", VLOOKUP($C28, 'REF - InstitutionType'!$B$4:$E$102, 4, FALSE), IF(EXACT($E28, ""), "", " [a.k.a : "&$E28&"]"))) -> PT. Indoprima Seluler | F28: IDP | L28: Customer | N28: =N27 + IF(EXACT(O28, ""), 0, 1) -> 123000000000025 | O28: =CONCATENATE("PERFORM ""SchData-OLTP-Master"".""Func_TblInstitution_SET""(varSystemLoginSession::bigint, null::bigint, null::varchar, null::timestamptz, null::timestamptz, null::varchar, varInstitutionBranchID::bigint, varBaseCurrencyID::bigint, '", B28, "'::varchar, ", IF(EXACT(C28, ""), "null", C28), "::bigint); ") -> PERFORM "SchData-OLTP-Master"."Func_TblInstitution_SET"(varSystemLoginSession::bigint, null::bigint, null::varchar, null::timestamptz, null::timestamptz, null::varchar, varInstitutionBranchID::bigint, varBaseCurrencyID::bigint, 'Indoprima Seluler'::varchar, 141000000000004::bigint);
