Workbook

Sheet Source
B2: Source : erpdb.master_login

Sheet MAIN
B2: Person Name | D2: Photo Log_FileUpload_Pointer_RefID | E2: Nomor Induk Kependudukan | I2: SYS_PID Prediction | J2: SQL Syntax | K2: Bulk SQL Syntax
I3: 25000000000000
B4: Abdollah Syani Siregar | C4: Abdollah | I4: =I3 + IF(EXACT(J4, ""), 0, 1) -> 25000000000001 | J4: =IF(EXACT(B4, ""), "", CONCATENATE("PERFORM ""SchData-OLTP-Master"".""Func_TblPerson_SET""(varSystemLoginSession, null::bigint, null::varchar, null::timestamptz, null::timestamptz, null::varchar, varInstitutionBranchID, varBaseCurrencyID, '", B4, "'::varchar, null::bigint);")) -> PERFORM "SchData-OLTP-Master"."Func_TblPerson_SET"(varSystemLoginSession, null::bigint, null::varchar, null::timestamptz, null::timestamptz, null::varchar, varInstitutionBranchID, varBaseCurrencyID, 'Abdollah Syani Siregar'::varchar, null::bigint); | K4: =CONCATENATE( "varSQL := varSQL || (CASE WHEN (varSQL = '') THEN '' ELSE ', ' END) || (SELECT JSON_BUILD_OBJECT (", "'recordID', NULL::bigint,", "'entities', ", "JSON_BUILD_OBJECT (", "'sysLoginSession_RefID', varSystemLoginSession::bigint,", "'sysDataAnnotation', NULL::varchar,", "'sysDataSetDateTimeTZ', NULL::timestamptz,", "'sysDataValidityStartDateTimeTZ', NULL::timestamptz,", "'sysDataValidityFinishDateTimeTZ', NULL::timestamptz,", "'sysPartitionRemovableRecordKey_RefID', NULL::bigint,", "'sysBranch_RefID', varInstitutionBranchID::bigint,", "'sysBaseCurrency_RefID',varBaseCurrencyID::bigint,", "'name', ", IF(EXACT($B4, ""), "null", CONCATENATE("'", SUBSTITUTE($B4, "'", "\'"), "'")), "::varchar,", "'photo_Log_FileUpload_Pointer_RefID', ", IF(EXACT($D4, ""), "null", CONCATENATE("'", SUBSTITUTE($D4, "'", "\'"), "'")), "::bigint", ")))::varchar;") -> varSQL := varSQL || (CASE WHEN (varSQL = '') THEN '' ELSE ', ' END) || (SELECT JSON_BUILD_OBJECT ('recordID', NULL::bigint,'entities', JSON_BUILD_OBJECT ('sysLoginSession_RefID', varSystemLoginSession::bigint,'sysDataAnnotation', NULL::varchar,'sysDataSetDateTimeTZ', NULL::timestamptz,'sysDataValidityStartDateTimeTZ', NULL::timestamptz,'sysDataValidityFinishDateTimeTZ', NULL::timestamptz,'sysPartitionRemovableRecordKey_RefID', NULL::bigint,'sysBranch_RefID', varInstitutionBranchID::bigint,'sysBaseCurrency_RefID',varBaseCurrencyID::bigint,'name', 'Abdollah Syani Siregar'::varchar,'photo_Log_FileUpload_Pointer_RefID', null::bigint)))::varchar;
B5: Abdul Karim | C5: karim | I5: =I4 + IF(EXACT(J5, ""), 0, 1) -> 25000000000002 | J5: =IF(EXACT(B5, ""), "", CONCATENATE("PERFORM ""SchData-OLTP-Master"".""Func_TblPerson_SET""(varSystemLoginSession, null::bigint, null::varchar, null::timestamptz, null::timestamptz, null::varchar, varInstitutionBranchID, varBaseCurrencyID, '", B5, "'::varchar, null::bigint);")) -> PERFORM "SchData-OLTP-Master"."Func_TblPerson_SET"(varSystemLoginSession, null::bigint, null::varchar, null::timestamptz, null::timestamptz, null::varchar, varInstitutionBranchID, varBaseCurrencyID, 'Abdul Karim'::varchar, null::bigint); | K5: =CONCATENATE( "varSQL := varSQL || (CASE WHEN (varSQL = '') THEN '' ELSE ', ' END) || (SELECT JSON_BUILD_OBJECT (", "'recordID', NULL::bigint,", "'entities', ", "JSON_BUILD_OBJECT (", "'sysLoginSession_RefID', varSystemLoginSession::bigint,", "'sysDataAnnotation', NULL::varchar,", "'sysDataSetDateTimeTZ', NULL::timestamptz,", "'sysDataValidityStartDateTimeTZ', NULL::timestamptz,", "'sysDataValidityFinishDateTimeTZ', NULL::timestamptz,", "'sysPartitionRemovableRecordKey_RefID', NULL::bigint,", "'sysBranch_RefID', varInstitutionBranchID::bigint,", "'sysBaseCurrency_RefID',varBaseCurrencyID::bigint,", "'name', ", IF(EXACT($B5, ""), "null", CONCATENATE("'", SUBSTITUTE($B5, "'", "\'"), "'")), "::varchar,", "'photo_Log_FileUpload_Pointer_RefID', ", IF(EXACT($D5, ""), "null", CONCATENATE("'", SUBSTITUTE($D5, "'", "\'"), "'")), "::bigint", ")))::varchar;") -> varSQL := varSQL || (CASE WHEN (varSQL = '') THEN '' ELSE ', ' END) || (SELECT JSON_BUILD_OBJECT ('recordID', NULL::bigint,'entities', JSON_BUILD_OBJECT ('sysLoginSession_RefID', varSystemLoginSession::bigint,'sysDataAnnotation', NULL::varchar,'sysDataSetDateTimeTZ', NULL::timestamptz,'sysDataValidityStartDateTimeTZ', NULL::timestamptz,'sysDataValidityFinishDateTimeTZ', NULL::timestamptz,'sysPartitionRemovableRecordKey_RefID', NULL::bigint,'sysBranch_RefID', varInstitutionBranchID::bigint,'sysBaseCurrency_RefID',varBaseCurrencyID::bigint,'name', 'Abdul Karim'::varchar,'photo_Log_FileUpload_Pointer_RefID', null::bigint)))::varchar;
B6: Abdul Rahman Sitompul | C6: abdul | I6: =I5 + IF(EXACT(J6, ""), 0, 1) -> 25000000000003 | J6: =IF(EXACT(B6, ""), "", CONCATENATE("PERFORM ""SchData-OLTP-Master"".""Func_TblPerson_SET""(varSystemLoginSession, null::bigint, null::varchar, null::timestamptz, null::timestamptz, null::varchar, varInstitutionBranchID, varBaseCurrencyID, '", B6, "'::varchar, null::bigint);")) -> PERFORM "SchData-OLTP-Master"."Func_TblPerson_SET"(varSystemLoginSession, null::bigint, null::varchar, null::timestamptz, null::timestamptz, null::varchar, varInstitutionBranchID, varBaseCurrencyID, 'Abdul Rahman Sitompul'::varchar, null::bigint); | K6: =CONCATENATE( "varSQL := varSQL || (CASE WHEN (varSQL = '') THEN '' ELSE ', ' END) || (SELECT JSON_BUILD_OBJECT (", "'recordID', NULL::bigint,", "'entities', ", "JSON_BUILD_OBJECT (", "'sysLoginSession_RefID', varSystemLoginSession::bigint,", "'sysDataAnnotation', NULL::varchar,", "'sysDataSetDateTimeTZ', NULL::timestamptz,", "'sysDataValidityStartDateTimeTZ', NULL::timestamptz,", "'sysDataValidityFinishDateTimeTZ', NULL::timestamptz,", "'sysPartitionRemovableRecordKey_RefID', NULL::bigint,", "'sysBranch_RefID', varInstitutionBranchID::bigint,", "'sysBaseCurrency_RefID',varBaseCurrencyID::bigint,", "'name', ", IF(EXACT($B6, ""), "null", CONCATENATE("'", SUBSTITUTE($B6, "'", "\'"), "'")), "::varchar,", "'photo_Log_FileUpload_Pointer_RefID', ", IF(EXACT($D6, ""), "null", CONCATENATE("'", SUBSTITUTE($D6, "'", "\'"), "'")), "::bigint", ")))::varchar;") -> varSQL := varSQL || (CASE WHEN (varSQL = '') THEN '' ELSE ', ' END) || (SELECT JSON_BUILD_OBJECT ('recordID', NULL::bigint,'entities', JSON_BUILD_OBJECT ('sysLoginSession_RefID', varSystemLoginSession::bigint,'sysDataAnnotation', NULL::varchar,'sysDataSetDateTimeTZ', NULL::timestamptz,'sysDataValidityStartDateTimeTZ', NULL::timestamptz,'sysDataValidityFinishDateTimeTZ', NULL::timestamptz,'sysPartitionRemovableRecordKey_RefID', NULL::bigint,'sysBranch_RefID', varInstitutionBranchID::bigint,'sysBaseCurrency_RefID',varBaseCurrencyID::bigint,'name', 'Abdul Rahman Sitompul'::varchar,'photo_Log_FileUpload_Pointer_RefID', null::bigint)))::varchar;
B7: Abdul Risan | C7: abdul.risan | I7: =I6 + IF(EXACT(J7, ""), 0, 1) -> 25000000000004 | J7: =IF(EXACT(B7, ""), "", CONCATENATE("PERFORM ""SchData-OLTP-Master"".""Func_TblPerson_SET""(varSystemLoginSession, null::bigint, null::varchar, null::timestamptz, null::timestamptz, null::varchar, varInstitutionBranchID, varBaseCurrencyID, '", B7, "'::varchar, null::bigint);")) -> PERFORM "SchData-OLTP-Master"."Func_TblPerson_SET"(varSystemLoginSession, null::bigint, null::varchar, null::timestamptz, null::timestamptz, null::varchar, varInstitutionBranchID, varBaseCurrencyID, 'Abdul Risan'::varchar, null::bigint); | K7: =CONCATENATE( "varSQL := varSQL || (CASE WHEN (varSQL = '') THEN '' ELSE ', ' END) || (SELECT JSON_BUILD_OBJECT (", "'recordID', NULL::bigint,", "'entities', ", "JSON_BUILD_OBJECT (", "'sysLoginSession_RefID', varSystemLoginSession::bigint,", "'sysDataAnnotation', NULL::varchar,", "'sysDataSetDateTimeTZ', NULL::timestamptz,", "'sysDataValidityStartDateTimeTZ', NULL::timestamptz,", "'sysDataValidityFinishDateTimeTZ', NULL::timestamptz,", "'sysPartitionRemovableRecordKey_RefID', NULL::bigint,", "'sysBranch_RefID', varInstitutionBranchID::bigint,", "'sysBaseCurrency_RefID',varBaseCurrencyID::bigint,", "'name', ", IF(EXACT($B7, ""), "null", CONCATENATE("'", SUBSTITUTE($B7, "'", "\'"), "'")), "::varchar,", "'photo_Log_FileUpload_Pointer_RefID', ", IF(EXACT($D7, ""), "null", CONCATENATE("'", SUBSTITUTE($D7, "'", "\'"), "'")), "::bigint", ")))::varchar;") -> varSQL := varSQL || (CASE WHEN (varSQL = '') THEN '' ELSE ', ' END) || (SELECT JSON_BUILD_OBJECT ('recordID', NULL::bigint,'entities', JSON_BUILD_OBJECT ('sysLoginSession_RefID', varSystemLoginSession::bigint,'sysDataAnnotation', NULL::varchar,'sysDataSetDateTimeTZ', NULL::timestamptz,'sysDataValidityStartDateTimeTZ', NULL::timestamptz,'sysDataValidityFinishDateTimeTZ', NULL::timestamptz,'sysPartitionRemovableRecordKey_RefID', NULL::bigint,'sysBranch_RefID', varInstitutionBranchID::bigint,'sysBaseCurrency_RefID',varBaseCurrencyID::bigint,'name', 'Abdul Risan'::varchar,'photo_Log_FileUpload_Pointer_RefID', null::bigint)))::varchar;
B8: Abdullah Nabil | C8: nabil | I8: =I7 + IF(EXACT(J8, ""), 0, 1) -> 25000000000005 | J8: =IF(EXACT(B8, ""), "", CONCATENATE("PERFORM ""SchData-OLTP-Master"".""Func_TblPerson_SET""(varSystemLoginSession, null::bigint, null::varchar, null::timestamptz, null::timestamptz, null::varchar, varInstitutionBranchID, varBaseCurrencyID, '", B8, "'::varchar, null::bigint);")) -> PERFORM "SchData-OLTP-Master"."Func_TblPerson_SET"(varSystemLoginSession, null::bigint, null::varchar, null::timestamptz, null::timestamptz, null::varchar, varInstitutionBranchID, varBaseCurrencyID, 'Abdullah Nabil'::varchar, null::bigint); | K8: =CONCATENATE( "varSQL := varSQL || (CASE WHEN (varSQL = '') THEN '' ELSE ', ' END) || (SELECT JSON_BUILD_OBJECT (", "'recordID', NULL::bigint,", "'entities', ", "JSON_BUILD_OBJECT (", "'sysLoginSession_RefID', varSystemLoginSession::bigint,", "'sysDataAnnotation', NULL::varchar,", "'sysDataSetDateTimeTZ', NULL::timestamptz,", "'sysDataValidityStartDateTimeTZ', NULL::timestamptz,", "'sysDataValidityFinishDateTimeTZ', NULL::timestamptz,", "'sysPartitionRemovableRecordKey_RefID', NULL::bigint,", "'sysBranch_RefID', varInstitutionBranchID::bigint,", "'sysBaseCurrency_RefID',varBaseCurrencyID::bigint,", "'name', ", IF(EXACT($B8, ""), "null", CONCATENATE("'", SUBSTITUTE($B8, "'", "\'"), "'")), "::varchar,", "'photo_Log_FileUpload_Pointer_RefID', ", IF(EXACT($D8, ""), "null", CONCATENATE("'", SUBSTITUTE($D8, "'", "\'"), "'")), "::bigint", ")))::varchar;") -> varSQL := varSQL || (CASE WHEN (varSQL = '') THEN '' ELSE ', ' END) || (SELECT JSON_BUILD_OBJECT ('recordID', NULL::bigint,'entities', JSON_BUILD_OBJECT ('sysLoginSession_RefID', varSystemLoginSession::bigint,'sysDataAnnotation', NULL::varchar,'sysDataSetDateTimeTZ', NULL::timestamptz,'sysDataValidityStartDateTimeTZ', NULL::timestamptz,'sysDataValidityFinishDateTimeTZ', NULL::timestamptz,'sysPartitionRemovableRecordKey_RefID', NULL::bigint,'sysBranch_RefID', varInstitutionBranchID::bigint,'sysBaseCurrency_RefID',varBaseCurrencyID::bigint,'name', 'Abdullah Nabil'::varchar,'photo_Log_FileUpload_Pointer_RefID', null::bigint)))::varchar;
B9: Adhitya Danar | C9: adhitya | I9: =I8 + IF(EXACT(J9, ""), 0, 1) -> 25000000000006 | J9: =IF(EXACT(B9, ""), "", CONCATENATE("PERFORM ""SchData-OLTP-Master"".""Func_TblPerson_SET""(varSystemLoginSession, null::bigint, null::varchar, null::timestamptz, null::timestamptz, null::varchar, varInstitutionBranchID, varBaseCurrencyID, '", B9, "'::varchar, null::bigint);")) -> PERFORM "SchData-OLTP-Master"."Func_TblPerson_SET"(varSystemLoginSession, null::bigint, null::varchar, null::timestamptz, null::timestamptz, null::varchar, varInstitutionBranchID, varBaseCurrencyID, 'Adhitya Danar'::varchar, null::bigint); | K9: =CONCATENATE( "varSQL := varSQL || (CASE WHEN (varSQL = '') THEN '' ELSE ', ' END) || (SELECT JSON_BUILD_OBJECT (", "'recordID', NULL::bigint,", "'entities', ", "JSON_BUILD_OBJECT (", "'sysLoginSession_RefID', varSystemLoginSession::bigint,", "'sysDataAnnotation', NULL::varchar,", "'sysDataSetDateTimeTZ', NULL::timestamptz,", "'sysDataValidityStartDateTimeTZ', NULL::timestamptz,", "'sysDataValidityFinishDateTimeTZ', NULL::timestamptz,", "'sysPartitionRemovableRecordKey_RefID', NULL::bigint,", "'sysBranch_RefID', varInstitutionBranchID::bigint,", "'sysBaseCurrency_RefID',varBaseCurrencyID::bigint,", "'name', ", IF(EXACT($B9, ""), "null", CONCATENATE("'", SUBSTITUTE($B9, "'", "\'"), "'")), "::varchar,", "'photo_Log_FileUpload_Pointer_RefID', ", IF(EXACT($D9, ""), "null", CONCATENATE("'", SUBSTITUTE($D9, "'", "\'"), "'")), "::bigint", ")))::varchar;") -> varSQL := varSQL || (CASE WHEN (varSQL = '') THEN '' ELSE ', ' END) || (SELECT JSON_BUILD_OBJECT ('recordID', NULL::bigint,'entities', JSON_BUILD_OBJECT ('sysLoginSession_RefID', varSystemLoginSession::bigint,'sysDataAnnotation', NULL::varchar,'sysDataSetDateTimeTZ', NULL::timestamptz,'sysDataValidityStartDateTimeTZ', NULL::timestamptz,'sysDataValidityFinishDateTimeTZ', NULL::timestamptz,'sysPartitionRemovableRecordKey_RefID', NULL::bigint,'sysBranch_RefID', varInstitutionBranchID::bigint,'sysBaseCurrency_RefID',varBaseCurrencyID::bigint,'name', 'Adhitya Danar'::varchar,'photo_Log_FileUpload_Pointer_RefID', null::bigint)))::varchar;
B10: Adi Ruswandi | C10: adi | I10: =I9 + IF(EXACT(J10, ""), 0, 1) -> 25000000000007 | J10: =IF(EXACT(B10, ""), "", CONCATENATE("PERFORM ""SchData-OLTP-Master"".""Func_TblPerson_SET""(varSystemLoginSession, null::bigint, null::varchar, null::timestamptz, null::timestamptz, null::varchar, varInstitutionBranchID, varBaseCurrencyID, '", B10, "'::varchar, null::bigint);")) -> PERFORM "SchData-OLTP-Master"."Func_TblPerson_SET"(varSystemLoginSession, null::bigint, null::varchar, null::timestamptz, null::timestamptz, null::varchar, varInstitutionBranchID, varBaseCurrencyID, 'Adi Ruswandi'::varchar, null::bigint); | K10: =CONCATENATE( "varSQL := varSQL || (CASE WHEN (varSQL = '') THEN '' ELSE ', ' END) || (SELECT JSON_BUILD_OBJECT (", "'recordID', NULL::bigint,", "'entities', ", "JSON_BUILD_OBJECT (", "'sysLoginSession_RefID', varSystemLoginSession::bigint,", "'sysDataAnnotation', NULL::varchar,", "'sysDataSetDateTimeTZ', NULL::timestamptz,", "'sysDataValidityStartDateTimeTZ', NULL::timestamptz,", "'sysDataValidityFinishDateTimeTZ', NULL::timestamptz,", "'sysPartitionRemovableRecordKey_RefID', NULL::bigint,", "'sysBranch_RefID', varInstitutionBranchID::bigint,", "'sysBaseCurrency_RefID',varBaseCurrencyID::bigint,", "'name', ", IF(EXACT($B10, ""), "null", CONCATENATE("'", SUBSTITUTE($B10, "'", "\'"), "'")), "::varchar,", "'photo_Log_FileUpload_Pointer_RefID', ", IF(EXACT($D10, ""), "null", CONCATENATE("'", SUBSTITUTE($D10, "'", "\'"), "'")), "::bigint", ")))::varchar;") -> varSQL := varSQL || (CASE WHEN (varSQL = '') THEN '' ELSE ', ' END) || (SELECT JSON_BUILD_OBJECT ('recordID', NULL::bigint,'entities', JSON_BUILD_OBJECT ('sysLoginSession_RefID', varSystemLoginSession::bigint,'sysDataAnnotation', NULL::varchar,'sysDataSetDateTimeTZ', NULL::timestamptz,'sysDataValidityStartDateTimeTZ', NULL::timestamptz,'sysDataValidityFinishDateTimeTZ', NULL::timestamptz,'sysPartitionRemovableRecordKey_RefID', NULL::bigint,'sysBranch_RefID', varInstitutionBranchID::bigint,'sysBaseCurrency_RefID',varBaseCurrencyID::bigint,'name', 'Adi Ruswandi'::varchar,'photo_Log_FileUpload_Pointer_RefID', null::bigint)))::varchar;
B11: Adietya Dharmawan | C11: adietya.dharmawan | I11: =I10 + IF(EXACT(J11, ""), 0, 1) -> 25000000000008 | J11: =IF(EXACT(B11, ""), "", CONCATENATE("PERFORM ""SchData-OLTP-Master"".""Func_TblPerson_SET""(varSystemLoginSession, null::bigint, null::varchar, null::timestamptz, null::timestamptz, null::varchar, varInstitutionBranchID, varBaseCurrencyID, '", B11, "'::varchar, null::bigint);")) -> PERFORM "SchData-OLTP-Master"."Func_TblPerson_SET"(varSystemLoginSession, null::bigint, null::varchar, null::timestamptz, null::timestamptz, null::varchar, varInstitutionBranchID, varBaseCurrencyID, 'Adietya Dharmawan'::varchar, null::bigint); | K11: =CONCATENATE( "varSQL := varSQL || (CASE WHEN (varSQL = '') THEN '' ELSE ', ' END) || (SELECT JSON_BUILD_OBJECT (", "'recordID', NULL::bigint,", "'entities', ", "JSON_BUILD_OBJECT (", "'sysLoginSession_RefID', varSystemLoginSession::bigint,", "'sysDataAnnotation', NULL::varchar,", "'sysDataSetDateTimeTZ', NULL::timestamptz,", "'sysDataValidityStartDateTimeTZ', NULL::timestamptz,", "'sysDataValidityFinishDateTimeTZ', NULL::timestamptz,", "'sysPartitionRemovableRecordKey_RefID', NULL::bigint,", "'sysBranch_RefID', varInstitutionBranchID::bigint,", "'sysBaseCurrency_RefID',varBaseCurrencyID::bigint,", "'name', ", IF(EXACT($B11, ""), "null", CONCATENATE("'", SUBSTITUTE($B11, "'", "\'"), "'")), "::varchar,", "'photo_Log_FileUpload_Pointer_RefID', ", IF(EXACT($D11, ""), "null", CONCATENATE("'", SUBSTITUTE($D11, "'", "\'"), "'")), "::bigint", ")))::varchar;") -> varSQL := varSQL || (CASE WHEN (varSQL = '') THEN '' ELSE ', ' END) || (SELECT JSON_BUILD_OBJECT ('recordID', NULL::bigint,'entities', JSON_BUILD_OBJECT ('sysLoginSession_RefID', varSystemLoginSession::bigint,'sysDataAnnotation', NULL::varchar,'sysDataSetDateTimeTZ', NULL::timestamptz,'sysDataValidityStartDateTimeTZ', NULL::timestamptz,'sysDataValidityFinishDateTimeTZ', NULL::timestamptz,'sysPartitionRemovableRecordKey_RefID', NULL::bigint,'sysBranch_RefID', varInstitutionBranchID::bigint,'sysBaseCurrency_RefID',varBaseCurrencyID::bigint,'name', 'Adietya Dharmawan'::varchar,'photo_Log_FileUpload_Pointer_RefID', null::bigint)))::varchar;
B12: Aditya Yudha Prawira | C12: aditya | I12: =I11 + IF(EXACT(J12, ""), 0, 1) -> 25000000000009 | J12: =IF(EXACT(B12, ""), "", CONCATENATE("PERFORM ""SchData-OLTP-Master"".""Func_TblPerson_SET""(varSystemLoginSession, null::bigint, null::varchar, null::timestamptz, null::timestamptz, null::varchar, varInstitutionBranchID, varBaseCurrencyID, '", B12, "'::varchar, null::bigint);")) -> PERFORM "SchData-OLTP-Master"."Func_TblPerson_SET"(varSystemLoginSession, null::bigint, null::varchar, null::timestamptz, null::timestamptz, null::varchar, varInstitutionBranchID, varBaseCurrencyID, 'Aditya Yudha Prawira'::varchar, null::bigint); | K12: =CONCATENATE( "varSQL := varSQL || (CASE WHEN (varSQL = '') THEN '' ELSE ', ' END) || (SELECT JSON_BUILD_OBJECT (", "'recordID', NULL::bigint,", "'entities', ", "JSON_BUILD_OBJECT (", "'sysLoginSession_RefID', varSystemLoginSession::bigint,", "'sysDataAnnotation', NULL::varchar,", "'sysDataSetDateTimeTZ', NULL::timestamptz,", "'sysDataValidityStartDateTimeTZ', NULL::timestamptz,", "'sysDataValidityFinishDateTimeTZ', NULL::timestamptz,", "'sysPartitionRemovableRecordKey_RefID', NULL::bigint,", "'sysBranch_RefID', varInstitutionBranchID::bigint,", "'sysBaseCurrency_RefID',varBaseCurrencyID::bigint,", "'name', ", IF(EXACT($B12, ""), "null", CONCATENATE("'", SUBSTITUTE($B12, "'", "\'"), "'")), "::varchar,", "'photo_Log_FileUpload_Pointer_RefID', ", IF(EXACT($D12, ""), "null", CONCATENATE("'", SUBSTITUTE($D12, "'", "\'"), "'")), "::bigint", ")))::varchar;") -> varSQL := varSQL || (CASE WHEN (varSQL = '') THEN '' ELSE ', ' END) || (SELECT JSON_BUILD_OBJECT ('recordID', NULL::bigint,'entities', JSON_BUILD_OBJECT ('sysLoginSession_RefID', varSystemLoginSession::bigint,'sysDataAnnotation', NULL::varchar,'sysDataSetDateTimeTZ', NULL::timestamptz,'sysDataValidityStartDateTimeTZ', NULL::timestamptz,'sysDataValidityFinishDateTimeTZ', NULL::timestamptz,'sysPartitionRemovableRecordKey_RefID', NULL::bigint,'sysBranch_RefID', varInstitutionBranchID::bigint,'sysBaseCurrency_RefID',varBaseCurrencyID::bigint,'name', 'Aditya Yudha Prawira'::varchar,'photo_Log_FileUpload_Pointer_RefID', null::bigint)))::varchar;
B13: Adli Margie | C13: adli | I13: =I12 + IF(EXACT(J13, ""), 0, 1) -> 25000000000010 | J13: =IF(EXACT(B13, ""), "", CONCATENATE("PERFORM ""SchData-OLTP-Master"".""Func_TblPerson_SET""(varSystemLoginSession, null::bigint, null::varchar, null::timestamptz, null::timestamptz, null::varchar, varInstitutionBranchID, varBaseCurrencyID, '", B13, "'::varchar, null::bigint);")) -> PERFORM "SchData-OLTP-Master"."Func_TblPerson_SET"(varSystemLoginSession, null::bigint, null::varchar, null::timestamptz, null::timestamptz, null::varchar, varInstitutionBranchID, varBaseCurrencyID, 'Adli Margie'::varchar, null::bigint); | K13: =CONCATENATE( "varSQL := varSQL || (CASE WHEN (varSQL = '') THEN '' ELSE ', ' END) || (SELECT JSON_BUILD_OBJECT (", "'recordID', NULL::bigint,", "'entities', ", "JSON_BUILD_OBJECT (", "'sysLoginSession_RefID', varSystemLoginSession::bigint,", "'sysDataAnnotation', NULL::varchar,", "'sysDataSetDateTimeTZ', NULL::timestamptz,", "'sysDataValidityStartDateTimeTZ', NULL::timestamptz,", "'sysDataValidityFinishDateTimeTZ', NULL::timestamptz,", "'sysPartitionRemovableRecordKey_RefID', NULL::bigint,", "'sysBranch_RefID', varInstitutionBranchID::bigint,", "'sysBaseCurrency_RefID',varBaseCurrencyID::bigint,", "'name', ", IF(EXACT($B13, ""), "null", CONCATENATE("'", SUBSTITUTE($B13, "'", "\'"), "'")), "::varchar,", "'photo_Log_FileUpload_Pointer_RefID', ", IF(EXACT($D13, ""), "null", CONCATENATE("'", SUBSTITUTE($D13, "'", "\'"), "'")), "::bigint", ")))::varchar;") -> varSQL := varSQL || (CASE WHEN (varSQL = '') THEN '' ELSE ', ' END) || (SELECT JSON_BUILD_OBJECT ('recordID', NULL::bigint,'entities', JSON_BUILD_OBJECT ('sysLoginSession_RefID', varSystemLoginSession::bigint,'sysDataAnnotation', NULL::varchar,'sysDataSetDateTimeTZ', NULL::timestamptz,'sysDataValidityStartDateTimeTZ', NULL::timestamptz,'sysDataValidityFinishDateTimeTZ', NULL::timestamptz,'sysPartitionRemovableRecordKey_RefID', NULL::bigint,'sysBranch_RefID', varInstitutionBranchID::bigint,'sysBaseCurrency_RefID',varBaseCurrencyID::bigint,'name', 'Adli Margie'::varchar,'photo_Log_FileUpload_Pointer_RefID', null::bigint)))::varchar;
B14: Afrida Eka Putri | C14: afrida | I14: =I13 + IF(EXACT(J14, ""), 0, 1) -> 25000000000011 | J14: =IF(EXACT(B14, ""), "", CONCATENATE("PERFORM ""SchData-OLTP-Master"".""Func_TblPerson_SET""(varSystemLoginSession, null::bigint, null::varchar, null::timestamptz, null::timestamptz, null::varchar, varInstitutionBranchID, varBaseCurrencyID, '", B14, "'::varchar, null::bigint);")) -> PERFORM "SchData-OLTP-Master"."Func_TblPerson_SET"(varSystemLoginSession, null::bigint, null::varchar, null::timestamptz, null::timestamptz, null::varchar, varInstitutionBranchID, varBaseCurrencyID, 'Afrida Eka Putri'::varchar, null::bigint); | K14: =CONCATENATE( "varSQL := varSQL || (CASE WHEN (varSQL = '') THEN '' ELSE ', ' END) || (SELECT JSON_BUILD_OBJECT (", "'recordID', NULL::bigint,", "'entities', ", "JSON_BUILD_OBJECT (", "'sysLoginSession_RefID', varSystemLoginSession::bigint,", "'sysDataAnnotation', NULL::varchar,", "'sysDataSetDateTimeTZ', NULL::timestamptz,", "'sysDataValidityStartDateTimeTZ', NULL::timestamptz,", "'sysDataValidityFinishDateTimeTZ', NULL::timestamptz,", "'sysPartitionRemovableRecordKey_RefID', NULL::bigint,", "'sysBranch_RefID', varInstitutionBranchID::bigint,", "'sysBaseCurrency_RefID',varBaseCurrencyID::bigint,", "'name', ", IF(EXACT($B14, ""), "null", CONCATENATE("'", SUBSTITUTE($B14, "'", "\'"), "'")), "::varchar,", "'photo_Log_FileUpload_Pointer_RefID', ", IF(EXACT($D14, ""), "null", CONCATENATE("'", SUBSTITUTE($D14, "'", "\'"), "'")), "::bigint", ")))::varchar;") -> varSQL := varSQL || (CASE WHEN (varSQL = '') THEN '' ELSE ', ' END) || (SELECT JSON_BUILD_OBJECT ('recordID', NULL::bigint,'entities', JSON_BUILD_OBJECT ('sysLoginSession_RefID', varSystemLoginSession::bigint,'sysDataAnnotation', NULL::varchar,'sysDataSetDateTimeTZ', NULL::timestamptz,'sysDataValidityStartDateTimeTZ', NULL::timestamptz,'sysDataValidityFinishDateTimeTZ', NULL::timestamptz,'sysPartitionRemovableRecordKey_RefID', NULL::bigint,'sysBranch_RefID', varInstitutionBranchID::bigint,'sysBaseCurrency_RefID',varBaseCurrencyID::bigint,'name', 'Afrida Eka Putri'::varchar,'photo_Log_FileUpload_Pointer_RefID', null::bigint)))::varchar;
B15: Agnes Sutedja | C15: agnes | E15: 3173054608700001 | I15: =I14 + IF(EXACT(J15, ""), 0, 1) -> 25000000000012 | J15: =IF(EXACT(B15, ""), "", CONCATENATE("PERFORM ""SchData-OLTP-Master"".""Func_TblPerson_SET""(varSystemLoginSession, null::bigint, null::varchar, null::timestamptz, null::timestamptz, null::varchar, varInstitutionBranchID, varBaseCurrencyID, '", B15, "'::varchar, null::bigint);")) -> PERFORM "SchData-OLTP-Master"."Func_TblPerson_SET"(varSystemLoginSession, null::bigint, null::varchar, null::timestamptz, null::timestamptz, null::varchar, varInstitutionBranchID, varBaseCurrencyID, 'Agnes Sutedja'::varchar, null::bigint); | K15: =CONCATENATE( "varSQL := varSQL || (CASE WHEN (varSQL = '') THEN '' ELSE ', ' END) || (SELECT JSON_BUILD_OBJECT (", "'recordID', NULL::bigint,", "'entities', ", "JSON_BUILD_OBJECT (", "'sysLoginSession_RefID', varSystemLoginSession::bigint,", "'sysDataAnnotation', NULL::varchar,", "'sysDataSetDateTimeTZ', NULL::timestamptz,", "'sysDataValidityStartDateTimeTZ', NULL::timestamptz,", "'sysDataValidityFinishDateTimeTZ', NULL::timestamptz,", "'sysPartitionRemovableRecordKey_RefID', NULL::bigint,", "'sysBranch_RefID', varInstitutionBranchID::bigint,", "'sysBaseCurrency_RefID',varBaseCurrencyID::bigint,", "'name', ", IF(EXACT($B15, ""), "null", CONCATENATE("'", SUBSTITUTE($B15, "'", "\'"), "'")), "::varchar,", "'photo_Log_FileUpload_Pointer_RefID', ", IF(EXACT($D15, ""), "null", CONCATENATE("'", SUBSTITUTE($D15, "'", "\'"), "'")), "::bigint", ")))::varchar;") -> varSQL := varSQL || (CASE WHEN (varSQL = '') THEN '' ELSE ', ' END) || (SELECT JSON_BUILD_OBJECT ('recordID', NULL::bigint,'entities', JSON_BUILD_OBJECT ('sysLoginSession_RefID', varSystemLoginSession::bigint,'sysDataAnnotation', NULL::varchar,'sysDataSetDateTimeTZ', NULL::timestamptz,'sysDataValidityStartDateTimeTZ', NULL::timestamptz,'sysDataValidityFinishDateTimeTZ', NULL::timestamptz,'sysPartitionRemovableRecordKey_RefID', NULL::bigint,'sysBranch_RefID', varInstitutionBranchID::bigint,'sysBaseCurrency_RefID',varBaseCurrencyID::bigint,'name', 'Agnes Sutedja'::varchar,'photo_Log_FileUpload_Pointer_RefID', null::bigint)))::varchar;
B16: Agung Hendarto | C16: hendarto | I16: =I15 + IF(EXACT(J16, ""), 0, 1) -> 25000000000013 | J16: =IF(EXACT(B16, ""), "", CONCATENATE("PERFORM ""SchData-OLTP-Master"".""Func_TblPerson_SET""(varSystemLoginSession, null::bigint, null::varchar, null::timestamptz, null::timestamptz, null::varchar, varInstitutionBranchID, varBaseCurrencyID, '", B16, "'::varchar, null::bigint);")) -> PERFORM "SchData-OLTP-Master"."Func_TblPerson_SET"(varSystemLoginSession, null::bigint, null::varchar, null::timestamptz, null::timestamptz, null::varchar, varInstitutionBranchID, varBaseCurrencyID, 'Agung Hendarto'::varchar, null::bigint); | K16: =CONCATENATE( "varSQL := varSQL || (CASE WHEN (varSQL = '') THEN '' ELSE ', ' END) || (SELECT JSON_BUILD_OBJECT (", "'recordID', NULL::bigint,", "'entities', ", "JSON_BUILD_OBJECT (", "'sysLoginSession_RefID', varSystemLoginSession::bigint,", "'sysDataAnnotation', NULL::varchar,", "'sysDataSetDateTimeTZ', NULL::timestamptz,", "'sysDataValidityStartDateTimeTZ', NULL::timestamptz,", "'sysDataValidityFinishDateTimeTZ', NULL::timestamptz,", "'sysPartitionRemovableRecordKey_RefID', NULL::bigint,", "'sysBranch_RefID', varInstitutionBranchID::bigint,", "'sysBaseCurrency_RefID',varBaseCurrencyID::bigint,", "'name', ", IF(EXACT($B16, ""), "null", CONCATENATE("'", SUBSTITUTE($B16, "'", "\'"), "'")), "::varchar,", "'photo_Log_FileUpload_Pointer_RefID', ", IF(EXACT($D16, ""), "null", CONCATENATE("'", SUBSTITUTE($D16, "'", "\'"), "'")), "::bigint", ")))::varchar;") -> varSQL := varSQL || (CASE WHEN (varSQL = '') THEN '' ELSE ', ' END) || (SELECT JSON_BUILD_OBJECT ('recordID', NULL::bigint,'entities', JSON_BUILD_OBJECT ('sysLoginSession_RefID', varSystemLoginSession::bigint,'sysDataAnnotation', NULL::varchar,'sysDataSetDateTimeTZ', NULL::timestamptz,'sysDataValidityStartDateTimeTZ', NULL::timestamptz,'sysDataValidityFinishDateTimeTZ', NULL::timestamptz,'sysPartitionRemovableRecordKey_RefID', NULL::bigint,'sysBranch_RefID', varInstitutionBranchID::bigint,'sysBaseCurrency_RefID',varBaseCurrencyID::bigint,'name', 'Agung Hendarto'::varchar,'photo_Log_FileUpload_Pointer_RefID', null::bigint)))::varchar;
B17: Agus Priyatno Mahmudo | C17: agusp | I17: =I16 + IF(EXACT(J17, ""), 0, 1) -> 25000000000014 | J17: =IF(EXACT(B17, ""), "", CONCATENATE("PERFORM ""SchData-OLTP-Master"".""Func_TblPerson_SET""(varSystemLoginSession, null::bigint, null::varchar, null::timestamptz, null::timestamptz, null::varchar, varInstitutionBranchID, varBaseCurrencyID, '", B17, "'::varchar, null::bigint);")) -> PERFORM "SchData-OLTP-Master"."Func_TblPerson_SET"(varSystemLoginSession, null::bigint, null::varchar, null::timestamptz, null::timestamptz, null::varchar, varInstitutionBranchID, varBaseCurrencyID, 'Agus Priyatno Mahmudo'::varchar, null::bigint); | K17: =CONCATENATE( "varSQL := varSQL || (CASE WHEN (varSQL = '') THEN '' ELSE ', ' END) || (SELECT JSON_BUILD_OBJECT (", "'recordID', NULL::bigint,", "'entities', ", "JSON_BUILD_OBJECT (", "'sysLoginSession_RefID', varSystemLoginSession::bigint,", "'sysDataAnnotation', NULL::varchar,", "'sysDataSetDateTimeTZ', NULL::timestamptz,", "'sysDataValidityStartDateTimeTZ', NULL::timestamptz,", "'sysDataValidityFinishDateTimeTZ', NULL::timestamptz,", "'sysPartitionRemovableRecordKey_RefID', NULL::bigint,", "'sysBranch_RefID', varInstitutionBranchID::bigint,", "'sysBaseCurrency_RefID',varBaseCurrencyID::bigint,", "'name', ", IF(EXACT($B17, ""), "null", CONCATENATE("'", SUBSTITUTE($B17, "'", "\'"), "'")), "::varchar,", "'photo_Log_FileUpload_Pointer_RefID', ", IF(EXACT($D17, ""), "null", CONCATENATE("'", SUBSTITUTE($D17, "'", "\'"), "'")), "::bigint", ")))::varchar;") -> varSQL := varSQL || (CASE WHEN (varSQL = '') THEN '' ELSE ', ' END) || (SELECT JSON_BUILD_OBJECT ('recordID', NULL::bigint,'entities', JSON_BUILD_OBJECT ('sysLoginSession_RefID', varSystemLoginSession::bigint,'sysDataAnnotation', NULL::varchar,'sysDataSetDateTimeTZ', NULL::timestamptz,'sysDataValidityStartDateTimeTZ', NULL::timestamptz,'sysDataValidityFinishDateTimeTZ', NULL::timestamptz,'sysPartitionRemovableRecordKey_RefID', NULL::bigint,'sysBranch_RefID', varInstitutionBranchID::bigint,'sysBaseCurrency_RefID',varBaseCurrencyID::bigint,'name', 'Agus Priyatno Mahmudo'::varchar,'photo_Log_FileUpload_Pointer_RefID', null::bigint)))::varchar;
B18: Agus Salim | C18: agus.salim | I18: =I17 + IF(EXACT(J18, ""), 0, 1) -> 25000000000015 | J18: =IF(EXACT(B18, ""), "", CONCATENATE("PERFORM ""SchData-OLTP-Master"".""Func_TblPerson_SET""(varSystemLoginSession, null::bigint, null::varchar, null::timestamptz, null::timestamptz, null::varchar, varInstitutionBranchID, varBaseCurrencyID, '", B18, "'::varchar, null::bigint);")) -> PERFORM "SchData-OLTP-Master"."Func_TblPerson_SET"(varSystemLoginSession, null::bigint, null::varchar, null::timestamptz, null::timestamptz, null::varchar, varInstitutionBranchID, varBaseCurrencyID, 'Agus Salim'::varchar, null::bigint); | K18: =CONCATENATE( "varSQL := varSQL || (CASE WHEN (varSQL = '') THEN '' ELSE ', ' END) || (SELECT JSON_BUILD_OBJECT (", "'recordID', NULL::bigint,", "'entities', ", "JSON_BUILD_OBJECT (", "'sysLoginSession_RefID', varSystemLoginSession::bigint,", "'sysDataAnnotation', NULL::varchar,", "'sysDataSetDateTimeTZ', NULL::timestamptz,", "'sysDataValidityStartDateTimeTZ', NULL::timestamptz,", "'sysDataValidityFinishDateTimeTZ', NULL::timestamptz,", "'sysPartitionRemovableRecordKey_RefID', NULL::bigint,", "'sysBranch_RefID', varInstitutionBranchID::bigint,", "'sysBaseCurrency_RefID',varBaseCurrencyID::bigint,", "'name', ", IF(EXACT($B18, ""), "null", CONCATENATE("'", SUBSTITUTE($B18, "'", "\'"), "'")), "::varchar,", "'photo_Log_FileUpload_Pointer_RefID', ", IF(EXACT($D18, ""), "null", CONCATENATE("'", SUBSTITUTE($D18, "'", "\'"), "'")), "::bigint", ")))::varchar;") -> varSQL := varSQL || (CASE WHEN (varSQL = '') THEN '' ELSE ', ' END) || (SELECT JSON_BUILD_OBJECT ('recordID', NULL::bigint,'entities', JSON_BUILD_OBJECT ('sysLoginSession_RefID', varSystemLoginSession::bigint,'sysDataAnnotation', NULL::varchar,'sysDataSetDateTimeTZ', NULL::timestamptz,'sysDataValidityStartDateTimeTZ', NULL::timestamptz,'sysDataValidityFinishDateTimeTZ', NULL::timestamptz,'sysPartitionRemovableRecordKey_RefID', NULL::bigint,'sysBranch_RefID', varInstitutionBranchID::bigint,'sysBaseCurrency_RefID',varBaseCurrencyID::bigint,'name', 'Agus Salim'::varchar,'photo_Log_FileUpload_Pointer_RefID', null::bigint)))::varchar;
B19: Agus Tanto | C19: agust | I19: =I18 + IF(EXACT(J19, ""), 0, 1) -> 25000000000016 | J19: =IF(EXACT(B19, ""), "", CONCATENATE("PERFORM ""SchData-OLTP-Master"".""Func_TblPerson_SET""(varSystemLoginSession, null::bigint, null::varchar, null::timestamptz, null::timestamptz, null::varchar, varInstitutionBranchID, varBaseCurrencyID, '", B19, "'::varchar, null::bigint);")) -> PERFORM "SchData-OLTP-Master"."Func_TblPerson_SET"(varSystemLoginSession, null::bigint, null::varchar, null::timestamptz, null::timestamptz, null::varchar, varInstitutionBranchID, varBaseCurrencyID, 'Agus Tanto'::varchar, null::bigint); | K19: =CONCATENATE( "varSQL := varSQL || (CASE WHEN (varSQL = '') THEN '' ELSE ', ' END) || (SELECT JSON_BUILD_OBJECT (", "'recordID', NULL::bigint,", "'entities', ", "JSON_BUILD_OBJECT (", "'sysLoginSession_RefID', varSystemLoginSession::bigint,", "'sysDataAnnotation', NULL::varchar,", "'sysDataSetDateTimeTZ', NULL::timestamptz,", "'sysDataValidityStartDateTimeTZ', NULL::timestamptz,", "'sysDataValidityFinishDateTimeTZ', NULL::timestamptz,", "'sysPartitionRemovableRecordKey_RefID', NULL::bigint,", "'sysBranch_RefID', varInstitutionBranchID::bigint,", "'sysBaseCurrency_RefID',varBaseCurrencyID::bigint,", "'name', ", IF(EXACT($B19, ""), "null", CONCATENATE("'", SUBSTITUTE($B19, "'", "\'"), "'")), "::varchar,", "'photo_Log_FileUpload_Pointer_RefID', ", IF(EXACT($D19, ""), "null", CONCATENATE("'", SUBSTITUTE($D19, "'", "\'"), "'")), "::bigint", ")))::varchar;") -> varSQL := varSQL || (CASE WHEN (varSQL = '') THEN '' ELSE ', ' END) || (SELECT JSON_BUILD_OBJECT ('recordID', NULL::bigint,'entities', JSON_BUILD_OBJECT ('sysLoginSession_RefID', varSystemLoginSession::bigint,'sysDataAnnotation', NULL::varchar,'sysDataSetDateTimeTZ', NULL::timestamptz,'sysDataValidityStartDateTimeTZ', NULL::timestamptz,'sysDataValidityFinishDateTimeTZ', NULL::timestamptz,'sysPartitionRemovableRecordKey_RefID', NULL::bigint,'sysBranch_RefID', varInstitutionBranchID::bigint,'sysBaseCurrency_RefID',varBaseCurrencyID::bigint,'name', 'Agus Tanto'::varchar,'photo_Log_FileUpload_Pointer_RefID', null::bigint)))::varchar;
B20: Ahmad Faiz Haems Muda | C20: faiz | E20: 3171041801820004 | I20: =I19 + IF(EXACT(J20, ""), 0, 1) -> 25000000000017 | J20: =IF(EXACT(B20, ""), "", CONCATENATE("PERFORM ""SchData-OLTP-Master"".""Func_TblPerson_SET""(varSystemLoginSession, null::bigint, null::varchar, null::timestamptz, null::timestamptz, null::varchar, varInstitutionBranchID, varBaseCurrencyID, '", B20, "'::varchar, null::bigint);")) -> PERFORM "SchData-OLTP-Master"."Func_TblPerson_SET"(varSystemLoginSession, null::bigint, null::varchar, null::timestamptz, null::timestamptz, null::varchar, varInstitutionBranchID, varBaseCurrencyID, 'Ahmad Faiz Haems Muda'::varchar, null::bigint); | K20: =CONCATENATE( "varSQL := varSQL || (CASE WHEN (varSQL = '') THEN '' ELSE ', ' END) || (SELECT JSON_BUILD_OBJECT (", "'recordID', NULL::bigint,", "'entities', ", "JSON_BUILD_OBJECT (", "'sysLoginSession_RefID', varSystemLoginSession::bigint,", "'sysDataAnnotation', NULL::varchar,", "'sysDataSetDateTimeTZ', NULL::timestamptz,", "'sysDataValidityStartDateTimeTZ', NULL::timestamptz,", "'sysDataValidityFinishDateTimeTZ', NULL::timestamptz,", "'sysPartitionRemovableRecordKey_RefID', NULL::bigint,", "'sysBranch_RefID', varInstitutionBranchID::bigint,", "'sysBaseCurrency_RefID',varBaseCurrencyID::bigint,", "'name', ", IF(EXACT($B20, ""), "null", CONCATENATE("'", SUBSTITUTE($B20, "'", "\'"), "'")), "::varchar,", "'photo_Log_FileUpload_Pointer_RefID', ", IF(EXACT($D20, ""), "null", CONCATENATE("'", SUBSTITUTE($D20, "'", "\'"), "'")), "::bigint", ")))::varchar;") -> varSQL := varSQL || (CASE WHEN (varSQL = '') THEN '' ELSE ', ' END) || (SELECT JSON_BUILD_OBJECT ('recordID', NULL::bigint,'entities', JSON_BUILD_OBJECT ('sysLoginSession_RefID', varSystemLoginSession::bigint,'sysDataAnnotation', NULL::varchar,'sysDataSetDateTimeTZ', NULL::timestamptz,'sysDataValidityStartDateTimeTZ', NULL::timestamptz,'sysDataValidityFinishDateTimeTZ', NULL::timestamptz,'sysPartitionRemovableRecordKey_RefID', NULL::bigint,'sysBranch_RefID', varInstitutionBranchID::bigint,'sysBaseCurrency_RefID',varBaseCurrencyID::bigint,'name', 'Ahmad Faiz Haems Muda'::varchar,'photo_Log_FileUpload_Pointer_RefID', null::bigint)))::varchar;
B21: Ahmad Faza | C21: faza | I21: =I20 + IF(EXACT(J21, ""), 0, 1) -> 25000000000018 | J21: =IF(EXACT(B21, ""), "", CONCATENATE("PERFORM ""SchData-OLTP-Master"".""Func_TblPerson_SET""(varSystemLoginSession, null::bigint, null::varchar, null::timestamptz, null::timestamptz, null::varchar, varInstitutionBranchID, varBaseCurrencyID, '", B21, "'::varchar, null::bigint);")) -> PERFORM "SchData-OLTP-Master"."Func_TblPerson_SET"(varSystemLoginSession, null::bigint, null::varchar, null::timestamptz, null::timestamptz, null::varchar, varInstitutionBranchID, varBaseCurrencyID, 'Ahmad Faza'::varchar, null::bigint); | K21: =CONCATENATE( "varSQL := varSQL || (CASE WHEN (varSQL = '') THEN '' ELSE ', ' END) || (SELECT JSON_BUILD_OBJECT (", "'recordID', NULL::bigint,", "'entities', ", "JSON_BUILD_OBJECT (", "'sysLoginSession_RefID', varSystemLoginSession::bigint,", "'sysDataAnnotation', NULL::varchar,", "'sysDataSetDateTimeTZ', NULL::timestamptz,", "'sysDataValidityStartDateTimeTZ', NULL::timestamptz,", "'sysDataValidityFinishDateTimeTZ', NULL::timestamptz,", "'sysPartitionRemovableRecordKey_RefID', NULL::bigint,", "'sysBranch_RefID', varInstitutionBranchID::bigint,", "'sysBaseCurrency_RefID',varBaseCurrencyID::bigint,", "'name', ", IF(EXACT($B21, ""), "null", CONCATENATE("'", SUBSTITUTE($B21, "'", "\'"), "'")), "::varchar,", "'photo_Log_FileUpload_Pointer_RefID', ", IF(EXACT($D21, ""), "null", CONCATENATE("'", SUBSTITUTE($D21, "'", "\'"), "'")), "::bigint", ")))::varchar;") -> varSQL := varSQL || (CASE WHEN (varSQL = '') THEN '' ELSE ', ' END) || (SELECT JSON_BUILD_OBJECT ('recordID', NULL::bigint,'entities', JSON_BUILD_OBJECT ('sysLoginSession_RefID', varSystemLoginSession::bigint,'sysDataAnnotation', NULL::varchar,'sysDataSetDateTimeTZ', NULL::timestamptz,'sysDataValidityStartDateTimeTZ', NULL::timestamptz,'sysDataValidityFinishDateTimeTZ', NULL::timestamptz,'sysPartitionRemovableRecordKey_RefID', NULL::bigint,'sysBranch_RefID', varInstitutionBranchID::bigint,'sysBaseCurrency_RefID',varBaseCurrencyID::bigint,'name', 'Ahmad Faza'::varchar,'photo_Log_FileUpload_Pointer_RefID', null::bigint)))::varchar;
B22: Ahmad Syaifulloh | C22: ahmad | I22: =I21 + IF(EXACT(J22, ""), 0, 1) -> 25000000000019 | J22: =IF(EXACT(B22, ""), "", CONCATENATE("PERFORM ""SchData-OLTP-Master"".""Func_TblPerson_SET""(varSystemLoginSession, null::bigint, null::varchar, null::timestamptz, null::timestamptz, null::varchar, varInstitutionBranchID, varBaseCurrencyID, '", B22, "'::varchar, null::bigint);")) -> PERFORM "SchData-OLTP-Master"."Func_TblPerson_SET"(varSystemLoginSession, null::bigint, null::varchar, null::timestamptz, null::timestamptz, null::varchar, varInstitutionBranchID, varBaseCurrencyID, 'Ahmad Syaifulloh'::varchar, null::bigint); | K22: =CONCATENATE( "varSQL := varSQL || (CASE WHEN (varSQL = '') THEN '' ELSE ', ' END) || (SELECT JSON_BUILD_OBJECT (", "'recordID', NULL::bigint,", "'entities', ", "JSON_BUILD_OBJECT (", "'sysLoginSession_RefID', varSystemLoginSession::bigint,", "'sysDataAnnotation', NULL::varchar,", "'sysDataSetDateTimeTZ', NULL::timestamptz,", "'sysDataValidityStartDateTimeTZ', NULL::timestamptz,", "'sysDataValidityFinishDateTimeTZ', NULL::timestamptz,", "'sysPartitionRemovableRecordKey_RefID', NULL::bigint,", "'sysBranch_RefID', varInstitutionBranchID::bigint,", "'sysBaseCurrency_RefID',varBaseCurrencyID::bigint,", "'name', ", IF(EXACT($B22, ""), "null", CONCATENATE("'", SUBSTITUTE($B22, "'", "\'"), "'")), "::varchar,", "'photo_Log_FileUpload_Pointer_RefID', ", IF(EXACT($D22, ""), "null", CONCATENATE("'", SUBSTITUTE($D22, "'", "\'"), "'")), "::bigint", ")))::varchar;") -> varSQL := varSQL || (CASE WHEN (varSQL = '') THEN '' ELSE ', ' END) || (SELECT JSON_BUILD_OBJECT ('recordID', NULL::bigint,'entities', JSON_BUILD_OBJECT ('sysLoginSession_RefID', varSystemLoginSession::bigint,'sysDataAnnotation', NULL::varchar,'sysDataSetDateTimeTZ', NULL::timestamptz,'sysDataValidityStartDateTimeTZ', NULL::timestamptz,'sysDataValidityFinishDateTimeTZ', NULL::timestamptz,'sysPartitionRemovableRecordKey_RefID', NULL::bigint,'sysBranch_RefID', varInstitutionBranchID::bigint,'sysBaseCurrency_RefID',varBaseCurrencyID::bigint,'name', 'Ahmad Syaifulloh'::varchar,'photo_Log_FileUpload_Pointer_RefID', null::bigint)))::varchar;
B23: Ahmad Zulkarnaen | C23: zulkarnaen | I23: =I22 + IF(EXACT(J23, ""), 0, 1) -> 25000000000020 | J23: =IF(EXACT(B23, ""), "", CONCATENATE("PERFORM ""SchData-OLTP-Master"".""Func_TblPerson_SET""(varSystemLoginSession, null::bigint, null::varchar, null::timestamptz, null::timestamptz, null::varchar, varInstitutionBranchID, varBaseCurrencyID, '", B23, "'::varchar, null::bigint);")) -> PERFORM "SchData-OLTP-Master"."Func_TblPerson_SET"(varSystemLoginSession, null::bigint, null::varchar, null::timestamptz, null::timestamptz, null::varchar, varInstitutionBranchID, varBaseCurrencyID, 'Ahmad Zulkarnaen'::varchar, null::bigint); | K23: =CONCATENATE( "varSQL := varSQL || (CASE WHEN (varSQL = '') THEN '' ELSE ', ' END) || (SELECT JSON_BUILD_OBJECT (", "'recordID', NULL::bigint,", "'entities', ", "JSON_BUILD_OBJECT (", "'sysLoginSession_RefID', varSystemLoginSession::bigint,", "'sysDataAnnotation', NULL::varchar,", "'sysDataSetDateTimeTZ', NULL::timestamptz,", "'sysDataValidityStartDateTimeTZ', NULL::timestamptz,", "'sysDataValidityFinishDateTimeTZ', NULL::timestamptz,", "'sysPartitionRemovableRecordKey_RefID', NULL::bigint,", "'sysBranch_RefID', varInstitutionBranchID::bigint,", "'sysBaseCurrency_RefID',varBaseCurrencyID::bigint,", "'name', ", IF(EXACT($B23, ""), "null", CONCATENATE("'", SUBSTITUTE($B23, "'", "\'"), "'")), "::varchar,", "'photo_Log_FileUpload_Pointer_RefID', ", IF(EXACT($D23, ""), "null", CONCATENATE("'", SUBSTITUTE($D23, "'", "\'"), "'")), "::bigint", ")))::varchar;") -> varSQL := varSQL || (CASE WHEN (varSQL = '') THEN '' ELSE ', ' END) || (SELECT JSON_BUILD_OBJECT ('recordID', NULL::bigint,'entities', JSON_BUILD_OBJECT ('sysLoginSession_RefID', varSystemLoginSession::bigint,'sysDataAnnotation', NULL::varchar,'sysDataSetDateTimeTZ', NULL::timestamptz,'sysDataValidityStartDateTimeTZ', NULL::timestamptz,'sysDataValidityFinishDateTimeTZ', NULL::timestamptz,'sysPartitionRemovableRecordKey_RefID', NULL::bigint,'sysBranch_RefID', varInstitutionBranchID::bigint,'sysBaseCurrency_RefID',varBaseCurrencyID::bigint,'name', 'Ahmad Zulkarnaen'::varchar,'photo_Log_FileUpload_Pointer_RefID', null::bigint)))::varchar;
B24: Ajan | C24: Ajan | I24: =I23 + IF(EXACT(J24, ""), 0, 1) -> 25000000000021 | J24: =IF(EXACT(B24, ""), "", CONCATENATE("PERFORM ""SchData-OLTP-Master"".""Func_TblPerson_SET""(varSystemLoginSession, null::bigint, null::varchar, null::timestamptz, null::timestamptz, null::varchar, varInstitutionBranchID, varBaseCurrencyID, '", B24, "'::varchar, null::bigint);")) -> PERFORM "SchData-OLTP-Master"."Func_TblPerson_SET"(varSystemLoginSession, null::bigint, null::varchar, null::timestamptz, null::timestamptz, null::varchar, varInstitutionBranchID, varBaseCurrencyID, 'Ajan'::varchar, null::bigint); | K24: =CONCATENATE( "varSQL := varSQL || (CASE WHEN (varSQL = '') THEN '' ELSE ', ' END) || (SELECT JSON_BUILD_OBJECT (", "'recordID', NULL::bigint,", "'entities', ", "JSON_BUILD_OBJECT (", "'sysLoginSession_RefID', varSystemLoginSession::bigint,", "'sysDataAnnotation', NULL::varchar,", "'sysDataSetDateTimeTZ', NULL::timestamptz,", "'sysDataValidityStartDateTimeTZ', NULL::timestamptz,", "'sysDataValidityFinishDateTimeTZ', NULL::timestamptz,", "'sysPartitionRemovableRecordKey_RefID', NULL::bigint,", "'sysBranch_RefID', varInstitutionBranchID::bigint,", "'sysBaseCurrency_RefID',varBaseCurrencyID::bigint,", "'name', ", IF(EXACT($B24, ""), "null", CONCATENATE("'", SUBSTITUTE($B24, "'", "\'"), "'")), "::varchar,", "'photo_Log_FileUpload_Pointer_RefID', ", IF(EXACT($D24, ""), "null", CONCATENATE("'", SUBSTITUTE($D24, "'", "\'"), "'")), "::bigint", ")))::varchar;") -> varSQL := varSQL || (CASE WHEN (varSQL = '') THEN '' ELSE ', ' END) || (SELECT JSON_BUILD_OBJECT ('recordID', NULL::bigint,'entities', JSON_BUILD_OBJECT ('sysLoginSession_RefID', varSystemLoginSession::bigint,'sysDataAnnotation', NULL::varchar,'sysDataSetDateTimeTZ', NULL::timestamptz,'sysDataValidityStartDateTimeTZ', NULL::timestamptz,'sysDataValidityFinishDateTimeTZ', NULL::timestamptz,'sysPartitionRemovableRecordKey_RefID', NULL::bigint,'sysBranch_RefID', varInstitutionBranchID::bigint,'sysBaseCurrency_RefID',varBaseCurrencyID::bigint,'name', 'Ajan'::varchar,'photo_Log_FileUpload_Pointer_RefID', null::bigint)))::varchar;
B25: Al Amin | C25: amin | I25: =I24 + IF(EXACT(J25, ""), 0, 1) -> 25000000000022 | J25: =IF(EXACT(B25, ""), "", CONCATENATE("PERFORM ""SchData-OLTP-Master"".""Func_TblPerson_SET""(varSystemLoginSession, null::bigint, null::varchar, null::timestamptz, null::timestamptz, null::varchar, varInstitutionBranchID, varBaseCurrencyID, '", B25, "'::varchar, null::bigint);")) -> PERFORM "SchData-OLTP-Master"."Func_TblPerson_SET"(varSystemLoginSession, null::bigint, null::varchar, null::timestamptz, null::timestamptz, null::varchar, varInstitutionBranchID, varBaseCurrencyID, 'Al Amin'::varchar, null::bigint); | K25: =CONCATENATE( "varSQL := varSQL || (CASE WHEN (varSQL = '') THEN '' ELSE ', ' END) || (SELECT JSON_BUILD_OBJECT (", "'recordID', NULL::bigint,", "'entities', ", "JSON_BUILD_OBJECT (", "'sysLoginSession_RefID', varSystemLoginSession::bigint,", "'sysDataAnnotation', NULL::varchar,", "'sysDataSetDateTimeTZ', NULL::timestamptz,", "'sysDataValidityStartDateTimeTZ', NULL::timestamptz,", "'sysDataValidityFinishDateTimeTZ', NULL::timestamptz,", "'sysPartitionRemovableRecordKey_RefID', NULL::bigint,", "'sysBranch_RefID', varInstitutionBranchID::bigint,", "'sysBaseCurrency_RefID',varBaseCurrencyID::bigint,", "'name', ", IF(EXACT($B25, ""), "null", CONCATENATE("'", SUBSTITUTE($B25, "'", "\'"), "'")), "::varchar,", "'photo_Log_FileUpload_Pointer_RefID', ", IF(EXACT($D25, ""), "null", CONCATENATE("'", SUBSTITUTE($D25, "'", "\'"), "'")), "::bigint", ")))::varchar;") -> varSQL := varSQL || (CASE WHEN (varSQL = '') THEN '' ELSE ', ' END) || (SELECT JSON_BUILD_OBJECT ('recordID', NULL::bigint,'entities', JSON_BUILD_OBJECT ('sysLoginSession_RefID', varSystemLoginSession::bigint,'sysDataAnnotation', NULL::varchar,'sysDataSetDateTimeTZ', NULL::timestamptz,'sysDataValidityStartDateTimeTZ', NULL::timestamptz,'sysDataValidityFinishDateTimeTZ', NULL::timestamptz,'sysPartitionRemovableRecordKey_RefID', NULL::bigint,'sysBranch_RefID', varInstitutionBranchID::bigint,'sysBaseCurrency_RefID',varBaseCurrencyID::bigint,'name', 'Al Amin'::varchar,'photo_Log_FileUpload_Pointer_RefID', null::bigint)))::varchar;
B26: Aldi Mulyadi | C26: aldi.mulyadi | I26: =I25 + IF(EXACT(J26, ""), 0, 1) -> 25000000000023 | J26: =IF(EXACT(B26, ""), "", CONCATENATE("PERFORM ""SchData-OLTP-Master"".""Func_TblPerson_SET""(varSystemLoginSession, null::bigint, null::varchar, null::timestamptz, null::timestamptz, null::varchar, varInstitutionBranchID, varBaseCurrencyID, '", B26, "'::varchar, null::bigint);")) -> PERFORM "SchData-OLTP-Master"."Func_TblPerson_SET"(varSystemLoginSession, null::bigint, null::varchar, null::timestamptz, null::timestamptz, null::varchar, varInstitutionBranchID, varBaseCurrencyID, 'Aldi Mulyadi'::varchar, null::bigint); | K26: =CONCATENATE( "varSQL := varSQL || (CASE WHEN (varSQL = '') THEN '' ELSE ', ' END) || (SELECT JSON_BUILD_OBJECT (", "'recordID', NULL::bigint,", "'entities', ", "JSON_BUILD_OBJECT (", "'sysLoginSession_RefID', varSystemLoginSession::bigint,", "'sysDataAnnotation', NULL::varchar,", "'sysDataSetDateTimeTZ', NULL::timestamptz,", "'sysDataValidityStartDateTimeTZ', NULL::timestamptz,", "'sysDataValidityFinishDateTimeTZ', NULL::timestamptz,", "'sysPartitionRemovableRecordKey_RefID', NULL::bigint,", "'sysBranch_RefID', varInstitutionBranchID::bigint,", "'sysBaseCurrency_RefID',varBaseCurrencyID::bigint,", "'name', ", IF(EXACT($B26, ""), "null", CONCATENATE("'", SUBSTITUTE($B26, "'", "\'"), "'")), "::varchar,", "'photo_Log_FileUpload_Pointer_RefID', ", IF(EXACT($D26, ""), "null", CONCATENATE("'", SUBSTITUTE($D26, "'", "\'"), "'")), "::bigint", ")))::varchar;") -> varSQL := varSQL || (CASE WHEN (varSQL = '') THEN '' ELSE ', ' END) || (SELECT JSON_BUILD_OBJECT ('recordID', NULL::bigint,'entities', JSON_BUILD_OBJECT ('sysLoginSession_RefID', varSystemLoginSession::bigint,'sysDataAnnotation', NULL::varchar,'sysDataSetDateTimeTZ', NULL::timestamptz,'sysDataValidityStartDateTimeTZ', NULL::timestamptz,'sysDataValidityFinishDateTimeTZ', NULL::timestamptz,'sysPartitionRemovableRecordKey_RefID', NULL::bigint,'sysBranch_RefID', varInstitutionBranchID::bigint,'sysBaseCurrency_RefID',varBaseCurrencyID::bigint,'name', 'Aldi Mulyadi'::varchar,'photo_Log_FileUpload_Pointer_RefID', null::bigint)))::varchar;
B27: Alexandri | C27: alexandri | I27: =I26 + IF(EXACT(J27, ""), 0, 1) -> 25000000000024 | J27: =IF(EXACT(B27, ""), "", CONCATENATE("PERFORM ""SchData-OLTP-Master"".""Func_TblPerson_SET""(varSystemLoginSession, null::bigint, null::varchar, null::timestamptz, null::timestamptz, null::varchar, varInstitutionBranchID, varBaseCurrencyID, '", B27, "'::varchar, null::bigint);")) -> PERFORM "SchData-OLTP-Master"."Func_TblPerson_SET"(varSystemLoginSession, null::bigint, null::varchar, null::timestamptz, null::timestamptz, null::varchar, varInstitutionBranchID, varBaseCurrencyID, 'Alexandri'::varchar, null::bigint); | K27: =CONCATENATE( "varSQL := varSQL || (CASE WHEN (varSQL = '') THEN '' ELSE ', ' END) || (SELECT JSON_BUILD_OBJECT (", "'recordID', NULL::bigint,", "'entities', ", "JSON_BUILD_OBJECT (", "'sysLoginSession_RefID', varSystemLoginSession::bigint,", "'sysDataAnnotation', NULL::varchar,", "'sysDataSetDateTimeTZ', NULL::timestamptz,", "'sysDataValidityStartDateTimeTZ', NULL::timestamptz,", "'sysDataValidityFinishDateTimeTZ', NULL::timestamptz,", "'sysPartitionRemovableRecordKey_RefID', NULL::bigint,", "'sysBranch_RefID', varInstitutionBranchID::bigint,", "'sysBaseCurrency_RefID',varBaseCurrencyID::bigint,", "'name', ", IF(EXACT($B27, ""), "null", CONCATENATE("'", SUBSTITUTE($B27, "'", "\'"), "'")), "::varchar,", "'photo_Log_FileUpload_Pointer_RefID', ", IF(EXACT($D27, ""), "null", CONCATENATE("'", SUBSTITUTE($D27, "'", "\'"), "'")), "::bigint", ")))::varchar;") -> varSQL := varSQL || (CASE WHEN (varSQL = '') THEN '' ELSE ', ' END) || (SELECT JSON_BUILD_OBJECT ('recordID', NULL::bigint,'entities', JSON_BUILD_OBJECT ('sysLoginSession_RefID', varSystemLoginSession::bigint,'sysDataAnnotation', NULL::varchar,'sysDataSetDateTimeTZ', NULL::timestamptz,'sysDataValidityStartDateTimeTZ', NULL::timestamptz,'sysDataValidityFinishDateTimeTZ', NULL::timestamptz,'sysPartitionRemovableRecordKey_RefID', NULL::bigint,'sysBranch_RefID', varInstitutionBranchID::bigint,'sysBaseCurrency_RefID',varBaseCurrencyID::bigint,'name', 'Alexandri'::varchar,'photo_Log_FileUpload_Pointer_RefID', null::bigint)))::varchar;
B28: Alfaedi | C28: faedi | I28: =I27 + IF(EXACT(J28, ""), 0, 1) -> 25000000000025 | J28: =IF(EXACT(B28, ""), "", CONCATENATE("PERFORM ""SchData-OLTP-Master"".""Func_TblPerson_SET""(varSystemLoginSession, null::bigint, null::varchar, null::timestamptz, null::timestamptz, null::varchar, varInstitutionBranchID, varBaseCurrencyID, '", B28, "'::varchar, null::bigint);")) -> PERFORM "SchData-OLTP-Master"."Func_TblPerson_SET"(varSystemLoginSession, null::bigint, null::varchar, null::timestamptz, null::timestamptz, null::varchar, varInstitutionBranchID, varBaseCurrencyID, 'Alfaedi'::varchar, null::bigint); | K28: =CONCATENATE( "varSQL := varSQL || (CASE WHEN (varSQL = '') THEN '' ELSE ', ' END) || (SELECT JSON_BUILD_OBJECT (", "'recordID', NULL::bigint,", "'entities', ", "JSON_BUILD_OBJECT (", "'sysLoginSession_RefID', varSystemLoginSession::bigint,", "'sysDataAnnotation', NULL::varchar,", "'sysDataSetDateTimeTZ', NULL::timestamptz,", "'sysDataValidityStartDateTimeTZ', NULL::timestamptz,", "'sysDataValidityFinishDateTimeTZ', NULL::timestamptz,", "'sysPartitionRemovableRecordKey_RefID', NULL::bigint,", "'sysBranch_RefID', varInstitutionBranchID::bigint,", "'sysBaseCurrency_RefID',varBaseCurrencyID::bigint,", "'name', ", IF(EXACT($B28, ""), "null", CONCATENATE("'", SUBSTITUTE($B28, "'", "\'"), "'")), "::varchar,", "'photo_Log_FileUpload_Pointer_RefID', ", IF(EXACT($D28, ""), "null", CONCATENATE("'", SUBSTITUTE($D28, "'", "\'"), "'")), "::bigint", ")))::varchar;") -> varSQL := varSQL || (CASE WHEN (varSQL = '') THEN '' ELSE ', ' END) || (SELECT JSON_BUILD_OBJECT ('recordID', NULL::bigint,'entities', JSON_BUILD_OBJECT ('sysLoginSession_RefID', varSystemLoginSession::bigint,'sysDataAnnotation', NULL::varchar,'sysDataSetDateTimeTZ', NULL::timestamptz,'sysDataValidityStartDateTimeTZ', NULL::timestamptz,'sysDataValidityFinishDateTimeTZ', NULL::timestamptz,'sysPartitionRemovableRecordKey_RefID', NULL::bigint,'sysBranch_RefID', varInstitutionBranchID::bigint,'sysBaseCurrency_RefID',varBaseCurrencyID::bigint,'name', 'Alfaedi'::varchar,'photo_Log_FileUpload_Pointer_RefID', null::bigint)))::varchar;
B29: Ali Wahono | C29: ali.wahono | I29: =I28 + IF(EXACT(J29, ""), 0, 1) -> 25000000000026 | J29: =IF(EXACT(B29, ""), "", CONCATENATE("PERFORM ""SchData-OLTP-Master"".""Func_TblPerson_SET""(varSystemLoginSession, null::bigint, null::varchar, null::timestamptz, null::timestamptz, null::varchar, varInstitutionBranchID, varBaseCurrencyID, '", B29, "'::varchar, null::bigint);")) -> PERFORM "SchData-OLTP-Master"."Func_TblPerson_SET"(varSystemLoginSession, null::bigint, null::varchar, null::timestamptz, null::timestamptz, null::varchar, varInstitutionBranchID, varBaseCurrencyID, 'Ali Wahono'::varchar, null::bigint); | K29: =CONCATENATE( "varSQL := varSQL || (CASE WHEN (varSQL = '') THEN '' ELSE ', ' END) || (SELECT JSON_BUILD_OBJECT (", "'recordID', NULL::bigint,", "'entities', ", "JSON_BUILD_OBJECT (", "'sysLoginSession_RefID', varSystemLoginSession::bigint,", "'sysDataAnnotation', NULL::varchar,", "'sysDataSetDateTimeTZ', NULL::timestamptz,", "'sysDataValidityStartDateTimeTZ', NULL::timestamptz,", "'sysDataValidityFinishDateTimeTZ', NULL::timestamptz,", "'sysPartitionRemovableRecordKey_RefID', NULL::bigint,", "'sysBranch_RefID', varInstitutionBranchID::bigint,", "'sysBaseCurrency_RefID',varBaseCurrencyID::bigint,", "'name', ", IF(EXACT($B29, ""), "null", CONCATENATE("'", SUBSTITUTE($B29, "'", "\'"), "'")), "::varchar,", "'photo_Log_FileUpload_Pointer_RefID', ", IF(EXACT($D29, ""), "null", CONCATENATE("'", SUBSTITUTE($D29, "'", "\'"), "'")), "::bigint", ")))::varchar;") -> varSQL := varSQL || (CASE WHEN (varSQL = '') THEN '' ELSE ', ' END) || (SELECT JSON_BUILD_OBJECT ('recordID', NULL::bigint,'entities', JSON_BUILD_OBJECT ('sysLoginSession_RefID', varSystemLoginSession::bigint,'sysDataAnnotation', NULL::varchar,'sysDataSetDateTimeTZ', NULL::timestamptz,'sysDataValidityStartDateTimeTZ', NULL::timestamptz,'sysDataValidityFinishDateTimeTZ', NULL::timestamptz,'sysPartitionRemovableRecordKey_RefID', NULL::bigint,'sysBranch_RefID', varInstitutionBranchID::bigint,'sysBaseCurrency_RefID',varBaseCurrencyID::bigint,'name', 'Ali Wahono'::varchar,'photo_Log_FileUpload_Pointer_RefID', null::bigint)))::varchar;
B30: Alphaliyanri Lasria | C30: alpha | I30: =I29 + IF(EXACT(J30, ""), 0, 1) -> 25000000000027 | J30: =IF(EXACT(B30, ""), "", CONCATENATE("PERFORM ""SchData-OLTP-Master"".""Func_TblPerson_SET""(varSystemLoginSession, null::bigint, null::varchar, null::timestamptz, null::timestamptz, null::varchar, varInstitutionBranchID, varBaseCurrencyID, '", B30, "'::varchar, null::bigint);")) -> PERFORM "SchData-OLTP-Master"."Func_TblPerson_SET"(varSystemLoginSession, null::bigint, null::varchar, null::timestamptz, null::timestamptz, null::varchar, varInstitutionBranchID, varBaseCurrencyID, 'Alphaliyanri Lasria'::varchar, null::bigint); | K30: =CONCATENATE( "varSQL := varSQL || (CASE WHEN (varSQL = '') THEN '' ELSE ', ' END) || (SELECT JSON_BUILD_OBJECT (", "'recordID', NULL::bigint,", "'entities', ", "JSON_BUILD_OBJECT (", "'sysLoginSession_RefID', varSystemLoginSession::bigint,", "'sysDataAnnotation', NULL::varchar,", "'sysDataSetDateTimeTZ', NULL::timestamptz,", "'sysDataValidityStartDateTimeTZ', NULL::timestamptz,", "'sysDataValidityFinishDateTimeTZ', NULL::timestamptz,", "'sysPartitionRemovableRecordKey_RefID', NULL::bigint,", "'sysBranch_RefID', varInstitutionBranchID::bigint,", "'sysBaseCurrency_RefID',varBaseCurrencyID::bigint,", "'name', ", IF(EXACT($B30, ""), "null", CONCATENATE("'", SUBSTITUTE($B30, "'", "\'"), "'")), "::varchar,", "'photo_Log_FileUpload_Pointer_RefID', ", IF(EXACT($D30, ""), "null", CONCATENATE("'", SUBSTITUTE($D30, "'", "\'"), "'")), "::bigint", ")))::varchar;") -> varSQL := varSQL || (CASE WHEN (varSQL = '') THEN '' ELSE ', ' END) || (SELECT JSON_BUILD_OBJECT ('recordID', NULL::bigint,'entities', JSON_BUILD_OBJECT ('sysLoginSession_RefID', varSystemLoginSession::bigint,'sysDataAnnotation', NULL::varchar,'sysDataSetDateTimeTZ', NULL::timestamptz,'sysDataValidityStartDateTimeTZ', NULL::timestamptz,'sysDataValidityFinishDateTimeTZ', NULL::timestamptz,'sysPartitionRemovableRecordKey_RefID', NULL::bigint,'sysBranch_RefID', varInstitutionBranchID::bigint,'sysBaseCurrency_RefID',varBaseCurrencyID::bigint,'name', 'Alphaliyanri Lasria'::varchar,'photo_Log_FileUpload_Pointer_RefID', null::bigint)))::varchar;
