Workbook

Sheet Main
B5: =IF(EXACT([1]MAIN!D4, ""), "", [1]MAIN!D4) -> 95000000000001 | C5: =IF(EXACT([1]MAIN!B4, ""), "", [1]MAIN!B4) -> Super User
B6: =IF(EXACT([1]MAIN!D5, ""), "", [1]MAIN!D5) -> 95000000000002 | C6: =IF(EXACT([1]MAIN!B5, ""), "", [1]MAIN!B5) -> Guest
B7: =IF(EXACT([1]MAIN!D6, ""), "", [1]MAIN!D6) -> 95000000000002 | C7: =IF(EXACT([1]MAIN!B6, ""), "", [1]MAIN!B6)
B8: =IF(EXACT([1]MAIN!D7, ""), "", [1]MAIN!D7) -> 95000000000003 | C8: =IF(EXACT([1]MAIN!B7, ""), "", [1]MAIN!B7) -> Default Employee Role
B9: =IF(EXACT([1]MAIN!D8, ""), "", [1]MAIN!D8) -> 95000000000003 | C9: =IF(EXACT([1]MAIN!B8, ""), "", [1]MAIN!B8)
B10: =IF(EXACT([1]MAIN!D9, ""), "", [1]MAIN!D9) -> 95000000000004 | C10: =IF(EXACT([1]MAIN!B9, ""), "", [1]MAIN!B9) -> Share Holder
B11: =IF(EXACT([1]MAIN!D10, ""), "", [1]MAIN!D10) -> 95000000000005 | C11: =IF(EXACT([1]MAIN!B10, ""), "", [1]MAIN!B10) -> Stack Holder
B12: =IF(EXACT([1]MAIN!D11, ""), "", [1]MAIN!D11) -> 95000000000006 | C12: =IF(EXACT([1]MAIN!B11, ""), "", [1]MAIN!B11) -> Public Accounting Firm
B13: =IF(EXACT([1]MAIN!D12, ""), "", [1]MAIN!D12) -> 95000000000007 | C13: =IF(EXACT([1]MAIN!B12, ""), "", [1]MAIN!B12) -> Commissary
B14: =IF(EXACT([1]MAIN!D13, ""), "", [1]MAIN!D13) -> 95000000000007 | C14: =IF(EXACT([1]MAIN!B13, ""), "", [1]MAIN!B13)
B15: =IF(EXACT([1]MAIN!D14, ""), "", [1]MAIN!D14) -> 95000000000008 | C15: =IF(EXACT([1]MAIN!B14, ""), "", [1]MAIN!B14) -> Director
B16: =IF(EXACT([1]MAIN!D15, ""), "", [1]MAIN!D15) -> 95000000000009 | C16: =IF(EXACT([1]MAIN!B15, ""), "", [1]MAIN!B15) -> President Director
... B64: =IF(EXACT([1]MAIN!D63, ""), "", [1]MAIN!D63) -> 95000000000049 | C64: =IF(EXACT([1]MAIN!B63, ""), "", [1]MAIN!B63) -> Health Safety Environment Coordinator
B65: =IF(EXACT([1]MAIN!D64, ""), "", [1]MAIN!D64) -> 95000000000050
B66: =IF(EXACT([1]MAIN!D65, ""), "", [1]MAIN!D65) -> 95000000000050 | C66: =IF(EXACT([1]MAIN!B65, ""), "", [1]MAIN!B65)
B67: =IF(EXACT([1]MAIN!D66, ""), "", [1]MAIN!D66) -> 95000000000051 | C67: =IF(EXACT([1]MAIN!B66, ""), "", [1]MAIN!B66) -> Human Resource Development Manager
B68: =IF(EXACT([1]MAIN!D67, ""), "", [1]MAIN!D67) -> 95000000000052 | C68: =IF(EXACT([1]MAIN!B67, ""), "", [1]MAIN!B67) -> Human Resource Development Coordinator
B69: =IF(EXACT([1]MAIN!D68, ""), "", [1]MAIN!D68) -> 95000000000053 | C69: =IF(EXACT([1]MAIN!B68, ""), "", [1]MAIN!B68) -> Human Resource Development Staff
B70: =IF(EXACT([1]MAIN!D69, ""), "", [1]MAIN!D69) -> 95000000000053 | C70: =IF(EXACT([1]MAIN!B69, ""), "", [1]MAIN!B69)
B71: =IF(EXACT([1]MAIN!D70, ""), "", [1]MAIN!D70) -> 95000000000054 | C71: =IF(EXACT([1]MAIN!B70, ""), "", [1]MAIN!B70) -> General Affairs Manager
B72: =IF(EXACT([1]MAIN!D71, ""), "", [1]MAIN!D71) -> 95000000000055 | C72: =IF(EXACT([1]MAIN!B71, ""), "", [1]MAIN!B71) -> General Affairs Coordinator
B73: =IF(EXACT([1]MAIN!D72, ""), "", [1]MAIN!D72) -> 95000000000056 | C73: =IF(EXACT([1]MAIN!B72, ""), "", [1]MAIN!B72) -> General Affairs Staff
B74: =IF(EXACT([1]MAIN!D73, ""), "", [1]MAIN!D73) -> 95000000000056 | C74: =IF(EXACT([1]MAIN!B73, ""), "", [1]MAIN!B73)
B75: =IF(EXACT([1]MAIN!D74, ""), "", [1]MAIN!D74) -> 95000000000057 | C75: =IF(EXACT([1]MAIN!B74, ""), "", [1]MAIN!B74) -> Legal Manager
B76: =IF(EXACT([1]MAIN!D75, ""), "", [1]MAIN!D75) -> 95000000000058 | C76: =IF(EXACT([1]MAIN!B75, ""), "", [1]MAIN!B75) -> Legal Coordinator

Sheet Entry
D2: =IF(EXACT((OFFSET([1]MAIN!$D$4, (COLUMN(D$1)-COLUMN($D$1)), 0)), ""), "", (OFFSET([1]MAIN!$D$4, (COLUMN(D$1)-COLUMN($D$1)), 0))) -> 95000000000001 | E2: =IF(EXACT((OFFSET([1]MAIN!$D$4, (COLUMN(E$1)-COLUMN($D$1)), 0)), ""), "", (OFFSET([1]MAIN!$D$4, (COLUMN(E$1)-COLUMN($D$1)), 0))) -> 95000000000002 | F2: =IF(EXACT((OFFSET([1]MAIN!$D$4, (COLUMN(F$1)-COLUMN($D$1)), 0)), ""), "", (OFFSET([1]MAIN!$D$4, (COLUMN(F$1)-COLUMN($D$1)), 0))) -> 95000000000002 | G2: =IF(EXACT((OFFSET([1]MAIN!$D$4, (COLUMN(G$1)-COLUMN($D$1)), 0)), ""), "", (OFFSET([1]MAIN!$D$4, (COLUMN(G$1)-COLUMN($D$1)), 0))) -> 95000000000003 | H2: =IF(EXACT((OFFSET([1]MAIN!$D$4, (COLUMN(H$1)-COLUMN($D$1)), 0)), ""), "", (OFFSET([1]MAIN!$D$4, (COLUMN(H$1)-COLUMN($D$1)), 0))) -> 95000000000003 | I2: =IF(EXACT((OFFSET([1]MAIN!$D$4, (COLUMN(I$1)-COLUMN($D$1)), 0)), ""), "", (OFFSET([1]MAIN!$D$4, (COLUMN(I$1)-COLUMN($D$1)), 0))) -> 95000000000004 | J2: =IF(EXACT((OFFSET([1]MAIN!$D$4, (COLUMN(J$1)-COLUMN($D$1)), 0)), ""), "", (OFFSET([1]MAIN!$D$4, (COLUMN(J$1)-COLUMN($D$1)), 0))) -> 95000000000005 | K2: =IF(EXACT((OFFSET([1]MAIN!$D$4, (COLUMN(K$1)-COLUMN($D$1)), 0)), ""), "", (OFFSET([1]MAIN!$D$4, (COLUMN(K$1)-COLUMN($D$1)), 0))) -> 95000000000006 | ... Y2: =IF(EXACT((OFFSET([1]MAIN!$D$4, (COLUMN(Y$1)-COLUMN($D$1)), 0)), ""), "", (OFFSET([1]MAIN!$D$4, (COLUMN(Y$1)-COLUMN($D$1)), 0))) -> 95000000000018 | AA2: =IF(EXACT((OFFSET([1]MAIN!$D$4, (COLUMN(AA$1)-COLUMN($D$1)), 0)), ""), "", (OFFSET([1]MAIN!$D$4, (COLUMN(AA$1)-COLUMN($D$1)), 0))) -> 95000000000019 | AB2: =IF(EXACT((OFFSET([1]MAIN!$D$4, (COLUMN(AB$1)-COLUMN($D$1)), 0)), ""), "", (OFFSET([1]MAIN!$D$4, (COLUMN(AB$1)-COLUMN($D$1)), 0))) -> 95000000000020 | AC2: =IF(EXACT((OFFSET([1]MAIN!$D$4, (COLUMN(AC$1)-COLUMN($D$1)), 0)), ""), "", (OFFSET([1]MAIN!$D$4, (COLUMN(AC$1)-COLUMN($D$1)), 0))) -> 95000000000021 | AD2: =IF(EXACT((OFFSET([1]MAIN!$D$4, (COLUMN(AD$1)-COLUMN($D$1)), 0)), ""), "", (OFFSET([1]MAIN!$D$4, (COLUMN(AD$1)-COLUMN($D$1)), 0))) -> 95000000000022 | AE2: =IF(EXACT((OFFSET([1]MAIN!$D$4, (COLUMN(AE$1)-COLUMN($D$1)), 0)), ""), "", (OFFSET([1]MAIN!$D$4, (COLUMN(AE$1)-COLUMN($D$1)), 0))) -> 95000000000023 | AF2: =IF(EXACT((OFFSET([1]MAIN!$D$4, (COLUMN(AF$1)-COLUMN($D$1)), 0)), ""), "", (OFFSET([1]MAIN!$D$4, (COLUMN(AF$1)-COLUMN($D$1)), 0))) -> 95000000000024 | AG2: =IF(EXACT((OFFSET([1]MAIN!$D$4, (COLUMN(AG$1)-COLUMN($D$1)), 0)), ""), "", (OFFSET([1]MAIN!$D$4, (COLUMN(AG$1)-COLUMN($D$1)), 0))) -> 95000000000025 | AH2: =IF(EXACT((OFFSET([1]MAIN!$D$4, (COLUMN(AH$1)-COLUMN($D$1)), 0)), ""), "", (OFFSET([1]MAIN!$D$4, (COLUMN(AH$1)-COLUMN($D$1)), 0))) -> 95000000000026 | ... BL2: =IF(EXACT((OFFSET([1]MAIN!$D$4, (COLUMN(BL$1)-COLUMN($D$1)), 0)), ""), "", (OFFSET([1]MAIN!$D$4, (COLUMN(BL$1)-COLUMN($D$1)), 0))) -> 95000000000050 | BN2: =IF(EXACT((OFFSET([1]MAIN!$D$4, (COLUMN(BN$1)-COLUMN($D$1)), 0)), ""), "", (OFFSET([1]MAIN!$D$4, (COLUMN(BN$1)-COLUMN($D$1)), 0))) -> 95000000000051 | BO2: =IF(EXACT((OFFSET([1]MAIN!$D$4, (COLUMN(BO$1)-COLUMN($D$1)), 0)), ""), "", (OFFSET([1]MAIN!$D$4, (COLUMN(BO$1)-COLUMN($D$1)), 0))) -> 95000000000052 | BP2: =IF(EXACT((OFFSET([1]MAIN!$D$4, (COLUMN(BP$1)-COLUMN($D$1)), 0)), ""), "", (OFFSET([1]MAIN!$D$4, (COLUMN(BP$1)-COLUMN($D$1)), 0))) -> 95000000000053 | BR2: =IF(EXACT((OFFSET([1]MAIN!$D$4, (COLUMN(BR$1)-COLUMN($D$1)), 0)), ""), "", (OFFSET([1]MAIN!$D$4, (COLUMN(BR$1)-COLUMN($D$1)), 0))) -> 95000000000054 | BS2: =IF(EXACT((OFFSET([1]MAIN!$D$4, (COLUMN(BS$1)-COLUMN($D$1)), 0)), ""), "", (OFFSET([1]MAIN!$D$4, (COLUMN(BS$1)-COLUMN($D$1)), 0))) -> 95000000000055 | BT2: =IF(EXACT((OFFSET([1]MAIN!$D$4, (COLUMN(BT$1)-COLUMN($D$1)), 0)), ""), "", (OFFSET([1]MAIN!$D$4, (COLUMN(BT$1)-COLUMN($D$1)), 0))) -> 95000000000056 | BV2: =IF(EXACT((OFFSET([1]MAIN!$D$4, (COLUMN(BV$1)-COLUMN($D$1)), 0)), ""), "", (OFFSET([1]MAIN!$D$4, (COLUMN(BV$1)-COLUMN($D$1)), 0))) -> 95000000000057 | BW2: =IF(EXACT((OFFSET([1]MAIN!$D$4, (COLUMN(BW$1)-COLUMN($D$1)), 0)), ""), "", (OFFSET([1]MAIN!$D$4, (COLUMN(BW$1)-COLUMN($D$1)), 0))) -> 95000000000058 | BX2: =IF(EXACT((OFFSET([1]MAIN!$D$4, (COLUMN(BX$1)-COLUMN($D$1)), 0)), ""), "", (OFFSET([1]MAIN!$D$4, (COLUMN(BX$1)-COLUMN($D$1)), 0))) -> 95000000000059 | BZ2: =IF(EXACT((OFFSET([1]MAIN!$D$4, (COLUMN(BZ$1)-COLUMN($D$1)), 0)), ""), "", (OFFSET([1]MAIN!$D$4, (COLUMN(BZ$1)-COLUMN($D$1)), 0))) -> 95000000000060 | CA2: =IF(EXACT((OFFSET([1]MAIN!$D$4, (COLUMN(CA$1)-COLUMN($D$1)), 0)), ""), "", (OFFSET([1]MAIN!$D$4, (COLUMN(CA$1)-COLUMN($D$1)), 0))) -> 95000000000061 | CB2: =IF(EXACT((OFFSET([1]MAIN!$D$4, (COLUMN(CB$1)-COLUMN($D$1)), 0)), ""), "", (OFFSET([1]MAIN!$D$4, (COLUMN(CB$1)-COLUMN($D$1)), 0))) -> 95000000000062 | CD2: =IF(EXACT((OFFSET([1]MAIN!$D$4, (COLUMN(CD$1)-COLUMN($D$1)), 0)), ""), "", (OFFSET([1]MAIN!$D$4, (COLUMN(CD$1)-COLUMN($D$1)), 0))) -> 95000000000063 | CE2: =IF(EXACT((OFFSET([1]MAIN!$D$4, (COLUMN(CE$1)-COLUMN($D$1)), 0)), ""), "", (OFFSET([1]MAIN!$D$4, (COLUMN(CE$1)-COLUMN($D$1)), 0))) -> 95000000000064 | CF2: =IF(EXACT((OFFSET([1]MAIN!$D$4, (COLUMN(CF$1)-COLUMN($D$1)), 0)), ""), "", (OFFSET([1]MAIN!$D$4, (COLUMN(CF$1)-COLUMN($D$1)), 0))) -> 95000000000065
D3: =IF(EXACT((OFFSET([1]MAIN!$B$4, (COLUMN(D$1)-COLUMN($D$1)), 0)), ""), "", (OFFSET([1]MAIN!$B$4, (COLUMN(D$1)-COLUMN($D$1)), 0))) -> Super User | E3: =IF(EXACT((OFFSET([1]MAIN!$B$4, (COLUMN(E$1)-COLUMN($D$1)), 0)), ""), "", (OFFSET([1]MAIN!$B$4, (COLUMN(E$1)-COLUMN($D$1)), 0))) -> Guest | F3: =IF(EXACT((OFFSET([1]MAIN!$B$4, (COLUMN(F$1)-COLUMN($D$1)), 0)), ""), "", (OFFSET([1]MAIN!$B$4, (COLUMN(F$1)-COLUMN($D$1)), 0))) | G3: =IF(EXACT((OFFSET([1]MAIN!$B$4, (COLUMN(G$1)-COLUMN($D$1)), 0)), ""), "", (OFFSET([1]MAIN!$B$4, (COLUMN(G$1)-COLUMN($D$1)), 0))) -> Default Employee Role | H3: =IF(EXACT((OFFSET([1]MAIN!$B$4, (COLUMN(H$1)-COLUMN($D$1)), 0)), ""), "", (OFFSET([1]MAIN!$B$4, (COLUMN(H$1)-COLUMN($D$1)), 0))) | I3: =IF(EXACT((OFFSET([1]MAIN!$B$4, (COLUMN(I$1)-COLUMN($D$1)), 0)), ""), "", (OFFSET([1]MAIN!$B$4, (COLUMN(I$1)-COLUMN($D$1)), 0))) -> Share Holder | J3: =IF(EXACT((OFFSET([1]MAIN!$B$4, (COLUMN(J$1)-COLUMN($D$1)), 0)), ""), "", (OFFSET([1]MAIN!$B$4, (COLUMN(J$1)-COLUMN($D$1)), 0))) -> Stack Holder | K3: =IF(EXACT((OFFSET([1]MAIN!$B$4, (COLUMN(K$1)-COLUMN($D$1)), 0)), ""), "", (OFFSET([1]MAIN!$B$4, (COLUMN(K$1)-COLUMN($D$1)), 0))) -> Public Accounting Firm | ... Y3: =IF(EXACT((OFFSET([1]MAIN!$B$4, (COLUMN(Y$1)-COLUMN($D$1)), 0)), ""), "", (OFFSET([1]MAIN!$B$4, (COLUMN(Y$1)-COLUMN($D$1)), 0))) -> Sales General Manager | AA3: =IF(EXACT((OFFSET([1]MAIN!$B$4, (COLUMN(AA$1)-COLUMN($D$1)), 0)), ""), "", (OFFSET([1]MAIN!$B$4, (COLUMN(AA$1)-COLUMN($D$1)), 0))) -> Project Manager | AB3: =IF(EXACT((OFFSET([1]MAIN!$B$4, (COLUMN(AB$1)-COLUMN($D$1)), 0)), ""), "", (OFFSET([1]MAIN!$B$4, (COLUMN(AB$1)-COLUMN($D$1)), 0))) -> Site Manager | AC3: =IF(EXACT((OFFSET([1]MAIN!$B$4, (COLUMN(AC$1)-COLUMN($D$1)), 0)), ""), "", (OFFSET([1]MAIN!$B$4, (COLUMN(AC$1)-COLUMN($D$1)), 0))) -> Project Controller Coordinator | AD3: =IF(EXACT((OFFSET([1]MAIN!$B$4, (COLUMN(AD$1)-COLUMN($D$1)), 0)), ""), "", (OFFSET([1]MAIN!$B$4, (COLUMN(AD$1)-COLUMN($D$1)), 0))) -> Project Controller Staff | AE3: =IF(EXACT((OFFSET([1]MAIN!$B$4, (COLUMN(AE$1)-COLUMN($D$1)), 0)), ""), "", (OFFSET([1]MAIN!$B$4, (COLUMN(AE$1)-COLUMN($D$1)), 0))) -> Project Administrator Coordinator | AF3: =IF(EXACT((OFFSET([1]MAIN!$B$4, (COLUMN(AF$1)-COLUMN($D$1)), 0)), ""), "", (OFFSET([1]MAIN!$B$4, (COLUMN(AF$1)-COLUMN($D$1)), 0))) -> Project Administrator Staff | AG3: =IF(EXACT((OFFSET([1]MAIN!$B$4, (COLUMN(AG$1)-COLUMN($D$1)), 0)), ""), "", (OFFSET([1]MAIN!$B$4, (COLUMN(AG$1)-COLUMN($D$1)), 0))) -> Project Worker Coordinator | AH3: =IF(EXACT((OFFSET([1]MAIN!$B$4, (COLUMN(AH$1)-COLUMN($D$1)), 0)), ""), "", (OFFSET([1]MAIN!$B$4, (COLUMN(AH$1)-COLUMN($D$1)), 0))) -> Project Worker Staff | ... BL3: =IF(EXACT((OFFSET([1]MAIN!$B$4, (COLUMN(BL$1)-COLUMN($D$1)), 0)), ""), "", (OFFSET([1]MAIN!$B$4, (COLUMN(BL$1)-COLUMN($D$1)), 0))) -> Health Safety Environment Staff | BN3: =IF(EXACT((OFFSET([1]MAIN!$B$4, (COLUMN(BN$1)-COLUMN($D$1)), 0)), ""), "", (OFFSET([1]MAIN!$B$4, (COLUMN(BN$1)-COLUMN($D$1)), 0))) -> Human Resource Development Manager | BO3: =IF(EXACT((OFFSET([1]MAIN!$B$4, (COLUMN(BO$1)-COLUMN($D$1)), 0)), ""), "", (OFFSET([1]MAIN!$B$4, (COLUMN(BO$1)-COLUMN($D$1)), 0))) -> Human Resource Development Coordinator | BP3: =IF(EXACT((OFFSET([1]MAIN!$B$4, (COLUMN(BP$1)-COLUMN($D$1)), 0)), ""), "", (OFFSET([1]MAIN!$B$4, (COLUMN(BP$1)-COLUMN($D$1)), 0))) -> Human Resource Development Staff | BR3: =IF(EXACT((OFFSET([1]MAIN!$B$4, (COLUMN(BR$1)-COLUMN($D$1)), 0)), ""), "", (OFFSET([1]MAIN!$B$4, (COLUMN(BR$1)-COLUMN($D$1)), 0))) -> General Affairs Manager | BS3: =IF(EXACT((OFFSET([1]MAIN!$B$4, (COLUMN(BS$1)-COLUMN($D$1)), 0)), ""), "", (OFFSET([1]MAIN!$B$4, (COLUMN(BS$1)-COLUMN($D$1)), 0))) -> General Affairs Coordinator | BT3: =IF(EXACT((OFFSET([1]MAIN!$B$4, (COLUMN(BT$1)-COLUMN($D$1)), 0)), ""), "", (OFFSET([1]MAIN!$B$4, (COLUMN(BT$1)-COLUMN($D$1)), 0))) -> General Affairs Staff | BV3: =IF(EXACT((OFFSET([1]MAIN!$B$4, (COLUMN(BV$1)-COLUMN($D$1)), 0)), ""), "", (OFFSET([1]MAIN!$B$4, (COLUMN(BV$1)-COLUMN($D$1)), 0))) -> Legal Manager | BW3: =IF(EXACT((OFFSET([1]MAIN!$B$4, (COLUMN(BW$1)-COLUMN($D$1)), 0)), ""), "", (OFFSET([1]MAIN!$B$4, (COLUMN(BW$1)-COLUMN($D$1)), 0))) -> Legal Coordinator | BX3: =IF(EXACT((OFFSET([1]MAIN!$B$4, (COLUMN(BX$1)-COLUMN($D$1)), 0)), ""), "", (OFFSET([1]MAIN!$B$4, (COLUMN(BX$1)-COLUMN($D$1)), 0))) -> Legal Staff | BZ3: =IF(EXACT((OFFSET([1]MAIN!$B$4, (COLUMN(BZ$1)-COLUMN($D$1)), 0)), ""), "", (OFFSET([1]MAIN!$B$4, (COLUMN(BZ$1)-COLUMN($D$1)), 0))) -> Tools And Asset Manager | CA3: =IF(EXACT((OFFSET([1]MAIN!$B$4, (COLUMN(CA$1)-COLUMN($D$1)), 0)), ""), "", (OFFSET([1]MAIN!$B$4, (COLUMN(CA$1)-COLUMN($D$1)), 0))) -> Tools And Asset Coordinator | CB3: =IF(EXACT((OFFSET([1]MAIN!$B$4, (COLUMN(CB$1)-COLUMN($D$1)), 0)), ""), "", (OFFSET([1]MAIN!$B$4, (COLUMN(CB$1)-COLUMN($D$1)), 0))) -> Tools And Asset Staff | CD3: =IF(EXACT((OFFSET([1]MAIN!$B$4, (COLUMN(CD$1)-COLUMN($D$1)), 0)), ""), "", (OFFSET([1]MAIN!$B$4, (COLUMN(CD$1)-COLUMN($D$1)), 0))) -> Engineering Manager | CE3: =IF(EXACT((OFFSET([1]MAIN!$B$4, (COLUMN(CE$1)-COLUMN($D$1)), 0)), ""), "", (OFFSET([1]MAIN!$B$4, (COLUMN(CE$1)-COLUMN($D$1)), 0))) -> Engineering Coordinator | CF3: =IF(EXACT((OFFSET([1]MAIN!$B$4, (COLUMN(CF$1)-COLUMN($D$1)), 0)), ""), "", (OFFSET([1]MAIN!$B$4, (COLUMN(CF$1)-COLUMN($D$1)), 0))) -> Engineering Staff
B4: =[2]Main!E2 -> 97000000000001 | C4: =VLOOKUP(B4, [2]Main!$E$2:$F$675, 2) -> System.Login | D4: √ | E4: √ | G4: √ | I4: √ | J4: √ | K4: √ | L4: √ | N4: √ | O4: √ | P4: √ | Q4: √ | R4: √ | S4: √ | U4: √ | V4: √ | W4: √ | X4: √ | Y4: √ | AA4: √ | AB4: √ | AC4: √ | AD4: √ | AE4: √ | AF4: √ | AG4: √ | AH4: √ | AJ4: √ | AK4: √ | AL4: √ | AM4: √ | AN4: √ | AP4: √ | AQ4: √ | AR4: √ | AT4: √ | AU4: √ | AV4: √ | AW4: √ | AX4: √ | AZ4: √ | BA4: √ | BB4: √ | BD4: √ | BE4: √ | BF4: √ | BG4: √ | BH4: √ | BJ4: √ | BK4: √ | BL4: √ | BN4: √ | BO4: √ | BP4: √ | BR4: √ | BS4: √ | BT4: √ | BV4: √ | BW4: √ | BX4: √ | BZ4: √ | CA4: √ | CB4: √ | CD4: √ | CE4: √ | CF4: √
B5: =[2]Main!E3 -> 97000000000002 | C5: =VLOOKUP(B5, [2]Main!$E$2:$F$675, 2) -> System.Logout | D5: √ | E5: √ | G5: √ | I5: √ | J5: √ | K5: √ | L5: √ | N5: √ | O5: √ | P5: √ | Q5: √ | R5: √ | S5: √ | U5: √ | V5: √ | W5: √ | X5: √ | Y5: √ | AA5: √ | AB5: √ | AC5: √ | AD5: √ | AE5: √ | AF5: √ | AG5: √ | AH5: √ | AJ5: √ | AK5: √ | AL5: √ | AM5: √ | AN5: √ | AP5: √ | AQ5: √ | AR5: √ | AT5: √ | AU5: √ | AV5: √ | AW5: √ | AX5: √ | AZ5: √ | BA5: √ | BB5: √ | BD5: √ | BE5: √ | BF5: √ | BG5: √ | BH5: √ | BJ5: √ | BK5: √ | BL5: √ | BN5: √ | BO5: √ | BP5: √ | BR5: √ | BS5: √ | BT5: √ | BV5: √ | BW5: √ | BX5: √ | BZ5: √ | CA5: √ | CB5: √ | CD5: √ | CE5: √ | CF5: √
B6: =[2]Main!E4 -> 97000000000003 | C6: =VLOOKUP(B6, [2]Main!$E$2:$F$675, 2) -> System.Lock | D6: √ | E6: √ | G6: √ | I6: √ | J6: √ | K6: √ | L6: √ | N6: √ | O6: √ | P6: √ | Q6: √ | R6: √ | S6: √ | U6: √ | V6: √ | W6: √ | X6: √ | Y6: √ | AA6: √ | AB6: √ | AC6: √ | AD6: √ | AE6: √ | AF6: √ | AG6: √ | AH6: √ | AJ6: √ | AK6: √ | AL6: √ | AM6: √ | AN6: √ | AP6: √ | AQ6: √ | AR6: √ | AT6: √ | AU6: √ | AV6: √ | AW6: √ | AX6: √ | AZ6: √ | BA6: √ | BB6: √ | BD6: √ | BE6: √ | BF6: √ | BG6: √ | BH6: √ | BJ6: √ | BK6: √ | BL6: √ | BN6: √ | BO6: √ | BP6: √ | BR6: √ | BS6: √ | BT6: √ | BV6: √ | BW6: √ | BX6: √ | BZ6: √ | CA6: √ | CB6: √ | CD6: √ | CE6: √ | CF6: √
B7: =[2]Main!E5 -> 97000000000004 | C7: =VLOOKUP(B7, [2]Main!$E$2:$F$675, 2) -> Dashboard.Home | D7: √ | E7: √ | G7: √ | I7: √ | J7: √ | K7: √ | L7: √ | N7: √ | O7: √ | P7: √ | Q7: √ | R7: √ | S7: √ | U7: √ | V7: √ | W7: √ | X7: √ | Y7: √ | AA7: √ | AB7: √ | AC7: √ | AD7: √ | AE7: √ | AF7: √ | AG7: √ | AH7: √ | AJ7: √ | AK7: √ | AL7: √ | AM7: √ | AN7: √ | AP7: √ | AQ7: √ | AR7: √ | AT7: √ | AU7: √ | AV7: √ | AW7: √ | AX7: √ | AZ7: √ | BA7: √ | BB7: √ | BD7: √ | BE7: √ | BF7: √ | BG7: √ | BH7: √ | BJ7: √ | BK7: √ | BL7: √ | BN7: √ | BO7: √ | BP7: √ | BR7: √ | BS7: √ | BT7: √ | BV7: √ | BW7: √ | BX7: √ | BZ7: √ | CA7: √ | CB7: √ | CD7: √ | CE7: √ | CF7: √
B8: =[2]Main!E6 -> 97000000000005 | C8: =VLOOKUP(B8, [2]Main!$E$2:$F$675, 2) -> Dashboard.DocumentTracking | N8: √ | O8: √ | P8: √ | Q8: √ | R8: √ | S8: √ | U8: √ | V8: √ | W8: √ | X8: √ | Y8: √ | AA8: √ | AB8: √ | AC8: √ | AD8: √ | AE8: √ | AF8: √ | AG8: √ | AH8: √ | AJ8: √ | AK8: √ | AL8: √ | AM8: √ | AN8: √ | AP8: √ | AQ8: √ | AR8: √ | AT8: √ | AU8: √ | AV8: √ | AW8: √ | AX8: √ | AZ8: √ | BA8: √ | BB8: √ | BD8: √ | BE8: √ | BF8: √ | BG8: √ | BH8: √ | BJ8: √ | BK8: √ | BL8: √ | BN8: √ | BO8: √ | BP8: √ | BR8: √ | BS8: √ | BT8: √ | BV8: √ | BW8: √ | BX8: √ | BZ8: √ | CA8: √ | CB8: √ | CD8: √ | CE8: √ | CF8: √
B9: =[2]Main!E7 -> 97000000000006 | C9: =VLOOKUP(B9, [2]Main!$E$2:$F$675, 2) -> Dashboard.MyDocumentTracking | N9: √ | O9: √ | P9: √ | Q9: √ | R9: √ | S9: √ | U9: √ | V9: √ | W9: √ | X9: √ | Y9: √ | AA9: √ | AB9: √ | AC9: √ | AD9: √ | AE9: √ | AF9: √ | AG9: √ | AH9: √ | AJ9: √ | AK9: √ | AL9: √ | AM9: √ | AN9: √ | AP9: √ | AQ9: √ | AR9: √ | AT9: √ | AU9: √ | AV9: √ | AW9: √ | AX9: √ | AZ9: √ | BA9: √ | BB9: √ | BD9: √ | BE9: √ | BF9: √ | BG9: √ | BH9: √ | BJ9: √ | BK9: √ | BL9: √ | BN9: √ | BO9: √ | BP9: √ | BR9: √ | BS9: √ | BT9: √ | BV9: √ | BW9: √ | BX9: √ | BZ9: √ | CA9: √ | CB9: √ | CD9: √ | CE9: √ | CF9: √
B10: =[2]Main!E8 -> 97000000000007 | C10: =VLOOKUP(B10, [2]Main!$E$2:$F$675, 2) -> Dashboard.MyDocumentDisposition | D10: √ | N10: √ | S10: √ | U10: √ | V10: √ | W10: √ | X10: √ | Y10: √ | AD10: √ | AF10: √ | AL10: √ | AN10: √ | AR10: √ | AU10: √ | AV10: √ | AW10: √ | AX10: √ | BB10: √ | BH10: √ | BL10: √ | BP10: √ | BR10: √ | BS10: √ | BT10: √ | BV10: √ | BW10: √ | BX10: √ | BZ10: √ | CA10: √ | CB10: √ | CD10: √ | CE10: √ | CF10: √
B11: =[2]Main!E9 -> 97000000000008 | C11: =VLOOKUP(B11, [2]Main!$E$2:$F$675, 2) -> Module.General.MasterData.Country.Transaction | D11: √ | N11: √ | S11: √ | U11: √ | V11: √ | W11: √ | X11: √ | Y11: √ | AD11: √ | AF11: √ | AL11: √ | AN11: √ | AR11: √ | AU11: √ | AV11: √ | AW11: √ | AX11: √ | BB11: √ | BH11: √ | BL11: √ | BP11: √ | BT11: √ | BX11: √ | CB11: √ | CF11: √
B12: =[2]Main!E10 -> 97000000000009 | C12: =VLOOKUP(B12, [2]Main!$E$2:$F$675, 2) -> Module.General.MasterData.CountryAdministrativeAreaLevel1.Transaction | D12: √ | N12: √ | S12: √ | U12: √ | V12: √ | W12: √ | X12: √ | Y12: √ | AD12: √ | AF12: √ | AL12: √ | AN12: √ | AR12: √ | AU12: √ | AV12: √ | AW12: √ | AX12: √ | BB12: √ | BH12: √ | BL12: √ | BP12: √ | BT12: √ | BX12: √ | CB12: √ | CF12: √
B13: =[2]Main!E11 -> 97000000000010 | C13: =VLOOKUP(B13, [2]Main!$E$2:$F$675, 2) -> Module.General.MasterData.CountryAdministrativeAreaLevel2.Transaction | D13: √ | N13: √ | S13: √ | U13: √ | V13: √ | W13: √ | X13: √ | Y13: √ | AD13: √ | AF13: √ | AL13: √ | AN13: √ | AR13: √ | AU13: √ | AV13: √ | AW13: √ | AX13: √ | BB13: √ | BH13: √ | BL13: √ | BP13: √ | BT13: √ | BX13: √ | CB13: √ | CF13: √
B14: =[2]Main!E12 -> 97000000000011 | C14: =VLOOKUP(B14, [2]Main!$E$2:$F$675, 2) -> Module.General.MasterData.CountryAdministrativeAreaLevel3.Transaction | D14: √ | N14: √ | S14: √ | U14: √ | V14: √ | W14: √ | X14: √ | Y14: √ | AD14: √ | AF14: √ | AL14: √ | AN14: √ | AR14: √ | AU14: √ | AV14: √ | AW14: √ | AX14: √ | BB14: √ | BH14: √ | BL14: √ | BP14: √ | BT14: √ | BX14: √ | CB14: √ | CF14: √
B15: =[2]Main!E13 -> 97000000000012 | C15: =VLOOKUP(B15, [2]Main!$E$2:$F$675, 2) -> Module.General.MasterData.CountryAdministrativeAreaLevel4.Transaction | D15: √ | N15: √ | S15: √ | U15: √ | V15: √ | W15: √ | X15: √ | Y15: √ | AD15: √ | AF15: √ | AL15: √ | AN15: √ | AR15: √ | AU15: √ | AV15: √ | AW15: √ | AX15: √ | BB15: √ | BH15: √ | BL15: √ | BP15: √ | BT15: √ | BX15: √ | CB15: √ | CF15: √
B16: =[2]Main!E14 -> 97000000000013 | C16: =VLOOKUP(B16, [2]Main!$E$2:$F$675, 2) -> Module.General.MasterData.BusinessDocumentType.Transaction | D16: √ | N16: √ | S16: √ | U16: √ | V16: √ | W16: √ | X16: √ | Y16: √ | AD16: √ | AF16: √ | AL16: √ | AN16: √ | AR16: √ | AU16: √ | AV16: √ | AW16: √ | AX16: √ | BB16: √ | BH16: √ | BL16: √ | BP16: √ | BT16: √ | BX16: √ | CB16: √ | CF16: √
B17: =[2]Main!E15 -> 97000000000014 | C17: =VLOOKUP(B17, [2]Main!$E$2:$F$675, 2) -> Module.General.MasterData.BusinessDocument.Transaction | D17: √ | N17: √ | S17: √ | U17: √ | V17: √ | W17: √ | X17: √ | Y17: √ | AD17: √ | AF17: √ | AL17: √ | AN17: √ | AR17: √ | AU17: √ | AV17: √ | AW17: √ | AX17: √ | BB17: √ | BH17: √ | BL17: √ | BP17: √ | BT17: √ | BX17: √ | CB17: √ | CF17: √
B18: =[2]Main!E16 -> 97000000000015 | C18: =VLOOKUP(B18, [2]Main!$E$2:$F$675, 2) -> Module.General.MasterData.BusinessDocumentVersion.Transaction | D18: √ | N18: √ | S18: √ | U18: √ | V18: √ | W18: √ | X18: √ | Y18: √ | AD18: √ | AF18: √ | AL18: √ | AN18: √ | AR18: √ | AU18: √ | AV18: √ | AW18: √ | AX18: √ | BB18: √ | BH18: √ | BL18: √ | BP18: √ | BT18: √ | BX18: √ | CB18: √ | CF18: √
B19: =[2]Main!E17 -> 97000000000016 | C19: =VLOOKUP(B19, [2]Main!$E$2:$F$675, 2) -> Module.General.MasterData.MenuManagement.Transaction | D19: √ | N19: √ | S19: √ | U19: √ | V19: √ | W19: √ | X19: √ | Y19: √ | AD19: √ | AF19: √ | AL19: √ | AN19: √ | AR19: √ | AU19: √ | AV19: √ | AW19: √ | AX19: √ | BB19: √ | BH19: √ | BL19: √ | BP19: √ | BT19: √ | BX19: √ | CB19: √ | CF19: √
B20: =[2]Main!E18 -> 97000000000017 | C20: =VLOOKUP(B20, [2]Main!$E$2:$F$675, 2) -> Module.Budgeting.MasterData.Budget.Transaction | D20: √ | N20: √ | S20: √ | U20: √ | V20: √ | W20: √ | X20: √ | Y20: √ | AD20: √ | AF20: √ | AL20: √ | AN20: √ | AR20: √ | AU20: √ | AV20: √ | AW20: √ | AX20: √ | BB20: √ | BH20: √ | BL20: √ | BP20: √ | BT20: √ | BX20: √ | CB20: √ | CF20: √
B21: =[2]Main!E19 -> 97000000000018 | C21: =VLOOKUP(B21, [2]Main!$E$2:$F$675, 2) -> Module.Budgeting.MasterData.BudgetSection.Transaction | D21: √ | N21: √ | S21: √ | U21: √ | V21: √ | W21: √ | X21: √ | Y21: √ | AD21: √ | AF21: √ | AL21: √ | AN21: √ | AR21: √ | AU21: √ | AV21: √ | AW21: √ | AX21: √ | BB21: √ | BH21: √ | BL21: √ | BP21: √ | BT21: √ | BX21: √ | CB21: √ | CF21: √
B22: =[2]Main!E20 -> 97000000000019 | C22: =VLOOKUP(B22, [2]Main!$E$2:$F$675, 2) -> Module.Budgeting.Data.Budget.Report.Transaction | D22: √ | N22: √ | S22: √ | U22: √ | V22: √ | W22: √ | X22: √ | Y22: √ | AD22: √ | AF22: √ | AL22: √ | AN22: √ | AR22: √ | AU22: √ | AV22: √ | AW22: √ | AX22: √ | BB22: √ | BH22: √ | BL22: √ | BP22: √ | BT22: √ | BX22: √ | CB22: √ | CF22: √
... B118: =[2]Main!E116 -> 97000000000115 | C118: =VLOOKUP(B118, [2]Main!$E$2:$F$675, 2) -> Module.CustomerRelation.MasterData.CustomerOrder.Report.DataList | D118: √ | N118: √ | S118: √ | U118: √ | V118: √ | W118: √ | X118: √ | Y118: √ | AD118: √ | AF118: √ | AL118: √ | AN118: √ | AR118: √ | AU118: √ | AV118: √ | AW118: √ | AX118: √ | BB118: √ | BH118: √ | BL118: √ | BP118: √ | BT118: √ | BX118: √ | CB118: √ | CF118: √

Sheet Process Result-1 (JSON)
D2: =IF(EXACT(Entry!D2, ""), "", Entry!D2) -> 95000000000001 | E2: =IF(EXACT(Entry!E2, ""), "", Entry!E2) -> 95000000000002 | F2: =IF(EXACT(Entry!F2, ""), "", Entry!F2) -> 95000000000002 | G2: =IF(EXACT(Entry!G2, ""), "", Entry!G2) -> 95000000000003 | I2: =IF(EXACT(Entry!I2, ""), "", Entry!I2) -> 95000000000004 | J2: =IF(EXACT(Entry!J2, ""), "", Entry!J2) -> 95000000000005 | K2: =IF(EXACT(Entry!K2, ""), "", Entry!K2) -> 95000000000006 | L2: =IF(EXACT(Entry!L2, ""), "", Entry!L2) -> 95000000000007 | N2: =IF(EXACT(Entry!N2, ""), "", Entry!N2) -> 95000000000008 | O2: =IF(EXACT(Entry!O2, ""), "", Entry!O2) -> 95000000000009 | P2: =IF(EXACT(Entry!P2, ""), "", Entry!P2) -> 95000000000010 | Q2: =IF(EXACT(Entry!Q2, ""), "", Entry!Q2) -> 95000000000011 | R2: =IF(EXACT(Entry!R2, ""), "", Entry!R2) -> 95000000000012 | S2: =IF(EXACT(Entry!S2, ""), "", Entry!S2) -> 95000000000013 | T2: =IF(EXACT(Entry!S2, ""), "", Entry!S2) -> 95000000000013 | U2: =IF(EXACT(Entry!U2, ""), "", Entry!U2) -> 95000000000014 | V2: =IF(EXACT(Entry!V2, ""), "", Entry!V2) -> 95000000000015 | W2: =IF(EXACT(Entry!W2, ""), "", Entry!W2) -> 95000000000016 | X2: =IF(EXACT(Entry!X2, ""), "", Entry!X2) -> 95000000000017 | Y2: =IF(EXACT(Entry!Y2, ""), "", Entry!Y2) -> 95000000000018 | AA2: =IF(EXACT(Entry!AA2, ""), "", Entry!AA2) -> 95000000000019 | AB2: =IF(EXACT(Entry!AB2, ""), "", Entry!AB2) -> 95000000000020 | AC2: =IF(EXACT(Entry!AC2, ""), "", Entry!AC2) -> 95000000000021 | AD2: =IF(EXACT(Entry!AD2, ""), "", Entry!AD2) -> 95000000000022 | AE2: =IF(EXACT(Entry!AE2, ""), "", Entry!AE2) -> 95000000000023 | AF2: =IF(EXACT(Entry!AF2, ""), "", Entry!AF2) -> 95000000000024 | AG2: =IF(EXACT(Entry!AG2, ""), "", Entry!AG2) -> 95000000000025 | AH2: =IF(EXACT(Entry!AH2, ""), "", Entry!AH2) -> 95000000000026 | AJ2: =IF(EXACT(Entry!AJ2, ""), "", Entry!AJ2) -> 95000000000027 | AK2: =IF(EXACT(Entry!AK2, ""), "", Entry!AK2) -> 95000000000028 | AL2: =IF(EXACT(Entry!AL2, ""), "", Entry!AL2) -> 95000000000029 | AM2: =IF(EXACT(Entry!AM2, ""), "", Entry!AM2) -> 95000000000030 | AN2: =IF(EXACT(Entry!AN2, ""), "", Entry!AN2) -> 95000000000031 | AP2: =IF(EXACT(Entry!AP2, ""), "", Entry!AP2) -> 95000000000032 | AQ2: =IF(EXACT(Entry!AQ2, ""), "", Entry!AQ2) -> 95000000000033 | AR2: =IF(EXACT(Entry!AR2, ""), "", Entry!AR2) -> 95000000000034 | AT2: =IF(EXACT(Entry!AT2, ""), "", Entry!AT2) -> 95000000000035 | AU2: =IF(EXACT(Entry!AU2, ""), "", Entry!AU2) -> 95000000000036 | AV2: =IF(EXACT(Entry!AV2, ""), "", Entry!AV2) -> 95000000000037 | AW2: =IF(EXACT(Entry!AW2, ""), "", Entry!AW2) -> 95000000000038 | AX2: =IF(EXACT(Entry!AX2, ""), "", Entry!AX2) -> 95000000000039 | AZ2: =IF(EXACT(Entry!AZ2, ""), "", Entry!AZ2) -> 95000000000040 | BA2: =IF(EXACT(Entry!BA2, ""), "", Entry!BA2) -> 95000000000041 | BB2: =IF(EXACT(Entry!BB2, ""), "", Entry!BB2) -> 95000000000042 | BD2: =IF(EXACT(Entry!BD2, ""), "", Entry!BD2) -> 95000000000043 | BE2: =IF(EXACT(Entry!BE2, ""), "", Entry!BE2) -> 95000000000044 | BF2: =IF(EXACT(Entry!BF2, ""), "", Entry!BF2) -> 95000000000045 | BG2: =IF(EXACT(Entry!BG2, ""), "", Entry!BG2) -> 95000000000046 | BH2: =IF(EXACT(Entry!BH2, ""), "", Entry!BH2) -> 95000000000047 | BJ2: =IF(EXACT(Entry!BJ2, ""), "", Entry!BJ2) -> 95000000000048 | BK2: =IF(EXACT(Entry!BK2, ""), "", Entry!BK2) -> 95000000000049 | BL2: =IF(EXACT(Entry!BL2, ""), "", Entry!BL2) -> 95000000000050 | BN2: =IF(EXACT(Entry!BN2, ""), "", Entry!BN2) -> 95000000000051 | BO2: =IF(EXACT(Entry!BO2, ""), "", Entry!BO2) -> 95000000000052 | BP2: =IF(EXACT(Entry!BP2, ""), "", Entry!BP2) -> 95000000000053 | BR2: =IF(EXACT(Entry!BR2, ""), "", Entry!BR2) -> 95000000000054 | BS2: =IF(EXACT(Entry!BS2, ""), "", Entry!BS2) -> 95000000000055 | BT2: =IF(EXACT(Entry!BT2, ""), "", Entry!BT2) -> 95000000000056 | BV2: =IF(EXACT(Entry!BV2, ""), "", Entry!BV2) -> 95000000000057 | BW2: =IF(EXACT(Entry!BW2, ""), "", Entry!BW2) -> 95000000000058 | BX2: =IF(EXACT(Entry!BX2, ""), "", Entry!BX2) -> 95000000000059 | BZ2: =IF(EXACT(Entry!BZ2, ""), "", Entry!BZ2) -> 95000000000060 | CA2: =IF(EXACT(Entry!CA2, ""), "", Entry!CA2) -> 95000000000061 | CB2: =IF(EXACT(Entry!CB2, ""), "", Entry!CB2) -> 95000000000062 | CD2: =IF(EXACT(Entry!CD2, ""), "", Entry!CD2) -> 95000000000063 | CE2: =IF(EXACT(Entry!CE2, ""), "", Entry!CE2) -> 95000000000064 | CF2: =IF(EXACT(Entry!CF2, ""), "", Entry!CF2) -> 95000000000065
C3: [95000000000001,97000000000001] | D3: =IF(EXACT(Entry!D3, ""), "", Entry!D3) -> Super User | E3: =IF(EXACT(Entry!E3, ""), "", Entry!E3) -> Guest | F3: =IF(EXACT(Entry!F3, ""), "", Entry!F3) | G3: =IF(EXACT(Entry!G3, ""), "", Entry!G3) -> Default Employee Role | I3: =IF(EXACT(Entry!I3, ""), "", Entry!I3) -> Share Holder | J3: =IF(EXACT(Entry!J3, ""), "", Entry!J3) -> Stack Holder | K3: =IF(EXACT(Entry!K3, ""), "", Entry!K3) -> Public Accounting Firm | L3: =IF(EXACT(Entry!L3, ""), "", Entry!L3) -> Commissary | N3: =IF(EXACT(Entry!N3, ""), "", Entry!N3) -> Director | O3: =IF(EXACT(Entry!O3, ""), "", Entry!O3) -> President Director | P3: =IF(EXACT(Entry!P3, ""), "", Entry!P3) -> Finance Director | Q3: =IF(EXACT(Entry!Q3, ""), "", Entry!Q3) -> Operational Director | R3: =IF(EXACT(Entry!R3, ""), "", Entry!R3) -> Marketing Director | S3: =IF(EXACT(Entry!S3, ""), "", Entry!S3) -> Information Technology Director | U3: =IF(EXACT(Entry!U3, ""), "", Entry!U3) -> Project General Manager | V3: =IF(EXACT(Entry!V3, ""), "", Entry!V3) -> Project Management Officer | W3: =IF(EXACT(Entry!W3, ""), "", Entry!W3) -> Finance, Accounting, & Tax General Manager | X3: =IF(EXACT(Entry!X3, ""), "", Entry!X3) -> HR, GA, & TAM General Manager | Y3: =IF(EXACT(Entry!Y3, ""), "", Entry!Y3) -> Sales General Manager | AA3: =IF(EXACT(Entry!AA3, ""), "", Entry!AA3) -> Project Manager | AB3: =IF(EXACT(Entry!AB3, ""), "", Entry!AB3) -> Site Manager | AC3: =IF(EXACT(Entry!AC3, ""), "", Entry!AC3) -> Project Controller Coordinator | AD3: =IF(EXACT(Entry!AD3, ""), "", Entry!AD3) -> Project Controller Staff | AE3: =IF(EXACT(Entry!AE3, ""), "", Entry!AE3) -> Project Administrator Coordinator | AF3: =IF(EXACT(Entry!AF3, ""), "", Entry!AF3) -> Project Administrator Staff | AG3: =IF(EXACT(Entry!AG3, ""), "", Entry!AG3) -> Project Worker Coordinator | AH3: =IF(EXACT(Entry!AH3, ""), "", Entry!AH3) -> Project Worker Staff | AJ3: =IF(EXACT(Entry!AJ3, ""), "", Entry!AJ3) -> Finance Manager | AK3: =IF(EXACT(Entry!AK3, ""), "", Entry!AK3) -> Cashier & Treasury Coordinator | AL3: =IF(EXACT(Entry!AL3, ""), "", Entry!AL3) -> Cashier & Treasury Staff | AM3: =IF(EXACT(Entry!AM3, ""), "", Entry!AM3) -> Cost Controller Coordinator | AN3: =IF(EXACT(Entry!AN3, ""), "", Entry!AN3) -> Cost Controller Staff | AP3: =IF(EXACT(Entry!AP3, ""), "", Entry!AP3) -> Accounting & Tax Manager | AQ3: =IF(EXACT(Entry!AQ3, ""), "", Entry!AQ3) -> Accounting & Tax Coordinator | AR3: =IF(EXACT(Entry!AR3, ""), "", Entry!AR3) -> Accounting & Tax Staff | AT3: =IF(EXACT(Entry!AT3, ""), "", Entry!AT3) -> IT System Manager | AU3: =IF(EXACT(Entry!AU3, ""), "", Entry!AU3) -> IT System Engineer Coordinator | AV3: =IF(EXACT(Entry!AV3, ""), "", Entry!AV3) -> IT System Engineer Staff | AW3: =IF(EXACT(Entry!AW3, ""), "", Entry!AW3) -> IT Software Engineer Coordinator | AX3: =IF(EXACT(Entry!AX3, ""), "", Entry!AX3) -> IT Software Engineer Staff | AZ3: =IF(EXACT(Entry!AZ3, ""), "", Entry!AZ3) -> Procurement Manager | BA3: =IF(EXACT(Entry!BA3, ""), "", Entry!BA3) -> Procurement Coordinator | BB3: =IF(EXACT(Entry!BB3, ""), "", Entry!BB3) -> Procurement Staff | BD3: =IF(EXACT(Entry!BD3, ""), "", Entry!BD3) -> Sales Manager | BE3: =IF(EXACT(Entry!BE3, ""), "", Entry!BE3) -> Sales Coordinator | BF3: =IF(EXACT(Entry!BF3, ""), "", Entry!BF3) -> Bid And Sales Administrator Staff | BG3: =IF(EXACT(Entry!BG3, ""), "", Entry!BG3) -> Sales Estimator Coordinator | BH3: =IF(EXACT(Entry!BH3, ""), "", Entry!BH3) -> Sales Estimator Staff | BJ3: =IF(EXACT(Entry!BJ3, ""), "", Entry!BJ3) -> Health Safety Environment Manager | BK3: =IF(EXACT(Entry!BK3, ""), "", Entry!BK3) -> Health Safety Environment Coordinator | BL3: =IF(EXACT(Entry!BL3, ""), "", Entry!BL3) -> Health Safety Environment Staff | BN3: =IF(EXACT(Entry!BN3, ""), "", Entry!BN3) -> Human Resource Development Manager | BO3: =IF(EXACT(Entry!BO3, ""), "", Entry!BO3) -> Human Resource Development Coordinator | BP3: =IF(EXACT(Entry!BP3, ""), "", Entry!BP3) -> Human Resource Development Staff | BR3: =IF(EXACT(Entry!BR3, ""), "", Entry!BR3) -> General Affairs Manager | BS3: =IF(EXACT(Entry!BS3, ""), "", Entry!BS3) -> General Affairs Coordinator | BT3: =IF(EXACT(Entry!BT3, ""), "", Entry!BT3) -> General Affairs Staff | BV3: =IF(EXACT(Entry!BV3, ""), "", Entry!BV3) -> Legal Manager | BW3: =IF(EXACT(Entry!BW3, ""), "", Entry!BW3) -> Legal Coordinator | BX3: =IF(EXACT(Entry!BX3, ""), "", Entry!BX3) -> Legal Staff | BZ3: =IF(EXACT(Entry!BZ3, ""), "", Entry!BZ3) -> Tools And Asset Manager | CA3: =IF(EXACT(Entry!CA3, ""), "", Entry!CA3) -> Tools And Asset Coordinator | CB3: =IF(EXACT(Entry!CB3, ""), "", Entry!CB3) -> Tools And Asset Staff | CD3: =IF(EXACT(Entry!CD3, ""), "", Entry!CD3) -> Engineering Manager | CE3: =IF(EXACT(Entry!CE3, ""), "", Entry!CE3) -> Engineering Coordinator | CF3: =IF(EXACT(Entry!CF3, ""), "", Entry!CF3) -> Engineering Staff
B4: =IF(EXACT(Entry!B4, ""), "", Entry!B4) -> 97000000000001 | C4: =IF(EXACT(Entry!C4, ""), "", Entry!C4) -> System.Login | D4: =IF(EXACT((OFFSET(Entry!$B$2, ROW()-ROW($B$2), COLUMN()-COLUMN($B$2))), ""), "", CONCATENATE("[", (OFFSET($B$2, 0, COLUMN()-COLUMN($B$2))-95000000000000), ",", (OFFSET($B$2, ROW()-ROW($B$2), 0)-97000000000000),"]")) -> [1,1] | E4: =IF(EXACT((OFFSET(Entry!$B$2, ROW()-ROW($B$2), COLUMN()-COLUMN($B$2))), ""), "", CONCATENATE("[", (OFFSET($B$2, 0, COLUMN()-COLUMN($B$2))-95000000000000), ",", (OFFSET($B$2, ROW()-ROW($B$2), 0)-97000000000000),"]")) -> [2,1] | F4: =IF(EXACT((OFFSET(Entry!$B$2, ROW()-ROW($B$2), COLUMN()-COLUMN($B$2))), ""), "", CONCATENATE("[", (OFFSET($B$2, 0, COLUMN()-COLUMN($B$2))-95000000000000), ",", (OFFSET($B$2, ROW()-ROW($B$2), 0)-97000000000000),"]")) | G4: =IF(EXACT((OFFSET(Entry!$B$2, ROW()-ROW($B$2), COLUMN()-COLUMN($B$2))), ""), "", CONCATENATE("[", (OFFSET($B$2, 0, COLUMN()-COLUMN($B$2))-95000000000000), ",", (OFFSET($B$2, ROW()-ROW($B$2), 0)-97000000000000),"]")) -> [3,1] | I4: =IF(EXACT((OFFSET(Entry!$B$2, ROW()-ROW($B$2), COLUMN()-COLUMN($B$2))), ""), "", CONCATENATE("[", (OFFSET($B$2, 0, COLUMN()-COLUMN($B$2))-95000000000000), ",", (OFFSET($B$2, ROW()-ROW($B$2), 0)-97000000000000),"]")) -> [4,1] | J4: =IF(EXACT((OFFSET(Entry!$B$2, ROW()-ROW($B$2), COLUMN()-COLUMN($B$2))), ""), "", CONCATENATE("[", (OFFSET($B$2, 0, COLUMN()-COLUMN($B$2))-95000000000000), ",", (OFFSET($B$2, ROW()-ROW($B$2), 0)-97000000000000),"]")) -> [5,1] | K4: =IF(EXACT((OFFSET(Entry!$B$2, ROW()-ROW($B$2), COLUMN()-COLUMN($B$2))), ""), "", CONCATENATE("[", (OFFSET($B$2, 0, COLUMN()-COLUMN($B$2))-95000000000000), ",", (OFFSET($B$2, ROW()-ROW($B$2), 0)-97000000000000),"]")) -> [6,1] | L4: =IF(EXACT((OFFSET(Entry!$B$2, ROW()-ROW($B$2), COLUMN()-COLUMN($B$2))), ""), "", CONCATENATE("[", (OFFSET($B$2, 0, COLUMN()-COLUMN($B$2))-95000000000000), ",", (OFFSET($B$2, ROW()-ROW($B$2), 0)-97000000000000),"]")) -> [7,1] | N4: =IF(EXACT((OFFSET(Entry!$B$2, ROW()-ROW($B$2), COLUMN()-COLUMN($B$2))), ""), "", CONCATENATE("[", (OFFSET($B$2, 0, COLUMN()-COLUMN($B$2))-95000000000000), ",", (OFFSET($B$2, ROW()-ROW($B$2), 0)-97000000000000),"]")) -> [8,1] | O4: =IF(EXACT((OFFSET(Entry!$B$2, ROW()-ROW($B$2), COLUMN()-COLUMN($B$2))), ""), "", CONCATENATE("[", (OFFSET($B$2, 0, COLUMN()-COLUMN($B$2))-95000000000000), ",", (OFFSET($B$2, ROW()-ROW($B$2), 0)-97000000000000),"]")) -> [9,1] | P4: =IF(EXACT((OFFSET(Entry!$B$2, ROW()-ROW($B$2), COLUMN()-COLUMN($B$2))), ""), "", CONCATENATE("[", (OFFSET($B$2, 0, COLUMN()-COLUMN($B$2))-95000000000000), ",", (OFFSET($B$2, ROW()-ROW($B$2), 0)-97000000000000),"]")) -> [10,1] | Q4: =IF(EXACT((OFFSET(Entry!$B$2, ROW()-ROW($B$2), COLUMN()-COLUMN($B$2))), ""), "", CONCATENATE("[", (OFFSET($B$2, 0, COLUMN()-COLUMN($B$2))-95000000000000), ",", (OFFSET($B$2, ROW()-ROW($B$2), 0)-97000000000000),"]")) -> [11,1] | R4: =IF(EXACT((OFFSET(Entry!$B$2, ROW()-ROW($B$2), COLUMN()-COLUMN($B$2))), ""), "", CONCATENATE("[", (OFFSET($B$2, 0, COLUMN()-COLUMN($B$2))-95000000000000), ",", (OFFSET($B$2, ROW()-ROW($B$2), 0)-97000000000000),"]")) -> [12,1] | S4: =IF(EXACT((OFFSET(Entry!$B$2, ROW()-ROW($B$2), COLUMN()-COLUMN($B$2))), ""), "", CONCATENATE("[", (OFFSET($B$2, 0, COLUMN()-COLUMN($B$2))-95000000000000), ",", (OFFSET($B$2, ROW()-ROW($B$2), 0)-97000000000000),"]")) -> [13,1] | T4: =IF(EXACT((OFFSET(Entry!$B$2, ROW()-ROW($B$2), COLUMN()-COLUMN($B$2))), ""), "", CONCATENATE("[", (OFFSET($B$2, 0, COLUMN()-COLUMN($B$2))-95000000000000), ",", (OFFSET($B$2, ROW()-ROW($B$2), 0)-97000000000000),"]")) | U4: =IF(EXACT((OFFSET(Entry!$B$2, ROW()-ROW($B$2), COLUMN()-COLUMN($B$2))), ""), "", CONCATENATE("[", (OFFSET($B$2, 0, COLUMN()-COLUMN($B$2))-95000000000000), ",", (OFFSET($B$2, ROW()-ROW($B$2), 0)-97000000000000),"]")) -> [14,1] | ... Y4: =IF(EXACT((OFFSET(Entry!$B$2, ROW()-ROW($B$2), COLUMN()-COLUMN($B$2))), ""), "", CONCATENATE("[", (OFFSET($B$2, 0, COLUMN()-COLUMN($B$2))-95000000000000), ",", (OFFSET($B$2, ROW()-ROW($B$2), 0)-97000000000000),"]")) -> [18,1] | AA4: =IF(EXACT((OFFSET(Entry!$B$2, ROW()-ROW($B$2), COLUMN()-COLUMN($B$2))), ""), "", CONCATENATE("[", (OFFSET($B$2, 0, COLUMN()-COLUMN($B$2))-95000000000000), ",", (OFFSET($B$2, ROW()-ROW($B$2), 0)-97000000000000),"]")) -> [19,1] | AB4: =IF(EXACT((OFFSET(Entry!$B$2, ROW()-ROW($B$2), COLUMN()-COLUMN($B$2))), ""), "", CONCATENATE("[", (OFFSET($B$2, 0, COLUMN()-COLUMN($B$2))-95000000000000), ",", (OFFSET($B$2, ROW()-ROW($B$2), 0)-97000000000000),"]")) -> [20,1] | AC4: =IF(EXACT((OFFSET(Entry!$B$2, ROW()-ROW($B$2), COLUMN()-COLUMN($B$2))), ""), "", CONCATENATE("[", (OFFSET($B$2, 0, COLUMN()-COLUMN($B$2))-95000000000000), ",", (OFFSET($B$2, ROW()-ROW($B$2), 0)-97000000000000),"]")) -> [21,1] | AD4: =IF(EXACT((OFFSET(Entry!$B$2, ROW()-ROW($B$2), COLUMN()-COLUMN($B$2))), ""), "", CONCATENATE("[", (OFFSET($B$2, 0, COLUMN()-COLUMN($B$2))-95000000000000), ",", (OFFSET($B$2, ROW()-ROW($B$2), 0)-97000000000000),"]")) -> [22,1] | AE4: =IF(EXACT((OFFSET(Entry!$B$2, ROW()-ROW($B$2), COLUMN()-COLUMN($B$2))), ""), "", CONCATENATE("[", (OFFSET($B$2, 0, COLUMN()-COLUMN($B$2))-95000000000000), ",", (OFFSET($B$2, ROW()-ROW($B$2), 0)-97000000000000),"]")) -> [23,1] | AF4: =IF(EXACT((OFFSET(Entry!$B$2, ROW()-ROW($B$2), COLUMN()-COLUMN($B$2))), ""), "", CONCATENATE("[", (OFFSET($B$2, 0, COLUMN()-COLUMN($B$2))-95000000000000), ",", (OFFSET($B$2, ROW()-ROW($B$2), 0)-97000000000000),"]")) -> [24,1] | AG4: =IF(EXACT((OFFSET(Entry!$B$2, ROW()-ROW($B$2), COLUMN()-COLUMN($B$2))), ""), "", CONCATENATE("[", (OFFSET($B$2, 0, COLUMN()-COLUMN($B$2))-95000000000000), ",", (OFFSET($B$2, ROW()-ROW($B$2), 0)-97000000000000),"]")) -> [25,1] | AH4: =IF(EXACT((OFFSET(Entry!$B$2, ROW()-ROW($B$2), COLUMN()-COLUMN($B$2))), ""), "", CONCATENATE("[", (OFFSET($B$2, 0, COLUMN()-COLUMN($B$2))-95000000000000), ",", (OFFSET($B$2, ROW()-ROW($B$2), 0)-97000000000000),"]")) -> [26,1] | AJ4: =IF(EXACT((OFFSET(Entry!$B$2, ROW()-ROW($B$2), COLUMN()-COLUMN($B$2))), ""), "", CONCATENATE("[", (OFFSET($B$2, 0, COLUMN()-COLUMN($B$2))-95000000000000), ",", (OFFSET($B$2, ROW()-ROW($B$2), 0)-97000000000000),"]")) -> [27,1] | AK4: =IF(EXACT((OFFSET(Entry!$B$2, ROW()-ROW($B$2), COLUMN()-COLUMN($B$2))), ""), "", CONCATENATE("[", (OFFSET($B$2, 0, COLUMN()-COLUMN($B$2))-95000000000000), ",", (OFFSET($B$2, ROW()-ROW($B$2), 0)-97000000000000),"]")) -> [28,1] | AL4: =IF(EXACT((OFFSET(Entry!$B$2, ROW()-ROW($B$2), COLUMN()-COLUMN($B$2))), ""), "", CONCATENATE("[", (OFFSET($B$2, 0, COLUMN()-COLUMN($B$2))-95000000000000), ",", (OFFSET($B$2, ROW()-ROW($B$2), 0)-97000000000000),"]")) -> [29,1] | AM4: =IF(EXACT((OFFSET(Entry!$B$2, ROW()-ROW($B$2), COLUMN()-COLUMN($B$2))), ""), "", CONCATENATE("[", (OFFSET($B$2, 0, COLUMN()-COLUMN($B$2))-95000000000000), ",", (OFFSET($B$2, ROW()-ROW($B$2), 0)-97000000000000),"]")) -> [30,1] | AN4: =IF(EXACT((OFFSET(Entry!$B$2, ROW()-ROW($B$2), COLUMN()-COLUMN($B$2))), ""), "", CONCATENATE("[", (OFFSET($B$2, 0, COLUMN()-COLUMN($B$2))-95000000000000), ",", (OFFSET($B$2, ROW()-ROW($B$2), 0)-97000000000000),"]")) -> [31,1] | AP4: =IF(EXACT((OFFSET(Entry!$B$2, ROW()-ROW($B$2), COLUMN()-COLUMN($B$2))), ""), "", CONCATENATE("[", (OFFSET($B$2, 0, COLUMN()-COLUMN($B$2))-95000000000000), ",", (OFFSET($B$2, ROW()-ROW($B$2), 0)-97000000000000),"]")) -> [32,1] | AQ4: =IF(EXACT((OFFSET(Entry!$B$2, ROW()-ROW($B$2), COLUMN()-COLUMN($B$2))), ""), "", CONCATENATE("[", (OFFSET($B$2, 0, COLUMN()-COLUMN($B$2))-95000000000000), ",", (OFFSET($B$2, ROW()-ROW($B$2), 0)-97000000000000),"]")) -> [33,1] | AR4: =IF(EXACT((OFFSET(Entry!$B$2, ROW()-ROW($B$2), COLUMN()-COLUMN($B$2))), ""), "", CONCATENATE("[", (OFFSET($B$2, 0, COLUMN()-COLUMN($B$2))-95000000000000), ",", (OFFSET($B$2, ROW()-ROW($B$2), 0)-97000000000000),"]")) -> [34,1] | AT4: =IF(EXACT((OFFSET(Entry!$B$2, ROW()-ROW($B$2), COLUMN()-COLUMN($B$2))), ""), "", CONCATENATE("[", (OFFSET($B$2, 0, COLUMN()-COLUMN($B$2))-95000000000000), ",", (OFFSET($B$2, ROW()-ROW($B$2), 0)-97000000000000),"]")) -> [35,1] | AU4: =IF(EXACT((OFFSET(Entry!$B$2, ROW()-ROW($B$2), COLUMN()-COLUMN($B$2))), ""), "", CONCATENATE("[", (OFFSET($B$2, 0, COLUMN()-COLUMN($B$2))-95000000000000), ",", (OFFSET($B$2, ROW()-ROW($B$2), 0)-97000000000000),"]")) -> [36,1] | AV4: =IF(EXACT((OFFSET(Entry!$B$2, ROW()-ROW($B$2), COLUMN()-COLUMN($B$2))), ""), "", CONCATENATE("[", (OFFSET($B$2, 0, COLUMN()-COLUMN($B$2))-95000000000000), ",", (OFFSET($B$2, ROW()-ROW($B$2), 0)-97000000000000),"]")) -> [37,1] | AW4: =IF(EXACT((OFFSET(Entry!$B$2, ROW()-ROW($B$2), COLUMN()-COLUMN($B$2))), ""), "", CONCATENATE("[", (OFFSET($B$2, 0, COLUMN()-COLUMN($B$2))-95000000000000), ",", (OFFSET($B$2, ROW()-ROW($B$2), 0)-97000000000000),"]")) -> [38,1] | AX4: =IF(EXACT((OFFSET(Entry!$B$2, ROW()-ROW($B$2), COLUMN()-COLUMN($B$2))), ""), "", CONCATENATE("[", (OFFSET($B$2, 0, COLUMN()-COLUMN($B$2))-95000000000000), ",", (OFFSET($B$2, ROW()-ROW($B$2), 0)-97000000000000),"]")) -> [39,1] | AZ4: =IF(EXACT((OFFSET(Entry!$B$2, ROW()-ROW($B$2), COLUMN()-COLUMN($B$2))), ""), "", CONCATENATE("[", (OFFSET($B$2, 0, COLUMN()-COLUMN($B$2))-95000000000000), ",", (OFFSET($B$2, ROW()-ROW($B$2), 0)-97000000000000),"]")) -> [40,1] | BA4: =IF(EXACT((OFFSET(Entry!$B$2, ROW()-ROW($B$2), COLUMN()-COLUMN($B$2))), ""), "", CONCATENATE("[", (OFFSET($B$2, 0, COLUMN()-COLUMN($B$2))-95000000000000), ",", (OFFSET($B$2, ROW()-ROW($B$2), 0)-97000000000000),"]")) -> [41,1] | BB4: =IF(EXACT((OFFSET(Entry!$B$2, ROW()-ROW($B$2), COLUMN()-COLUMN($B$2))), ""), "", CONCATENATE("[", (OFFSET($B$2, 0, COLUMN()-COLUMN($B$2))-95000000000000), ",", (OFFSET($B$2, ROW()-ROW($B$2), 0)-97000000000000),"]")) -> [42,1] | BD4: =IF(EXACT((OFFSET(Entry!$B$2, ROW()-ROW($B$2), COLUMN()-COLUMN($B$2))), ""), "", CONCATENATE("[", (OFFSET($B$2, 0, COLUMN()-COLUMN($B$2))-95000000000000), ",", (OFFSET($B$2, ROW()-ROW($B$2), 0)-97000000000000),"]")) -> [43,1] | BE4: =IF(EXACT((OFFSET(Entry!$B$2, ROW()-ROW($B$2), COLUMN()-COLUMN($B$2))), ""), "", CONCATENATE("[", (OFFSET($B$2, 0, COLUMN()-COLUMN($B$2))-95000000000000), ",", (OFFSET($B$2, ROW()-ROW($B$2), 0)-97000000000000),"]")) -> [44,1] | BF4: =IF(EXACT((OFFSET(Entry!$B$2, ROW()-ROW($B$2), COLUMN()-COLUMN($B$2))), ""), "", CONCATENATE("[", (OFFSET($B$2, 0, COLUMN()-COLUMN($B$2))-95000000000000), ",", (OFFSET($B$2, ROW()-ROW($B$2), 0)-97000000000000),"]")) -> [45,1] | BG4: =IF(EXACT((OFFSET(Entry!$B$2, ROW()-ROW($B$2), COLUMN()-COLUMN($B$2))), ""), "", CONCATENATE("[", (OFFSET($B$2, 0, COLUMN()-COLUMN($B$2))-95000000000000), ",", (OFFSET($B$2, ROW()-ROW($B$2), 0)-97000000000000),"]")) -> [46,1] | BH4: =IF(EXACT((OFFSET(Entry!$B$2, ROW()-ROW($B$2), COLUMN()-COLUMN($B$2))), ""), "", CONCATENATE("[", (OFFSET($B$2, 0, COLUMN()-COLUMN($B$2))-95000000000000), ",", (OFFSET($B$2, ROW()-ROW($B$2), 0)-97000000000000),"]")) -> [47,1] | BJ4: =IF(EXACT((OFFSET(Entry!$B$2, ROW()-ROW($B$2), COLUMN()-COLUMN($B$2))), ""), "", CONCATENATE("[", (OFFSET($B$2, 0, COLUMN()-COLUMN($B$2))-95000000000000), ",", (OFFSET($B$2, ROW()-ROW($B$2), 0)-97000000000000),"]")) -> [48,1] | BK4: =IF(EXACT((OFFSET(Entry!$B$2, ROW()-ROW($B$2), COLUMN()-COLUMN($B$2))), ""), "", CONCATENATE("[", (OFFSET($B$2, 0, COLUMN()-COLUMN($B$2))-95000000000000), ",", (OFFSET($B$2, ROW()-ROW($B$2), 0)-97000000000000),"]")) -> [49,1] | BL4: =IF(EXACT((OFFSET(Entry!$B$2, ROW()-ROW($B$2), COLUMN()-COLUMN($B$2))), ""), "", CONCATENATE("[", (OFFSET($B$2, 0, COLUMN()-COLUMN($B$2))-95000000000000), ",", (OFFSET($B$2, ROW()-ROW($B$2), 0)-97000000000000),"]")) -> [50,1] | BN4: =IF(EXACT((OFFSET(Entry!$B$2, ROW()-ROW($B$2), COLUMN()-COLUMN($B$2))), ""), "", CONCATENATE("[", (OFFSET($B$2, 0, COLUMN()-COLUMN($B$2))-95000000000000), ",", (OFFSET($B$2, ROW()-ROW($B$2), 0)-97000000000000),"]")) -> [51,1] | BO4: =IF(EXACT((OFFSET(Entry!$B$2, ROW()-ROW($B$2), COLUMN()-COLUMN($B$2))), ""), "", CONCATENATE("[", (OFFSET($B$2, 0, COLUMN()-COLUMN($B$2))-95000000000000), ",", (OFFSET($B$2, ROW()-ROW($B$2), 0)-97000000000000),"]")) -> [52,1] | BP4: =IF(EXACT((OFFSET(Entry!$B$2, ROW()-ROW($B$2), COLUMN()-COLUMN($B$2))), ""), "", CONCATENATE("[", (OFFSET($B$2, 0, COLUMN()-COLUMN($B$2))-95000000000000), ",", (OFFSET($B$2, ROW()-ROW($B$2), 0)-97000000000000),"]")) -> [53,1] | BR4: =IF(EXACT((OFFSET(Entry!$B$2, ROW()-ROW($B$2), COLUMN()-COLUMN($B$2))), ""), "", CONCATENATE("[", (OFFSET($B$2, 0, COLUMN()-COLUMN($B$2))-95000000000000), ",", (OFFSET($B$2, ROW()-ROW($B$2), 0)-97000000000000),"]")) -> [54,1] | BS4: =IF(EXACT((OFFSET(Entry!$B$2, ROW()-ROW($B$2), COLUMN()-COLUMN($B$2))), ""), "", CONCATENATE("[", (OFFSET($B$2, 0, COLUMN()-COLUMN($B$2))-95000000000000), ",", (OFFSET($B$2, ROW()-ROW($B$2), 0)-97000000000000),"]")) -> [55,1] | BT4: =IF(EXACT((OFFSET(Entry!$B$2, ROW()-ROW($B$2), COLUMN()-COLUMN($B$2))), ""), "", CONCATENATE("[", (OFFSET($B$2, 0, COLUMN()-COLUMN($B$2))-95000000000000), ",", (OFFSET($B$2, ROW()-ROW($B$2), 0)-97000000000000),"]")) -> [56,1] | BV4: =IF(EXACT((OFFSET(Entry!$B$2, ROW()-ROW($B$2), COLUMN()-COLUMN($B$2))), ""), "", CONCATENATE("[", (OFFSET($B$2, 0, COLUMN()-COLUMN($B$2))-95000000000000), ",", (OFFSET($B$2, ROW()-ROW($B$2), 0)-97000000000000),"]")) -> [57,1] | BW4: =IF(EXACT((OFFSET(Entry!$B$2, ROW()-ROW($B$2), COLUMN()-COLUMN($B$2))), ""), "", CONCATENATE("[", (OFFSET($B$2, 0, COLUMN()-COLUMN($B$2))-95000000000000), ",", (OFFSET($B$2, ROW()-ROW($B$2), 0)-97000000000000),"]")) -> [58,1] | BX4: =IF(EXACT((OFFSET(Entry!$B$2, ROW()-ROW($B$2), COLUMN()-COLUMN($B$2))), ""), "", CONCATENATE("[", (OFFSET($B$2, 0, COLUMN()-COLUMN($B$2))-95000000000000), ",", (OFFSET($B$2, ROW()-ROW($B$2), 0)-97000000000000),"]")) -> [59,1] | BZ4: =IF(EXACT((OFFSET(Entry!$B$2, ROW()-ROW($B$2), COLUMN()-COLUMN($B$2))), ""), "", CONCATENATE("[", (OFFSET($B$2, 0, COLUMN()-COLUMN($B$2))-95000000000000), ",", (OFFSET($B$2, ROW()-ROW($B$2), 0)-97000000000000),"]")) -> [60,1] | CA4: =IF(EXACT((OFFSET(Entry!$B$2, ROW()-ROW($B$2), COLUMN()-COLUMN($B$2))), ""), "", CONCATENATE("[", (OFFSET($B$2, 0, COLUMN()-COLUMN($B$2))-95000000000000), ",", (OFFSET($B$2, ROW()-ROW($B$2), 0)-97000000000000),"]")) -> [61,1] | CB4: =IF(EXACT((OFFSET(Entry!$B$2, ROW()-ROW($B$2), COLUMN()-COLUMN($B$2))), ""), "", CONCATENATE("[", (OFFSET($B$2, 0, COLUMN()-COLUMN($B$2))-95000000000000), ",", (OFFSET($B$2, ROW()-ROW($B$2), 0)-97000000000000),"]")) -> [62,1] | CD4: =IF(EXACT((OFFSET(Entry!$B$2, ROW()-ROW($B$2), COLUMN()-COLUMN($B$2))), ""), "", CONCATENATE("[", (OFFSET($B$2, 0, COLUMN()-COLUMN($B$2))-95000000000000), ",", (OFFSET($B$2, ROW()-ROW($B$2), 0)-97000000000000),"]")) -> [63,1] | CE4: =IF(EXACT((OFFSET(Entry!$B$2, ROW()-ROW($B$2), COLUMN()-COLUMN($B$2))), ""), "", CONCATENATE("[", (OFFSET($B$2, 0, COLUMN()-COLUMN($B$2))-95000000000000), ",", (OFFSET($B$2, ROW()-ROW($B$2), 0)-97000000000000),"]")) -> [64,1] | CF4: =IF(EXACT((OFFSET(Entry!$B$2, ROW()-ROW($B$2), COLUMN()-COLUMN($B$2))), ""), "", CONCATENATE("[", (OFFSET($B$2, 0, COLUMN()-COLUMN($B$2))-95000000000000), ",", (OFFSET($B$2, ROW()-ROW($B$2), 0)-97000000000000),"]")) -> [65,1]
