Workbook

Sheet MAIN
B2: User Role RefID | C2: User Role Name | D2: User Role Group RefID | E2: User Role Group Name | G2: SYS_PID Prediction | H2: SQL Syntax
G3: 253000000000000
B4: =IF(EXACT([1]DataLookUp!$B4, ""), "", [1]DataLookUp!$B4) -> 95000000000001 | C4: =IF(EXACT(B4, ""), "", [1]DataLookUp!$C4) -> Super User | D4: 252000000000001 | E4: =IF(EXACT(D4, ""), "", VLOOKUP(D4, [2]DataLookUp!$B$4:$C$32, 2, FALSE)) -> System | G4: =G3 + IF(EXACT(H4, ""), 0, 1) -> 253000000000001 | H4: =IF(AND(EXACT(B4, ""), EXACT(D4, "")), "", CONCATENATE("PERFORM ""SchSysConfig"".""Func_TblAppObject_UserRole_SET""(varSystemLoginSession, null::bigint, null::varchar, null::timestamptz, null::timestamptz, null::varchar, varInstitutionBranchID, varBaseCurrencyID, ", (IF(EXACT(B4, ""), "NULL", CONCATENATE("'", B4, "'"))),"::varchar);")) -> PERFORM "SchSysConfig"."Func_TblAppObject_UserRole_SET"(varSystemLoginSession, null::bigint, null::varchar, null::timestamptz, null::timestamptz, null::varchar, varInstitutionBranchID, varBaseCurrencyID, '95000000000001'::varchar); | J4: =IF(EXACT($H4, ""), "", CONCATENATE( "varSQL := varSQL || (CASE WHEN (varSQL = '') THEN '' ELSE ', ' END) || (SELECT JSON_BUILD_OBJECT (", "'recordID', NULL::bigint,", "'entities', ", "JSON_BUILD_OBJECT (", "'sysLoginSession_RefID', varSystemLoginSession::bigint,", "'sysDataAnnotation', NULL::varchar,", "'sysDataSetDateTimeTZ', NULL::timestamptz,", "'sysDataValidityStartDateTimeTZ', NULL::timestamptz,", "'sysDataValidityFinishDateTimeTZ', NULL::timestamptz,", "'sysPartitionRemovableRecordKey_RefID', NULL::bigint,", "'sysBranch_RefID', varInstitutionBranchID::bigint,", "'sysBaseCurrency_RefID',varBaseCurrencyID::bigint,", "'userRoleGroup_RefID', ", IF(EXACT($D4, ""), "null", CONCATENATE("'", SUBSTITUTE($D4, "'", "\'"), "'")), "::bigint, ", "'userRole_RefID', ", IF(EXACT($B4, ""), "null", CONCATENATE("'", SUBSTITUTE($B4, "'", "\'"), "'")), "::bigint", ")))::varchar;")) -> varSQL := varSQL || (CASE WHEN (varSQL = '') THEN '' ELSE ', ' END) || (SELECT JSON_BUILD_OBJECT ('recordID', NULL::bigint,'entities', JSON_BUILD_OBJECT ('sysLoginSession_RefID', varSystemLoginSession::bigint,'sysDataAnnotation', NULL::varchar,'sysDataSetDateTimeTZ', NULL::timestamptz,'sysDataValidityStartDateTimeTZ', NULL::timestamptz,'sysDataValidityFinishDateTimeTZ', NULL::timestamptz,'sysPartitionRemovableRecordKey_RefID', NULL::bigint,'sysBranch_RefID', varInstitutionBranchID::bigint,'sysBaseCurrency_RefID',varBaseCurrencyID::bigint,'userRoleGroup_RefID', '252000000000001'::bigint, 'userRole_RefID', '95000000000001'::bigint)))::varchar;
B5: =IF(EXACT([1]DataLookUp!$B5, ""), "", [1]DataLookUp!$B5) -> 95000000000002 | C5: =IF(EXACT(B5, ""), "", [1]DataLookUp!$C5) -> Guest | D5: 252000000000001 | E5: =IF(EXACT(D5, ""), "", VLOOKUP(D5, [2]DataLookUp!$B$4:$C$32, 2, FALSE)) -> System | G5: =G4 + IF(EXACT(H5, ""), 0, 1) -> 253000000000002 | H5: =IF(AND(EXACT(B5, ""), EXACT(D5, "")), "", CONCATENATE("PERFORM ""SchSysConfig"".""Func_TblAppObject_UserRole_SET""(varSystemLoginSession, null::bigint, null::varchar, null::timestamptz, null::timestamptz, null::varchar, varInstitutionBranchID, varBaseCurrencyID, ", (IF(EXACT(B5, ""), "NULL", CONCATENATE("'", B5, "'"))),"::varchar);")) -> PERFORM "SchSysConfig"."Func_TblAppObject_UserRole_SET"(varSystemLoginSession, null::bigint, null::varchar, null::timestamptz, null::timestamptz, null::varchar, varInstitutionBranchID, varBaseCurrencyID, '95000000000002'::varchar); | J5: =IF(EXACT($H5, ""), "", CONCATENATE( "varSQL := varSQL || (CASE WHEN (varSQL = '') THEN '' ELSE ', ' END) || (SELECT JSON_BUILD_OBJECT (", "'recordID', NULL::bigint,", "'entities', ", "JSON_BUILD_OBJECT (", "'sysLoginSession_RefID', varSystemLoginSession::bigint,", "'sysDataAnnotation', NULL::varchar,", "'sysDataSetDateTimeTZ', NULL::timestamptz,", "'sysDataValidityStartDateTimeTZ', NULL::timestamptz,", "'sysDataValidityFinishDateTimeTZ', NULL::timestamptz,", "'sysPartitionRemovableRecordKey_RefID', NULL::bigint,", "'sysBranch_RefID', varInstitutionBranchID::bigint,", "'sysBaseCurrency_RefID',varBaseCurrencyID::bigint,", "'userRoleGroup_RefID', ", IF(EXACT($D5, ""), "null", CONCATENATE("'", SUBSTITUTE($D5, "'", "\'"), "'")), "::bigint, ", "'userRole_RefID', ", IF(EXACT($B5, ""), "null", CONCATENATE("'", SUBSTITUTE($B5, "'", "\'"), "'")), "::bigint", ")))::varchar;")) -> varSQL := varSQL || (CASE WHEN (varSQL = '') THEN '' ELSE ', ' END) || (SELECT JSON_BUILD_OBJECT ('recordID', NULL::bigint,'entities', JSON_BUILD_OBJECT ('sysLoginSession_RefID', varSystemLoginSession::bigint,'sysDataAnnotation', NULL::varchar,'sysDataSetDateTimeTZ', NULL::timestamptz,'sysDataValidityStartDateTimeTZ', NULL::timestamptz,'sysDataValidityFinishDateTimeTZ', NULL::timestamptz,'sysPartitionRemovableRecordKey_RefID', NULL::bigint,'sysBranch_RefID', varInstitutionBranchID::bigint,'sysBaseCurrency_RefID',varBaseCurrencyID::bigint,'userRoleGroup_RefID', '252000000000001'::bigint, 'userRole_RefID', '95000000000002'::bigint)))::varchar;
B6: =IF(EXACT([1]DataLookUp!$B6, ""), "", [1]DataLookUp!$B6) | C6: =IF(EXACT(B6, ""), "", [1]DataLookUp!$C6) | E6: =IF(EXACT(D6, ""), "", VLOOKUP(D6, [2]DataLookUp!$B$4:$C$32, 2, FALSE)) | G6: =G5 + IF(EXACT(H6, ""), 0, 1) -> 253000000000002 | H6: =IF(AND(EXACT(B6, ""), EXACT(D6, "")), "", CONCATENATE("PERFORM ""SchSysConfig"".""Func_TblAppObject_UserRole_SET""(varSystemLoginSession, null::bigint, null::varchar, null::timestamptz, null::timestamptz, null::varchar, varInstitutionBranchID, varBaseCurrencyID, ", (IF(EXACT(B6, ""), "NULL", CONCATENATE("'", B6, "'"))),"::varchar);")) | J6: =IF(EXACT($H6, ""), "", CONCATENATE( "varSQL := varSQL || (CASE WHEN (varSQL = '') THEN '' ELSE ', ' END) || (SELECT JSON_BUILD_OBJECT (", "'recordID', NULL::bigint,", "'entities', ", "JSON_BUILD_OBJECT (", "'sysLoginSession_RefID', varSystemLoginSession::bigint,", "'sysDataAnnotation', NULL::varchar,", "'sysDataSetDateTimeTZ', NULL::timestamptz,", "'sysDataValidityStartDateTimeTZ', NULL::timestamptz,", "'sysDataValidityFinishDateTimeTZ', NULL::timestamptz,", "'sysPartitionRemovableRecordKey_RefID', NULL::bigint,", "'sysBranch_RefID', varInstitutionBranchID::bigint,", "'sysBaseCurrency_RefID',varBaseCurrencyID::bigint,", "'userRoleGroup_RefID', ", IF(EXACT($D6, ""), "null", CONCATENATE("'", SUBSTITUTE($D6, "'", "\'"), "'")), "::bigint, ", "'userRole_RefID', ", IF(EXACT($B6, ""), "null", CONCATENATE("'", SUBSTITUTE($B6, "'", "\'"), "'")), "::bigint", ")))::varchar;"))
B7: =IF(EXACT([1]DataLookUp!$B7, ""), "", [1]DataLookUp!$B7) -> 95000000000003 | C7: =IF(EXACT(B7, ""), "", [1]DataLookUp!$C7) -> Default Employee Role | D7: 252000000000001 | E7: =IF(EXACT(D7, ""), "", VLOOKUP(D7, [2]DataLookUp!$B$4:$C$32, 2, FALSE)) -> System | G7: =G6 + IF(EXACT(H7, ""), 0, 1) -> 253000000000003 | H7: =IF(AND(EXACT(B7, ""), EXACT(D7, "")), "", CONCATENATE("PERFORM ""SchSysConfig"".""Func_TblAppObject_UserRole_SET""(varSystemLoginSession, null::bigint, null::varchar, null::timestamptz, null::timestamptz, null::varchar, varInstitutionBranchID, varBaseCurrencyID, ", (IF(EXACT(B7, ""), "NULL", CONCATENATE("'", B7, "'"))),"::varchar);")) -> PERFORM "SchSysConfig"."Func_TblAppObject_UserRole_SET"(varSystemLoginSession, null::bigint, null::varchar, null::timestamptz, null::timestamptz, null::varchar, varInstitutionBranchID, varBaseCurrencyID, '95000000000003'::varchar); | J7: =IF(EXACT($H7, ""), "", CONCATENATE( "varSQL := varSQL || (CASE WHEN (varSQL = '') THEN '' ELSE ', ' END) || (SELECT JSON_BUILD_OBJECT (", "'recordID', NULL::bigint,", "'entities', ", "JSON_BUILD_OBJECT (", "'sysLoginSession_RefID', varSystemLoginSession::bigint,", "'sysDataAnnotation', NULL::varchar,", "'sysDataSetDateTimeTZ', NULL::timestamptz,", "'sysDataValidityStartDateTimeTZ', NULL::timestamptz,", "'sysDataValidityFinishDateTimeTZ', NULL::timestamptz,", "'sysPartitionRemovableRecordKey_RefID', NULL::bigint,", "'sysBranch_RefID', varInstitutionBranchID::bigint,", "'sysBaseCurrency_RefID',varBaseCurrencyID::bigint,", "'userRoleGroup_RefID', ", IF(EXACT($D7, ""), "null", CONCATENATE("'", SUBSTITUTE($D7, "'", "\'"), "'")), "::bigint, ", "'userRole_RefID', ", IF(EXACT($B7, ""), "null", CONCATENATE("'", SUBSTITUTE($B7, "'", "\'"), "'")), "::bigint", ")))::varchar;")) -> varSQL := varSQL || (CASE WHEN (varSQL = '') THEN '' ELSE ', ' END) || (SELECT JSON_BUILD_OBJECT ('recordID', NULL::bigint,'entities', JSON_BUILD_OBJECT ('sysLoginSession_RefID', varSystemLoginSession::bigint,'sysDataAnnotation', NULL::varchar,'sysDataSetDateTimeTZ', NULL::timestamptz,'sysDataValidityStartDateTimeTZ', NULL::timestamptz,'sysDataValidityFinishDateTimeTZ', NULL::timestamptz,'sysPartitionRemovableRecordKey_RefID', NULL::bigint,'sysBranch_RefID', varInstitutionBranchID::bigint,'sysBaseCurrency_RefID',varBaseCurrencyID::bigint,'userRoleGroup_RefID', '252000000000001'::bigint, 'userRole_RefID', '95000000000003'::bigint)))::varchar;
B8: =IF(EXACT([1]DataLookUp!$B8, ""), "", [1]DataLookUp!$B8) | C8: =IF(EXACT(B8, ""), "", [1]DataLookUp!$C8) | E8: =IF(EXACT(D8, ""), "", VLOOKUP(D8, [2]DataLookUp!$B$4:$C$32, 2, FALSE)) | G8: =G7 + IF(EXACT(H8, ""), 0, 1) -> 253000000000003 | H8: =IF(AND(EXACT(B8, ""), EXACT(D8, "")), "", CONCATENATE("PERFORM ""SchSysConfig"".""Func_TblAppObject_UserRole_SET""(varSystemLoginSession, null::bigint, null::varchar, null::timestamptz, null::timestamptz, null::varchar, varInstitutionBranchID, varBaseCurrencyID, ", (IF(EXACT(B8, ""), "NULL", CONCATENATE("'", B8, "'"))),"::varchar);")) | J8: =IF(EXACT($H8, ""), "", CONCATENATE( "varSQL := varSQL || (CASE WHEN (varSQL = '') THEN '' ELSE ', ' END) || (SELECT JSON_BUILD_OBJECT (", "'recordID', NULL::bigint,", "'entities', ", "JSON_BUILD_OBJECT (", "'sysLoginSession_RefID', varSystemLoginSession::bigint,", "'sysDataAnnotation', NULL::varchar,", "'sysDataSetDateTimeTZ', NULL::timestamptz,", "'sysDataValidityStartDateTimeTZ', NULL::timestamptz,", "'sysDataValidityFinishDateTimeTZ', NULL::timestamptz,", "'sysPartitionRemovableRecordKey_RefID', NULL::bigint,", "'sysBranch_RefID', varInstitutionBranchID::bigint,", "'sysBaseCurrency_RefID',varBaseCurrencyID::bigint,", "'userRoleGroup_RefID', ", IF(EXACT($D8, ""), "null", CONCATENATE("'", SUBSTITUTE($D8, "'", "\'"), "'")), "::bigint, ", "'userRole_RefID', ", IF(EXACT($B8, ""), "null", CONCATENATE("'", SUBSTITUTE($B8, "'", "\'"), "'")), "::bigint", ")))::varchar;"))
B9: =IF(EXACT([1]DataLookUp!$B9, ""), "", [1]DataLookUp!$B9) -> 95000000000004 | C9: =IF(EXACT(B9, ""), "", [1]DataLookUp!$C9) -> Share Holder | D9: 252000000000002 | E9: =IF(EXACT(D9, ""), "", VLOOKUP(D9, [2]DataLookUp!$B$4:$C$32, 2, FALSE)) -> External | G9: =G8 + IF(EXACT(H9, ""), 0, 1) -> 253000000000004 | H9: =IF(AND(EXACT(B9, ""), EXACT(D9, "")), "", CONCATENATE("PERFORM ""SchSysConfig"".""Func_TblAppObject_UserRole_SET""(varSystemLoginSession, null::bigint, null::varchar, null::timestamptz, null::timestamptz, null::varchar, varInstitutionBranchID, varBaseCurrencyID, ", (IF(EXACT(B9, ""), "NULL", CONCATENATE("'", B9, "'"))),"::varchar);")) -> PERFORM "SchSysConfig"."Func_TblAppObject_UserRole_SET"(varSystemLoginSession, null::bigint, null::varchar, null::timestamptz, null::timestamptz, null::varchar, varInstitutionBranchID, varBaseCurrencyID, '95000000000004'::varchar); | J9: =IF(EXACT($H9, ""), "", CONCATENATE( "varSQL := varSQL || (CASE WHEN (varSQL = '') THEN '' ELSE ', ' END) || (SELECT JSON_BUILD_OBJECT (", "'recordID', NULL::bigint,", "'entities', ", "JSON_BUILD_OBJECT (", "'sysLoginSession_RefID', varSystemLoginSession::bigint,", "'sysDataAnnotation', NULL::varchar,", "'sysDataSetDateTimeTZ', NULL::timestamptz,", "'sysDataValidityStartDateTimeTZ', NULL::timestamptz,", "'sysDataValidityFinishDateTimeTZ', NULL::timestamptz,", "'sysPartitionRemovableRecordKey_RefID', NULL::bigint,", "'sysBranch_RefID', varInstitutionBranchID::bigint,", "'sysBaseCurrency_RefID',varBaseCurrencyID::bigint,", "'userRoleGroup_RefID', ", IF(EXACT($D9, ""), "null", CONCATENATE("'", SUBSTITUTE($D9, "'", "\'"), "'")), "::bigint, ", "'userRole_RefID', ", IF(EXACT($B9, ""), "null", CONCATENATE("'", SUBSTITUTE($B9, "'", "\'"), "'")), "::bigint", ")))::varchar;")) -> varSQL := varSQL || (CASE WHEN (varSQL = '') THEN '' ELSE ', ' END) || (SELECT JSON_BUILD_OBJECT ('recordID', NULL::bigint,'entities', JSON_BUILD_OBJECT ('sysLoginSession_RefID', varSystemLoginSession::bigint,'sysDataAnnotation', NULL::varchar,'sysDataSetDateTimeTZ', NULL::timestamptz,'sysDataValidityStartDateTimeTZ', NULL::timestamptz,'sysDataValidityFinishDateTimeTZ', NULL::timestamptz,'sysPartitionRemovableRecordKey_RefID', NULL::bigint,'sysBranch_RefID', varInstitutionBranchID::bigint,'sysBaseCurrency_RefID',varBaseCurrencyID::bigint,'userRoleGroup_RefID', '252000000000002'::bigint, 'userRole_RefID', '95000000000004'::bigint)))::varchar;
B10: =IF(EXACT([1]DataLookUp!$B10, ""), "", [1]DataLookUp!$B10) -> 95000000000005 | C10: =IF(EXACT(B10, ""), "", [1]DataLookUp!$C10) -> Stack Holder | D10: 252000000000002 | E10: =IF(EXACT(D10, ""), "", VLOOKUP(D10, [2]DataLookUp!$B$4:$C$32, 2, FALSE)) -> External | G10: =G9 + IF(EXACT(H10, ""), 0, 1) -> 253000000000005 | H10: =IF(AND(EXACT(B10, ""), EXACT(D10, "")), "", CONCATENATE("PERFORM ""SchSysConfig"".""Func_TblAppObject_UserRole_SET""(varSystemLoginSession, null::bigint, null::varchar, null::timestamptz, null::timestamptz, null::varchar, varInstitutionBranchID, varBaseCurrencyID, ", (IF(EXACT(B10, ""), "NULL", CONCATENATE("'", B10, "'"))),"::varchar);")) -> PERFORM "SchSysConfig"."Func_TblAppObject_UserRole_SET"(varSystemLoginSession, null::bigint, null::varchar, null::timestamptz, null::timestamptz, null::varchar, varInstitutionBranchID, varBaseCurrencyID, '95000000000005'::varchar); | J10: =IF(EXACT($H10, ""), "", CONCATENATE( "varSQL := varSQL || (CASE WHEN (varSQL = '') THEN '' ELSE ', ' END) || (SELECT JSON_BUILD_OBJECT (", "'recordID', NULL::bigint,", "'entities', ", "JSON_BUILD_OBJECT (", "'sysLoginSession_RefID', varSystemLoginSession::bigint,", "'sysDataAnnotation', NULL::varchar,", "'sysDataSetDateTimeTZ', NULL::timestamptz,", "'sysDataValidityStartDateTimeTZ', NULL::timestamptz,", "'sysDataValidityFinishDateTimeTZ', NULL::timestamptz,", "'sysPartitionRemovableRecordKey_RefID', NULL::bigint,", "'sysBranch_RefID', varInstitutionBranchID::bigint,", "'sysBaseCurrency_RefID',varBaseCurrencyID::bigint,", "'userRoleGroup_RefID', ", IF(EXACT($D10, ""), "null", CONCATENATE("'", SUBSTITUTE($D10, "'", "\'"), "'")), "::bigint, ", "'userRole_RefID', ", IF(EXACT($B10, ""), "null", CONCATENATE("'", SUBSTITUTE($B10, "'", "\'"), "'")), "::bigint", ")))::varchar;")) -> varSQL := varSQL || (CASE WHEN (varSQL = '') THEN '' ELSE ', ' END) || (SELECT JSON_BUILD_OBJECT ('recordID', NULL::bigint,'entities', JSON_BUILD_OBJECT ('sysLoginSession_RefID', varSystemLoginSession::bigint,'sysDataAnnotation', NULL::varchar,'sysDataSetDateTimeTZ', NULL::timestamptz,'sysDataValidityStartDateTimeTZ', NULL::timestamptz,'sysDataValidityFinishDateTimeTZ', NULL::timestamptz,'sysPartitionRemovableRecordKey_RefID', NULL::bigint,'sysBranch_RefID', varInstitutionBranchID::bigint,'sysBaseCurrency_RefID',varBaseCurrencyID::bigint,'userRoleGroup_RefID', '252000000000002'::bigint, 'userRole_RefID', '95000000000005'::bigint)))::varchar;
B11: =IF(EXACT([1]DataLookUp!$B11, ""), "", [1]DataLookUp!$B11) -> 95000000000006 | C11: =IF(EXACT(B11, ""), "", [1]DataLookUp!$C11) -> Public Accounting Firm | D11: 252000000000002 | E11: =IF(EXACT(D11, ""), "", VLOOKUP(D11, [2]DataLookUp!$B$4:$C$32, 2, FALSE)) -> External | G11: =G10 + IF(EXACT(H11, ""), 0, 1) -> 253000000000006 | H11: =IF(AND(EXACT(B11, ""), EXACT(D11, "")), "", CONCATENATE("PERFORM ""SchSysConfig"".""Func_TblAppObject_UserRole_SET""(varSystemLoginSession, null::bigint, null::varchar, null::timestamptz, null::timestamptz, null::varchar, varInstitutionBranchID, varBaseCurrencyID, ", (IF(EXACT(B11, ""), "NULL", CONCATENATE("'", B11, "'"))),"::varchar);")) -> PERFORM "SchSysConfig"."Func_TblAppObject_UserRole_SET"(varSystemLoginSession, null::bigint, null::varchar, null::timestamptz, null::timestamptz, null::varchar, varInstitutionBranchID, varBaseCurrencyID, '95000000000006'::varchar); | J11: =IF(EXACT($H11, ""), "", CONCATENATE( "varSQL := varSQL || (CASE WHEN (varSQL = '') THEN '' ELSE ', ' END) || (SELECT JSON_BUILD_OBJECT (", "'recordID', NULL::bigint,", "'entities', ", "JSON_BUILD_OBJECT (", "'sysLoginSession_RefID', varSystemLoginSession::bigint,", "'sysDataAnnotation', NULL::varchar,", "'sysDataSetDateTimeTZ', NULL::timestamptz,", "'sysDataValidityStartDateTimeTZ', NULL::timestamptz,", "'sysDataValidityFinishDateTimeTZ', NULL::timestamptz,", "'sysPartitionRemovableRecordKey_RefID', NULL::bigint,", "'sysBranch_RefID', varInstitutionBranchID::bigint,", "'sysBaseCurrency_RefID',varBaseCurrencyID::bigint,", "'userRoleGroup_RefID', ", IF(EXACT($D11, ""), "null", CONCATENATE("'", SUBSTITUTE($D11, "'", "\'"), "'")), "::bigint, ", "'userRole_RefID', ", IF(EXACT($B11, ""), "null", CONCATENATE("'", SUBSTITUTE($B11, "'", "\'"), "'")), "::bigint", ")))::varchar;")) -> varSQL := varSQL || (CASE WHEN (varSQL = '') THEN '' ELSE ', ' END) || (SELECT JSON_BUILD_OBJECT ('recordID', NULL::bigint,'entities', JSON_BUILD_OBJECT ('sysLoginSession_RefID', varSystemLoginSession::bigint,'sysDataAnnotation', NULL::varchar,'sysDataSetDateTimeTZ', NULL::timestamptz,'sysDataValidityStartDateTimeTZ', NULL::timestamptz,'sysDataValidityFinishDateTimeTZ', NULL::timestamptz,'sysPartitionRemovableRecordKey_RefID', NULL::bigint,'sysBranch_RefID', varInstitutionBranchID::bigint,'sysBaseCurrency_RefID',varBaseCurrencyID::bigint,'userRoleGroup_RefID', '252000000000002'::bigint, 'userRole_RefID', '95000000000006'::bigint)))::varchar;
B12: =IF(EXACT([1]DataLookUp!$B12, ""), "", [1]DataLookUp!$B12) -> 95000000000007 | C12: =IF(EXACT(B12, ""), "", [1]DataLookUp!$C12) -> Commissary | D12: 252000000000004 | E12: =IF(EXACT(D12, ""), "", VLOOKUP(D12, [2]DataLookUp!$B$4:$C$32, 2, FALSE)) -> Board Of Comissioner | G12: =G11 + IF(EXACT(H12, ""), 0, 1) -> 253000000000007 | H12: =IF(AND(EXACT(B12, ""), EXACT(D12, "")), "", CONCATENATE("PERFORM ""SchSysConfig"".""Func_TblAppObject_UserRole_SET""(varSystemLoginSession, null::bigint, null::varchar, null::timestamptz, null::timestamptz, null::varchar, varInstitutionBranchID, varBaseCurrencyID, ", (IF(EXACT(B12, ""), "NULL", CONCATENATE("'", B12, "'"))),"::varchar);")) -> PERFORM "SchSysConfig"."Func_TblAppObject_UserRole_SET"(varSystemLoginSession, null::bigint, null::varchar, null::timestamptz, null::timestamptz, null::varchar, varInstitutionBranchID, varBaseCurrencyID, '95000000000007'::varchar); | J12: =IF(EXACT($H12, ""), "", CONCATENATE( "varSQL := varSQL || (CASE WHEN (varSQL = '') THEN '' ELSE ', ' END) || (SELECT JSON_BUILD_OBJECT (", "'recordID', NULL::bigint,", "'entities', ", "JSON_BUILD_OBJECT (", "'sysLoginSession_RefID', varSystemLoginSession::bigint,", "'sysDataAnnotation', NULL::varchar,", "'sysDataSetDateTimeTZ', NULL::timestamptz,", "'sysDataValidityStartDateTimeTZ', NULL::timestamptz,", "'sysDataValidityFinishDateTimeTZ', NULL::timestamptz,", "'sysPartitionRemovableRecordKey_RefID', NULL::bigint,", "'sysBranch_RefID', varInstitutionBranchID::bigint,", "'sysBaseCurrency_RefID',varBaseCurrencyID::bigint,", "'userRoleGroup_RefID', ", IF(EXACT($D12, ""), "null", CONCATENATE("'", SUBSTITUTE($D12, "'", "\'"), "'")), "::bigint, ", "'userRole_RefID', ", IF(EXACT($B12, ""), "null", CONCATENATE("'", SUBSTITUTE($B12, "'", "\'"), "'")), "::bigint", ")))::varchar;")) -> varSQL := varSQL || (CASE WHEN (varSQL = '') THEN '' ELSE ', ' END) || (SELECT JSON_BUILD_OBJECT ('recordID', NULL::bigint,'entities', JSON_BUILD_OBJECT ('sysLoginSession_RefID', varSystemLoginSession::bigint,'sysDataAnnotation', NULL::varchar,'sysDataSetDateTimeTZ', NULL::timestamptz,'sysDataValidityStartDateTimeTZ', NULL::timestamptz,'sysDataValidityFinishDateTimeTZ', NULL::timestamptz,'sysPartitionRemovableRecordKey_RefID', NULL::bigint,'sysBranch_RefID', varInstitutionBranchID::bigint,'sysBaseCurrency_RefID',varBaseCurrencyID::bigint,'userRoleGroup_RefID', '252000000000004'::bigint, 'userRole_RefID', '95000000000007'::bigint)))::varchar;
B13: =IF(EXACT([1]DataLookUp!$B13, ""), "", [1]DataLookUp!$B13) | C13: =IF(EXACT(B13, ""), "", [1]DataLookUp!$C13) | E13: =IF(EXACT(D13, ""), "", VLOOKUP(D13, [2]DataLookUp!$B$4:$C$32, 2, FALSE)) | G13: =G12 + IF(EXACT(H13, ""), 0, 1) -> 253000000000007 | H13: =IF(AND(EXACT(B13, ""), EXACT(D13, "")), "", CONCATENATE("PERFORM ""SchSysConfig"".""Func_TblAppObject_UserRole_SET""(varSystemLoginSession, null::bigint, null::varchar, null::timestamptz, null::timestamptz, null::varchar, varInstitutionBranchID, varBaseCurrencyID, ", (IF(EXACT(B13, ""), "NULL", CONCATENATE("'", B13, "'"))),"::varchar);")) | J13: =IF(EXACT($H13, ""), "", CONCATENATE( "varSQL := varSQL || (CASE WHEN (varSQL = '') THEN '' ELSE ', ' END) || (SELECT JSON_BUILD_OBJECT (", "'recordID', NULL::bigint,", "'entities', ", "JSON_BUILD_OBJECT (", "'sysLoginSession_RefID', varSystemLoginSession::bigint,", "'sysDataAnnotation', NULL::varchar,", "'sysDataSetDateTimeTZ', NULL::timestamptz,", "'sysDataValidityStartDateTimeTZ', NULL::timestamptz,", "'sysDataValidityFinishDateTimeTZ', NULL::timestamptz,", "'sysPartitionRemovableRecordKey_RefID', NULL::bigint,", "'sysBranch_RefID', varInstitutionBranchID::bigint,", "'sysBaseCurrency_RefID',varBaseCurrencyID::bigint,", "'userRoleGroup_RefID', ", IF(EXACT($D13, ""), "null", CONCATENATE("'", SUBSTITUTE($D13, "'", "\'"), "'")), "::bigint, ", "'userRole_RefID', ", IF(EXACT($B13, ""), "null", CONCATENATE("'", SUBSTITUTE($B13, "'", "\'"), "'")), "::bigint", ")))::varchar;"))
B14: =IF(EXACT([1]DataLookUp!$B14, ""), "", [1]DataLookUp!$B14) -> 95000000000008 | C14: =IF(EXACT(B14, ""), "", [1]DataLookUp!$C14) -> Director | D14: 252000000000003 | E14: =IF(EXACT(D14, ""), "", VLOOKUP(D14, [2]DataLookUp!$B$4:$C$32, 2, FALSE)) -> Board Of Director | G14: =G13 + IF(EXACT(H14, ""), 0, 1) -> 253000000000008 | H14: =IF(AND(EXACT(B14, ""), EXACT(D14, "")), "", CONCATENATE("PERFORM ""SchSysConfig"".""Func_TblAppObject_UserRole_SET""(varSystemLoginSession, null::bigint, null::varchar, null::timestamptz, null::timestamptz, null::varchar, varInstitutionBranchID, varBaseCurrencyID, ", (IF(EXACT(B14, ""), "NULL", CONCATENATE("'", B14, "'"))),"::varchar);")) -> PERFORM "SchSysConfig"."Func_TblAppObject_UserRole_SET"(varSystemLoginSession, null::bigint, null::varchar, null::timestamptz, null::timestamptz, null::varchar, varInstitutionBranchID, varBaseCurrencyID, '95000000000008'::varchar); | J14: =IF(EXACT($H14, ""), "", CONCATENATE( "varSQL := varSQL || (CASE WHEN (varSQL = '') THEN '' ELSE ', ' END) || (SELECT JSON_BUILD_OBJECT (", "'recordID', NULL::bigint,", "'entities', ", "JSON_BUILD_OBJECT (", "'sysLoginSession_RefID', varSystemLoginSession::bigint,", "'sysDataAnnotation', NULL::varchar,", "'sysDataSetDateTimeTZ', NULL::timestamptz,", "'sysDataValidityStartDateTimeTZ', NULL::timestamptz,", "'sysDataValidityFinishDateTimeTZ', NULL::timestamptz,", "'sysPartitionRemovableRecordKey_RefID', NULL::bigint,", "'sysBranch_RefID', varInstitutionBranchID::bigint,", "'sysBaseCurrency_RefID',varBaseCurrencyID::bigint,", "'userRoleGroup_RefID', ", IF(EXACT($D14, ""), "null", CONCATENATE("'", SUBSTITUTE($D14, "'", "\'"), "'")), "::bigint, ", "'userRole_RefID', ", IF(EXACT($B14, ""), "null", CONCATENATE("'", SUBSTITUTE($B14, "'", "\'"), "'")), "::bigint", ")))::varchar;")) -> varSQL := varSQL || (CASE WHEN (varSQL = '') THEN '' ELSE ', ' END) || (SELECT JSON_BUILD_OBJECT ('recordID', NULL::bigint,'entities', JSON_BUILD_OBJECT ('sysLoginSession_RefID', varSystemLoginSession::bigint,'sysDataAnnotation', NULL::varchar,'sysDataSetDateTimeTZ', NULL::timestamptz,'sysDataValidityStartDateTimeTZ', NULL::timestamptz,'sysDataValidityFinishDateTimeTZ', NULL::timestamptz,'sysPartitionRemovableRecordKey_RefID', NULL::bigint,'sysBranch_RefID', varInstitutionBranchID::bigint,'sysBaseCurrency_RefID',varBaseCurrencyID::bigint,'userRoleGroup_RefID', '252000000000003'::bigint, 'userRole_RefID', '95000000000008'::bigint)))::varchar;
B15: =IF(EXACT([1]DataLookUp!$B15, ""), "", [1]DataLookUp!$B15) -> 95000000000009 | C15: =IF(EXACT(B15, ""), "", [1]DataLookUp!$C15) -> President Director | D15: 252000000000003 | E15: =IF(EXACT(D15, ""), "", VLOOKUP(D15, [2]DataLookUp!$B$4:$C$32, 2, FALSE)) -> Board Of Director | G15: =G14 + IF(EXACT(H15, ""), 0, 1) -> 253000000000009 | H15: =IF(AND(EXACT(B15, ""), EXACT(D15, "")), "", CONCATENATE("PERFORM ""SchSysConfig"".""Func_TblAppObject_UserRole_SET""(varSystemLoginSession, null::bigint, null::varchar, null::timestamptz, null::timestamptz, null::varchar, varInstitutionBranchID, varBaseCurrencyID, ", (IF(EXACT(B15, ""), "NULL", CONCATENATE("'", B15, "'"))),"::varchar);")) -> PERFORM "SchSysConfig"."Func_TblAppObject_UserRole_SET"(varSystemLoginSession, null::bigint, null::varchar, null::timestamptz, null::timestamptz, null::varchar, varInstitutionBranchID, varBaseCurrencyID, '95000000000009'::varchar); | J15: =IF(EXACT($H15, ""), "", CONCATENATE( "varSQL := varSQL || (CASE WHEN (varSQL = '') THEN '' ELSE ', ' END) || (SELECT JSON_BUILD_OBJECT (", "'recordID', NULL::bigint,", "'entities', ", "JSON_BUILD_OBJECT (", "'sysLoginSession_RefID', varSystemLoginSession::bigint,", "'sysDataAnnotation', NULL::varchar,", "'sysDataSetDateTimeTZ', NULL::timestamptz,", "'sysDataValidityStartDateTimeTZ', NULL::timestamptz,", "'sysDataValidityFinishDateTimeTZ', NULL::timestamptz,", "'sysPartitionRemovableRecordKey_RefID', NULL::bigint,", "'sysBranch_RefID', varInstitutionBranchID::bigint,", "'sysBaseCurrency_RefID',varBaseCurrencyID::bigint,", "'userRoleGroup_RefID', ", IF(EXACT($D15, ""), "null", CONCATENATE("'", SUBSTITUTE($D15, "'", "\'"), "'")), "::bigint, ", "'userRole_RefID', ", IF(EXACT($B15, ""), "null", CONCATENATE("'", SUBSTITUTE($B15, "'", "\'"), "'")), "::bigint", ")))::varchar;")) -> varSQL := varSQL || (CASE WHEN (varSQL = '') THEN '' ELSE ', ' END) || (SELECT JSON_BUILD_OBJECT ('recordID', NULL::bigint,'entities', JSON_BUILD_OBJECT ('sysLoginSession_RefID', varSystemLoginSession::bigint,'sysDataAnnotation', NULL::varchar,'sysDataSetDateTimeTZ', NULL::timestamptz,'sysDataValidityStartDateTimeTZ', NULL::timestamptz,'sysDataValidityFinishDateTimeTZ', NULL::timestamptz,'sysPartitionRemovableRecordKey_RefID', NULL::bigint,'sysBranch_RefID', varInstitutionBranchID::bigint,'sysBaseCurrency_RefID',varBaseCurrencyID::bigint,'userRoleGroup_RefID', '252000000000003'::bigint, 'userRole_RefID', '95000000000009'::bigint)))::varchar;
B16: =IF(EXACT([1]DataLookUp!$B16, ""), "", [1]DataLookUp!$B16) -> 95000000000010 | C16: =IF(EXACT(B16, ""), "", [1]DataLookUp!$C16) -> Finance Director | D16: 252000000000003 | E16: =IF(EXACT(D16, ""), "", VLOOKUP(D16, [2]DataLookUp!$B$4:$C$32, 2, FALSE)) -> Board Of Director | G16: =G15 + IF(EXACT(H16, ""), 0, 1) -> 253000000000010 | H16: =IF(AND(EXACT(B16, ""), EXACT(D16, "")), "", CONCATENATE("PERFORM ""SchSysConfig"".""Func_TblAppObject_UserRole_SET""(varSystemLoginSession, null::bigint, null::varchar, null::timestamptz, null::timestamptz, null::varchar, varInstitutionBranchID, varBaseCurrencyID, ", (IF(EXACT(B16, ""), "NULL", CONCATENATE("'", B16, "'"))),"::varchar);")) -> PERFORM "SchSysConfig"."Func_TblAppObject_UserRole_SET"(varSystemLoginSession, null::bigint, null::varchar, null::timestamptz, null::timestamptz, null::varchar, varInstitutionBranchID, varBaseCurrencyID, '95000000000010'::varchar); | J16: =IF(EXACT($H16, ""), "", CONCATENATE( "varSQL := varSQL || (CASE WHEN (varSQL = '') THEN '' ELSE ', ' END) || (SELECT JSON_BUILD_OBJECT (", "'recordID', NULL::bigint,", "'entities', ", "JSON_BUILD_OBJECT (", "'sysLoginSession_RefID', varSystemLoginSession::bigint,", "'sysDataAnnotation', NULL::varchar,", "'sysDataSetDateTimeTZ', NULL::timestamptz,", "'sysDataValidityStartDateTimeTZ', NULL::timestamptz,", "'sysDataValidityFinishDateTimeTZ', NULL::timestamptz,", "'sysPartitionRemovableRecordKey_RefID', NULL::bigint,", "'sysBranch_RefID', varInstitutionBranchID::bigint,", "'sysBaseCurrency_RefID',varBaseCurrencyID::bigint,", "'userRoleGroup_RefID', ", IF(EXACT($D16, ""), "null", CONCATENATE("'", SUBSTITUTE($D16, "'", "\'"), "'")), "::bigint, ", "'userRole_RefID', ", IF(EXACT($B16, ""), "null", CONCATENATE("'", SUBSTITUTE($B16, "'", "\'"), "'")), "::bigint", ")))::varchar;")) -> varSQL := varSQL || (CASE WHEN (varSQL = '') THEN '' ELSE ', ' END) || (SELECT JSON_BUILD_OBJECT ('recordID', NULL::bigint,'entities', JSON_BUILD_OBJECT ('sysLoginSession_RefID', varSystemLoginSession::bigint,'sysDataAnnotation', NULL::varchar,'sysDataSetDateTimeTZ', NULL::timestamptz,'sysDataValidityStartDateTimeTZ', NULL::timestamptz,'sysDataValidityFinishDateTimeTZ', NULL::timestamptz,'sysPartitionRemovableRecordKey_RefID', NULL::bigint,'sysBranch_RefID', varInstitutionBranchID::bigint,'sysBaseCurrency_RefID',varBaseCurrencyID::bigint,'userRoleGroup_RefID', '252000000000003'::bigint, 'userRole_RefID', '95000000000010'::bigint)))::varchar;
B17: =IF(EXACT([1]DataLookUp!$B17, ""), "", [1]DataLookUp!$B17) -> 95000000000011 | C17: =IF(EXACT(B17, ""), "", [1]DataLookUp!$C17) -> Operational Director | D17: 252000000000003 | E17: =IF(EXACT(D17, ""), "", VLOOKUP(D17, [2]DataLookUp!$B$4:$C$32, 2, FALSE)) -> Board Of Director | G17: =G16 + IF(EXACT(H17, ""), 0, 1) -> 253000000000011 | H17: =IF(AND(EXACT(B17, ""), EXACT(D17, "")), "", CONCATENATE("PERFORM ""SchSysConfig"".""Func_TblAppObject_UserRole_SET""(varSystemLoginSession, null::bigint, null::varchar, null::timestamptz, null::timestamptz, null::varchar, varInstitutionBranchID, varBaseCurrencyID, ", (IF(EXACT(B17, ""), "NULL", CONCATENATE("'", B17, "'"))),"::varchar);")) -> PERFORM "SchSysConfig"."Func_TblAppObject_UserRole_SET"(varSystemLoginSession, null::bigint, null::varchar, null::timestamptz, null::timestamptz, null::varchar, varInstitutionBranchID, varBaseCurrencyID, '95000000000011'::varchar); | J17: =IF(EXACT($H17, ""), "", CONCATENATE( "varSQL := varSQL || (CASE WHEN (varSQL = '') THEN '' ELSE ', ' END) || (SELECT JSON_BUILD_OBJECT (", "'recordID', NULL::bigint,", "'entities', ", "JSON_BUILD_OBJECT (", "'sysLoginSession_RefID', varSystemLoginSession::bigint,", "'sysDataAnnotation', NULL::varchar,", "'sysDataSetDateTimeTZ', NULL::timestamptz,", "'sysDataValidityStartDateTimeTZ', NULL::timestamptz,", "'sysDataValidityFinishDateTimeTZ', NULL::timestamptz,", "'sysPartitionRemovableRecordKey_RefID', NULL::bigint,", "'sysBranch_RefID', varInstitutionBranchID::bigint,", "'sysBaseCurrency_RefID',varBaseCurrencyID::bigint,", "'userRoleGroup_RefID', ", IF(EXACT($D17, ""), "null", CONCATENATE("'", SUBSTITUTE($D17, "'", "\'"), "'")), "::bigint, ", "'userRole_RefID', ", IF(EXACT($B17, ""), "null", CONCATENATE("'", SUBSTITUTE($B17, "'", "\'"), "'")), "::bigint", ")))::varchar;")) -> varSQL := varSQL || (CASE WHEN (varSQL = '') THEN '' ELSE ', ' END) || (SELECT JSON_BUILD_OBJECT ('recordID', NULL::bigint,'entities', JSON_BUILD_OBJECT ('sysLoginSession_RefID', varSystemLoginSession::bigint,'sysDataAnnotation', NULL::varchar,'sysDataSetDateTimeTZ', NULL::timestamptz,'sysDataValidityStartDateTimeTZ', NULL::timestamptz,'sysDataValidityFinishDateTimeTZ', NULL::timestamptz,'sysPartitionRemovableRecordKey_RefID', NULL::bigint,'sysBranch_RefID', varInstitutionBranchID::bigint,'sysBaseCurrency_RefID',varBaseCurrencyID::bigint,'userRoleGroup_RefID', '252000000000003'::bigint, 'userRole_RefID', '95000000000011'::bigint)))::varchar;
B18: =IF(EXACT([1]DataLookUp!$B18, ""), "", [1]DataLookUp!$B18) -> 95000000000012 | C18: =IF(EXACT(B18, ""), "", [1]DataLookUp!$C18) -> Marketing Director | D18: 252000000000003 | E18: =IF(EXACT(D18, ""), "", VLOOKUP(D18, [2]DataLookUp!$B$4:$C$32, 2, FALSE)) -> Board Of Director | G18: =G17 + IF(EXACT(H18, ""), 0, 1) -> 253000000000012 | H18: =IF(AND(EXACT(B18, ""), EXACT(D18, "")), "", CONCATENATE("PERFORM ""SchSysConfig"".""Func_TblAppObject_UserRole_SET""(varSystemLoginSession, null::bigint, null::varchar, null::timestamptz, null::timestamptz, null::varchar, varInstitutionBranchID, varBaseCurrencyID, ", (IF(EXACT(B18, ""), "NULL", CONCATENATE("'", B18, "'"))),"::varchar);")) -> PERFORM "SchSysConfig"."Func_TblAppObject_UserRole_SET"(varSystemLoginSession, null::bigint, null::varchar, null::timestamptz, null::timestamptz, null::varchar, varInstitutionBranchID, varBaseCurrencyID, '95000000000012'::varchar); | J18: =IF(EXACT($H18, ""), "", CONCATENATE( "varSQL := varSQL || (CASE WHEN (varSQL = '') THEN '' ELSE ', ' END) || (SELECT JSON_BUILD_OBJECT (", "'recordID', NULL::bigint,", "'entities', ", "JSON_BUILD_OBJECT (", "'sysLoginSession_RefID', varSystemLoginSession::bigint,", "'sysDataAnnotation', NULL::varchar,", "'sysDataSetDateTimeTZ', NULL::timestamptz,", "'sysDataValidityStartDateTimeTZ', NULL::timestamptz,", "'sysDataValidityFinishDateTimeTZ', NULL::timestamptz,", "'sysPartitionRemovableRecordKey_RefID', NULL::bigint,", "'sysBranch_RefID', varInstitutionBranchID::bigint,", "'sysBaseCurrency_RefID',varBaseCurrencyID::bigint,", "'userRoleGroup_RefID', ", IF(EXACT($D18, ""), "null", CONCATENATE("'", SUBSTITUTE($D18, "'", "\'"), "'")), "::bigint, ", "'userRole_RefID', ", IF(EXACT($B18, ""), "null", CONCATENATE("'", SUBSTITUTE($B18, "'", "\'"), "'")), "::bigint", ")))::varchar;")) -> varSQL := varSQL || (CASE WHEN (varSQL = '') THEN '' ELSE ', ' END) || (SELECT JSON_BUILD_OBJECT ('recordID', NULL::bigint,'entities', JSON_BUILD_OBJECT ('sysLoginSession_RefID', varSystemLoginSession::bigint,'sysDataAnnotation', NULL::varchar,'sysDataSetDateTimeTZ', NULL::timestamptz,'sysDataValidityStartDateTimeTZ', NULL::timestamptz,'sysDataValidityFinishDateTimeTZ', NULL::timestamptz,'sysPartitionRemovableRecordKey_RefID', NULL::bigint,'sysBranch_RefID', varInstitutionBranchID::bigint,'sysBaseCurrency_RefID',varBaseCurrencyID::bigint,'userRoleGroup_RefID', '252000000000003'::bigint, 'userRole_RefID', '95000000000012'::bigint)))::varchar;
B19: =IF(EXACT([1]DataLookUp!$B19, ""), "", [1]DataLookUp!$B19) -> 95000000000013 | C19: =IF(EXACT(B19, ""), "", [1]DataLookUp!$C19) -> Information Technology Director | D19: 252000000000003 | E19: =IF(EXACT(D19, ""), "", VLOOKUP(D19, [2]DataLookUp!$B$4:$C$32, 2, FALSE)) -> Board Of Director | G19: =G18 + IF(EXACT(H19, ""), 0, 1) -> 253000000000013 | H19: =IF(AND(EXACT(B19, ""), EXACT(D19, "")), "", CONCATENATE("PERFORM ""SchSysConfig"".""Func_TblAppObject_UserRole_SET""(varSystemLoginSession, null::bigint, null::varchar, null::timestamptz, null::timestamptz, null::varchar, varInstitutionBranchID, varBaseCurrencyID, ", (IF(EXACT(B19, ""), "NULL", CONCATENATE("'", B19, "'"))),"::varchar);")) -> PERFORM "SchSysConfig"."Func_TblAppObject_UserRole_SET"(varSystemLoginSession, null::bigint, null::varchar, null::timestamptz, null::timestamptz, null::varchar, varInstitutionBranchID, varBaseCurrencyID, '95000000000013'::varchar); | J19: =IF(EXACT($H19, ""), "", CONCATENATE( "varSQL := varSQL || (CASE WHEN (varSQL = '') THEN '' ELSE ', ' END) || (SELECT JSON_BUILD_OBJECT (", "'recordID', NULL::bigint,", "'entities', ", "JSON_BUILD_OBJECT (", "'sysLoginSession_RefID', varSystemLoginSession::bigint,", "'sysDataAnnotation', NULL::varchar,", "'sysDataSetDateTimeTZ', NULL::timestamptz,", "'sysDataValidityStartDateTimeTZ', NULL::timestamptz,", "'sysDataValidityFinishDateTimeTZ', NULL::timestamptz,", "'sysPartitionRemovableRecordKey_RefID', NULL::bigint,", "'sysBranch_RefID', varInstitutionBranchID::bigint,", "'sysBaseCurrency_RefID',varBaseCurrencyID::bigint,", "'userRoleGroup_RefID', ", IF(EXACT($D19, ""), "null", CONCATENATE("'", SUBSTITUTE($D19, "'", "\'"), "'")), "::bigint, ", "'userRole_RefID', ", IF(EXACT($B19, ""), "null", CONCATENATE("'", SUBSTITUTE($B19, "'", "\'"), "'")), "::bigint", ")))::varchar;")) -> varSQL := varSQL || (CASE WHEN (varSQL = '') THEN '' ELSE ', ' END) || (SELECT JSON_BUILD_OBJECT ('recordID', NULL::bigint,'entities', JSON_BUILD_OBJECT ('sysLoginSession_RefID', varSystemLoginSession::bigint,'sysDataAnnotation', NULL::varchar,'sysDataSetDateTimeTZ', NULL::timestamptz,'sysDataValidityStartDateTimeTZ', NULL::timestamptz,'sysDataValidityFinishDateTimeTZ', NULL::timestamptz,'sysPartitionRemovableRecordKey_RefID', NULL::bigint,'sysBranch_RefID', varInstitutionBranchID::bigint,'sysBaseCurrency_RefID',varBaseCurrencyID::bigint,'userRoleGroup_RefID', '252000000000003'::bigint, 'userRole_RefID', '95000000000013'::bigint)))::varchar;
B20: =IF(EXACT([1]DataLookUp!$B20, ""), "", [1]DataLookUp!$B20) | C20: =IF(EXACT(B20, ""), "", [1]DataLookUp!$C20) | E20: =IF(EXACT(D20, ""), "", VLOOKUP(D20, [2]DataLookUp!$B$4:$C$32, 2, FALSE)) | G20: =G19 + IF(EXACT(H20, ""), 0, 1) -> 253000000000013 | H20: =IF(AND(EXACT(B20, ""), EXACT(D20, "")), "", CONCATENATE("PERFORM ""SchSysConfig"".""Func_TblAppObject_UserRole_SET""(varSystemLoginSession, null::bigint, null::varchar, null::timestamptz, null::timestamptz, null::varchar, varInstitutionBranchID, varBaseCurrencyID, ", (IF(EXACT(B20, ""), "NULL", CONCATENATE("'", B20, "'"))),"::varchar);")) | J20: =IF(EXACT($H20, ""), "", CONCATENATE( "varSQL := varSQL || (CASE WHEN (varSQL = '') THEN '' ELSE ', ' END) || (SELECT JSON_BUILD_OBJECT (", "'recordID', NULL::bigint,", "'entities', ", "JSON_BUILD_OBJECT (", "'sysLoginSession_RefID', varSystemLoginSession::bigint,", "'sysDataAnnotation', NULL::varchar,", "'sysDataSetDateTimeTZ', NULL::timestamptz,", "'sysDataValidityStartDateTimeTZ', NULL::timestamptz,", "'sysDataValidityFinishDateTimeTZ', NULL::timestamptz,", "'sysPartitionRemovableRecordKey_RefID', NULL::bigint,", "'sysBranch_RefID', varInstitutionBranchID::bigint,", "'sysBaseCurrency_RefID',varBaseCurrencyID::bigint,", "'userRoleGroup_RefID', ", IF(EXACT($D20, ""), "null", CONCATENATE("'", SUBSTITUTE($D20, "'", "\'"), "'")), "::bigint, ", "'userRole_RefID', ", IF(EXACT($B20, ""), "null", CONCATENATE("'", SUBSTITUTE($B20, "'", "\'"), "'")), "::bigint", ")))::varchar;"))
B21: =IF(EXACT([1]DataLookUp!$B21, ""), "", [1]DataLookUp!$B21) -> 95000000000014 | C21: =IF(EXACT(B21, ""), "", [1]DataLookUp!$C21) -> Project General Manager | D21: 252000000000005 | E21: =IF(EXACT(D21, ""), "", VLOOKUP(D21, [2]DataLookUp!$B$4:$C$32, 2, FALSE)) -> Top Level Management | G21: =G20 + IF(EXACT(H21, ""), 0, 1) -> 253000000000014 | H21: =IF(AND(EXACT(B21, ""), EXACT(D21, "")), "", CONCATENATE("PERFORM ""SchSysConfig"".""Func_TblAppObject_UserRole_SET""(varSystemLoginSession, null::bigint, null::varchar, null::timestamptz, null::timestamptz, null::varchar, varInstitutionBranchID, varBaseCurrencyID, ", (IF(EXACT(B21, ""), "NULL", CONCATENATE("'", B21, "'"))),"::varchar);")) -> PERFORM "SchSysConfig"."Func_TblAppObject_UserRole_SET"(varSystemLoginSession, null::bigint, null::varchar, null::timestamptz, null::timestamptz, null::varchar, varInstitutionBranchID, varBaseCurrencyID, '95000000000014'::varchar); | J21: =IF(EXACT($H21, ""), "", CONCATENATE( "varSQL := varSQL || (CASE WHEN (varSQL = '') THEN '' ELSE ', ' END) || (SELECT JSON_BUILD_OBJECT (", "'recordID', NULL::bigint,", "'entities', ", "JSON_BUILD_OBJECT (", "'sysLoginSession_RefID', varSystemLoginSession::bigint,", "'sysDataAnnotation', NULL::varchar,", "'sysDataSetDateTimeTZ', NULL::timestamptz,", "'sysDataValidityStartDateTimeTZ', NULL::timestamptz,", "'sysDataValidityFinishDateTimeTZ', NULL::timestamptz,", "'sysPartitionRemovableRecordKey_RefID', NULL::bigint,", "'sysBranch_RefID', varInstitutionBranchID::bigint,", "'sysBaseCurrency_RefID',varBaseCurrencyID::bigint,", "'userRoleGroup_RefID', ", IF(EXACT($D21, ""), "null", CONCATENATE("'", SUBSTITUTE($D21, "'", "\'"), "'")), "::bigint, ", "'userRole_RefID', ", IF(EXACT($B21, ""), "null", CONCATENATE("'", SUBSTITUTE($B21, "'", "\'"), "'")), "::bigint", ")))::varchar;")) -> varSQL := varSQL || (CASE WHEN (varSQL = '') THEN '' ELSE ', ' END) || (SELECT JSON_BUILD_OBJECT ('recordID', NULL::bigint,'entities', JSON_BUILD_OBJECT ('sysLoginSession_RefID', varSystemLoginSession::bigint,'sysDataAnnotation', NULL::varchar,'sysDataSetDateTimeTZ', NULL::timestamptz,'sysDataValidityStartDateTimeTZ', NULL::timestamptz,'sysDataValidityFinishDateTimeTZ', NULL::timestamptz,'sysPartitionRemovableRecordKey_RefID', NULL::bigint,'sysBranch_RefID', varInstitutionBranchID::bigint,'sysBaseCurrency_RefID',varBaseCurrencyID::bigint,'userRoleGroup_RefID', '252000000000005'::bigint, 'userRole_RefID', '95000000000014'::bigint)))::varchar;
B22: =IF(EXACT([1]DataLookUp!$B22, ""), "", [1]DataLookUp!$B22) -> 95000000000015 | C22: =IF(EXACT(B22, ""), "", [1]DataLookUp!$C22) -> Project Management Officer | D22: 252000000000005 | E22: =IF(EXACT(D22, ""), "", VLOOKUP(D22, [2]DataLookUp!$B$4:$C$32, 2, FALSE)) -> Top Level Management | G22: =G21 + IF(EXACT(H22, ""), 0, 1) -> 253000000000015 | H22: =IF(AND(EXACT(B22, ""), EXACT(D22, "")), "", CONCATENATE("PERFORM ""SchSysConfig"".""Func_TblAppObject_UserRole_SET""(varSystemLoginSession, null::bigint, null::varchar, null::timestamptz, null::timestamptz, null::varchar, varInstitutionBranchID, varBaseCurrencyID, ", (IF(EXACT(B22, ""), "NULL", CONCATENATE("'", B22, "'"))),"::varchar);")) -> PERFORM "SchSysConfig"."Func_TblAppObject_UserRole_SET"(varSystemLoginSession, null::bigint, null::varchar, null::timestamptz, null::timestamptz, null::varchar, varInstitutionBranchID, varBaseCurrencyID, '95000000000015'::varchar); | J22: =IF(EXACT($H22, ""), "", CONCATENATE( "varSQL := varSQL || (CASE WHEN (varSQL = '') THEN '' ELSE ', ' END) || (SELECT JSON_BUILD_OBJECT (", "'recordID', NULL::bigint,", "'entities', ", "JSON_BUILD_OBJECT (", "'sysLoginSession_RefID', varSystemLoginSession::bigint,", "'sysDataAnnotation', NULL::varchar,", "'sysDataSetDateTimeTZ', NULL::timestamptz,", "'sysDataValidityStartDateTimeTZ', NULL::timestamptz,", "'sysDataValidityFinishDateTimeTZ', NULL::timestamptz,", "'sysPartitionRemovableRecordKey_RefID', NULL::bigint,", "'sysBranch_RefID', varInstitutionBranchID::bigint,", "'sysBaseCurrency_RefID',varBaseCurrencyID::bigint,", "'userRoleGroup_RefID', ", IF(EXACT($D22, ""), "null", CONCATENATE("'", SUBSTITUTE($D22, "'", "\'"), "'")), "::bigint, ", "'userRole_RefID', ", IF(EXACT($B22, ""), "null", CONCATENATE("'", SUBSTITUTE($B22, "'", "\'"), "'")), "::bigint", ")))::varchar;")) -> varSQL := varSQL || (CASE WHEN (varSQL = '') THEN '' ELSE ', ' END) || (SELECT JSON_BUILD_OBJECT ('recordID', NULL::bigint,'entities', JSON_BUILD_OBJECT ('sysLoginSession_RefID', varSystemLoginSession::bigint,'sysDataAnnotation', NULL::varchar,'sysDataSetDateTimeTZ', NULL::timestamptz,'sysDataValidityStartDateTimeTZ', NULL::timestamptz,'sysDataValidityFinishDateTimeTZ', NULL::timestamptz,'sysPartitionRemovableRecordKey_RefID', NULL::bigint,'sysBranch_RefID', varInstitutionBranchID::bigint,'sysBaseCurrency_RefID',varBaseCurrencyID::bigint,'userRoleGroup_RefID', '252000000000005'::bigint, 'userRole_RefID', '95000000000015'::bigint)))::varchar;
B23: =IF(EXACT([1]DataLookUp!$B23, ""), "", [1]DataLookUp!$B23) -> 95000000000016 | C23: =IF(EXACT(B23, ""), "", [1]DataLookUp!$C23) -> Finance, Accounting, & Tax General Manager | D23: 252000000000005 | E23: =IF(EXACT(D23, ""), "", VLOOKUP(D23, [2]DataLookUp!$B$4:$C$32, 2, FALSE)) -> Top Level Management | G23: =G22 + IF(EXACT(H23, ""), 0, 1) -> 253000000000016 | H23: =IF(AND(EXACT(B23, ""), EXACT(D23, "")), "", CONCATENATE("PERFORM ""SchSysConfig"".""Func_TblAppObject_UserRole_SET""(varSystemLoginSession, null::bigint, null::varchar, null::timestamptz, null::timestamptz, null::varchar, varInstitutionBranchID, varBaseCurrencyID, ", (IF(EXACT(B23, ""), "NULL", CONCATENATE("'", B23, "'"))),"::varchar);")) -> PERFORM "SchSysConfig"."Func_TblAppObject_UserRole_SET"(varSystemLoginSession, null::bigint, null::varchar, null::timestamptz, null::timestamptz, null::varchar, varInstitutionBranchID, varBaseCurrencyID, '95000000000016'::varchar); | J23: =IF(EXACT($H23, ""), "", CONCATENATE( "varSQL := varSQL || (CASE WHEN (varSQL = '') THEN '' ELSE ', ' END) || (SELECT JSON_BUILD_OBJECT (", "'recordID', NULL::bigint,", "'entities', ", "JSON_BUILD_OBJECT (", "'sysLoginSession_RefID', varSystemLoginSession::bigint,", "'sysDataAnnotation', NULL::varchar,", "'sysDataSetDateTimeTZ', NULL::timestamptz,", "'sysDataValidityStartDateTimeTZ', NULL::timestamptz,", "'sysDataValidityFinishDateTimeTZ', NULL::timestamptz,", "'sysPartitionRemovableRecordKey_RefID', NULL::bigint,", "'sysBranch_RefID', varInstitutionBranchID::bigint,", "'sysBaseCurrency_RefID',varBaseCurrencyID::bigint,", "'userRoleGroup_RefID', ", IF(EXACT($D23, ""), "null", CONCATENATE("'", SUBSTITUTE($D23, "'", "\'"), "'")), "::bigint, ", "'userRole_RefID', ", IF(EXACT($B23, ""), "null", CONCATENATE("'", SUBSTITUTE($B23, "'", "\'"), "'")), "::bigint", ")))::varchar;")) -> varSQL := varSQL || (CASE WHEN (varSQL = '') THEN '' ELSE ', ' END) || (SELECT JSON_BUILD_OBJECT ('recordID', NULL::bigint,'entities', JSON_BUILD_OBJECT ('sysLoginSession_RefID', varSystemLoginSession::bigint,'sysDataAnnotation', NULL::varchar,'sysDataSetDateTimeTZ', NULL::timestamptz,'sysDataValidityStartDateTimeTZ', NULL::timestamptz,'sysDataValidityFinishDateTimeTZ', NULL::timestamptz,'sysPartitionRemovableRecordKey_RefID', NULL::bigint,'sysBranch_RefID', varInstitutionBranchID::bigint,'sysBaseCurrency_RefID',varBaseCurrencyID::bigint,'userRoleGroup_RefID', '252000000000005'::bigint, 'userRole_RefID', '95000000000016'::bigint)))::varchar;
B24: =IF(EXACT([1]DataLookUp!$B24, ""), "", [1]DataLookUp!$B24) -> 95000000000017 | C24: =IF(EXACT(B24, ""), "", [1]DataLookUp!$C24) -> HR, GA, & TAM General Manager | D24: 252000000000005 | E24: =IF(EXACT(D24, ""), "", VLOOKUP(D24, [2]DataLookUp!$B$4:$C$32, 2, FALSE)) -> Top Level Management | G24: =G23 + IF(EXACT(H24, ""), 0, 1) -> 253000000000017 | H24: =IF(AND(EXACT(B24, ""), EXACT(D24, "")), "", CONCATENATE("PERFORM ""SchSysConfig"".""Func_TblAppObject_UserRole_SET""(varSystemLoginSession, null::bigint, null::varchar, null::timestamptz, null::timestamptz, null::varchar, varInstitutionBranchID, varBaseCurrencyID, ", (IF(EXACT(B24, ""), "NULL", CONCATENATE("'", B24, "'"))),"::varchar);")) -> PERFORM "SchSysConfig"."Func_TblAppObject_UserRole_SET"(varSystemLoginSession, null::bigint, null::varchar, null::timestamptz, null::timestamptz, null::varchar, varInstitutionBranchID, varBaseCurrencyID, '95000000000017'::varchar); | J24: =IF(EXACT($H24, ""), "", CONCATENATE( "varSQL := varSQL || (CASE WHEN (varSQL = '') THEN '' ELSE ', ' END) || (SELECT JSON_BUILD_OBJECT (", "'recordID', NULL::bigint,", "'entities', ", "JSON_BUILD_OBJECT (", "'sysLoginSession_RefID', varSystemLoginSession::bigint,", "'sysDataAnnotation', NULL::varchar,", "'sysDataSetDateTimeTZ', NULL::timestamptz,", "'sysDataValidityStartDateTimeTZ', NULL::timestamptz,", "'sysDataValidityFinishDateTimeTZ', NULL::timestamptz,", "'sysPartitionRemovableRecordKey_RefID', NULL::bigint,", "'sysBranch_RefID', varInstitutionBranchID::bigint,", "'sysBaseCurrency_RefID',varBaseCurrencyID::bigint,", "'userRoleGroup_RefID', ", IF(EXACT($D24, ""), "null", CONCATENATE("'", SUBSTITUTE($D24, "'", "\'"), "'")), "::bigint, ", "'userRole_RefID', ", IF(EXACT($B24, ""), "null", CONCATENATE("'", SUBSTITUTE($B24, "'", "\'"), "'")), "::bigint", ")))::varchar;")) -> varSQL := varSQL || (CASE WHEN (varSQL = '') THEN '' ELSE ', ' END) || (SELECT JSON_BUILD_OBJECT ('recordID', NULL::bigint,'entities', JSON_BUILD_OBJECT ('sysLoginSession_RefID', varSystemLoginSession::bigint,'sysDataAnnotation', NULL::varchar,'sysDataSetDateTimeTZ', NULL::timestamptz,'sysDataValidityStartDateTimeTZ', NULL::timestamptz,'sysDataValidityFinishDateTimeTZ', NULL::timestamptz,'sysPartitionRemovableRecordKey_RefID', NULL::bigint,'sysBranch_RefID', varInstitutionBranchID::bigint,'sysBaseCurrency_RefID',varBaseCurrencyID::bigint,'userRoleGroup_RefID', '252000000000005'::bigint, 'userRole_RefID', '95000000000017'::bigint)))::varchar;
B25: =IF(EXACT([1]DataLookUp!$B25, ""), "", [1]DataLookUp!$B25) -> 95000000000018 | C25: =IF(EXACT(B25, ""), "", [1]DataLookUp!$C25) -> Sales General Manager | D25: 252000000000005 | E25: =IF(EXACT(D25, ""), "", VLOOKUP(D25, [2]DataLookUp!$B$4:$C$32, 2, FALSE)) -> Top Level Management | G25: =G24 + IF(EXACT(H25, ""), 0, 1) -> 253000000000018 | H25: =IF(AND(EXACT(B25, ""), EXACT(D25, "")), "", CONCATENATE("PERFORM ""SchSysConfig"".""Func_TblAppObject_UserRole_SET""(varSystemLoginSession, null::bigint, null::varchar, null::timestamptz, null::timestamptz, null::varchar, varInstitutionBranchID, varBaseCurrencyID, ", (IF(EXACT(B25, ""), "NULL", CONCATENATE("'", B25, "'"))),"::varchar);")) -> PERFORM "SchSysConfig"."Func_TblAppObject_UserRole_SET"(varSystemLoginSession, null::bigint, null::varchar, null::timestamptz, null::timestamptz, null::varchar, varInstitutionBranchID, varBaseCurrencyID, '95000000000018'::varchar); | J25: =IF(EXACT($H25, ""), "", CONCATENATE( "varSQL := varSQL || (CASE WHEN (varSQL = '') THEN '' ELSE ', ' END) || (SELECT JSON_BUILD_OBJECT (", "'recordID', NULL::bigint,", "'entities', ", "JSON_BUILD_OBJECT (", "'sysLoginSession_RefID', varSystemLoginSession::bigint,", "'sysDataAnnotation', NULL::varchar,", "'sysDataSetDateTimeTZ', NULL::timestamptz,", "'sysDataValidityStartDateTimeTZ', NULL::timestamptz,", "'sysDataValidityFinishDateTimeTZ', NULL::timestamptz,", "'sysPartitionRemovableRecordKey_RefID', NULL::bigint,", "'sysBranch_RefID', varInstitutionBranchID::bigint,", "'sysBaseCurrency_RefID',varBaseCurrencyID::bigint,", "'userRoleGroup_RefID', ", IF(EXACT($D25, ""), "null", CONCATENATE("'", SUBSTITUTE($D25, "'", "\'"), "'")), "::bigint, ", "'userRole_RefID', ", IF(EXACT($B25, ""), "null", CONCATENATE("'", SUBSTITUTE($B25, "'", "\'"), "'")), "::bigint", ")))::varchar;")) -> varSQL := varSQL || (CASE WHEN (varSQL = '') THEN '' ELSE ', ' END) || (SELECT JSON_BUILD_OBJECT ('recordID', NULL::bigint,'entities', JSON_BUILD_OBJECT ('sysLoginSession_RefID', varSystemLoginSession::bigint,'sysDataAnnotation', NULL::varchar,'sysDataSetDateTimeTZ', NULL::timestamptz,'sysDataValidityStartDateTimeTZ', NULL::timestamptz,'sysDataValidityFinishDateTimeTZ', NULL::timestamptz,'sysPartitionRemovableRecordKey_RefID', NULL::bigint,'sysBranch_RefID', varInstitutionBranchID::bigint,'sysBaseCurrency_RefID',varBaseCurrencyID::bigint,'userRoleGroup_RefID', '252000000000005'::bigint, 'userRole_RefID', '95000000000018'::bigint)))::varchar;
B26: =IF(EXACT([1]DataLookUp!$B26, ""), "", [1]DataLookUp!$B26) | C26: =IF(EXACT(B26, ""), "", [1]DataLookUp!$C26) | E26: =IF(EXACT(D26, ""), "", VLOOKUP(D26, [2]DataLookUp!$B$4:$C$32, 2, FALSE)) | G26: =G25 + IF(EXACT(H26, ""), 0, 1) -> 253000000000018 | H26: =IF(AND(EXACT(B26, ""), EXACT(D26, "")), "", CONCATENATE("PERFORM ""SchSysConfig"".""Func_TblAppObject_UserRole_SET""(varSystemLoginSession, null::bigint, null::varchar, null::timestamptz, null::timestamptz, null::varchar, varInstitutionBranchID, varBaseCurrencyID, ", (IF(EXACT(B26, ""), "NULL", CONCATENATE("'", B26, "'"))),"::varchar);")) | J26: =IF(EXACT($H26, ""), "", CONCATENATE( "varSQL := varSQL || (CASE WHEN (varSQL = '') THEN '' ELSE ', ' END) || (SELECT JSON_BUILD_OBJECT (", "'recordID', NULL::bigint,", "'entities', ", "JSON_BUILD_OBJECT (", "'sysLoginSession_RefID', varSystemLoginSession::bigint,", "'sysDataAnnotation', NULL::varchar,", "'sysDataSetDateTimeTZ', NULL::timestamptz,", "'sysDataValidityStartDateTimeTZ', NULL::timestamptz,", "'sysDataValidityFinishDateTimeTZ', NULL::timestamptz,", "'sysPartitionRemovableRecordKey_RefID', NULL::bigint,", "'sysBranch_RefID', varInstitutionBranchID::bigint,", "'sysBaseCurrency_RefID',varBaseCurrencyID::bigint,", "'userRoleGroup_RefID', ", IF(EXACT($D26, ""), "null", CONCATENATE("'", SUBSTITUTE($D26, "'", "\'"), "'")), "::bigint, ", "'userRole_RefID', ", IF(EXACT($B26, ""), "null", CONCATENATE("'", SUBSTITUTE($B26, "'", "\'"), "'")), "::bigint", ")))::varchar;"))
B27: =IF(EXACT([1]DataLookUp!$B27, ""), "", [1]DataLookUp!$B27) -> 95000000000019 | C27: =IF(EXACT(B27, ""), "", [1]DataLookUp!$C27) -> Project Manager | D27: 252000000000015 | E27: =IF(EXACT(D27, ""), "", VLOOKUP(D27, [2]DataLookUp!$B$4:$C$32, 2, FALSE)) -> Department - Project | G27: =G26 + IF(EXACT(H27, ""), 0, 1) -> 253000000000019 | H27: =IF(AND(EXACT(B27, ""), EXACT(D27, "")), "", CONCATENATE("PERFORM ""SchSysConfig"".""Func_TblAppObject_UserRole_SET""(varSystemLoginSession, null::bigint, null::varchar, null::timestamptz, null::timestamptz, null::varchar, varInstitutionBranchID, varBaseCurrencyID, ", (IF(EXACT(B27, ""), "NULL", CONCATENATE("'", B27, "'"))),"::varchar);")) -> PERFORM "SchSysConfig"."Func_TblAppObject_UserRole_SET"(varSystemLoginSession, null::bigint, null::varchar, null::timestamptz, null::timestamptz, null::varchar, varInstitutionBranchID, varBaseCurrencyID, '95000000000019'::varchar); | J27: =IF(EXACT($H27, ""), "", CONCATENATE( "varSQL := varSQL || (CASE WHEN (varSQL = '') THEN '' ELSE ', ' END) || (SELECT JSON_BUILD_OBJECT (", "'recordID', NULL::bigint,", "'entities', ", "JSON_BUILD_OBJECT (", "'sysLoginSession_RefID', varSystemLoginSession::bigint,", "'sysDataAnnotation', NULL::varchar,", "'sysDataSetDateTimeTZ', NULL::timestamptz,", "'sysDataValidityStartDateTimeTZ', NULL::timestamptz,", "'sysDataValidityFinishDateTimeTZ', NULL::timestamptz,", "'sysPartitionRemovableRecordKey_RefID', NULL::bigint,", "'sysBranch_RefID', varInstitutionBranchID::bigint,", "'sysBaseCurrency_RefID',varBaseCurrencyID::bigint,", "'userRoleGroup_RefID', ", IF(EXACT($D27, ""), "null", CONCATENATE("'", SUBSTITUTE($D27, "'", "\'"), "'")), "::bigint, ", "'userRole_RefID', ", IF(EXACT($B27, ""), "null", CONCATENATE("'", SUBSTITUTE($B27, "'", "\'"), "'")), "::bigint", ")))::varchar;")) -> varSQL := varSQL || (CASE WHEN (varSQL = '') THEN '' ELSE ', ' END) || (SELECT JSON_BUILD_OBJECT ('recordID', NULL::bigint,'entities', JSON_BUILD_OBJECT ('sysLoginSession_RefID', varSystemLoginSession::bigint,'sysDataAnnotation', NULL::varchar,'sysDataSetDateTimeTZ', NULL::timestamptz,'sysDataValidityStartDateTimeTZ', NULL::timestamptz,'sysDataValidityFinishDateTimeTZ', NULL::timestamptz,'sysPartitionRemovableRecordKey_RefID', NULL::bigint,'sysBranch_RefID', varInstitutionBranchID::bigint,'sysBaseCurrency_RefID',varBaseCurrencyID::bigint,'userRoleGroup_RefID', '252000000000015'::bigint, 'userRole_RefID', '95000000000019'::bigint)))::varchar;
B28: =IF(EXACT([1]DataLookUp!$B28, ""), "", [1]DataLookUp!$B28) -> 95000000000020 | C28: =IF(EXACT(B28, ""), "", [1]DataLookUp!$C28) -> Site Manager | D28: 252000000000015 | E28: =IF(EXACT(D28, ""), "", VLOOKUP(D28, [2]DataLookUp!$B$4:$C$32, 2, FALSE)) -> Department - Project | G28: =G27 + IF(EXACT(H28, ""), 0, 1) -> 253000000000020 | H28: =IF(AND(EXACT(B28, ""), EXACT(D28, "")), "", CONCATENATE("PERFORM ""SchSysConfig"".""Func_TblAppObject_UserRole_SET""(varSystemLoginSession, null::bigint, null::varchar, null::timestamptz, null::timestamptz, null::varchar, varInstitutionBranchID, varBaseCurrencyID, ", (IF(EXACT(B28, ""), "NULL", CONCATENATE("'", B28, "'"))),"::varchar);")) -> PERFORM "SchSysConfig"."Func_TblAppObject_UserRole_SET"(varSystemLoginSession, null::bigint, null::varchar, null::timestamptz, null::timestamptz, null::varchar, varInstitutionBranchID, varBaseCurrencyID, '95000000000020'::varchar); | J28: =IF(EXACT($H28, ""), "", CONCATENATE( "varSQL := varSQL || (CASE WHEN (varSQL = '') THEN '' ELSE ', ' END) || (SELECT JSON_BUILD_OBJECT (", "'recordID', NULL::bigint,", "'entities', ", "JSON_BUILD_OBJECT (", "'sysLoginSession_RefID', varSystemLoginSession::bigint,", "'sysDataAnnotation', NULL::varchar,", "'sysDataSetDateTimeTZ', NULL::timestamptz,", "'sysDataValidityStartDateTimeTZ', NULL::timestamptz,", "'sysDataValidityFinishDateTimeTZ', NULL::timestamptz,", "'sysPartitionRemovableRecordKey_RefID', NULL::bigint,", "'sysBranch_RefID', varInstitutionBranchID::bigint,", "'sysBaseCurrency_RefID',varBaseCurrencyID::bigint,", "'userRoleGroup_RefID', ", IF(EXACT($D28, ""), "null", CONCATENATE("'", SUBSTITUTE($D28, "'", "\'"), "'")), "::bigint, ", "'userRole_RefID', ", IF(EXACT($B28, ""), "null", CONCATENATE("'", SUBSTITUTE($B28, "'", "\'"), "'")), "::bigint", ")))::varchar;")) -> varSQL := varSQL || (CASE WHEN (varSQL = '') THEN '' ELSE ', ' END) || (SELECT JSON_BUILD_OBJECT ('recordID', NULL::bigint,'entities', JSON_BUILD_OBJECT ('sysLoginSession_RefID', varSystemLoginSession::bigint,'sysDataAnnotation', NULL::varchar,'sysDataSetDateTimeTZ', NULL::timestamptz,'sysDataValidityStartDateTimeTZ', NULL::timestamptz,'sysDataValidityFinishDateTimeTZ', NULL::timestamptz,'sysPartitionRemovableRecordKey_RefID', NULL::bigint,'sysBranch_RefID', varInstitutionBranchID::bigint,'sysBaseCurrency_RefID',varBaseCurrencyID::bigint,'userRoleGroup_RefID', '252000000000015'::bigint, 'userRole_RefID', '95000000000020'::bigint)))::varchar;
B29: =IF(EXACT([1]DataLookUp!$B29, ""), "", [1]DataLookUp!$B29) -> 95000000000021 | C29: =IF(EXACT(B29, ""), "", [1]DataLookUp!$C29) -> Project Controller Coordinator | D29: 252000000000015 | E29: =IF(EXACT(D29, ""), "", VLOOKUP(D29, [2]DataLookUp!$B$4:$C$32, 2, FALSE)) -> Department - Project | G29: =G28 + IF(EXACT(H29, ""), 0, 1) -> 253000000000021 | H29: =IF(AND(EXACT(B29, ""), EXACT(D29, "")), "", CONCATENATE("PERFORM ""SchSysConfig"".""Func_TblAppObject_UserRole_SET""(varSystemLoginSession, null::bigint, null::varchar, null::timestamptz, null::timestamptz, null::varchar, varInstitutionBranchID, varBaseCurrencyID, ", (IF(EXACT(B29, ""), "NULL", CONCATENATE("'", B29, "'"))),"::varchar);")) -> PERFORM "SchSysConfig"."Func_TblAppObject_UserRole_SET"(varSystemLoginSession, null::bigint, null::varchar, null::timestamptz, null::timestamptz, null::varchar, varInstitutionBranchID, varBaseCurrencyID, '95000000000021'::varchar); | J29: =IF(EXACT($H29, ""), "", CONCATENATE( "varSQL := varSQL || (CASE WHEN (varSQL = '') THEN '' ELSE ', ' END) || (SELECT JSON_BUILD_OBJECT (", "'recordID', NULL::bigint,", "'entities', ", "JSON_BUILD_OBJECT (", "'sysLoginSession_RefID', varSystemLoginSession::bigint,", "'sysDataAnnotation', NULL::varchar,", "'sysDataSetDateTimeTZ', NULL::timestamptz,", "'sysDataValidityStartDateTimeTZ', NULL::timestamptz,", "'sysDataValidityFinishDateTimeTZ', NULL::timestamptz,", "'sysPartitionRemovableRecordKey_RefID', NULL::bigint,", "'sysBranch_RefID', varInstitutionBranchID::bigint,", "'sysBaseCurrency_RefID',varBaseCurrencyID::bigint,", "'userRoleGroup_RefID', ", IF(EXACT($D29, ""), "null", CONCATENATE("'", SUBSTITUTE($D29, "'", "\'"), "'")), "::bigint, ", "'userRole_RefID', ", IF(EXACT($B29, ""), "null", CONCATENATE("'", SUBSTITUTE($B29, "'", "\'"), "'")), "::bigint", ")))::varchar;")) -> varSQL := varSQL || (CASE WHEN (varSQL = '') THEN '' ELSE ', ' END) || (SELECT JSON_BUILD_OBJECT ('recordID', NULL::bigint,'entities', JSON_BUILD_OBJECT ('sysLoginSession_RefID', varSystemLoginSession::bigint,'sysDataAnnotation', NULL::varchar,'sysDataSetDateTimeTZ', NULL::timestamptz,'sysDataValidityStartDateTimeTZ', NULL::timestamptz,'sysDataValidityFinishDateTimeTZ', NULL::timestamptz,'sysPartitionRemovableRecordKey_RefID', NULL::bigint,'sysBranch_RefID', varInstitutionBranchID::bigint,'sysBaseCurrency_RefID',varBaseCurrencyID::bigint,'userRoleGroup_RefID', '252000000000015'::bigint, 'userRole_RefID', '95000000000021'::bigint)))::varchar;
