Workbook

Sheet MAIN
B2: User Role Name | D2: SYS_PID Prediction | E2: SQL Syntax
D3: 95000000000000
B4: Super User | D4: =D3 + IF(EXACT(E4, ""), 0, 1) -> 95000000000001 | E4: =IF(EXACT(B4, ""), "", CONCATENATE("PERFORM ""SchSysConfig"".""Func_TblAppObject_UserRole_SET""(varSystemLoginSession, null::bigint, null::varchar, null::timestamptz, null::timestamptz, null::varchar, varInstitutionBranchID, varBaseCurrencyID, ", (IF(EXACT(B4, ""), "NULL", CONCATENATE("'", B4, "'"))),"::varchar);")) -> PERFORM "SchSysConfig"."Func_TblAppObject_UserRole_SET"(varSystemLoginSession, null::bigint, null::varchar, null::timestamptz, null::timestamptz, null::varchar, varInstitutionBranchID, varBaseCurrencyID, 'Super User'::varchar); | G4: =IF(EXACT($E4, ""), "", CONCATENATE( "varSQL := varSQL || (CASE WHEN (varSQL = '') THEN '' ELSE ', ' END) || (SELECT JSON_BUILD_OBJECT (", "'recordID', NULL::bigint,", "'entities', ", "JSON_BUILD_OBJECT (", "'sysLoginSession_RefID', varSystemLoginSession::bigint,", "'sysDataAnnotation', NULL::varchar,", "'sysDataSetDateTimeTZ', NULL::timestamptz,", "'sysDataValidityStartDateTimeTZ', NULL::timestamptz,", "'sysDataValidityFinishDateTimeTZ', NULL::timestamptz,", "'sysPartitionRemovableRecordKey_RefID', NULL::bigint,", "'sysBranch_RefID', varInstitutionBranchID::bigint,", "'sysBaseCurrency_RefID',varBaseCurrencyID::bigint,", "'name', ", IF(EXACT($B4, ""), "null", CONCATENATE("'", SUBSTITUTE($B4, "'", "\'"), "'")), "::varchar", ")))::varchar;")) -> varSQL := varSQL || (CASE WHEN (varSQL = '') THEN '' ELSE ', ' END) || (SELECT JSON_BUILD_OBJECT ('recordID', NULL::bigint,'entities', JSON_BUILD_OBJECT ('sysLoginSession_RefID', varSystemLoginSession::bigint,'sysDataAnnotation', NULL::varchar,'sysDataSetDateTimeTZ', NULL::timestamptz,'sysDataValidityStartDateTimeTZ', NULL::timestamptz,'sysDataValidityFinishDateTimeTZ', NULL::timestamptz,'sysPartitionRemovableRecordKey_RefID', NULL::bigint,'sysBranch_RefID', varInstitutionBranchID::bigint,'sysBaseCurrency_RefID',varBaseCurrencyID::bigint,'name', 'Super User'::varchar)))::varchar;
B5: Guest | D5: =D4 + IF(EXACT(E5, ""), 0, 1) -> 95000000000002 | E5: =IF(EXACT(B5, ""), "", CONCATENATE("PERFORM ""SchSysConfig"".""Func_TblAppObject_UserRole_SET""(varSystemLoginSession, null::bigint, null::varchar, null::timestamptz, null::timestamptz, null::varchar, varInstitutionBranchID, varBaseCurrencyID, ", (IF(EXACT(B5, ""), "NULL", CONCATENATE("'", B5, "'"))),"::varchar);")) -> PERFORM "SchSysConfig"."Func_TblAppObject_UserRole_SET"(varSystemLoginSession, null::bigint, null::varchar, null::timestamptz, null::timestamptz, null::varchar, varInstitutionBranchID, varBaseCurrencyID, 'Guest'::varchar); | G5: =IF(EXACT($E5, ""), "", CONCATENATE( "varSQL := varSQL || (CASE WHEN (varSQL = '') THEN '' ELSE ', ' END) || (SELECT JSON_BUILD_OBJECT (", "'recordID', NULL::bigint,", "'entities', ", "JSON_BUILD_OBJECT (", "'sysLoginSession_RefID', varSystemLoginSession::bigint,", "'sysDataAnnotation', NULL::varchar,", "'sysDataSetDateTimeTZ', NULL::timestamptz,", "'sysDataValidityStartDateTimeTZ', NULL::timestamptz,", "'sysDataValidityFinishDateTimeTZ', NULL::timestamptz,", "'sysPartitionRemovableRecordKey_RefID', NULL::bigint,", "'sysBranch_RefID', varInstitutionBranchID::bigint,", "'sysBaseCurrency_RefID',varBaseCurrencyID::bigint,", "'name', ", IF(EXACT($B5, ""), "null", CONCATENATE("'", SUBSTITUTE($B5, "'", "\'"), "'")), "::varchar", ")))::varchar;")) -> varSQL := varSQL || (CASE WHEN (varSQL = '') THEN '' ELSE ', ' END) || (SELECT JSON_BUILD_OBJECT ('recordID', NULL::bigint,'entities', JSON_BUILD_OBJECT ('sysLoginSession_RefID', varSystemLoginSession::bigint,'sysDataAnnotation', NULL::varchar,'sysDataSetDateTimeTZ', NULL::timestamptz,'sysDataValidityStartDateTimeTZ', NULL::timestamptz,'sysDataValidityFinishDateTimeTZ', NULL::timestamptz,'sysPartitionRemovableRecordKey_RefID', NULL::bigint,'sysBranch_RefID', varInstitutionBranchID::bigint,'sysBaseCurrency_RefID',varBaseCurrencyID::bigint,'name', 'Guest'::varchar)))::varchar;
D6: =D5 + IF(EXACT(E6, ""), 0, 1) -> 95000000000002 | E6: =IF(EXACT(B6, ""), "", CONCATENATE("PERFORM ""SchSysConfig"".""Func_TblAppObject_UserRole_SET""(varSystemLoginSession, null::bigint, null::varchar, null::timestamptz, null::timestamptz, null::varchar, varInstitutionBranchID, varBaseCurrencyID, ", (IF(EXACT(B6, ""), "NULL", CONCATENATE("'", B6, "'"))),"::varchar);")) | G6: =IF(EXACT($E6, ""), "", CONCATENATE( "varSQL := varSQL || (CASE WHEN (varSQL = '') THEN '' ELSE ', ' END) || (SELECT JSON_BUILD_OBJECT (", "'recordID', NULL::bigint,", "'entities', ", "JSON_BUILD_OBJECT (", "'sysLoginSession_RefID', varSystemLoginSession::bigint,", "'sysDataAnnotation', NULL::varchar,", "'sysDataSetDateTimeTZ', NULL::timestamptz,", "'sysDataValidityStartDateTimeTZ', NULL::timestamptz,", "'sysDataValidityFinishDateTimeTZ', NULL::timestamptz,", "'sysPartitionRemovableRecordKey_RefID', NULL::bigint,", "'sysBranch_RefID', varInstitutionBranchID::bigint,", "'sysBaseCurrency_RefID',varBaseCurrencyID::bigint,", "'name', ", IF(EXACT($B6, ""), "null", CONCATENATE("'", SUBSTITUTE($B6, "'", "\'"), "'")), "::varchar", ")))::varchar;"))
B7: Default Employee Role | D7: =D6 + IF(EXACT(E7, ""), 0, 1) -> 95000000000003 | E7: =IF(EXACT(B7, ""), "", CONCATENATE("PERFORM ""SchSysConfig"".""Func_TblAppObject_UserRole_SET""(varSystemLoginSession, null::bigint, null::varchar, null::timestamptz, null::timestamptz, null::varchar, varInstitutionBranchID, varBaseCurrencyID, ", (IF(EXACT(B7, ""), "NULL", CONCATENATE("'", B7, "'"))),"::varchar);")) -> PERFORM "SchSysConfig"."Func_TblAppObject_UserRole_SET"(varSystemLoginSession, null::bigint, null::varchar, null::timestamptz, null::timestamptz, null::varchar, varInstitutionBranchID, varBaseCurrencyID, 'Default Employee Role'::varchar); | G7: =IF(EXACT($E7, ""), "", CONCATENATE( "varSQL := varSQL || (CASE WHEN (varSQL = '') THEN '' ELSE ', ' END) || (SELECT JSON_BUILD_OBJECT (", "'recordID', NULL::bigint,", "'entities', ", "JSON_BUILD_OBJECT (", "'sysLoginSession_RefID', varSystemLoginSession::bigint,", "'sysDataAnnotation', NULL::varchar,", "'sysDataSetDateTimeTZ', NULL::timestamptz,", "'sysDataValidityStartDateTimeTZ', NULL::timestamptz,", "'sysDataValidityFinishDateTimeTZ', NULL::timestamptz,", "'sysPartitionRemovableRecordKey_RefID', NULL::bigint,", "'sysBranch_RefID', varInstitutionBranchID::bigint,", "'sysBaseCurrency_RefID',varBaseCurrencyID::bigint,", "'name', ", IF(EXACT($B7, ""), "null", CONCATENATE("'", SUBSTITUTE($B7, "'", "\'"), "'")), "::varchar", ")))::varchar;")) -> varSQL := varSQL || (CASE WHEN (varSQL = '') THEN '' ELSE ', ' END) || (SELECT JSON_BUILD_OBJECT ('recordID', NULL::bigint,'entities', JSON_BUILD_OBJECT ('sysLoginSession_RefID', varSystemLoginSession::bigint,'sysDataAnnotation', NULL::varchar,'sysDataSetDateTimeTZ', NULL::timestamptz,'sysDataValidityStartDateTimeTZ', NULL::timestamptz,'sysDataValidityFinishDateTimeTZ', NULL::timestamptz,'sysPartitionRemovableRecordKey_RefID', NULL::bigint,'sysBranch_RefID', varInstitutionBranchID::bigint,'sysBaseCurrency_RefID',varBaseCurrencyID::bigint,'name', 'Default Employee Role'::varchar)))::varchar;
D8: =D7 + IF(EXACT(E8, ""), 0, 1) -> 95000000000003 | E8: =IF(EXACT(B8, ""), "", CONCATENATE("PERFORM ""SchSysConfig"".""Func_TblAppObject_UserRole_SET""(varSystemLoginSession, null::bigint, null::varchar, null::timestamptz, null::timestamptz, null::varchar, varInstitutionBranchID, varBaseCurrencyID, ", (IF(EXACT(B8, ""), "NULL", CONCATENATE("'", B8, "'"))),"::varchar);")) | G8: =IF(EXACT($E8, ""), "", CONCATENATE( "varSQL := varSQL || (CASE WHEN (varSQL = '') THEN '' ELSE ', ' END) || (SELECT JSON_BUILD_OBJECT (", "'recordID', NULL::bigint,", "'entities', ", "JSON_BUILD_OBJECT (", "'sysLoginSession_RefID', varSystemLoginSession::bigint,", "'sysDataAnnotation', NULL::varchar,", "'sysDataSetDateTimeTZ', NULL::timestamptz,", "'sysDataValidityStartDateTimeTZ', NULL::timestamptz,", "'sysDataValidityFinishDateTimeTZ', NULL::timestamptz,", "'sysPartitionRemovableRecordKey_RefID', NULL::bigint,", "'sysBranch_RefID', varInstitutionBranchID::bigint,", "'sysBaseCurrency_RefID',varBaseCurrencyID::bigint,", "'name', ", IF(EXACT($B8, ""), "null", CONCATENATE("'", SUBSTITUTE($B8, "'", "\'"), "'")), "::varchar", ")))::varchar;"))
B9: Share Holder | D9: =D8 + IF(EXACT(E9, ""), 0, 1) -> 95000000000004 | E9: =IF(EXACT(B9, ""), "", CONCATENATE("PERFORM ""SchSysConfig"".""Func_TblAppObject_UserRole_SET""(varSystemLoginSession, null::bigint, null::varchar, null::timestamptz, null::timestamptz, null::varchar, varInstitutionBranchID, varBaseCurrencyID, ", (IF(EXACT(B9, ""), "NULL", CONCATENATE("'", B9, "'"))),"::varchar);")) -> PERFORM "SchSysConfig"."Func_TblAppObject_UserRole_SET"(varSystemLoginSession, null::bigint, null::varchar, null::timestamptz, null::timestamptz, null::varchar, varInstitutionBranchID, varBaseCurrencyID, 'Share Holder'::varchar); | G9: =IF(EXACT($E9, ""), "", CONCATENATE( "varSQL := varSQL || (CASE WHEN (varSQL = '') THEN '' ELSE ', ' END) || (SELECT JSON_BUILD_OBJECT (", "'recordID', NULL::bigint,", "'entities', ", "JSON_BUILD_OBJECT (", "'sysLoginSession_RefID', varSystemLoginSession::bigint,", "'sysDataAnnotation', NULL::varchar,", "'sysDataSetDateTimeTZ', NULL::timestamptz,", "'sysDataValidityStartDateTimeTZ', NULL::timestamptz,", "'sysDataValidityFinishDateTimeTZ', NULL::timestamptz,", "'sysPartitionRemovableRecordKey_RefID', NULL::bigint,", "'sysBranch_RefID', varInstitutionBranchID::bigint,", "'sysBaseCurrency_RefID',varBaseCurrencyID::bigint,", "'name', ", IF(EXACT($B9, ""), "null", CONCATENATE("'", SUBSTITUTE($B9, "'", "\'"), "'")), "::varchar", ")))::varchar;")) -> varSQL := varSQL || (CASE WHEN (varSQL = '') THEN '' ELSE ', ' END) || (SELECT JSON_BUILD_OBJECT ('recordID', NULL::bigint,'entities', JSON_BUILD_OBJECT ('sysLoginSession_RefID', varSystemLoginSession::bigint,'sysDataAnnotation', NULL::varchar,'sysDataSetDateTimeTZ', NULL::timestamptz,'sysDataValidityStartDateTimeTZ', NULL::timestamptz,'sysDataValidityFinishDateTimeTZ', NULL::timestamptz,'sysPartitionRemovableRecordKey_RefID', NULL::bigint,'sysBranch_RefID', varInstitutionBranchID::bigint,'sysBaseCurrency_RefID',varBaseCurrencyID::bigint,'name', 'Share Holder'::varchar)))::varchar;
B10: Stack Holder | D10: =D9 + IF(EXACT(E10, ""), 0, 1) -> 95000000000005 | E10: =IF(EXACT(B10, ""), "", CONCATENATE("PERFORM ""SchSysConfig"".""Func_TblAppObject_UserRole_SET""(varSystemLoginSession, null::bigint, null::varchar, null::timestamptz, null::timestamptz, null::varchar, varInstitutionBranchID, varBaseCurrencyID, ", (IF(EXACT(B10, ""), "NULL", CONCATENATE("'", B10, "'"))),"::varchar);")) -> PERFORM "SchSysConfig"."Func_TblAppObject_UserRole_SET"(varSystemLoginSession, null::bigint, null::varchar, null::timestamptz, null::timestamptz, null::varchar, varInstitutionBranchID, varBaseCurrencyID, 'Stack Holder'::varchar); | G10: =IF(EXACT($E10, ""), "", CONCATENATE( "varSQL := varSQL || (CASE WHEN (varSQL = '') THEN '' ELSE ', ' END) || (SELECT JSON_BUILD_OBJECT (", "'recordID', NULL::bigint,", "'entities', ", "JSON_BUILD_OBJECT (", "'sysLoginSession_RefID', varSystemLoginSession::bigint,", "'sysDataAnnotation', NULL::varchar,", "'sysDataSetDateTimeTZ', NULL::timestamptz,", "'sysDataValidityStartDateTimeTZ', NULL::timestamptz,", "'sysDataValidityFinishDateTimeTZ', NULL::timestamptz,", "'sysPartitionRemovableRecordKey_RefID', NULL::bigint,", "'sysBranch_RefID', varInstitutionBranchID::bigint,", "'sysBaseCurrency_RefID',varBaseCurrencyID::bigint,", "'name', ", IF(EXACT($B10, ""), "null", CONCATENATE("'", SUBSTITUTE($B10, "'", "\'"), "'")), "::varchar", ")))::varchar;")) -> varSQL := varSQL || (CASE WHEN (varSQL = '') THEN '' ELSE ', ' END) || (SELECT JSON_BUILD_OBJECT ('recordID', NULL::bigint,'entities', JSON_BUILD_OBJECT ('sysLoginSession_RefID', varSystemLoginSession::bigint,'sysDataAnnotation', NULL::varchar,'sysDataSetDateTimeTZ', NULL::timestamptz,'sysDataValidityStartDateTimeTZ', NULL::timestamptz,'sysDataValidityFinishDateTimeTZ', NULL::timestamptz,'sysPartitionRemovableRecordKey_RefID', NULL::bigint,'sysBranch_RefID', varInstitutionBranchID::bigint,'sysBaseCurrency_RefID',varBaseCurrencyID::bigint,'name', 'Stack Holder'::varchar)))::varchar;
B11: Public Accounting Firm | D11: =D10 + IF(EXACT(E11, ""), 0, 1) -> 95000000000006 | E11: =IF(EXACT(B11, ""), "", CONCATENATE("PERFORM ""SchSysConfig"".""Func_TblAppObject_UserRole_SET""(varSystemLoginSession, null::bigint, null::varchar, null::timestamptz, null::timestamptz, null::varchar, varInstitutionBranchID, varBaseCurrencyID, ", (IF(EXACT(B11, ""), "NULL", CONCATENATE("'", B11, "'"))),"::varchar);")) -> PERFORM "SchSysConfig"."Func_TblAppObject_UserRole_SET"(varSystemLoginSession, null::bigint, null::varchar, null::timestamptz, null::timestamptz, null::varchar, varInstitutionBranchID, varBaseCurrencyID, 'Public Accounting Firm'::varchar); | G11: =IF(EXACT($E11, ""), "", CONCATENATE( "varSQL := varSQL || (CASE WHEN (varSQL = '') THEN '' ELSE ', ' END) || (SELECT JSON_BUILD_OBJECT (", "'recordID', NULL::bigint,", "'entities', ", "JSON_BUILD_OBJECT (", "'sysLoginSession_RefID', varSystemLoginSession::bigint,", "'sysDataAnnotation', NULL::varchar,", "'sysDataSetDateTimeTZ', NULL::timestamptz,", "'sysDataValidityStartDateTimeTZ', NULL::timestamptz,", "'sysDataValidityFinishDateTimeTZ', NULL::timestamptz,", "'sysPartitionRemovableRecordKey_RefID', NULL::bigint,", "'sysBranch_RefID', varInstitutionBranchID::bigint,", "'sysBaseCurrency_RefID',varBaseCurrencyID::bigint,", "'name', ", IF(EXACT($B11, ""), "null", CONCATENATE("'", SUBSTITUTE($B11, "'", "\'"), "'")), "::varchar", ")))::varchar;")) -> varSQL := varSQL || (CASE WHEN (varSQL = '') THEN '' ELSE ', ' END) || (SELECT JSON_BUILD_OBJECT ('recordID', NULL::bigint,'entities', JSON_BUILD_OBJECT ('sysLoginSession_RefID', varSystemLoginSession::bigint,'sysDataAnnotation', NULL::varchar,'sysDataSetDateTimeTZ', NULL::timestamptz,'sysDataValidityStartDateTimeTZ', NULL::timestamptz,'sysDataValidityFinishDateTimeTZ', NULL::timestamptz,'sysPartitionRemovableRecordKey_RefID', NULL::bigint,'sysBranch_RefID', varInstitutionBranchID::bigint,'sysBaseCurrency_RefID',varBaseCurrencyID::bigint,'name', 'Public Accounting Firm'::varchar)))::varchar;
B12: Commissary | D12: =D11 + IF(EXACT(E12, ""), 0, 1) -> 95000000000007 | E12: =IF(EXACT(B12, ""), "", CONCATENATE("PERFORM ""SchSysConfig"".""Func_TblAppObject_UserRole_SET""(varSystemLoginSession, null::bigint, null::varchar, null::timestamptz, null::timestamptz, null::varchar, varInstitutionBranchID, varBaseCurrencyID, ", (IF(EXACT(B12, ""), "NULL", CONCATENATE("'", B12, "'"))),"::varchar);")) -> PERFORM "SchSysConfig"."Func_TblAppObject_UserRole_SET"(varSystemLoginSession, null::bigint, null::varchar, null::timestamptz, null::timestamptz, null::varchar, varInstitutionBranchID, varBaseCurrencyID, 'Commissary'::varchar); | G12: =IF(EXACT($E12, ""), "", CONCATENATE( "varSQL := varSQL || (CASE WHEN (varSQL = '') THEN '' ELSE ', ' END) || (SELECT JSON_BUILD_OBJECT (", "'recordID', NULL::bigint,", "'entities', ", "JSON_BUILD_OBJECT (", "'sysLoginSession_RefID', varSystemLoginSession::bigint,", "'sysDataAnnotation', NULL::varchar,", "'sysDataSetDateTimeTZ', NULL::timestamptz,", "'sysDataValidityStartDateTimeTZ', NULL::timestamptz,", "'sysDataValidityFinishDateTimeTZ', NULL::timestamptz,", "'sysPartitionRemovableRecordKey_RefID', NULL::bigint,", "'sysBranch_RefID', varInstitutionBranchID::bigint,", "'sysBaseCurrency_RefID',varBaseCurrencyID::bigint,", "'name', ", IF(EXACT($B12, ""), "null", CONCATENATE("'", SUBSTITUTE($B12, "'", "\'"), "'")), "::varchar", ")))::varchar;")) -> varSQL := varSQL || (CASE WHEN (varSQL = '') THEN '' ELSE ', ' END) || (SELECT JSON_BUILD_OBJECT ('recordID', NULL::bigint,'entities', JSON_BUILD_OBJECT ('sysLoginSession_RefID', varSystemLoginSession::bigint,'sysDataAnnotation', NULL::varchar,'sysDataSetDateTimeTZ', NULL::timestamptz,'sysDataValidityStartDateTimeTZ', NULL::timestamptz,'sysDataValidityFinishDateTimeTZ', NULL::timestamptz,'sysPartitionRemovableRecordKey_RefID', NULL::bigint,'sysBranch_RefID', varInstitutionBranchID::bigint,'sysBaseCurrency_RefID',varBaseCurrencyID::bigint,'name', 'Commissary'::varchar)))::varchar;
D13: =D12 + IF(EXACT(E13, ""), 0, 1) -> 95000000000007 | E13: =IF(EXACT(B13, ""), "", CONCATENATE("PERFORM ""SchSysConfig"".""Func_TblAppObject_UserRole_SET""(varSystemLoginSession, null::bigint, null::varchar, null::timestamptz, null::timestamptz, null::varchar, varInstitutionBranchID, varBaseCurrencyID, ", (IF(EXACT(B13, ""), "NULL", CONCATENATE("'", B13, "'"))),"::varchar);")) | G13: =IF(EXACT($E13, ""), "", CONCATENATE( "varSQL := varSQL || (CASE WHEN (varSQL = '') THEN '' ELSE ', ' END) || (SELECT JSON_BUILD_OBJECT (", "'recordID', NULL::bigint,", "'entities', ", "JSON_BUILD_OBJECT (", "'sysLoginSession_RefID', varSystemLoginSession::bigint,", "'sysDataAnnotation', NULL::varchar,", "'sysDataSetDateTimeTZ', NULL::timestamptz,", "'sysDataValidityStartDateTimeTZ', NULL::timestamptz,", "'sysDataValidityFinishDateTimeTZ', NULL::timestamptz,", "'sysPartitionRemovableRecordKey_RefID', NULL::bigint,", "'sysBranch_RefID', varInstitutionBranchID::bigint,", "'sysBaseCurrency_RefID',varBaseCurrencyID::bigint,", "'name', ", IF(EXACT($B13, ""), "null", CONCATENATE("'", SUBSTITUTE($B13, "'", "\'"), "'")), "::varchar", ")))::varchar;"))
B14: Director | D14: =D13 + IF(EXACT(E14, ""), 0, 1) -> 95000000000008 | E14: =IF(EXACT(B14, ""), "", CONCATENATE("PERFORM ""SchSysConfig"".""Func_TblAppObject_UserRole_SET""(varSystemLoginSession, null::bigint, null::varchar, null::timestamptz, null::timestamptz, null::varchar, varInstitutionBranchID, varBaseCurrencyID, ", (IF(EXACT(B14, ""), "NULL", CONCATENATE("'", B14, "'"))),"::varchar);")) -> PERFORM "SchSysConfig"."Func_TblAppObject_UserRole_SET"(varSystemLoginSession, null::bigint, null::varchar, null::timestamptz, null::timestamptz, null::varchar, varInstitutionBranchID, varBaseCurrencyID, 'Director'::varchar); | G14: =IF(EXACT($E14, ""), "", CONCATENATE( "varSQL := varSQL || (CASE WHEN (varSQL = '') THEN '' ELSE ', ' END) || (SELECT JSON_BUILD_OBJECT (", "'recordID', NULL::bigint,", "'entities', ", "JSON_BUILD_OBJECT (", "'sysLoginSession_RefID', varSystemLoginSession::bigint,", "'sysDataAnnotation', NULL::varchar,", "'sysDataSetDateTimeTZ', NULL::timestamptz,", "'sysDataValidityStartDateTimeTZ', NULL::timestamptz,", "'sysDataValidityFinishDateTimeTZ', NULL::timestamptz,", "'sysPartitionRemovableRecordKey_RefID', NULL::bigint,", "'sysBranch_RefID', varInstitutionBranchID::bigint,", "'sysBaseCurrency_RefID',varBaseCurrencyID::bigint,", "'name', ", IF(EXACT($B14, ""), "null", CONCATENATE("'", SUBSTITUTE($B14, "'", "\'"), "'")), "::varchar", ")))::varchar;")) -> varSQL := varSQL || (CASE WHEN (varSQL = '') THEN '' ELSE ', ' END) || (SELECT JSON_BUILD_OBJECT ('recordID', NULL::bigint,'entities', JSON_BUILD_OBJECT ('sysLoginSession_RefID', varSystemLoginSession::bigint,'sysDataAnnotation', NULL::varchar,'sysDataSetDateTimeTZ', NULL::timestamptz,'sysDataValidityStartDateTimeTZ', NULL::timestamptz,'sysDataValidityFinishDateTimeTZ', NULL::timestamptz,'sysPartitionRemovableRecordKey_RefID', NULL::bigint,'sysBranch_RefID', varInstitutionBranchID::bigint,'sysBaseCurrency_RefID',varBaseCurrencyID::bigint,'name', 'Director'::varchar)))::varchar;
B15: President Director | D15: =D14 + IF(EXACT(E15, ""), 0, 1) -> 95000000000009 | E15: =IF(EXACT(B15, ""), "", CONCATENATE("PERFORM ""SchSysConfig"".""Func_TblAppObject_UserRole_SET""(varSystemLoginSession, null::bigint, null::varchar, null::timestamptz, null::timestamptz, null::varchar, varInstitutionBranchID, varBaseCurrencyID, ", (IF(EXACT(B15, ""), "NULL", CONCATENATE("'", B15, "'"))),"::varchar);")) -> PERFORM "SchSysConfig"."Func_TblAppObject_UserRole_SET"(varSystemLoginSession, null::bigint, null::varchar, null::timestamptz, null::timestamptz, null::varchar, varInstitutionBranchID, varBaseCurrencyID, 'President Director'::varchar); | G15: =IF(EXACT($E15, ""), "", CONCATENATE( "varSQL := varSQL || (CASE WHEN (varSQL = '') THEN '' ELSE ', ' END) || (SELECT JSON_BUILD_OBJECT (", "'recordID', NULL::bigint,", "'entities', ", "JSON_BUILD_OBJECT (", "'sysLoginSession_RefID', varSystemLoginSession::bigint,", "'sysDataAnnotation', NULL::varchar,", "'sysDataSetDateTimeTZ', NULL::timestamptz,", "'sysDataValidityStartDateTimeTZ', NULL::timestamptz,", "'sysDataValidityFinishDateTimeTZ', NULL::timestamptz,", "'sysPartitionRemovableRecordKey_RefID', NULL::bigint,", "'sysBranch_RefID', varInstitutionBranchID::bigint,", "'sysBaseCurrency_RefID',varBaseCurrencyID::bigint,", "'name', ", IF(EXACT($B15, ""), "null", CONCATENATE("'", SUBSTITUTE($B15, "'", "\'"), "'")), "::varchar", ")))::varchar;")) -> varSQL := varSQL || (CASE WHEN (varSQL = '') THEN '' ELSE ', ' END) || (SELECT JSON_BUILD_OBJECT ('recordID', NULL::bigint,'entities', JSON_BUILD_OBJECT ('sysLoginSession_RefID', varSystemLoginSession::bigint,'sysDataAnnotation', NULL::varchar,'sysDataSetDateTimeTZ', NULL::timestamptz,'sysDataValidityStartDateTimeTZ', NULL::timestamptz,'sysDataValidityFinishDateTimeTZ', NULL::timestamptz,'sysPartitionRemovableRecordKey_RefID', NULL::bigint,'sysBranch_RefID', varInstitutionBranchID::bigint,'sysBaseCurrency_RefID',varBaseCurrencyID::bigint,'name', 'President Director'::varchar)))::varchar;
B16: Finance Director | D16: =D15 + IF(EXACT(E16, ""), 0, 1) -> 95000000000010 | E16: =IF(EXACT(B16, ""), "", CONCATENATE("PERFORM ""SchSysConfig"".""Func_TblAppObject_UserRole_SET""(varSystemLoginSession, null::bigint, null::varchar, null::timestamptz, null::timestamptz, null::varchar, varInstitutionBranchID, varBaseCurrencyID, ", (IF(EXACT(B16, ""), "NULL", CONCATENATE("'", B16, "'"))),"::varchar);")) -> PERFORM "SchSysConfig"."Func_TblAppObject_UserRole_SET"(varSystemLoginSession, null::bigint, null::varchar, null::timestamptz, null::timestamptz, null::varchar, varInstitutionBranchID, varBaseCurrencyID, 'Finance Director'::varchar); | G16: =IF(EXACT($E16, ""), "", CONCATENATE( "varSQL := varSQL || (CASE WHEN (varSQL = '') THEN '' ELSE ', ' END) || (SELECT JSON_BUILD_OBJECT (", "'recordID', NULL::bigint,", "'entities', ", "JSON_BUILD_OBJECT (", "'sysLoginSession_RefID', varSystemLoginSession::bigint,", "'sysDataAnnotation', NULL::varchar,", "'sysDataSetDateTimeTZ', NULL::timestamptz,", "'sysDataValidityStartDateTimeTZ', NULL::timestamptz,", "'sysDataValidityFinishDateTimeTZ', NULL::timestamptz,", "'sysPartitionRemovableRecordKey_RefID', NULL::bigint,", "'sysBranch_RefID', varInstitutionBranchID::bigint,", "'sysBaseCurrency_RefID',varBaseCurrencyID::bigint,", "'name', ", IF(EXACT($B16, ""), "null", CONCATENATE("'", SUBSTITUTE($B16, "'", "\'"), "'")), "::varchar", ")))::varchar;")) -> varSQL := varSQL || (CASE WHEN (varSQL = '') THEN '' ELSE ', ' END) || (SELECT JSON_BUILD_OBJECT ('recordID', NULL::bigint,'entities', JSON_BUILD_OBJECT ('sysLoginSession_RefID', varSystemLoginSession::bigint,'sysDataAnnotation', NULL::varchar,'sysDataSetDateTimeTZ', NULL::timestamptz,'sysDataValidityStartDateTimeTZ', NULL::timestamptz,'sysDataValidityFinishDateTimeTZ', NULL::timestamptz,'sysPartitionRemovableRecordKey_RefID', NULL::bigint,'sysBranch_RefID', varInstitutionBranchID::bigint,'sysBaseCurrency_RefID',varBaseCurrencyID::bigint,'name', 'Finance Director'::varchar)))::varchar;
B17: Operational Director | D17: =D16 + IF(EXACT(E17, ""), 0, 1) -> 95000000000011 | E17: =IF(EXACT(B17, ""), "", CONCATENATE("PERFORM ""SchSysConfig"".""Func_TblAppObject_UserRole_SET""(varSystemLoginSession, null::bigint, null::varchar, null::timestamptz, null::timestamptz, null::varchar, varInstitutionBranchID, varBaseCurrencyID, ", (IF(EXACT(B17, ""), "NULL", CONCATENATE("'", B17, "'"))),"::varchar);")) -> PERFORM "SchSysConfig"."Func_TblAppObject_UserRole_SET"(varSystemLoginSession, null::bigint, null::varchar, null::timestamptz, null::timestamptz, null::varchar, varInstitutionBranchID, varBaseCurrencyID, 'Operational Director'::varchar); | G17: =IF(EXACT($E17, ""), "", CONCATENATE( "varSQL := varSQL || (CASE WHEN (varSQL = '') THEN '' ELSE ', ' END) || (SELECT JSON_BUILD_OBJECT (", "'recordID', NULL::bigint,", "'entities', ", "JSON_BUILD_OBJECT (", "'sysLoginSession_RefID', varSystemLoginSession::bigint,", "'sysDataAnnotation', NULL::varchar,", "'sysDataSetDateTimeTZ', NULL::timestamptz,", "'sysDataValidityStartDateTimeTZ', NULL::timestamptz,", "'sysDataValidityFinishDateTimeTZ', NULL::timestamptz,", "'sysPartitionRemovableRecordKey_RefID', NULL::bigint,", "'sysBranch_RefID', varInstitutionBranchID::bigint,", "'sysBaseCurrency_RefID',varBaseCurrencyID::bigint,", "'name', ", IF(EXACT($B17, ""), "null", CONCATENATE("'", SUBSTITUTE($B17, "'", "\'"), "'")), "::varchar", ")))::varchar;")) -> varSQL := varSQL || (CASE WHEN (varSQL = '') THEN '' ELSE ', ' END) || (SELECT JSON_BUILD_OBJECT ('recordID', NULL::bigint,'entities', JSON_BUILD_OBJECT ('sysLoginSession_RefID', varSystemLoginSession::bigint,'sysDataAnnotation', NULL::varchar,'sysDataSetDateTimeTZ', NULL::timestamptz,'sysDataValidityStartDateTimeTZ', NULL::timestamptz,'sysDataValidityFinishDateTimeTZ', NULL::timestamptz,'sysPartitionRemovableRecordKey_RefID', NULL::bigint,'sysBranch_RefID', varInstitutionBranchID::bigint,'sysBaseCurrency_RefID',varBaseCurrencyID::bigint,'name', 'Operational Director'::varchar)))::varchar;
B18: Marketing Director | D18: =D17 + IF(EXACT(E18, ""), 0, 1) -> 95000000000012 | E18: =IF(EXACT(B18, ""), "", CONCATENATE("PERFORM ""SchSysConfig"".""Func_TblAppObject_UserRole_SET""(varSystemLoginSession, null::bigint, null::varchar, null::timestamptz, null::timestamptz, null::varchar, varInstitutionBranchID, varBaseCurrencyID, ", (IF(EXACT(B18, ""), "NULL", CONCATENATE("'", B18, "'"))),"::varchar);")) -> PERFORM "SchSysConfig"."Func_TblAppObject_UserRole_SET"(varSystemLoginSession, null::bigint, null::varchar, null::timestamptz, null::timestamptz, null::varchar, varInstitutionBranchID, varBaseCurrencyID, 'Marketing Director'::varchar); | G18: =IF(EXACT($E18, ""), "", CONCATENATE( "varSQL := varSQL || (CASE WHEN (varSQL = '') THEN '' ELSE ', ' END) || (SELECT JSON_BUILD_OBJECT (", "'recordID', NULL::bigint,", "'entities', ", "JSON_BUILD_OBJECT (", "'sysLoginSession_RefID', varSystemLoginSession::bigint,", "'sysDataAnnotation', NULL::varchar,", "'sysDataSetDateTimeTZ', NULL::timestamptz,", "'sysDataValidityStartDateTimeTZ', NULL::timestamptz,", "'sysDataValidityFinishDateTimeTZ', NULL::timestamptz,", "'sysPartitionRemovableRecordKey_RefID', NULL::bigint,", "'sysBranch_RefID', varInstitutionBranchID::bigint,", "'sysBaseCurrency_RefID',varBaseCurrencyID::bigint,", "'name', ", IF(EXACT($B18, ""), "null", CONCATENATE("'", SUBSTITUTE($B18, "'", "\'"), "'")), "::varchar", ")))::varchar;")) -> varSQL := varSQL || (CASE WHEN (varSQL = '') THEN '' ELSE ', ' END) || (SELECT JSON_BUILD_OBJECT ('recordID', NULL::bigint,'entities', JSON_BUILD_OBJECT ('sysLoginSession_RefID', varSystemLoginSession::bigint,'sysDataAnnotation', NULL::varchar,'sysDataSetDateTimeTZ', NULL::timestamptz,'sysDataValidityStartDateTimeTZ', NULL::timestamptz,'sysDataValidityFinishDateTimeTZ', NULL::timestamptz,'sysPartitionRemovableRecordKey_RefID', NULL::bigint,'sysBranch_RefID', varInstitutionBranchID::bigint,'sysBaseCurrency_RefID',varBaseCurrencyID::bigint,'name', 'Marketing Director'::varchar)))::varchar;
B19: Information Technology Director | D19: =D18 + IF(EXACT(E19, ""), 0, 1) -> 95000000000013 | E19: =IF(EXACT(B19, ""), "", CONCATENATE("PERFORM ""SchSysConfig"".""Func_TblAppObject_UserRole_SET""(varSystemLoginSession, null::bigint, null::varchar, null::timestamptz, null::timestamptz, null::varchar, varInstitutionBranchID, varBaseCurrencyID, ", (IF(EXACT(B19, ""), "NULL", CONCATENATE("'", B19, "'"))),"::varchar);")) -> PERFORM "SchSysConfig"."Func_TblAppObject_UserRole_SET"(varSystemLoginSession, null::bigint, null::varchar, null::timestamptz, null::timestamptz, null::varchar, varInstitutionBranchID, varBaseCurrencyID, 'Information Technology Director'::varchar); | G19: =IF(EXACT($E19, ""), "", CONCATENATE( "varSQL := varSQL || (CASE WHEN (varSQL = '') THEN '' ELSE ', ' END) || (SELECT JSON_BUILD_OBJECT (", "'recordID', NULL::bigint,", "'entities', ", "JSON_BUILD_OBJECT (", "'sysLoginSession_RefID', varSystemLoginSession::bigint,", "'sysDataAnnotation', NULL::varchar,", "'sysDataSetDateTimeTZ', NULL::timestamptz,", "'sysDataValidityStartDateTimeTZ', NULL::timestamptz,", "'sysDataValidityFinishDateTimeTZ', NULL::timestamptz,", "'sysPartitionRemovableRecordKey_RefID', NULL::bigint,", "'sysBranch_RefID', varInstitutionBranchID::bigint,", "'sysBaseCurrency_RefID',varBaseCurrencyID::bigint,", "'name', ", IF(EXACT($B19, ""), "null", CONCATENATE("'", SUBSTITUTE($B19, "'", "\'"), "'")), "::varchar", ")))::varchar;")) -> varSQL := varSQL || (CASE WHEN (varSQL = '') THEN '' ELSE ', ' END) || (SELECT JSON_BUILD_OBJECT ('recordID', NULL::bigint,'entities', JSON_BUILD_OBJECT ('sysLoginSession_RefID', varSystemLoginSession::bigint,'sysDataAnnotation', NULL::varchar,'sysDataSetDateTimeTZ', NULL::timestamptz,'sysDataValidityStartDateTimeTZ', NULL::timestamptz,'sysDataValidityFinishDateTimeTZ', NULL::timestamptz,'sysPartitionRemovableRecordKey_RefID', NULL::bigint,'sysBranch_RefID', varInstitutionBranchID::bigint,'sysBaseCurrency_RefID',varBaseCurrencyID::bigint,'name', 'Information Technology Director'::varchar)))::varchar;
D20: =D19 + IF(EXACT(E20, ""), 0, 1) -> 95000000000013 | E20: =IF(EXACT(B20, ""), "", CONCATENATE("PERFORM ""SchSysConfig"".""Func_TblAppObject_UserRole_SET""(varSystemLoginSession, null::bigint, null::varchar, null::timestamptz, null::timestamptz, null::varchar, varInstitutionBranchID, varBaseCurrencyID, ", (IF(EXACT(B20, ""), "NULL", CONCATENATE("'", B20, "'"))),"::varchar);")) | G20: =IF(EXACT($E20, ""), "", CONCATENATE( "varSQL := varSQL || (CASE WHEN (varSQL = '') THEN '' ELSE ', ' END) || (SELECT JSON_BUILD_OBJECT (", "'recordID', NULL::bigint,", "'entities', ", "JSON_BUILD_OBJECT (", "'sysLoginSession_RefID', varSystemLoginSession::bigint,", "'sysDataAnnotation', NULL::varchar,", "'sysDataSetDateTimeTZ', NULL::timestamptz,", "'sysDataValidityStartDateTimeTZ', NULL::timestamptz,", "'sysDataValidityFinishDateTimeTZ', NULL::timestamptz,", "'sysPartitionRemovableRecordKey_RefID', NULL::bigint,", "'sysBranch_RefID', varInstitutionBranchID::bigint,", "'sysBaseCurrency_RefID',varBaseCurrencyID::bigint,", "'name', ", IF(EXACT($B20, ""), "null", CONCATENATE("'", SUBSTITUTE($B20, "'", "\'"), "'")), "::varchar", ")))::varchar;"))
B21: Project General Manager | D21: =D20 + IF(EXACT(E21, ""), 0, 1) -> 95000000000014 | E21: =IF(EXACT(B21, ""), "", CONCATENATE("PERFORM ""SchSysConfig"".""Func_TblAppObject_UserRole_SET""(varSystemLoginSession, null::bigint, null::varchar, null::timestamptz, null::timestamptz, null::varchar, varInstitutionBranchID, varBaseCurrencyID, ", (IF(EXACT(B21, ""), "NULL", CONCATENATE("'", B21, "'"))),"::varchar);")) -> PERFORM "SchSysConfig"."Func_TblAppObject_UserRole_SET"(varSystemLoginSession, null::bigint, null::varchar, null::timestamptz, null::timestamptz, null::varchar, varInstitutionBranchID, varBaseCurrencyID, 'Project General Manager'::varchar); | G21: =IF(EXACT($E21, ""), "", CONCATENATE( "varSQL := varSQL || (CASE WHEN (varSQL = '') THEN '' ELSE ', ' END) || (SELECT JSON_BUILD_OBJECT (", "'recordID', NULL::bigint,", "'entities', ", "JSON_BUILD_OBJECT (", "'sysLoginSession_RefID', varSystemLoginSession::bigint,", "'sysDataAnnotation', NULL::varchar,", "'sysDataSetDateTimeTZ', NULL::timestamptz,", "'sysDataValidityStartDateTimeTZ', NULL::timestamptz,", "'sysDataValidityFinishDateTimeTZ', NULL::timestamptz,", "'sysPartitionRemovableRecordKey_RefID', NULL::bigint,", "'sysBranch_RefID', varInstitutionBranchID::bigint,", "'sysBaseCurrency_RefID',varBaseCurrencyID::bigint,", "'name', ", IF(EXACT($B21, ""), "null", CONCATENATE("'", SUBSTITUTE($B21, "'", "\'"), "'")), "::varchar", ")))::varchar;")) -> varSQL := varSQL || (CASE WHEN (varSQL = '') THEN '' ELSE ', ' END) || (SELECT JSON_BUILD_OBJECT ('recordID', NULL::bigint,'entities', JSON_BUILD_OBJECT ('sysLoginSession_RefID', varSystemLoginSession::bigint,'sysDataAnnotation', NULL::varchar,'sysDataSetDateTimeTZ', NULL::timestamptz,'sysDataValidityStartDateTimeTZ', NULL::timestamptz,'sysDataValidityFinishDateTimeTZ', NULL::timestamptz,'sysPartitionRemovableRecordKey_RefID', NULL::bigint,'sysBranch_RefID', varInstitutionBranchID::bigint,'sysBaseCurrency_RefID',varBaseCurrencyID::bigint,'name', 'Project General Manager'::varchar)))::varchar;
B22: Project Management Officer | D22: =D21 + IF(EXACT(E22, ""), 0, 1) -> 95000000000015 | E22: =IF(EXACT(B22, ""), "", CONCATENATE("PERFORM ""SchSysConfig"".""Func_TblAppObject_UserRole_SET""(varSystemLoginSession, null::bigint, null::varchar, null::timestamptz, null::timestamptz, null::varchar, varInstitutionBranchID, varBaseCurrencyID, ", (IF(EXACT(B22, ""), "NULL", CONCATENATE("'", B22, "'"))),"::varchar);")) -> PERFORM "SchSysConfig"."Func_TblAppObject_UserRole_SET"(varSystemLoginSession, null::bigint, null::varchar, null::timestamptz, null::timestamptz, null::varchar, varInstitutionBranchID, varBaseCurrencyID, 'Project Management Officer'::varchar); | G22: =IF(EXACT($E22, ""), "", CONCATENATE( "varSQL := varSQL || (CASE WHEN (varSQL = '') THEN '' ELSE ', ' END) || (SELECT JSON_BUILD_OBJECT (", "'recordID', NULL::bigint,", "'entities', ", "JSON_BUILD_OBJECT (", "'sysLoginSession_RefID', varSystemLoginSession::bigint,", "'sysDataAnnotation', NULL::varchar,", "'sysDataSetDateTimeTZ', NULL::timestamptz,", "'sysDataValidityStartDateTimeTZ', NULL::timestamptz,", "'sysDataValidityFinishDateTimeTZ', NULL::timestamptz,", "'sysPartitionRemovableRecordKey_RefID', NULL::bigint,", "'sysBranch_RefID', varInstitutionBranchID::bigint,", "'sysBaseCurrency_RefID',varBaseCurrencyID::bigint,", "'name', ", IF(EXACT($B22, ""), "null", CONCATENATE("'", SUBSTITUTE($B22, "'", "\'"), "'")), "::varchar", ")))::varchar;")) -> varSQL := varSQL || (CASE WHEN (varSQL = '') THEN '' ELSE ', ' END) || (SELECT JSON_BUILD_OBJECT ('recordID', NULL::bigint,'entities', JSON_BUILD_OBJECT ('sysLoginSession_RefID', varSystemLoginSession::bigint,'sysDataAnnotation', NULL::varchar,'sysDataSetDateTimeTZ', NULL::timestamptz,'sysDataValidityStartDateTimeTZ', NULL::timestamptz,'sysDataValidityFinishDateTimeTZ', NULL::timestamptz,'sysPartitionRemovableRecordKey_RefID', NULL::bigint,'sysBranch_RefID', varInstitutionBranchID::bigint,'sysBaseCurrency_RefID',varBaseCurrencyID::bigint,'name', 'Project Management Officer'::varchar)))::varchar;
B23: Finance, Accounting, & Tax General Manager | D23: =D22 + IF(EXACT(E23, ""), 0, 1) -> 95000000000016 | E23: =IF(EXACT(B23, ""), "", CONCATENATE("PERFORM ""SchSysConfig"".""Func_TblAppObject_UserRole_SET""(varSystemLoginSession, null::bigint, null::varchar, null::timestamptz, null::timestamptz, null::varchar, varInstitutionBranchID, varBaseCurrencyID, ", (IF(EXACT(B23, ""), "NULL", CONCATENATE("'", B23, "'"))),"::varchar);")) -> PERFORM "SchSysConfig"."Func_TblAppObject_UserRole_SET"(varSystemLoginSession, null::bigint, null::varchar, null::timestamptz, null::timestamptz, null::varchar, varInstitutionBranchID, varBaseCurrencyID, 'Finance, Accounting, & Tax General Manager'::varchar); | G23: =IF(EXACT($E23, ""), "", CONCATENATE( "varSQL := varSQL || (CASE WHEN (varSQL = '') THEN '' ELSE ', ' END) || (SELECT JSON_BUILD_OBJECT (", "'recordID', NULL::bigint,", "'entities', ", "JSON_BUILD_OBJECT (", "'sysLoginSession_RefID', varSystemLoginSession::bigint,", "'sysDataAnnotation', NULL::varchar,", "'sysDataSetDateTimeTZ', NULL::timestamptz,", "'sysDataValidityStartDateTimeTZ', NULL::timestamptz,", "'sysDataValidityFinishDateTimeTZ', NULL::timestamptz,", "'sysPartitionRemovableRecordKey_RefID', NULL::bigint,", "'sysBranch_RefID', varInstitutionBranchID::bigint,", "'sysBaseCurrency_RefID',varBaseCurrencyID::bigint,", "'name', ", IF(EXACT($B23, ""), "null", CONCATENATE("'", SUBSTITUTE($B23, "'", "\'"), "'")), "::varchar", ")))::varchar;")) -> varSQL := varSQL || (CASE WHEN (varSQL = '') THEN '' ELSE ', ' END) || (SELECT JSON_BUILD_OBJECT ('recordID', NULL::bigint,'entities', JSON_BUILD_OBJECT ('sysLoginSession_RefID', varSystemLoginSession::bigint,'sysDataAnnotation', NULL::varchar,'sysDataSetDateTimeTZ', NULL::timestamptz,'sysDataValidityStartDateTimeTZ', NULL::timestamptz,'sysDataValidityFinishDateTimeTZ', NULL::timestamptz,'sysPartitionRemovableRecordKey_RefID', NULL::bigint,'sysBranch_RefID', varInstitutionBranchID::bigint,'sysBaseCurrency_RefID',varBaseCurrencyID::bigint,'name', 'Finance, Accounting, & Tax General Manager'::varchar)))::varchar;
B24: HR, GA, & TAM General Manager | D24: =D23 + IF(EXACT(E24, ""), 0, 1) -> 95000000000017 | E24: =IF(EXACT(B24, ""), "", CONCATENATE("PERFORM ""SchSysConfig"".""Func_TblAppObject_UserRole_SET""(varSystemLoginSession, null::bigint, null::varchar, null::timestamptz, null::timestamptz, null::varchar, varInstitutionBranchID, varBaseCurrencyID, ", (IF(EXACT(B24, ""), "NULL", CONCATENATE("'", B24, "'"))),"::varchar);")) -> PERFORM "SchSysConfig"."Func_TblAppObject_UserRole_SET"(varSystemLoginSession, null::bigint, null::varchar, null::timestamptz, null::timestamptz, null::varchar, varInstitutionBranchID, varBaseCurrencyID, 'HR, GA, & TAM General Manager'::varchar); | G24: =IF(EXACT($E24, ""), "", CONCATENATE( "varSQL := varSQL || (CASE WHEN (varSQL = '') THEN '' ELSE ', ' END) || (SELECT JSON_BUILD_OBJECT (", "'recordID', NULL::bigint,", "'entities', ", "JSON_BUILD_OBJECT (", "'sysLoginSession_RefID', varSystemLoginSession::bigint,", "'sysDataAnnotation', NULL::varchar,", "'sysDataSetDateTimeTZ', NULL::timestamptz,", "'sysDataValidityStartDateTimeTZ', NULL::timestamptz,", "'sysDataValidityFinishDateTimeTZ', NULL::timestamptz,", "'sysPartitionRemovableRecordKey_RefID', NULL::bigint,", "'sysBranch_RefID', varInstitutionBranchID::bigint,", "'sysBaseCurrency_RefID',varBaseCurrencyID::bigint,", "'name', ", IF(EXACT($B24, ""), "null", CONCATENATE("'", SUBSTITUTE($B24, "'", "\'"), "'")), "::varchar", ")))::varchar;")) -> varSQL := varSQL || (CASE WHEN (varSQL = '') THEN '' ELSE ', ' END) || (SELECT JSON_BUILD_OBJECT ('recordID', NULL::bigint,'entities', JSON_BUILD_OBJECT ('sysLoginSession_RefID', varSystemLoginSession::bigint,'sysDataAnnotation', NULL::varchar,'sysDataSetDateTimeTZ', NULL::timestamptz,'sysDataValidityStartDateTimeTZ', NULL::timestamptz,'sysDataValidityFinishDateTimeTZ', NULL::timestamptz,'sysPartitionRemovableRecordKey_RefID', NULL::bigint,'sysBranch_RefID', varInstitutionBranchID::bigint,'sysBaseCurrency_RefID',varBaseCurrencyID::bigint,'name', 'HR, GA, & TAM General Manager'::varchar)))::varchar;
B25: Sales General Manager | D25: =D24 + IF(EXACT(E25, ""), 0, 1) -> 95000000000018 | E25: =IF(EXACT(B25, ""), "", CONCATENATE("PERFORM ""SchSysConfig"".""Func_TblAppObject_UserRole_SET""(varSystemLoginSession, null::bigint, null::varchar, null::timestamptz, null::timestamptz, null::varchar, varInstitutionBranchID, varBaseCurrencyID, ", (IF(EXACT(B25, ""), "NULL", CONCATENATE("'", B25, "'"))),"::varchar);")) -> PERFORM "SchSysConfig"."Func_TblAppObject_UserRole_SET"(varSystemLoginSession, null::bigint, null::varchar, null::timestamptz, null::timestamptz, null::varchar, varInstitutionBranchID, varBaseCurrencyID, 'Sales General Manager'::varchar); | G25: =IF(EXACT($E25, ""), "", CONCATENATE( "varSQL := varSQL || (CASE WHEN (varSQL = '') THEN '' ELSE ', ' END) || (SELECT JSON_BUILD_OBJECT (", "'recordID', NULL::bigint,", "'entities', ", "JSON_BUILD_OBJECT (", "'sysLoginSession_RefID', varSystemLoginSession::bigint,", "'sysDataAnnotation', NULL::varchar,", "'sysDataSetDateTimeTZ', NULL::timestamptz,", "'sysDataValidityStartDateTimeTZ', NULL::timestamptz,", "'sysDataValidityFinishDateTimeTZ', NULL::timestamptz,", "'sysPartitionRemovableRecordKey_RefID', NULL::bigint,", "'sysBranch_RefID', varInstitutionBranchID::bigint,", "'sysBaseCurrency_RefID',varBaseCurrencyID::bigint,", "'name', ", IF(EXACT($B25, ""), "null", CONCATENATE("'", SUBSTITUTE($B25, "'", "\'"), "'")), "::varchar", ")))::varchar;")) -> varSQL := varSQL || (CASE WHEN (varSQL = '') THEN '' ELSE ', ' END) || (SELECT JSON_BUILD_OBJECT ('recordID', NULL::bigint,'entities', JSON_BUILD_OBJECT ('sysLoginSession_RefID', varSystemLoginSession::bigint,'sysDataAnnotation', NULL::varchar,'sysDataSetDateTimeTZ', NULL::timestamptz,'sysDataValidityStartDateTimeTZ', NULL::timestamptz,'sysDataValidityFinishDateTimeTZ', NULL::timestamptz,'sysPartitionRemovableRecordKey_RefID', NULL::bigint,'sysBranch_RefID', varInstitutionBranchID::bigint,'sysBaseCurrency_RefID',varBaseCurrencyID::bigint,'name', 'Sales General Manager'::varchar)))::varchar;
D26: =D25 + IF(EXACT(E26, ""), 0, 1) -> 95000000000018 | E26: =IF(EXACT(B26, ""), "", CONCATENATE("PERFORM ""SchSysConfig"".""Func_TblAppObject_UserRole_SET""(varSystemLoginSession, null::bigint, null::varchar, null::timestamptz, null::timestamptz, null::varchar, varInstitutionBranchID, varBaseCurrencyID, ", (IF(EXACT(B26, ""), "NULL", CONCATENATE("'", B26, "'"))),"::varchar);")) | G26: =IF(EXACT($E26, ""), "", CONCATENATE( "varSQL := varSQL || (CASE WHEN (varSQL = '') THEN '' ELSE ', ' END) || (SELECT JSON_BUILD_OBJECT (", "'recordID', NULL::bigint,", "'entities', ", "JSON_BUILD_OBJECT (", "'sysLoginSession_RefID', varSystemLoginSession::bigint,", "'sysDataAnnotation', NULL::varchar,", "'sysDataSetDateTimeTZ', NULL::timestamptz,", "'sysDataValidityStartDateTimeTZ', NULL::timestamptz,", "'sysDataValidityFinishDateTimeTZ', NULL::timestamptz,", "'sysPartitionRemovableRecordKey_RefID', NULL::bigint,", "'sysBranch_RefID', varInstitutionBranchID::bigint,", "'sysBaseCurrency_RefID',varBaseCurrencyID::bigint,", "'name', ", IF(EXACT($B26, ""), "null", CONCATENATE("'", SUBSTITUTE($B26, "'", "\'"), "'")), "::varchar", ")))::varchar;"))
B27: Project Manager | D27: =D26 + IF(EXACT(E27, ""), 0, 1) -> 95000000000019 | E27: =IF(EXACT(B27, ""), "", CONCATENATE("PERFORM ""SchSysConfig"".""Func_TblAppObject_UserRole_SET""(varSystemLoginSession, null::bigint, null::varchar, null::timestamptz, null::timestamptz, null::varchar, varInstitutionBranchID, varBaseCurrencyID, ", (IF(EXACT(B27, ""), "NULL", CONCATENATE("'", B27, "'"))),"::varchar);")) -> PERFORM "SchSysConfig"."Func_TblAppObject_UserRole_SET"(varSystemLoginSession, null::bigint, null::varchar, null::timestamptz, null::timestamptz, null::varchar, varInstitutionBranchID, varBaseCurrencyID, 'Project Manager'::varchar); | G27: =IF(EXACT($E27, ""), "", CONCATENATE( "varSQL := varSQL || (CASE WHEN (varSQL = '') THEN '' ELSE ', ' END) || (SELECT JSON_BUILD_OBJECT (", "'recordID', NULL::bigint,", "'entities', ", "JSON_BUILD_OBJECT (", "'sysLoginSession_RefID', varSystemLoginSession::bigint,", "'sysDataAnnotation', NULL::varchar,", "'sysDataSetDateTimeTZ', NULL::timestamptz,", "'sysDataValidityStartDateTimeTZ', NULL::timestamptz,", "'sysDataValidityFinishDateTimeTZ', NULL::timestamptz,", "'sysPartitionRemovableRecordKey_RefID', NULL::bigint,", "'sysBranch_RefID', varInstitutionBranchID::bigint,", "'sysBaseCurrency_RefID',varBaseCurrencyID::bigint,", "'name', ", IF(EXACT($B27, ""), "null", CONCATENATE("'", SUBSTITUTE($B27, "'", "\'"), "'")), "::varchar", ")))::varchar;")) -> varSQL := varSQL || (CASE WHEN (varSQL = '') THEN '' ELSE ', ' END) || (SELECT JSON_BUILD_OBJECT ('recordID', NULL::bigint,'entities', JSON_BUILD_OBJECT ('sysLoginSession_RefID', varSystemLoginSession::bigint,'sysDataAnnotation', NULL::varchar,'sysDataSetDateTimeTZ', NULL::timestamptz,'sysDataValidityStartDateTimeTZ', NULL::timestamptz,'sysDataValidityFinishDateTimeTZ', NULL::timestamptz,'sysPartitionRemovableRecordKey_RefID', NULL::bigint,'sysBranch_RefID', varInstitutionBranchID::bigint,'sysBaseCurrency_RefID',varBaseCurrencyID::bigint,'name', 'Project Manager'::varchar)))::varchar;
B28: Site Manager | D28: =D27 + IF(EXACT(E28, ""), 0, 1) -> 95000000000020 | E28: =IF(EXACT(B28, ""), "", CONCATENATE("PERFORM ""SchSysConfig"".""Func_TblAppObject_UserRole_SET""(varSystemLoginSession, null::bigint, null::varchar, null::timestamptz, null::timestamptz, null::varchar, varInstitutionBranchID, varBaseCurrencyID, ", (IF(EXACT(B28, ""), "NULL", CONCATENATE("'", B28, "'"))),"::varchar);")) -> PERFORM "SchSysConfig"."Func_TblAppObject_UserRole_SET"(varSystemLoginSession, null::bigint, null::varchar, null::timestamptz, null::timestamptz, null::varchar, varInstitutionBranchID, varBaseCurrencyID, 'Site Manager'::varchar); | G28: =IF(EXACT($E28, ""), "", CONCATENATE( "varSQL := varSQL || (CASE WHEN (varSQL = '') THEN '' ELSE ', ' END) || (SELECT JSON_BUILD_OBJECT (", "'recordID', NULL::bigint,", "'entities', ", "JSON_BUILD_OBJECT (", "'sysLoginSession_RefID', varSystemLoginSession::bigint,", "'sysDataAnnotation', NULL::varchar,", "'sysDataSetDateTimeTZ', NULL::timestamptz,", "'sysDataValidityStartDateTimeTZ', NULL::timestamptz,", "'sysDataValidityFinishDateTimeTZ', NULL::timestamptz,", "'sysPartitionRemovableRecordKey_RefID', NULL::bigint,", "'sysBranch_RefID', varInstitutionBranchID::bigint,", "'sysBaseCurrency_RefID',varBaseCurrencyID::bigint,", "'name', ", IF(EXACT($B28, ""), "null", CONCATENATE("'", SUBSTITUTE($B28, "'", "\'"), "'")), "::varchar", ")))::varchar;")) -> varSQL := varSQL || (CASE WHEN (varSQL = '') THEN '' ELSE ', ' END) || (SELECT JSON_BUILD_OBJECT ('recordID', NULL::bigint,'entities', JSON_BUILD_OBJECT ('sysLoginSession_RefID', varSystemLoginSession::bigint,'sysDataAnnotation', NULL::varchar,'sysDataSetDateTimeTZ', NULL::timestamptz,'sysDataValidityStartDateTimeTZ', NULL::timestamptz,'sysDataValidityFinishDateTimeTZ', NULL::timestamptz,'sysPartitionRemovableRecordKey_RefID', NULL::bigint,'sysBranch_RefID', varInstitutionBranchID::bigint,'sysBaseCurrency_RefID',varBaseCurrencyID::bigint,'name', 'Site Manager'::varchar)))::varchar;
B29: Project Controller Coordinator | D29: =D28 + IF(EXACT(E29, ""), 0, 1) -> 95000000000021 | E29: =IF(EXACT(B29, ""), "", CONCATENATE("PERFORM ""SchSysConfig"".""Func_TblAppObject_UserRole_SET""(varSystemLoginSession, null::bigint, null::varchar, null::timestamptz, null::timestamptz, null::varchar, varInstitutionBranchID, varBaseCurrencyID, ", (IF(EXACT(B29, ""), "NULL", CONCATENATE("'", B29, "'"))),"::varchar);")) -> PERFORM "SchSysConfig"."Func_TblAppObject_UserRole_SET"(varSystemLoginSession, null::bigint, null::varchar, null::timestamptz, null::timestamptz, null::varchar, varInstitutionBranchID, varBaseCurrencyID, 'Project Controller Coordinator'::varchar); | G29: =IF(EXACT($E29, ""), "", CONCATENATE( "varSQL := varSQL || (CASE WHEN (varSQL = '') THEN '' ELSE ', ' END) || (SELECT JSON_BUILD_OBJECT (", "'recordID', NULL::bigint,", "'entities', ", "JSON_BUILD_OBJECT (", "'sysLoginSession_RefID', varSystemLoginSession::bigint,", "'sysDataAnnotation', NULL::varchar,", "'sysDataSetDateTimeTZ', NULL::timestamptz,", "'sysDataValidityStartDateTimeTZ', NULL::timestamptz,", "'sysDataValidityFinishDateTimeTZ', NULL::timestamptz,", "'sysPartitionRemovableRecordKey_RefID', NULL::bigint,", "'sysBranch_RefID', varInstitutionBranchID::bigint,", "'sysBaseCurrency_RefID',varBaseCurrencyID::bigint,", "'name', ", IF(EXACT($B29, ""), "null", CONCATENATE("'", SUBSTITUTE($B29, "'", "\'"), "'")), "::varchar", ")))::varchar;")) -> varSQL := varSQL || (CASE WHEN (varSQL = '') THEN '' ELSE ', ' END) || (SELECT JSON_BUILD_OBJECT ('recordID', NULL::bigint,'entities', JSON_BUILD_OBJECT ('sysLoginSession_RefID', varSystemLoginSession::bigint,'sysDataAnnotation', NULL::varchar,'sysDataSetDateTimeTZ', NULL::timestamptz,'sysDataValidityStartDateTimeTZ', NULL::timestamptz,'sysDataValidityFinishDateTimeTZ', NULL::timestamptz,'sysPartitionRemovableRecordKey_RefID', NULL::bigint,'sysBranch_RefID', varInstitutionBranchID::bigint,'sysBaseCurrency_RefID',varBaseCurrencyID::bigint,'name', 'Project Controller Coordinator'::varchar)))::varchar;
B30: Project Controller Staff | D30: =D29 + IF(EXACT(E30, ""), 0, 1) -> 95000000000022 | E30: =IF(EXACT(B30, ""), "", CONCATENATE("PERFORM ""SchSysConfig"".""Func_TblAppObject_UserRole_SET""(varSystemLoginSession, null::bigint, null::varchar, null::timestamptz, null::timestamptz, null::varchar, varInstitutionBranchID, varBaseCurrencyID, ", (IF(EXACT(B30, ""), "NULL", CONCATENATE("'", B30, "'"))),"::varchar);")) -> PERFORM "SchSysConfig"."Func_TblAppObject_UserRole_SET"(varSystemLoginSession, null::bigint, null::varchar, null::timestamptz, null::timestamptz, null::varchar, varInstitutionBranchID, varBaseCurrencyID, 'Project Controller Staff'::varchar); | G30: =IF(EXACT($E30, ""), "", CONCATENATE( "varSQL := varSQL || (CASE WHEN (varSQL = '') THEN '' ELSE ', ' END) || (SELECT JSON_BUILD_OBJECT (", "'recordID', NULL::bigint,", "'entities', ", "JSON_BUILD_OBJECT (", "'sysLoginSession_RefID', varSystemLoginSession::bigint,", "'sysDataAnnotation', NULL::varchar,", "'sysDataSetDateTimeTZ', NULL::timestamptz,", "'sysDataValidityStartDateTimeTZ', NULL::timestamptz,", "'sysDataValidityFinishDateTimeTZ', NULL::timestamptz,", "'sysPartitionRemovableRecordKey_RefID', NULL::bigint,", "'sysBranch_RefID', varInstitutionBranchID::bigint,", "'sysBaseCurrency_RefID',varBaseCurrencyID::bigint,", "'name', ", IF(EXACT($B30, ""), "null", CONCATENATE("'", SUBSTITUTE($B30, "'", "\'"), "'")), "::varchar", ")))::varchar;")) -> varSQL := varSQL || (CASE WHEN (varSQL = '') THEN '' ELSE ', ' END) || (SELECT JSON_BUILD_OBJECT ('recordID', NULL::bigint,'entities', JSON_BUILD_OBJECT ('sysLoginSession_RefID', varSystemLoginSession::bigint,'sysDataAnnotation', NULL::varchar,'sysDataSetDateTimeTZ', NULL::timestamptz,'sysDataValidityStartDateTimeTZ', NULL::timestamptz,'sysDataValidityFinishDateTimeTZ', NULL::timestamptz,'sysPartitionRemovableRecordKey_RefID', NULL::bigint,'sysBranch_RefID', varInstitutionBranchID::bigint,'sysBaseCurrency_RefID',varBaseCurrencyID::bigint,'name', 'Project Controller Staff'::varchar)))::varchar;
B31: Project Administrator Coordinator | D31: =D30 + IF(EXACT(E31, ""), 0, 1) -> 95000000000023 | E31: =IF(EXACT(B31, ""), "", CONCATENATE("PERFORM ""SchSysConfig"".""Func_TblAppObject_UserRole_SET""(varSystemLoginSession, null::bigint, null::varchar, null::timestamptz, null::timestamptz, null::varchar, varInstitutionBranchID, varBaseCurrencyID, ", (IF(EXACT(B31, ""), "NULL", CONCATENATE("'", B31, "'"))),"::varchar);")) -> PERFORM "SchSysConfig"."Func_TblAppObject_UserRole_SET"(varSystemLoginSession, null::bigint, null::varchar, null::timestamptz, null::timestamptz, null::varchar, varInstitutionBranchID, varBaseCurrencyID, 'Project Administrator Coordinator'::varchar); | G31: =IF(EXACT($E31, ""), "", CONCATENATE( "varSQL := varSQL || (CASE WHEN (varSQL = '') THEN '' ELSE ', ' END) || (SELECT JSON_BUILD_OBJECT (", "'recordID', NULL::bigint,", "'entities', ", "JSON_BUILD_OBJECT (", "'sysLoginSession_RefID', varSystemLoginSession::bigint,", "'sysDataAnnotation', NULL::varchar,", "'sysDataSetDateTimeTZ', NULL::timestamptz,", "'sysDataValidityStartDateTimeTZ', NULL::timestamptz,", "'sysDataValidityFinishDateTimeTZ', NULL::timestamptz,", "'sysPartitionRemovableRecordKey_RefID', NULL::bigint,", "'sysBranch_RefID', varInstitutionBranchID::bigint,", "'sysBaseCurrency_RefID',varBaseCurrencyID::bigint,", "'name', ", IF(EXACT($B31, ""), "null", CONCATENATE("'", SUBSTITUTE($B31, "'", "\'"), "'")), "::varchar", ")))::varchar;")) -> varSQL := varSQL || (CASE WHEN (varSQL = '') THEN '' ELSE ', ' END) || (SELECT JSON_BUILD_OBJECT ('recordID', NULL::bigint,'entities', JSON_BUILD_OBJECT ('sysLoginSession_RefID', varSystemLoginSession::bigint,'sysDataAnnotation', NULL::varchar,'sysDataSetDateTimeTZ', NULL::timestamptz,'sysDataValidityStartDateTimeTZ', NULL::timestamptz,'sysDataValidityFinishDateTimeTZ', NULL::timestamptz,'sysPartitionRemovableRecordKey_RefID', NULL::bigint,'sysBranch_RefID', varInstitutionBranchID::bigint,'sysBaseCurrency_RefID',varBaseCurrencyID::bigint,'name', 'Project Administrator Coordinator'::varchar)))::varchar;
B32: Project Administrator Staff | D32: =D31 + IF(EXACT(E32, ""), 0, 1) -> 95000000000024 | E32: =IF(EXACT(B32, ""), "", CONCATENATE("PERFORM ""SchSysConfig"".""Func_TblAppObject_UserRole_SET""(varSystemLoginSession, null::bigint, null::varchar, null::timestamptz, null::timestamptz, null::varchar, varInstitutionBranchID, varBaseCurrencyID, ", (IF(EXACT(B32, ""), "NULL", CONCATENATE("'", B32, "'"))),"::varchar);")) -> PERFORM "SchSysConfig"."Func_TblAppObject_UserRole_SET"(varSystemLoginSession, null::bigint, null::varchar, null::timestamptz, null::timestamptz, null::varchar, varInstitutionBranchID, varBaseCurrencyID, 'Project Administrator Staff'::varchar); | G32: =IF(EXACT($E32, ""), "", CONCATENATE( "varSQL := varSQL || (CASE WHEN (varSQL = '') THEN '' ELSE ', ' END) || (SELECT JSON_BUILD_OBJECT (", "'recordID', NULL::bigint,", "'entities', ", "JSON_BUILD_OBJECT (", "'sysLoginSession_RefID', varSystemLoginSession::bigint,", "'sysDataAnnotation', NULL::varchar,", "'sysDataSetDateTimeTZ', NULL::timestamptz,", "'sysDataValidityStartDateTimeTZ', NULL::timestamptz,", "'sysDataValidityFinishDateTimeTZ', NULL::timestamptz,", "'sysPartitionRemovableRecordKey_RefID', NULL::bigint,", "'sysBranch_RefID', varInstitutionBranchID::bigint,", "'sysBaseCurrency_RefID',varBaseCurrencyID::bigint,", "'name', ", IF(EXACT($B32, ""), "null", CONCATENATE("'", SUBSTITUTE($B32, "'", "\'"), "'")), "::varchar", ")))::varchar;")) -> varSQL := varSQL || (CASE WHEN (varSQL = '') THEN '' ELSE ', ' END) || (SELECT JSON_BUILD_OBJECT ('recordID', NULL::bigint,'entities', JSON_BUILD_OBJECT ('sysLoginSession_RefID', varSystemLoginSession::bigint,'sysDataAnnotation', NULL::varchar,'sysDataSetDateTimeTZ', NULL::timestamptz,'sysDataValidityStartDateTimeTZ', NULL::timestamptz,'sysDataValidityFinishDateTimeTZ', NULL::timestamptz,'sysPartitionRemovableRecordKey_RefID', NULL::bigint,'sysBranch_RefID', varInstitutionBranchID::bigint,'sysBaseCurrency_RefID',varBaseCurrencyID::bigint,'name', 'Project Administrator Staff'::varchar)))::varchar;
B33: Project Worker Coordinator | D33: =D32 + IF(EXACT(E33, ""), 0, 1) -> 95000000000025 | E33: =IF(EXACT(B33, ""), "", CONCATENATE("PERFORM ""SchSysConfig"".""Func_TblAppObject_UserRole_SET""(varSystemLoginSession, null::bigint, null::varchar, null::timestamptz, null::timestamptz, null::varchar, varInstitutionBranchID, varBaseCurrencyID, ", (IF(EXACT(B33, ""), "NULL", CONCATENATE("'", B33, "'"))),"::varchar);")) -> PERFORM "SchSysConfig"."Func_TblAppObject_UserRole_SET"(varSystemLoginSession, null::bigint, null::varchar, null::timestamptz, null::timestamptz, null::varchar, varInstitutionBranchID, varBaseCurrencyID, 'Project Worker Coordinator'::varchar); | G33: =IF(EXACT($E33, ""), "", CONCATENATE( "varSQL := varSQL || (CASE WHEN (varSQL = '') THEN '' ELSE ', ' END) || (SELECT JSON_BUILD_OBJECT (", "'recordID', NULL::bigint,", "'entities', ", "JSON_BUILD_OBJECT (", "'sysLoginSession_RefID', varSystemLoginSession::bigint,", "'sysDataAnnotation', NULL::varchar,", "'sysDataSetDateTimeTZ', NULL::timestamptz,", "'sysDataValidityStartDateTimeTZ', NULL::timestamptz,", "'sysDataValidityFinishDateTimeTZ', NULL::timestamptz,", "'sysPartitionRemovableRecordKey_RefID', NULL::bigint,", "'sysBranch_RefID', varInstitutionBranchID::bigint,", "'sysBaseCurrency_RefID',varBaseCurrencyID::bigint,", "'name', ", IF(EXACT($B33, ""), "null", CONCATENATE("'", SUBSTITUTE($B33, "'", "\'"), "'")), "::varchar", ")))::varchar;")) -> varSQL := varSQL || (CASE WHEN (varSQL = '') THEN '' ELSE ', ' END) || (SELECT JSON_BUILD_OBJECT ('recordID', NULL::bigint,'entities', JSON_BUILD_OBJECT ('sysLoginSession_RefID', varSystemLoginSession::bigint,'sysDataAnnotation', NULL::varchar,'sysDataSetDateTimeTZ', NULL::timestamptz,'sysDataValidityStartDateTimeTZ', NULL::timestamptz,'sysDataValidityFinishDateTimeTZ', NULL::timestamptz,'sysPartitionRemovableRecordKey_RefID', NULL::bigint,'sysBranch_RefID', varInstitutionBranchID::bigint,'sysBaseCurrency_RefID',varBaseCurrencyID::bigint,'name', 'Project Worker Coordinator'::varchar)))::varchar;
B34: Project Worker Staff | D34: =D33 + IF(EXACT(E34, ""), 0, 1) -> 95000000000026 | E34: =IF(EXACT(B34, ""), "", CONCATENATE("PERFORM ""SchSysConfig"".""Func_TblAppObject_UserRole_SET""(varSystemLoginSession, null::bigint, null::varchar, null::timestamptz, null::timestamptz, null::varchar, varInstitutionBranchID, varBaseCurrencyID, ", (IF(EXACT(B34, ""), "NULL", CONCATENATE("'", B34, "'"))),"::varchar);")) -> PERFORM "SchSysConfig"."Func_TblAppObject_UserRole_SET"(varSystemLoginSession, null::bigint, null::varchar, null::timestamptz, null::timestamptz, null::varchar, varInstitutionBranchID, varBaseCurrencyID, 'Project Worker Staff'::varchar); | G34: =IF(EXACT($E34, ""), "", CONCATENATE( "varSQL := varSQL || (CASE WHEN (varSQL = '') THEN '' ELSE ', ' END) || (SELECT JSON_BUILD_OBJECT (", "'recordID', NULL::bigint,", "'entities', ", "JSON_BUILD_OBJECT (", "'sysLoginSession_RefID', varSystemLoginSession::bigint,", "'sysDataAnnotation', NULL::varchar,", "'sysDataSetDateTimeTZ', NULL::timestamptz,", "'sysDataValidityStartDateTimeTZ', NULL::timestamptz,", "'sysDataValidityFinishDateTimeTZ', NULL::timestamptz,", "'sysPartitionRemovableRecordKey_RefID', NULL::bigint,", "'sysBranch_RefID', varInstitutionBranchID::bigint,", "'sysBaseCurrency_RefID',varBaseCurrencyID::bigint,", "'name', ", IF(EXACT($B34, ""), "null", CONCATENATE("'", SUBSTITUTE($B34, "'", "\'"), "'")), "::varchar", ")))::varchar;")) -> varSQL := varSQL || (CASE WHEN (varSQL = '') THEN '' ELSE ', ' END) || (SELECT JSON_BUILD_OBJECT ('recordID', NULL::bigint,'entities', JSON_BUILD_OBJECT ('sysLoginSession_RefID', varSystemLoginSession::bigint,'sysDataAnnotation', NULL::varchar,'sysDataSetDateTimeTZ', NULL::timestamptz,'sysDataValidityStartDateTimeTZ', NULL::timestamptz,'sysDataValidityFinishDateTimeTZ', NULL::timestamptz,'sysPartitionRemovableRecordKey_RefID', NULL::bigint,'sysBranch_RefID', varInstitutionBranchID::bigint,'sysBaseCurrency_RefID',varBaseCurrencyID::bigint,'name', 'Project Worker Staff'::varchar)))::varchar;
D35: =D34 + IF(EXACT(E35, ""), 0, 1) -> 95000000000026 | E35: =IF(EXACT(B35, ""), "", CONCATENATE("PERFORM ""SchSysConfig"".""Func_TblAppObject_UserRole_SET""(varSystemLoginSession, null::bigint, null::varchar, null::timestamptz, null::timestamptz, null::varchar, varInstitutionBranchID, varBaseCurrencyID, ", (IF(EXACT(B35, ""), "NULL", CONCATENATE("'", B35, "'"))),"::varchar);")) | G35: =IF(EXACT($E35, ""), "", CONCATENATE( "varSQL := varSQL || (CASE WHEN (varSQL = '') THEN '' ELSE ', ' END) || (SELECT JSON_BUILD_OBJECT (", "'recordID', NULL::bigint,", "'entities', ", "JSON_BUILD_OBJECT (", "'sysLoginSession_RefID', varSystemLoginSession::bigint,", "'sysDataAnnotation', NULL::varchar,", "'sysDataSetDateTimeTZ', NULL::timestamptz,", "'sysDataValidityStartDateTimeTZ', NULL::timestamptz,", "'sysDataValidityFinishDateTimeTZ', NULL::timestamptz,", "'sysPartitionRemovableRecordKey_RefID', NULL::bigint,", "'sysBranch_RefID', varInstitutionBranchID::bigint,", "'sysBaseCurrency_RefID',varBaseCurrencyID::bigint,", "'name', ", IF(EXACT($B35, ""), "null", CONCATENATE("'", SUBSTITUTE($B35, "'", "\'"), "'")), "::varchar", ")))::varchar;"))
